Workbook
Name __S1: {"Book1"}
Name __S1: {"Book1"}
Name __S1: {"Book1"}
Name __S1: {"Book1"}
Name _a1: {"'Sheet1'!$L$16"}
Name _a1: {"'Sheet1'!$L$16"}
Name _a1: {"'Sheet1'!$L$16"}
Name _a1: {"'Sheet1'!$L$16"}
Name _S1: {"Book1"}
Name _S1: {"Book1"}
Name _S1: {"Book1"}
Name _S1: {"Book1"}
Name Ă: #REF!
Name Ạ196: #REF!
Name â259: #REF!
Name â259: #REF!
Name â312: #REF!
Name â312: #REF!
Name Acquisition_PlanA: #REF!
Name Acquisition_PlanB: #REF!
Name Actual: (PeriodInActual*(#REF!>0))*PeriodInPlan
Name Actual: (PeriodInActual*(#REF!>0))*PeriodInPlan
Name Actual: (PeriodInActual*(#REF!>0))*PeriodInPlan
Name Actual: (PeriodInActual*(#REF!>0))*PeriodInPlan
Name ActualBeyond: PeriodInActual*(#REF!>0)
Name ActualBeyond: PeriodInActual*(#REF!>0)
Name ActualBeyond: PeriodInActual*(#REF!>0)
Name ActualBeyond: PeriodInActual*(#REF!>0)
Name adf: #REF!
Name adf: #REF!
Name AdvIncQ12020: #REF!
Name AdvIncQ12021: #REF!
Name AdvIncQ12022: #REF!
Name AdvIncQ12023: #REF!
Name AdvIncQ12024: #REF!
Name AdvIncQ22020: #REF!
Name AdvIncQ22021: #REF!
Name AdvIncQ22022: #REF!
Name AdvIncQ22023: #REF!
Name AdvIncQ22024: #REF!
Name AdvIncQ32020: #REF!
Name AdvIncQ32021: #REF!
Name AdvIncQ32022: #REF!
Name AdvIncQ32023: #REF!
Name AdvIncQ32024: #REF!
Name AdvIncQ42020: #REF!
Name AdvIncQ42021: #REF!
Name AdvIncQ42022: #REF!
Name AdvIncQ42023: #REF!
Name AdvIncQ42024: #REF!
Name AdvPenRate2020: #REF!
Name AdvPenRate2021: #REF!
Name AdvPenRate2022: #REF!
Name AdvPenRate2023: #REF!
Name AdvPenRate2024: #REF!
Name AllReportList: #REF!
Name Amount_act: #REF!
Name Amount_CF: #REF!
Name Amount_F: #REF!
Name Amount_KPI_act: #REF!

Sheet IR
D3: category_product_name_final | E3: report_date | F3: closing_balance_total | G3: closing_balance_overdue | H3: closing_balance_indue | I3: closing_balance_dpd_under10
D4: Bikeloan | E4: 45839 | F4: 14756199 | G4: 9366003 | H4: 5390196 | I4: 14756199
D5: Bikeloan | E5: 45840 | F5: 14756199 | G5: 9366003 | H5: 5390196 | I5: 14756199 | J5: 45839 | W5: Only DPD 0 | Y5: DPDto10
D6: Bikeloan | E6: 45841 | F6: 14756199 | G6: 9366003 | H6: 5390196 | I6: 14756199 | J6: 45840 | P6: Sum of closing_balance_dpd_under10 | Q6: Column Labels | V6: IR | W6: =ROUND(SUM(Q18:S20)/SUM(Q15:S17)*365,3) -> 0.498 | Y6: =SUM(Q18:S20)/SUM(Y15:AA17)*365 -> 0.48738193
D7: Bikeloan | E7: 45842 | F7: 14756199 | G7: 9366003 | H7: 5390196 | I7: 14756199 | J7: 45841 | P7: Row Labels | Q7: Jul | R7: Aug | S7: Sep | T7: Grand Total
D8: Bikeloan | E8: 45843 | F8: 14756199 | G8: 9366003 | H8: 5390196 | I8: 14756199 | J8: 45842 | P8: Bikeloan | Q8: 239812300 | R8: 147123641 | S8: 125836026 | T8: 512771967
D9: Bikeloan | E9: 45844 | F9: 14756199 | G9: 9366003 | H9: 5390196 | I9: 14756199 | J9: 45843 | P9: Cashloan | Q9: 78436590748098 | R9: 90255148949428 | S9: 100589895287302 | T9: 269281634984828
D10: Bikeloan | E10: 45845 | F10: 14756199 | G10: 9366003 | H10: 5390196 | I10: 14756199 | J10: 45844 | P10: Overdraft | Q10: 7136242574215 | R10: 6746808038715 | S10: 5974343866384 | T10: 19857394479314
D11: Bikeloan | E11: 45846 | F11: 14756199 | G11: 9366003 | H11: 5390196 | I11: 14756199 | J11: 45845 | P11: Payday | Q11: 4622575283656 | R11: 6916178026946 | S11: 9155304671675 | T11: 20694057982277
D12: Bikeloan | E12: 45847 | F12: 14756199 | G12: 9366003 | H12: 5390196 | I12: 5390196 | J12: 45846 | P12: Paylater | Q12: 1614363094217 | R12: 1979638013131 | S12: 2393220164489 | T12: 5987221271837
D13: Bikeloan | E13: 45848 | F13: 14756199 | G13: 9366003 | H13: 5390196 | I13: 5390196 | J13: 45847 | P13: Grand Total | Q13: 91810011512486 | R13: 105897920151861 | S13: 118112889825876 | T13: 315820821490223
D14: Bikeloan | E14: 45849 | F14: 14756199 | G14: 9366003 | H14: 5390196 | I14: 5390196 | J14: 45848 | Q14: Indue | U14: Indue | Y14: Indue 10
D15: Bikeloan | E15: 45850 | F15: 14756199 | G15: 9366003 | H15: 5390196 | I15: 5390196 | J15: 45849 | O15: Balance | P15: CL | Q15: 76815377331487 | R15: 88356842904043 | S15: 98510201219076 | Y15: 78436590748098 | Z15: 90255148949428 | AA15: 100589895287302 | AD15: =SUM(Q18:S18)/SUM(Y15:AA15)*365 -> 0.49171714
D16: Bikeloan | E16: 45851 | F16: 14756199 | G16: 9366003 | H16: 5390196 | I16: 5390196 | J16: 45850 | P16: PD | Q16: 4524046156012 | R16: 6752896242376 | S16: 8931338959705 | Y16: 4622575283656 | Z16: 6916178026946 | AA16: 9155304671675 | AD16: =SUM(Q19:S19)/SUM(Y16:AA16)*365 -> 0.55165627
D17: Bikeloan | E17: 45852 | F17: 14756199 | G17: 9366003 | H17: 5390196 | I17: 5390196 | J17: 45851 | P17: OD | Q17: 7046693541652 | R17: 6663812994227 | S17: 5882758745896 | Y17: 7136242574215 | Z17: 6746808038715 | AA17: 5974343866384 | AD17: =SUM(Q20:S20)/SUM(Y17:AA17)*365 -> 0.36161072
D18: Bikeloan | E18: 45853 | F18: 14756199 | G18: 9366003 | H18: 5390196 | I18: 5390196 | J18: 45852 | O18: Thu lãi | P18: CL | Q18: =SUM(Q24:Q32) -> 106108627740 | R18: =SUM(R24:R32) -> 121377125554 | S18: =SUM(S24:S32) -> 135282451913 | U18: =Q18/Q15*365 -> 0.50419135 | V18: =R18/R15*365 -> 0.501406 | W18: =S18/S15*365 -> 0.50124854
D19: Bikeloan | E19: 45854 | F19: 14756199 | G19: 9366003 | H19: 5390196 | I19: 5390196 | J19: 45853 | P19: PD | Q19: =SUM(Q34:Q36) -> 7243462161 | R19: =SUM(R34:R36) -> 10646665908 | S19: =SUM(S34:S36) -> 13386602820 | U19: =Q19/Q16*365 -> 0.58440246 | V19: =R19/R16*365 -> 0.57546169 | W19: =S19/S16*365 -> 0.54707475
D20: Bikeloan | E20: 45855 | F20: 14756199 | G20: 9366003 | H20: 5390196 | I20: 5390196 | J20: 45854 | P20: OD | Q20: =Q39 -> 7097575425 | R20: =R39 -> 6741642587 | S20: =S39 -> 5833786603 | U20: =Q20/Q17*365 -> 0.36763555 | V20: =R20/R17*365 -> 0.36926299 | W20: =S20/S17*365 -> 0.36196149
D21: Bikeloan | E21: 45856 | F21: 14756199 | G21: 9366003 | H21: 5390196 | I21: 5390196 | J21: 45855
D22: Bikeloan | E22: 45857 | F22: 14756199 | G22: 9366003 | H22: 5390196 | I22: 5390196 | J22: 45856
D23: Bikeloan | E23: 45858 | F23: 14756199 | G23: 9366003 | H23: 5390196 | I23: 5390196 | J23: 45857
D24: Bikeloan | E24: 45859 | F24: 14756199 | G24: 9366003 | H24: 5390196 | I24: 5390196 | J24: 45858 | N24: cashloan | O24: cashloan | P24: VDS | Q24: 48463084122 | R24: 53272770215 | S24: 57987623749
D25: Bikeloan | E25: 45860 | F25: 14756199 | G25: 9366003 | H25: 5390196 | I25: 5390196 | J25: 45859 | N25: cashloan | O25: payroll | P25: VDS | Q25: 180134709 | R25: 177793395 | S25: 162715192
D26: Bikeloan | E26: 45861 | F26: 14756199 | G26: 9366003 | H26: 5390196 | I26: 5390196 | J26: 45860 | N26: cashloan | O26: cashloan | P26: BEG | Q26: 208673555 | R26: 170907800 | S26: 140807807
D27: Bikeloan | E27: 45862 | F27: 14756199 | G27: 9366003 | H27: 5390196 | I27: 5390196 | J27: 45861 | N27: cashloan | O27: cashloan | P27: NGS | Q27: 619417378 | R27: 493982632 | S27: 409380520
D28: Bikeloan | E28: 45863 | F28: 14756199 | G28: 9366003 | H28: 5390196 | I28: 5390196 | J28: 45862 | N28: cashloan | O28: cashloan | P28: CAKE | Q28: 42400864409 | R28: 48200259590 | S28: 53511511977
D29: Bikeloan | E29: 45864 | F29: 14756199 | G29: 9366003 | H29: 5390196 | I29: 5390196 | J29: 45863 | N29: cashloan | O29: cashloan | P29: MWG | Q29: 6378275744 | R29: 8067738498 | S29: 10087675211
D30: Bikeloan | E30: 45865 | F30: 14756199 | G30: 9366003 | H30: 5390196 | I30: 5390196 | J30: 45864 | N30: cashloan | O30: cashloan | P30: VNPAY | Q30: 2629288891 | R30: 2780395647 | S30: 2886582366
D31: Bikeloan | E31: 45866 | F31: 14203249 | G31: 9366003 | H31: 4837246 | I31: 4837246 | J31: 45865 | N31: cashloan | O31: cashloan | P31: ZALOPAY | Q31: 5190014930 | R31: 8151740830 | S31: 9991296076
D32: Bikeloan | E32: 45867 | F32: 14203249 | G32: 9366003 | H32: 4837246 | I32: 4837246 | J32: 45866 | N32: cashloan | O32: cashloan | P32: VNPOST | Q32: 38874002 | R32: 61536947 | S32: 104859015
D33: Bikeloan | E33: 45868 | F33: 14203249 | G33: 9366003 | H33: 4837246 | I33: 4837246 | J33: 45867
D34: Bikeloan | E34: 45869 | F34: 14203249 | G34: 9366003 | H34: 4837246 | I34: 4837246 | J34: 45868 | N34: Payday | O34: payday | P34: VDS | Q34: 6851571155 | R34: 7025398016 | S34: 8428697029
D35: Bikeloan | E35: 45870 | F35: 14203249 | G35: 9366003 | H35: 4837246 | I35: 4837246 | J35: 45869 | N35: Payday | O35: payroll | P35: VDS
D36: Bikeloan | E36: 45871 | F36: 14203249 | G36: 9366003 | H36: 4837246 | I36: 4837246 | J36: 45870 | N36: Payday | O36: payday | P36: CAKE | Q36: 391891006 | R36: 3621267892 | S36: 4957905791
D37: Bikeloan | E37: 45872 | F37: 14203249 | G37: 9366003 | H37: 4837246 | I37: 4837246 | J37: 45871 | N37: Payday | O37: payday | P37: VNPAY | Q37: 0 | R37: 0 | S37: 2307342
D38: Bikeloan | E38: 45873 | F38: 14203249 | G38: 9366003 | H38: 4837246 | I38: 4837246 | J38: 45872
D39: Bikeloan | E39: 45874 | F39: 14203249 | G39: 9366003 | H39: 4837246 | I39: 4837246 | J39: 45873 | N39: overdraft | P39: CAKE | Q39: 7097575425 | R39: 6741642587 | S39: 5833786603
D40: Bikeloan | E40: 45875 | F40: 14203249 | G40: 9366003 | H40: 4837246 | I40: 4837246 | J40: 45874
D41: Bikeloan | E41: 45876 | F41: 14203249 | G41: 9366003 | H41: 4837246 | I41: 4837246 | J41: 45875
D42: Bikeloan | E42: 45877 | F42: 14203249 | G42: 9366003 | H42: 4837246 | I42: 4837246 | J42: 45876
...

Sheet NOTE
A1: SAP MODEL - CASHLOAN
B2: OFFICIAL | N2: HKN | O2: v9 | P2: 20251001
B3: 1. Notes and disclaimer
C4: a. Giới thiệu về SAP
D5: - SAP: Single Account Profitability (Hiệu quả sản phẩm trên từng đơn vị sản phẩm)
D6: - Model SAP được sử dụng như một (01) trong các mô hình dự đoán hiệu quả vòng đời của sản phẩm.
D7: - Do sự phức tạp của sản phẩm, các hệ thống vận hành (hệ thống hạch kế toán, hệ thống quản trị rủi ro, hệ thống quản trị…), hành vi người sử dụng hành vi người sử dụng, model chỉ có thể mô phỏng tương đối trung bình vòng đời của sản phẩm.
D8: - Do tính chất thời điểm, mô hình được xây dựng mô phỏng theo cách vận hành sản phẩm tại thời điểm phát hành. Trường hợp hệ thống thay đổi, sản phẩm thay đổi, mô hình sẽ không thể phản ánh đúng bản chất vận hành sản phẩm.
D9: - Mô hình được tính toán dựa vào các yếu tố đầu vào xác định tại một thời điểm xác định, do đó kết quả của mô hình có thể có sự khác biệt so với thực tế vận hành sản phẩm.
D10: - Mô hình SAP Cashloan tính hiệu quả của khoản vay giải ngân và thời hạn tối đa được áp dụng là 5 năm ( 60 tháng) kể từ ngày bắt đầu sản phẩm đối với sử dụng phương pháp dự phòng IFRS
E11: - Lưu ý rằng trường hợp áp dụng cho khoản vay 5 năm, thì các chi phí sẽ không được tính toán đầy đủ do chi phí COF cho thời gian từ lúc khoản vay kết thúc tới lúc được xóa trên sổ kế toán.
E12: - Chỉ nên sử dụng với khoản vay dưới 4 năm (48 tháng) để được tính toán đầy đủ chi phí
E13: - Đối với phương pháp tính rủi ro VAS, thời hạn khoản vay tối đa sử dụng là 4 năm (48 tháng)
C15: b. Giới thiệu về PnL
D16: - Trong file tính này, Profit & Lost (PnL) được dự phóng từ trung bình cộng kết quả kinh doanh trên từng sản phẩm (SAP) với yếu tố "sale plan" (số giải ngân) qua từng tháng, do đó có thể khác biệt so với kết quả thực tế vận hành.
D17: - Dòng tiền thực tế qua từng tháng có thể khác biệt với mô hình tính toán do nhiều yếu tố tác động bên ngoài thay đổi, do đó, vui lòng chỉ sử dụng mô hình cho mục đích tham khảo.
D18: - Cho mục đích tính dự phòng dòng tiền ngắn và trung hạn, mô hình PnL được cutoff tại thời điểm 5 năm (60 tháng) kể từ ngày bắt đầu khởi chạy sản phẩm đầu tiên.
B20: 2. Instruction
D21: - Dành cho người sử dụng
E22: - Chỉ chỉnh sửa vào các ô màu vàng
E23: - 2 sheets "SAP_Leadsheet" và "Sale plan&PnL" cung cấp yếu tố đầu vào và đầu ra để tính toán mô hình SAP cũng như PnL.
F24: - Sheet SAP_Leadsheet được cấu trúc 2 phần, bên trái là các yếu tố đầu vào (input) và bên phải là kết quả dự đoán (output). Đơn vị sử dụng tại bảng tính là triệu VND (mVND) và phần trăm (%)
F25: - Sheet "Sale plan & PL" được cấu trúc 2 phần, bên trên là sale plan và bên dưới là kết quả PnL
E26: - 2 sheets "SAP_Spreadsheet" và "PL projection speadsheet" là các file tính toán cho 2 sheet "SAP_Leadsheet", "Sales plan & PL"
F27: - 2 sheets được cấu trúc từ trên xuống dưới theo thứ tự tính toán mô phỏng để đưa ra kết quả kinh doanh cuối cùng
F28: - 2 sheets đã được tạm khóa. Trường hợp cần mở khóa, điều chỉnh các yếu tố, vui lòng liên hệ với nhóm vận hành để được hỗ trợ.
D30: - Dành riêng cho người vận hành, hiệu chỉnh
E31: - Cần cẩn trọng khi điều chỉnh ở các file "speadsheet" vì 1 khi sai lệch rất khó tìm ra lỗi (VD: sửa nhầm ô, link nhầm vị trí,…)
B34: 3. Legend
C35: GENERAL INPUT
G37: Diễn giải | L37: Chú thích
D38: Risk input | G38: Loại phương pháp tính rủi ro | L38: Lựa chon phương pháp tính rủi ro VAS và IFRS
D39: Write off | G39: Thời điểm WO | L39: Lựa chọn thời điểm ghi nhận WO là 360 hoặc 180
C40: REVENUE INPUT
G42: Diễn giải | L42: Chú thích
C43: Amount & Tenor
D44: Loan amount | G44: Số tiền vay giải ngân (có thể bao gồm bảo hiểm hoặc không) | L44: Trường hợp số tiền giải ngân > giá trị hàng hóa, chỉ ghi = số thực tế giải ngân
D45: Payment Method | G45: Phương pháp tính lãi | L45: EMI (Equated monthly Installment)- số tiền thanh toán cố định hàng tháng
D46: Nominal Tenor | G46: Thời hạn vay | L46: Thời hạn ghi nhận trên khoản vay ( VD: 1 tháng, 3 tháng, 12 tháng,…)
D47: Maturity to Termination | G47: Thời hạn từ lúc đáo hạn tới lúc tới khi ra ngoại bảng | L47: Nên để 6 tháng để khớp với hệ thống kế toán, rủi ro đang ghi nhận WO180+
...

Sheet Leadsheet
B1: SAP CASHLOAN MODEL | D1: 1
B2: =NOTE!N2 -> HKN | C2: =NOTE!P2 -> 20251001 | D2: =NOTE!O2 -> v9 | K2: NOTE
K3: Please read carefully about before using model
B4: Product | C4: Unsecured Cashloan | D4: UPL | E4: Risk input | G4: IFRS | H4: =G4 -> IFRS | L4: Disclaimer
B5: Sub-Product | C5: Cashloan | D5: ALL | E5: Write off | G5: DPD180+ | H5: =G5 -> DPD180+ | L5: Instruction
B6: Sub-Segments | C6: ALL | D6: ALL | E6: Quarter | G6: Q3.2025 | H6: =G6 -> Q3.2025 | L6: Legend
B8: REVENUE INPUT | H8: Cur: mVND | K8: GENERAL OUTPUT | U8: Cur: mVND
B10: Amount & Tenor | C10: Loan amount | E10: =DATA!G20 -> 16.17916 | N10: Life time | O10: Year 1 | P10: Year 2 | Q10: Year 3 | R10: Year 4 | S10: Year 5 | T10: % ANR | U10: % Disbursement
C11: Payment Method | E11: EMI | K11: ANR | N11: =N29 -> 5.0874047 | O11: =O29 -> 8.1418252 | P11: =P29 -> 0.50577392 | Q11: =Q29 -> 0 | R11: =R29 -> 0 | S11: =S29 -> 0 | U11: =N11/$E$10 -> 0.31444183
C12: Nominal Tenor | E12: =DATA!H21 -> 14 | K12: TOI | N12: =SUM(N13:N15) -> 3.957503 | O12: =SUM(O13:O15) -> 3.9068384 | P12: =SUM(P13:P15) -> 0.050664579 | Q12: =SUM(Q13:Q15) -> 0 | R12: =SUM(R13:R15) -> 0 | S12: =SUM(S13:S15) -> 0 | T12: =N12/$E$14*12/$N$11 -> 0.46674129 | U12: =N12/$E$10 -> 0.24460497
C13: Maturity to Termination | E13: 6 | K13: Net interest income | N13: =N31 -> 2.9290827 | O13: =O31 -> 2.8807437 | P13: =P31 -> 0.048339043 | Q13: =Q31 -> 0 | R13: =R31 -> 0 | S13: =S31 -> 0 | T13: =N13/$E$14*12/$N$11 -> 0.34545112 | U13: =N13/$E$10 -> 0.18104047
C14: Month on book | E14: =E12+E13 -> 20 | K14: Net fee income | N14: =N34 -> 1.0284203 | O14: =O34 -> 1.0260947 | P14: =P34 -> 0.0023255362 | Q14: =Q34 -> 0 | R14: =R34 -> 0 | S14: =S34 -> 0 | T14: =N14/$E$14*12/$N$11 -> 0.12129017 | U14: =N14/$E$10 -> 0.063564503
K15: Other income | N15: =N38 -> 0 | O15: =O38 -> 0 | P15: =P38 -> 0 | Q15: =Q38 -> 0 | R15: =R38 -> 0 | S15: =S38 -> 0 | T15: =N15/$E$14*12/$N$11 -> 0 | U15: =N15/$E$10 -> 0
K16: PROVISION | N16: =N39 -> -2.4867754 | O16: =O39 -> -2.4144567 | P16: =P39 -> -0.072318713 | Q16: =Q39 -> 0 | R16: =R39 -> 0 | S16: =S39 -> 0 | T16: =N16/$E$14*12/$N$11 -> -0.29328614 | U16: =N16/$E$10 -> -0.15370238
B17: Pricing | C17: From | D17: To | E17: IR | F17: COF | G17: NIM | K17: OPEX | N17: =SUM(N18:N21) -> -1.051908 | O17: =SUM(O18:O21) -> -1.0208987 | P17: =SUM(P18:P21) -> -0.03100928 | Q17: =SUM(Q18:Q21) -> 0 | R17: =SUM(R18:R21) -> 0 | S17: =SUM(S18:S21) -> 0 | T17: =N17/$E$14*12/$N$11 -> -0.12406027 | U17: =N17/$E$10 -> -0.065016228
A18: 1 | B18: 1 | C18: 1 | D18: =E12 -> 14 | E18: =IR!AD15 -> 0.49171714 | F18: =COF!J1 -> 0.069062919 | G18: =E18-F18 -> 0.42265422 | K18: Acquisition cost | N18: =SUM(N41) -> -0.38973564 | O18: =SUM(O41) -> -0.4343572 | P18: =SUM(P41) -> 0.044621561 | Q18: =SUM(Q41) -> 0 | R18: =SUM(R41) -> 0 | S18: =SUM(S41) -> 0 | T18: =N18/$E$14*12/$N$11 -> -0.045964769 | U18: =N18/$E$10 -> -0.024088743
A19: 2 | B19: 2 | C19: =IF(D18="","",IF(D18>$E$12,"",D18+1)) -> 15 | D19: =E14 -> 20 | E19: =E18 -> 0.49171714 | F19: =COF!J1 -> 0.069062919 | G19: =E19-F19 -> 0.42265422 | K19: UW & Disbursal | N19: =N45 -> -0.066756457 | O19: =O45 -> -0.066756457 | P19: =P45 -> 0 | Q19: =Q45 -> 0 | R19: =R45 -> 0 | S19: =S45 -> 0 | T19: =N19/$E$14*12/$N$11 -> -0.0078731449 | U19: =N19/$E$10 -> -0.0041260768
A20: 3 | B20: 3 | K20: Collection & aftersale service | N20: =N48 -> -0.098911856 | O20: =O48 -> -0.080561609 | P20: =P48 -> -0.018350247 | Q20: =Q48 -> 0 | R20: =R48 -> 0 | S20: =S48 -> 0 | T20: =N20/$E$14*12/$N$11 -> -0.011665499 | U20: =N20/$E$10 -> -0.0061135347
A21: 4 | B21: 4 | K21: Support unit | N21: =N52 -> -0.49650401 | O21: =O52 -> -0.43922342 | P21: =P52 -> -0.057280595 | Q21: =Q52 -> 0 | R21: =R52 -> 0 | S21: =S52 -> 0 | T21: =N21/$E$14*12/$N$11 -> -0.058556853 | U21: =N21/$E$10 -> -0.030687873
A22: 5 | B22: 5 | K22: PBT | N22: =N12+N16+N17 -> 0.41881959 | O22: =O12+O16+O17 -> 0.47148301 | P22: =P12+P16+P17 -> -0.052663414 | Q22: =Q12+Q16+Q17 -> 0 | R22: =R12+R16+R17 -> 0 | S22: =S12+S16+S17 -> 0 | T22: =N22/$E$14*12/$N$11 -> 0.049394883 | U22: =N22/$E$10 -> 0.025886362
B23: 6 | K23: In which: PROFIT BEFORE SU | N23: =N22-N21 -> 0.91532361 | O23: =O22-O21 -> 0.91070643 | P23: =P22-P21 -> 0.0046171806 | Q23: =Q22-Q21 -> 0 | R23: =R22-R21 -> 0 | S23: =S22-S21 -> 0 | T23: =N23/$E$14*12/$N$11 -> 0.10795174 | U23: =N23/$E$10 -> 0.056574235
B25: Early prepayment | C25: From | D25: To | E25: Penalty fee | F25: Penalty IR | G25: %Attrition
B26: 1 | C26: 1 | D26: 1 | E26: =DATA!E73 -> 0.075631948 | G26: =DATA!G73 -> 0.11584981 | H26: per cohort | I26: 0.10601949 | K26: PERFORMANCE OUTPUT | U26: Cur: mVND
B27: 2 | C27: =D26+1 -> 2 | D27: 3 | E27: =DATA!E74 -> 0.075631948 | G27: =DATA!G74 -> 0.047684839 | H27: per cohort | I27: 0.047922919
B28: 3 | C28: =D27+1 -> 4 | D28: 14 | E28: =DATA!E75 -> 0.048252779 | G28: =DATA!G75 -> 0.023340862 | H28: per cohort | I28: 0.029 | N28: Life time | O28: Year 1 | P28: Year 2 | Q28: Year 3 | R28: Year 4 | S28: Year 5 | T28: % ANR | U28: % Disbursement
B29: 4 | C29: =IF(D28="","",IF(D28>$E$12,"",D28+1)) -> 15 | K29: ANR | N29: =SUM(SAP_Speadsheet!$D$50:$BF$50)/COUNTIF(SAP_Speadsheet!$D$50:$BF$50,">0") -> 5.0874047 | O29: =IFERROR(SUM(SAP_Speadsheet!$D$50:$P$50)/COUNTIF(SAP_Speadsheet!$D$50:$P$50,">0"),0) -> 8.1418252 | P29: =IFERROR(SUM(SAP_Speadsheet!$Q$50:$AB$50)/COUNTIF(SAP_Speadsheet!$Q$50:$AB$50,">0"),0) -> 0.50577392 | Q29: =IFERROR(SUM(SAP_Speadsheet!$AC$50:$AN$50)/COUNTIF(SAP_Speadsheet!$AC$50:$AN$50,">0"),0) -> 0 | R29: =IFERROR(SUM(SAP_Speadsheet!$AO$50:$AZ$50)/COUNTIF(SAP_Speadsheet!$AO$50:$AZ$50,">0"),0) -> 0 | S29: =IFERROR(SUM(SAP_Speadsheet!$BA$50:$BF$50)/COUNTIF(SAP_Speadsheet!$BA$50:$BF$50,">0"),0) -> 0 | U29: =N29/$E$10 -> 0.31444183
B30: 5 | C30: =IF(D29="","",IF(D29>$E$12,"",D29+1)) | E30: =IF(D30="",0,SUMIFS(#REF!,#REF!,Leadsheet!G$24,#REF!,Leadsheet!$A30,#REF!,Leadsheet!$C$4,#REF!,Leadsheet!$G$5,#REF!,Leadsheet!$D$5,#REF!,Leadsheet!G4)) -> 0 | F30: 0 | K30: TOI | N30: =SUM(O30:S30) -> 3.957503 | O30: =SUM(SAP_Speadsheet!$E$55:$P$55) -> 3.9068384 | P30: =SUM(SAP_Speadsheet!$Q$55:$AB$55) -> 0.050664579 | Q30: =SUM(SAP_Speadsheet!$AC$55:$AN$55) -> 0 | R30: =SUM(SAP_Speadsheet!$AO$55:$AZ$55) -> 0 | S30: =SUM(SAP_Speadsheet!$BA$55:$BF$55) -> 0 | T30: =N30/$E$14*12/$N$29 -> 0.46674129 | U30: =N30/$E$10 -> 0.24460497
B31: 6 | C31: =IF(D30="","",IF(D30>$E$12,"",D30+1)) | E31: =IF(D31="",0,SUMIFS(#REF!,#REF!,Leadsheet!G$24,#REF!,Leadsheet!$A31,#REF!,Leadsheet!$C$4,#REF!,Leadsheet!$G$5,#REF!,Leadsheet!$D$5,#REF!,Leadsheet!G4)) -> 0 | F31: 0 | K31: Net interest income | N31: =SUM(O31:S31) -> 2.9290827 | O31: =SUM(SAP_Speadsheet!$E$57:$P$57) -> 2.8807437 | P31: =SUM(SAP_Speadsheet!$Q$57:$AB$57) -> 0.048339043 | Q31: =SUM(SAP_Speadsheet!$AC$57:$AN$57) -> 0 | R31: =SUM(SAP_Speadsheet!$AO$57:$AZ$57) -> 0 | S31: =SUM(SAP_Speadsheet!$BA$57:$BF$57) -> 0 | T31: =N31/$E$14*12/$N$29 -> 0.34545112 | U31: =N31/$E$10 -> 0.18104047
K32: Interest income | N32: =SUM(O32:S32) -> 3.5146678 | O32: =SUM(SAP_Speadsheet!$E$58:$P$58) -> 3.4430419 | P32: =SUM(SAP_Speadsheet!$Q$58:$AB$58) -> 0.071625858 | Q32: =SUM(SAP_Speadsheet!$AC$58:$AN$58) -> 0 | R32: =SUM(SAP_Speadsheet!$AO$58:$AZ$58) -> 0 | S32: =SUM(SAP_Speadsheet!$BA$58:$BF$58) -> 0 | T32: =N32/$E$14*12/$N$29 -> 0.41451404 | U32: =N32/$E$10 -> 0.21723425
B33: Credit insurrance | C33: Banca Premium (excl. in loan) | F33: per disbursement amount | K33: Cost of fund | N33: =SUM(O33:S33) -> -0.58558503 | O33: =SUM(SAP_Speadsheet!$E$59:$P$59) -> -0.56229821 | P33: =SUM(SAP_Speadsheet!$Q$59:$AB$59) -> -0.023286816 | Q33: =SUM(SAP_Speadsheet!$AC$59:$AN$59) -> 0 | R33: =SUM(SAP_Speadsheet!$AO$59:$AZ$59) -> 0 | S33: =SUM(SAP_Speadsheet!$BA$59:$BF$59) -> 0 | T33: =N33/$E$14*12/$N$29 -> -0.069062919 | U33: =N33/$E$10 -> -0.036193784
C34: Banca Premium (incl. in loan) | E34: =DATA!J20 -> 0.068797748 | F34: per disbursement amount | K34: Net fee income | N34: =SUM(O34:S34) -> 1.0284203 | O34: =SUM(SAP_Speadsheet!$E$61:$P$61) -> 1.0260947 | P34: =SUM(SAP_Speadsheet!$Q$61:$AB$61) -> 0.0023255362 | Q34: =SUM(SAP_Speadsheet!$AC$61:$AN$61) -> 0 | R34: =SUM(SAP_Speadsheet!$AO$61:$AZ$61) -> 0 | S34: =SUM(SAP_Speadsheet!$BA$61:$BF$61) -> 0 | T34: =N34/$E$14*12/$N$29 -> 0.12129017 | U34: =N34/$E$10 -> 0.063564503
C35: Penetration | E35: =DATA!K20 -> 0.78737421 | F35: per disbursement amount | K35: Early termination fee | N35: =SUM(O35:S35) -> 0.31675681 | O35: =SUM(SAP_Speadsheet!$E$62:$P$62) -> 0.31443127 | P35: =SUM(SAP_Speadsheet!$Q$62:$AB$62) -> 0.0023255362 | Q35: =SUM(SAP_Speadsheet!$AC$62:$AN$62) -> 0 | R35: =SUM(SAP_Speadsheet!$AO$62:$AZ$62) -> 0 | S35: =SUM(SAP_Speadsheet!$BA$62:$BF$62) -> 0 | T35: =N35/$E$14*12/$N$29 -> 0.037357768 | U35: =N35/$E$10 -> 0.019578075
C36: Commission to CAKE | E36: 0.856 | F36: per disbursement amount | H36: done | K36: Insurance commission | N36: =SUM(O36:S36) -> 0.71166346 | O36: =SUM(SAP_Speadsheet!$E$63:$P$63) -> 0.71166346 | P36: =SUM(SAP_Speadsheet!$Q$63:$AB$63) -> 0 | Q36: =SUM(SAP_Speadsheet!$AC$63:$AN$63) -> 0 | R36: =SUM(SAP_Speadsheet!$AO$63:$AZ$63) -> 0 | S36: =SUM(SAP_Speadsheet!$BA$63:$BF$63) -> 0 | T36: =N36/$E$14*12/$N$29 -> 0.083932399 | U36: =N36/$E$10 -> 0.043986428
H37: done | K37: Support fee | N37: =SUM(O37:S37) -> 0 | O37: =SUM(SAP_Speadsheet!$E$64:$P$64) -> 0 | P37: =SUM(SAP_Speadsheet!$Q$64:$AB$64) -> 0 | Q37: =SUM(SAP_Speadsheet!$AC$64:$AN$64) -> 0 | R37: =SUM(SAP_Speadsheet!$AO$64:$AZ$64) -> 0 | S37: =SUM(SAP_Speadsheet!$BA$64:$BF$64) -> 0 | T37: =N37/$E$14*12/$N$29 -> 0 | U37: =N37/$E$10 -> 0
B38: Support fee | C38: One-time | F38: $ per account | K38: Other income | N38: =SUM(O38:S38) -> 0 | O38: =SUM(SAP_Speadsheet!$E$68:$P$68) -> 0 | P38: =SUM(SAP_Speadsheet!$Q$68:$AB$68) -> 0 | Q38: =SUM(SAP_Speadsheet!$AC$68:$AN$68) -> 0 | R38: =SUM(SAP_Speadsheet!$AO$68:$AZ$68) -> 0 | S38: =SUM(SAP_Speadsheet!$BA$68:$BF$68) -> 0 | T38: =N38/$E$14*12/$N$29 -> 0 | U38: =N38/$E$10 -> 0
C39: One-time | F39: % per ticketsize | K39: PROVISION | N39: =SUM(O39:S39) -> -2.4867754 | O39: =SUM(SAP_Speadsheet!$E$183:$P$183) -> -2.4144567 | P39: =SUM(SAP_Speadsheet!$Q$183:$AB$183) -> -0.072318713 | Q39: =SUM(SAP_Speadsheet!$AC$183:$AN$183) -> 0 | R39: =SUM(SAP_Speadsheet!$AO$183:$AZ$183) -> 0 | S39: =SUM(SAP_Speadsheet!$BA$183:$BF$183) -> 0 | T39: =N39/$E$14*12/$N$29 -> -0.29328614 | U39: =N39/$E$10 -> -0.15370238
C40: Monthly fee | F40: %monthly per ticketsize | K40: OPEX | N40: =SUM(O40:S40) -> -1.051908 | O40: =+SUM(O41,O45,O48,O52) -> -1.0208987 | P40: =+SUM(P41,P45,P48,P52) -> -0.03100928 | Q40: =+SUM(Q41,Q45,Q48,Q52) -> 0 | R40: =+SUM(R41,R45,R48,R52) -> 0 | S40: =+SUM(S41,S45,S48,S52) -> 0 | T40: =N40/$E$14*12/$N$29 -> -0.12406027 | U40: =N40/$E$10 -> -0.065016228
B41: COST INPUT | H41: Cur: mVND | K41: Acquisition cost | N41: =SUM(O41:S41) -> -0.38973564 | O41: =SUM(O42:O44) -> -0.4343572 | P41: =SUM(P42:P44) -> 0.044621561 | Q41: =SUM(Q42:Q44) -> 0 | R41: =SUM(R42:R44) -> 0 | S41: =SUM(S42:S44) -> 0 | T41: =N41/$E$14*12/$N$29 -> -0.045964769 | U41: =N41/$E$10 -> -0.024088743
K42: Lead Acquisition | N42: =SUM(O42:S42) -> 0 | O42: =SUM(SAP_Speadsheet!$E$73:$P$73) -> 0 | P42: =SUM(SAP_Speadsheet!$Q$73:$AB$73) -> 0 | Q42: =SUM(SAP_Speadsheet!$AC$73:$AN$73) -> 0 | R42: =SUM(SAP_Speadsheet!$AO$73:$AZ$73) -> 0 | S42: =SUM(SAP_Speadsheet!$BA$73:$BF$73) -> 0 | T42: =N42/$E$14*12/$N$29 -> 0 | U42: =N42/$E$10 -> 0
B43: Inflation rate | E43: 0.035 | F43: % per year | K43: Sharing performance | N43: =SUM(O43:S43) -> -0.3254024 | O43: =SUM(SAP_Speadsheet!$E$74:$P$74) -> -0.37002396 | P43: =SUM(SAP_Speadsheet!$Q$74:$AB$74) -> 0.044621561 | Q43: =SUM(SAP_Speadsheet!$AC$74:$AN$74) -> 0 | R43: =SUM(SAP_Speadsheet!$AO$74:$AZ$74) -> 0 | S43: =SUM(SAP_Speadsheet!$BA$74:$BF$74) -> 0 | T43: =N43/$E$14*12/$N$29 -> -0.038377415 | U43: =N43/$E$10 -> -0.020112441
...

Sheet COF
E1: =SUBTOTAL(9,E3:E43) -> 301221724219420 | F1: =SUBTOTAL(9,F3:F43) -> 5.699521e+10 | H1: =F1/E1*365 -> 0.069062919 | J1: 0.069062919
E2: =SUM(E4:E42) -> 348822682508025 | F2: =SUM(F4:F42) -> 6.3783621e+10 | H2: =SUM(H4:H42) -> 1173
B3: Nhom | C3: SP | D3: pl | E3: Sum of BALANCE | F3: Sum of Lai DCV | G3: Month | H3: Day
B4: UPL | C4: cl | D4: BE CASHLOAN | E4: 175237237692 | F4: 35108054 | G4: 9 | H4: 30
B5: UPL | C5: cl | D5: CAKE CASHLOAN | E5: 45792086198052 | F5: 8.8220401e+09 | G5: 9 | H5: 30
B6: UPL | C6: OD | D6: CAKE OVERDRAFT | E6: 7169005435909 | F6: 9.9109849e+08 | G6: 9 | H6: 30
B7: UPL | C7: PD | D7: CAKE PAYDAY | E7: 3672603510227 | F7: 5.4667902e+08 | G7: 9 | H7: 30
B8: UPL | C8: cl | D8: MWG CASHLOAN | E8: 7860835561894 | F8: 1.5211837e+09 | G8: 9 | H8: 30
B9: UPL | C9: cl | D9: NGS CASHLOAN | E9: 530282165595 | F9: 1.1619612e+08 | G9: 9 | H9: 30
B10: UPL | C10: cl | D10: VIETTEL CASHLOAN | E10: 47500871433668 | F10: 9.1994775e+09 | G10: 9 | H10: 30
B11: UPL | C11: PD | D11: VIETTEL PAYDAY | E11: 6555226346162 | F11: 1.021781e+09 | G11: 9 | H11: 30
B12: UPL | C12: PD | D12: VIETTEL PAYDAYPAYROLL | E12: 25934847005 | F12: 3828070.8 | G12: 9 | H12: 30
B13: UPL | C13: cl | D13: VIETTEL PAYROLL CASHLOAN | E13: 234239258102 | F13: 44742343 | G13: 9 | H13: 30
B14: UPL | C14: cl | D14: VNPAY CASHLOAN | E14: 2538375718443 | F14: 4.6902939e+08 | G14: 9 | H14: 30
B15: UPL | C15: cl | D15: VNPOST CASHLOAN | E15: 74534379401 | F15: 14917048 | G15: 9 | H15: 30
... B42: UPL | C42: cl | D42: Zalopay CASHLOAN | E42: 3450971717669 | F42: 6.384429e+08 | G42: 7 | H42: 31

Sheet DATA
B2: 1 | C2: Aproval rate, signed rate
C4: aprroval rate | E4: 0.282
C5: Signed rate | E5: 0.872
B14: 2 | C14: Disburse, Tenor, Insurance, IR
C16: Disburse date | D16: # Disburse | E16: Disburse amount (VND) | F16: Current balance (VND) | G16: Ticket size (VND) | H16: Avg tenor (Month) | I16: Avg IR (%) | J16: Insurance fee (VND) | K16: % Insurance penetration by date
C17: 45901 | D17: 64399 | E17: 1159826780000 | F17: 975998286085 | G17: 18010012 | H17: 16.439712 | I17: 0.510707 | J17: 60006780000 | K17: 0.78936008 | L17: =E17-J17 -> 1099820000000
C18: 45870 | D18: 55372 | E18: 847454320000 | F18: 634711890892 | G18: 15304745 | H18: 14.340967 | I18: 0.51144044 | J18: 43161320000 | K18: 0.78330203 | L18: =E18-J18 -> 804293000000
C19: 45839 | D19: 60775 | E19: 913801540000 | F19: 618505332727 | G19: 15035813 | H19: 14.339729 | I19: 0.51137145 | J19: 46934540000 | K19: 0.78863019 | L19: =E19-J19 -> 866867000000
C20: AVG | E20: =SUM(E17:E19)/10^9 -> 2921.0826 | G20: =SUM(E17:E19)/SUM(D17:D19)/10^6 -> 16.17916 | H20: =ROUND(SUMPRODUCT(H17:H19,$E$17:$E$19)/SUM($E$17:$E$19),0) -> 15 | I20: =SUMPRODUCT(I17:I19,E17:E19)/SUM(E17:E19) -> 0.51112764 | J20: =SUM(J17:J19)/SUMPRODUCT(K17:K19,L17:L19) -> 0.068797748 | K20: =SUMPRODUCT(K17:K19,E17:E19)/SUM(E17:E19) -> 0.78737421
G21: adjust tenor | H21: 14
B24: 3 | C24: UW, collection, MKT
C28: Chanel | D28: Catergory | E28: 45809 | F28: 45839 | G28: 45870 | H28: 45901 | M28: 45809 | N28: 45839 | O28: 45870 | P28: 45901 | R28: Chanel | S28: Catergory | T28: 45809 | U28: 45839 | V28: 45870 | W28: 45901
C29: VDS | D29: new_account | E29: 17951 | F29: 25713 | G29: 23272 | H29: 26446 | K29: VDS | L29: active_account | M29: 130324 | N29: 138380 | O29: 143825 | P29: 150208 | R29: VDS | S29: disburse/spend | U29: 380965670000 | V29: 346289200000 | W29: 465278440000 | X29: =SUM(U29:W29) -> 1192533310000 | Y29: =X29/SUM($X$29:$X$37) -> 0.40825045
C30: VDS | D30: new_account | E30: 24 | F30: 52 | G30: 63 | H30: 59 | K30: VDS | L30: active_account | M30: 777 | N30: 769 | O30: 762 | P30: 743 | R30: VDS | S30: disburse/spend | U30: 809800000 | V30: 1040200000 | W30: 953500000 | X30: =SUM(U30:W30) -> 2803500000 | Y30: =X30/SUM($X$29:$X$37) -> 0.0009597469
C31: BEG | D31: new_account | E31: 4 | F31: 5 | G31: 1 | H31: 3 | K31: BEG | L31: active_account | M31: 1241 | N31: 1035 | O31: 852 | P31: 714 | R31: BEG | S31: disburse/spend | U31: 98750000 | V31: 18900000 | W31: 42000000 | X31: =SUM(U31:W31) -> 159650000 | Y31: =X31/SUM($X$29:$X$37) -> 5.4654393e-05
C32: NGS | D32: new_account | K32: NGS | L32: active_account | M32: 3581 | N32: 2876 | O32: 2390 | P32: 2116 | R32: NGS | S32: disburse/spend | X32: =SUM(U32:W32) -> 0 | Y32: =X32/SUM($X$29:$X$37) -> 0
C33: CAKE | D33: new_account | E33: 18609 | F33: 24183 | G33: 21277 | H33: 25356 | K33: CAKE | L33: active_account | M33: 107363 | N33: 119486 | O33: 128198 | P33: 138424 | R33: CAKE | S33: disburse/spend | U33: 377695150000 | V33: 338629710000 | W33: 486195060000 | X33: =SUM(U33:W33) -> 1202519920000 | Y33: =X33/SUM($X$29:$X$37) -> 0.41166926
C34: MWG | D34: new_account | E34: 2611 | F34: 3066 | G34: 3734 | H34: 5548 | K34: MWG | L34: active_account | M34: 11727 | N34: 14390 | O34: 17656 | P34: 22600 | R34: MWG | S34: disburse/spend | U34: 52339690000 | V34: 63562000000 | W34: 100769400000 | X34: =SUM(U34:W34) -> 216671090000 | Y34: =X34/SUM($X$29:$X$37) -> 0.074174926
C35: VNPAY | D35: new_account | E35: 1354 | F35: 1192 | G35: 1135 | H35: 1479 | K35: VNPAY | L35: active_account | M35: 7123 | N35: 8013 | O35: 8674 | P35: 9522 | R35: VNPAY | S35: disburse/spend | U35: 13288530000 | V35: 13484550000 | W35: 21050400000 | X35: =SUM(U35:W35) -> 47823480000 | Y35: =X35/SUM($X$29:$X$37) -> 0.016371834
C36: ZALOPAY | D36: new_account | E36: 4759 | F36: 6515 | G36: 5840 | H36: 5356 | K36: ZALOPAY | L36: active_account | M36: 7243 | N36: 13144 | O36: 17888 | P36: 21762 | R36: ZALOPAY | S36: disburse/spend | U36: 87997150000 | V36: 83818310000 | W36: 83034230000 | X36: =SUM(U36:W36) -> 254849690000 | Y36: =X36/SUM($X$29:$X$37) -> 0.087244944
C37: VNPOST | D37: new_account | E37: 46 | F37: 49 | G37: 50 | H37: 152 | K37: VNPOST | L37: active_account | M37: 55 | N37: 103 | O37: 152 | P37: 301 | R37: VNPOST | S37: disburse/spend | U37: 606800000 | V37: 611450000 | W37: 2503750000 | X37: =SUM(U37:W37) -> 3722000000 | Y37: =X37/SUM($X$29:$X$37) -> 0.0012741851
E38: =SUM(E29:E37) -> 45358 | F38: =SUM(F29:F37) -> 60775 | G38: =SUM(G29:G37) -> 55372 | H38: =SUM(H29:H37) -> 64399 | M38: =SUM(M29:M37) -> 269434 | N38: =SUM(N29:N37) -> 298196 | O38: =SUM(O29:O37) -> 320397 | P38: =SUM(P29:P37) -> 346390 | U38: =SUM(U29:U37) -> 913801540000 | V38: =SUM(V29:V37) -> 847454320000 | W38: =SUM(W29:W37) -> 1159826780000
C41: =SUM(F41:H41)/SUM(F38:H38)/10^6 -> 0.064333234 | D41: marketing_acquisition_cost | F41: 5215708344 | G41: 4069855327 | H41: 2329544305
C42: =SUM(F42:H42)/SUM(F38:H38)/10^6 -> 0.062756457 | D42: Underwriting | F42: 2.8988283e+09 | G42: 3959670920 | H42: 4471927973
C43: 0.008 | D43: Collection | F43: 995176950 | G43: 1.0483845e+09 | H43: 1.2973813e+09 | I43: (Chi phi Q3 không đầy đủ do chuyển đổi hệ thống)
B47: 4 | C47: Partner acquisition cost | D47: (tính theo tỉ lệ giải ngân)
D48: Sharing TOI | E48: Leadgen
C49: VDS | D49: 0.5 | E49: 0
C50: VDS | D50: 0.5 | E50: 0
C51: BEG | D51: 0.5 | E51: 0
C52: NGS | D52: 0.35 | E52: 0
C53: CAKE | D53: 0 | E53: 0
C54: MWG | D54: 0.35 | E54: 0.005
C55: VNPAY | E55: 0.02
C56: ZALOPAY | E56: 0.025
C57: VNPOST | D57: 0.3 | E57: 0
C58: AVERAGE | D58: =SUMPRODUCT(D49:D57,X29:X37)/SUM(X29:X37) -> 0.23097591 | E58: =SUMPRODUCT(E49:E57,X29:X37)/SUM(X29:X37) -> 0.0028794349
B60: 5
C61: CAKE
C62: From | D62: To | E62: Penalty fee | F62: Penalty IR | G62: %Attrition | J62: From | K62: To | L62: Penalty fee | M62: Penalty IR | N62: %Attrition | Q62: From | R62: To | S62: Penalty fee | T62: Penalty IR | U62: %Attrition
...

Sheet SAP_Speadsheet
B1: SAP Speadsheet
C4: Method
C5: Month on book | D5: 0 | E5: =D5+1 -> 1 | F5: =E5+1 -> 2 | G5: =F5+1 -> 3 | H5: =G5+1 -> 4 | I5: =H5+1 -> 5 | J5: =I5+1 -> 6 | K5: =J5+1 -> 7 | L5: =K5+1 -> 8 | ... BL5: =BK5+1 -> 60
C6: Oustanding tenor | D6: =IF(Leadsheet!$E$12-SAP_Speadsheet!D5<0,0,Leadsheet!$E$12-SAP_Speadsheet!D5) -> 14 | E6: =IF(Leadsheet!$E$12-SAP_Speadsheet!E5<0,0,Leadsheet!$E$12-SAP_Speadsheet!E5) -> 13 | F6: =IF(Leadsheet!$E$12-SAP_Speadsheet!F5<0,0,Leadsheet!$E$12-SAP_Speadsheet!F5) -> 12 | G6: =IF(Leadsheet!$E$12-SAP_Speadsheet!G5<0,0,Leadsheet!$E$12-SAP_Speadsheet!G5) -> 11 | H6: =IF(Leadsheet!$E$12-SAP_Speadsheet!H5<0,0,Leadsheet!$E$12-SAP_Speadsheet!H5) -> 10 | I6: =IF(Leadsheet!$E$12-SAP_Speadsheet!I5<0,0,Leadsheet!$E$12-SAP_Speadsheet!I5) -> 9 | J6: =IF(Leadsheet!$E$12-SAP_Speadsheet!J5<0,0,Leadsheet!$E$12-SAP_Speadsheet!J5) -> 8 | K6: =IF(Leadsheet!$E$12-SAP_Speadsheet!K5<0,0,Leadsheet!$E$12-SAP_Speadsheet!K5) -> 7 | ... BL6: =IF(Leadsheet!$E$12-SAP_Speadsheet!BL5<0,0,Leadsheet!$E$12-SAP_Speadsheet!BL5) -> 0
C7: Last month on book | D7: =Leadsheet!E13+Leadsheet!E12 -> 20
B9: Balance
B10: Interest rate
C11: INR rate | D11: =Leadsheet!E18 -> 0.49171714 | E11: =IF(E$5>$D$7,0,VLOOKUP(SAP_Speadsheet!E$5,Leadsheet!$C$18:$F$23,3,1)) -> 0.49171714 | F11: =IF(F$5>$D$7,0,VLOOKUP(SAP_Speadsheet!F$5,Leadsheet!$C$18:$F$23,3,1)) -> 0.49171714 | G11: =IF(G$5>$D$7,0,VLOOKUP(SAP_Speadsheet!G$5,Leadsheet!$C$18:$F$23,3,1)) -> 0.49171714 | H11: =IF(H$5>$D$7,0,VLOOKUP(SAP_Speadsheet!H$5,Leadsheet!$C$18:$F$23,3,1)) -> 0.49171714 | I11: =IF(I$5>$D$7,0,VLOOKUP(SAP_Speadsheet!I$5,Leadsheet!$C$18:$F$23,3,1)) -> 0.49171714 | J11: =IF(J$5>$D$7,0,VLOOKUP(SAP_Speadsheet!J$5,Leadsheet!$C$18:$F$23,3,1)) -> 0.49171714 | K11: =IF(K$5>$D$7,0,VLOOKUP(SAP_Speadsheet!K$5,Leadsheet!$C$18:$F$23,3,1)) -> 0.49171714 | L11: =IF(L$5>$D$7,0,VLOOKUP(SAP_Speadsheet!L$5,Leadsheet!$C$18:$F$23,3,1)) -> 0.49171714 | ... BL11: =IF(BL$5>$D$7,0,VLOOKUP(SAP_Speadsheet!BL$5,Leadsheet!$C$18:$F$23,3,1)) -> 0
C12: COF rate | D12: =Leadsheet!F18 -> 0.069062919 | E12: =IF(E$5>$D$7,0,VLOOKUP(SAP_Speadsheet!E$5,Leadsheet!$C$18:$F$23,4,1)) -> 0.069062919 | F12: =IF(F$5>$D$7,0,VLOOKUP(SAP_Speadsheet!F$5,Leadsheet!$C$18:$F$23,4,1)) -> 0.069062919 | G12: =IF(G$5>$D$7,0,VLOOKUP(SAP_Speadsheet!G$5,Leadsheet!$C$18:$F$23,4,1)) -> 0.069062919 | H12: =IF(H$5>$D$7,0,VLOOKUP(SAP_Speadsheet!H$5,Leadsheet!$C$18:$F$23,4,1)) -> 0.069062919 | I12: =IF(I$5>$D$7,0,VLOOKUP(SAP_Speadsheet!I$5,Leadsheet!$C$18:$F$23,4,1)) -> 0.069062919 | J12: =IF(J$5>$D$7,0,VLOOKUP(SAP_Speadsheet!J$5,Leadsheet!$C$18:$F$23,4,1)) -> 0.069062919 | K12: =IF(K$5>$D$7,0,VLOOKUP(SAP_Speadsheet!K$5,Leadsheet!$C$18:$F$23,4,1)) -> 0.069062919 | L12: =IF(L$5>$D$7,0,VLOOKUP(SAP_Speadsheet!L$5,Leadsheet!$C$18:$F$23,4,1)) -> 0.069062919 | ... BL12: =IF(BL$5>$D$7,0,VLOOKUP(SAP_Speadsheet!BL$5,Leadsheet!$C$18:$F$23,4,1)) -> 0
C13: Attrition rate | E13: =IF(E$5<Leadsheet!$E$12,VLOOKUP(SAP_Speadsheet!E$5,Leadsheet!$C$26:$G$30,5,1),0) -> 0.11584981 | F13: =IF(F$5<Leadsheet!$E$12,VLOOKUP(SAP_Speadsheet!F$5,Leadsheet!$C$26:$G$30,5,1),0) -> 0.047684839 | G13: =IF(G$5<Leadsheet!$E$12,VLOOKUP(SAP_Speadsheet!G$5,Leadsheet!$C$26:$G$30,5,1),0) -> 0.047684839 | H13: =IF(H$5<Leadsheet!$E$12,VLOOKUP(SAP_Speadsheet!H$5,Leadsheet!$C$26:$G$30,5,1),0) -> 0.023340862 | I13: =IF(I$5<Leadsheet!$E$12,VLOOKUP(SAP_Speadsheet!I$5,Leadsheet!$C$26:$G$30,5,1),0) -> 0.023340862 | J13: =IF(J$5<Leadsheet!$E$12,VLOOKUP(SAP_Speadsheet!J$5,Leadsheet!$C$26:$G$30,5,1),0) -> 0.023340862 | K13: =IF(K$5<Leadsheet!$E$12,VLOOKUP(SAP_Speadsheet!K$5,Leadsheet!$C$26:$G$30,5,1),0) -> 0.023340862 | L13: =IF(L$5<Leadsheet!$E$12,VLOOKUP(SAP_Speadsheet!L$5,Leadsheet!$C$26:$G$30,5,1),0) -> 0.023340862 | ... BL13: =IF(BL$5<Leadsheet!$E$12,VLOOKUP(SAP_Speadsheet!BL$5,Leadsheet!$C$26:$G$30,5,1),0) -> 0
C14: Prepayment Penalty | E14: =IF(E$5<Leadsheet!$E$12,VLOOKUP(SAP_Speadsheet!E$5,Leadsheet!$C$26:$F$30,3,1),0) -> 0.075631948 | F14: =IF(F$5<Leadsheet!$E$12,VLOOKUP(SAP_Speadsheet!F$5,Leadsheet!$C$26:$F$30,3,1),0) -> 0.075631948 | G14: =IF(G$5<Leadsheet!$E$12,VLOOKUP(SAP_Speadsheet!G$5,Leadsheet!$C$26:$F$30,3,1),0) -> 0.075631948 | H14: =IF(H$5<Leadsheet!$E$12,VLOOKUP(SAP_Speadsheet!H$5,Leadsheet!$C$26:$F$30,3,1),0) -> 0.048252779 | I14: =IF(I$5<Leadsheet!$E$12,VLOOKUP(SAP_Speadsheet!I$5,Leadsheet!$C$26:$F$30,3,1),0) -> 0.048252779 | J14: =IF(J$5<Leadsheet!$E$12,VLOOKUP(SAP_Speadsheet!J$5,Leadsheet!$C$26:$F$30,3,1),0) -> 0.048252779 | K14: =IF(K$5<Leadsheet!$E$12,VLOOKUP(SAP_Speadsheet!K$5,Leadsheet!$C$26:$F$30,3,1),0) -> 0.048252779 | L14: =IF(L$5<Leadsheet!$E$12,VLOOKUP(SAP_Speadsheet!L$5,Leadsheet!$C$26:$F$30,3,1),0) -> 0.048252779 | ... BL14: =IF(BL$5<Leadsheet!$E$12,VLOOKUP(SAP_Speadsheet!BL$5,Leadsheet!$C$26:$F$30,3,1),0) -> 0
B16: EMI | C16: Account accumulated | D16: 1 | E16: =IF(E5>$D$7,0,D16-E13) -> 0.88415019 | F16: =IF(F5>$D$7,0,E16-F13) -> 0.83646535 | G16: =IF(G5>$D$7,0,F16-G13) -> 0.78878051 | H16: =IF(H5>$D$7,0,G16-H13) -> 0.76543965 | I16: =IF(I5>$D$7,0,H16-I13) -> 0.74209878 | J16: =IF(J5>$D$7,0,I16-J13) -> 0.71875792 | K16: =IF(K5>$D$7,0,J16-K13) -> 0.69541706 | L16: =IF(L5>$D$7,0,K16-L13) -> 0.6720762 | ... BL16: =IF(BL5>$D$7,0,BK16-BL13) -> 0
C17: Nominal ENR | D17: =Leadsheet!E10 -> 16.17916 | E17: =IF(E$5>Leadsheet!$E$12,0,D17+E21+E18) -> 13.426217 | F17: =IF(F$5>Leadsheet!$E$12,0,SAP_Speadsheet!E17+SAP_Speadsheet!F21+F18) -> 11.941635 | G17: =IF(G$5>Leadsheet!$E$12,0,SAP_Speadsheet!F17+SAP_Speadsheet!G21+G18) -> 10.531459 | H17: =IF(H$5>Leadsheet!$E$12,0,SAP_Speadsheet!G17+SAP_Speadsheet!H21+H18) -> 9.479942 | I17: =IF(I$5>Leadsheet!$E$12,0,SAP_Speadsheet!H17+SAP_Speadsheet!I21+I18) -> 8.4467879 | J17: =IF(J$5>Leadsheet!$E$12,0,SAP_Speadsheet!I17+SAP_Speadsheet!J21+J18) -> 7.4313214 | K17: =IF(K$5>Leadsheet!$E$12,0,SAP_Speadsheet!J17+SAP_Speadsheet!K21+K18) -> 6.4333425 | L17: =IF(L$5>Leadsheet!$E$12,0,SAP_Speadsheet!K17+SAP_Speadsheet!L21+L18) -> 5.4521869 | M17: =IF(M$5>Leadsheet!$E$12,0,SAP_Speadsheet!L17+SAP_Speadsheet!M21+M18) -> 4.4877879 | ... BL17: =IF(BL$5>Leadsheet!$E$12,0,SAP_Speadsheet!BK17+SAP_Speadsheet!BL21+BL18) -> 0
C18: Fully Prepayment Amount | E18: =-IF(E6>0,IFERROR(D27*(D16-E16)/D16,0),0) -> -1.8743527 | F18: =-IF(F6>0,IFERROR(E27*(E16-F16)/E16,0),0) -> -0.68203023 | G18: =-IF(G6>0,IFERROR(F27*(F16-G16)/F16,0),0) -> -0.61987502 | H18: =-IF(H6>0,IFERROR(G27*(G16-H16)/G16,0),0) -> -0.27456373 | I18: =-IF(I6>0,IFERROR(H27*(H16-I16)/H16,0),0) -> -0.24712905 | J18: =-IF(J6>0,IFERROR(I27*(I16-J16)/I16,0),0) -> -0.22049169 | K18: =-IF(K6>0,IFERROR(J27*(J16-K16)/J16,0),0) -> -0.19427521 | L18: =-IF(L6>0,IFERROR(K27*(K16-L16)/K16,0),0) -> -0.1690434 | ... BL18: =-IF(BL6>0,IFERROR(BK27*(BK16-BL16)/BK16,0),0) -> 0
C19: EMI payment | E19: =-IFERROR(PMT(D11/12,D6,-D17),0) -> -1.5415542 | F19: =-IFERROR(PMT(E11/12,E6,-E17),0) -> -1.3527105 | G19: =-IFERROR(PMT(F11/12,F6,-F17),0) -> -1.2796264 | H19: =-IFERROR(PMT(G11/12,G6,-G17),0) -> -1.2084951 | I19: =-IFERROR(PMT(H11/12,H6,-H17),0) -> -1.1744792 | J19: =-IFERROR(PMT(I11/12,I6,-I17),0) -> -1.141094 | K19: =-IFERROR(PMT(J11/12,J6,-J17),0) -> -1.1082127 | L19: =-IFERROR(PMT(K11/12,K6,-K17),0) -> -1.0757277 | ... BL19: =-IFERROR(PMT(BK11/12,BK6,-BK17),0) -> 0
C20: Nominal Interest | E20: =-IF(E5>$D$6,0,D17*D11/12) -> -0.66296419 | F20: =-IF(F5>$D$6,0,E17*E11/12) -> -0.55015843 | G20: =-IF(G5>$D$6,0,F17*F11/12) -> -0.48932555 | H20: =-IF(H5>$D$6,0,G17*G11/12) -> -0.43154158 | I20: =-IF(I5>$D$6,0,H17*H11/12) -> -0.38845416 | J20: =-IF(J5>$D$6,0,I17*I11/12) -> -0.3461192 | K20: =-IF(K5>$D$6,0,J17*J11/12) -> -0.30450901 | L20: =-IF(L5>$D$6,0,K17*K11/12) -> -0.2636154 | ... BL20: =-IF(BL5>$D$6,0,BK17*BK11/12) -> 0
C21: Nominal Payment | E21: =E19-E20 -> -0.87859002 | F21: =F19-F20 -> -0.80255208 | G21: =G19-G20 -> -0.79030084 | H21: =H19-H20 -> -0.77695355 | I21: =I19-I20 -> -0.78602501 | J21: =J19-J20 -> -0.7949748 | K21: =K19-K20 -> -0.80370366 | L21: =L19-L20 -> -0.81211226 | ... BL21: =BL19-BL20 -> 0
C24: Schedule Payment | E24: =IF(E5>Leadsheet!$E$12,0,IFERROR(E21/D17*D27*(1-Leadsheet!$D$91)+E18,0)) -> -2.7081346 | F24: =IF(F5>Leadsheet!$E$12,0,IFERROR(F21/E17*E27*(1-Leadsheet!$D$91)+F18,0)) -> -1.3993868 | G24: =IF(G5>Leadsheet!$E$12,0,IFERROR(G21/F17*F27*(1-Leadsheet!$D$91)+G18,0)) -> -1.30279 | H24: =IF(H5>Leadsheet!$E$12,0,IFERROR(H21/G17*G27*(1-Leadsheet!$D$91)+H18,0)) -> -0.92417741 | I24: =IF(I5>Leadsheet!$E$12,0,IFERROR(I21/H17*H27*(1-Leadsheet!$D$91)+I18,0)) -> -0.88482663 | J24: =IF(J5>Leadsheet!$E$12,0,IFERROR(J21/I17*I27*(1-Leadsheet!$D$91)+J18,0)) -> -0.84662246 | K24: =IF(K5>Leadsheet!$E$12,0,IFERROR(K21/J17*J27*(1-Leadsheet!$D$91)+K18,0)) -> -0.80829059 | L24: =IF(L5>Leadsheet!$E$12,0,IFERROR(L21/K17*K27*(1-Leadsheet!$D$91)+L18,0)) -> -0.77239753 | ... BL24: =IF(BL5>Leadsheet!$E$12,0,IFERROR(BL21/BK17*BK27*(1-Leadsheet!$D$91)+BL18,0)) -> 0
A26: SBV | B26: Overdue | C26: Balance by Bucket/Group
A27: G1 | B27: 0 | C27: B0 | D27: =Leadsheet!E10 -> 16.17916 | E27: =IF(E5>=Leadsheet!$E$12,0,D44+E24-SUM(E28:E41)) -> 12.645888 | F27: =IF(F5>=Leadsheet!$E$12,0,E44+F24-SUM(F28:F41)) -> 10.87356 | G27: =IF(G5>=Leadsheet!$E$12,0,F44+G24-SUM(G28:G41)) -> 9.2785999 | H27: =IF(H5>=Leadsheet!$E$12,0,G44+H24-SUM(H28:H41)) -> 8.1043441 | I27: =IF(I5>=Leadsheet!$E$12,0,H44+I24-SUM(I28:I41)) -> 7.0103074 | J27: =IF(J5>=Leadsheet!$E$12,0,I44+J24-SUM(J28:J41)) -> 5.9825059 | K27: =IF(K5>=Leadsheet!$E$12,0,J44+K24-SUM(K28:K41)) -> 5.036475 | L27: =IF(L5>=Leadsheet!$E$12,0,K44+L24-SUM(L28:L41)) -> 4.158775 | ... BL27: =IF(BL5>=Leadsheet!$E$12,0,BK44+BL24-SUM(BL28:BL41)) -> 0
A28: G2 | B28: 30 | C28: B1 | E28: =IF(E$5>$D$7,0,D27*Leadsheet!$D91) -> 0.82513717 | F28: =IF(F$5>$D$7,0,E27*Leadsheet!$D91) -> 0.6449403 | G28: =IF(G$5>$D$7,0,F27*Leadsheet!$D91) -> 0.55455157 | H28: =IF(H$5>$D$7,0,G27*Leadsheet!$D91) -> 0.47320859 | I28: =IF(I$5>$D$7,0,H27*Leadsheet!$D91) -> 0.41332155 | J28: =IF(J$5>$D$7,0,I27*Leadsheet!$D91) -> 0.35752568 | K28: =IF(K$5>$D$7,0,J27*Leadsheet!$D91) -> 0.3051078 | L28: =IF(L$5>$D$7,0,K27*Leadsheet!$D91) -> 0.25686023 | ... BL28: =IF(BL$5>$D$7,0,BK27*Leadsheet!$D91) -> 0
A29: G2 | B29: 60 | C29: B2 | E29: =IF(E$5>$D$7,0,D28*Leadsheet!$D92) -> 0 | F29: =IF(F$5>$D$7,0,E28*Leadsheet!$D92) -> 0.55313814 | G29: =IF(G$5>$D$7,0,F28*Leadsheet!$D92) -> 0.43234155 | H29: =IF(H$5>$D$7,0,G28*Leadsheet!$D92) -> 0.37174864 | I29: =IF(I$5>$D$7,0,H28*Leadsheet!$D92) -> 0.31721965 | J29: =IF(J$5>$D$7,0,I28*Leadsheet!$D92) -> 0.27707383 | K29: =IF(K$5>$D$7,0,J28*Leadsheet!$D92) -> 0.23967056 | L29: =IF(L$5>$D$7,0,K28*Leadsheet!$D92) -> 0.20453176 | ... BL29: =IF(BL$5>$D$7,0,BK28*Leadsheet!$D92) -> 0
A30: G2 | B30: 90 | C30: B3 | E30: =IF(E$5>$D$7,0,D29*Leadsheet!$D93) -> 0 | F30: =IF(F$5>$D$7,0,E29*Leadsheet!$D93) -> 0 | G30: =IF(G$5>$D$7,0,F29*Leadsheet!$D93) -> 0.50335571 | H30: =IF(H$5>$D$7,0,G29*Leadsheet!$D93) -> 0.39343081 | I30: =IF(I$5>$D$7,0,H29*Leadsheet!$D93) -> 0.33829127 | J30: =IF(J$5>$D$7,0,I29*Leadsheet!$D93) -> 0.28866988 | K30: =IF(K$5>$D$7,0,J29*Leadsheet!$D93) -> 0.25213718 | L30: =IF(L$5>$D$7,0,K29*Leadsheet!$D93) -> 0.21810021 | ... AU30: =IF(AU$5>$D$7,0,AT29*Leadsheet!$D93) -> 0 | AV30: 0 | AW30: =IF(AW$5>$D$7,0,AV29*Leadsheet!$D93) -> 0 | AX30: =IF(AX$5>$D$7,0,AW29*Leadsheet!$D93) -> 0 | AY30: =IF(AY$5>$D$7,0,AX29*Leadsheet!$D93) -> 0 | AZ30: =IF(AZ$5>$D$7,0,AY29*Leadsheet!$D93) -> 0 | BA30: =IF(BA$5>$D$7,0,AZ29*Leadsheet!$D93) -> 0 | BB30: =IF(BB$5>$D$7,0,BA29*Leadsheet!$D93) -> 0 | BC30: =IF(BC$5>$D$7,0,BB29*Leadsheet!$D93) -> 0 | BD30: =IF(BD$5>$D$7,0,BC29*Leadsheet!$D93) -> 0 | ... BL30: =IF(BL$5>$D$7,0,BK29*Leadsheet!$D93) -> 0
A31: G3 | B31: 120 | C31: B4 | E31: =IF(E$5>$D$7,0,D30*Leadsheet!$D94) -> 0 | F31: =IF(F$5>$D$7,0,E30*Leadsheet!$D94) -> 0 | G31: =IF(G$5>$D$7,0,F30*Leadsheet!$D94) -> 0 | H31: =IF(H$5>$D$7,0,G30*Leadsheet!$D94) -> 0.50193915 | I31: =IF(I$5>$D$7,0,H30*Leadsheet!$D94) -> 0.39232361 | J31: =IF(J$5>$D$7,0,I30*Leadsheet!$D94) -> 0.33733924 | K31: =IF(K$5>$D$7,0,J30*Leadsheet!$D94) -> 0.2878575 | L31: =IF(L$5>$D$7,0,K30*Leadsheet!$D94) -> 0.25142761 | ... BL31: =IF(BL$5>$D$7,0,BK30*Leadsheet!$D94) -> 0
A32: G3 | B32: 150 | C32: B5 | E32: =IF(E$5>$D$7,0,D31*Leadsheet!$D95) -> 0 | F32: =IF(F$5>$D$7,0,E31*Leadsheet!$D95) -> 0 | G32: =IF(G$5>$D$7,0,F31*Leadsheet!$D95) -> 0 | H32: =IF(H$5>$D$7,0,G31*Leadsheet!$D95) -> 0 | I32: =IF(I$5>$D$7,0,H31*Leadsheet!$D95) -> 0.48838118 | J32: =IF(J$5>$D$7,0,I31*Leadsheet!$D95) -> 0.38172648 | K32: =IF(K$5>$D$7,0,J31*Leadsheet!$D95) -> 0.32822731 | L32: =IF(L$5>$D$7,0,K31*Leadsheet!$D95) -> 0.28008212 | ... BL32: =IF(BL$5>$D$7,0,BK31*Leadsheet!$D95) -> 0
A33: G3 | B33: 180 | C33: B6 | E33: =IF(E$5>$D$7,0,D32*Leadsheet!$D96) -> 0 | F33: =IF(F$5>$D$7,0,E32*Leadsheet!$D96) -> 0 | G33: =IF(G$5>$D$7,0,F32*Leadsheet!$D96) -> 0 | H33: =IF(H$5>$D$7,0,G32*Leadsheet!$D96) -> 0 | I33: =IF(I$5>$D$7,0,H32*Leadsheet!$D96) -> 0 | J33: =IF(J$5>$D$7,0,I32*Leadsheet!$D96) -> 0.48838118 | K33: =IF(K$5>$D$7,0,J32*Leadsheet!$D96) -> 0.38172648 | L33: =IF(L$5>$D$7,0,K32*Leadsheet!$D96) -> 0.32822731 | ... BL33: =IF(BL$5>$D$7,0,BK32*Leadsheet!$D96) -> 0
A34: G4 | B34: 210 | C34: B7 | E34: =IF(E$5>$D$7,0,D33*Leadsheet!$D97) -> 0 | F34: =IF(F$5>$D$7,0,E33*Leadsheet!$D97) -> 0 | G34: =IF(G$5>$D$7,0,F33*Leadsheet!$D97) -> 0 | H34: =IF(H$5>$D$7,0,G33*Leadsheet!$D97) -> 0 | I34: =IF(I$5>$D$7,0,H33*Leadsheet!$D97) -> 0 | J34: =IF(J$5>$D$7,0,I33*Leadsheet!$D97) -> 0 | K34: =IF(K$5>$D$7,0,J33*Leadsheet!$D97) -> 0.47372974 | L34: =IF(L$5>$D$7,0,K33*Leadsheet!$D97) -> 0.37027469 | ... BL34: =IF(BL$5>$D$7,0,BK33*Leadsheet!$D97) -> 0
A35: G4 | B35: 240 | C35: B8 | E35: =IF(E$5>$D$7,0,D34*Leadsheet!$D98) -> 0 | F35: =IF(F$5>$D$7,0,E34*Leadsheet!$D98) -> 0 | G35: =IF(G$5>$D$7,0,F34*Leadsheet!$D98) -> 0 | H35: =IF(H$5>$D$7,0,G34*Leadsheet!$D98) -> 0 | I35: =IF(I$5>$D$7,0,H34*Leadsheet!$D98) -> 0 | J35: =IF(J$5>$D$7,0,I34*Leadsheet!$D98) -> 0 | K35: =IF(K$5>$D$7,0,J34*Leadsheet!$D98) -> 0 | L35: =IF(L$5>$D$7,0,K34*Leadsheet!$D98) -> 0.46425515 | ... BL35: =IF(BL$5>$D$7,0,BK34*Leadsheet!$D98) -> 0
A36: G4 | B36: 270 | C36: B9 | E36: =IF(E$5>$D$7,0,D35*Leadsheet!$D99) -> 0 | F36: =IF(F$5>$D$7,0,E35*Leadsheet!$D99) -> 0 | G36: =IF(G$5>$D$7,0,F35*Leadsheet!$D99) -> 0 | H36: =IF(H$5>$D$7,0,G35*Leadsheet!$D99) -> 0 | I36: =IF(I$5>$D$7,0,H35*Leadsheet!$D99) -> 0 | J36: =IF(J$5>$D$7,0,I35*Leadsheet!$D99) -> 0 | K36: =IF(K$5>$D$7,0,J35*Leadsheet!$D99) -> 0 | L36: =IF(L$5>$D$7,0,K35*Leadsheet!$D99) -> 0 | ... BL36: =IF(BL$5>$D$7,0,BK35*Leadsheet!$D99) -> 0
A37: G4 | B37: 300 | C37: B10 | E37: =IF(E$5>$D$7,0,D36*Leadsheet!$D100) -> 0 | F37: =IF(F$5>$D$7,0,E36*Leadsheet!$D100) -> 0 | G37: =IF(G$5>$D$7,0,F36*Leadsheet!$D100) -> 0 | H37: =IF(H$5>$D$7,0,G36*Leadsheet!$D100) -> 0 | I37: =IF(I$5>$D$7,0,H36*Leadsheet!$D100) -> 0 | J37: =IF(J$5>$D$7,0,I36*Leadsheet!$D100) -> 0 | K37: =IF(K$5>$D$7,0,J36*Leadsheet!$D100) -> 0 | L37: =IF(L$5>$D$7,0,K36*Leadsheet!$D100) -> 0 | ... BL37: =IF(BL$5>$D$7,0,BK36*Leadsheet!$D100) -> 0
A38: G4 | B38: 330 | C38: B11 | E38: =IF(E$5>$D$7,0,D37*Leadsheet!$D101) -> 0 | F38: =IF(F$5>$D$7,0,E37*Leadsheet!$D101) -> 0 | G38: =IF(G$5>$D$7,0,F37*Leadsheet!$D101) -> 0 | H38: =IF(H$5>$D$7,0,G37*Leadsheet!$D101) -> 0 | I38: =IF(I$5>$D$7,0,H37*Leadsheet!$D101) -> 0 | J38: =IF(J$5>$D$7,0,I37*Leadsheet!$D101) -> 0 | K38: =IF(K$5>$D$7,0,J37*Leadsheet!$D101) -> 0 | L38: =IF(L$5>$D$7,0,K37*Leadsheet!$D101) -> 0 | ... BL38: =IF(BL$5>$D$7,0,BK37*Leadsheet!$D101) -> 0
A39: G4 | B39: 360 | C39: B12 | E39: =IF(E$5>$D$7,0,D38*Leadsheet!$D102) -> 0 | F39: =IF(F$5>$D$7,0,E38*Leadsheet!$D102) -> 0 | G39: =IF(G$5>$D$7,0,F38*Leadsheet!$D102) -> 0 | H39: =IF(H$5>$D$7,0,G38*Leadsheet!$D102) -> 0 | I39: =IF(I$5>$D$7,0,H38*Leadsheet!$D102) -> 0 | J39: =IF(J$5>$D$7,0,I38*Leadsheet!$D102) -> 0 | K39: =IF(K$5>$D$7,0,J38*Leadsheet!$D102) -> 0 | L39: =IF(L$5>$D$7,0,K38*Leadsheet!$D102) -> 0 | ... BL39: =IF(BL$5>$D$7,0,BK38*Leadsheet!$D102) -> 0
A40: G5 | B40: 390 | C40: B13 | E40: =IF(E$5>$D$7,0,D39*Leadsheet!$D103) -> 0 | F40: =IF(F$5>$D$7,0,E39*Leadsheet!$D103) -> 0 | G40: =IF(G$5>$D$7,0,F39*Leadsheet!$D103) -> 0 | H40: =IF(H$5>$D$7,0,G39*Leadsheet!$D103) -> 0 | I40: =IF(I$5>$D$7,0,H39*Leadsheet!$D103) -> 0 | J40: =IF(J$5>$D$7,0,I39*Leadsheet!$D103) -> 0 | K40: =IF(K$5>$D$7,0,J39*Leadsheet!$D103) -> 0 | L40: =IF(L$5>$D$7,0,K39*Leadsheet!$D103) -> 0 | ... BL40: =IF(BL$5>$D$7,0,BK39*Leadsheet!$D103) -> 0
A41: G5 | B41: 420+ | C41: B14+ | E41: =IF(E5>$D$7,0,D40+D41) -> 0 | F41: =IF(F5>$D$7,0,E40+E41) -> 0 | G41: =IF(G5>$D$7,0,F40+F41) -> 0 | H41: =IF(H5>$D$7,0,G40+G41) -> 0 | I41: =IF(I5>$D$7,0,H40+H41) -> 0 | J41: =IF(J5>$D$7,0,I40+I41) -> 0 | K41: =IF(K5>$D$7,0,J40+J41) -> 0 | L41: =IF(L5>$D$7,0,K40+K41) -> 0 | ... BL41: =IF(BL5>$D$7,0,BK40+BK41) -> 0
B43: ENR
C44: Total bank | D44: =SUM(D27:D41) -> 16.17916 | E44: =SUM(E27:E41) -> 13.471025 | F44: =SUM(F27:F41) -> 12.071639 | G44: =SUM(G27:G41) -> 10.768849 | H44: =SUM(H27:H41) -> 9.8446713 | I44: =SUM(I27:I41) -> 8.9598446 | J44: =SUM(J27:J41) -> 8.1132222 | K44: =SUM(K27:K41) -> 7.3049316 | ... BL44: =SUM(BL27:BL41) -> 0
C45: Outstanding balance | D45: {=IF(D5=$D$7,0,_xlfn.IFS(Leadsheet!$G$5="DPD360+",SUM(SAP_Speadsheet!D27:D40),Leadsheet!$G$5="DPD180+",SUM(SAP_Speadsheet!D27:D34)))} -> 16.17916 | E45: {=IF(E5=$D$7,0,_xlfn.IFS(Leadsheet!$G$5="DPD360+",SUM(SAP_Speadsheet!E27:E40),Leadsheet!$G$5="DPD180+",SUM(SAP_Speadsheet!E27:E34)))} -> 13.471025 | F45: {=IF(F5=$D$7,0,_xlfn.IFS(Leadsheet!$G$5="DPD360+",SUM(SAP_Speadsheet!F27:F40),Leadsheet!$G$5="DPD180+",SUM(SAP_Speadsheet!F27:F34)))} -> 12.071639 | G45: {=IF(G5=$D$7,0,_xlfn.IFS(Leadsheet!$G$5="DPD360+",SUM(SAP_Speadsheet!G27:G40),Leadsheet!$G$5="DPD180+",SUM(SAP_Speadsheet!G27:G34)))} -> 10.768849 | H45: {=IF(H5=$D$7,0,_xlfn.IFS(Leadsheet!$G$5="DPD360+",SUM(SAP_Speadsheet!H27:H40),Leadsheet!$G$5="DPD180+",SUM(SAP_Speadsheet!H27:H34)))} -> 9.8446713 | I45: {=IF(I5=$D$7,0,_xlfn.IFS(Leadsheet!$G$5="DPD360+",SUM(SAP_Speadsheet!I27:I40),Leadsheet!$G$5="DPD180+",SUM(SAP_Speadsheet!I27:I34)))} -> 8.9598446 | J45: {=IF(J5=$D$7,0,_xlfn.IFS(Leadsheet!$G$5="DPD360+",SUM(SAP_Speadsheet!J27:J40),Leadsheet!$G$5="DPD180+",SUM(SAP_Speadsheet!J27:J34)))} -> 8.1132222 | K45: {=IF(K5=$D$7,0,_xlfn.IFS(Leadsheet!$G$5="DPD360+",SUM(SAP_Speadsheet!K27:K40),Leadsheet!$G$5="DPD180+",SUM(SAP_Speadsheet!K27:K34)))} -> 7.3049316 | ... BL45: {=IF(BL5=$D$7,0,_xlfn.IFS(Leadsheet!$G$5="DPD360+",SUM(SAP_Speadsheet!BL27:BL40),Leadsheet!$G$5="DPD180+",SUM(SAP_Speadsheet!BL27:BL34)))} -> 0
C46: Writeoff balance | D46: =D44-D45 -> 0 | E46: =E44-E45 -> 0 | F46: =F44-F45 -> 0 | G46: =G44-G45 -> 0 | H46: =H44-H45 -> 0 | I46: =I44-I45 -> 0 | J46: =J44-J45 -> 0 | K46: =K44-K45 -> 0 | ... BL46: =BL44-BL45 -> 0
C47: Outstanding Bal/TB | D47: =IFERROR(D45/D44,"") -> 1 | E47: =IFERROR(E45/E44,"") -> 1 | F47: =IFERROR(F45/F44,"") -> 1 | G47: =IFERROR(G45/G44,"") -> 1 | H47: =IFERROR(H45/H44,"") -> 1 | I47: =IFERROR(I45/I44,"") -> 1 | J47: =IFERROR(J45/J44,"") -> 1 | K47: =IFERROR(K45/K44,"") -> 1 | ... BL47: =IFERROR(BL45/BL44,"")
B49: ANR
...

Sheet Saleplan&PnL
C1: PROFIT & LOSS 60M
C2: I. | D2: SALES PLAN
C4: Business month | D4: 45658 | E4: =EOMONTH(D4,1) -> 45716 | F4: =EOMONTH(E4,1) -> 45747 | G4: =EOMONTH(F4,1) -> 45777 | H4: =EOMONTH(G4,1) -> 45808 | I4: =EOMONTH(H4,1) -> 45838 | J4: =EOMONTH(I4,1) -> 45869 | K4: =EOMONTH(J4,1) -> 45900 | L4: =EOMONTH(K4,1) -> 45930 | ... BL4: =EOMONTH(BK4,1) -> 47514
C5: Don't delete | D5: =YEAR(D4) -> 2025 | E5: =YEAR(E4) -> 2025 | F5: =YEAR(F4) -> 2025 | G5: =YEAR(G4) -> 2025 | H5: =YEAR(H4) -> 2025 | I5: =YEAR(I4) -> 2025 | J5: =YEAR(J4) -> 2025 | K5: =YEAR(K4) -> 2025 | ... BL5: =YEAR(BL4) -> 2030
C6: New disbursement (bVND) | J6: =DATA!E19/10^9 -> 913.80154 | K6: =DATA!E18/10^9 -> 847.45432 | L6: =DATA!E17/10^9 -> 1159.8268
C8: II. | D8: PROFIT & LOSS
C10: FISCAL YEAR | E10: Total | F10: =YEAR(D4) -> 2025 | G10: =F10+1 -> 2026 | H10: =G10+1 -> 2027 | I10: =H10+1 -> 2028 | J10: =I10+1 -> 2029 | K10: =J10+1 -> 2030
E11: bVND | F11: bVND | G11: bVND | H11: bVND | I11: bVND | J11: bVND | K11: bVND
C13: NEW DISBURSAL | E13: =SUM(F13:O13) -> 2921.0826 | F13: =SUMIF($D$5:$BL$5,F$10,$D$6:$BL$6) -> 2921.0826 | G13: =SUMIF($D$5:$BL$5,G$10,$D$6:$BL$6) -> 0 | H13: =SUMIF($D$5:$BL$5,H$10,$D$6:$BL$6) -> 0 | I13: =SUMIF($D$5:$BL$5,I$10,$D$6:$BL$6) -> 0 | J13: =SUMIF($D$5:$BL$5,J$10,$D$6:$BL$6) -> 0 | K13: =SUMIF($D$5:$BL$5,K$10,$D$6:$BL$6) -> 0
C14: Monthly disbursement | E14: =AVERAGE(D6:AM6) -> 973.69421 | F14: =IFERROR(F13/COUNTIFS($D$5:$BL$5,F10,$D$6:$BL$6,"<>"&""),0) -> 973.69421 | G14: =IFERROR(G13/COUNTIFS($D$5:$BL$5,G10,$D$6:$BL$6,"<>"&""),0) -> 0 | H14: =IFERROR(H13/COUNTIFS($D$5:$BL$5,H10,$D$6:$BL$6,"<>"&""),0) -> 0 | I14: =IFERROR(I13/COUNTIFS($D$5:$BL$5,I10,$D$6:$BL$6,"<>"&""),0) -> 0 | J14: =IFERROR(J13/COUNTIFS($D$5:$BL$5,J10,$D$6:$BL$6,"<>"&""),0) -> 0 | K14: =IFERROR(K13/COUNTIFS($D$5:$BL$5,K10,$D$6:$BL$6,"<>"&""),0) -> 0
C16: EOP | F16: =OFFSET(PnL_Speadsheet!$A$7,0,MATCH(DATE('Saleplan&PnL'!F$10,12,31),PnL_Speadsheet!$B$4:$BI$4,0))/1000 -> 1633.2676 | G16: =OFFSET(PnL_Speadsheet!$A$7,0,MATCH(DATE('Saleplan&PnL'!G$10,12,31),PnL_Speadsheet!$B$4:$BI$4,0))/1000 -> 461.60411 | H16: =OFFSET(PnL_Speadsheet!$A$7,0,MATCH(DATE('Saleplan&PnL'!H$10,12,31),PnL_Speadsheet!$B$4:$BI$4,0))/1000 -> 0 | I16: =OFFSET(PnL_Speadsheet!$A$7,0,MATCH(DATE('Saleplan&PnL'!I$10,12,31),PnL_Speadsheet!$B$4:$BI$4,0))/1000 -> 0 | J16: =OFFSET(PnL_Speadsheet!$A$7,0,MATCH(DATE('Saleplan&PnL'!J$10,12,31),PnL_Speadsheet!$B$4:$BI$4,0))/1000 -> 0 | K16: =IFERROR(OFFSET(PnL_Speadsheet!$A$7,0,MATCH(DATE('Saleplan&PnL'!K$10,12,31),PnL_Speadsheet!$B$4:$BI$4,0))/1000,0) -> 0
C17: ADB | E17: =IFERROR(SUM(PnL_Speadsheet!B8:AK8)/1000/COUNTIF(PnL_Speadsheet!B8:BI8,"<>0"),0) -> 835.00498 | F17: =IFERROR(SUMIF(PnL_Speadsheet!$B$3:$BI$3,F$10,PnL_Speadsheet!$B8:$BI8)/1000/COUNTIFS(PnL_Speadsheet!$B$3:$BI$3,'Saleplan&PnL'!F$10,PnL_Speadsheet!$B$8:$BI$8,"<>0"),0) -> 1735.127 | G17: =IFERROR(SUMIF(PnL_Speadsheet!$B$3:$BI$3,G$10,PnL_Speadsheet!$B8:$BI8)/1000/COUNTIFS(PnL_Speadsheet!$B$3:$BI$3,'Saleplan&PnL'!G$10,PnL_Speadsheet!$B$8:$BI$8,"<>0"),0) -> 658.74919 | H17: =IFERROR(SUMIF(PnL_Speadsheet!$B$3:$BI$3,H$10,PnL_Speadsheet!$B8:$BI8)/1000/COUNTIFS(PnL_Speadsheet!$B$3:$BI$3,'Saleplan&PnL'!H$10,PnL_Speadsheet!$B$8:$BI$8,"<>0"),0) -> 13.589247 | I17: =IFERROR(SUMIF(PnL_Speadsheet!$B$3:$BI$3,I$10,PnL_Speadsheet!$B8:$BI8)/1000/COUNTIFS(PnL_Speadsheet!$B$3:$BI$3,'Saleplan&PnL'!I$10,PnL_Speadsheet!$B$8:$BI$8,"<>0"),0) -> 0 | J17: =IFERROR(SUMIF(PnL_Speadsheet!$B$3:$BI$3,J$10,PnL_Speadsheet!$B8:$BI8)/1000/COUNTIFS(PnL_Speadsheet!$B$3:$BI$3,'Saleplan&PnL'!J$10,PnL_Speadsheet!$B$8:$BI$8,"<>0"),0) -> 0 | K17: =IFERROR(SUMIF(PnL_Speadsheet!$B$3:$BI$3,K$10,PnL_Speadsheet!$B8:$BI8)/1000/COUNTIFS(PnL_Speadsheet!$B$3:$BI$3,'Saleplan&PnL'!K$10,PnL_Speadsheet!$B$8:$BI$8,"<>0"),0) -> 0
C19: TOI | E19: =SUM(F19:O19) -> 714.50738 | F19: =SUMIF(PnL_Speadsheet!$B$3:$BI$3,F$10,PnL_Speadsheet!$B9:$BI9)/1000 -> 515.74448 | G19: =SUMIF(PnL_Speadsheet!$B$3:$BI$3,G$10,PnL_Speadsheet!$B9:$BI9)/1000 -> 199.07574 | H19: =SUMIF(PnL_Speadsheet!$B$3:$BI$3,H$10,PnL_Speadsheet!$B9:$BI9)/1000 -> -0.31283769 | I19: =SUMIF(PnL_Speadsheet!$B$3:$BI$3,I$10,PnL_Speadsheet!$B9:$BI9)/1000 -> 0 | J19: =SUMIF(PnL_Speadsheet!$B$3:$BI$3,J$10,PnL_Speadsheet!$B9:$BI9)/1000 -> 0 | K19: =SUMIF(PnL_Speadsheet!$B$3:$BI$3,K$10,PnL_Speadsheet!$B9:$BI9)/1000 -> 0
C20: NII | E20: =SUM(F20:O20) -> 528.83124 | F20: =SUMIF(PnL_Speadsheet!$B$3:$BI$3,F$10,PnL_Speadsheet!$B11:$BI11)/1000 -> 339.59453 | G20: =SUMIF(PnL_Speadsheet!$B$3:$BI$3,G$10,PnL_Speadsheet!$B11:$BI11)/1000 -> 189.54955 | H20: =SUMIF(PnL_Speadsheet!$B$3:$BI$3,H$10,PnL_Speadsheet!$B11:$BI11)/1000 -> -0.31283769 | I20: =SUMIF(PnL_Speadsheet!$B$3:$BI$3,I$10,PnL_Speadsheet!$B11:$BI11)/1000 -> 0 | J20: =SUMIF(PnL_Speadsheet!$B$3:$BI$3,J$10,PnL_Speadsheet!$B11:$BI11)/1000 -> 0 | K20: =SUMIF(PnL_Speadsheet!$B$3:$BI$3,K$10,PnL_Speadsheet!$B11:$BI11)/1000 -> 0
C21: NFI | E21: =SUM(F21:O21) -> 185.67614 | F21: =SUMIF(PnL_Speadsheet!$B$3:$BI$3,F$10,PnL_Speadsheet!$B14:$BI14)/1000 -> 176.14995 | G21: =SUMIF(PnL_Speadsheet!$B$3:$BI$3,G$10,PnL_Speadsheet!$B14:$BI14)/1000 -> 9.5261898 | H21: =SUMIF(PnL_Speadsheet!$B$3:$BI$3,H$10,PnL_Speadsheet!$B14:$BI14)/1000 -> 0 | I21: =SUMIF(PnL_Speadsheet!$B$3:$BI$3,I$10,PnL_Speadsheet!$B14:$BI14)/1000 -> 0 | J21: =SUMIF(PnL_Speadsheet!$B$3:$BI$3,J$10,PnL_Speadsheet!$B14:$BI14)/1000 -> 0 | K21: =SUMIF(PnL_Speadsheet!$B$3:$BI$3,K$10,PnL_Speadsheet!$B14:$BI14)/1000 -> 0
C22: Other TOI | E22: =SUM(F22:O22) -> 0 | F22: =SUMIF(PnL_Speadsheet!$B$3:$BI$3,F$10,PnL_Speadsheet!$B18:$BI18)/1000 -> 0 | G22: =SUMIF(PnL_Speadsheet!$B$3:$BI$3,G$10,PnL_Speadsheet!$B18:$BI18)/1000 -> 0 | H22: =SUMIF(PnL_Speadsheet!$B$3:$BI$3,H$10,PnL_Speadsheet!$B18:$BI18)/1000 -> 0 | I22: =SUMIF(PnL_Speadsheet!$B$3:$BI$3,I$10,PnL_Speadsheet!$B18:$BI18)/1000 -> 0 | J22: =SUMIF(PnL_Speadsheet!$B$3:$BI$3,J$10,PnL_Speadsheet!$B18:$BI18)/1000 -> 0 | K22: =SUMIF(PnL_Speadsheet!$B$3:$BI$3,K$10,PnL_Speadsheet!$B18:$BI18)/1000 -> 0
C23: PROVISION | E23: =SUM(F23:O23) -> -448.97487 | F23: =SUMIF(PnL_Speadsheet!$B$3:$BI$3,F$10,PnL_Speadsheet!$B31:$BI31)/1000 -> -308.09718 | G23: =SUMIF(PnL_Speadsheet!$B$3:$BI$3,G$10,PnL_Speadsheet!$B31:$BI31)/1000 -> -138.00738 | H23: =SUMIF(PnL_Speadsheet!$B$3:$BI$3,H$10,PnL_Speadsheet!$B31:$BI31)/1000 -> -2.8703149 | I23: =SUMIF(PnL_Speadsheet!$B$3:$BI$3,I$10,PnL_Speadsheet!$B31:$BI31)/1000 -> 0 | J23: =SUMIF(PnL_Speadsheet!$B$3:$BI$3,J$10,PnL_Speadsheet!$B31:$BI31)/1000 -> 0 | K23: =SUMIF(PnL_Speadsheet!$B$3:$BI$3,K$10,PnL_Speadsheet!$B31:$BI31)/1000 -> 0
C24: OPEX | E24: =SUM(F24:O24) -> -189.91672 | F24: =SUMIF(PnL_Speadsheet!$B$3:$BI$3,F$10,PnL_Speadsheet!$B19:$BI19)/1000 -> -151.88943 | G24: =SUMIF(PnL_Speadsheet!$B$3:$BI$3,G$10,PnL_Speadsheet!$B19:$BI19)/1000 -> -37.33756 | H24: =SUMIF(PnL_Speadsheet!$B$3:$BI$3,H$10,PnL_Speadsheet!$B19:$BI19)/1000 -> -0.68973811 | I24: =SUMIF(PnL_Speadsheet!$B$3:$BI$3,I$10,PnL_Speadsheet!$B19:$BI19)/1000 -> 0 | J24: =SUMIF(PnL_Speadsheet!$B$3:$BI$3,J$10,PnL_Speadsheet!$B19:$BI19)/1000 -> 0 | K24: =SUMIF(PnL_Speadsheet!$B$3:$BI$3,K$10,PnL_Speadsheet!$B19:$BI19)/1000 -> 0
C25: Sales incentives | E25: =SUM(F25:O25) -> -58.749777 | F25: =(SUMIF(PnL_Speadsheet!$B$3:$BI$3,F$10,PnL_Speadsheet!$B21:$BI22)/1000+SUMIF(PnL_Speadsheet!$B$3:$BI$3,F$10,PnL_Speadsheet!$B22:$BI22)/1000) -> -84.40678 | G25: =(SUMIF(PnL_Speadsheet!$B$3:$BI$3,G$10,PnL_Speadsheet!$B21:$BI22)/1000+SUMIF(PnL_Speadsheet!$B$3:$BI$3,G$10,PnL_Speadsheet!$B22:$BI22)/1000) -> 25.619843 | H25: =(SUMIF(PnL_Speadsheet!$B$3:$BI$3,H$10,PnL_Speadsheet!$B21:$BI22)/1000+SUMIF(PnL_Speadsheet!$B$3:$BI$3,H$10,PnL_Speadsheet!$B22:$BI22)/1000) -> 0.037160601 | I25: =(SUMIF(PnL_Speadsheet!$B$3:$BI$3,I$10,PnL_Speadsheet!$B21:$BI22)/1000+SUMIF(PnL_Speadsheet!$B$3:$BI$3,I$10,PnL_Speadsheet!$B22:$BI22)/1000) -> 0 | J25: =(SUMIF(PnL_Speadsheet!$B$3:$BI$3,J$10,PnL_Speadsheet!$B21:$BI22)/1000+SUMIF(PnL_Speadsheet!$B$3:$BI$3,J$10,PnL_Speadsheet!$B22:$BI22)/1000) -> 0 | K25: =(SUMIF(PnL_Speadsheet!$B$3:$BI$3,K$10,PnL_Speadsheet!$B21:$BI22)/1000+SUMIF(PnL_Speadsheet!$B$3:$BI$3,K$10,PnL_Speadsheet!$B22:$BI22)/1000) -> 0
