Workbook
Name __S1: {"Book1"}
Name __S1: {"Book1"}
Name __S1: {"Book1"}
Name _a1: {"'Sheet1'!$L$16"}
Name _a1: {"'Sheet1'!$L$16"}
Name _a1: {"'Sheet1'!$L$16"}
Name _S1: {"Book1"}
Name _S1: {"Book1"}
Name _S1: {"Book1"}
Name Ă: #REF!
Name Ạ196: #REF!
Name â259: #REF!
Name â259: #REF!
Name â312: #REF!
Name â312: #REF!
Name Acquisition_PlanA: #REF!
Name Acquisition_PlanB: #REF!
Name Actual: (PeriodInActual*(#REF!>0))*PeriodInPlan
Name Actual: (PeriodInActual*(#REF!>0))*PeriodInPlan
Name Actual: (PeriodInActual*(#REF!>0))*PeriodInPlan
Name ActualBeyond: PeriodInActual*(#REF!>0)
Name ActualBeyond: PeriodInActual*(#REF!>0)
Name ActualBeyond: PeriodInActual*(#REF!>0)
Name adf: #REF!
Name adf: #REF!
Name AdvIncQ12020: #REF!
Name AdvIncQ12021: #REF!
Name AdvIncQ12022: #REF!
Name AdvIncQ12023: #REF!
Name AdvIncQ12024: #REF!
Name AdvIncQ22020: #REF!
Name AdvIncQ22021: #REF!
Name AdvIncQ22022: #REF!
Name AdvIncQ22023: #REF!
Name AdvIncQ22024: #REF!
Name AdvIncQ32020: #REF!
Name AdvIncQ32021: #REF!
Name AdvIncQ32022: #REF!
Name AdvIncQ32023: #REF!
Name AdvIncQ32024: #REF!
Name AdvIncQ42020: #REF!
Name AdvIncQ42021: #REF!
Name AdvIncQ42022: #REF!
Name AdvIncQ42023: #REF!
Name AdvIncQ42024: #REF!
Name AdvPenRate2020: #REF!
Name AdvPenRate2021: #REF!
Name AdvPenRate2022: #REF!
Name AdvPenRate2023: #REF!
Name AdvPenRate2024: #REF!
Name AllReportList: #REF!
Name Amount_act: #REF!
Name Amount_CF: #REF!
Name Amount_F: #REF!
Name Amount_KPI_act: #REF!
Name approval: #REF!
Name approval: #REF!
Name Attribute_F: #REF!
Name B: #REF!
Name b2bSpr: #REF!

Sheet IR
A1: product_final | B1: Product | C1: Partner | D1: report_date | E1: closing_balance_total | F1: closing_balance_dpd_above0 | G1: closing_balance_dpd_0 | H1: closing_balance_dpd_above10 | I1: closing_balance_dpd_under10
A2: [BE] - Bikeloan VFS | B2: BL | C2: BEG | D2: 45839 | E2: 0 | F2: 0 | G2: 0 | H2: 0 | I2: 0
A3: [BE] - Bikeloan VFS | B3: BL | C3: BEG | D3: 45840 | E3: 0 | F3: 0 | G3: 0 | H3: 0 | I3: 0
A4: [BE] - Bikeloan VFS | B4: BL | C4: BEG | D4: 45841 | E4: 0 | F4: 0 | G4: 0 | H4: 0 | I4: 0
A5: [BE] - Bikeloan VFS | B5: BL | C5: BEG | D5: 45842 | E5: 0 | F5: 0 | G5: 0 | H5: 0 | I5: 0 | O5: Product | P5: CL
A6: [BE] - Bikeloan VFS | B6: BL | C6: BEG | D6: 45843 | E6: 0 | F6: 0 | G6: 0 | H6: 0 | I6: 0
A7: [BE] - Bikeloan VFS | B7: BL | C7: BEG | D7: 45844 | E7: 0 | F7: 0 | G7: 0 | H7: 0 | I7: 0 | O7: Sum of closing_balance_dpd_under10 | P7: Column Labels
A8: [BE] - Bikeloan VFS | B8: BL | C8: BEG | D8: 45845 | E8: 0 | F8: 0 | G8: 0 | H8: 0 | I8: 0 | P8: Jul | Q8: Aug | R8: Sep | S8: Grand Total
A9: [BE] - Bikeloan VFS | B9: BL | C9: BEG | D9: 45846 | E9: 0 | F9: 0 | G9: 0 | H9: 0 | I9: 0
A10: [BE] - Bikeloan VFS | B10: BL | C10: BEG | D10: 45847 | E10: 0 | F10: 0 | G10: 0 | H10: 0 | I10: 0 | O10: Row Labels
A11: [BE] - Bikeloan VFS | B11: BL | C11: BEG | D11: 45848 | E11: 0 | F11: 0 | G11: 0 | H11: 0 | I11: 0 | O11: BEG | P11: 170179815390 | Q11: 140268239545 | R11: 112615949748 | S11: 423064004683
A12: [BE] - Bikeloan VFS | B12: BL | C12: BEG | D12: 45849 | E12: 0 | F12: 0 | G12: 0 | H12: 0 | I12: 0 | O12: CAKE | P12: 32022506029594 | Q12: 36743192910881 | R12: 41010445577689 | S12: 109776144518164
A13: [BE] - Bikeloan VFS | B13: BL | C13: BEG | D13: 45850 | E13: 0 | F13: 0 | G13: 0 | H13: 0 | I13: 0 | O13: MWG | P13: 4698496703097 | Q13: 5972450288857 | R13: 7508268877050 | S13: 18179215869004
A14: [BE] - Bikeloan VFS | B14: BL | C14: BEG | D14: 45851 | E14: 0 | F14: 0 | G14: 0 | H14: 0 | I14: 0 | O14: NGS | P14: 469139173426 | Q14: 394181683617 | R14: 324147875998 | S14: 1187468733041
A15: [BE] - Bikeloan VFS | B15: BL | C15: BEG | D15: 45852 | E15: 0 | F15: 0 | G15: 0 | H15: 0 | I15: 0 | O15: VDS | P15: 35304282404241 | Q15: 38988498527615 | R15: 42211543513670 | S15: 116504324445526
A16: [BE] - Bikeloan VFS | B16: BL | C16: BEG | D16: 45853 | E16: 0 | F16: 0 | G16: 0 | H16: 0 | I16: 0 | O16: VNPAY | P16: 2095037806093 | Q16: 2230103452703 | R16: 2307997283046 | S16: 6633138541842
A17: [BE] - Bikeloan VFS | B17: BL | C17: BEG | D17: 45854 | E17: 0 | F17: 0 | G17: 0 | H17: 0 | I17: 0 | O17: VNPOST | P17: 29336097917 | Q17: 46333290385 | R17: 80785915191 | S17: 156455303493
A18: [BE] - Bikeloan VFS | B18: BL | C18: BEG | D18: 45855 | E18: 0 | F18: 0 | G18: 0 | H18: 0 | I18: 0 | O18: ZALOPAY | P18: 3647612718340 | Q18: 5740120555825 | R18: 7034090294910 | S18: 16421823569075
A19: [BE] - Bikeloan VFS | B19: BL | C19: BEG | D19: 45856 | E19: 0 | F19: 0 | G19: 0 | H19: 0 | I19: 0 | O19: Grand Total | P19: 78436590748098 | Q19: 90255148949428 | R19: 100589895287302 | S19: 269281634984828
A20: [BE] - Bikeloan VFS | B20: BL | C20: BEG | D20: 45857 | E20: 0 | F20: 0 | G20: 0 | H20: 0 | I20: 0
A21: [BE] - Bikeloan VFS | B21: BL | C21: BEG | D21: 45858 | E21: 0 | F21: 0 | G21: 0 | H21: 0 | I21: 0
A22: [BE] - Bikeloan VFS | B22: BL | C22: BEG | D22: 45859 | E22: 0 | F22: 0 | G22: 0 | H22: 0 | I22: 0
A23: [BE] - Bikeloan VFS | B23: BL | C23: BEG | D23: 45860 | E23: 0 | F23: 0 | G23: 0 | H23: 0 | I23: 0
A24: [BE] - Bikeloan VFS | B24: BL | C24: BEG | D24: 45861 | E24: 0 | F24: 0 | G24: 0 | H24: 0 | I24: 0 | T24: CAKE | U24: =SUM(P29:R29)/GETPIVOTDATA("closing_balance_dpd_under10",$O$7,"Partner","CAKE")*365 -> 0.47916706
A25: [BE] - Bikeloan VFS | B25: BL | C25: BEG | D25: 45862 | E25: 0 | F25: 0 | G25: 0 | H25: 0 | I25: 0 | M25: cashloan | N25: cashloan | O25: VDS | P25: 48463084122 | Q25: 53272770215 | R25: 57987623749 | T25: VDS | U25: =SUM(P25:R26)/GETPIVOTDATA("closing_balance_dpd_under10",$O$7,"Partner","VDS")*365 -> 0.50203376
A26: [BE] - Bikeloan VFS | B26: BL | C26: BEG | D26: 45863 | E26: 0 | F26: 0 | G26: 0 | H26: 0 | I26: 0 | M26: cashloan | N26: payroll | O26: VDS | P26: 180134709 | Q26: 177793395 | R26: 162715192 | T26: MWG | U26: =SUM(P30:R30)/GETPIVOTDATA("closing_balance_dpd_under10",$O$7,"Partner","MWG")*365 -> 0.49258432
A27: [BE] - Bikeloan VFS | B27: BL | C27: BEG | D27: 45864 | E27: 0 | F27: 0 | G27: 0 | H27: 0 | I27: 0 | M27: cashloan | N27: cashloan | O27: BEG | P27: 208673555 | Q27: 170907800 | R27: 140807807 | T27: VNPAY | U27: =SUM(P31:R31)/GETPIVOTDATA("closing_balance_dpd_under10",$O$7,"Partner","VNPAY")*365 -> 0.45651653
A28: [BE] - Bikeloan VFS | B28: BL | C28: BEG | D28: 45865 | E28: 0 | F28: 0 | G28: 0 | H28: 0 | I28: 0 | M28: cashloan | N28: cashloan | O28: NGS | P28: 619417378 | Q28: 493982632 | R28: 409380520 | T28: ZALOPAY | U28: =SUM(P32:R32)/GETPIVOTDATA("closing_balance_dpd_under10",$O$7,"Partner","ZALOPAY")*365 -> 0.51861256
A29: [BE] - Bikeloan VFS | B29: BL | C29: BEG | D29: 45866 | E29: 0 | F29: 0 | G29: 0 | H29: 0 | I29: 0 | M29: cashloan | N29: cashloan | O29: CAKE | P29: 42400864409 | Q29: 48200259590 | R29: 53511511977
A30: [BE] - Bikeloan VFS | B30: BL | C30: BEG | D30: 45867 | E30: 0 | F30: 0 | G30: 0 | H30: 0 | I30: 0 | M30: cashloan | N30: cashloan | O30: MWG | P30: 6378275744 | Q30: 8067738498 | R30: 10087675211
A31: [BE] - Bikeloan VFS | B31: BL | C31: BEG | D31: 45868 | E31: 0 | F31: 0 | G31: 0 | H31: 0 | I31: 0 | M31: cashloan | N31: cashloan | O31: VNPAY | P31: 2629288891 | Q31: 2780395647 | R31: 2886582366
A32: [BE] - Bikeloan VFS | B32: BL | C32: BEG | D32: 45869 | E32: 0 | F32: 0 | G32: 0 | H32: 0 | I32: 0 | M32: cashloan | N32: cashloan | O32: ZALOPAY | P32: 5190014930 | Q32: 8151740830 | R32: 9991296076
A33: [BE] - Bikeloan VFS | B33: BL | C33: BEG | D33: 45870 | E33: 0 | F33: 0 | G33: 0 | H33: 0 | I33: 0 | M33: cashloan | N33: cashloan | O33: VNPOST | P33: 38874002 | Q33: 61536947 | R33: 104859015
A34: [BE] - Bikeloan VFS | B34: BL | C34: BEG | D34: 45871 | E34: 0 | F34: 0 | G34: 0 | H34: 0 | I34: 0
A35: [BE] - Bikeloan VFS | B35: BL | C35: BEG | D35: 45872 | E35: 0 | F35: 0 | G35: 0 | H35: 0 | I35: 0
A36: [BE] - Bikeloan VFS | B36: BL | C36: BEG | D36: 45873 | E36: 0 | F36: 0 | G36: 0 | H36: 0 | I36: 0
A37: [BE] - Bikeloan VFS | B37: BL | C37: BEG | D37: 45874 | E37: 0 | F37: 0 | G37: 0 | H37: 0 | I37: 0
A38: [BE] - Bikeloan VFS | B38: BL | C38: BEG | D38: 45875 | E38: 0 | F38: 0 | G38: 0 | H38: 0 | I38: 0
A39: [BE] - Bikeloan VFS | B39: BL | C39: BEG | D39: 45876 | E39: 0 | F39: 0 | G39: 0 | H39: 0 | I39: 0
A40: [BE] - Bikeloan VFS | B40: BL | C40: BEG | D40: 45877 | E40: 0 | F40: 0 | G40: 0 | H40: 0 | I40: 0
...

Sheet COF
F1: =SUBTOTAL(9,F3:F43) -> 16198720096480 | G1: =SUBTOTAL(9,G3:G43) -> 3.1233841e+09 | I1: =G1/F1*365 -> 0.070378103 | K1: 0.070378103
F2: =SUM(F4:F42) -> 348822682508025 | G2: =SUM(G4:G42) -> 6.3783621e+10 | I2: =SUM(I4:I42) -> 1173
B3: Nhom | C3: SP | D3: Partner | E3: pl | F3: Sum of BALANCE | G3: Sum of Lai DCV | H3: Month | I3: Day
B4: UPL | C4: cl | D4: BE | E4: BE CASHLOAN | F4: 175237237692 | G4: 35108054 | H4: 9 | I4: 30
B5: UPL | C5: cl | D5: CAKE | E5: CAKE CASHLOAN | F5: 45792086198052 | G5: 8.8220401e+09 | H5: 9 | I5: 30
B6: UPL | C6: OD | D6: CAKE | E6: CAKE OVERDRAFT | F6: 7169005435909 | G6: 9.9109849e+08 | H6: 9 | I6: 30
B7: UPL | C7: PD | D7: CAKE | E7: CAKE PAYDAY | F7: 3672603510227 | G7: 5.4667902e+08 | H7: 9 | I7: 30
B8: UPL | C8: cl | D8: MWG | E8: MWG CASHLOAN | F8: 7860835561894 | G8: 1.5211837e+09 | H8: 9 | I8: 30
B9: UPL | C9: cl | D9: NGS | E9: NGS CASHLOAN | F9: 530282165595 | G9: 1.1619612e+08 | H9: 9 | I9: 30
B10: UPL | C10: cl | D10: VDS | E10: VIETTEL CASHLOAN | F10: 47500871433668 | G10: 9.1994775e+09 | H10: 9 | I10: 30
B11: UPL | C11: PD | D11: VDS | E11: VIETTEL PAYDAY | F11: 6555226346162 | G11: 1.021781e+09 | H11: 9 | I11: 30
B12: UPL | C12: PD | D12: VDS | E12: VIETTEL PAYDAYPAYROLL | F12: 25934847005 | G12: 3828070.8 | H12: 9 | I12: 30
B13: UPL | C13: cl | D13: VDS | E13: VIETTEL PAYROLL CASHLOAN | F13: 234239258102 | G13: 44742343 | H13: 9 | I13: 30
B14: UPL | C14: cl | D14: VNPAY | E14: VNPAY CASHLOAN | F14: 2538375718443 | G14: 4.6902939e+08 | H14: 9 | I14: 30
B15: UPL | C15: cl | D15: VNPOST | E15: VNPOST CASHLOAN | F15: 74534379401 | G15: 14917048 | H15: 9 | I15: 30
... B42: UPL | C42: cl | D42: ZALOPAY | E42: Zalopay CASHLOAN | F42: 3450971717669 | G42: 6.384429e+08 | H42: 7 | I42: 31

Sheet NOTE
A1: SAP MODEL - CASHLOAN
B2: OFFICIAL | N2: HKN | O2: v9 | P2: 20251001
B3: 1. Notes and disclaimer
C4: a. Giới thiệu về SAP
D5: - SAP: Single Account Profitability (Hiệu quả sản phẩm trên từng đơn vị sản phẩm)
D6: - Model SAP được sử dụng như một (01) trong các mô hình dự đoán hiệu quả vòng đời của sản phẩm.
D7: - Do sự phức tạp của sản phẩm, các hệ thống vận hành (hệ thống hạch kế toán, hệ thống quản trị rủi ro, hệ thống quản trị…), hành vi người sử dụng hành vi người sử dụng, model chỉ có thể mô phỏng tương đối trung bình vòng đời của sản phẩm.
D8: - Do tính chất thời điểm, mô hình được xây dựng mô phỏng theo cách vận hành sản phẩm tại thời điểm phát hành. Trường hợp hệ thống thay đổi, sản phẩm thay đổi, mô hình sẽ không thể phản ánh đúng bản chất vận hành sản phẩm.
D9: - Mô hình được tính toán dựa vào các yếu tố đầu vào xác định tại một thời điểm xác định, do đó kết quả của mô hình có thể có sự khác biệt so với thực tế vận hành sản phẩm.
D10: - Mô hình SAP Cashloan tính hiệu quả của khoản vay giải ngân và thời hạn tối đa được áp dụng là 5 năm ( 60 tháng) kể từ ngày bắt đầu sản phẩm đối với sử dụng phương pháp dự phòng IFRS
E11: - Lưu ý rằng trường hợp áp dụng cho khoản vay 5 năm, thì các chi phí sẽ không được tính toán đầy đủ do chi phí COF cho thời gian từ lúc khoản vay kết thúc tới lúc được xóa trên sổ kế toán.
E12: - Chỉ nên sử dụng với khoản vay dưới 4 năm (48 tháng) để được tính toán đầy đủ chi phí
E13: - Đối với phương pháp tính rủi ro VAS, thời hạn khoản vay tối đa sử dụng là 4 năm (48 tháng)
C15: b. Giới thiệu về PnL
D16: - Trong file tính này, Profit & Lost (PnL) được dự phóng từ trung bình cộng kết quả kinh doanh trên từng sản phẩm (SAP) với yếu tố "sale plan" (số giải ngân) qua từng tháng, do đó có thể khác biệt so với kết quả thực tế vận hành.
D17: - Dòng tiền thực tế qua từng tháng có thể khác biệt với mô hình tính toán do nhiều yếu tố tác động bên ngoài thay đổi, do đó, vui lòng chỉ sử dụng mô hình cho mục đích tham khảo.
D18: - Cho mục đích tính dự phòng dòng tiền ngắn và trung hạn, mô hình PnL được cutoff tại thời điểm 5 năm (60 tháng) kể từ ngày bắt đầu khởi chạy sản phẩm đầu tiên.
B20: 2. Instruction
D21: - Dành cho người sử dụng
E22: - Chỉ chỉnh sửa vào các ô màu vàng
E23: - 2 sheets "SAP_Leadsheet" và "Sale plan&PnL" cung cấp yếu tố đầu vào và đầu ra để tính toán mô hình SAP cũng như PnL.
F24: - Sheet SAP_Leadsheet được cấu trúc 2 phần, bên trái là các yếu tố đầu vào (input) và bên phải là kết quả dự đoán (output). Đơn vị sử dụng tại bảng tính là triệu VND (mVND) và phần trăm (%)
F25: - Sheet "Sale plan & PL" được cấu trúc 2 phần, bên trên là sale plan và bên dưới là kết quả PnL
E26: - 2 sheets "SAP_Spreadsheet" và "PL projection speadsheet" là các file tính toán cho 2 sheet "SAP_Leadsheet", "Sales plan & PL"
F27: - 2 sheets được cấu trúc từ trên xuống dưới theo thứ tự tính toán mô phỏng để đưa ra kết quả kinh doanh cuối cùng
F28: - 2 sheets đã được tạm khóa. Trường hợp cần mở khóa, điều chỉnh các yếu tố, vui lòng liên hệ với nhóm vận hành để được hỗ trợ.
D30: - Dành riêng cho người vận hành, hiệu chỉnh
E31: - Cần cẩn trọng khi điều chỉnh ở các file "speadsheet" vì 1 khi sai lệch rất khó tìm ra lỗi (VD: sửa nhầm ô, link nhầm vị trí,…)
B34: 3. Legend
C35: GENERAL INPUT
G37: Diễn giải | L37: Chú thích
D38: Risk input | G38: Loại phương pháp tính rủi ro | L38: Lựa chon phương pháp tính rủi ro VAS và IFRS
D39: Write off | G39: Thời điểm WO | L39: Lựa chọn thời điểm ghi nhận WO là 360 hoặc 180
C40: REVENUE INPUT
G42: Diễn giải | L42: Chú thích
C43: Amount & Tenor
D44: Loan amount | G44: Số tiền vay giải ngân (có thể bao gồm bảo hiểm hoặc không) | L44: Trường hợp số tiền giải ngân > giá trị hàng hóa, chỉ ghi = số thực tế giải ngân
D45: Payment Method | G45: Phương pháp tính lãi | L45: EMI (Equated monthly Installment)- số tiền thanh toán cố định hàng tháng
D46: Nominal Tenor | G46: Thời hạn vay | L46: Thời hạn ghi nhận trên khoản vay ( VD: 1 tháng, 3 tháng, 12 tháng,…)
D47: Maturity to Termination | G47: Thời hạn từ lúc đáo hạn tới lúc tới khi ra ngoại bảng | L47: Nên để 6 tháng để khớp với hệ thống kế toán, rủi ro đang ghi nhận WO180+
...

Sheet Leadsheet
B1: SAP CASHLOAN MODEL | D1: 1
B2: =NOTE!N2 -> HKN | C2: =NOTE!P2 -> 20251001 | D2: =NOTE!O2 -> v9 | K2: NOTE
K3: Please read carefully about before using model
B4: Product | C4: Unsecured Cashloan | D4: UPL | E4: Risk input | G4: IFRS | H4: =G4 -> IFRS | L4: Disclaimer
B5: Sub-Product | C5: Cashloan | D5: ALL | E5: Write off | G5: DPD180+ | H5: =G5 -> DPD180+ | L5: Instruction
B6: Sub-Segments | C6: ZALOPAY | D6: ALL | E6: Quarter | G6: Q3.2025 | H6: =G6 -> Q3.2025 | L6: Legend
B8: REVENUE INPUT | H8: Cur: mVND | K8: GENERAL OUTPUT | U8: Cur: mVND
B10: Amount & Tenor | C10: Loan amount | E10: =DATA!G20 -> 14.389345 | N10: Life time | O10: Year 1 | P10: Year 2 | Q10: Year 3 | R10: Year 4 | S10: Year 5 | T10: % ANR | U10: % Disbursement
C11: Payment Method | E11: EMI | K11: ANR | N11: =N29 -> 4.491385 | O11: =O29 -> 7.2311727 | P11: =P29 -> 0.3817034 | Q11: =Q29 -> 0 | R11: =R29 -> 0 | S11: =S29 -> 0 | U11: =N11/$E$10 -> 0.31213269
C12: Nominal Tenor | E12: =DATA!H20 -> 14 | K12: TOI | N12: =SUM(N13:N15) -> 3.4971427 | O12: =SUM(O13:O15) -> 3.4461461 | P12: =SUM(P13:P15) -> 0.050996647 | Q12: =SUM(Q13:Q15) -> 0 | R12: =SUM(R13:R15) -> 0 | S12: =SUM(S13:S15) -> 0 | T12: =N12/$E$14*12/$N$11 -> 0.46718009 | U12: =N12/$E$10 -> 0.24303697
C13: Maturity to Termination | E13: 6 | K13: Net interest income | N13: =N31 -> 2.9659145 | O13: =O31 -> 2.9163234 | P13: =P31 -> 0.049591122 | Q13: =Q31 -> 0 | R13: =R31 -> 0 | S13: =S31 -> 0 | T13: =N13/$E$14*12/$N$11 -> 0.3962138 | U13: =N13/$E$10 -> 0.2061188
C14: Month on book | E14: =E12+E13 -> 20 | K14: Net fee income | N14: =N34 -> 0.53122822 | O14: =O34 -> 0.52982269 | P14: =P34 -> 0.0014055248 | Q14: =Q34 -> 0 | R14: =R34 -> 0 | S14: =S34 -> 0 | T14: =N14/$E$14*12/$N$11 -> 0.070966291 | U14: =N14/$E$10 -> 0.036918165
K15: Other income | N15: =N38 -> 0 | O15: =O38 -> 0 | P15: =P38 -> 0 | Q15: =Q38 -> 0 | R15: =R38 -> 0 | S15: =S38 -> 0 | T15: =N15/$E$14*12/$N$11 -> 0 | U15: =N15/$E$10 -> 0
K16: PROVISION | N16: =N39 -> -1.8345326 | O16: =O39 -> -1.7819252 | P16: =P39 -> -0.052607412 | Q16: =Q39 -> 0 | R16: =R39 -> 0 | S16: =S39 -> 0 | T16: =N16/$E$14*12/$N$11 -> -0.24507353 | U16: =N16/$E$10 -> -0.12749243
B17: Pricing | C17: From | D17: To | E17: IR | F17: COF | G17: NIM | K17: OPEX | N17: =SUM(N18:N21) -> -0.99439331 | O17: =SUM(O18:O21) -> -0.92092924 | P17: =SUM(P18:P21) -> -0.07346407 | Q17: =SUM(Q18:Q21) -> 0 | R17: =SUM(R18:R21) -> 0 | S17: =SUM(S18:S21) -> 0 | T17: =N17/$E$14*12/$N$11 -> -0.13284009 | U17: =N17/$E$10 -> -0.069106225
A18: 1 | B18: 1 | C18: 1 | D18: =E12 -> 14 | E18: =IR!U28 -> 0.51861256 | F18: =COF!K1 -> 0.070378103 | G18: =E18-F18 -> 0.44823445 | K18: Acquisition cost | N18: =SUM(N41) -> -0.35973363 | O18: =SUM(O41) -> -0.35973363 | P18: =SUM(P41) -> 0 | Q18: =SUM(Q41) -> 0 | R18: =SUM(R41) -> 0 | S18: =SUM(S41) -> 0 | T18: =N18/$E$14*12/$N$11 -> -0.048056485 | U18: =N18/$E$10 -> -0.025
A19: 2 | B19: 2 | C19: =IF(D18="","",IF(D18>$E$12,"",D18+1)) -> 15 | D19: =E14 -> 20 | E19: =E18 -> 0.51861256 | F19: =F18 -> 0.070378103 | G19: =E19-F19 -> 0.44823445 | K19: UW & Disbursal | N19: =N45 -> -0.038198394 | O19: =O45 -> -0.038198394 | P19: =P45 -> 0 | Q19: =Q45 -> 0 | R19: =R45 -> 0 | S19: =S45 -> 0 | T19: =N19/$E$14*12/$N$11 -> -0.0051028885 | U19: =N19/$E$10 -> -0.0026546305
A20: 3 | B20: 3 | K20: Collection & aftersale service | N20: =N48 -> -0.095508824 | O20: =O48 -> -0.0788665 | P20: =P48 -> -0.016642324 | Q20: =Q48 -> 0 | R20: =R48 -> 0 | S20: =S48 -> 0 | T20: =N20/$E$14*12/$N$11 -> -0.012758936 | U20: =N20/$E$10 -> -0.0066374685
A21: 4 | B21: 4 | K21: Support unit | N21: =N52 -> -0.50095247 | O21: =O52 -> -0.44413072 | P21: =P52 -> -0.056821746 | Q21: =Q52 -> 0 | R21: =R52 -> 0 | S21: =S52 -> 0 | T21: =N21/$E$14*12/$N$11 -> -0.066921781 | U21: =N21/$E$10 -> -0.034814126
A22: 5 | B22: 5 | K22: PBT | N22: =N12+N16+N17 -> 0.66821686 | O22: =O12+O16+O17 -> 0.74329169 | P22: =P12+P16+P17 -> -0.075074836 | Q22: =Q12+Q16+Q17 -> 0 | R22: =R12+R16+R17 -> 0 | S22: =S12+S16+S17 -> 0 | T22: =N22/$E$14*12/$N$11 -> 0.089266478 | U22: =N22/$E$10 -> 0.04643831
B23: 6 | K23: In which: PROFIT BEFORE SU | N23: =N22-N21 -> 1.1691693 | O23: =O22-O21 -> 1.1874224 | P23: =P22-P21 -> -0.01825309 | Q23: =Q22-Q21 -> 0 | R23: =R22-R21 -> 0 | S23: =S22-S21 -> 0 | T23: =N23/$E$14*12/$N$11 -> 0.15618826 | U23: =N23/$E$10 -> 0.081252435
B25: Early prepayment | C25: From | D25: To | E25: Penalty fee | F25: Penalty IR | G25: %Attrition
B26: 1 | C26: 1 | D26: 1 | E26: 0.03 | G26: 0.08 | H26: per cohort | K26: PERFORMANCE OUTPUT | U26: Cur: mVND
B27: 2 | C27: =D26+1 -> 2 | D27: 3 | E27: 0.03 | G27: 0.06 | H27: per cohort
B28: 3 | C28: =D27+1 -> 4 | D28: 14 | E28: 0.03 | G28: 0.025 | H28: per cohort | N28: Life time | O28: Year 1 | P28: Year 2 | Q28: Year 3 | R28: Year 4 | S28: Year 5 | T28: % ANR | U28: % Disbursement
B29: 4 | C29: =IF(D28="","",IF(D28>$E$12,"",D28+1)) -> 15 | K29: ANR | N29: =SUM(SAP_Speadsheet!$D$50:$BF$50)/COUNTIF(SAP_Speadsheet!$D$50:$BF$50,">0") -> 4.491385 | O29: =IFERROR(SUM(SAP_Speadsheet!$D$50:$P$50)/COUNTIF(SAP_Speadsheet!$D$50:$P$50,">0"),0) -> 7.2311727 | P29: =IFERROR(SUM(SAP_Speadsheet!$Q$50:$AB$50)/COUNTIF(SAP_Speadsheet!$Q$50:$AB$50,">0"),0) -> 0.3817034 | Q29: =IFERROR(SUM(SAP_Speadsheet!$AC$50:$AN$50)/COUNTIF(SAP_Speadsheet!$AC$50:$AN$50,">0"),0) -> 0 | R29: =IFERROR(SUM(SAP_Speadsheet!$AO$50:$AZ$50)/COUNTIF(SAP_Speadsheet!$AO$50:$AZ$50,">0"),0) -> 0 | S29: =IFERROR(SUM(SAP_Speadsheet!$BA$50:$BF$50)/COUNTIF(SAP_Speadsheet!$BA$50:$BF$50,">0"),0) -> 0 | U29: =N29/$E$10 -> 0.31213269
B30: 5 | C30: =IF(D29="","",IF(D29>$E$12,"",D29+1)) | E30: =IF(D30="",0,SUMIFS(#REF!,#REF!,Leadsheet!G$24,#REF!,Leadsheet!$A30,#REF!,Leadsheet!$C$4,#REF!,Leadsheet!$G$5,#REF!,Leadsheet!$D$5,#REF!,Leadsheet!G4)) -> 0 | F30: 0 | K30: TOI | N30: =SUM(O30:S30) -> 3.4971427 | O30: =SUM(SAP_Speadsheet!$E$55:$P$55) -> 3.4461461 | P30: =SUM(SAP_Speadsheet!$Q$55:$AB$55) -> 0.050996647 | Q30: =SUM(SAP_Speadsheet!$AC$55:$AN$55) -> 0 | R30: =SUM(SAP_Speadsheet!$AO$55:$AZ$55) -> 0 | S30: =SUM(SAP_Speadsheet!$BA$55:$BF$55) -> 0 | T30: =N30/$E$14*12/$N$29 -> 0.46718009 | U30: =N30/$E$10 -> 0.24303697
B31: 6 | C31: =IF(D30="","",IF(D30>$E$12,"",D30+1)) | E31: =IF(D31="",0,SUMIFS(#REF!,#REF!,Leadsheet!G$24,#REF!,Leadsheet!$A31,#REF!,Leadsheet!$C$4,#REF!,Leadsheet!$G$5,#REF!,Leadsheet!$D$5,#REF!,Leadsheet!G4)) -> 0 | F31: 0 | K31: Net interest income | N31: =SUM(O31:S31) -> 2.9659145 | O31: =SUM(SAP_Speadsheet!$E$57:$P$57) -> 2.9163234 | P31: =SUM(SAP_Speadsheet!$Q$57:$AB$57) -> 0.049591122 | Q31: =SUM(SAP_Speadsheet!$AC$57:$AN$57) -> 0 | R31: =SUM(SAP_Speadsheet!$AO$57:$AZ$57) -> 0 | S31: =SUM(SAP_Speadsheet!$BA$57:$BF$57) -> 0 | T31: =N31/$E$14*12/$N$29 -> 0.3962138 | U31: =N31/$E$10 -> 0.2061188
K32: Interest income | N32: =SUM(O32:S32) -> 3.4927398 | O32: =SUM(SAP_Speadsheet!$E$58:$P$58) -> 3.4252396 | P32: =SUM(SAP_Speadsheet!$Q$58:$AB$58) -> 0.067500163 | Q32: =SUM(SAP_Speadsheet!$AC$58:$AN$58) -> 0 | R32: =SUM(SAP_Speadsheet!$AO$58:$AZ$58) -> 0 | S32: =SUM(SAP_Speadsheet!$BA$58:$BF$58) -> 0 | T32: =N32/$E$14*12/$N$29 -> 0.46659191 | U32: =N32/$E$10 -> 0.24273098
B33: Credit insurrance | C33: Banca Premium (excl. in loan) | F33: per disbursement amount | K33: Cost of fund | N33: =SUM(O33:S33) -> -0.52682525 | O33: =SUM(SAP_Speadsheet!$E$59:$P$59) -> -0.50891621 | P33: =SUM(SAP_Speadsheet!$Q$59:$AB$59) -> -0.017909041 | Q33: =SUM(SAP_Speadsheet!$AC$59:$AN$59) -> 0 | R33: =SUM(SAP_Speadsheet!$AO$59:$AZ$59) -> 0 | S33: =SUM(SAP_Speadsheet!$BA$59:$BF$59) -> 0 | T33: =N33/$E$14*12/$N$29 -> -0.070378103 | U33: =N33/$E$10 -> -0.036612177
C34: Banca Premium (incl. in loan) | E34: =DATA!J20 -> 0.070807838 | F34: per disbursement amount | K34: Net fee income | N34: =SUM(O34:S34) -> 0.53122822 | O34: =SUM(SAP_Speadsheet!$E$61:$P$61) -> 0.52982269 | P34: =SUM(SAP_Speadsheet!$Q$61:$AB$61) -> 0.0014055248 | Q34: =SUM(SAP_Speadsheet!$AC$61:$AN$61) -> 0 | R34: =SUM(SAP_Speadsheet!$AO$61:$AZ$61) -> 0 | S34: =SUM(SAP_Speadsheet!$BA$61:$BF$61) -> 0 | T34: =N34/$E$14*12/$N$29 -> 0.070966291 | U34: =N34/$E$10 -> 0.036918165
C35: Penetration | E35: =DATA!K20 -> 0.47917585 | F35: per disbursement amount | K35: Early termination fee | N35: =SUM(O35:S35) -> 0.12702464 | O35: =SUM(SAP_Speadsheet!$E$62:$P$62) -> 0.12561911 | P35: =SUM(SAP_Speadsheet!$Q$62:$AB$62) -> 0.0014055248 | Q35: =SUM(SAP_Speadsheet!$AC$62:$AN$62) -> 0 | R35: =SUM(SAP_Speadsheet!$AO$62:$AZ$62) -> 0 | S35: =SUM(SAP_Speadsheet!$BA$62:$BF$62) -> 0 | T35: =N35/$E$14*12/$N$29 -> 0.016969105 | U35: =N35/$E$10 -> 0.0088276873
C36: Commission to CAKE | E36: 0.856 | F36: per disbursement amount | H36: done | K36: Insurance commission | N36: =SUM(O36:S36) -> 0.40420358 | O36: =SUM(SAP_Speadsheet!$E$63:$P$63) -> 0.40420358 | P36: =SUM(SAP_Speadsheet!$Q$63:$AB$63) -> 0 | Q36: =SUM(SAP_Speadsheet!$AC$63:$AN$63) -> 0 | R36: =SUM(SAP_Speadsheet!$AO$63:$AZ$63) -> 0 | S36: =SUM(SAP_Speadsheet!$BA$63:$BF$63) -> 0 | T36: =N36/$E$14*12/$N$29 -> 0.053997186 | U36: =N36/$E$10 -> 0.028090478
H37: done | K37: Support fee | N37: =SUM(O37:S37) -> 0 | O37: =SUM(SAP_Speadsheet!$E$64:$P$64) -> 0 | P37: =SUM(SAP_Speadsheet!$Q$64:$AB$64) -> 0 | Q37: =SUM(SAP_Speadsheet!$AC$64:$AN$64) -> 0 | R37: =SUM(SAP_Speadsheet!$AO$64:$AZ$64) -> 0 | S37: =SUM(SAP_Speadsheet!$BA$64:$BF$64) -> 0 | T37: =N37/$E$14*12/$N$29 -> 0 | U37: =N37/$E$10 -> 0
B38: Support fee | C38: One-time | F38: $ per account | K38: Other income | N38: =SUM(O38:S38) -> 0 | O38: =SUM(SAP_Speadsheet!$E$68:$P$68) -> 0 | P38: =SUM(SAP_Speadsheet!$Q$68:$AB$68) -> 0 | Q38: =SUM(SAP_Speadsheet!$AC$68:$AN$68) -> 0 | R38: =SUM(SAP_Speadsheet!$AO$68:$AZ$68) -> 0 | S38: =SUM(SAP_Speadsheet!$BA$68:$BF$68) -> 0 | T38: =N38/$E$14*12/$N$29 -> 0 | U38: =N38/$E$10 -> 0
C39: One-time | F39: % per ticketsize | K39: PROVISION | N39: =SUM(O39:S39) -> -1.8345326 | O39: =SUM(SAP_Speadsheet!$E$183:$P$183) -> -1.7819252 | P39: =SUM(SAP_Speadsheet!$Q$183:$AB$183) -> -0.052607412 | Q39: =SUM(SAP_Speadsheet!$AC$183:$AN$183) -> 0 | R39: =SUM(SAP_Speadsheet!$AO$183:$AZ$183) -> 0 | S39: =SUM(SAP_Speadsheet!$BA$183:$BF$183) -> 0 | T39: =N39/$E$14*12/$N$29 -> -0.24507353 | U39: =N39/$E$10 -> -0.12749243
C40: Monthly fee | F40: %monthly per ticketsize | K40: OPEX | N40: =SUM(O40:S40) -> -0.99439331 | O40: =+SUM(O41,O45,O48,O52) -> -0.92092924 | P40: =+SUM(P41,P45,P48,P52) -> -0.07346407 | Q40: =+SUM(Q41,Q45,Q48,Q52) -> 0 | R40: =+SUM(R41,R45,R48,R52) -> 0 | S40: =+SUM(S41,S45,S48,S52) -> 0 | T40: =N40/$E$14*12/$N$29 -> -0.13284009 | U40: =N40/$E$10 -> -0.069106225
B41: COST INPUT | H41: Cur: mVND | K41: Acquisition cost | N41: =SUM(O41:S41) -> -0.35973363 | O41: =SUM(O42:O44) -> -0.35973363 | P41: =SUM(P42:P44) -> 0 | Q41: =SUM(Q42:Q44) -> 0 | R41: =SUM(R42:R44) -> 0 | S41: =SUM(S42:S44) -> 0 | T41: =N41/$E$14*12/$N$29 -> -0.048056485 | U41: =N41/$E$10 -> -0.025
K42: Lead Acquisition | N42: =SUM(O42:S42) -> -0.35973363 | O42: =SUM(SAP_Speadsheet!$E$73:$P$73) -> -0.35973363 | P42: =SUM(SAP_Speadsheet!$Q$73:$AB$73) -> 0 | Q42: =SUM(SAP_Speadsheet!$AC$73:$AN$73) -> 0 | R42: =SUM(SAP_Speadsheet!$AO$73:$AZ$73) -> 0 | S42: =SUM(SAP_Speadsheet!$BA$73:$BF$73) -> 0 | T42: =N42/$E$14*12/$N$29 -> -0.048056485 | U42: =N42/$E$10 -> -0.025
B43: Inflation rate | E43: 0.035 | F43: % per year | K43: Sharing performance | N43: =SUM(O43:S43) -> 0 | O43: =SUM(SAP_Speadsheet!$E$74:$P$74) -> 0 | P43: =SUM(SAP_Speadsheet!$Q$74:$AB$74) -> 0 | Q43: =SUM(SAP_Speadsheet!$AC$74:$AN$74) -> 0 | R43: =SUM(SAP_Speadsheet!$AO$74:$AZ$74) -> 0 | S43: =SUM(SAP_Speadsheet!$BA$74:$BF$74) -> 0 | T43: =N43/$E$14*12/$N$29 -> 0 | U43: =N43/$E$10 -> 0
...

Sheet DATA
B2: 1 | C2: Aproval rate, signed rate
C4: aprroval rate | E4: 0.455
C5: Signed rate | E5: 0.954
B14: 2 | C14: Disburse, Tenor, Insurance, IR
C16: Disburse date | D16: # Disburse | E16: Disburse amount (VND) | F16: Current balance (VND) | G16: Ticket size (VND) | H16: Avg tenor (Month) | I16: Avg IR (%) | J16: Insurance fee (VND) | K16: % Insurance penetration by date
C17: 45901 | D17: 5356 | E17: 83034230000 | F17: 72384844421 | G17: 15503030 | H17: 13.371733 | I17: 0.52493465 | J17: 2862230000 | K17: 0.50130695 | L17: =E17-J17 -> 80172000000
C18: 45870 | D18: 5840 | E18: 83818310000 | F18: 66141256151 | G18: 14352450 | H18: 13.956678 | I18: 0.52588185 | J18: 2760310000 | K18: 0.48236301 | L18: =E18-J18 -> 81058000000
C19: 45839 | D19: 6515 | E19: 87997150000 | F19: 62650264764 | G19: 13506853 | H19: 13.730008 | I19: 0.52723715 | J19: 2740150000 | K19: 0.4552571 | L19: =E19-J19 -> 85257000000
C20: AVG | G20: =SUM(E17:E19)/SUM(D17:D19)/10^6 -> 14.389345 | H20: =ROUND(SUMPRODUCT(H17:H19,$E$17:$E$19)/SUM($E$17:$E$19),0) -> 14 | I20: =SUMPRODUCT(I17:I19,E17:E19)/SUM(E17:E19) -> 0.52604121 | J20: =SUM(J17:J19)/SUMPRODUCT(K17:K19,L17:L19) -> 0.070807838 | K20: =SUMPRODUCT(K17:K19,E17:E19)/SUM(E17:E19) -> 0.47917585
B24: 3 | C24: UW, collection, MKT
D25: 6 | E25: 7 | F25: 8 | G25: 9 | I25: AVG
C26: New ACC | E26: 6515 | F26: 5840 | G26: 5356
C27: Active acc | D27: 7243 | E27: 13144 | F27: 17888 | G27: 21762
C29: MKT acquisition | I29: =SUM(E29:G29)/SUM(E26:G26)/10^6 -> 0
C30: UW | E30: 1.237893e+08 | F30: 2.3264011e+08 | G30: 2.4925835e+08 | I30: =SUM(E30:G30)/SUM(E26:G26)/10^6 -> 0.034198394
C31: Collection | E31: 26828762 | F31: 46328553 | G31: 72622946 | H31: =SUM(E31:G31)/SUM(D27:F27) -> 3808.7593 | I31: =8000/10^6 -> 0.008 | J31: Sử dụng mức tương đương Q2 do quý 3 thay đổi collection, chi phí ko đầy đủ
C32: SMS | E32: 4183841.8 | F32: 5100190.9 | G32: 9493145.7 | H32: =SUM(E32:G32)/SUM(E27:G27) -> 355.6688 | I32: 0.0007
C33: Partner acquisition | I33: =SUM(E33:G33)/SUM(E17:E19) -> 0
B36: 4 | C36: RR
C38: Sum of principal_balance_at_report_month | D38: Column Labels
C39: Row Labels | D39: 202506 | E39: 202507 | F39: 202508 | G39: 202509 | H39: Grand Total
C40: 0 | D40: 69480875106 | E40: 144317132226 | F40: 203122629388 | G40: 252065074464 | H40: 668985711184
C41: 1 | D41: 1249099314 | E41: 2262297913 | F41: 4759822395 | G41: 7295815497 | H41: 15567035119
C42: 2 | E42: 753631097 | F42: 1728253388 | G42: 3422841764 | H42: 5904726249
C43: 3 | F43: 778788469 | G43: 1636938736 | H43: 2415727205
C44: 4 | G44: 767238469 | H44: 767238469
C45: Grand Total | D45: 70729974420 | E45: 147333061236 | F45: 210389493640 | G45: 265187908930 | H45: 693640438226
B58: Row Labels | C58: 7 | D58: 8 | E58: 9 | F58: AVG | G58: ADJ | H58: 202506 | I58: 202507 | J58: 202508 | K58: 202509 | N58: EOM Bucket | O58: report_month | P58: principal_balance_at_report_month
B59: 0 | C59: =I60/H59 -> 0.032560009 | D59: =J60/I59 -> 0.032981686 | E59: =K60/J59 -> 0.03591828 | F59: =AVERAGE(C59:E59) -> 0.033819992 | G59: =F59 -> 0.033819992 | H59: 69480875106 | I59: 144317132226 | J59: 203122629388 | K59: 252065074464 | N59: 0 | O59: 202510 | P59: 294414851862
B60: 1 | C60: =I61/H60 -> 0.60333961 | D60: =J61/I60 -> 0.76393714 | E60: =K61/J60 -> 0.71911124 | F60: =AVERAGE(C60:E60) -> 0.69546266 | G60: =F60 -> 0.69546266 | H60: 1249099314 | I60: 2262297913 | J60: 4759822395 | K60: 7295815497 | N60: 0 | O60: 202508 | P60: 203122629388
B61: 2 | C61: =I62/H61 -> #DIV/0! | D61: =J62/I61 -> 1.0333815 | E61: =K62/J61 -> 0.94716362 | F61: =AVERAGE(D61:E61) -> 0.99027258 | G61: =F61 -> 0.99027258 | I61: 753631097 | J61: 1728253388 | K61: 3422841764 | N61: 0 | O61: 202509 | P61: 252065074464
B62: 3 | C62: =I63/H62 -> #DIV/0! | D62: =J63/I62 -> #DIV/0! | E62: =K63/J62 -> 0.98516927 | F62: =E62 -> 0.98516927 | G62: =F62 -> 0.98516927 | J62: 778788469 | K62: 1636938736 | N62: 0 | O62: 202504 | P62: 8294394
B63: 4 | C63: =I64/H63 -> #DIV/0! | D63: =J64/I63 -> #DIV/0! | E63: =K64/J63 -> #DIV/0! | G63: 1 | K63: 767238469 | N63: 0 | O63: 202506 | P63: 69480875106
B64: 5 | C64: =I65/H64 -> #DIV/0! | D64: =J65/I64 -> #DIV/0! | E64: =K65/J64 -> #DIV/0! | G64: 1 | N64: 0 | O64: 202507 | P64: 144317132226
B65: 6 | C65: =I66/H65 -> #DIV/0! | D65: =J66/I65 -> #DIV/0! | E65: =K66/J65 -> #DIV/0! | G65: 1 | N65: 0 | O65: 202505 | P65: 28358115388
B66: 7 | C66: =I67/H66 -> #DIV/0! | D66: =J67/I66 -> #DIV/0! | E66: =K67/J66 -> #DIV/0! | G66: 1 | N66: 0 | O66: 202503 | P66: 9630000
B67: 8 | C67: =I68/H67 -> #DIV/0! | D67: =J68/I67 -> #DIV/0! | E67: =K68/J67 -> #DIV/0! | G67: 1 | N67: 1 | O67: 202506 | P67: 1249099314
B68: 9 | C68: =I69/H68 -> #DIV/0! | D68: =J69/I68 -> #DIV/0! | E68: =K69/J68 -> #DIV/0! | N68: 1 | O68: 202508 | P68: 4759822395
B69: 10 | C69: =I70/H69 -> #DIV/0! | D69: =J70/I69 -> #DIV/0! | E69: =K70/J69 -> #DIV/0! | N69: 1 | O69: 202509 | P69: 7295815497
B70: 11 | C70: =I71/H70 -> #DIV/0! | D70: =J71/I70 -> #DIV/0! | E70: =K71/J70 -> #DIV/0! | N70: 1 | O70: 202510 | P70: 9918665014
...

Sheet SAP_Speadsheet
B1: SAP Speadsheet
C4: Method
C5: Month on book | D5: 0 | E5: =D5+1 -> 1 | F5: =E5+1 -> 2 | G5: =F5+1 -> 3 | H5: =G5+1 -> 4 | I5: =H5+1 -> 5 | J5: =I5+1 -> 6 | K5: =J5+1 -> 7 | L5: =K5+1 -> 8 | ... BL5: =BK5+1 -> 60
C6: Oustanding tenor | D6: =IF(Leadsheet!$E$12-SAP_Speadsheet!D5<0,0,Leadsheet!$E$12-SAP_Speadsheet!D5) -> 14 | E6: =IF(Leadsheet!$E$12-SAP_Speadsheet!E5<0,0,Leadsheet!$E$12-SAP_Speadsheet!E5) -> 13 | F6: =IF(Leadsheet!$E$12-SAP_Speadsheet!F5<0,0,Leadsheet!$E$12-SAP_Speadsheet!F5) -> 12 | G6: =IF(Leadsheet!$E$12-SAP_Speadsheet!G5<0,0,Leadsheet!$E$12-SAP_Speadsheet!G5) -> 11 | H6: =IF(Leadsheet!$E$12-SAP_Speadsheet!H5<0,0,Leadsheet!$E$12-SAP_Speadsheet!H5) -> 10 | I6: =IF(Leadsheet!$E$12-SAP_Speadsheet!I5<0,0,Leadsheet!$E$12-SAP_Speadsheet!I5) -> 9 | J6: =IF(Leadsheet!$E$12-SAP_Speadsheet!J5<0,0,Leadsheet!$E$12-SAP_Speadsheet!J5) -> 8 | K6: =IF(Leadsheet!$E$12-SAP_Speadsheet!K5<0,0,Leadsheet!$E$12-SAP_Speadsheet!K5) -> 7 | ... BL6: =IF(Leadsheet!$E$12-SAP_Speadsheet!BL5<0,0,Leadsheet!$E$12-SAP_Speadsheet!BL5) -> 0
C7: Last month on book | D7: =Leadsheet!E13+Leadsheet!E12 -> 20
B9: Balance
B10: Interest rate
C11: INR rate | D11: =Leadsheet!E18 -> 0.51861256 | E11: =IF(E$5>$D$7,0,VLOOKUP(SAP_Speadsheet!E$5,Leadsheet!$C$18:$F$23,3,1)) -> 0.51861256 | F11: =IF(F$5>$D$7,0,VLOOKUP(SAP_Speadsheet!F$5,Leadsheet!$C$18:$F$23,3,1)) -> 0.51861256 | G11: =IF(G$5>$D$7,0,VLOOKUP(SAP_Speadsheet!G$5,Leadsheet!$C$18:$F$23,3,1)) -> 0.51861256 | H11: =IF(H$5>$D$7,0,VLOOKUP(SAP_Speadsheet!H$5,Leadsheet!$C$18:$F$23,3,1)) -> 0.51861256 | I11: =IF(I$5>$D$7,0,VLOOKUP(SAP_Speadsheet!I$5,Leadsheet!$C$18:$F$23,3,1)) -> 0.51861256 | J11: =IF(J$5>$D$7,0,VLOOKUP(SAP_Speadsheet!J$5,Leadsheet!$C$18:$F$23,3,1)) -> 0.51861256 | K11: =IF(K$5>$D$7,0,VLOOKUP(SAP_Speadsheet!K$5,Leadsheet!$C$18:$F$23,3,1)) -> 0.51861256 | L11: =IF(L$5>$D$7,0,VLOOKUP(SAP_Speadsheet!L$5,Leadsheet!$C$18:$F$23,3,1)) -> 0.51861256 | ... BL11: =IF(BL$5>$D$7,0,VLOOKUP(SAP_Speadsheet!BL$5,Leadsheet!$C$18:$F$23,3,1)) -> 0
C12: COF rate | D12: =Leadsheet!F18 -> 0.070378103 | E12: =IF(E$5>$D$7,0,VLOOKUP(SAP_Speadsheet!E$5,Leadsheet!$C$18:$F$23,4,1)) -> 0.070378103 | F12: =IF(F$5>$D$7,0,VLOOKUP(SAP_Speadsheet!F$5,Leadsheet!$C$18:$F$23,4,1)) -> 0.070378103 | G12: =IF(G$5>$D$7,0,VLOOKUP(SAP_Speadsheet!G$5,Leadsheet!$C$18:$F$23,4,1)) -> 0.070378103 | H12: =IF(H$5>$D$7,0,VLOOKUP(SAP_Speadsheet!H$5,Leadsheet!$C$18:$F$23,4,1)) -> 0.070378103 | I12: =IF(I$5>$D$7,0,VLOOKUP(SAP_Speadsheet!I$5,Leadsheet!$C$18:$F$23,4,1)) -> 0.070378103 | J12: =IF(J$5>$D$7,0,VLOOKUP(SAP_Speadsheet!J$5,Leadsheet!$C$18:$F$23,4,1)) -> 0.070378103 | K12: =IF(K$5>$D$7,0,VLOOKUP(SAP_Speadsheet!K$5,Leadsheet!$C$18:$F$23,4,1)) -> 0.070378103 | L12: =IF(L$5>$D$7,0,VLOOKUP(SAP_Speadsheet!L$5,Leadsheet!$C$18:$F$23,4,1)) -> 0.070378103 | ... BL12: =IF(BL$5>$D$7,0,VLOOKUP(SAP_Speadsheet!BL$5,Leadsheet!$C$18:$F$23,4,1)) -> 0
C13: Attrition rate | E13: =IF(E$5<Leadsheet!$E$12,VLOOKUP(SAP_Speadsheet!E$5,Leadsheet!$C$26:$G$30,5,1),0) -> 0.08 | F13: =IF(F$5<Leadsheet!$E$12,VLOOKUP(SAP_Speadsheet!F$5,Leadsheet!$C$26:$G$30,5,1),0) -> 0.06 | G13: =IF(G$5<Leadsheet!$E$12,VLOOKUP(SAP_Speadsheet!G$5,Leadsheet!$C$26:$G$30,5,1),0) -> 0.06 | H13: =IF(H$5<Leadsheet!$E$12,VLOOKUP(SAP_Speadsheet!H$5,Leadsheet!$C$26:$G$30,5,1),0) -> 0.025 | I13: =IF(I$5<Leadsheet!$E$12,VLOOKUP(SAP_Speadsheet!I$5,Leadsheet!$C$26:$G$30,5,1),0) -> 0.025 | J13: =IF(J$5<Leadsheet!$E$12,VLOOKUP(SAP_Speadsheet!J$5,Leadsheet!$C$26:$G$30,5,1),0) -> 0.025 | K13: =IF(K$5<Leadsheet!$E$12,VLOOKUP(SAP_Speadsheet!K$5,Leadsheet!$C$26:$G$30,5,1),0) -> 0.025 | L13: =IF(L$5<Leadsheet!$E$12,VLOOKUP(SAP_Speadsheet!L$5,Leadsheet!$C$26:$G$30,5,1),0) -> 0.025 | ... BL13: =IF(BL$5<Leadsheet!$E$12,VLOOKUP(SAP_Speadsheet!BL$5,Leadsheet!$C$26:$G$30,5,1),0) -> 0
C14: Prepayment Penalty | E14: =IF(E$5<Leadsheet!$E$12,VLOOKUP(SAP_Speadsheet!E$5,Leadsheet!$C$26:$F$30,3,1),0) -> 0.03 | F14: =IF(F$5<Leadsheet!$E$12,VLOOKUP(SAP_Speadsheet!F$5,Leadsheet!$C$26:$F$30,3,1),0) -> 0.03 | G14: =IF(G$5<Leadsheet!$E$12,VLOOKUP(SAP_Speadsheet!G$5,Leadsheet!$C$26:$F$30,3,1),0) -> 0.03 | H14: =IF(H$5<Leadsheet!$E$12,VLOOKUP(SAP_Speadsheet!H$5,Leadsheet!$C$26:$F$30,3,1),0) -> 0.03 | I14: =IF(I$5<Leadsheet!$E$12,VLOOKUP(SAP_Speadsheet!I$5,Leadsheet!$C$26:$F$30,3,1),0) -> 0.03 | J14: =IF(J$5<Leadsheet!$E$12,VLOOKUP(SAP_Speadsheet!J$5,Leadsheet!$C$26:$F$30,3,1),0) -> 0.03 | K14: =IF(K$5<Leadsheet!$E$12,VLOOKUP(SAP_Speadsheet!K$5,Leadsheet!$C$26:$F$30,3,1),0) -> 0.03 | L14: =IF(L$5<Leadsheet!$E$12,VLOOKUP(SAP_Speadsheet!L$5,Leadsheet!$C$26:$F$30,3,1),0) -> 0.03 | ... BL14: =IF(BL$5<Leadsheet!$E$12,VLOOKUP(SAP_Speadsheet!BL$5,Leadsheet!$C$26:$F$30,3,1),0) -> 0
B16: EMI | C16: Account accumulated | D16: 1 | E16: =IF(E5>$D$7,0,D16-E13) -> 0.92 | F16: =IF(F5>$D$7,0,E16-F13) -> 0.86 | G16: =IF(G5>$D$7,0,F16-G13) -> 0.8 | H16: =IF(H5>$D$7,0,G16-H13) -> 0.775 | I16: =IF(I5>$D$7,0,H16-I13) -> 0.75 | J16: =IF(J5>$D$7,0,I16-J13) -> 0.725 | K16: =IF(K5>$D$7,0,J16-K13) -> 0.7 | L16: =IF(L5>$D$7,0,K16-L13) -> 0.675 | ... BL16: =IF(BL5>$D$7,0,BK16-BL13) -> 0
C17: Nominal ENR | D17: =Leadsheet!E10 -> 14.389345 | E17: =IF(E$5>Leadsheet!$E$12,0,D17+E21+E18) -> 12.468753 | F17: =IF(F$5>Leadsheet!$E$12,0,SAP_Speadsheet!E17+SAP_Speadsheet!F21+F18) -> 10.950759 | G17: =IF(G$5>Leadsheet!$E$12,0,SAP_Speadsheet!F17+SAP_Speadsheet!G21+G18) -> 9.5178705 | H17: =IF(H$5>Leadsheet!$E$12,0,SAP_Speadsheet!G17+SAP_Speadsheet!H21+H18) -> 8.5520703 | I17: =IF(I$5>Leadsheet!$E$12,0,SAP_Speadsheet!H17+SAP_Speadsheet!I21+I18) -> 7.6041584 | J17: =IF(J$5>Leadsheet!$E$12,0,SAP_Speadsheet!I17+SAP_Speadsheet!J21+J18) -> 6.6744414 | K17: =IF(K$5>Leadsheet!$E$12,0,SAP_Speadsheet!J17+SAP_Speadsheet!K21+K18) -> 5.7631232 | L17: =IF(L$5>Leadsheet!$E$12,0,SAP_Speadsheet!K17+SAP_Speadsheet!L21+L18) -> 4.8705264 | M17: =IF(M$5>Leadsheet!$E$12,0,SAP_Speadsheet!L17+SAP_Speadsheet!M21+M18) -> 3.9971376 | ... BL17: =IF(BL$5>Leadsheet!$E$12,0,SAP_Speadsheet!BK17+SAP_Speadsheet!BL21+BL18) -> 0
C18: Fully Prepayment Amount | E18: =-IF(E6>0,IFERROR(D27*(D16-E16)/D16,0),0) -> -1.1511476 | F18: =-IF(F6>0,IFERROR(E27*(E16-F16)/E16,0),0) -> -0.78313876 | G18: =-IF(G6>0,IFERROR(F27*(F16-G16)/F16,0),0) -> -0.71743978 | H18: =-IF(H6>0,IFERROR(G27*(G16-H16)/G16,0),0) -> -0.27174787 | I18: =-IF(I6>0,IFERROR(H27*(H16-I16)/H16,0),0) -> -0.24616284 | J18: =-IF(J6>0,IFERROR(I27*(I16-J16)/I16,0),0) -> -0.2205957 | K18: =-IF(K6>0,IFERROR(J27*(J16-K16)/J16,0),0) -> -0.19521801 | L18: =-IF(L6>0,IFERROR(K27*(K16-L16)/K16,0),0) -> -0.17002458 | ... BL18: =-IF(BL6>0,IFERROR(BK27*(BK16-BL16)/BK16,0),0) -> 0
C19: EMI payment | E19: =-IFERROR(PMT(D11/12,D6,-D17),0) -> -1.3913195 | F19: =-IFERROR(PMT(E11/12,E6,-E17),0) -> -1.2737258 | G19: =-IFERROR(PMT(F11/12,F6,-F17),0) -> -1.1887154 | H19: =-IFERROR(PMT(G11/12,G6,-G17),0) -> -1.1053929 | I19: =-IFERROR(PMT(H11/12,H6,-H17),0) -> -1.07135 | J19: =-IFERROR(PMT(I11/12,I6,-I17),0) -> -1.0377556 | K19: =-IFERROR(PMT(J11/12,J6,-J17),0) -> -1.0045543 | L19: =-IFERROR(PMT(K11/12,K6,-K17),0) -> -0.97164126 | ... BL19: =-IFERROR(PMT(BK11/12,BK6,-BK17),0) -> 0
C20: Nominal Interest | E20: =-IF(E5>$D$6,0,D17*D11/12) -> -0.62187459 | F20: =-IF(F5>$D$6,0,E17*E11/12) -> -0.53887097 | G20: =-IF(G5>$D$6,0,F17*F11/12) -> -0.47326676 | H20: =-IF(H5>$D$6,0,G17*G11/12) -> -0.4113406 | I20: =-IF(I5>$D$6,0,H17*H11/12) -> -0.36960092 | J20: =-IF(J5>$D$6,0,I17*I11/12) -> -0.32863434 | K20: =-IF(K5>$D$6,0,J17*J11/12) -> -0.2884541 | L20: =-IF(L5>$D$6,0,K17*K11/12) -> -0.24906901 | ... BL20: =-IF(BL5>$D$6,0,BK17*BK11/12) -> 0
C21: Nominal Payment | E21: =E19-E20 -> -0.76944493 | F21: =F19-F20 -> -0.73485487 | G21: =G19-G20 -> -0.71544862 | H21: =H19-H20 -> -0.69405228 | I21: =I19-I20 -> -0.70174907 | J21: =J19-J20 -> -0.70912129 | K21: =K19-K20 -> -0.7161002 | L21: =L19-L20 -> -0.72257225 | ... BL21: =BL19-BL20 -> 0
C24: Schedule Payment | E24: =IF(E5>Leadsheet!$E$12,0,IFERROR(E21/D17*D27*(1-Leadsheet!$D$91)+E18,0)) -> -1.8945699 | F24: =IF(F5>Leadsheet!$E$12,0,IFERROR(F21/E17*E27*(1-Leadsheet!$D$91)+F18,0)) -> -1.4669117 | G24: =IF(G5>Leadsheet!$E$12,0,IFERROR(G21/F17*F27*(1-Leadsheet!$D$91)+G18,0)) -> -1.3665597 | H24: =IF(H5>Leadsheet!$E$12,0,IFERROR(H21/G17*G27*(1-Leadsheet!$D$91)+H18,0)) -> -0.8844178 | I24: =IF(I5>Leadsheet!$E$12,0,IFERROR(I21/H17*H27*(1-Leadsheet!$D$91)+I18,0)) -> -0.85115928 | J24: =IF(J5>Leadsheet!$E$12,0,IFERROR(J21/I17*I27*(1-Leadsheet!$D$91)+J18,0)) -> -0.81686946 | K24: =IF(K5>Leadsheet!$E$12,0,IFERROR(K21/J17*J27*(1-Leadsheet!$D$91)+K18,0)) -> -0.78207842 | L24: =IF(L5>Leadsheet!$E$12,0,IFERROR(L21/K17*K27*(1-Leadsheet!$D$91)+L18,0)) -> -0.74672621 | ... BL24: =IF(BL5>Leadsheet!$E$12,0,IFERROR(BL21/BK17*BK27*(1-Leadsheet!$D$91)+BL18,0)) -> 0
A26: SBV | B26: Overdue | C26: Balance by Bucket/Group
A27: G1 | B27: 0 | C27: B0 | D27: =Leadsheet!E10 -> 14.389345 | E27: =IF(E5>=Leadsheet!$E$12,0,D44+E24-SUM(E28:E41)) -> 12.008128 | F27: =IF(F5>=Leadsheet!$E$12,0,E44+F24-SUM(F28:F41)) -> 10.283303 | G27: =IF(G5>=Leadsheet!$E$12,0,F44+G24-SUM(G28:G41)) -> 8.6959318 | H27: =IF(H5>=Leadsheet!$E$12,0,G44+H24-SUM(H28:H41)) -> 7.631048 | I27: =IF(I5>=Leadsheet!$E$12,0,H44+I24-SUM(I28:I41)) -> 6.6178709 | J27: =IF(J5>=Leadsheet!$E$12,0,I44+J24-SUM(J28:J41)) -> 5.6613224 | K27: =IF(K5>=Leadsheet!$E$12,0,J44+K24-SUM(K28:K41)) -> 4.7606884 | L27: =IF(L5>=Leadsheet!$E$12,0,K44+L24-SUM(L28:L41)) -> 3.9154144 | ... BL27: =IF(BL5>=Leadsheet!$E$12,0,BK44+BL24-SUM(BL28:BL41)) -> 0
A28: G2 | B28: 30 | C28: B1 | E28: =IF(E$5>$D$7,0,D27*Leadsheet!$D91) -> 0.48664753 | F28: =IF(F$5>$D$7,0,E27*Leadsheet!$D91) -> 0.40611478 | G28: =IF(G$5>$D$7,0,F27*Leadsheet!$D91) -> 0.34778124 | H28: =IF(H$5>$D$7,0,G27*Leadsheet!$D91) -> 0.29409634 | I28: =IF(I$5>$D$7,0,H27*Leadsheet!$D91) -> 0.25808198 | J28: =IF(J$5>$D$7,0,I27*Leadsheet!$D91) -> 0.22381634 | K28: =IF(K$5>$D$7,0,J27*Leadsheet!$D91) -> 0.19146588 | L28: =IF(L$5>$D$7,0,K27*Leadsheet!$D91) -> 0.16100644 | ... BL28: =IF(BL$5>$D$7,0,BK27*Leadsheet!$D91) -> 0
A29: G2 | B29: 60 | C29: B2 | E29: =IF(E$5>$D$7,0,D28*Leadsheet!$D92) -> 0 | F29: =IF(F$5>$D$7,0,E28*Leadsheet!$D92) -> 0.33844519 | G29: =IF(G$5>$D$7,0,F28*Leadsheet!$D92) -> 0.28243766 | H29: =IF(H$5>$D$7,0,G28*Leadsheet!$D92) -> 0.24186887 | I29: =IF(I$5>$D$7,0,H28*Leadsheet!$D92) -> 0.20453303 | J29: =IF(J$5>$D$7,0,I28*Leadsheet!$D92) -> 0.17948638 | K29: =IF(K$5>$D$7,0,J28*Leadsheet!$D92) -> 0.15565591 | L29: =IF(L$5>$D$7,0,K28*Leadsheet!$D92) -> 0.13315737 | ... BL29: =IF(BL$5>$D$7,0,BK28*Leadsheet!$D92) -> 0
A30: G2 | B30: 90 | C30: B3 | E30: =IF(E$5>$D$7,0,D29*Leadsheet!$D93) -> 0 | F30: =IF(F$5>$D$7,0,E29*Leadsheet!$D93) -> 0 | G30: =IF(G$5>$D$7,0,F29*Leadsheet!$D93) -> 0.33515299 | H30: =IF(H$5>$D$7,0,G29*Leadsheet!$D93) -> 0.27969027 | I30: =IF(I$5>$D$7,0,H29*Leadsheet!$D93) -> 0.23951611 | J30: =IF(J$5>$D$7,0,I29*Leadsheet!$D93) -> 0.20254345 | K30: =IF(K$5>$D$7,0,J29*Leadsheet!$D93) -> 0.17774044 | L30: =IF(L$5>$D$7,0,K29*Leadsheet!$D93) -> 0.15414178 | ... AU30: =IF(AU$5>$D$7,0,AT29*Leadsheet!$D93) -> 0 | AV30: 0 | AW30: =IF(AW$5>$D$7,0,AV29*Leadsheet!$D93) -> 0 | AX30: =IF(AX$5>$D$7,0,AW29*Leadsheet!$D93) -> 0 | AY30: =IF(AY$5>$D$7,0,AX29*Leadsheet!$D93) -> 0 | AZ30: =IF(AZ$5>$D$7,0,AY29*Leadsheet!$D93) -> 0 | BA30: =IF(BA$5>$D$7,0,AZ29*Leadsheet!$D93) -> 0 | BB30: =IF(BB$5>$D$7,0,BA29*Leadsheet!$D93) -> 0 | BC30: =IF(BC$5>$D$7,0,BB29*Leadsheet!$D93) -> 0 | BD30: =IF(BD$5>$D$7,0,BC29*Leadsheet!$D93) -> 0 | ... BL30: =IF(BL$5>$D$7,0,BK29*Leadsheet!$D93) -> 0
A31: G3 | B31: 120 | C31: B4 | E31: =IF(E$5>$D$7,0,D30*Leadsheet!$D94) -> 0 | F31: =IF(F$5>$D$7,0,E30*Leadsheet!$D94) -> 0 | G31: =IF(G$5>$D$7,0,F30*Leadsheet!$D94) -> 0 | H31: =IF(H$5>$D$7,0,G30*Leadsheet!$D94) -> 0.33018243 | I31: =IF(I$5>$D$7,0,H30*Leadsheet!$D94) -> 0.27554226 | J31: =IF(J$5>$D$7,0,I30*Leadsheet!$D94) -> 0.23596391 | K31: =IF(K$5>$D$7,0,J30*Leadsheet!$D94) -> 0.19953958 | L31: =IF(L$5>$D$7,0,K30*Leadsheet!$D94) -> 0.17510442 | ... BL31: =IF(BL$5>$D$7,0,BK30*Leadsheet!$D94) -> 0
A32: G3 | B32: 150 | C32: B5 | E32: =IF(E$5>$D$7,0,D31*Leadsheet!$D95) -> 0 | F32: =IF(F$5>$D$7,0,E31*Leadsheet!$D95) -> 0 | G32: =IF(G$5>$D$7,0,F31*Leadsheet!$D95) -> 0 | H32: =IF(H$5>$D$7,0,G31*Leadsheet!$D95) -> 0 | I32: =IF(I$5>$D$7,0,H31*Leadsheet!$D95) -> 0.33018243 | J32: =IF(J$5>$D$7,0,I31*Leadsheet!$D95) -> 0.27554226 | K32: =IF(K$5>$D$7,0,J31*Leadsheet!$D95) -> 0.23596391 | L32: =IF(L$5>$D$7,0,K31*Leadsheet!$D95) -> 0.19953958 | ... BL32: =IF(BL$5>$D$7,0,BK31*Leadsheet!$D95) -> 0
A33: G3 | B33: 180 | C33: B6 | E33: =IF(E$5>$D$7,0,D32*Leadsheet!$D96) -> 0 | F33: =IF(F$5>$D$7,0,E32*Leadsheet!$D96) -> 0 | G33: =IF(G$5>$D$7,0,F32*Leadsheet!$D96) -> 0 | H33: =IF(H$5>$D$7,0,G32*Leadsheet!$D96) -> 0 | I33: =IF(I$5>$D$7,0,H32*Leadsheet!$D96) -> 0 | J33: =IF(J$5>$D$7,0,I32*Leadsheet!$D96) -> 0.33018243 | K33: =IF(K$5>$D$7,0,J32*Leadsheet!$D96) -> 0.27554226 | L33: =IF(L$5>$D$7,0,K32*Leadsheet!$D96) -> 0.23596391 | ... BL33: =IF(BL$5>$D$7,0,BK32*Leadsheet!$D96) -> 0
A34: G4 | B34: 210 | C34: B7 | E34: =IF(E$5>$D$7,0,D33*Leadsheet!$D97) -> 0 | F34: =IF(F$5>$D$7,0,E33*Leadsheet!$D97) -> 0 | G34: =IF(G$5>$D$7,0,F33*Leadsheet!$D97) -> 0 | H34: =IF(H$5>$D$7,0,G33*Leadsheet!$D97) -> 0 | I34: =IF(I$5>$D$7,0,H33*Leadsheet!$D97) -> 0 | J34: =IF(J$5>$D$7,0,I33*Leadsheet!$D97) -> 0 | K34: =IF(K$5>$D$7,0,J33*Leadsheet!$D97) -> 0.33018243 | L34: =IF(L$5>$D$7,0,K33*Leadsheet!$D97) -> 0.27554226 | ... BL34: =IF(BL$5>$D$7,0,BK33*Leadsheet!$D97) -> 0
A35: G4 | B35: 240 | C35: B8 | E35: =IF(E$5>$D$7,0,D34*Leadsheet!$D98) -> 0 | F35: =IF(F$5>$D$7,0,E34*Leadsheet!$D98) -> 0 | G35: =IF(G$5>$D$7,0,F34*Leadsheet!$D98) -> 0 | H35: =IF(H$5>$D$7,0,G34*Leadsheet!$D98) -> 0 | I35: =IF(I$5>$D$7,0,H34*Leadsheet!$D98) -> 0 | J35: =IF(J$5>$D$7,0,I34*Leadsheet!$D98) -> 0 | K35: =IF(K$5>$D$7,0,J34*Leadsheet!$D98) -> 0 | L35: =IF(L$5>$D$7,0,K34*Leadsheet!$D98) -> 0.33018243 | ... BL35: =IF(BL$5>$D$7,0,BK34*Leadsheet!$D98) -> 0
A36: G4 | B36: 270 | C36: B9 | E36: =IF(E$5>$D$7,0,D35*Leadsheet!$D99) -> 0 | F36: =IF(F$5>$D$7,0,E35*Leadsheet!$D99) -> 0 | G36: =IF(G$5>$D$7,0,F35*Leadsheet!$D99) -> 0 | H36: =IF(H$5>$D$7,0,G35*Leadsheet!$D99) -> 0 | I36: =IF(I$5>$D$7,0,H35*Leadsheet!$D99) -> 0 | J36: =IF(J$5>$D$7,0,I35*Leadsheet!$D99) -> 0 | K36: =IF(K$5>$D$7,0,J35*Leadsheet!$D99) -> 0 | L36: =IF(L$5>$D$7,0,K35*Leadsheet!$D99) -> 0 | ... BL36: =IF(BL$5>$D$7,0,BK35*Leadsheet!$D99) -> 0
A37: G4 | B37: 300 | C37: B10 | E37: =IF(E$5>$D$7,0,D36*Leadsheet!$D100) -> 0 | F37: =IF(F$5>$D$7,0,E36*Leadsheet!$D100) -> 0 | G37: =IF(G$5>$D$7,0,F36*Leadsheet!$D100) -> 0 | H37: =IF(H$5>$D$7,0,G36*Leadsheet!$D100) -> 0 | I37: =IF(I$5>$D$7,0,H36*Leadsheet!$D100) -> 0 | J37: =IF(J$5>$D$7,0,I36*Leadsheet!$D100) -> 0 | K37: =IF(K$5>$D$7,0,J36*Leadsheet!$D100) -> 0 | L37: =IF(L$5>$D$7,0,K36*Leadsheet!$D100) -> 0 | ... BL37: =IF(BL$5>$D$7,0,BK36*Leadsheet!$D100) -> 0
A38: G4 | B38: 330 | C38: B11 | E38: =IF(E$5>$D$7,0,D37*Leadsheet!$D101) -> 0 | F38: =IF(F$5>$D$7,0,E37*Leadsheet!$D101) -> 0 | G38: =IF(G$5>$D$7,0,F37*Leadsheet!$D101) -> 0 | H38: =IF(H$5>$D$7,0,G37*Leadsheet!$D101) -> 0 | I38: =IF(I$5>$D$7,0,H37*Leadsheet!$D101) -> 0 | J38: =IF(J$5>$D$7,0,I37*Leadsheet!$D101) -> 0 | K38: =IF(K$5>$D$7,0,J37*Leadsheet!$D101) -> 0 | L38: =IF(L$5>$D$7,0,K37*Leadsheet!$D101) -> 0 | ... BL38: =IF(BL$5>$D$7,0,BK37*Leadsheet!$D101) -> 0
A39: G4 | B39: 360 | C39: B12 | E39: =IF(E$5>$D$7,0,D38*Leadsheet!$D102) -> 0 | F39: =IF(F$5>$D$7,0,E38*Leadsheet!$D102) -> 0 | G39: =IF(G$5>$D$7,0,F38*Leadsheet!$D102) -> 0 | H39: =IF(H$5>$D$7,0,G38*Leadsheet!$D102) -> 0 | I39: =IF(I$5>$D$7,0,H38*Leadsheet!$D102) -> 0 | J39: =IF(J$5>$D$7,0,I38*Leadsheet!$D102) -> 0 | K39: =IF(K$5>$D$7,0,J38*Leadsheet!$D102) -> 0 | L39: =IF(L$5>$D$7,0,K38*Leadsheet!$D102) -> 0 | ... BL39: =IF(BL$5>$D$7,0,BK38*Leadsheet!$D102) -> 0
A40: G5 | B40: 390 | C40: B13 | E40: =IF(E$5>$D$7,0,D39*Leadsheet!$D103) -> 0 | F40: =IF(F$5>$D$7,0,E39*Leadsheet!$D103) -> 0 | G40: =IF(G$5>$D$7,0,F39*Leadsheet!$D103) -> 0 | H40: =IF(H$5>$D$7,0,G39*Leadsheet!$D103) -> 0 | I40: =IF(I$5>$D$7,0,H39*Leadsheet!$D103) -> 0 | J40: =IF(J$5>$D$7,0,I39*Leadsheet!$D103) -> 0 | K40: =IF(K$5>$D$7,0,J39*Leadsheet!$D103) -> 0 | L40: =IF(L$5>$D$7,0,K39*Leadsheet!$D103) -> 0 | ... BL40: =IF(BL$5>$D$7,0,BK39*Leadsheet!$D103) -> 0
A41: G5 | B41: 420+ | C41: B14+ | E41: =IF(E5>$D$7,0,D40+D41) -> 0 | F41: =IF(F5>$D$7,0,E40+E41) -> 0 | G41: =IF(G5>$D$7,0,F40+F41) -> 0 | H41: =IF(H5>$D$7,0,G40+G41) -> 0 | I41: =IF(I5>$D$7,0,H40+H41) -> 0 | J41: =IF(J5>$D$7,0,I40+I41) -> 0 | K41: =IF(K5>$D$7,0,J40+J41) -> 0 | L41: =IF(L5>$D$7,0,K40+K41) -> 0 | ... BL41: =IF(BL5>$D$7,0,BK40+BK41) -> 0
B43: ENR
C44: Total bank | D44: =SUM(D27:D41) -> 14.389345 | E44: =SUM(E27:E41) -> 12.494775 | F44: =SUM(F27:F41) -> 11.027863 | G44: =SUM(G27:G41) -> 9.6613037 | H44: =SUM(H27:H41) -> 8.7768859 | I44: =SUM(I27:I41) -> 7.9257267 | J44: =SUM(J27:J41) -> 7.1088572 | K44: =SUM(K27:K41) -> 6.3267788 | ... BL44: =SUM(BL27:BL41) -> 0
C45: Outstanding balance | D45: {=IF(D5=$D$7,0,_xlfn.IFS(Leadsheet!$G$5="DPD360+",SUM(SAP_Speadsheet!D27:D40),Leadsheet!$G$5="DPD180+",SUM(SAP_Speadsheet!D27:D34)))} -> 14.389345 | E45: {=IF(E5=$D$7,0,_xlfn.IFS(Leadsheet!$G$5="DPD360+",SUM(SAP_Speadsheet!E27:E40),Leadsheet!$G$5="DPD180+",SUM(SAP_Speadsheet!E27:E34)))} -> 12.494775 | F45: {=IF(F5=$D$7,0,_xlfn.IFS(Leadsheet!$G$5="DPD360+",SUM(SAP_Speadsheet!F27:F40),Leadsheet!$G$5="DPD180+",SUM(SAP_Speadsheet!F27:F34)))} -> 11.027863 | G45: {=IF(G5=$D$7,0,_xlfn.IFS(Leadsheet!$G$5="DPD360+",SUM(SAP_Speadsheet!G27:G40),Leadsheet!$G$5="DPD180+",SUM(SAP_Speadsheet!G27:G34)))} -> 9.6613037 | H45: {=IF(H5=$D$7,0,_xlfn.IFS(Leadsheet!$G$5="DPD360+",SUM(SAP_Speadsheet!H27:H40),Leadsheet!$G$5="DPD180+",SUM(SAP_Speadsheet!H27:H34)))} -> 8.7768859 | I45: {=IF(I5=$D$7,0,_xlfn.IFS(Leadsheet!$G$5="DPD360+",SUM(SAP_Speadsheet!I27:I40),Leadsheet!$G$5="DPD180+",SUM(SAP_Speadsheet!I27:I34)))} -> 7.9257267 | J45: {=IF(J5=$D$7,0,_xlfn.IFS(Leadsheet!$G$5="DPD360+",SUM(SAP_Speadsheet!J27:J40),Leadsheet!$G$5="DPD180+",SUM(SAP_Speadsheet!J27:J34)))} -> 7.1088572 | K45: {=IF(K5=$D$7,0,_xlfn.IFS(Leadsheet!$G$5="DPD360+",SUM(SAP_Speadsheet!K27:K40),Leadsheet!$G$5="DPD180+",SUM(SAP_Speadsheet!K27:K34)))} -> 6.3267788 | ... BL45: {=IF(BL5=$D$7,0,_xlfn.IFS(Leadsheet!$G$5="DPD360+",SUM(SAP_Speadsheet!BL27:BL40),Leadsheet!$G$5="DPD180+",SUM(SAP_Speadsheet!BL27:BL34)))} -> 0
C46: Writeoff balance | D46: =D44-D45 -> 0 | E46: =E44-E45 -> 0 | F46: =F44-F45 -> 0 | G46: =G44-G45 -> 0 | H46: =H44-H45 -> 0 | I46: =I44-I45 -> 0 | J46: =J44-J45 -> 0 | K46: =K44-K45 -> 0 | ... BL46: =BL44-BL45 -> 0
C47: Outstanding Bal/TB | D47: =IFERROR(D45/D44,"") -> 1 | E47: =IFERROR(E45/E44,"") -> 1 | F47: =IFERROR(F45/F44,"") -> 1 | G47: =IFERROR(G45/G44,"") -> 1 | H47: =IFERROR(H45/H44,"") -> 1 | I47: =IFERROR(I45/I44,"") -> 1 | J47: =IFERROR(J45/J44,"") -> 1 | K47: =IFERROR(K45/K44,"") -> 1 | ... BL47: =IFERROR(BL45/BL44,"")
B49: ANR
...

Sheet Saleplan&PnL
C1: PROFIT & LOSS 60M
C2: I. | D2: SALES PLAN
C4: Business month | D4: 45658 | E4: =EOMONTH(D4,1) -> 45716 | F4: =EOMONTH(E4,1) -> 45747 | G4: =EOMONTH(F4,1) -> 45777 | H4: =EOMONTH(G4,1) -> 45808 | I4: =EOMONTH(H4,1) -> 45838 | J4: =EOMONTH(I4,1) -> 45869 | K4: =EOMONTH(J4,1) -> 45900 | L4: =EOMONTH(K4,1) -> 45930 | ... BL4: =EOMONTH(BK4,1) -> 47514
C5: Don't delete | D5: =YEAR(D4) -> 2025 | E5: =YEAR(E4) -> 2025 | F5: =YEAR(F4) -> 2025 | G5: =YEAR(G4) -> 2025 | H5: =YEAR(H4) -> 2025 | I5: =YEAR(I4) -> 2025 | J5: =YEAR(J4) -> 2025 | K5: =YEAR(K4) -> 2025 | ... BL5: =YEAR(BL4) -> 2030
C6: New disbursement (bVND) | J6: =DATA!E19/10^9 -> 87.99715 | K6: =DATA!E18/10^9 -> 83.81831 | L6: =DATA!E17/10^9 -> 83.03423
C8: II. | D8: PROFIT & LOSS
C10: FISCAL YEAR | E10: Total | F10: =YEAR(D4) -> 2025 | G10: =F10+1 -> 2026 | H10: =G10+1 -> 2027 | I10: =H10+1 -> 2028 | J10: =I10+1 -> 2029 | K10: =J10+1 -> 2030
E11: bVND | F11: bVND | G11: bVND | H11: bVND | I11: bVND | J11: bVND | K11: bVND
C13: NEW DISBURSAL | E13: =SUM(F13:O13) -> 254.84969 | F13: =SUMIF($D$5:$BL$5,F$10,$D$6:$BL$6) -> 254.84969 | G13: =SUMIF($D$5:$BL$5,G$10,$D$6:$BL$6) -> 0 | H13: =SUMIF($D$5:$BL$5,H$10,$D$6:$BL$6) -> 0 | I13: =SUMIF($D$5:$BL$5,I$10,$D$6:$BL$6) -> 0 | J13: =SUMIF($D$5:$BL$5,J$10,$D$6:$BL$6) -> 0 | K13: =SUMIF($D$5:$BL$5,K$10,$D$6:$BL$6) -> 0
C14: Monthly disbursement | E14: =AVERAGE(D6:AM6) -> 84.949897 | F14: =IFERROR(F13/COUNTIFS($D$5:$BL$5,F10,$D$6:$BL$6,"<>"&""),0) -> 84.949897 | G14: =IFERROR(G13/COUNTIFS($D$5:$BL$5,G10,$D$6:$BL$6,"<>"&""),0) -> 0 | H14: =IFERROR(H13/COUNTIFS($D$5:$BL$5,H10,$D$6:$BL$6,"<>"&""),0) -> 0 | I14: =IFERROR(I13/COUNTIFS($D$5:$BL$5,I10,$D$6:$BL$6,"<>"&""),0) -> 0 | J14: =IFERROR(J13/COUNTIFS($D$5:$BL$5,J10,$D$6:$BL$6,"<>"&""),0) -> 0 | K14: =IFERROR(K13/COUNTIFS($D$5:$BL$5,K10,$D$6:$BL$6,"<>"&""),0) -> 0
C16: EOP | F16: =OFFSET(PnL_Speadsheet!$A$7,0,MATCH(DATE('Saleplan&PnL'!F$10,12,31),PnL_Speadsheet!$B$4:$BI$4,0))/1000 -> 140.28943 | G16: =OFFSET(PnL_Speadsheet!$A$7,0,MATCH(DATE('Saleplan&PnL'!G$10,12,31),PnL_Speadsheet!$B$4:$BI$4,0))/1000 -> 33.636463 | H16: =OFFSET(PnL_Speadsheet!$A$7,0,MATCH(DATE('Saleplan&PnL'!H$10,12,31),PnL_Speadsheet!$B$4:$BI$4,0))/1000 -> 0 | I16: =OFFSET(PnL_Speadsheet!$A$7,0,MATCH(DATE('Saleplan&PnL'!I$10,12,31),PnL_Speadsheet!$B$4:$BI$4,0))/1000 -> 0 | J16: =OFFSET(PnL_Speadsheet!$A$7,0,MATCH(DATE('Saleplan&PnL'!J$10,12,31),PnL_Speadsheet!$B$4:$BI$4,0))/1000 -> 0 | K16: =IFERROR(OFFSET(PnL_Speadsheet!$A$7,0,MATCH(DATE('Saleplan&PnL'!K$10,12,31),PnL_Speadsheet!$B$4:$BI$4,0))/1000,0) -> 0
C17: ADB | E17: =IFERROR(SUM(PnL_Speadsheet!B8:AK8)/1000/COUNTIF(PnL_Speadsheet!B8:BI8,"<>0"),0) -> 72.315381 | F17: =IFERROR(SUMIF(PnL_Speadsheet!$B$3:$BI$3,F$10,PnL_Speadsheet!$B8:$BI8)/1000/COUNTIFS(PnL_Speadsheet!$B$3:$BI$3,'Saleplan&PnL'!F$10,PnL_Speadsheet!$B$8:$BI$8,"<>0"),0) -> 156.42537 | G17: =IFERROR(SUMIF(PnL_Speadsheet!$B$3:$BI$3,G$10,PnL_Speadsheet!$B8:$BI8)/1000/COUNTIFS(PnL_Speadsheet!$B$3:$BI$3,'Saleplan&PnL'!G$10,PnL_Speadsheet!$B$8:$BI$8,"<>0"),0) -> 54.076986 | H17: =IFERROR(SUMIF(PnL_Speadsheet!$B$3:$BI$3,H$10,PnL_Speadsheet!$B8:$BI8)/1000/COUNTIFS(PnL_Speadsheet!$B$3:$BI$3,'Saleplan&PnL'!H$10,PnL_Speadsheet!$B$8:$BI$8,"<>0"),0) -> 0.86558657 | I17: =IFERROR(SUMIF(PnL_Speadsheet!$B$3:$BI$3,I$10,PnL_Speadsheet!$B8:$BI8)/1000/COUNTIFS(PnL_Speadsheet!$B$3:$BI$3,'Saleplan&PnL'!I$10,PnL_Speadsheet!$B$8:$BI$8,"<>0"),0) -> 0 | J17: =IFERROR(SUMIF(PnL_Speadsheet!$B$3:$BI$3,J$10,PnL_Speadsheet!$B8:$BI8)/1000/COUNTIFS(PnL_Speadsheet!$B$3:$BI$3,'Saleplan&PnL'!J$10,PnL_Speadsheet!$B$8:$BI$8,"<>0"),0) -> 0 | K17: =IFERROR(SUMIF(PnL_Speadsheet!$B$3:$BI$3,K$10,PnL_Speadsheet!$B8:$BI8)/1000/COUNTIFS(PnL_Speadsheet!$B$3:$BI$3,'Saleplan&PnL'!K$10,PnL_Speadsheet!$B$8:$BI$8,"<>0"),0) -> 0
C19: TOI | E19: =SUM(F19:O19) -> 61.937895 | F19: =SUMIF(PnL_Speadsheet!$B$3:$BI$3,F$10,PnL_Speadsheet!$B9:$BI9)/1000 -> 42.744901 | G19: =SUMIF(PnL_Speadsheet!$B$3:$BI$3,G$10,PnL_Speadsheet!$B9:$BI9)/1000 -> 19.2133 | H19: =SUMIF(PnL_Speadsheet!$B$3:$BI$3,H$10,PnL_Speadsheet!$B9:$BI9)/1000 -> -0.020306113 | I19: =SUMIF(PnL_Speadsheet!$B$3:$BI$3,I$10,PnL_Speadsheet!$B9:$BI9)/1000 -> 0 | J19: =SUMIF(PnL_Speadsheet!$B$3:$BI$3,J$10,PnL_Speadsheet!$B9:$BI9)/1000 -> 0 | K19: =SUMIF(PnL_Speadsheet!$B$3:$BI$3,K$10,PnL_Speadsheet!$B9:$BI9)/1000 -> 0
C20: NII | E20: =SUM(F20:O20) -> 52.529312 | F20: =SUMIF(PnL_Speadsheet!$B$3:$BI$3,F$10,PnL_Speadsheet!$B11:$BI11)/1000 -> 33.904078 | G20: =SUMIF(PnL_Speadsheet!$B$3:$BI$3,G$10,PnL_Speadsheet!$B11:$BI11)/1000 -> 18.64554 | H20: =SUMIF(PnL_Speadsheet!$B$3:$BI$3,H$10,PnL_Speadsheet!$B11:$BI11)/1000 -> -0.020306113 | I20: =SUMIF(PnL_Speadsheet!$B$3:$BI$3,I$10,PnL_Speadsheet!$B11:$BI11)/1000 -> 0 | J20: =SUMIF(PnL_Speadsheet!$B$3:$BI$3,J$10,PnL_Speadsheet!$B11:$BI11)/1000 -> 0 | K20: =SUMIF(PnL_Speadsheet!$B$3:$BI$3,K$10,PnL_Speadsheet!$B11:$BI11)/1000 -> 0
C21: NFI | E21: =SUM(F21:O21) -> 9.408583 | F21: =SUMIF(PnL_Speadsheet!$B$3:$BI$3,F$10,PnL_Speadsheet!$B14:$BI14)/1000 -> 8.8408229 | G21: =SUMIF(PnL_Speadsheet!$B$3:$BI$3,G$10,PnL_Speadsheet!$B14:$BI14)/1000 -> 0.56776011 | H21: =SUMIF(PnL_Speadsheet!$B$3:$BI$3,H$10,PnL_Speadsheet!$B14:$BI14)/1000 -> 0 | I21: =SUMIF(PnL_Speadsheet!$B$3:$BI$3,I$10,PnL_Speadsheet!$B14:$BI14)/1000 -> 0 | J21: =SUMIF(PnL_Speadsheet!$B$3:$BI$3,J$10,PnL_Speadsheet!$B14:$BI14)/1000 -> 0 | K21: =SUMIF(PnL_Speadsheet!$B$3:$BI$3,K$10,PnL_Speadsheet!$B14:$BI14)/1000 -> 0
C22: Other TOI | E22: =SUM(F22:O22) -> 0 | F22: =SUMIF(PnL_Speadsheet!$B$3:$BI$3,F$10,PnL_Speadsheet!$B18:$BI18)/1000 -> 0 | G22: =SUMIF(PnL_Speadsheet!$B$3:$BI$3,G$10,PnL_Speadsheet!$B18:$BI18)/1000 -> 0 | H22: =SUMIF(PnL_Speadsheet!$B$3:$BI$3,H$10,PnL_Speadsheet!$B18:$BI18)/1000 -> 0 | I22: =SUMIF(PnL_Speadsheet!$B$3:$BI$3,I$10,PnL_Speadsheet!$B18:$BI18)/1000 -> 0 | J22: =SUMIF(PnL_Speadsheet!$B$3:$BI$3,J$10,PnL_Speadsheet!$B18:$BI18)/1000 -> 0 | K22: =SUMIF(PnL_Speadsheet!$B$3:$BI$3,K$10,PnL_Speadsheet!$B18:$BI18)/1000 -> 0
C23: PROVISION | E23: =SUM(F23:O23) -> -32.491406 | F23: =SUMIF(PnL_Speadsheet!$B$3:$BI$3,F$10,PnL_Speadsheet!$B31:$BI31)/1000 -> -22.502491 | G23: =SUMIF(PnL_Speadsheet!$B$3:$BI$3,G$10,PnL_Speadsheet!$B31:$BI31)/1000 -> -9.7888724 | H23: =SUMIF(PnL_Speadsheet!$B$3:$BI$3,H$10,PnL_Speadsheet!$B31:$BI31)/1000 -> -0.20004279 | I23: =SUMIF(PnL_Speadsheet!$B$3:$BI$3,I$10,PnL_Speadsheet!$B31:$BI31)/1000 -> 0 | J23: =SUMIF(PnL_Speadsheet!$B$3:$BI$3,J$10,PnL_Speadsheet!$B31:$BI31)/1000 -> 0 | K23: =SUMIF(PnL_Speadsheet!$B$3:$BI$3,K$10,PnL_Speadsheet!$B31:$BI31)/1000 -> 0
C24: OPEX | E24: =SUM(F24:O24) -> -17.6117 | F24: =SUMIF(PnL_Speadsheet!$B$3:$BI$3,F$10,PnL_Speadsheet!$B19:$BI19)/1000 -> -11.48628 | G24: =SUMIF(PnL_Speadsheet!$B$3:$BI$3,G$10,PnL_Speadsheet!$B19:$BI19)/1000 -> -6.0677319 | H24: =SUMIF(PnL_Speadsheet!$B$3:$BI$3,H$10,PnL_Speadsheet!$B19:$BI19)/1000 -> -0.057688203 | I24: =SUMIF(PnL_Speadsheet!$B$3:$BI$3,I$10,PnL_Speadsheet!$B19:$BI19)/1000 -> 0 | J24: =SUMIF(PnL_Speadsheet!$B$3:$BI$3,J$10,PnL_Speadsheet!$B19:$BI19)/1000 -> 0 | K24: =SUMIF(PnL_Speadsheet!$B$3:$BI$3,K$10,PnL_Speadsheet!$B19:$BI19)/1000 -> 0
C25: Sales incentives | E25: =SUM(F25:O25) -> -6.3712422 | F25: =(SUMIF(PnL_Speadsheet!$B$3:$BI$3,F$10,PnL_Speadsheet!$B21:$BI22)/1000+SUMIF(PnL_Speadsheet!$B$3:$BI$3,F$10,PnL_Speadsheet!$B22:$BI22)/1000) -> -6.3712422 | G25: =(SUMIF(PnL_Speadsheet!$B$3:$BI$3,G$10,PnL_Speadsheet!$B21:$BI22)/1000+SUMIF(PnL_Speadsheet!$B$3:$BI$3,G$10,PnL_Speadsheet!$B22:$BI22)/1000) -> 0 | H25: =(SUMIF(PnL_Speadsheet!$B$3:$BI$3,H$10,PnL_Speadsheet!$B21:$BI22)/1000+SUMIF(PnL_Speadsheet!$B$3:$BI$3,H$10,PnL_Speadsheet!$B22:$BI22)/1000) -> 0 | I25: =(SUMIF(PnL_Speadsheet!$B$3:$BI$3,I$10,PnL_Speadsheet!$B21:$BI22)/1000+SUMIF(PnL_Speadsheet!$B$3:$BI$3,I$10,PnL_Speadsheet!$B22:$BI22)/1000) -> 0 | J25: =(SUMIF(PnL_Speadsheet!$B$3:$BI$3,J$10,PnL_Speadsheet!$B21:$BI22)/1000+SUMIF(PnL_Speadsheet!$B$3:$BI$3,J$10,PnL_Speadsheet!$B22:$BI22)/1000) -> 0 | K25: =(SUMIF(PnL_Speadsheet!$B$3:$BI$3,K$10,PnL_Speadsheet!$B21:$BI22)/1000+SUMIF(PnL_Speadsheet!$B$3:$BI$3,K$10,PnL_Speadsheet!$B22:$BI22)/1000) -> 0
C26: Marketing | E26: =SUM(F26:O26) -> 0 | F26: =SUMIF(PnL_Speadsheet!$B$3:$BI$3,F$10,PnL_Speadsheet!$B23:$BI23)/1000 -> 0 | G26: =SUMIF(PnL_Speadsheet!$B$3:$BI$3,G$10,PnL_Speadsheet!$B23:$BI23)/1000 -> 0 | H26: =SUMIF(PnL_Speadsheet!$B$3:$BI$3,H$10,PnL_Speadsheet!$B23:$BI23)/1000 -> 0 | I26: =SUMIF(PnL_Speadsheet!$B$3:$BI$3,I$10,PnL_Speadsheet!$B23:$BI23)/1000 -> 0 | J26: =SUMIF(PnL_Speadsheet!$B$3:$BI$3,J$10,PnL_Speadsheet!$B23:$BI23)/1000 -> 0 | K26: =SUMIF(PnL_Speadsheet!$B$3:$BI$3,K$10,PnL_Speadsheet!$B23:$BI23)/1000 -> 0
C27: UW & Disbursal | E27: =SUM(F27:O27) -> -0.67653176 | F27: =SUMIF(PnL_Speadsheet!$B$3:$BI$3,F$10,PnL_Speadsheet!$B24:$BI24)/1000 -> -0.67653176 | G27: =SUMIF(PnL_Speadsheet!$B$3:$BI$3,G$10,PnL_Speadsheet!$B24:$BI24)/1000 -> 0 | H27: =SUMIF(PnL_Speadsheet!$B$3:$BI$3,H$10,PnL_Speadsheet!$B24:$BI24)/1000 -> 0 | I27: =SUMIF(PnL_Speadsheet!$B$3:$BI$3,I$10,PnL_Speadsheet!$B24:$BI24)/1000 -> 0 | J27: =SUMIF(PnL_Speadsheet!$B$3:$BI$3,J$10,PnL_Speadsheet!$B24:$BI24)/1000 -> 0 | K27: =SUMIF(PnL_Speadsheet!$B$3:$BI$3,K$10,PnL_Speadsheet!$B24:$BI24)/1000 -> 0
C28: Collection & AMC | E28: =SUM(F28:O28) -> -1.5706172 | F28: =SUMIF(PnL_Speadsheet!$B$3:$BI$3,F$10,PnL_Speadsheet!$B28:$BI28)/1000 -> -0.61796104 | G28: =SUMIF(PnL_Speadsheet!$B$3:$BI$3,G$10,PnL_Speadsheet!$B28:$BI28)/1000 -> -0.89496798 | H28: =SUMIF(PnL_Speadsheet!$B$3:$BI$3,H$10,PnL_Speadsheet!$B28:$BI28)/1000 -> -0.057688203 | I28: =SUMIF(PnL_Speadsheet!$B$3:$BI$3,I$10,PnL_Speadsheet!$B28:$BI28)/1000 -> 0 | J28: =SUMIF(PnL_Speadsheet!$B$3:$BI$3,J$10,PnL_Speadsheet!$B28:$BI28)/1000 -> 0 | K28: =SUMIF(PnL_Speadsheet!$B$3:$BI$3,K$10,PnL_Speadsheet!$B28:$BI28)/1000 -> 0
