Workbook
Name __S1: {"Book1"}
Name __S1: {"Book1"}
Name __S1: {"Book1"}
Name _a1: {"'Sheet1'!$L$16"}
Name _a1: {"'Sheet1'!$L$16"}
Name _a1: {"'Sheet1'!$L$16"}
Name _S1: {"Book1"}
Name _S1: {"Book1"}
Name _S1: {"Book1"}
Name Ă: #REF!
Name Ạ196: #REF!
Name â259: #REF!
Name â259: #REF!
Name â312: #REF!
Name â312: #REF!
Name Acquisition_PlanA: #REF!
Name Acquisition_PlanB: #REF!
Name Actual: (PeriodInActual*(#REF!>0))*PeriodInPlan
Name Actual: (PeriodInActual*(#REF!>0))*PeriodInPlan
Name ActualBeyond: PeriodInActual*(#REF!>0)
Name ActualBeyond: PeriodInActual*(#REF!>0)
Name adf: #REF!
Name adf: #REF!
Name adf: #REF!
Name AdvIncQ12020: #REF!
Name AdvIncQ12020: #REF!
Name AdvIncQ12021: #REF!
Name AdvIncQ12021: #REF!
Name AdvIncQ12022: #REF!
Name AdvIncQ12022: #REF!
Name AdvIncQ12023: #REF!
Name AdvIncQ12023: #REF!
Name AdvIncQ12024: #REF!
Name AdvIncQ12024: #REF!
Name AdvIncQ22020: #REF!
Name AdvIncQ22020: #REF!
Name AdvIncQ22021: #REF!
Name AdvIncQ22021: #REF!
Name AdvIncQ22022: #REF!
Name AdvIncQ22022: #REF!
Name AdvIncQ22023: #REF!
Name AdvIncQ22023: #REF!
Name AdvIncQ22024: #REF!
Name AdvIncQ22024: #REF!
Name AdvIncQ32020: #REF!
Name AdvIncQ32020: #REF!
Name AdvIncQ32021: #REF!
Name AdvIncQ32021: #REF!
Name AdvIncQ32022: #REF!
Name AdvIncQ32022: #REF!
Name AdvIncQ32023: #REF!
Name AdvIncQ32023: #REF!
Name AdvIncQ32024: #REF!
Name AdvIncQ32024: #REF!
Name AdvIncQ42020: #REF!
Name AdvIncQ42020: #REF!
Name AdvIncQ42021: #REF!
Name AdvIncQ42021: #REF!
Name AdvIncQ42022: #REF!
Name AdvIncQ42022: #REF!

Sheet NOTE
A1: SAP MODEL - PAYLATER
N2: KHN | O2: v10 | P2: 20251201
B3: 1. Notes and disclaimer
C4: a. Giới thiệu về SAP
D5: - SAP: Single Account Profitability (Hiệu quả sản phẩm trên từng đơn vị sản phẩm)
D6: - Model SAP được sử dụng như 1 mô hình dự đoán hiệu quả vòng đời của sản phẩm.
D7: - Do sự phức tạp của sản phẩm, các hệ thống vận hành (hệ thống hạch kế toán, hệ thống quản trị rủi ro, hệ thống quản trị…), hành vi người sử dụng hành vi người sử dụng, model chỉ có thể mô phỏng tương đối trung bình vòng đời của sản phẩm.
D8: - Mô hình được tính toán dựa vào các yếu tố đầu vào xác định tại thời điểm, do đó kết quả của mô hình có thể có sự khác biệt so với thực tế vận hành sản phẩm.
D9: - Mô hình SAP Paylater tính hiệu quả của 1 thẻ mở và được cutoff tối đa tại thời điểm 5 năm ( 60 tháng) kể từ ngày bắt đầu sản phẩm
E10: - Trường hợp sử dụng phương pháp tính dự phòng VAS, cần ghi nhận thêm chi phí dự phòng năm thứ 6 liên quan tới hiệu quả sản phẩm thẻ 5 năm.
E11: - Trường hợp sử dụng phương pháp tính dự phòng VAS, cần ghi nhận thêm chi phí dự phòng năm thứ 4 liên quan tới hiệu quả sản phẩm thẻ 3 năm.
C13: b. Giới thiệu về PnL
D14: - Trong file tính này, Profit & Lost (PnL) được dự phóng từ trung bình cộng kết quả kinh doanh trên từng sản phẩm (SAP) với yếu tố "sale plan" (số thẻ mở mới) qua từng tháng, do đó có thể khác biệt so với kết quả thực tế vận hành.
D15: - Dòng tiền thực tế qua từng tháng có thể khác biệt với mô hình tính toán do nhiều yếu tố tác động bên ngoài thay đổi, do đó, vui lòng chỉ sử dụng mô hình cho mục đích tham khảo.
D16: - Cho mục đích tính dự phòng dòng tiền ngắn và trung hạn, mô hình PnL được cutoff tại thời điểm 5 năm (60 tháng) kể từ ngày bắt đầu khởi chạy sản phẩm đầu tiên.
B18: 2. Instruction
D19: - Dành cho người sử dụng
E20: - Chỉ chỉnh sửa vào các ô màu vàng
E21: - 2 sheets "SAP_Leadsheet" và "Sale plan&PL" cung cấp yếu tố đầu vào và đầu ra để tính toán mô hình SAP cũng như PnL.
F22: - Sheet SAP_Leadsheet được cấu trúc 2 phần, bên trái là các yếu tố đầu vào (input) và bên phải là kết quả dự đoán (output). Đơn vị sử dụng tại bảng tính là triệu VND (mVND) và phần trăm (%)
F23: - Sheet "Sale plan & PL" được cấu trúc 2 phần, bên trên là sale plan và bên dưới là kết quả PnL
E24: - 2 sheets "SAP_Spreadsheet" và "PL projection speadsheet" là các file tính toán cho 2 sheet "SAP_Leadsheet", "Sales plan & PL"
F25: - 2 sheets được cấu trúc từ trên xuống dưới theo thứ tự tính toán mô phỏng để đưa ra kết quả kinh doanh cuối cùng
F26: - 2 sheets đã được tạm khóa. Trường hợp cần mở khóa, điều chỉnh các yếu tố, vui lòng liên hệ với nhóm vận hành để được hỗ trợ.
D28: - Dành riêng cho người vận hành, hiệu chỉnh
E29: - Cần cẩn trọng khi điều chỉnh ở các file "speadsheet" vì 1 khi sai lệch rất khó tìm ra lỗi (VD: sửa nhầm ô, link nhầm vị trí,…)
B32: 3. Legend
C34: REVENUE INPUT
C36: Card Status
D37: Activate at beginning | E37: Tỉ lệ active thẻ tại thời điểm tháng 1 | G37: Tỉ lệ active được tính là khách hàng có spending và/hoặc có outstanding balance
D38: Average attrition rate | E38: Tỉ lệ giảm active qua từng thàng | G38: Lấy trung bình tỉ lệ giảm active thẻ của các tháng (tính theo cohort)
C40: Term of using
D41: Tenor | E41: Thời hạn tài khoản
D42: Due date | E42: Ngày tới thời hạn miễn lãi
D43: Free-interest period | E43: Thời gian được miễn lãi (VD 45-55 ngày)
C45: Usage Status
D46: Spd / active card | E46: Tổng chi tiêu tiêu tháng/số thẻ active
C48: Payment status
D49: Port Revolving rate | E49: Tỉ lệ chuyển đổi dư nợ (được tính là %/ANR tháng trước)
D50: Repayment rate | E50: Tỉ lệ thanh toán dư nợ (được tính %/ANR tháng trước)
...

Sheet DATA
B1: =C1&"_"&D1 -> All_Q1 | C1: =SAP_Leadsheet!C8 -> All | D1: =SAP_Leadsheet!C11 -> Q1
B2: Mapping | C2: Value | F2: All_Q1 | G2: MWG_Q1 | H2: VNPAY_Q1 | I2: BE_Q1 | J2: VDS_Q1
A3: Activate at beginning | B3: Active at beginning | C3: =INDEX($E$44:$AJ$53,MATCH($B$1,$E$44:$E$53,0),MATCH($B3,$E$44:$AJ$44,0)) -> 0.6392418 | E3: Spending | F3: =INDEX($E$44:$AJ$53,MATCH(F$2,$E$44:$E$53,0),MATCH($E3,$E$44:$AJ$44,0)) -> 1.0580627 | G3: =INDEX($E$44:$AJ$53,MATCH(G$2,$E$44:$E$53,0),MATCH($E3,$E$44:$AJ$44,0)) -> 1.6779288 | H3: =INDEX($E$44:$AJ$53,MATCH(H$2,$E$44:$E$53,0),MATCH($E3,$E$44:$AJ$44,0)) -> 0.9657573 | I3: =INDEX($E$44:$AJ$53,MATCH(I$2,$E$44:$E$53,0),MATCH($E3,$E$44:$AJ$44,0)) -> 0.43001421 | J3: =INDEX($E$44:$AJ$53,MATCH(J$2,$E$44:$E$53,0),MATCH($E3,$E$44:$AJ$44,0)) -> 0.52334755
A4: Spd / activate card | B4: Spending | C4: =INDEX($E$44:$AJ$53,MATCH($B$1,$E$44:$E$53,0),MATCH($B4,$E$44:$AJ$44,0)) -> 1.0580627 | E4: IR | F4: =INDEX($E$44:$AJ$53,MATCH(F$2,$E$44:$E$53,0),MATCH($E4,$E$44:$AJ$44,0)) -> 0.47795381 | G4: =INDEX($E$44:$AJ$53,MATCH(G$2,$E$44:$E$53,0),MATCH($E4,$E$44:$AJ$44,0)) -> 0.55 | H4: =INDEX($E$44:$AJ$53,MATCH(H$2,$E$44:$E$53,0),MATCH($E4,$E$44:$AJ$44,0)) -> 0.39 | I4: =INDEX($E$44:$AJ$53,MATCH(I$2,$E$44:$E$53,0),MATCH($E4,$E$44:$AJ$44,0)) -> 0.4 | J4: =INDEX($E$44:$AJ$53,MATCH(J$2,$E$44:$E$53,0),MATCH($E4,$E$44:$AJ$44,0)) -> 0.39
A5: Port Revolving rate | B5: % revolving | C5: =INDEX($E$44:$AJ$53,MATCH($B$1,$E$44:$E$53,0),MATCH($B5,$E$44:$AJ$44,0)) -> 0.69849829 | E5: COF | F5: =INDEX($E$44:$AJ$53,MATCH(F$2,$E$44:$E$53,0),MATCH($E5,$E$44:$AJ$44,0)) -> 0.069938802 | G5: =INDEX($E$44:$AJ$53,MATCH(G$2,$E$44:$E$53,0),MATCH($E5,$E$44:$AJ$44,0)) -> 0.069920144 | H5: =INDEX($E$44:$AJ$53,MATCH(H$2,$E$44:$E$53,0),MATCH($E5,$E$44:$AJ$44,0)) -> 0.069959036 | I5: =INDEX($E$44:$AJ$53,MATCH(I$2,$E$44:$E$53,0),MATCH($E5,$E$44:$AJ$44,0)) -> 0.06995507 | J5: =INDEX($E$44:$AJ$53,MATCH(J$2,$E$44:$E$53,0),MATCH($E5,$E$44:$AJ$44,0)) -> 0.069963269
A6: Payment rate | B6: % repayment | C6: =INDEX($E$44:$AJ$53,MATCH($B$1,$E$44:$E$53,0),MATCH($B6,$E$44:$AJ$44,0)) -> 0.36991535 | E6: Monthly fee (Subscription fee) | F6: =INDEX($E$44:$AJ$53,MATCH(F$2,$E$44:$E$53,0),MATCH($E6,$E$44:$AJ$44,0)) -> 0.0275 | G6: =INDEX($E$44:$AJ$53,MATCH(G$2,$E$44:$E$53,0),MATCH($E6,$E$44:$AJ$44,0)) -> 0.02 | H6: =INDEX($E$44:$AJ$53,MATCH(H$2,$E$44:$E$53,0),MATCH($E6,$E$44:$AJ$44,0)) -> 0.03 | I6: =INDEX($E$44:$AJ$53,MATCH(I$2,$E$44:$E$53,0),MATCH($E6,$E$44:$AJ$44,0)) -> 0.03 | J6: =INDEX($E$44:$AJ$53,MATCH(J$2,$E$44:$E$53,0),MATCH($E6,$E$44:$AJ$44,0)) -> 0.03
A7: IR | B7: IR | C7: =INDEX($E$44:$AJ$53,MATCH($B$1,$E$44:$E$53,0),MATCH($B7,$E$44:$AJ$44,0)) -> 0.47795381 | E7: % revolving | F7: =INDEX($E$44:$AJ$53,MATCH(F$2,$E$44:$E$53,0),MATCH($E7,$E$44:$AJ$44,0)) -> 0.69849829 | G7: =INDEX($E$44:$AJ$53,MATCH(G$2,$E$44:$E$53,0),MATCH($E7,$E$44:$AJ$44,0)) -> 0.77837592 | H7: =INDEX($E$44:$AJ$53,MATCH(H$2,$E$44:$E$53,0),MATCH($E7,$E$44:$AJ$44,0)) -> 0.68524609 | I7: =INDEX($E$44:$AJ$53,MATCH(I$2,$E$44:$E$53,0),MATCH($E7,$E$44:$AJ$44,0)) -> 0.71313914 | J7: =INDEX($E$44:$AJ$53,MATCH(J$2,$E$44:$E$53,0),MATCH($E7,$E$44:$AJ$44,0)) -> 0.7232694
A8: COF | B8: COF | C8: =INDEX($E$44:$AJ$53,MATCH($B$1,$E$44:$E$53,0),MATCH($B8,$E$44:$AJ$44,0)) -> 0.069938802 | E8: Active at beginning | F8: =INDEX($E$44:$AJ$53,MATCH(F$2,$E$44:$E$53,0),MATCH($E8,$E$44:$AJ$44,0)) -> 0.6392418 | G8: =INDEX($E$44:$AJ$53,MATCH(G$2,$E$44:$E$53,0),MATCH($E8,$E$44:$AJ$44,0)) -> 0.73403333 | H8: =INDEX($E$44:$AJ$53,MATCH(H$2,$E$44:$E$53,0),MATCH($E8,$E$44:$AJ$44,0)) -> 0.67973333 | I8: =INDEX($E$44:$AJ$53,MATCH(I$2,$E$44:$E$53,0),MATCH($E8,$E$44:$AJ$44,0)) -> 0.76776667 | J8: =INDEX($E$44:$AJ$53,MATCH(J$2,$E$44:$E$53,0),MATCH($E8,$E$44:$AJ$44,0)) -> 0.51063333
A9: Monthly fee (Subscription fee) | B9: Monthly fee (Subscription fee) | C9: =INDEX($E$44:$AJ$53,MATCH($B$1,$E$44:$E$53,0),MATCH($B9,$E$44:$AJ$44,0)) -> 0.0275 | E9: Active Month 4 | F9: =F8-F18*3 -> 0.60615117 | G9: =G8-G18*3 -> 0.68223167 | H9: =H8-H18*3 -> 0.64317708 | I9: =I8-I18*3 -> 0.715925 | J9: =J8-J18*3 -> 0.49795833
A10: Late payment penalty (fee) | B10: Late payment penalty (fee) | C10: =INDEX($E$44:$AJ$53,MATCH($B$1,$E$44:$E$53,0),MATCH($B10,$E$44:$AJ$44,0)) -> 0.072785593 | E10: %Installment | F10: =SUM(F11:F13) -> 0.34727685 | G10: =SUM(G11:G13) -> 0.59915944 | H10: =SUM(H11:H13) -> 0.017235754 | I10: =SUM(I11:I13) -> 0.062170492 | J10: =SUM(J11:J13) -> 0
A11: Spending promotion | B11: Promotion | C11: =INDEX($E$44:$AJ$53,MATCH($B$1,$E$44:$E$53,0),MATCH($B11,$E$44:$AJ$44,0)) -> 0.0045099003 | E11: Subvention | F11: =INDEX($E$44:$AJ$53,MATCH(F$2,$E$44:$E$53,0),MATCH($E11,$E$44:$AJ$44,0)) -> 0.29616921 | G11: =INDEX($E$44:$AJ$53,MATCH(G$2,$E$44:$E$53,0),MATCH($E11,$E$44:$AJ$44,0)) -> 0.52936116 | H11: =INDEX($E$44:$AJ$53,MATCH(H$2,$E$44:$E$53,0),MATCH($E11,$E$44:$AJ$44,0)) -> 0 | I11: =INDEX($E$44:$AJ$53,MATCH(I$2,$E$44:$E$53,0),MATCH($E11,$E$44:$AJ$44,0)) -> 0 | J11: =INDEX($E$44:$AJ$53,MATCH(J$2,$E$44:$E$53,0),MATCH($E11,$E$44:$AJ$44,0)) -> 0
A12: Marketing cost | B12: MKT | C12: =INDEX($E$44:$AJ$53,MATCH($B$1,$E$44:$E$53,0),MATCH($B12,$E$44:$AJ$44,0)) -> 0 | E12: Monthly fee | F12: =INDEX($E$44:$AJ$53,MATCH(F$2,$E$44:$E$53,0),MATCH($E12,$E$44:$AJ$44,0)) -> 0.04851372 | G12: =INDEX($E$44:$AJ$53,MATCH(G$2,$E$44:$E$53,0),MATCH($E12,$E$44:$AJ$44,0)) -> 0.06671633 | H12: =INDEX($E$44:$AJ$53,MATCH(H$2,$E$44:$E$53,0),MATCH($E12,$E$44:$AJ$44,0)) -> 0.012915199 | I12: =INDEX($E$44:$AJ$53,MATCH(I$2,$E$44:$E$53,0),MATCH($E12,$E$44:$AJ$44,0)) -> 0.062170492 | J12: =INDEX($E$44:$AJ$53,MATCH(J$2,$E$44:$E$53,0),MATCH($E12,$E$44:$AJ$44,0)) -> 0
A13: Underwriting cost & Score | B13: UW | C13: =INDEX($E$44:$AJ$53,MATCH($B$1,$E$44:$E$53,0),MATCH($B13,$E$44:$AJ$44,0)) -> 0.065146706 | E13: No fee | F13: =INDEX($E$44:$AJ$53,MATCH(F$2,$E$44:$E$53,0),MATCH($E13,$E$44:$AJ$44,0)) -> 0.0025939226 | G13: =INDEX($E$44:$AJ$53,MATCH(G$2,$E$44:$E$53,0),MATCH($E13,$E$44:$AJ$44,0)) -> 0.0030819445 | H13: =INDEX($E$44:$AJ$53,MATCH(H$2,$E$44:$E$53,0),MATCH($E13,$E$44:$AJ$44,0)) -> 0.0043205554 | I13: =INDEX($E$44:$AJ$53,MATCH(I$2,$E$44:$E$53,0),MATCH($E13,$E$44:$AJ$44,0)) -> 0 | J13: =INDEX($E$44:$AJ$53,MATCH(J$2,$E$44:$E$53,0),MATCH($E13,$E$44:$AJ$44,0)) -> 0
A14: Approval rate | B14: Approval rate | C14: =INDEX($E$44:$AJ$53,MATCH($B$1,$E$44:$E$53,0),MATCH($B14,$E$44:$AJ$44,0)) -> 0.267
A15: Disbursement rate | B15: Disbursement rate | C15: =INDEX($E$44:$AJ$53,MATCH($B$1,$E$44:$E$53,0),MATCH($B15,$E$44:$AJ$44,0)) -> 0.795
A16: Disbursement cost | B16: Disburse cost | C16: =INDEX($E$44:$AJ$53,MATCH($B$1,$E$44:$E$53,0),MATCH($B16,$E$44:$AJ$44,0)) -> 0.0026777105
A17: Collections_all | B17: Collection | C17: =INDEX($E$44:$AJ$53,MATCH($B$1,$E$44:$E$53,0),MATCH($B17,$E$44:$AJ$44,0)) -> 0.0049936505 | E17: Attrition rate | F17: All_Q1 | G17: MWG_Q1 | H17: VNPAY_Q1 | I17: BE_Q1 | J17: VDS_Q1
A18: Email & SMS | B18: SMS | C18: =INDEX($E$44:$AJ$53,MATCH($B$1,$E$44:$E$53,0),MATCH($B18,$E$44:$AJ$44,0)) -> 0.0037145494 | E18: Year 1 | F18: =INDEX($E$44:$L$49,MATCH(F$17,$E$44:$E$49,0),MATCH($E18,$E$44:$L$44,0)) -> 0.011030208 | G18: =INDEX($E$44:$L$49,MATCH(G$17,$E$44:$E$49,0),MATCH($E18,$E$44:$L$44,0)) -> 0.017267222 | H18: =INDEX($E$44:$L$49,MATCH(H$17,$E$44:$E$49,0),MATCH($E18,$E$44:$L$44,0)) -> 0.012185417 | I18: =INDEX($E$44:$L$49,MATCH(I$17,$E$44:$E$49,0),MATCH($E18,$E$44:$L$44,0)) -> 0.017280556 | J18: =INDEX($E$44:$L$49,MATCH(J$17,$E$44:$E$49,0),MATCH($E18,$E$44:$L$44,0)) -> 0.004225
A19: Direct HR | B19: Direct HR cost | C19: =INDEX($AR$44:$AV$48,MATCH($B19,$AR$44:$AR$48,0),MATCH($D$1,$AR$44:$AV$44,0)) -> 0.002
A20: Indirect HR | B20: Indirect HR cost | C20: =INDEX($AR$44:$AV$48,MATCH($B20,$AR$44:$AR$48,0),MATCH($D$1,$AR$44:$AV$44,0)) -> 0.00063414273 | F20: All_Q1 | G20: MWG_Q1 | H20: VNPAY_Q1 | I20: BE_Q1 | J20: VDS_Q1
A21: IT | B21: Indirect system cost | C21: =INDEX($AR$44:$AV$48,MATCH($B21,$AR$44:$AR$48,0),MATCH($D$1,$AR$44:$AV$44,0)) -> 0.0007468595 | E21: B00 | F21: =SUMIFS($BG:$BG,$BA:$BA,$E21,$AY:$AY,F$20) -> 0.047889979 | G21: =SUMIFS($BG:$BG,$BA:$BA,$E21,$AY:$AY,G$20) -> 0.035199152 | H21: =SUMIFS($BG:$BG,$BA:$BA,$E21,$AY:$AY,H$20) -> 0.0496 | I21: =SUMIFS($BG:$BG,$BA:$BA,$E21,$AY:$AY,I$20) -> 0.0608 | J21: =SUMIFS($BG:$BG,$BA:$BA,$E21,$AY:$AY,J$20) -> 0.074
A22: Other supports | B22: Other indirect supporting cost | C22: =INDEX($AR$44:$AV$48,MATCH($B22,$AR$44:$AR$48,0),MATCH($D$1,$AR$44:$AV$44,0)) -> 0.00098977289 | E22: B01 | F22: =SUMIFS($BG:$BG,$BA:$BA,$E22,$AY:$AY,F$20) -> 0.85717022 | G22: =SUMIFS($BG:$BG,$BA:$BA,$E22,$AY:$AY,G$20) -> 0.82375771 | H22: =SUMIFS($BG:$BG,$BA:$BA,$E22,$AY:$AY,H$20) -> 0.878 | I22: =SUMIFS($BG:$BG,$BA:$BA,$E22,$AY:$AY,I$20) -> 0.874 | J22: =SUMIFS($BG:$BG,$BA:$BA,$E22,$AY:$AY,J$20) -> 0.81892316
A23: Sharing NII | B23: Sharing NII | C23: =INDEX($E$44:$AO$53,MATCH($B$1,$E$44:$E$53,0),MATCH($B23,$E$44:$AO$44,0)) -> 0.33230275 | E23: B02 | F23: =SUMIFS($BG:$BG,$BA:$BA,$E23,$AY:$AY,F$20) -> 0.94435758 | G23: =SUMIFS($BG:$BG,$BA:$BA,$E23,$AY:$AY,G$20) -> 0.95445681 | H23: =SUMIFS($BG:$BG,$BA:$BA,$E23,$AY:$AY,H$20) -> 0.96281673 | I23: =SUMIFS($BG:$BG,$BA:$BA,$E23,$AY:$AY,I$20) -> 0.936 | J23: =SUMIFS($BG:$BG,$BA:$BA,$E23,$AY:$AY,J$20) -> 0.92415678
A24: Sharing NFI | B24: Sharing NFI | C24: =INDEX($E$44:$AO$53,MATCH($B$1,$E$44:$E$53,0),MATCH($B24,$E$44:$AO$44,0)) -> 0.33230275 | E24: B03 | F24: =SUMIFS($BG:$BG,$BA:$BA,$E24,$AY:$AY,F$20) -> 0.96426366 | G24: =SUMIFS($BG:$BG,$BA:$BA,$E24,$AY:$AY,G$20) -> 0.96662103 | H24: =SUMIFS($BG:$BG,$BA:$BA,$E24,$AY:$AY,H$20) -> 0.98180702 | I24: =SUMIFS($BG:$BG,$BA:$BA,$E24,$AY:$AY,I$20) -> 0.95463697 | J24: =SUMIFS($BG:$BG,$BA:$BA,$E24,$AY:$AY,J$20) -> 0.95398963
A25: Sharing Risk DPD 90+ | B25: Sharing Risk DPD 90+ | C25: =INDEX($E$44:$AO$53,MATCH($B$1,$E$44:$E$53,0),MATCH($B25,$E$44:$AO$44,0)) -> 0.33230275 | E25: B04 | F25: =SUMIFS($BG:$BG,$BA:$BA,$E25,$AY:$AY,F$20) -> 0.98262623 | G25: =SUMIFS($BG:$BG,$BA:$BA,$E25,$AY:$AY,G$20) -> 0.9883535 | H25: =SUMIFS($BG:$BG,$BA:$BA,$E25,$AY:$AY,H$20) -> 0.98896246 | I25: =SUMIFS($BG:$BG,$BA:$BA,$E25,$AY:$AY,I$20) -> 0.96453427 | J25: =SUMIFS($BG:$BG,$BA:$BA,$E25,$AY:$AY,J$20) -> 0.98865468
A26: Sharing TOI +Risk DPD90+ | B26: Sharing TOI +Risk DPD90+ | C26: =INDEX($E$44:$AO$53,MATCH($B$1,$E$44:$E$53,0),MATCH($B26,$E$44:$AO$44,0)) -> 0
A27: Initial fee | B27: Initial fee | C27: =INDEX($E$44:$AO$53,MATCH($B$1,$E$44:$E$53,0),MATCH($B27,$E$44:$AO$44,0)) -> 0.031770112
A29: Average attrition rate
A30: Year 1 | B30: Year 2 | C30: Year 3 | D30: Year 4 | E30: Year 5
A31: =INDEX($E$44:$L$49,MATCH($B$1,$E$44:$E$49,0),MATCH(A$30,$E$44:$L$44,0)) -> 0.011030208 | B31: =INDEX($E$44:$L$49,MATCH($B$1,$E$44:$E$49,0),MATCH(B$30,$E$44:$L$44,0)) -> 0.0068777618 | C31: =INDEX($E$44:$L$49,MATCH($B$1,$E$44:$E$49,0),MATCH(C$30,$E$44:$L$44,0)) -> 0.0054648835 | D31: =INDEX($E$44:$L$49,MATCH($B$1,$E$44:$E$49,0),MATCH(D$30,$E$44:$L$44,0)) -> 0.0042795518 | E31: =INDEX($E$44:$L$49,MATCH($B$1,$E$44:$E$49,0),MATCH(E$30,$E$44:$L$44,0)) -> 0.003317893
B33: EMI Penetration | C33: Tenor | D33: Subvention fee | F33: Bucket | G33: 1 | H33: 2 | I33: 3 | J33: 4 | K33: 5
A34: Retail 0% Installment | B34: {=TRANSPOSE(_xlfn.XLOOKUP($B$1,E44:$E$49,AD44:AF49))} -> 0.29616921 | C34: {=TRANSPOSE(_xlfn.XLOOKUP($B$1,$E$44:$E$49,$AG$44:$AI$49))} -> 5 | D34: =_xlfn.XLOOKUP($B$1,$E$44:$E$49,$AJ$44:$AJ$49) -> 0.07017491 | F34: B00 | G34: =SUMIFS(BB:BB,$AY:$AY,$B$1,$BA:$BA,$F34) -> 0.072699894 | H34: =SUMIFS(BC:BC,$AY:$AY,$B$1,$BA:$BA,$F34) -> 0.0535 | I34: =SUMIFS(BD:BD,$AY:$AY,$B$1,$BA:$BA,$F34) -> 0.0415 | J34: =SUMIFS(BE:BE,$AY:$AY,$B$1,$BA:$BA,$F34) -> 0.0375 | K34: =SUMIFS(BF:BF,$AY:$AY,$B$1,$BA:$BA,$F34) -> 0.03425
A35: Retail monthly installment | B35: 0.04851372 | C35: 6 | F35: B01 | G35: =SUMIFS(BB:BB,$AY:$AY,$B$1,$BA:$BA,$F35) -> 0.90027608 | H35: =SUMIFS(BC:BC,$AY:$AY,$B$1,$BA:$BA,$F35) -> 0.878075 | I35: =SUMIFS(BD:BD,$AY:$AY,$B$1,$BA:$BA,$F35) -> 0.845 | J35: =SUMIFS(BE:BE,$AY:$AY,$B$1,$BA:$BA,$F35) -> 0.8325 | K35: =SUMIFS(BF:BF,$AY:$AY,$B$1,$BA:$BA,$F35) -> 0.83
A36: Cash installment | B36: 0.0025939226 | C36: 3 | F36: B02 | G36: =SUMIFS(BB:BB,$AY:$AY,$B$1,$BA:$BA,$F36) -> 0.96147117 | H36: =SUMIFS(BC:BC,$AY:$AY,$B$1,$BA:$BA,$F36) -> 0.94570418 | I36: =SUMIFS(BD:BD,$AY:$AY,$B$1,$BA:$BA,$F36) -> 0.93820418 | J36: =SUMIFS(BE:BE,$AY:$AY,$B$1,$BA:$BA,$F36) -> 0.93820418 | K36: =SUMIFS(BF:BF,$AY:$AY,$B$1,$BA:$BA,$F36) -> 0.93820418
F37: B03 | G37: =SUMIFS(BB:BB,$AY:$AY,$B$1,$BA:$BA,$F37) -> 0.97863629 | H37: =SUMIFS(BC:BC,$AY:$AY,$B$1,$BA:$BA,$F37) -> 0.96132675 | I37: =SUMIFS(BD:BD,$AY:$AY,$B$1,$BA:$BA,$F37) -> 0.96045175 | J37: =SUMIFS(BE:BE,$AY:$AY,$B$1,$BA:$BA,$F37) -> 0.96045175 | K37: =SUMIFS(BF:BF,$AY:$AY,$B$1,$BA:$BA,$F37) -> 0.96045175
F38: B04 | G38: =SUMIFS(BB:BB,$AY:$AY,$B$1,$BA:$BA,$F38) -> 0.98774368 | H38: =SUMIFS(BC:BC,$AY:$AY,$B$1,$BA:$BA,$F38) -> 0.97616561 | I38: =SUMIFS(BD:BD,$AY:$AY,$B$1,$BA:$BA,$F38) -> 0.97974061 | J38: =SUMIFS(BE:BE,$AY:$AY,$B$1,$BA:$BA,$F38) -> 0.97974061 | K38: =SUMIFS(BF:BF,$AY:$AY,$B$1,$BA:$BA,$F38) -> 0.98974061
F39: B05 | G39: =SUMIFS(BB:BB,$AY:$AY,$B$1,$BA:$BA,$F39) -> 0.99170021 | H39: =SUMIFS(BC:BC,$AY:$AY,$B$1,$BA:$BA,$F39) -> 0.98827646 | I39: =SUMIFS(BD:BD,$AY:$AY,$B$1,$BA:$BA,$F39) -> 0.99110146 | J39: =SUMIFS(BE:BE,$AY:$AY,$B$1,$BA:$BA,$F39) -> 0.99110146 | K39: =SUMIFS(BF:BF,$AY:$AY,$B$1,$BA:$BA,$F39) -> 0.99110146
F40: B06 | G40: =SUMIFS(BB:BB,$AY:$AY,$B$1,$BA:$BA,$F40) -> 0.99493965 | H40: =SUMIFS(BC:BC,$AY:$AY,$B$1,$BA:$BA,$F40) -> 0.99378871 | I40: =SUMIFS(BD:BD,$AY:$AY,$B$1,$BA:$BA,$F40) -> 0.99378871 | J40: =SUMIFS(BE:BE,$AY:$AY,$B$1,$BA:$BA,$F40) -> 0.99378871 | K40: =SUMIFS(BF:BF,$AY:$AY,$B$1,$BA:$BA,$F40) -> 0.99378871
H43: Average attrition rate | AD43: EMI Penetration | AG43: Tenor | BK43: Original
A44: Group | B44: Partner | C44: Product | D44: Sub Product | E44: Index | F44: Period | G44: Active at beginning | H44: Year 1 | I44: Year 2 | J44: Year 3 | K44: Year 4 | L44: Year 5 | M44: Approval rate | N44: Disbursement rate | O44: IR | P44: COF | Q44: Spending | R44: Monthly fee (Subscription fee) | S44: Late payment penalty (fee) | T44: MKT | U44: UW | V44: Collection | W44: SMS | X44: Disburse cost | Y44: Leadgen | Z44: Promotion | AA44: Sharing | AB44: % repayment | AC44: % revolving | AD44: Subvention | AE44: Monthly fee | AF44: No fee | AG44: Subvention | AH44: Monthly fee | AI44: No fee | AJ44: Subvention fee | AK44: Initial fee | AL44: Sharing NII | AM44: Sharing NFI | AN44: Sharing Risk DPD 90+ | AO44: Sharing TOI +Risk DPD90+ | AR44: Phân bổ | AS44: Q1 | AT44: Q2 | AU44: Q3 | AV44: Q4 | AX44: Channel | AY44: Index | AZ44: Period | BA44: Bucket | BB44: 1 | BC44: 2 | BD44: 3 | BE44: 4 | BF44: 5 | BG44: AVG | BK44: Channel | BL44: Index | BM44: Period | BN44: Bucket | BO44: 1 | BP44: 2 | BQ44: 3 | BR44: 4 | BS44: 5 | BT44: AVG
...

Sheet SAP_Leadsheet
B1: SAP MODEL - PAYLATER CARD
B2: Leadsheet
B3: HKN | C3: =NOTE!P2 -> 20251201 | D3: =NOTE!O2 -> v10
B5: Select model type
B6: Write off | C6: DPD180+
B7: Provision | C7: IFRS
B8: Chanel | C8: All
B9: EMI mode | C9: EMI
B10: Customer type
B11: Quarter | C11: Q1
B13: REVENUE INPUT | I13: Cur: mVND, % | L13: SUMMARY OUTPUT | V13: Cur: mVND, %
E15: Year 1 | F15: Year 2 | G15: Year 3 | H15: Year 4 | I15: Year 5 | N15: Lifetime | O15: Year 1 | P15: Year 2 | Q15: Year 3 | R15: Year 4 | S15: Year 5 | T15: Year 6 | U15: % of ANR | V15: % of Spending
B17: Card Status | C17: Activate at beginning | E17: =DATA!C3 -> 0.6392418 | F17: Account having spending at month 1 | L17: Spending | N17: =N48 -> 26.542458 | O17: =O48 -> 7.3460319 | P17: =P48 -> 6.0081549 | Q17: =Q48 -> 5.0768553 | R17: =R48 -> 4.3420441 | S17: =S48 -> 3.7693718 | T17: =T48 -> 0
C18: Average attrition rate | E18: =DATA!A31 -> 0.011030208 | F18: =DATA!B31 -> 0.0068777618 | G18: =DATA!C31 -> 0.0054648835 | H18: =DATA!D31 -> 0.0042795518 | I18: =DATA!E31 -> 0.003317893 | J18: =IF(E17-E18*11-(F18+G18+H18+I18)*12<0,"check","OK") -> OK | L18: ANR | N18: =N49 -> 1.3704774 | O18: =O49 -> 1.6955335 | P18: =P49 -> 1.5692588 | Q18: =Q49 -> 1.3739191 | R18: =R49 -> 1.1886385 | S18: =S49 -> 1.0250369 | T18: =T49 -> 0
C19: per cohort | E19: including account have spending & balance | L19: TOI | N19: =N50 -> 2.0433936 | O19: =O50 -> 0.50288459 | P19: =P50 -> 0.43975111 | Q19: =Q50 -> 0.41715861 | R19: =R50 -> 0.37418294 | S19: =S50 -> 0.30941638 | T19: =T50 -> 0 | U19: =U50 -> 0.29820173 | V19: =V50 -> 0.076985848
L20: Net interest income | N20: =N51 -> 0.68910667 | O20: =O51 -> 0.12270156 | P20: =P51 -> 0.13217939 | Q20: =Q51 -> 0.15081336 | R20: =R51 -> 0.14375553 | S20: =S51 -> 0.13965683 | T20: =T51 -> 0 | U20: =U51 -> 0.10056447 | V20: =V51 -> 0.025962429
B21: Term of using | C21: Tenor | E21: 60 | F21: month | L21: Net fee income | N21: =N54 -> 1.354287 | O21: =O54 -> 0.38018303 | P21: =P54 -> 0.30757172 | Q21: =Q54 -> 0.26634524 | R21: =R54 -> 0.23042741 | S21: =S54 -> 0.16975955 | T21: =T54 -> 0 | U21: =U54 -> 0.19763726 | V21: =V54 -> 0.051023419
C22: Due date | E22: 5 | F22: Date of month | L22: Other income | N22: =N65 -> 0 | O22: =O65 -> 0 | P22: =P65 -> 0 | Q22: =Q65 -> 0 | R22: =R65 -> 0 | S22: =S65 -> 0 | T22: =T65 -> 0 | U22: =N22/$N$49/60*12 -> 0 | V22: =N22/$N$48/60*12 -> 0
C23: Free-interest period | E23: 45 | F23: days | L23: Provision cost | N23: =N66 -> -2.4358372 | O23: =O66 -> -0.90924204 | P23: =P66 -> -0.55696735 | Q23: =Q66 -> -0.39672309 | R23: =R66 -> -0.3172374 | S23: =S66 -> -0.25566734 | T23: =T66 -> 0 | U23: =U66 -> -0.35547281 | V23: =V66 -> -0.091771351
L24: Operation expenses | N24: =N67 -> -0.61325013 | O24: =O67 -> -0.24788521 | P24: =P67 -> -0.10309891 | Q24: =Q67 -> -0.09212599 | R24: =R67 -> -0.08912664 | S24: =S67 -> -0.081013382 | T24: =T67 -> 0 | U24: =U67 -> -0.089494382 | V24: =V67 -> -0.023104497
B25: Usage Status | C25: Spd / activate card | E25: =DATA!C4 -> 1.0580627 | F25: =E25 -> 1.0580627 | G25: =F25 -> 1.0580627 | H25: =G25 -> 1.0580627 | I25: =H25 -> 1.0580627 | L25: Variable Cost | N25: =N67-N81 -> -0.49676331 | O25: =O67-O81 -> -0.21753932 | P25: =P67-P81 -> -0.077342081 | Q25: =Q67-Q81 -> -0.069599557 | R25: =R67-R81 -> -0.069185947 | S25: =S67-S81 -> -0.063096409 | T25: =T67-T81 -> 0 | U25: =N25/$N$49/60*12 -> -0.072494931 | V25: =N25/$N$48/60*12 -> -0.0037431598
L26: Sales & Marketing | N26: =N68 -> -0.084967274 | O26: =O68 -> -0.056124799 | P26: =P68 -> 0 | Q26: =Q68 -> -0.0035983073 | R26: =R68 -> -0.012164168 | S26: =S68 -> -0.013079999 | T26: =T68 -> 0 | U26: =U68 -> -0.012399661 | V26: =V68 -> -0.0032011833
B27: Payment status | C27: Port Revolving rate | E27: =DATA!C5 -> 0.69849829 | L27: Promotion | N27: =N73 -> -0.11970384 | O27: =O73 -> -0.033129871 | P27: =P73 -> -0.027096179 | Q27: =Q73 -> -0.022896111 | R27: =R73 -> -0.019582186 | S27: =S73 -> -0.016999491 | T27: =T73 -> 0 | U27: =U73 -> -0.017468926 | V27: =V73 -> -0.0045099003
C28: Payment rate | E28: =DATA!C6 -> 0.36991535 | F28: =E28 -> 0.36991535 | G28: =F28 -> 0.36991535 | H28: =G28 -> 0.36991535 | I28: =H28 -> 0.36991535 | L28: UW & Disbursal cost | N28: =N74 -> -0.067824417 | O28: =O74 -> -0.067824417 | P28: =P74 -> 0 | Q28: =Q74 -> 0 | R28: =R74 -> 0 | S28: =S74 -> 0 | T28: =T74 -> 0 | U28: =U74 -> -0.0098979259 | V28: =V74 -> -0.0025553179
E29: payment T/ non-EMI ANR T-1 (excl WO) | L29: Collection | N29: =N77 -> -0.12527023 | O29: =O77 -> -0.034670455 | P29: =P77 -> -0.028356189 | Q29: =Q77 -> -0.023960811 | R29: =R77 -> -0.020492784 | S29: =S77 -> -0.01778999 | T29: =T77 -> 0 | U29: =U77 -> -0.018281255 | V29: =V77 -> -0.0047196168
L30: After sale service | N30: =N80 -> -0.098997552 | O30: =O80 -> -0.025789774 | P30: =P80 -> -0.021889713 | Q30: =Q80 -> -0.019144327 | R30: =R80 -> -0.016946808 | S30: =S80 -> -0.015226929 | T30: =T80 -> 0 | U30: =U80 -> -0.014447163 | V30: =V80 -> -0.0037297809
B31: Pricing | C31: CII rate | E31: =DATA!C7 -> 0.47795381 | F31: annually | L31: Overhead cost | N31: =N81 -> -0.11648682 | O31: =O81 -> -0.030345889 | P31: =P81 -> -0.025756829 | Q31: =Q81 -> -0.022526433 | R31: =R81 -> -0.019940693 | S31: =S81 -> -0.017916973 | T31: =T81 -> 0 | U31: =N31/$N$49/60*12 -> -0.016999451 | V31: =N31/$N$48/60*12 -> -0.00087773949
C32: COF rate | E32: =DATA!C8 -> 0.069938802 | F32: annually | L32: PBT | N32: =N82 -> -1.0056937 | O32: =O82 -> -0.65424266 | P32: =P82 -> -0.22031515 | Q32: =Q82 -> -0.071690469 | R32: =R82 -> -0.032181101 | S32: =S82 -> -0.027264335 | T32: =T82 -> 0 | U32: =U82 -> -0.14676546 | V32: =V82 -> -0.037889999
L33: Profit before sup.cost | N33: =N83 -> -0.8892069 | O33: =O83 -> -0.62389677 | P33: =P83 -> -0.19455832 | Q33: =Q83 -> -0.049164036 | R33: =R83 -> -0.012240409 | S33: =S83 -> -0.0093473619 | T33: =T83 -> 0 | U33: =U83 -> -0.12976601 | V33: =V83 -> -0.033501302
B34: Fee/charge | C34: Annual fee | F34: per card/year
C35: Annual Fee waiver | F35: % accard port
C36: Monthly fee (Subscription fee) | E36: =DATA!C9 -> 0.0275 | F36: per card having spending/month
C37: Transaction fee | F37: per spend/month
C38: Late payment interest | E38: 0 | F38: annually | G38: %Late payment collected | I38: 1
C39: Late payment penalty (fee) | E39: =DATA!C10 -> 0.072785593 | F39: per account | G39: %Late payment collected | I39: 1
C40: Min due fee | F40: per revolving balance/month
B43: Other fee(no share) | C43: Issuance fee | F43: per issued account
C44: Termination fee | F44: per terminated account
L45: PERFORMANCE OUTPUT | V45: Cur: mVND, %
B46: EMI
...

Sheet SAP_Spreadsheet
A1: Index!A1 | B1: SAP Model Paylater
B2: Spreadsheet
B4: Calendar | C4: =(30*4+31*7+28)/12 -> 30.416667 | AE4: =IF(AE$7<13,SAP_Leadsheet!$E$18,IF(SAP_Leadsheet!AF$6<25,SAP_Leadsheet!$F$18,IF(AE$7<37,SAP_Leadsheet!$G$18,IF(AE$7<49,SAP_Leadsheet!$H$18,SAP_Leadsheet!$I$18)))) -> 0.0068777618
B5: Validation | C5: No | D5: COF (*) | E5: =SAP_Leadsheet!E32 -> 0.069938802
E6: Year | G6: =ROUNDUP(G7/12,0) -> 1 | H6: =ROUNDUP(H7/12,0) -> 1 | I6: =ROUNDUP(I7/12,0) -> 1 | J6: =ROUNDUP(J7/12,0) -> 1 | K6: =ROUNDUP(K7/12,0) -> 1 | L6: =ROUNDUP(L7/12,0) -> 1 | M6: =ROUNDUP(M7/12,0) -> 1 | N6: =ROUNDUP(N7/12,0) -> 1 | ... BZ6: =ROUNDUP(BZ7/12,0) -> 6
E7: Month | G7: 1 | H7: =G7+1 -> 2 | I7: =H7+1 -> 3 | J7: =I7+1 -> 4 | K7: =J7+1 -> 5 | L7: =K7+1 -> 6 | M7: =L7+1 -> 7 | N7: =M7+1 -> 8 | O7: =N7+1 -> 9 | ... BZ7: =BY7+1 -> 72
A8: 1 | B8: CARD OPERATION | AE8: =IF(AE$7<37,SAP_Leadsheet!$G$18,IF(AE$7<49,SAP_Leadsheet!$H$18,SAP_Leadsheet!$I$18)) -> 0.0054648835
C10: Card Status | D10: Issued card | F10: # Card | G10: 1 | H10: =G10 -> 1 | I10: =H10 -> 1 | J10: =I10 -> 1 | K10: =J10 -> 1 | L10: =K10 -> 1 | M10: =L10 -> 1 | N10: =M10 -> 1 | O10: =N10 -> 1 | ... BN10: =BM10 -> 1
D11: Activate card | F11: # Card | G11: =G10*SAP_Leadsheet!E17 -> 0.6392418 | H11: =G11-H12 -> 0.62821159 | I11: =H11-I12 -> 0.61718138 | J11: =I11-J12 -> 0.60615117 | K11: =J11-K12 -> 0.59512097 | L11: =K11-L12 -> 0.58409076 | M11: =L11-M12 -> 0.57306055 | N11: =M11-N12 -> 0.56203034 | O11: =N11-O12 -> 0.55100014 | ... BN11: =BM11-BN12 -> 0.27862843
D12: Attrition rate | F12: % | G12: =OFFSET(SAP_Leadsheet!$D$18,0,SAP_Spreadsheet!G6) -> 0.011030208 | H12: =OFFSET(SAP_Leadsheet!$D$18,0,SAP_Spreadsheet!H6) -> 0.011030208 | I12: =OFFSET(SAP_Leadsheet!$D$18,0,SAP_Spreadsheet!I6) -> 0.011030208 | J12: =OFFSET(SAP_Leadsheet!$D$18,0,SAP_Spreadsheet!J6) -> 0.011030208 | K12: =OFFSET(SAP_Leadsheet!$D$18,0,SAP_Spreadsheet!K6) -> 0.011030208 | L12: =OFFSET(SAP_Leadsheet!$D$18,0,SAP_Spreadsheet!L6) -> 0.011030208 | M12: =OFFSET(SAP_Leadsheet!$D$18,0,SAP_Spreadsheet!M6) -> 0.011030208 | N12: =OFFSET(SAP_Leadsheet!$D$18,0,SAP_Spreadsheet!N6) -> 0.011030208 | ... BN12: =OFFSET(SAP_Leadsheet!$D$18,0,SAP_Spreadsheet!BN6) -> 0.003317893
C15: Spending status | D15: Spd per activate card (Port) | F15: mVND | G15: =OFFSET(SAP_Leadsheet!$E$25,0,SAP_Spreadsheet!G6-1) -> 1.0580627 | H15: =OFFSET(SAP_Leadsheet!$E$25,0,SAP_Spreadsheet!H6-1) -> 1.0580627 | I15: =OFFSET(SAP_Leadsheet!$E$25,0,SAP_Spreadsheet!I6-1) -> 1.0580627 | J15: =OFFSET(SAP_Leadsheet!$E$25,0,SAP_Spreadsheet!J6-1) -> 1.0580627 | K15: =OFFSET(SAP_Leadsheet!$E$25,0,SAP_Spreadsheet!K6-1) -> 1.0580627 | L15: =OFFSET(SAP_Leadsheet!$E$25,0,SAP_Spreadsheet!L6-1) -> 1.0580627 | M15: =OFFSET(SAP_Leadsheet!$E$25,0,SAP_Spreadsheet!M6-1) -> 1.0580627 | N15: =OFFSET(SAP_Leadsheet!$E$25,0,SAP_Spreadsheet!N6-1) -> 1.0580627 | ... BN15: =OFFSET(SAP_Leadsheet!$E$25,0,SAP_Spreadsheet!BN6-1) -> 1.0580627
A18: 3 | B18: BS by bucket
B20: CORE | C20: Core statement | D20: Beginning Bal | F20: mVND | G20: 0 | H20: =IF(H7>SAP_Leadsheet!$E$21,0,G25) -> 0.48759132 | I20: =IF(I7>SAP_Leadsheet!$E$21,0,H25) -> 0.95111634 | J20: =IF(J7>SAP_Leadsheet!$E$21,0,I25) -> 1.2742303 | K20: =IF(K7>SAP_Leadsheet!$E$21,0,J25) -> 1.4791941 | L20: =IF(L7>SAP_Leadsheet!$E$21,0,K25) -> 1.6143421 | M20: =IF(M7>SAP_Leadsheet!$E$21,0,L25) -> 1.6764079 | N20: =IF(N7>SAP_Leadsheet!$E$21,0,M25) -> 1.686068 | O20: =IF(O7>SAP_Leadsheet!$E$21,0,N25) -> 1.6677372 | ... BN20: =IF(BN7>SAP_Leadsheet!$E$21,0,BM25) -> 3.1736266
D21: New spending | F21: mVND | G21: =IF(G7>SAP_Leadsheet!$E$21,0,G15*G11) -> 0.67635791 | H21: =IF(H7>SAP_Leadsheet!$E$21,0,H15*H11) -> 0.66468725 | I21: =IF(I7>SAP_Leadsheet!$E$21,0,I15*I11) -> 0.6530166 | J21: =IF(J7>SAP_Leadsheet!$E$21,0,J15*J11) -> 0.64134595 | K21: =IF(K7>SAP_Leadsheet!$E$21,0,K15*K11) -> 0.6296753 | L21: =IF(L7>SAP_Leadsheet!$E$21,0,L15*L11) -> 0.61800465 | M21: =IF(M7>SAP_Leadsheet!$E$21,0,M15*M11) -> 0.606334 | N21: =IF(N7>SAP_Leadsheet!$E$21,0,N15*N11) -> 0.59466335 | ... BN21: =IF(BN7>SAP_Leadsheet!$E$21,0,BN15*BN11) -> 0.29480635
D22: EMI Capitalized | F22: mVND | G22: =-G29 -> 0.046116857 | H22: =-H29 -> 0.09143796 | I22: =-I29 -> 0.13596331 | J22: =-J29 -> 0.1791081 | K22: =-K29 -> 0.22146723 | L22: =-L29 -> 0.22297742 | M22: =-M29 -> 0.21892448 | N22: =-N29 -> 0.21487153 | ... BN22: =-BN29 -> 0.021080872
D23: Move to EMI | F23: mVND | G23: =-G28 -> -0.23488344 | H23: =-H28 -> -0.2308305 | I23: =-I28 -> -0.22677755 | J23: =-J28 -> -0.2227246 | K23: =-K28 -> -0.21867165 | L23: =-L28 -> -0.21461871 | M23: =-M28 -> -0.21056576 | N23: =-N28 -> -0.20651281 | ... BN23: =-BN28 -> 0
D24: Paid off | F24: mVND | H24: {=IF(H7>SAP_Leadsheet!$E$21,0,-G632*INDEX(SAP_Leadsheet!$E$28:$I$28,1,G6))} -> -0.061769696 | I24: {=IF(I7>SAP_Leadsheet!$E$21,0,-H632*INDEX(SAP_Leadsheet!$E$28:$I$28,1,H6))} -> -0.23908841 | J24: {=IF(J7>SAP_Leadsheet!$E$21,0,-I632*INDEX(SAP_Leadsheet!$E$28:$I$28,1,I6))} -> -0.39276569 | K24: {=IF(K7>SAP_Leadsheet!$E$21,0,-J632*INDEX(SAP_Leadsheet!$E$28:$I$28,1,J6))} -> -0.49732284 | L24: {=IF(L7>SAP_Leadsheet!$E$21,0,-K632*INDEX(SAP_Leadsheet!$E$28:$I$28,1,K6))} -> -0.56429759 | M24: {=IF(M7>SAP_Leadsheet!$E$21,0,-L632*INDEX(SAP_Leadsheet!$E$28:$I$28,1,L6))} -> -0.60503262 | N24: {=IF(N7>SAP_Leadsheet!$E$21,0,-M632*INDEX(SAP_Leadsheet!$E$28:$I$28,1,M6))} -> -0.62135278 | O24: {=IF(O7>SAP_Leadsheet!$E$21,0,-N632*INDEX(SAP_Leadsheet!$E$28:$I$28,1,N6))} -> -0.62138022 | ... BN24: {=IF(BN7>SAP_Leadsheet!$E$21,0,-BM632*INDEX(SAP_Leadsheet!$E$28:$I$28,1,BM6))} -> -0.33560137
D25: Ending Bal | F25: mVND | G25: =IF(SAP_Leadsheet!$E$21<G7,0,SUM(G20:G24)) -> 0.48759132 | H25: =IF(SAP_Leadsheet!$E$21<H7,0,SUM(H20:H24)) -> 0.95111634 | I25: =IF(SAP_Leadsheet!$E$21<I7,0,SUM(I20:I24)) -> 1.2742303 | J25: =IF(SAP_Leadsheet!$E$21<J7,0,SUM(J20:J24)) -> 1.4791941 | K25: =IF(SAP_Leadsheet!$E$21<K7,0,SUM(K20:K24)) -> 1.6143421 | L25: =IF(SAP_Leadsheet!$E$21<L7,0,SUM(L20:L24)) -> 1.6764079 | M25: =IF(SAP_Leadsheet!$E$21<M7,0,SUM(M20:M24)) -> 1.686068 | N25: =IF(SAP_Leadsheet!$E$21<N7,0,SUM(N20:N24)) -> 1.6677372 | ... BN25: =IF(SAP_Leadsheet!$E$21<BN7,0,SUM(BN20:BN24)) -> 3.1539125
B27: Installment | C27: Total EMI | D27: Beginning Bal | F27: mVND | G27: 0 | H27: =G30 -> 0.18876659 | I27: =H30 -> 0.32815912 | J27: =I30 -> 0.41897336 | K27: =J30 -> 0.46258986 | L27: =K30 -> 0.45979428 | M27: =L30 -> 0.45143557 | N27: =M30 -> 0.44307685 | O27: =N30 -> 0.43471814 | ... BN27: =BM30 -> 0.021080872
D28: New Billing | F28: mVND | G28: =G34+G224+G413 -> 0.23488344 | H28: =H34+H224+H413 -> 0.2308305 | I28: =I34+I224+I413 -> 0.22677755 | J28: =J34+J224+J413 -> 0.2227246 | K28: =K34+K224+K413 -> 0.21867165 | L28: =L34+L224+L413 -> 0.21461871 | M28: =M34+M224+M413 -> 0.21056576 | N28: =N34+N224+N413 -> 0.20651281 | ... BN28: =BN34+BN224+BN413 -> 0
D29: Paid off | F29: mVND | G29: =G35+G225+G414 -> -0.046116857 | H29: =H35+H225+H414 -> -0.09143796 | I29: =I35+I225+I414 -> -0.13596331 | J29: =J35+J225+J414 -> -0.1791081 | K29: =K35+K225+K414 -> -0.22146723 | L29: =L35+L225+L414 -> -0.22297742 | M29: =M35+M225+M414 -> -0.21892448 | N29: =N35+N225+N414 -> -0.21487153 | ... BN29: =BN35+BN225+BN414 -> -0.021080872
D30: Ending Bal | F30: mVND | G30: =G27+G28+G29 -> 0.18876659 | H30: =H27+H28+H29 -> 0.32815912 | I30: =I27+I28+I29 -> 0.41897336 | J30: =J27+J28+J29 -> 0.46258986 | K30: =K27+K28+K29 -> 0.45979428 | L30: =L27+L28+L29 -> 0.45143557 | M30: =M27+M28+M29 -> 0.44307685 | N30: =N27+N28+N29 -> 0.43471814 | ... BN30: =BN27+BN28+BN29 -> -3.3653635e-16
A32: 2.4
C33: Cash installment | D33: Beginning Bal | F33: mVND | G33: 0 | H33: =G158 -> 0.0011696133 | I33: =H158 -> 0.0017342382 | J33: =I158 -> 0.0017039654 | K33: =J158 -> 0.0016736926 | L33: =K158 -> 0.0016434199 | M33: =L158 -> 0.0016131471 | N33: =M158 -> 0.0015828744 | O33: =N158 -> 0.0015526016 | ... BN33: =BM158 -> 0.00026097233
D34: New Billing | F34: mVND | G34: =IF(SAP_Leadsheet!$C$9="non-EMI",0,IF(G7+SAP_Leadsheet!$E$49-1>SAP_Leadsheet!$E$21,0,SAP_Leadsheet!$E$48*G21)) -> 0.00175442 | H34: =IF(SAP_Leadsheet!$C$9="non-EMI",0,IF(H7+SAP_Leadsheet!$E$49-1>SAP_Leadsheet!$E$21,0,SAP_Leadsheet!$E$48*H21)) -> 0.0017241473 | I34: =IF(SAP_Leadsheet!$C$9="non-EMI",0,IF(I7+SAP_Leadsheet!$E$49-1>SAP_Leadsheet!$E$21,0,SAP_Leadsheet!$E$48*I21)) -> 0.0016938745 | J34: =IF(SAP_Leadsheet!$C$9="non-EMI",0,IF(J7+SAP_Leadsheet!$E$49-1>SAP_Leadsheet!$E$21,0,SAP_Leadsheet!$E$48*J21)) -> 0.0016636017 | K34: =IF(SAP_Leadsheet!$C$9="non-EMI",0,IF(K7+SAP_Leadsheet!$E$49-1>SAP_Leadsheet!$E$21,0,SAP_Leadsheet!$E$48*K21)) -> 0.001633329 | L34: =IF(SAP_Leadsheet!$C$9="non-EMI",0,IF(L7+SAP_Leadsheet!$E$49-1>SAP_Leadsheet!$E$21,0,SAP_Leadsheet!$E$48*L21)) -> 0.0016030562 | M34: =IF(SAP_Leadsheet!$C$9="non-EMI",0,IF(M7+SAP_Leadsheet!$E$49-1>SAP_Leadsheet!$E$21,0,SAP_Leadsheet!$E$48*M21)) -> 0.0015727834 | N34: =IF(SAP_Leadsheet!$C$9="non-EMI",0,IF(N7+SAP_Leadsheet!$E$49-1>SAP_Leadsheet!$E$21,0,SAP_Leadsheet!$E$48*N21)) -> 0.0015425107 | ... BN34: =IF(SAP_Leadsheet!$C$9="non-EMI",0,IF(BN7+SAP_Leadsheet!$E$49-1>SAP_Leadsheet!$E$21,0,SAP_Leadsheet!$E$48*BN21)) -> 0
D35: Paid off | F35: mVND | G35: =G36+G97 -> -0.00058480667 | H35: =H36+H97 -> -0.0011595224 | I35: =I36+I97 -> -0.0017241473 | J35: =J36+J97 -> -0.0016938745 | K35: =K36+K97 -> -0.0016636017 | L35: =L36+L97 -> -0.001633329 | M35: =M36+M97 -> -0.0016030562 | N35: =N36+N97 -> -0.0015727834 | ... BN35: =BN36+BN97 -> -0.00026097233
D36: Early payment | G36: =-SUM(G37:G96) -> 0 | H36: =-SUM(H37:H96) -> 0 | I36: =-SUM(I37:I96) -> 0 | J36: =-SUM(J37:J96) -> 0 | K36: =-SUM(K37:K96) -> 0 | L36: =-SUM(L37:L96) -> 0 | M36: =-SUM(M37:M96) -> 0 | N36: =-SUM(N37:N96) -> 0 | ... BN36: =-SUM(BN37:BN96) -> 0
C37: {=TRANSPOSE(G7:BN7)} -> 1 | G37: =IF(OR($C98>G$7,$C98+$E98-2<G$7),0,($D98-SUM($F98:F98)-SUM($F37:F37))*SAP_Leadsheet!$E$53) -> 0 | H37: =IF(OR($C98>H$7,$C98+$E98-2<H$7),0,($D98-SUM($F98:G98)-SUM($F37:G37))*SAP_Leadsheet!$E$53) -> 0 | I37: =IF(OR($C98>I$7,$C98+$E98-2<I$7),0,($D98-SUM($F98:H98)-SUM($F37:H37))*SAP_Leadsheet!$E$53) -> 0 | J37: =IF(OR($C98>J$7,$C98+$E98-2<J$7),0,($D98-SUM($F98:I98)-SUM($F37:I37))*SAP_Leadsheet!$E$53) -> 0 | K37: =IF(OR($C98>K$7,$C98+$E98-2<K$7),0,($D98-SUM($F98:J98)-SUM($F37:J37))*SAP_Leadsheet!$E$53) -> 0 | L37: =IF(OR($C98>L$7,$C98+$E98-2<L$7),0,($D98-SUM($F98:K98)-SUM($F37:K37))*SAP_Leadsheet!$E$53) -> 0 | M37: =IF(OR($C98>M$7,$C98+$E98-2<M$7),0,($D98-SUM($F98:L98)-SUM($F37:L37))*SAP_Leadsheet!$E$53) -> 0 | N37: =IF(OR($C98>N$7,$C98+$E98-2<N$7),0,($D98-SUM($F98:M98)-SUM($F37:M37))*SAP_Leadsheet!$E$53) -> 0 | ... BN37: =IF(OR($C98>BN$7,$C98+$E98-2<BN$7),0,($D98-SUM($F98:BM98)-SUM($F37:BM37))*SAP_Leadsheet!$E$53) -> 0
C38: 2 | G38: =IF(OR($C99>G$7,$C99+$E99-2<G$7),0,($D99-SUM($F99:F99)-SUM($F38:F38))*SAP_Leadsheet!$E$53) -> 0 | H38: =IF(OR($C99>H$7,$C99+$E99-2<H$7),0,($D99-SUM($F99:G99)-SUM($F38:G38))*SAP_Leadsheet!$E$53) -> 0 | I38: =IF(OR($C99>I$7,$C99+$E99-2<I$7),0,($D99-SUM($F99:H99)-SUM($F38:H38))*SAP_Leadsheet!$E$53) -> 0 | J38: =IF(OR($C99>J$7,$C99+$E99-2<J$7),0,($D99-SUM($F99:I99)-SUM($F38:I38))*SAP_Leadsheet!$E$53) -> 0 | K38: =IF(OR($C99>K$7,$C99+$E99-2<K$7),0,($D99-SUM($F99:J99)-SUM($F38:J38))*SAP_Leadsheet!$E$53) -> 0 | L38: =IF(OR($C99>L$7,$C99+$E99-2<L$7),0,($D99-SUM($F99:K99)-SUM($F38:K38))*SAP_Leadsheet!$E$53) -> 0 | M38: =IF(OR($C99>M$7,$C99+$E99-2<M$7),0,($D99-SUM($F99:L99)-SUM($F38:L38))*SAP_Leadsheet!$E$53) -> 0 | N38: =IF(OR($C99>N$7,$C99+$E99-2<N$7),0,($D99-SUM($F99:M99)-SUM($F38:M38))*SAP_Leadsheet!$E$53) -> 0 | ... BN38: =IF(OR($C99>BN$7,$C99+$E99-2<BN$7),0,($D99-SUM($F99:BM99)-SUM($F38:BM38))*SAP_Leadsheet!$E$53) -> 0
C39: 3 | G39: =IF(OR($C100>G$7,$C100+$E100-2<G$7),0,($D100-SUM($F100:F100)-SUM($F39:F39))*SAP_Leadsheet!$E$53) -> 0 | H39: =IF(OR($C100>H$7,$C100+$E100-2<H$7),0,($D100-SUM($F100:G100)-SUM($F39:G39))*SAP_Leadsheet!$E$53) -> 0 | I39: =IF(OR($C100>I$7,$C100+$E100-2<I$7),0,($D100-SUM($F100:H100)-SUM($F39:H39))*SAP_Leadsheet!$E$53) -> 0 | J39: =IF(OR($C100>J$7,$C100+$E100-2<J$7),0,($D100-SUM($F100:I100)-SUM($F39:I39))*SAP_Leadsheet!$E$53) -> 0 | K39: =IF(OR($C100>K$7,$C100+$E100-2<K$7),0,($D100-SUM($F100:J100)-SUM($F39:J39))*SAP_Leadsheet!$E$53) -> 0 | L39: =IF(OR($C100>L$7,$C100+$E100-2<L$7),0,($D100-SUM($F100:K100)-SUM($F39:K39))*SAP_Leadsheet!$E$53) -> 0 | M39: =IF(OR($C100>M$7,$C100+$E100-2<M$7),0,($D100-SUM($F100:L100)-SUM($F39:L39))*SAP_Leadsheet!$E$53) -> 0 | N39: =IF(OR($C100>N$7,$C100+$E100-2<N$7),0,($D100-SUM($F100:M100)-SUM($F39:M39))*SAP_Leadsheet!$E$53) -> 0 | ... BN39: =IF(OR($C100>BN$7,$C100+$E100-2<BN$7),0,($D100-SUM($F100:BM100)-SUM($F39:BM39))*SAP_Leadsheet!$E$53) -> 0
C40: 4 | G40: =IF(OR($C101>G$7,$C101+$E101-2<G$7),0,($D101-SUM($F101:F101)-SUM($F40:F40))*SAP_Leadsheet!$E$53) -> 0 | H40: =IF(OR($C101>H$7,$C101+$E101-2<H$7),0,($D101-SUM($F101:G101)-SUM($F40:G40))*SAP_Leadsheet!$E$53) -> 0 | I40: =IF(OR($C101>I$7,$C101+$E101-2<I$7),0,($D101-SUM($F101:H101)-SUM($F40:H40))*SAP_Leadsheet!$E$53) -> 0 | J40: =IF(OR($C101>J$7,$C101+$E101-2<J$7),0,($D101-SUM($F101:I101)-SUM($F40:I40))*SAP_Leadsheet!$E$53) -> 0 | K40: =IF(OR($C101>K$7,$C101+$E101-2<K$7),0,($D101-SUM($F101:J101)-SUM($F40:J40))*SAP_Leadsheet!$E$53) -> 0 | L40: =IF(OR($C101>L$7,$C101+$E101-2<L$7),0,($D101-SUM($F101:K101)-SUM($F40:K40))*SAP_Leadsheet!$E$53) -> 0 | M40: =IF(OR($C101>M$7,$C101+$E101-2<M$7),0,($D101-SUM($F101:L101)-SUM($F40:L40))*SAP_Leadsheet!$E$53) -> 0 | N40: =IF(OR($C101>N$7,$C101+$E101-2<N$7),0,($D101-SUM($F101:M101)-SUM($F40:M40))*SAP_Leadsheet!$E$53) -> 0 | ... BN40: =IF(OR($C101>BN$7,$C101+$E101-2<BN$7),0,($D101-SUM($F101:BM101)-SUM($F40:BM40))*SAP_Leadsheet!$E$53) -> 0
C41: 5 | G41: =IF(OR($C102>G$7,$C102+$E102-2<G$7),0,($D102-SUM($F102:F102)-SUM($F41:F41))*SAP_Leadsheet!$E$53) -> 0 | H41: =IF(OR($C102>H$7,$C102+$E102-2<H$7),0,($D102-SUM($F102:G102)-SUM($F41:G41))*SAP_Leadsheet!$E$53) -> 0 | I41: =IF(OR($C102>I$7,$C102+$E102-2<I$7),0,($D102-SUM($F102:H102)-SUM($F41:H41))*SAP_Leadsheet!$E$53) -> 0 | J41: =IF(OR($C102>J$7,$C102+$E102-2<J$7),0,($D102-SUM($F102:I102)-SUM($F41:I41))*SAP_Leadsheet!$E$53) -> 0 | K41: =IF(OR($C102>K$7,$C102+$E102-2<K$7),0,($D102-SUM($F102:J102)-SUM($F41:J41))*SAP_Leadsheet!$E$53) -> 0 | L41: =IF(OR($C102>L$7,$C102+$E102-2<L$7),0,($D102-SUM($F102:K102)-SUM($F41:K41))*SAP_Leadsheet!$E$53) -> 0 | M41: =IF(OR($C102>M$7,$C102+$E102-2<M$7),0,($D102-SUM($F102:L102)-SUM($F41:L41))*SAP_Leadsheet!$E$53) -> 0 | N41: =IF(OR($C102>N$7,$C102+$E102-2<N$7),0,($D102-SUM($F102:M102)-SUM($F41:M41))*SAP_Leadsheet!$E$53) -> 0 | ... BN41: =IF(OR($C102>BN$7,$C102+$E102-2<BN$7),0,($D102-SUM($F102:BM102)-SUM($F41:BM41))*SAP_Leadsheet!$E$53) -> 0
C42: 6 | G42: =IF(OR($C103>G$7,$C103+$E103-2<G$7),0,($D103-SUM($F103:F103)-SUM($F42:F42))*SAP_Leadsheet!$E$53) -> 0 | H42: =IF(OR($C103>H$7,$C103+$E103-2<H$7),0,($D103-SUM($F103:G103)-SUM($F42:G42))*SAP_Leadsheet!$E$53) -> 0 | I42: =IF(OR($C103>I$7,$C103+$E103-2<I$7),0,($D103-SUM($F103:H103)-SUM($F42:H42))*SAP_Leadsheet!$E$53) -> 0 | J42: =IF(OR($C103>J$7,$C103+$E103-2<J$7),0,($D103-SUM($F103:I103)-SUM($F42:I42))*SAP_Leadsheet!$E$53) -> 0 | K42: =IF(OR($C103>K$7,$C103+$E103-2<K$7),0,($D103-SUM($F103:J103)-SUM($F42:J42))*SAP_Leadsheet!$E$53) -> 0 | L42: =IF(OR($C103>L$7,$C103+$E103-2<L$7),0,($D103-SUM($F103:K103)-SUM($F42:K42))*SAP_Leadsheet!$E$53) -> 0 | M42: =IF(OR($C103>M$7,$C103+$E103-2<M$7),0,($D103-SUM($F103:L103)-SUM($F42:L42))*SAP_Leadsheet!$E$53) -> 0 | N42: =IF(OR($C103>N$7,$C103+$E103-2<N$7),0,($D103-SUM($F103:M103)-SUM($F42:M42))*SAP_Leadsheet!$E$53) -> 0 | ... BN42: =IF(OR($C103>BN$7,$C103+$E103-2<BN$7),0,($D103-SUM($F103:BM103)-SUM($F42:BM42))*SAP_Leadsheet!$E$53) -> 0
C43: 7 | G43: =IF(OR($C104>G$7,$C104+$E104-2<G$7),0,($D104-SUM($F104:F104)-SUM($F43:F43))*SAP_Leadsheet!$E$53) -> 0 | H43: =IF(OR($C104>H$7,$C104+$E104-2<H$7),0,($D104-SUM($F104:G104)-SUM($F43:G43))*SAP_Leadsheet!$E$53) -> 0 | I43: =IF(OR($C104>I$7,$C104+$E104-2<I$7),0,($D104-SUM($F104:H104)-SUM($F43:H43))*SAP_Leadsheet!$E$53) -> 0 | J43: =IF(OR($C104>J$7,$C104+$E104-2<J$7),0,($D104-SUM($F104:I104)-SUM($F43:I43))*SAP_Leadsheet!$E$53) -> 0 | K43: =IF(OR($C104>K$7,$C104+$E104-2<K$7),0,($D104-SUM($F104:J104)-SUM($F43:J43))*SAP_Leadsheet!$E$53) -> 0 | L43: =IF(OR($C104>L$7,$C104+$E104-2<L$7),0,($D104-SUM($F104:K104)-SUM($F43:K43))*SAP_Leadsheet!$E$53) -> 0 | M43: =IF(OR($C104>M$7,$C104+$E104-2<M$7),0,($D104-SUM($F104:L104)-SUM($F43:L43))*SAP_Leadsheet!$E$53) -> 0 | N43: =IF(OR($C104>N$7,$C104+$E104-2<N$7),0,($D104-SUM($F104:M104)-SUM($F43:M43))*SAP_Leadsheet!$E$53) -> 0 | ... BN43: =IF(OR($C104>BN$7,$C104+$E104-2<BN$7),0,($D104-SUM($F104:BM104)-SUM($F43:BM43))*SAP_Leadsheet!$E$53) -> 0
C44: 8 | G44: =IF(OR($C105>G$7,$C105+$E105-2<G$7),0,($D105-SUM($F105:F105)-SUM($F44:F44))*SAP_Leadsheet!$E$53) -> 0 | H44: =IF(OR($C105>H$7,$C105+$E105-2<H$7),0,($D105-SUM($F105:G105)-SUM($F44:G44))*SAP_Leadsheet!$E$53) -> 0 | I44: =IF(OR($C105>I$7,$C105+$E105-2<I$7),0,($D105-SUM($F105:H105)-SUM($F44:H44))*SAP_Leadsheet!$E$53) -> 0 | J44: =IF(OR($C105>J$7,$C105+$E105-2<J$7),0,($D105-SUM($F105:I105)-SUM($F44:I44))*SAP_Leadsheet!$E$53) -> 0 | K44: =IF(OR($C105>K$7,$C105+$E105-2<K$7),0,($D105-SUM($F105:J105)-SUM($F44:J44))*SAP_Leadsheet!$E$53) -> 0 | L44: =IF(OR($C105>L$7,$C105+$E105-2<L$7),0,($D105-SUM($F105:K105)-SUM($F44:K44))*SAP_Leadsheet!$E$53) -> 0 | M44: =IF(OR($C105>M$7,$C105+$E105-2<M$7),0,($D105-SUM($F105:L105)-SUM($F44:L44))*SAP_Leadsheet!$E$53) -> 0 | N44: =IF(OR($C105>N$7,$C105+$E105-2<N$7),0,($D105-SUM($F105:M105)-SUM($F44:M44))*SAP_Leadsheet!$E$53) -> 0 | ... BN44: =IF(OR($C105>BN$7,$C105+$E105-2<BN$7),0,($D105-SUM($F105:BM105)-SUM($F44:BM44))*SAP_Leadsheet!$E$53) -> 0
C45: 9 | G45: =IF(OR($C106>G$7,$C106+$E106-2<G$7),0,($D106-SUM($F106:F106)-SUM($F45:F45))*SAP_Leadsheet!$E$53) -> 0 | H45: =IF(OR($C106>H$7,$C106+$E106-2<H$7),0,($D106-SUM($F106:G106)-SUM($F45:G45))*SAP_Leadsheet!$E$53) -> 0 | I45: =IF(OR($C106>I$7,$C106+$E106-2<I$7),0,($D106-SUM($F106:H106)-SUM($F45:H45))*SAP_Leadsheet!$E$53) -> 0 | J45: =IF(OR($C106>J$7,$C106+$E106-2<J$7),0,($D106-SUM($F106:I106)-SUM($F45:I45))*SAP_Leadsheet!$E$53) -> 0 | K45: =IF(OR($C106>K$7,$C106+$E106-2<K$7),0,($D106-SUM($F106:J106)-SUM($F45:J45))*SAP_Leadsheet!$E$53) -> 0 | L45: =IF(OR($C106>L$7,$C106+$E106-2<L$7),0,($D106-SUM($F106:K106)-SUM($F45:K45))*SAP_Leadsheet!$E$53) -> 0 | M45: =IF(OR($C106>M$7,$C106+$E106-2<M$7),0,($D106-SUM($F106:L106)-SUM($F45:L45))*SAP_Leadsheet!$E$53) -> 0 | N45: =IF(OR($C106>N$7,$C106+$E106-2<N$7),0,($D106-SUM($F106:M106)-SUM($F45:M45))*SAP_Leadsheet!$E$53) -> 0 | ... BN45: =IF(OR($C106>BN$7,$C106+$E106-2<BN$7),0,($D106-SUM($F106:BM106)-SUM($F45:BM45))*SAP_Leadsheet!$E$53) -> 0
C46: 10 | G46: =IF(OR($C107>G$7,$C107+$E107-2<G$7),0,($D107-SUM($F107:F107)-SUM($F46:F46))*SAP_Leadsheet!$E$53) -> 0 | H46: =IF(OR($C107>H$7,$C107+$E107-2<H$7),0,($D107-SUM($F107:G107)-SUM($F46:G46))*SAP_Leadsheet!$E$53) -> 0 | I46: =IF(OR($C107>I$7,$C107+$E107-2<I$7),0,($D107-SUM($F107:H107)-SUM($F46:H46))*SAP_Leadsheet!$E$53) -> 0 | J46: =IF(OR($C107>J$7,$C107+$E107-2<J$7),0,($D107-SUM($F107:I107)-SUM($F46:I46))*SAP_Leadsheet!$E$53) -> 0 | K46: =IF(OR($C107>K$7,$C107+$E107-2<K$7),0,($D107-SUM($F107:J107)-SUM($F46:J46))*SAP_Leadsheet!$E$53) -> 0 | L46: =IF(OR($C107>L$7,$C107+$E107-2<L$7),0,($D107-SUM($F107:K107)-SUM($F46:K46))*SAP_Leadsheet!$E$53) -> 0 | M46: =IF(OR($C107>M$7,$C107+$E107-2<M$7),0,($D107-SUM($F107:L107)-SUM($F46:L46))*SAP_Leadsheet!$E$53) -> 0 | N46: =IF(OR($C107>N$7,$C107+$E107-2<N$7),0,($D107-SUM($F107:M107)-SUM($F46:M46))*SAP_Leadsheet!$E$53) -> 0 | ... BN46: =IF(OR($C107>BN$7,$C107+$E107-2<BN$7),0,($D107-SUM($F107:BM107)-SUM($F46:BM46))*SAP_Leadsheet!$E$53) -> 0
C47: 11 | G47: =IF(OR($C108>G$7,$C108+$E108-2<G$7),0,($D108-SUM($F108:F108)-SUM($F47:F47))*SAP_Leadsheet!$E$53) -> 0 | H47: =IF(OR($C108>H$7,$C108+$E108-2<H$7),0,($D108-SUM($F108:G108)-SUM($F47:G47))*SAP_Leadsheet!$E$53) -> 0 | I47: =IF(OR($C108>I$7,$C108+$E108-2<I$7),0,($D108-SUM($F108:H108)-SUM($F47:H47))*SAP_Leadsheet!$E$53) -> 0 | J47: =IF(OR($C108>J$7,$C108+$E108-2<J$7),0,($D108-SUM($F108:I108)-SUM($F47:I47))*SAP_Leadsheet!$E$53) -> 0 | K47: =IF(OR($C108>K$7,$C108+$E108-2<K$7),0,($D108-SUM($F108:J108)-SUM($F47:J47))*SAP_Leadsheet!$E$53) -> 0 | L47: =IF(OR($C108>L$7,$C108+$E108-2<L$7),0,($D108-SUM($F108:K108)-SUM($F47:K47))*SAP_Leadsheet!$E$53) -> 0 | M47: =IF(OR($C108>M$7,$C108+$E108-2<M$7),0,($D108-SUM($F108:L108)-SUM($F47:L47))*SAP_Leadsheet!$E$53) -> 0 | N47: =IF(OR($C108>N$7,$C108+$E108-2<N$7),0,($D108-SUM($F108:M108)-SUM($F47:M47))*SAP_Leadsheet!$E$53) -> 0 | ... BN47: =IF(OR($C108>BN$7,$C108+$E108-2<BN$7),0,($D108-SUM($F108:BM108)-SUM($F47:BM47))*SAP_Leadsheet!$E$53) -> 0
C48: 12 | G48: =IF(OR($C109>G$7,$C109+$E109-2<G$7),0,($D109-SUM($F109:F109)-SUM($F48:F48))*SAP_Leadsheet!$E$53) -> 0 | H48: =IF(OR($C109>H$7,$C109+$E109-2<H$7),0,($D109-SUM($F109:G109)-SUM($F48:G48))*SAP_Leadsheet!$E$53) -> 0 | I48: =IF(OR($C109>I$7,$C109+$E109-2<I$7),0,($D109-SUM($F109:H109)-SUM($F48:H48))*SAP_Leadsheet!$E$53) -> 0 | J48: =IF(OR($C109>J$7,$C109+$E109-2<J$7),0,($D109-SUM($F109:I109)-SUM($F48:I48))*SAP_Leadsheet!$E$53) -> 0 | K48: =IF(OR($C109>K$7,$C109+$E109-2<K$7),0,($D109-SUM($F109:J109)-SUM($F48:J48))*SAP_Leadsheet!$E$53) -> 0 | L48: =IF(OR($C109>L$7,$C109+$E109-2<L$7),0,($D109-SUM($F109:K109)-SUM($F48:K48))*SAP_Leadsheet!$E$53) -> 0 | M48: =IF(OR($C109>M$7,$C109+$E109-2<M$7),0,($D109-SUM($F109:L109)-SUM($F48:L48))*SAP_Leadsheet!$E$53) -> 0 | N48: =IF(OR($C109>N$7,$C109+$E109-2<N$7),0,($D109-SUM($F109:M109)-SUM($F48:M48))*SAP_Leadsheet!$E$53) -> 0 | ... BN48: =IF(OR($C109>BN$7,$C109+$E109-2<BN$7),0,($D109-SUM($F109:BM109)-SUM($F48:BM48))*SAP_Leadsheet!$E$53) -> 0
C49: 13 | G49: =IF(OR($C110>G$7,$C110+$E110-2<G$7),0,($D110-SUM($F110:F110)-SUM($F49:F49))*SAP_Leadsheet!$E$53) -> 0 | H49: =IF(OR($C110>H$7,$C110+$E110-2<H$7),0,($D110-SUM($F110:G110)-SUM($F49:G49))*SAP_Leadsheet!$E$53) -> 0 | I49: =IF(OR($C110>I$7,$C110+$E110-2<I$7),0,($D110-SUM($F110:H110)-SUM($F49:H49))*SAP_Leadsheet!$E$53) -> 0 | J49: =IF(OR($C110>J$7,$C110+$E110-2<J$7),0,($D110-SUM($F110:I110)-SUM($F49:I49))*SAP_Leadsheet!$E$53) -> 0 | K49: =IF(OR($C110>K$7,$C110+$E110-2<K$7),0,($D110-SUM($F110:J110)-SUM($F49:J49))*SAP_Leadsheet!$E$53) -> 0 | L49: =IF(OR($C110>L$7,$C110+$E110-2<L$7),0,($D110-SUM($F110:K110)-SUM($F49:K49))*SAP_Leadsheet!$E$53) -> 0 | M49: =IF(OR($C110>M$7,$C110+$E110-2<M$7),0,($D110-SUM($F110:L110)-SUM($F49:L49))*SAP_Leadsheet!$E$53) -> 0 | N49: =IF(OR($C110>N$7,$C110+$E110-2<N$7),0,($D110-SUM($F110:M110)-SUM($F49:M49))*SAP_Leadsheet!$E$53) -> 0 | ... BN49: =IF(OR($C110>BN$7,$C110+$E110-2<BN$7),0,($D110-SUM($F110:BM110)-SUM($F49:BM49))*SAP_Leadsheet!$E$53) -> 0
...

Sheet Sales plan& PnL
E1: PROFIT & LOSS 60M | H1: =SAP_Leadsheet!C6 -> DPD180+
A3: Code | B3: Product | C3: Old/new | D3: Item | F3: I. | G3: SALES PLAN
A4: =B4&D4&C4 -> Auto loan | B4: Auto loan
H5: If you want to estimate the mix price & promotion tenor for your product package, please input here & link to Leadsheet properly in term of pricing
A6: =B6&D6&C6 -> Auto loan | B6: Auto loan | H6: Please input your expected disbursement volume with date of lauching out product if you would like to project 60M profit and loss.
A8: =B8&D8&C8 -> Auto loan | B8: Auto loan | H8: Business month | J8: 45658 | K8: =EOMONTH(J8,1) -> 45716 | L8: =EOMONTH(K8,1) -> 45747 | M8: =EOMONTH(L8,1) -> 45777 | N8: =EOMONTH(M8,1) -> 45808 | O8: =EOMONTH(N8,1) -> 45838 | P8: =EOMONTH(O8,1) -> 45869 | Q8: =EOMONTH(P8,1) -> 45900 | R8: =EOMONTH(Q8,1) -> 45930 | ... BR8: =EOMONTH(BQ8,1) -> 47514
H9: Don't delete | J9: =YEAR(J8) -> 2025 | K9: =YEAR(K8) -> 2025 | L9: =YEAR(L8) -> 2025 | M9: =YEAR(M8) -> 2025 | N9: =YEAR(N8) -> 2025 | O9: =YEAR(O8) -> 2025 | P9: =YEAR(P8) -> 2025 | Q9: =YEAR(Q8) -> 2025 | ... BR9: =YEAR(BR8) -> 2030
A10: =B10&D10&C10 -> Auto loan | B10: Auto loan | H10: New issued (Card)
F12: II. | G12: PROFIT & LOSS
H14: FISCAL YEAR | J14: Total | K14: =J9 -> 2025 | L14: =K14+1 -> 2026 | M14: =L14+1 -> 2027 | N14: =M14+1 -> 2028 | O14: =N14+1 -> 2029 | P14: =O14+1 -> 2030
J15: bVND | K15: bVND | L15: bVND | M15: bVND | N15: bVND | O15: bVND | P15: bVND
H17: New Issued Paylater | J17: =SUM(K17:U17) -> 0 | K17: =SUMIF($J$9:$BQ$9,K$14,$J$10:$BQ$10) -> 0 | L17: =SUMIF($J$9:$BQ$9,L$14,$J$10:$BQ$10) -> 0 | M17: =SUMIF($J$9:$BQ$9,M$14,$J$10:$BQ$10) -> 0 | N17: =SUMIF($J$9:$BQ$9,N$14,$J$10:$BQ$10) -> 0 | O17: =SUMIF($J$9:$BQ$9,O$14,$J$10:$BQ$10) -> 0 | P17: =SUMIF($J$9:$BQ$9,P$14,$J$10:$BQ$10) -> 0
H18: Average monthly issued Paylater | J18: =AVERAGE(J10:AS10) -> #DIV/0! | K18: =K17/COUNTIF($J$9:$AS$9,K14) -> 0 | L18: =L17/COUNTIF($J$9:$AS$9,L14) -> 0 | M18: =M17/COUNTIF($J$9:$AS$9,M14) -> 0 | N18: =N17/COUNTIF($J$9:$BQ$9,N14) -> 0 | O18: =O17/COUNTIF($J$9:$BQ$9,O14) -> 0 | P18: =IFERROR(P17/COUNTIF($J$9:$BQ$9,P14),0) -> 0
H20: EOP | K20: =OFFSET(PnL_Speadsheet!$D$7,0,MATCH(DATE('Sales plan& PnL'!K$14,12,31),PnL_Speadsheet!$E$4:$BL$4,0))/1000 -> 0 | L20: =OFFSET(PnL_Speadsheet!$D$7,0,MATCH(DATE('Sales plan& PnL'!L$14,12,31),PnL_Speadsheet!$E$4:$BL$4,0))/1000 -> 0 | M20: =OFFSET(PnL_Speadsheet!$D$7,0,MATCH(DATE('Sales plan& PnL'!M$14,12,31),PnL_Speadsheet!$E$4:$BL$4,0))/1000 -> 0 | N20: =OFFSET(PnL_Speadsheet!$D$7,0,MATCH(DATE('Sales plan& PnL'!N$14,12,31),PnL_Speadsheet!$E$4:$BL$4,0))/1000 -> 0 | O20: =PnL_Speadsheet!BL7/1000 -> 0 | P20: =PnL_Speadsheet!BN7/1000 -> 0
H21: ADB | J21: =SUM(PnL_Speadsheet!E8:BK8)/1000/COUNT(PnL_Speadsheet!E3:BK3) -> 0 | K21: =SUMIF(PnL_Speadsheet!$E$3:$BL$3,K$14,PnL_Speadsheet!$E8:$BL8)/1000/COUNTIF(PnL_Speadsheet!$E$3:$BL$3,'Sales plan& PnL'!K$14) -> 0 | L21: =SUMIF(PnL_Speadsheet!$E$3:$BL$3,L$14,PnL_Speadsheet!$E8:$BL8)/1000/COUNTIF(PnL_Speadsheet!$E$3:$BL$3,'Sales plan& PnL'!L$14) -> 0 | M21: =SUMIF(PnL_Speadsheet!$E$3:$BL$3,M$14,PnL_Speadsheet!$E8:$BL8)/1000/COUNTIF(PnL_Speadsheet!$E$3:$BL$3,'Sales plan& PnL'!M$14) -> 0 | N21: =SUMIF(PnL_Speadsheet!$E$3:$BL$3,N$14,PnL_Speadsheet!$E8:$BL8)/1000/COUNTIF(PnL_Speadsheet!$E$3:$BL$3,'Sales plan& PnL'!N$14) -> 0 | O21: =SUMIF(PnL_Speadsheet!$E$3:$BL$3,O$14,PnL_Speadsheet!$E8:$BL8)/1000/COUNTIF(PnL_Speadsheet!$E$3:$BL$3,'Sales plan& PnL'!O$14) -> 0 | P21: =IFERROR(SUMIF(PnL_Speadsheet!$E$3:$BL$3,P$14,PnL_Speadsheet!$E8:$BL8)/1000/COUNTIF(PnL_Speadsheet!$E$3:$BL$3,'Sales plan& PnL'!P$14),0) -> 0
H23: TOI | J23: =SUM(K23:U23) -> 0 | K23: =SUMIF(PnL_Speadsheet!$E$3:$BL$3,K$14,PnL_Speadsheet!$E9:$BL9)/1000 -> 0 | L23: =SUMIF(PnL_Speadsheet!$E$3:$BL$3,L$14,PnL_Speadsheet!$E9:$BL9)/1000 -> 0 | M23: =SUMIF(PnL_Speadsheet!$E$3:$BL$3,M$14,PnL_Speadsheet!$E9:$BL9)/1000 -> 0 | N23: =SUMIF(PnL_Speadsheet!$E$3:$BL$3,N$14,PnL_Speadsheet!$E9:$BL9)/1000 -> 0 | O23: =SUMIF(PnL_Speadsheet!$E$3:$BL$3,O$14,PnL_Speadsheet!$E9:$BL9)/1000 -> 0 | P23: =SUMIF(PnL_Speadsheet!$E$3:$BL$3,P$14,PnL_Speadsheet!$E9:$BL9)/1000 -> 0
H24: NII | J24: =SUM(K24:U24) -> 0 | K24: =SUMIF(PnL_Speadsheet!$E$3:$BL$3,K$14,PnL_Speadsheet!$E10:$BL10)/1000 -> 0 | L24: =SUMIF(PnL_Speadsheet!$E$3:$BL$3,L$14,PnL_Speadsheet!$E10:$BL10)/1000 -> 0 | M24: =SUMIF(PnL_Speadsheet!$E$3:$BL$3,M$14,PnL_Speadsheet!$E10:$BL10)/1000 -> 0 | N24: =SUMIF(PnL_Speadsheet!$E$3:$BL$3,N$14,PnL_Speadsheet!$E10:$BL10)/1000 -> 0 | O24: =SUMIF(PnL_Speadsheet!$E$3:$BL$3,O$14,PnL_Speadsheet!$E10:$BL10)/1000 -> 0 | P24: =SUMIF(PnL_Speadsheet!$E$3:$BL$3,P$14,PnL_Speadsheet!$E10:$BL10)/1000 -> 0
H25: CII | J25: =SUM(K25:U25) -> 0 | K25: =SUMIF(PnL_Speadsheet!$E$3:$BL$3,K$14,PnL_Speadsheet!$E11:$BL11)/1000 -> 0 | L25: =SUMIF(PnL_Speadsheet!$E$3:$BL$3,L$14,PnL_Speadsheet!$E11:$BL11)/1000 -> 0 | M25: =SUMIF(PnL_Speadsheet!$E$3:$BL$3,M$14,PnL_Speadsheet!$E11:$BL11)/1000 -> 0 | N25: =SUMIF(PnL_Speadsheet!$E$3:$BL$3,N$14,PnL_Speadsheet!$E11:$BL11)/1000 -> 0 | O25: =SUMIF(PnL_Speadsheet!$E$3:$BL$3,O$14,PnL_Speadsheet!$E11:$BL11)/1000 -> 0 | P25: =SUMIF(PnL_Speadsheet!$E$3:$BL$3,P$14,PnL_Speadsheet!$E11:$BL11)/1000 -> 0
H26: COF | J26: =SUM(K26:U26) -> 0 | K26: =SUMIF(PnL_Speadsheet!$E$3:$BL$3,K$14,PnL_Speadsheet!$E12:$BL12)/1000 -> 0 | L26: =SUMIF(PnL_Speadsheet!$E$3:$BL$3,L$14,PnL_Speadsheet!$E12:$BL12)/1000 -> 0 | M26: =SUMIF(PnL_Speadsheet!$E$3:$BL$3,M$14,PnL_Speadsheet!$E12:$BL12)/1000 -> 0 | N26: =SUMIF(PnL_Speadsheet!$E$3:$BL$3,N$14,PnL_Speadsheet!$E12:$BL12)/1000 -> 0 | O26: =SUMIF(PnL_Speadsheet!$E$3:$BL$3,O$14,PnL_Speadsheet!$E12:$BL12)/1000 -> 0 | P26: =SUMIF(PnL_Speadsheet!$E$3:$BL$3,P$14,PnL_Speadsheet!$E12:$BL12)/1000 -> 0
H27: NFI | J27: =SUM(K27:U27) -> 0 | K27: =SUMIF(PnL_Speadsheet!$E$3:$BL$3,K$14,PnL_Speadsheet!$E13:$BL13)/1000 -> 0 | L27: =SUMIF(PnL_Speadsheet!$E$3:$BL$3,L$14,PnL_Speadsheet!$E13:$BL13)/1000 -> 0 | M27: =SUMIF(PnL_Speadsheet!$E$3:$BL$3,M$14,PnL_Speadsheet!$E13:$BL13)/1000 -> 0 | N27: =SUMIF(PnL_Speadsheet!$E$3:$BL$3,N$14,PnL_Speadsheet!$E13:$BL13)/1000 -> 0 | O27: =SUMIF(PnL_Speadsheet!$E$3:$BL$3,O$14,PnL_Speadsheet!$E13:$BL13)/1000 -> 0 | P27: =SUMIF(PnL_Speadsheet!$E$3:$BL$3,P$14,PnL_Speadsheet!$E13:$BL13)/1000 -> 0
H28: Annual fee | J28: =SUM(K28:U28) -> 0 | K28: =SUMIF(PnL_Speadsheet!$E$3:$BL$3,K$14,PnL_Speadsheet!$E14:$BL14)/1000 -> 0 | L28: =SUMIF(PnL_Speadsheet!$E$3:$BL$3,L$14,PnL_Speadsheet!$E14:$BL14)/1000 -> 0 | M28: =SUMIF(PnL_Speadsheet!$E$3:$BL$3,M$14,PnL_Speadsheet!$E14:$BL14)/1000 -> 0 | N28: =SUMIF(PnL_Speadsheet!$E$3:$BL$3,N$14,PnL_Speadsheet!$E14:$BL14)/1000 -> 0 | O28: =SUMIF(PnL_Speadsheet!$E$3:$BL$3,O$14,PnL_Speadsheet!$E14:$BL14)/1000 -> 0 | P28: =SUMIF(PnL_Speadsheet!$E$3:$BL$3,P$14,PnL_Speadsheet!$E14:$BL14)/1000 -> 0
H29: Monthly fee | J29: =SUM(K29:U29) -> 0 | K29: =SUMIF(PnL_Speadsheet!$E$3:$BL$3,K$14,PnL_Speadsheet!$E15:$BL15)/1000 -> 0 | L29: =SUMIF(PnL_Speadsheet!$E$3:$BL$3,L$14,PnL_Speadsheet!$E15:$BL15)/1000 -> 0 | M29: =SUMIF(PnL_Speadsheet!$E$3:$BL$3,M$14,PnL_Speadsheet!$E15:$BL15)/1000 -> 0 | N29: =SUMIF(PnL_Speadsheet!$E$3:$BL$3,N$14,PnL_Speadsheet!$E15:$BL15)/1000 -> 0 | O29: =SUMIF(PnL_Speadsheet!$E$3:$BL$3,O$14,PnL_Speadsheet!$E15:$BL15)/1000 -> 0 | P29: =SUMIF(PnL_Speadsheet!$E$3:$BL$3,P$14,PnL_Speadsheet!$E15:$BL15)/1000 -> 0
H30: Transaction fee | J30: =SUM(K30:U30) -> 0 | K30: =SUMIF(PnL_Speadsheet!$E$3:$BL$3,K$14,PnL_Speadsheet!$E16:$BL16)/1000 -> 0 | L30: =SUMIF(PnL_Speadsheet!$E$3:$BL$3,L$14,PnL_Speadsheet!$E16:$BL16)/1000 -> 0 | M30: =SUMIF(PnL_Speadsheet!$E$3:$BL$3,M$14,PnL_Speadsheet!$E16:$BL16)/1000 -> 0 | N30: =SUMIF(PnL_Speadsheet!$E$3:$BL$3,N$14,PnL_Speadsheet!$E16:$BL16)/1000 -> 0 | O30: =SUMIF(PnL_Speadsheet!$E$3:$BL$3,O$14,PnL_Speadsheet!$E16:$BL16)/1000 -> 0 | P30: =SUMIF(PnL_Speadsheet!$E$3:$BL$3,P$14,PnL_Speadsheet!$E16:$BL16)/1000 -> 0
H31: Issuance fee | J31: =SUM(K31:U31) -> 0 | K31: =SUMIF(PnL_Speadsheet!$E$3:$BL$3,K$14,PnL_Speadsheet!$E17:$BL17)/1000 -> 0 | L31: =SUMIF(PnL_Speadsheet!$E$3:$BL$3,L$14,PnL_Speadsheet!$E17:$BL17)/1000 -> 0 | M31: =SUMIF(PnL_Speadsheet!$E$3:$BL$3,M$14,PnL_Speadsheet!$E17:$BL17)/1000 -> 0 | N31: =SUMIF(PnL_Speadsheet!$E$3:$BL$3,N$14,PnL_Speadsheet!$E17:$BL17)/1000 -> 0 | O31: =SUMIF(PnL_Speadsheet!$E$3:$BL$3,O$14,PnL_Speadsheet!$E17:$BL17)/1000 -> 0 | P31: =SUMIF(PnL_Speadsheet!$E$3:$BL$3,P$14,PnL_Speadsheet!$E17:$BL17)/1000 -> 0
H32: Subvention fee | J32: =SUM(K32:U32) -> 0 | K32: =SUMIF(PnL_Speadsheet!$E$3:$BL$3,K$14,PnL_Speadsheet!$E18:$BL18)/1000 -> 0 | L32: =SUMIF(PnL_Speadsheet!$E$3:$BL$3,L$14,PnL_Speadsheet!$E18:$BL18)/1000 -> 0 | M32: =SUMIF(PnL_Speadsheet!$E$3:$BL$3,M$14,PnL_Speadsheet!$E18:$BL18)/1000 -> 0 | N32: =SUMIF(PnL_Speadsheet!$E$3:$BL$3,N$14,PnL_Speadsheet!$E18:$BL18)/1000 -> 0 | O32: =SUMIF(PnL_Speadsheet!$E$3:$BL$3,O$14,PnL_Speadsheet!$E18:$BL18)/1000 -> 0 | P32: =SUMIF(PnL_Speadsheet!$E$3:$BL$3,P$14,PnL_Speadsheet!$E18:$BL18)/1000 -> 0
H33: Late payment | J33: =SUM(K33:U33) -> 0 | K33: =SUMIF(PnL_Speadsheet!$E$3:$BL$3,K$14,PnL_Speadsheet!$E19:$BL19)/1000 -> 0 | L33: =SUMIF(PnL_Speadsheet!$E$3:$BL$3,L$14,PnL_Speadsheet!$E19:$BL19)/1000 -> 0 | M33: =SUMIF(PnL_Speadsheet!$E$3:$BL$3,M$14,PnL_Speadsheet!$E19:$BL19)/1000 -> 0 | N33: =SUMIF(PnL_Speadsheet!$E$3:$BL$3,N$14,PnL_Speadsheet!$E19:$BL19)/1000 -> 0 | O33: =SUMIF(PnL_Speadsheet!$E$3:$BL$3,O$14,PnL_Speadsheet!$E19:$BL19)/1000 -> 0 | P33: =SUMIF(PnL_Speadsheet!$E$3:$BL$3,P$14,PnL_Speadsheet!$E19:$BL19)/1000 -> 0
H34: Min due fee | J34: =SUM(K34:U34) -> 0 | K34: =SUMIF(PnL_Speadsheet!$E$3:$BL$3,K$14,PnL_Speadsheet!$E20:$BL20)/1000 -> 0 | L34: =SUMIF(PnL_Speadsheet!$E$3:$BL$3,L$14,PnL_Speadsheet!$E20:$BL20)/1000 -> 0 | M34: =SUMIF(PnL_Speadsheet!$E$3:$BL$3,M$14,PnL_Speadsheet!$E20:$BL20)/1000 -> 0 | N34: =SUMIF(PnL_Speadsheet!$E$3:$BL$3,N$14,PnL_Speadsheet!$E20:$BL20)/1000 -> 0 | O34: =SUMIF(PnL_Speadsheet!$E$3:$BL$3,O$14,PnL_Speadsheet!$E20:$BL20)/1000 -> 0 | P34: =SUMIF(PnL_Speadsheet!$E$3:$BL$3,P$14,PnL_Speadsheet!$E20:$BL20)/1000 -> 0
... H38: Other income | J38: =SUM(K38:U38) -> 0 | K38: =SUMIF(PnL_Speadsheet!$E$3:$BL$3,K$14,PnL_Speadsheet!$E24:$BL24)/1000 -> 0 | L38: =SUMIF(PnL_Speadsheet!$E$3:$BL$3,L$14,PnL_Speadsheet!$E24:$BL24)/1000 -> 0 | M38: =SUMIF(PnL_Speadsheet!$E$3:$BL$3,M$14,PnL_Speadsheet!$E24:$BL24)/1000 -> 0 | N38: =SUMIF(PnL_Speadsheet!$E$3:$BL$3,N$14,PnL_Speadsheet!$E24:$BL24)/1000 -> 0 | O38: =SUMIF(PnL_Speadsheet!$E$3:$BL$3,O$14,PnL_Speadsheet!$E24:$BL24)/1000 -> 0 | P38: =SUMIF(PnL_Speadsheet!$E$3:$BL$3,P$14,PnL_Speadsheet!$E24:$BL24)/1000 -> 0
