Workbook

Sheet Sales Plan 2026 - fin v4
X1: 875394.36 | Y1: 922073.47 | Z1: 1002542.4 | AA1: 866824.65
X2: 474605.64 | Y2: 477926.53 | Z2: 500457.64 | AA2: 633175.35
X3: 0 | Y3: 0 | Z3: 0
X4: 0 | Y4: 0 | Z4: 0
X5: 1350000 | Y5: 1400000 | Z5: 1503000
A6: BASE CASE | B6: 2 | C6: 3 | D6: 4 | E6: 5 | F6: 6 | G6: 7 | H6: 8 | I6: 9 | J6: 10 | K6: 11 | L6: 12 | M6: 13 | X6: 1350000 | Y6: 1400000 | Z6: 1503000
A7: Growth rate_VDS | B7: 323385.09 | C7: 266374.9 | D7: 360136.61 | E7: 414390.82 | F7: 406686.28 | G7: 426354.68 | H7: 563773.05 | I7: 536583.98 | J7: 736960.97 | K7: 814274.6 | L7: 860000 | M7: 903000 | N7: 558.33333 | O7: 0.03 | P7: -0.1 | Q7: 0.03 | R7: 0.03 | S7: 0.04 | T7: 0.04 | U7: 0.04 | V7: 0.04 | W7: 0.05 | X7: 0.05 | Y7: 0.05 | Z7: 0.05 | AA7: 3345841.4 | AD7: 0.81818182 | AM7: 0.05 | AN7: -0.1 | AO7: 0.05 | AP7: 0.05 | AQ7: 0.05 | AR7: 0.05 | AS7: 0.05 | AT7: 0.05 | AU7: 0.05 | AV7: 0.05 | AW7: 0.05 | AX7: 0.05 | BA7: 0.05 | BB7: -0.1 | BC7: 0.05 | BD7: 0.05 | BE7: 0.05 | BF7: 0.05 | BG7: 0.05 | BH7: 0.05 | BI7: 0.05 | BJ7: 0.05 | BK7: 0.05 | BL7: 0.05 | BO7: 0.05 | BP7: -0.1 | BQ7: 0.05 | BR7: 0.05 | BS7: 0.05 | BT7: 0.05 | BU7: 0.05 | BV7: 0.05 | BW7: 0.05 | BX7: 0.05 | BY7: 0.05 | BZ7: 0.05
K8: TRUE | M8: TRUE | N8: TRUE | AA8: 264
B9: 631570.36 | C9: 532086.84 | D9: 716597.67 | E9: 830767.11 | F9: 877642.74 | G9: 966595.44 | H9: 1316244.1 | I9: 1305289.4 | J9: 1760068.3 | K9: 1971790.3 | L9: 2097306 | M9: 2203270.9 | N9: 15209229 | O9: 2234708.7 | P9: 2023260.5 | Q9: 2407403.3 | R9: 2546233.5 | S9: 2766108.4 | T9: 3083685.9 | U9: 3364946 | V9: 3649659 | W9: 3975987.4 | X9: 4288782.5 | Y9: 4691511.8 | Z9: 5117810.3 | AA9: 40150097 | AC9: 1 | AD9: v3 | AE9: -2075048.6 | AM9: 4783945.8 | AN9: 4459551.2 | AO9: 4946143.1 | AP9: 5116450.3 | AQ9: 5295272.8 | AR9: 5483036.4 | AS9: 5680188.2 | AT9: 5887197.7 | AU9: 6104557.5 | AV9: 6332785.4 | AW9: 6572424.7 | AX9: 6824045.9 | AY9: 67485599 | BA9: 6942273.3 | BB9: 6693995.7 | BC9: 7066412.1 | BD9: 7196757.9 | BE9: 7333620.9 | BF9: 7477327.1 | BG9: 7628218.6 | BH9: 7786654.7 | BI9: 7953012.5 | BJ9: 8127688.3 | BK9: 8311097.8 | BL9: 8503677.9 | BM9: 91020737 | BO9: 8705886.9 | BP9: 8281247.9 | BQ9: 8918206.4 | BR9: 9141141.8 | BS9: 9375224.1 | BT9: 9621010.4 | BU9: 9879086 | BV9: 10150065 | BW9: 10434594 | BX9: 10733349 | BY9: 11047041 | BZ9: 11376418 | CA9: 1.1766327e+08
A10: Product x Partner | B10: 45658 | C10: 45689 | D10: 45717 | E10: 45748 | F10: 45778 | G10: 45809 | H10: 45839 | I10: 45870 | J10: 45901 | K10: 45931 | L10: 45962 | M10: 45992 | N10: FY25 | O10: 46023 | P10: 46054 | Q10: 46082 | R10: 46113 | S10: 46143 | T10: 46174 | U10: 46204 | V10: 46235 | W10: 46266 | X10: 46296 | Y10: 46327 | Z10: 46357 | AA10: FY26 | AD10: 36000000 | AE10: -4150097.2 | AH10: 40763980 | AM10: 46388 | AN10: 46419 | AO10: 46447 | AP10: 46478 | AQ10: 46508 | AR10: 46539 | AS10: 46569 | AT10: 46600 | AU10: 46631 | AV10: 46661 | AW10: 46692 | AX10: 46722 | AY10: FY27 | BA10: 46753 | BB10: 46784 | BC10: 46813 | BD10: 46844 | BE10: 46874 | BF10: 46905 | BG10: 46935 | BH10: 46966 | BI10: 46997 | BJ10: 47027 | BK10: 47058 | BL10: 47088 | BM10: FY28 | BO10: 47119 | BP10: 47150 | BQ10: 47178 | BR10: 47209 | BS10: 47239 | BT10: 47270 | BU10: 47300 | BV10: 47331 | BW10: 47362 | BX10: 47392 | BY10: 47423 | BZ10: 47453 | CA10: FY29
A11: [VDS] - Cashloan | B11: 182010.09 | C11: 132889.9 | D11: 201291.11 | E11: 250592.99 | F11: 238828.11 | G11: 261750.05 | H11: 381775.47 | I11: 347329.4 | J11: 466231.94 | K11: 490981.46 | L11: 500000 | M11: 525000 | N11: 3978680.5 | O11: 538913.11 | P11: 484838.11 | Q11: 555135.61 | R11: 571844.78 | S11: 594792.05 | T11: 618657.21 | U11: 643476.97 | V11: 669289.52 | W11: 702845.84 | X11: 728588.36 | Y11: 783767.78 | Z11: 866824.65 | AA11: 7758974 | AB11: 872594.8 | AC11: 0.1932492 | AD11: 8225920.3 | AE11: -466946.31 | AF11: -38912.192 | AG11: -172920.72 | AH11: 9314479.2 | AL11: 0.22849779 | AM11: 866824.65 | AN11: 866824.65 | AO11: 866824.65 | AP11: 866824.65 | AQ11: 866824.65 | AR11: 866824.65 | AS11: 866824.65 | AT11: 866824.65 | AU11: 866824.65 | AV11: 866824.65 | AW11: 866824.65 | AX11: 866824.65 | AY11: 10401896 | BA11: 866824.65 | BB11: 866824.65 | BC11: 866824.65 | BD11: 866824.65 | BE11: 866824.65 | BF11: 866824.65 | BG11: 866824.65 | BH11: 866824.65 | BI11: 866824.65 | BJ11: 866824.65 | BK11: 866824.65 | BL11: 866824.65 | BM11: 10401896 | BO11: 866824.65 | BP11: 866824.65 | BQ11: 866824.65 | BR11: 866824.65 | BS11: 866824.65 | BT11: 866824.65 | BU11: 866824.65 | BV11: 866824.65 | BW11: 866824.65 | BX11: 866824.65 | BY11: 866824.65 | BZ11: 866824.65 | CA11: 10401896
A12: [VDS] - Payday | B12: 141375 | C12: 133485 | D12: 158845.5 | E12: 163797.83 | F12: 167858.17 | G12: 164604.63 | H12: 181997.58 | I12: 189254.58 | J12: 270729.03 | K12: 323293.14 | L12: 360000 | M12: 378000 | N12: 2633240.5 | O12: 387503.11 | P12: 348569.11 | Q12: 399183.31 | R12: 411213.91 | S12: 427735.94 | T12: 444918.86 | U12: 462789.09 | V12: 481374.13 | W12: 505534.68 | X12: 521411.64 | Y12: 566232.22 | Z12: 633175.35 | AA12: 5589641.3 | AB12: 630405.2 | AC12: 0.13921862 | AD12: 4482180.6 | AE12: 1107460.7 | AF12: 92288.396 | AG12: -172920.72 | AH12: 5075320 | AI12: -1500 | AL12: 0.12450502 | AM12: 633175.35 | AN12: 633175.35 | AO12: 633175.35 | AP12: 633175.35 | AQ12: 633175.35 | AR12: 633175.35 | AS12: 633175.35 | AT12: 633175.35 | AU12: 633175.35 | AV12: 633175.35 | AW12: 633175.35 | AX12: 633175.35 | AY12: 7598104.2 | BA12: 633175.35 | BB12: 633175.35 | BC12: 633175.35 | BD12: 633175.35 | BE12: 633175.35 | BF12: 633175.35 | BG12: 633175.35 | BH12: 633175.35 | BI12: 633175.35 | BJ12: 633175.35 | BK12: 633175.35 | BL12: 633175.35 | BM12: 7598104.2 | BO12: 633175.35 | BP12: 633175.35 | BQ12: 633175.35 | BR12: 633175.35 | BS12: 633175.35 | BT12: 633175.35 | BU12: 633175.35 | BV12: 633175.35 | BW12: 633175.35 | BX12: 633175.35 | BY12: 633175.35 | BZ12: 633175.35 | CA12: 7598104.2
A13: [Cake] - Cashloan | B13: 148327.83 | C13: 111579.44 | D13: 175949.31 | E13: 227662.41 | F13: 232669.35 | G13: 273801.46 | H13: 377695.15 | I13: 338629.71 | J13: 486195.06 | K13: 501046.57 | L13: 518857.68 | M13: 544800.57 | N13: 3937214.5 | O13: 577488.6 | P13: 519739.74 | Q13: 594813.26 | R13: 630502.06 | S13: 668332.18 | T13: 708432.11 | U13: 750938.04 | V13: 795994.32 | W13: 843753.98 | X13: 875394.36 | Y13: 922073.47 | Z13: 1002542.4 | AA13: 8890004.5 | AC13: 0.22141925 | AD13: 9252605.7 | AE13: -362601.26 | AF13: -30216.772 | AG13: -172920.72 | AH13: 10477029 | AI13: -2542.3579 | AJ13: 8887462.1 | AK13: 0.22135593 | AL13: 0.25701683 | AM13: 1236081.4 | AN13: 1112473.3 | AO13: 1297885.5 | AP13: 1362779.8 | AQ13: 1430918.8 | AR13: 1502464.7 | AS13: 1577587.9 | AT13: 1656467.3 | AU13: 1739290.7 | AV13: 1826255.2 | AW13: 1917568 | AX13: 2013446.4 | AY13: 18673219 | BA13: 2013446.4 | BB13: 2013446.4 | BC13: 2013446.4 | BD13: 2013446.4 | BE13: 2013446.4 | BF13: 2013446.4 | BG13: 2013446.4 | BH13: 2013446.4 | BI13: 2013446.4 | BJ13: 2013446.4 | BK13: 2013446.4 | BL13: 2013446.4 | BM13: 24161357 | BO13: 2013446.4 | BP13: 2013446.4 | BQ13: 2013446.4 | BR13: 2013446.4 | BS13: 2013446.4 | BT13: 2013446.4 | BU13: 2013446.4 | BV13: 2013446.4 | BW13: 2013446.4 | BX13: 2013446.4 | BY13: 2013446.4 | BZ13: 2013446.4 | CA13: 24161357
A14: [Cake] - Payday | B14: 0 | C14: 0 | D14: 0 | E14: 0 | F14: 0 | G14: 0 | H14: 54666.36 | I14: 124745.62 | J14: 196888.97 | K14: 261541.76 | L14: 280000 | M14: 294000 | N14: 1211842.7 | O14: 308700 | P14: 277830 | Q14: 324135 | R14: 340341.75 | S14: 357358.84 | T14: 375226.78 | U14: 393988.12 | V14: 413687.52 | W14: 434371.9 | X14: 474605.64 | Y14: 477926.53 | Z14: 500457.64 | AA14: 4678629.7 | AC14: 0.11652848 | AD14: 4163672.6 | AE14: 514957.14 | AF14: 42913.095 | AG14: -172920.72 | AH14: 4714662.9 | AI14: -457.64212 | AJ14: 4678172.1 | AK14: 0.11651708 | AL14: 0.11565757 | AM14: 556236.65 | AN14: 500612.98 | AO14: 584048.48 | AP14: 613250.9 | AQ14: 643913.45 | AR14: 676109.12 | AS14: 709914.58 | AT14: 745410.31 | AU14: 782680.82 | AV14: 821814.86 | AW14: 862905.6 | AX14: 906050.89 | AY14: 8402948.6 | BA14: 906050.89 | BB14: 906050.89 | BC14: 906050.89 | BD14: 906050.89 | BE14: 906050.89 | BF14: 906050.89 | BG14: 906050.89 | BH14: 906050.89 | BI14: 906050.89 | BJ14: 906050.89 | BK14: 906050.89 | BL14: 906050.89 | BM14: 10872611 | BO14: 906050.89 | BP14: 906050.89 | BQ14: 906050.89 | BR14: 906050.89 | BS14: 906050.89 | BT14: 906050.89 | BU14: 906050.89 | BV14: 906050.89 | BW14: 906050.89 | BX14: 906050.89 | BY14: 906050.89 | BZ14: 906050.89 | CA14: 10872611
A15: [MWG] - Cashloan | B15: 16174.22 | C15: 12849.79 | D15: 23384.84 | E15: 28065.69 | F15: 33835.15 | G15: 40487.38 | H15: 52339.69 | I15: 63562 | J15: 100769.4 | K15: 93235.54 | L15: 120000 | M15: 126000 | N15: 710703.7 | O15: 127800.75 | P15: 121410.71 | Q15: 140580.83 | R15: 170916.69 | S15: 188008.36 | T15: 206809.19 | U15: 249155.84 | V15: 274071.42 | W15: 301478.56 | X15: 331626.42 | Y15: 396509.85 | Z15: 436160.83 | AA15: 2944529.5 | AC15: 0.07333804 | AD15: 2369386.3 | AE15: 575143.17 | AF15: 47928.598 | AH15: 2682933.7 | AL15: 0.065816286 | AM15: 457968.88 | AN15: 412171.99 | AO15: 480867.32 | AP15: 504910.69 | AQ15: 530156.22 | AR15: 556664.03 | AS15: 584497.23 | AT15: 613722.09 | AU15: 644408.2 | AV15: 676628.61 | AW15: 710460.04 | AX15: 745983.04 | AY15: 6918438.3 | BA15: 783282.19 | BB15: 704953.97 | BC15: 822446.3 | BD15: 863568.62 | BE15: 906747.05 | BF15: 952084.4 | BG15: 999688.62 | BH15: 1049673.1 | BI15: 1102156.7 | BJ15: 1157264.5 | BK15: 1215127.8 | BL15: 1275884.2 | BM15: 11832877 | BO15: 1339678.4 | BP15: 1205710.5 | BQ15: 1406662.3 | BR15: 1476995.4 | BS15: 1550845.2 | BT15: 1628387.4 | BU15: 1709806.8 | BV15: 1795297.1 | BW15: 1885062 | BX15: 1979315.1 | BY15: 2078280.8 | BZ15: 2182194.9 | CA15: 20238236
A16: [ZLP] - Cashloan | B16: 0 | C16: 0 | D16: 20.33 | E16: 0 | F16: 29177 | G16: 47654.46 | H16: 87997.15 | I16: 83818.31 | J16: 83034.23 | K16: 126424.86 | L16: 128428.7 | M16: 134850.14 | N16: 721405.18 | O16: 138895.64 | P16: 125006.08 | Q16: 143062.51 | R16: 147354.39 | S16: 153248.56 | T16: 159378.5 | U16: 165753.64 | V16: 172383.79 | W16: 181002.98 | X16: 190053.13 | Y16: 199555.78 | Z16: 209533.57 | AA16: 1985228.6 | AC16: 0.049445175 | AD16: 1985097.5 | AE16: 131.04084 | AF16: 10.92007 | AH16: 2247791 | AL16: 0.055141598 | AM16: 220010.25 | AN16: 198009.23 | AO16: 231010.77 | AP16: 242561.3 | AQ16: 254689.37 | AR16: 267423.84 | AS16: 280795.03 | AT16: 294834.78 | AU16: 309576.52 | AV16: 325055.35 | AW16: 341308.11 | AX16: 358373.52 | AY16: 3323648.1 | BA16: 376292.19 | BB16: 338662.97 | BC16: 395106.8 | BD16: 414862.14 | BE16: 435605.25 | BF16: 457385.51 | BG16: 480254.79 | BH16: 504267.53 | BI16: 529480.91 | BJ16: 555954.95 | BK16: 583752.7 | BL16: 612940.33 | BM16: 5684566.1 | BO16: 643587.35 | BP16: 579228.61 | BQ16: 675766.72 | BR16: 709555.05 | BS16: 745032.81 | BT16: 782284.45 | BU16: 821398.67 | BV16: 862468.6 | BW16: 905592.03 | BX16: 950871.63 | BY16: 998415.22 | BZ16: 1048336 | CA16: 9722537.1
A17: [ZLP] - Payday | B17: 0 | C17: 0 | D17: 0 | E17: 0 | F17: 0 | G17: 0 | H17: 0 | I17: 0 | J17: 0 | K17: 0 | L17: 5000 | M17: 5250 | N17: 10250 | O17: 5407.5 | P17: 4866.75 | Q17: 5569.725 | R17: 5736.8168 | S17: 5966.2894 | T17: 6204.941 | U17: 6453.1386 | V17: 6711.2642 | W17: 7046.8274 | X17: 7399.1688 | Y17: 7769.1272 | Z17: 8157.5836 | AA17: 77289.132 | AC17: 0.0019250049 | AD17: 794039.02 | AE17: -716749.88 | AF17: -59729.157 | AH17: 899116.4 | AL17: 0.022056639 | AM17: 8565.4627 | AN17: 7708.9165 | AO17: 8993.7359 | AP17: 9443.4227 | AQ17: 9915.5938 | AR17: 10411.373 | AS17: 10931.942 | AT17: 11478.539 | AU17: 12052.466 | AV17: 12655.09 | AW17: 13287.844 | AX17: 13952.236 | AY17: 129396.62 | BA17: 14649.848 | BB17: 13184.863 | BC17: 15382.34 | BD17: 16151.457 | BE17: 16959.03 | BF17: 17806.982 | BG17: 18697.331 | BH17: 19632.197 | BI17: 20613.807 | BJ17: 21644.498 | BK17: 22726.723 | BL17: 23863.059 | BM17: 221312.14 | BO17: 25056.212 | BP17: 22550.591 | BQ17: 26309.022 | BR17: 27624.473 | BS17: 29005.697 | BT17: 30455.982 | BU17: 31978.781 | BV17: 33577.72 | BW17: 35256.606 | BX17: 37019.436 | BY17: 38870.408 | BZ17: 40813.929 | CA17: 378518.86
A18: Other CL + PD | B18: 10537.81 | C18: 9389.08 | D18: 12006.33 | E18: 13583.92 | F18: 19045.68 | G18: 16901.63 | H18: 13994.08 | I18: 14114.9 | J18: 24352.15 | K18: 35509.82 | L18: 35836.153 | M18: 37627.961 | N18: 242899.51 | AA18: 0 | AC18: 0 | AD18: 529879.57 | AE18: -529879.57 | AF18: -44156.63 | AH18: 600000 | AJ18: 1500 | AL18: 0.014718877 | AM18: 0 | AN18: 0 | AO18: 0 | AP18: 0 | AQ18: 0 | AR18: 0 | AS18: 0 | AT18: 0 | AU18: 0 | AV18: 0 | AW18: 0 | AX18: 0 | AY18: 0 | BA18: 0 | BB18: 0 | BC18: 0 | BD18: 0 | BE18: 0 | BF18: 0 | BG18: 0 | BH18: 0 | BI18: 0 | BJ18: 0 | BK18: 0 | BL18: 0 | BM18: 0 | BO18: 0 | BP18: 0 | BQ18: 0 | BR18: 0 | BS18: 0 | BT18: 0 | BU18: 0 | BV18: 0 | BW18: 0 | BX18: 0 | BY18: 0 | BZ18: 0 | CA18: 0
A19: Tiktok | O19: 0 | P19: 0 | Q19: 0 | R19: 0 | S19: 0 | T19: 0 | U19: 0 | V19: 0 | W19: 0 | X19: 0 | Y19: 0 | Z19: 0 | AA19: 0 | AC19: 0
A20: Shoppee | O20: 0 | P20: 0 | Q20: 0 | R20: 0 | S20: 0 | T20: 0 | U20: 0 | V20: 0 | W20: 0 | X20: 0 | Y20: 0 | Z20: 0 | AA20: 0 | AC20: 0
A21: Misa | O21: 0 | P21: 0 | Q21: 0 | R21: 0 | S21: 0 | T21: 0 | U21: 0 | V21: 0 | W21: 0 | X21: 0 | Y21: 0 | Z21: 0 | AA21: 0 | AC21: 0
A22: Others | O22: 0 | P22: 0 | Q22: 0 | R22: 0 | S22: 0 | T22: 0 | U22: 0 | V22: 0 | W22: 0 | X22: 0 | Y22: 0 | Z22: 0 | AA22: 0 | AC22: 0
A23: [MWG] - Paylater (QTV) | B23: 0 | C23: 0 | D23: 0 | E23: 0 | F23: 17.32 | G23: 2109.7991 | H23: 6670.1321 | I23: 10652.884 | J23: 11801.154 | K23: 19076.948 | L23: 23421.773 | M23: 31453.426 | N23: 105203.44 | O23: 60000 | P23: 51000 | Q23: 78000 | R23: 101400 | S23: 131820 | T23: 171366 | U23: 222775.8 | V23: 289608.54 | W23: 376491.1 | X23: 459319.14 | Y23: 560369.36 | Z23: 683650.61 | AA23: 3185800.6 | AC23: 0.079347269 | AD23: 357611.5 | AE23: 2828189.1 | AF23: 235682.42 | AH23: 404935.22 | AL23: 0.0099336527 | AM23: 717833.15 | AN23: 646049.83 | AO23: 753724.8 | AP23: 791411.04 | AQ23: 830981.59 | AR23: 872530.67 | AS23: 916157.21 | AT23: 961965.07 | AU23: 1010063.3 | AV23: 1060566.5 | AW23: 1113594.8 | AX23: 1169274.6 | AY23: 10844153 | BA23: 1227738.3 | BB23: 1104964.5 | BC23: 1289125.2 | BD23: 1353581.5 | BE23: 1421260.5 | BF23: 1492323.6 | BG23: 1566939.7 | BH23: 1645286.7 | BI23: 1727551.1 | BJ23: 1813928.6 | BK23: 1904625 | BL23: 1999856.3 | BM23: 18547181 | BO23: 2099849.1 | BP23: 1889864.2 | BQ23: 2204841.6 | BR23: 2315083.6 | BS23: 2430837.8 | BT23: 2552379.7 | BU23: 2679998.7 | BV23: 2813998.6 | BW23: 2954698.6 | BX23: 3102433.5 | BY23: 3257555.2 | BZ23: 3420432.9 | CA23: 31721973
A24: Other Paylater (BAU) | B24: 24083.991 | C24: 36640.461 | D24: 33026.916 | E24: 32576.933 | F24: 36674.359 | G24: 40526.528 | H24: 41027.761 | I24: 35877.703 | J24: 33807.241 | K24: 36440.748 | L24: 41522.254 | M24: 42049.387 | N24: 434254.28 | O24: 45000 | P24: 45000 | Q24: 45000 | R24: 45000 | S24: 45000 | T24: 45000 | U24: 45000 | V24: 45000 | W24: 45000 | X24: 45000 | Y24: 45000 | Z24: 45000 | AA24: 540000 | AC24: 0.013449532 | AD24: 589678.91 | AE24: -49678.913 | AF24: -4139.9094 | AH24: 667712.76 | AJ24: 541500 | AL24: 0.01637997 | AM24: 47250 | AN24: 42525 | AO24: 49612.5 | AP24: 52093.125 | AQ24: 54697.781 | AR24: 57432.67 | AS24: 60304.304 | AT24: 63319.519 | AU24: 66485.495 | AV24: 69809.77 | AW24: 73300.258 | AX24: 76965.271 | AY24: 713795.69 | BA24: 80813.535 | BB24: 72732.181 | BC24: 84854.211 | BD24: 89096.922 | BE24: 93551.768 | BF24: 98229.356 | BG24: 103140.82 | BH24: 108297.87 | BI24: 113712.76 | BJ24: 119398.4 | BK24: 125368.32 | BL24: 131636.73 | BM24: 1220832.9 | BO24: 138218.57 | BP24: 124396.71 | BQ24: 145129.5 | BR24: 152385.97 | BS24: 160005.27 | BT24: 168005.53 | BU24: 176405.81 | BV24: 185226.1 | BW24: 194487.41 | BX24: 204211.78 | BY24: 214422.37 | BZ24: 225143.48 | CA24: 2088038.5
A25: [Ecom] - Paylater | B25: 0 | C25: 0 | D25: 0 | E25: 0 | F25: 0 | G25: 0 | H25: 0 | I25: 0 | J25: 0 | K25: 0 | L25: 0 | M25: 0 | N25: 0 | Q25: 76923.077 | R25: 76923.077 | S25: 153846.15 | T25: 307692.31 | U25: 384615.38 | V25: 461538.46 | W25: 538461.54 | X25: 615384.62 | Y25: 692307.69 | Z25: 692307.69 | AA25: 4000000 | AC25: 0.09962616 | AD25: 2296144.8 | AE25: 1703855.2 | AF25: 170385.52 | AH25: 2600000 | AL25: 0.0637818
A26: OD | B26: 109061.42 | C26: 95253.172 | D26: 112073.33 | E26: 114487.34 | F26: 119537.6 | G26: 118759.5 | H26: 118080.71 | I26: 97304.269 | J26: 86259.163 | K26: 84239.415 | L26: 84239.415 | M26: 84239.415 | N26: 1223534.8 | O26: 45000 | P26: 45000 | Q26: 45000 | R26: 45000 | S26: 40000 | T26: 40000 | U26: 40000 | V26: 40000 | W26: 40000 | X26: 40000 | Y26: 40000 | Z26: 40000 | AA26: 500000 | AC26: 0.01245327 | AD26: 953783.22 | AE26: -453783.22 | AF26: -37815.268 | AH26: 1080000 | AL26: 0.026493978 | AM26: 40000 | AN26: 40000 | AO26: 40000 | AP26: 40000 | AQ26: 40000 | AR26: 40000 | AS26: 40000 | AT26: 40000 | AU26: 40000 | AV26: 40000 | AW26: 40000 | AX26: 40000 | AY26: 480000 | BA26: 40000 | BB26: 40000 | BC26: 40000 | BD26: 40000 | BE26: 40000 | BF26: 40000 | BG26: 40000 | BH26: 40000 | BI26: 40000 | BJ26: 40000 | BK26: 40000 | BL26: 40000 | BM26: 480000 | BO26: 40000 | BP26: 40000 | BQ26: 40000 | BR26: 40000 | BS26: 40000 | BT26: 40000 | BU26: 40000 | BV26: 40000 | BW26: 40000 | BX26: 40000 | BY26: 40000 | BZ26: 40000 | CA26: 480000
O28: 0.07 | P28: -0.1 | Q28: 0.05 | R28: 0.05 | S28: 0.05 | T28: 0.05 | U28: 0.05 | V28: 0.05 | W28: 0.05 | X28: 0.05 | Y28: 0.05 | Z28: 0.05
O29: 314580 | P29: 1090658.4 | Q29: 324135 | R29: 291721.5 | S29: 340341.75 | T29: 357358.84 | U29: 375226.78 | V29: 393988.12 | W29: 413687.52 | X29: 434371.9 | Y29: 456090.5 | Z29: 498335.92 | AD29: 0.10033393
AF30: 0
B31: 631570.36 | C31: 532086.84 | D31: 716597.67 | E31: 830767.11 | F31: 877642.74 | G31: 966595.44 | H31: 1316244.1 | I31: 1305289.4 | J31: 1760068.3 | K31: 1971790.3 | L31: 2097306 | M31: 2203270.9 | N31: 15209229 | O31: =SUM(O32:O40) -> 2234708.7 | P31: =SUM(P32:P40) -> 2023260.5 | Q31: =SUM(Q32:Q40) -> 2407403.3 | R31: =SUM(R32:R40) -> 2546233.5 | S31: =SUM(S32:S40) -> 2766108.4 | T31: =SUM(T32:T40) -> 3083685.9 | U31: =SUM(U32:U40) -> 3364946 | V31: =SUM(V32:V40) -> 3649659 | ... AA31: =SUM(AA32:AA40) -> 40150097 | AM31: 4783945.8 | AN31: 4459551.2 | AO31: 4946143.1 | AP31: 5116450.3 | AQ31: 5295272.8 | AR31: 5483036.4 | AS31: 5680188.2 | AT31: 5887197.7 | AU31: 6104557.5 | AV31: 6332785.4 | AW31: 6572424.7 | AX31: 6824045.9 | AY31: 67485599 | BA31: 6942273.3 | BB31: 6693995.7 | BC31: 7066412.1 | BD31: 7196757.9 | BE31: 7333620.9 | BF31: 7477327.1 | BG31: 7628218.6 | BH31: 7786654.7 | BI31: 7953012.5 | BJ31: 8127688.3 | BK31: 8311097.8 | BL31: 8503677.9 | BM31: 91020737 | BO31: 8705886.9 | BP31: 8281247.9 | BQ31: 8918206.4 | BR31: 9141141.8 | BS31: 9375224.1 | BT31: 9621010.4 | BU31: 9879086 | BV31: 10150065 | BW31: 10434594 | BX31: 10733349 | BY31: 11047041 | BZ31: 11376418 | CA31: 1.1766327e+08
A32: VDS | B32: 323385.09 | C32: 266374.9 | D32: 360136.61 | E32: 414390.82 | F32: 406686.28 | G32: 426354.68 | H32: 563773.05 | I32: 536583.98 | J32: 736960.97 | K32: 814274.6 | L32: 860000 | M32: 903000 | N32: 6611921 | O32: 926416.21 | P32: 833407.21 | Q32: 954318.91 | R32: 983058.69 | S32: 1022528 | T32: 1063576.1 | U32: 1106266.1 | V32: 1150663.7 | W32: 1208380.5 | X32: 1250000 | Y32: 1350000 | Z32: 1500000 | AA32: 13348615 | AM32: 1500000 | AN32: 1500000 | AO32: 1500000 | AP32: 1500000 | AQ32: 1500000 | AR32: 1500000 | AS32: 1500000 | AT32: 1500000 | AU32: 1500000 | AV32: 1500000 | AW32: 1500000 | AX32: 1500000 | AY32: 18000000 | BA32: 1500000 | BB32: 1500000 | BC32: 1500000 | BD32: 1500000 | BE32: 1500000 | BF32: 1500000 | BG32: 1500000 | BH32: 1500000 | BI32: 1500000 | BJ32: 1500000 | BK32: 1500000 | BL32: 1500000 | BM32: 18000000 | BO32: 1500000 | BP32: 1500000 | BQ32: 1500000 | BR32: 1500000 | BS32: 1500000 | BT32: 1500000 | BU32: 1500000 | BV32: 1500000 | BW32: 1500000 | BX32: 1500000 | BY32: 1500000 | BZ32: 1500000 | CA32: 18000000
A33: Cake | B33: 148327.83 | C33: 111579.44 | D33: 175949.31 | E33: 227662.41 | F33: 232669.35 | G33: 273801.46 | H33: 432361.51 | I33: 463375.33 | J33: 683084.03 | K33: 762588.33 | L33: 798857.68 | M33: 838800.57 | N33: 5149057.2 | O33: 886188.6 | P33: 797569.74 | Q33: 918948.26 | R33: 970843.81 | S33: 1025691 | T33: 1083658.9 | U33: 1144926.2 | V33: 1209681.8 | W33: 1278125.9 | X33: 1350000 | Y33: 1400000 | Z33: 1503000 | AA33: 13568634 | AM33: 1792318.1 | AN33: 1613086.3 | AO33: 1881934 | AP33: 1976030.7 | AQ33: 2074832.2 | AR33: 2178573.8 | AS33: 2287502.5 | AT33: 2401877.7 | AU33: 2521971.5 | AV33: 2648070.1 | AW33: 2780473.6 | AX33: 2919497.3 | AY33: 27076168 | BA33: 2919497.3 | BB33: 2919497.3 | BC33: 2919497.3 | BD33: 2919497.3 | BE33: 2919497.3 | BF33: 2919497.3 | BG33: 2919497.3 | BH33: 2919497.3 | BI33: 2919497.3 | BJ33: 2919497.3 | BK33: 2919497.3 | BL33: 2919497.3 | BM33: 35033968 | BO33: 2919497.3 | BP33: 2919497.3 | BQ33: 2919497.3 | BR33: 2919497.3 | BS33: 2919497.3 | BT33: 2919497.3 | BU33: 2919497.3 | BV33: 2919497.3 | BW33: 2919497.3 | BX33: 2919497.3 | BY33: 2919497.3 | BZ33: 2919497.3 | CA33: 35033968
A34: MWG | B34: 16174.22 | C34: 12849.79 | D34: 23384.84 | E34: 28065.69 | F34: 33835.15 | G34: 40487.38 | H34: 52339.69 | I34: 63562 | J34: 100769.4 | K34: 93235.54 | L34: 120000 | M34: 126000 | N34: 710703.7 | O34: 127800.75 | P34: 121410.71 | Q34: 140580.83 | R34: 170916.69 | S34: 188008.36 | T34: 206809.19 | U34: 249155.84 | V34: 274071.42 | W34: 301478.56 | X34: 331626.42 | Y34: 396509.85 | Z34: 436160.83 | AA34: 2944529.5 | AM34: 457968.88 | AN34: 412171.99 | AO34: 480867.32 | AP34: 504910.69 | AQ34: 530156.22 | AR34: 556664.03 | AS34: 584497.23 | AT34: 613722.09 | AU34: 644408.2 | AV34: 676628.61 | AW34: 710460.04 | AX34: 745983.04 | AY34: 6918438.3 | BA34: 783282.19 | BB34: 704953.97 | BC34: 822446.3 | BD34: 863568.62 | BE34: 906747.05 | BF34: 952084.4 | BG34: 999688.62 | BH34: 1049673.1 | BI34: 1102156.7 | BJ34: 1157264.5 | BK34: 1215127.8 | BL34: 1275884.2 | BM34: 11832877 | BO34: 1339678.4 | BP34: 1205710.5 | BQ34: 1406662.3 | BR34: 1476995.4 | BS34: 1550845.2 | BT34: 1628387.4 | BU34: 1709806.8 | BV34: 1795297.1 | BW34: 1885062 | BX34: 1979315.1 | BY34: 2078280.8 | BZ34: 2182194.9 | CA34: 20238236
A35: ZLP | B35: 0 | C35: 0 | D35: 20.33 | E35: 0 | F35: 29177 | G35: 47654.46 | H35: 87997.15 | I35: 83818.31 | J35: 83034.23 | K35: 126424.86 | L35: 133428.7 | M35: 140100.14 | N35: 731655.18 | O35: 144303.14 | P35: 129872.83 | Q35: 148632.24 | R35: 153091.2 | S35: 159214.85 | T35: 165583.44 | U35: 172206.78 | V35: 179095.05 | W35: 188049.81 | X35: 197452.3 | Y35: 207324.91 | Z35: 217691.16 | AA35: 2062517.7 | AM35: 228575.72 | AN35: 205718.14 | AO35: 240004.5 | AP35: 252004.73 | AQ35: 264604.96 | AR35: 277835.21 | AS35: 291726.97 | AT35: 306313.32 | AU35: 321628.99 | AV35: 337710.43 | AW35: 354595.96 | AX35: 372325.75 | AY35: 3453044.7 | BA35: 390942.04 | BB35: 351847.84 | BC35: 410489.14 | BD35: 431013.6 | BE35: 452564.28 | BF35: 475192.5 | BG35: 498952.12 | BH35: 523899.73 | BI35: 550094.71 | BJ35: 577599.45 | BK35: 606479.42 | BL35: 636803.39 | BM35: 5905878.2 | BO35: 668643.56 | BP35: 601779.21 | BQ35: 702075.74 | BR35: 737179.53 | BS35: 774038.5 | BT35: 812740.43 | BU35: 853377.45 | BV35: 896046.32 | BW35: 940848.64 | BX35: 987891.07 | BY35: 1037285.6 | BZ35: 1089149.9 | CA35: 10101056
A36: Other CL + PD | B36: 10537.81 | C36: 9389.08 | D36: 12006.33 | E36: 13583.92 | F36: 19045.68 | G36: 16901.63 | H36: 13994.08 | I36: 14114.9 | J36: 24352.15 | K36: 35509.82 | L36: 35836.153 | M36: 37627.961 | N36: 242899.51 | O36: 0 | P36: 0 | Q36: 0 | R36: 0 | S36: 0 | T36: 0 | U36: 0 | V36: 0 | W36: 0 | X36: 0 | Y36: 0 | Z36: 0 | AA36: 0 | AM36: 0 | AN36: 0 | AO36: 0 | AP36: 0 | AQ36: 0 | AR36: 0 | AS36: 0 | AT36: 0 | AU36: 0 | AV36: 0 | AW36: 0 | AX36: 0 | AY36: 0 | BA36: 0 | BB36: 0 | BC36: 0 | BD36: 0 | BE36: 0 | BF36: 0 | BG36: 0 | BH36: 0 | BI36: 0 | BJ36: 0 | BK36: 0 | BL36: 0 | BM36: 0 | BO36: 0 | BP36: 0 | BQ36: 0 | BR36: 0 | BS36: 0 | BT36: 0 | BU36: 0 | BV36: 0 | BW36: 0 | BX36: 0 | BY36: 0 | BZ36: 0 | CA36: 0
A37: [MWG] - Paylater (QTV) | B37: 0 | C37: 0 | D37: 0 | E37: 0 | F37: 17.32 | G37: 2109.7991 | H37: 6670.1321 | I37: 10652.884 | J37: 11801.154 | K37: 19076.948 | L37: 23421.773 | M37: 31453.426 | N37: 105203.44 | O37: 60000 | P37: 51000 | Q37: 78000 | R37: 101400 | S37: 131820 | T37: 171366 | U37: 222775.8 | V37: 289608.54 | W37: 376491.1 | X37: 459319.14 | Y37: 560369.36 | Z37: 683650.61 | AA37: 3185800.6 | AM37: 717833.15 | AN37: 646049.83 | AO37: 753724.8 | AP37: 791411.04 | AQ37: 830981.59 | AR37: 872530.67 | AS37: 916157.21 | AT37: 961965.07 | AU37: 1010063.3 | AV37: 1060566.5 | AW37: 1113594.8 | AX37: 1169274.6 | AY37: 10844153 | BA37: 1227738.3 | BB37: 1104964.5 | BC37: 1289125.2 | BD37: 1353581.5 | BE37: 1421260.5 | BF37: 1492323.6 | BG37: 1566939.7 | BH37: 1645286.7 | BI37: 1727551.1 | BJ37: 1813928.6 | BK37: 1904625 | BL37: 1999856.3 | BM37: 18547181 | BO37: 2099849.1 | BP37: 1889864.2 | BQ37: 2204841.6 | BR37: 2315083.6 | BS37: 2430837.8 | BT37: 2552379.7 | BU37: 2679998.7 | BV37: 2813998.6 | BW37: 2954698.6 | BX37: 3102433.5 | BY37: 3257555.2 | BZ37: 3420432.9 | CA37: 31721973
A38: Other Paylater | B38: 24083.991 | C38: 36640.461 | D38: 33026.916 | E38: 32576.933 | F38: 36674.359 | G38: 40526.528 | H38: 41027.761 | I38: 35877.703 | J38: 33807.241 | K38: 36440.748 | L38: 41522.254 | M38: 42049.387 | N38: 434254.28 | O38: 45000 | P38: 45000 | Q38: 45000 | R38: 45000 | S38: 45000 | T38: 45000 | U38: 45000 | V38: 45000 | W38: 45000 | X38: 45000 | Y38: 45000 | Z38: 45000 | AA38: 540000 | AM38: 47250 | AN38: 42525 | AO38: 49612.5 | AP38: 52093.125 | AQ38: 54697.781 | AR38: 57432.67 | AS38: 60304.304 | AT38: 63319.519 | AU38: 66485.495 | AV38: 69809.77 | AW38: 73300.258 | AX38: 76965.271 | AY38: 713795.69 | BA38: 80813.535 | BB38: 72732.181 | BC38: 84854.211 | BD38: 89096.922 | BE38: 93551.768 | BF38: 98229.356 | BG38: 103140.82 | BH38: 108297.87 | BI38: 113712.76 | BJ38: 119398.4 | BK38: 125368.32 | BL38: 131636.73 | BM38: 1220832.9 | BO38: 138218.57 | BP38: 124396.71 | BQ38: 145129.5 | BR38: 152385.97 | BS38: 160005.27 | BT38: 168005.53 | BU38: 176405.81 | BV38: 185226.1 | BW38: 194487.41 | BX38: 204211.78 | BY38: 214422.37 | BZ38: 225143.48 | CA38: 2088038.5
A39: OD | B39: 109061.42 | C39: 95253.172 | D39: 112073.33 | E39: 114487.34 | F39: 119537.6 | G39: 118759.5 | H39: 118080.71 | I39: 97304.269 | J39: 86259.163 | K39: 84239.415 | L39: 84239.415 | M39: 84239.415 | N39: 1223534.8 | O39: 45000 | P39: 45000 | Q39: 45000 | R39: 45000 | S39: 40000 | T39: 40000 | U39: 40000 | V39: 40000 | W39: 40000 | X39: 40000 | Y39: 40000 | Z39: 40000 | AA39: 500000 | AM39: 40000 | AN39: 40000 | AO39: 40000 | AP39: 40000 | AQ39: 40000 | AR39: 40000 | AS39: 40000 | AT39: 40000 | AU39: 40000 | AV39: 40000 | AW39: 40000 | AX39: 40000 | AY39: 480000 | BA39: 40000 | BB39: 40000 | BC39: 40000 | BD39: 40000 | BE39: 40000 | BF39: 40000 | BG39: 40000 | BH39: 40000 | BI39: 40000 | BJ39: 40000 | BK39: 40000 | BL39: 40000 | BM39: 480000 | BO39: 40000 | BP39: 40000 | BQ39: 40000 | BR39: 40000 | BS39: 40000 | BT39: 40000 | BU39: 40000 | BV39: 40000 | BW39: 40000 | BX39: 40000 | BY39: 40000 | BZ39: 40000 | CA39: 480000
A40: [Ecom] - Paylater | B40: 0 | C40: 0 | D40: 0 | E40: 0 | F40: 0 | G40: 0 | H40: 0 | I40: 0 | J40: 0 | K40: 0 | L40: 0 | M40: 0 | N40: 0 | O40: 0 | P40: 0 | Q40: 76923.077 | R40: 76923.077 | S40: 153846.15 | T40: 307692.31 | U40: 384615.38 | V40: 461538.46 | W40: 538461.54 | X40: 615384.62 | Y40: 692307.69 | Z40: 692307.69 | AA40: 4000000
A42: VDS | B42: 0.51203335 | C42: 0.50062298 | D42: 0.50256459 | E42: 0.49880504 | F42: 0.46338477 | G42: 0.44108907 | H42: 0.42831953 | I42: 0.41108431 | J42: 0.41871157 | K42: 0.41296207 | L42: 0.41004985 | M42: 0.4098452 | N42: 0.43473084 | O42: 0.41455793 | P42: 0.41191296 | Q42: 0.39641007 | R42: 0.38608349 | S42: 0.36966303 | T42: 0.34490415 | U42: 0.3287619 | V42: 0.31527977 | W42: 0.3039196 | X42: 0.29145801 | Y42: 0.28775373 | Z42: 0.2930941 | AA42: 0.33246782 | AM42: 0.3135487 | AN42: 0.33635671 | AO42: 0.3032666 | AP42: 0.29317201 | AQ42: 0.28327153 | AR42: 0.27357104 | AS42: 0.26407576 | AT42: 0.25479015 | AU42: 0.24571805 | AV42: 0.2368626 | AW42: 0.22822627 | AX42: 0.21981095 | AY42: 0.26672357 | BA42: 0.21606755 | BB42: 0.22408141 | BC42: 0.2122718 | BD42: 0.20842719 | BE42: 0.20453743 | BF42: 0.20060644 | BG42: 0.19663831 | BH42: 0.19263728 | BI42: 0.18860778 | BJ42: 0.18455432 | BK42: 0.18048157 | BL42: 0.17639426 | BM42: 0.19775713 | BO42: 0.17229721 | BP42: 0.18113212 | BQ42: 0.16819526 | BR42: 0.16409329 | BS42: 0.15999618 | BT42: 0.15590878 | BU42: 0.15183591 | BV42: 0.1477823 | BW42: 0.1437526 | BX42: 0.13975135 | BY42: 0.13578296 | BZ42: 0.13185169 | CA42: 0.15297892
...

Sheet Break by BD
E1: 35610097 | F1: =D4-E1 -> 4540000
D4: ='Sales Plan 2026 - fin v4'!AA9 -> 40150097 | E4: 5633
D5: Disbursement | E5: TOI | F5: CL | G5: PD | H5: OD
C6: Huong | D6: =SUM(D7:D9) -> 17681133 | E6: =SUM(E7:E9) -> 3268.8563
C7: VDS | D7: ='Sales Plan 2026 - fin v4'!AA32 -> 13348615 | E7: =SUM(F7:G7) -> 2399 | F7: 1852 | G7: 547
C8: ZLP | D8: ='Sales Plan 2026 - fin v4'!AA35 -> 2062517.7 | E8: =D8*K8/1000 -> 414.09964 | I8: 2326 | J8: 467 | K8: =J8/I8 -> 0.20077386
C9: Other | D9: =F1*50% -> 2270000 | E9: =D9*K8/1000 -> 455.75666
C11: Ngoc | D11: =SUM(D12:D13) -> 8400330 | E11: =5633-E6-E16 -> 611.14369
C12: MWG | D12: ='Sales Plan 2026 - fin v4'!AA34+'Sales Plan 2026 - fin v4'!AA37 -> 6130330 | E12: =SUM(E13:E14) -> 0
C13: Other | D13: =F1*50% -> 2270000
C16: Ngan | D16: =SUM(D17:D18) -> 14068634 | E16: =SUM(E17:E18) -> 1753
C17: CAKE CL + PD | D17: ='Sales Plan 2026 - fin v4'!AA33 -> 13568634 | E17: =SUM(F17:G17) -> 1699 | F17: 1285 | G17: 414 | H17: 54
C18: CAKE OD | D18: ='Sales Plan 2026 - fin v4'!AA39 -> 500000 | E18: =H17 -> 54

Sheet Chị Ngân Cake CL
E3: CASH LOAN
E5: OVERVIEW
G6: =MONTH(G7) -> 1 | H6: =MONTH(H7) -> 2 | I6: =MONTH(I7) -> 3 | J6: =MONTH(J7) -> 4 | K6: =MONTH(K7) -> 5 | L6: =MONTH(L7) -> 6 | M6: =MONTH(M7) -> 7 | N6: =MONTH(N7) -> 8 | O6: 9
E7: OVERVIEW | G7: 45658 | H7: =EDATE(G7,1) -> 45689 | I7: =EDATE(H7,1) -> 45717 | J7: =EDATE(I7,1) -> 45748 | K7: =EDATE(J7,1) -> 45778 | L7: =EDATE(K7,1) -> 45809 | M7: =EDATE(L7,1) -> 45839 | N7: =EDATE(M7,1) -> 45870 | O7: =EDATE(N7,1) -> 45901 | ... R7: =EDATE(Q7,1) -> 45992 | S7: FY25 | T7: =EDATE(R7,1) -> 46023 | U7: =EDATE(T7,1) -> 46054 | V7: =EDATE(U7,1) -> 46082 | W7: =EDATE(V7,1) -> 46113 | X7: =EDATE(W7,1) -> 46143 | Y7: =EDATE(X7,1) -> 46174 | Z7: =EDATE(Y7,1) -> 46204 | AA7: =EDATE(Z7,1) -> 46235 | AB7: =EDATE(AA7,1) -> 46266 | ... AE7: =EDATE(AD7,1) -> 46357 | AF7: FY26
E8: [CAKE] - CASHLOAN
E9: App-in | F9: # | G9: =SUM(G22,G35) -> 82211 | H9: =SUM(H22,H35) -> 68741 | I9: =SUM(I22,I35) -> 89225 | J9: =SUM(J22,J35) -> 104138 | K9: =SUM(K22,K35) -> 106864 | L9: =SUM(L22,L35) -> 118112 | M9: =SUM(M22,M35) -> 143445 | N9: =SUM(N22,N35) -> 149102 | ... R9: =SUM(R22,R35) -> 160000 | S9: =SUM(G9:R9) -> 1500786 | T9: =SUM(T22,T35) -> 160270.02 | U9: =SUM(U22,U35) -> 143025.28 | V9: =SUM(V22,V35) -> 160729.31 | W9: =SUM(W22,W35) -> 169972.38 | X9: =SUM(X22,X35) -> 170188.1 | Y9: =SUM(Y22,Y35) -> 170349.34 | Z9: =SUM(Z22,Z35) -> 180159.26 | AA9: =SUM(AA22,AA35) -> 180255.23 | ... AE9: =SUM(AE22,AE35) -> 190791.51 | AF9: =SUM(T9:AE9) -> 2087259.1
E10: %Los check | F10: % | G10: 1 | H10: 1 | I10: 0.99992155 | J10: 0.99998052 | K10: 1 | L10: 0.99998276 | M10: 1 | N10: 0.99998642 | O10: 0.99999364 | P10: 0.99999364 | Q10: 0.99999364 | R10: 0.99999364 | S10: 1 | T10: 1 | U10: 1 | V10: 1 | W10: 1 | X10: 1 | Y10: 1 | Z10: 1 | AA10: 1 | AB10: 1 | AC10: 1 | AD10: 1 | AE10: 1 | AF10: 1
E11: %Los process | F11: % | G11: 0.99474523 | H11: 0.99349733 | I11: 0.9956511 | J11: 0.99356089 | K11: 0.99546941 | L11: 0.99756112 | M11: 0.99876942 | N11: 0.99081541 | O11: 0.99805492 | P11: 0.99805492 | Q11: 0.99805492 | R11: 0.99805492 | S11: 1 | T11: 1 | U11: 1 | V11: 1 | W11: 1 | X11: 1 | Y11: 1 | Z11: 1 | AA11: 1 | AB11: 1 | AC11: 1 | AD11: 1 | AE11: 1 | AF11: 1
E12: %AR | F12: % | G12: =G13/G9 -> 0.20667551 | H12: =H13/H9 -> 0.17845245 | I12: =I13/I9 -> 0.21013169 | J12: =J13/J9 -> 0.17678465 | K12: =K13/K9 -> 0.16804537 | L12: =L13/L9 -> 0.18372392 | M12: =M13/M9 -> 0.19350274 | N12: =N13/N9 -> 0.16606752 | ... AF12: =AF13/AF9 -> 0.25795846 | AG12: =AG13/(T10*T11*T12*T14*T16*T18) -> 126869.24 | AH12: =AH13/(U10*U11*U12*U14*U16*U18) -> 110201.64 | AI12: =AI13/(V10*V11*V12*V14*V16*V18) -> 128832.03 | AJ12: =AJ13/(W10*W11*W12*W14*W16*W18) -> 139225.16 | AK12: =AK13/(X10*X11*X12*X14*X16*X18) -> 140147.79 | AL12: =AL13/(Y10*Y11*Y12*Y14*Y16*Y18) -> 141086.81 | AM12: =AM13/(Z10*Z11*Z12*Z14*Z16*Z18) -> 152208.2 | AN12: =AN13/(AA10*AA11*AA12*AA14*AA16*AA18) -> 152889.57 | ... AR12: =AR13/(AE10*AE11*AE12*AE14*AE16*AE18) -> 165587.31
E13: Approved App | F13: # | G13: =SUM(G26,G39) -> 16991 | H13: =SUM(H26,H39) -> 12267 | I13: =SUM(I26,I39) -> 18749 | J13: =SUM(J26,J39) -> 18410 | K13: =SUM(K26,K39) -> 17958 | L13: =SUM(L26,L39) -> 21700 | M13: =SUM(M26,M39) -> 27757 | N13: =SUM(N26,N39) -> 24761 | ... R13: =SUM(R26,R39) -> 29424.21 | S13: =SUM(G13:R13) -> 276092.63 | T13: =SUM(T26,T39) -> 35772.269 | U13: =SUM(U26,U39) -> 32401.728 | V13: =SUM(V26,V39) -> 37335.957 | W13: =SUM(W26,W39) -> 40867.542 | X13: =SUM(X26,X39) -> 41761.067 | Y13: =SUM(Y26,Y39) -> 42779.365 | Z13: =SUM(Z26,Z39) -> 47286.894 | AA13: =SUM(AA26,AA39) -> 48203.525 | ... AE13: =SUM(AE26,AE39) -> 54947.955 | AF13: =SUM(T13:AE13) -> 538426.15 | AG13: =T19-$AK$19 -> 540033.78 | AH13: =U19-$AK$19 -> 477334.19 | AI13: =V19-$AK$19 -> 574237.43 | AJ13: =W19-$AK$19 -> 643773.41 | AK13: =X19-$AK$19 -> 663289.31 | AL13: =Y19-$AK$19 -> 685481.49 | AM13: =Z19-$AK$19 -> 774213.71 | AN13: =AA19-$AK$19 -> 794315.65 | ... AR13: =AE19-$AK$19 -> 934061.31
E14: %Sign | F14: % | G14: =G15/G13 -> 0.81713849 | H14: =H15/H13 -> 0.84225972 | I14: =I15/I13 -> 0.84857859 | J14: =J15/J13 -> 0.85214557 | K14: =K15/K13 -> 0.86373761 | L14: =L15/L13 -> 0.85857143 | M14: =M15/M13 -> 0.87113161 | N14: =N15/N13 -> 0.86155648 | ... AF14: =AF15/AF13 -> 0.86605498
E15: Sign App | F15: # | G15: =SUM(G28,G41) -> 13884 | H15: =SUM(H28,H41) -> 10332 | I15: =SUM(I28,I41) -> 15910 | J15: =SUM(J28,J41) -> 15688 | K15: =SUM(K28,K41) -> 15511 | L15: =SUM(L28,L41) -> 18631 | M15: =SUM(M28,M41) -> 24180 | N15: =SUM(N28,N41) -> 21333 | ... R15: =SUM(R28,R41) -> 25465.624 | S15: =SUM(G15:R15) -> 237160.87 | T15: =SUM(T28,T41) -> 30990.396 | U15: =SUM(U28,U41) -> 28070.63 | V15: =SUM(V28,V41) -> 32338.928 | W15: =SUM(W28,W41) -> 35401.33 | X15: =SUM(X28,X41) -> 36170.996 | Y15: =SUM(Y28,Y41) -> 37046.412 | Z15: =SUM(Z28,Z41) -> 40956.135 | AA15: =SUM(AA28,AA41) -> 41745.556 | ... AE15: =SUM(AE28,AE41) -> 47577.893 | AF15: =SUM(T15:AE15) -> 466306.64
E16: %Disb | F16: % | G16: =G17/G15 -> 1 | H16: =H17/H15 -> 0.99970964 | I16: =I17/I15 -> 0.99993715 | J16: =J17/J15 -> 1 | K16: =K17/K15 -> 0.99993553 | L16: =L17/L15 -> 0.9997853 | M16: =M17/M15 -> 1 | N16: =N17/N15 -> 1 | ... AF16: =AF17/AF15 -> 1
E17: Disbursed app | F17: # | G17: =SUM(G30,G43) -> 13884 | H17: =SUM(H30,H43) -> 10329 | I17: =SUM(I30,I43) -> 15909 | J17: =SUM(J30,J43) -> 15688 | K17: =SUM(K30,K43) -> 15510 | L17: =SUM(L30,L43) -> 18627 | M17: =SUM(M30,M43) -> 24180 | N17: =SUM(N30,N43) -> 21333 | ... R17: =SUM(R30,R43) -> 25465.624 | S17: =SUM(G17:R17) -> 237151.87 | T17: =SUM(T30,T43) -> 30990.396 | U17: =SUM(U30,U43) -> 28070.63 | V17: =SUM(V30,V43) -> 32338.928 | W17: =SUM(W30,W43) -> 35401.33 | X17: =SUM(X30,X43) -> 36170.996 | Y17: =SUM(Y30,Y43) -> 37046.412 | Z17: =SUM(Z30,Z43) -> 40956.135 | AA17: =SUM(AA30,AA43) -> 41745.556 | ... AE17: =SUM(AE30,AE43) -> 47577.893 | AF17: =SUM(T17:AE17) -> 466306.64
E18: Ticket size | F18: Mil VND | G18: =G19/G17 -> 10.683364 | H18: =H19/H17 -> 10.80254 | I18: =I19/I17 -> 11.059734 | J18: =J19/J17 -> 14.511882 | K18: =K19/K17 -> 15.001248 | L18: =L19/L17 -> 14.699171 | M18: =M19/M17 -> 15.620147 | N18: =N19/N17 -> 15.873516 | ... AF18: =AF19/AF17 -> 22.375478
E19: Disburse amt | F19: Mil VND | G19: =SUM(G32,G45) -> 148327.83 | H19: =SUM(H32,H45) -> 111579.44 | I19: =SUM(I32,I45) -> 175949.31 | J19: =SUM(J32,J45) -> 227662.41 | K19: =SUM(K32,K45) -> 232669.35 | L19: =SUM(L32,L45) -> 273801.46 | M19: =SUM(M32,M45) -> 377695.15 | N19: =SUM(N32,N45) -> 338629.71 | ... R19: =SUM(R32,R45) -> 489522.67 | S19: =SUM(G19:R19) -> 3841077.7 | T19: =SUM(T32,T45) -> 682208.12 | U19: =SUM(U32,U45) -> 619508.53 | V19: =SUM(V32,V45) -> 716411.76 | W19: =SUM(W32,W45) -> 785947.74 | X19: =SUM(X32,X45) -> 805463.64 | Y19: =SUM(Y32,Y45) -> 827655.82 | Z19: =SUM(Z32,Z45) -> 916388.04 | AA19: =SUM(AA32,AA45) -> 936489.99 | ... AE19: =SUM(AE32,AE45) -> 1076235.6 | AF19: =SUM(T19:AE19) -> 10433834 | AG19: =AF19/12 -> 869486.17 | AI19: 8727742 | AJ19: =AF19-AI19 -> 1706092 | AK19: =AJ19/12 -> 142174.33 | AL19: =AK19/2 -> 71087.167
AK20: =AK19/4 -> 35543.584
A21: [Cake] - Cashloan | E21: [Cake] - Mass | AK21: =AK20*2 -> 71087.167
A22: [Cake] - Cashloan | E22: App-in | F22: # | G22: 82211 | H22: 68741 | I22: 89225 | J22: 102656 | K22: 105505 | L22: 116039 | M22: 141397 | N22: 147314 | O22: 157321 | P22: =P57 -> 158356.68 | Q22: =Q57 -> 158356.68 | R22: =R57 -> 158356.68 | S22: =SUM(G22:R22) -> 1485479 | T22: =SUM(T112,T125) -> 128216.02 | U22: =SUM(U112,U125) -> 114420.23 | V22: =SUM(V112,V125) -> 128583.44 | W22: =SUM(W112,W125) -> 135977.91 | X22: =SUM(X112,X125) -> 136150.48 | Y22: =SUM(Y112,Y125) -> 136279.47 | Z22: =SUM(Z112,Z125) -> 144127.41 | AA22: =SUM(AA112,AA125) -> 144204.18 | ... AF22: =SUM(AF112,AF125) -> 1669807.3
A23: [Cake] - Cashloan | E23: %Los check | F23: % | G23: 1 | H23: 1 | I23: 0.99992155 | J23: 0.99998052 | K23: 1 | L23: 0.99998276 | M23: 1 | N23: 0.99998642 | O23: 0.99999364 | P23: =O23 -> 0.99999364 | Q23: =P23 -> 0.99999364 | R23: =Q23 -> 0.99999364 | S23: 1 | T23: 1 | U23: 1 | V23: 1 | W23: 1 | X23: 1 | Y23: 1 | Z23: 1 | AA23: 1 | AB23: 1 | AC23: 1 | AD23: 1 | AE23: 1 | AF23: 1
A24: [Cake] - Cashloan | E24: %Los process | F24: % | G24: 0.99474523 | H24: 0.99349733 | I24: 0.9956511 | J24: 0.99356089 | K24: 0.99546941 | L24: 0.99756112 | M24: 0.99876942 | N24: 0.99081541 | O24: 0.99805492 | P24: =O24 -> 0.99805492 | Q24: =P24 -> 0.99805492 | R24: =Q24 -> 0.99805492 | S24: 1 | T24: 1 | U24: 1 | V24: 1 | W24: 1 | X24: 1 | Y24: 1 | Z24: 1 | AA24: 1 | AB24: 1 | AC24: 1 | AD24: 1 | AE24: 1 | AF24: 1
A25: [Cake] - Cashloan | E25: %AR | F25: % | G25: 0.20776728 | H25: 0.17962046 | I25: 0.21106608 | J25: 0.16941359 | K25: 0.16183458 | L25: 0.17673687 | M25: 0.18676136 | N25: 0.16075747 | O25: 0.17727719 | P25: =O25 -> 0.17727719 | Q25: =P25 -> 0.17727719 | R25: =Q25 -> 0.17727719 | S25: =S26/S22 -> 0.17803666 | T25: =T26/T22 -> 0.184 | U25: =U26/U22 -> 0.18545455 | V25: =V26/V22 -> 0.18690909 | W25: =W26/W22 -> 0.19436364 | X25: =X26/X22 -> 0.19581818 | Y25: =Y26/Y22 -> 0.19727273 | Z25: =Z26/Z22 -> 0.20872727 | ... AF25: =AF26/AF22 -> 0.20346415
A26: [Cake] - Cashloan | E26: Approved App | F26: # | G26: =G22*G23*G24*G25 -> 16991 | H26: =H22*H23*H24*H25 -> 12267 | I26: =I22*I23*I24*I25 -> 18749 | J26: =J22*J23*J24*J25 -> 17279 | K26: =K22*K23*K24*K25 -> 16997 | L26: =L22*L23*L24*L25 -> 20458 | M26: =M22*M23*M24*M25 -> 26375 | N26: =N22*N23*N24*N25 -> 23464 | ... R26: =R22*R23*R24*R25 -> 28018.243 | S26: =SUM(G26:R26) -> 264469.73 | T26: =SUM(T116,T129) -> 23591.747 | U26: =SUM(U116,U129) -> 21219.751 | V26: =SUM(V116,V129) -> 24033.415 | W26: =SUM(W116,W129) -> 26429.161 | X26: =SUM(X116,X129) -> 26660.74 | Y26: =SUM(Y116,Y129) -> 26884.223 | Z26: =SUM(Z116,Z129) -> 30083.322 | AA26: =SUM(AA116,AA129) -> 30309.097 | ... AE26: =SUM(AE116,AE129) -> 33579.306 | AF26: =SUM(T26:AE26) -> 339745.92
A27: [Cake] - Cashloan | E27: %Sign | F27: % | G27: 0.81713849 | H27: 0.84225972 | I27: 0.84857859 | J27: 0.85548932 | K27: 0.86644702 | L27: 0.86108124 | M27: 0.87272038 | N27: 0.86387658 | O27: 0.86603197 | P27: =O27 -> 0.86603197 | Q27: =P27 -> 0.86603197 | R27: =Q27 -> 0.86603197 | S27: =S28/S26 -> 0.85998153 | T27: =T28/T26 -> 0.87 | U27: =U28/U26 -> 0.87 | V27: =V28/V26 -> 0.87 | W27: =W28/W26 -> 0.87 | X27: =X28/X26 -> 0.87 | Y27: =Y28/Y26 -> 0.87 | Z27: =Z28/Z26 -> 0.87 | ... AF27: =AF28/AF26 -> 0.87
A28: [Cake] - Cashloan | E28: Sign App | F28: # | G28: =G26*G27 -> 13884 | H28: =H26*H27 -> 10332 | I28: =I26*I27 -> 15910 | J28: =J26*J27 -> 14782 | K28: =K26*K27 -> 14727 | L28: =L26*L27 -> 17616 | M28: =M26*M27 -> 23018 | N28: =N26*N27 -> 20270 | ... R28: =R26*R27 -> 24264.695 | S28: =SUM(G28:R28) -> 227439.08 | T28: =SUM(T118,T131) -> 20524.82 | U28: =SUM(U118,U131) -> 18461.183 | V28: =SUM(V118,V131) -> 20909.071 | W28: =SUM(W118,W131) -> 22993.37 | X28: =SUM(X118,X131) -> 23194.844 | Y28: =SUM(Y118,Y131) -> 23389.274 | Z28: =SUM(Z118,Z131) -> 26172.49 | AA28: =SUM(AA118,AA131) -> 26368.914 | ... AE28: =SUM(AE118,AE131) -> 29213.996 | AF28: =SUM(T28:AE28) -> 295578.95
A29: [Cake] - Cashloan | E29: %Disb | F29: % | G29: 1 | H29: 0.99970964 | I29: 0.99993715 | J29: 1 | K29: 0.9999321 | L29: 0.99977293 | M29: 1 | N29: 1 | O29: 1 | P29: 1 | Q29: 1 | R29: 1 | S29: 1 | T29: =T30/T28 -> 1 | U29: =U30/U28 -> 1 | V29: =V30/V28 -> 1 | W29: =W30/W28 -> 1 | X29: =X30/X28 -> 1 | Y29: =Y30/Y28 -> 1 | Z29: =Z30/Z28 -> 1 | AA29: =AA30/AA28 -> 1 | ... AF29: =AF30/AF28 -> 1
A30: [Cake] - Cashloan | E30: Disbursed app | F30: # | G30: =G22*G23*G24*G25*G27*G29 -> 13884 | H30: =H22*H23*H24*H25*H27*H29 -> 10329 | I30: =I22*I23*I24*I25*I27*I29 -> 15909 | J30: =J22*J23*J24*J25*J27*J29 -> 14782 | K30: =K22*K23*K24*K25*K27*K29 -> 14726 | L30: =L22*L23*L24*L25*L27*L29 -> 17612 | M30: =M22*M23*M24*M25*M27*M29 -> 23018 | N30: =N22*N23*N24*N25*N27*N29 -> 20270 | O30: =O22*O23*O24*O25*O27*O29 -> 24106 | P30: =P28*P29 -> 24264.695 | Q30: =Q28*Q29 -> 24264.695 | R30: =R28*R29 -> 24264.695 | S30: =SUM(G30:R30) -> 227430.08 | T30: =SUM(T120,T133) -> 20524.82 | U30: =SUM(U120,U133) -> 18461.183 | V30: =SUM(V120,V133) -> 20909.071 | W30: =SUM(W120,W133) -> 22993.37 | X30: =SUM(X120,X133) -> 23194.844 | Y30: =SUM(Y120,Y133) -> 23389.274 | Z30: =SUM(Z120,Z133) -> 26172.49 | AA30: =SUM(AA120,AA133) -> 26368.914 | ... AE30: =SUM(AE120,AE133) -> 29213.996 | AF30: =SUM(T30:AE30) -> 295578.95
A31: [Cake] - Cashloan | E31: Ticket size | F31: Mil VND | G31: 10.683364 | H31: 10.80254 | I31: 11.059734 | J31: 14.511882 | K31: 15.001248 | L31: 14.699171 | M31: 15.620147 | N31: 15.873516 | O31: =O32/O30 -> 18.643342 | P31: =O31 -> 18.643342 | Q31: =P31 -> 18.643342 | R31: =Q31 -> 18.643342 | S31: =S32/S30 -> 15.771988 | T31: =T32/T30 -> 18.869565 | U31: =U32/U30 -> 18.862745 | V31: =V32/V30 -> 18.856031 | W31: =W32/W30 -> 18.946679 | X31: =X32/X30 -> 18.939647 | Y31: =Y32/Y30 -> 18.932719 | Z31: =Z32/Z30 -> 19.073171 | ... AF31: =AF32/AF30 -> 19.004465
A32: [Cake] - Cashloan | E32: Disburse amt | F32: Mil VND | G32: 148327.83 | H32: 111579.44 | I32: 175949.31 | J32: 209320.01 | K32: 216389 | L32: 253453.26 | M32: 351386.1 | N32: 314078.11 | O32: 449416.41 | P32: =P30*P31 -> 452375.01 | Q32: =Q30*Q31 -> 452375.01 | R32: =R30*R31 -> 452375.01 | S32: =SUM(G32:R32) -> 3587024.5 | T32: =SUM(T122,T135) -> 387294.43 | U32: =SUM(U122,U135) -> 348228.6 | V32: =SUM(V122,V135) -> 394262.09 | W32: =SUM(W122,W135) -> 435648 | X32: =SUM(X122,X135) -> 439302.16 | Y32: =SUM(Y122,Y135) -> 442822.55 | Z32: =SUM(Z122,Z135) -> 499192.37 | AA32: =SUM(AA122,AA135) -> 502742.97 | ... AE32: =SUM(AE122,AE135) -> 557721.74 | AF32: =SUM(T32:AE32) -> 5617320 | AG32: =AF32/12 -> 468110
A34: [Cake] - Cashloan | E34: [Cake] - Pre-approved
A35: [Cake] - Cashloan | E35: App-in | F35: # | J35: 1482 | K35: 1359 | L35: 2073 | M35: 2048 | N35: 1788 | O35: 1627 | P35: =P58 -> 1643.324 | Q35: =Q58 -> 1643.324 | R35: =R58 -> 1643.324 | S35: =SUM(G35:R35) -> 15306.972 | T35: =SUM(T142,T155) -> 32054.004 | U35: =SUM(U142,U155) -> 28605.056 | V35: =SUM(V142,V155) -> 32145.861 | W35: =SUM(W142,W155) -> 33994.477 | X35: =SUM(X142,X155) -> 34037.621 | Y35: =SUM(Y142,Y155) -> 34069.868 | Z35: =SUM(Z142,Z155) -> 36031.853 | AA35: =SUM(AA142,AA155) -> 36051.045 | ... AE35: =SUM(AE142,AE155) -> 38158.302 | AF35: =SUM(T35:AE35) -> 417451.82
A36: [Cake] - Cashloan | E36: %Los check | F36: % | J36: 1 | K36: 1 | L36: 1 | M36: 1 | N36: 1 | O36: 1 | P36: =O36 -> 1 | Q36: =P36 -> 1 | R36: =Q36 -> 1 | S36: 1 | T36: 1 | U36: 1 | V36: 1 | W36: 1 | X36: 1 | Y36: 1 | Z36: 1 | AA36: 1 | AB36: 1 | AC36: 1 | AD36: 1 | AE36: 1 | AF36: 1
A37: [Cake] - Cashloan | E37: %Los process | F37: % | J37: 0.99325236 | K37: 0.99411332 | L37: 0.99758804 | M37: 0.99560547 | N37: 0.98545861 | O37: 0.99877074 | P37: =O37 -> 0.99877074 | Q37: =P37 -> 0.99877074 | R37: =Q37 -> 0.99877074 | S37: 1 | T37: 1 | U37: 1 | V37: 1 | W37: 1 | X37: 1 | Y37: 1 | Z37: 1 | AA37: 1 | AB37: 1 | AC37: 1 | AD37: 1 | AE37: 1 | AF37: 1
A38: [Cake] - Cashloan | E38: %AR | F38: % | J38: 0.76834239 | K38: 0.71132494 | L38: 0.60058027 | M38: 0.67778323 | N38: 0.73609535 | O38: 0.85661538 | P38: =O38 -> 0.85661538 | Q38: =P38 -> 0.85661538 | R38: =Q38 -> 0.85661538 | S38: =S39/S35 -> 0.75932056 | T38: =T39/T35 -> 0.38 | U38: =U39/U35 -> 0.39090909 | V38: =V39/V35 -> 0.41381818 | W38: =W39/W35 -> 0.42472727 | X38: =X39/X35 -> 0.44363636 | Y38: =Y39/Y35 -> 0.46654545 | Z38: =Z39/Z35 -> 0.47745455 | ... AF38: =AF39/AF35 -> 0.4759357
A39: [Cake] - Cashloan | E39: Approved App | F39: # | J39: =J35*J36*J37*J38 -> 1131 | K39: =K35*K36*K37*K38 -> 961 | L39: =L35*L36*L37*L38 -> 1242 | M39: =M35*M36*M37*M38 -> 1382 | N39: =N35*N36*N37*N38 -> 1297 | O39: =O35*O36*O37*O38 -> 1392 | P39: =P35*P36*P37*P38 -> 1405.9662 | Q39: =Q35*Q36*Q37*Q38 -> 1405.9662 | R39: =R35*R36*R37*R38 -> 1405.9662 | S39: =SUM(G39:R39) -> 11622.899 | T39: =SUM(T146,T159) -> 12180.522 | U39: =SUM(U146,U159) -> 11181.977 | V39: =SUM(V146,V159) -> 13302.542 | W39: =SUM(W146,W159) -> 14438.381 | X39: =SUM(X146,X159) -> 15100.326 | Y39: =SUM(Y146,Y159) -> 15895.142 | Z39: =SUM(Z146,Z159) -> 17203.572 | AA39: =SUM(AA146,AA159) -> 17894.428 | ... AE39: =SUM(AE146,AE159) -> 21368.649 | AF39: =SUM(T39:AE39) -> 198680.23
A40: [Cake] - Cashloan | E40: %Sign | F40: % | J40: 0.80106101 | K40: 0.81581686 | L40: 0.81723027 | M40: 0.84081042 | N40: 0.81958365 | O40: 0.85416667 | P40: =O40 -> 0.85416667 | Q40: =P40 -> 0.85416667 | R40: =Q40 -> 0.85416667 | S40: =S41/S39 -> 0.83643407 | T40: =T41/T39 -> 0.85920589 | U40: =U41/U39 -> 0.85936921 | V40: =V41/V39 -> 0.85922352 | W40: =W41/W39 -> 0.85937338 | X40: =X41/X39 -> 0.85932924 | Y40: =Y41/Y39 -> 0.85920198 | Z40: =Z41/Z39 -> 0.85933578 | ... AF40: =AF41/AF39 -> 0.85930893
A41: [Cake] - Cashloan | E41: Sign App | F41: # | J41: =J39*J40 -> 906 | K41: =K39*K40 -> 784 | L41: =L39*L40 -> 1015 | M41: =M39*M40 -> 1162 | N41: =N39*N40 -> 1063 | O41: =O39*O40 -> 1189 | P41: =P39*P40 -> 1200.9295 | Q41: =Q39*Q40 -> 1200.9295 | R41: =R39*R40 -> 1200.9295 | S41: =SUM(G41:R41) -> 9721.7884 | T41: =SUM(T148,T161) -> 10465.576 | U41: =SUM(U148,U161) -> 9609.4464 | V41: =SUM(V148,V161) -> 11429.857 | W41: =SUM(W148,W161) -> 12407.961 | X41: =SUM(X148,X161) -> 12976.152 | Y41: =SUM(Y148,Y161) -> 13657.138 | Z41: =SUM(Z148,Z161) -> 14783.645 | AA41: =SUM(AA148,AA161) -> 15376.642 | ... AE41: =SUM(AE148,AE161) -> 18363.897 | AF41: =SUM(T41:AE41) -> 170727.69
A42: [Cake] - Cashloan | E42: %Disb | F42: % | J42: 1 | K42: 1 | L42: 1 | M42: 1 | N42: 1 | O42: 1 | P42: =O42 -> 1 | Q42: =P42 -> 1 | R42: =Q42 -> 1 | S42: 1 | T42: =T43/T41 -> 1 | U42: =U43/U41 -> 1 | V42: =V43/V41 -> 1 | W42: =W43/W41 -> 1 | X42: =X43/X41 -> 1 | Y42: =Y43/Y41 -> 1 | Z42: =Z43/Z41 -> 1 | AA42: =AA43/AA41 -> 1 | ... AF42: =AF43/AF41 -> 1
A43: [Cake] - Cashloan | E43: Disbursed app | F43: # | J43: =J35*J36*J37*J38*J40*J42 -> 906 | K43: =K35*K36*K37*K38*K40*K42 -> 784 | L43: =L35*L36*L37*L38*L40*L42 -> 1015 | M43: =M35*M36*M37*M38*M40*M42 -> 1162 | N43: =N35*N36*N37*N38*N40*N42 -> 1063 | O43: =O35*O36*O37*O38*O40*O42 -> 1189 | P43: =P41*P42 -> 1200.9295 | Q43: =Q41*Q42 -> 1200.9295 | R43: =R41*R42 -> 1200.9295 | S43: =SUM(G43:R43) -> 9721.7884 | T43: =SUM(T150,T163) -> 10465.576 | U43: =SUM(U150,U163) -> 9609.4464 | V43: =SUM(V150,V163) -> 11429.857 | W43: =SUM(W150,W163) -> 12407.961 | X43: =SUM(X150,X163) -> 12976.152 | Y43: =SUM(Y150,Y163) -> 13657.138 | Z43: =SUM(Z150,Z163) -> 14783.645 | AA43: =SUM(AA150,AA163) -> 15376.642 | ... AE43: =SUM(AE150,AE163) -> 18363.897 | AF43: =SUM(T43:AE43) -> 170727.69
A44: [Cake] - Cashloan | E44: Ticket size | F44: Mil VND | J44: =J45/J43 -> 20.245475 | K44: =K45/K43 -> 20.765753 | L44: =L45/L43 -> 20.047488 | M44: =M45/M43 -> 22.641179 | N44: =N45/N43 -> 23.096519 | O44: =O45/O43 -> 30.932422 | P44: =O44 -> 30.932422 | Q44: =P44 -> 30.932422 | R44: =Q44 -> 30.932422 | S44: =S45/S43 -> 26.132355 | T44: =T45/T43 -> 28.179404 | U44: =U45/U43 -> 28.230547 | V44: =V45/V43 -> 28.184926 | W44: =W45/W43 -> 28.231854 | X44: =X45/X43 -> 28.218033 | Y44: =Y45/Y43 -> 28.178179 | Z44: =Z45/Z43 -> 28.220082 | ... AF44: =AF45/AF43 -> 28.211674
...

Sheet Chị Ngân (Cake Payday)
E3: CASH LOAN
E5: OVERVIEW
G6: =MONTH(G7) -> 1 | H6: =MONTH(H7) -> 2 | I6: =MONTH(I7) -> 3 | J6: =MONTH(J7) -> 4 | K6: =MONTH(K7) -> 5 | L6: =MONTH(L7) -> 6 | M6: =MONTH(M7) -> 7 | N6: =MONTH(N7) -> 8 | O6: 9
E7: OVERVIEW | G7: 45658 | H7: =EDATE(G7,1) -> 45689 | I7: =EDATE(H7,1) -> 45717 | J7: =EDATE(I7,1) -> 45748 | K7: =EDATE(J7,1) -> 45778 | L7: =EDATE(K7,1) -> 45809 | M7: =EDATE(L7,1) -> 45839 | N7: =EDATE(M7,1) -> 45870 | O7: =EDATE(N7,1) -> 45901 | ... R7: =EDATE(Q7,1) -> 45992 | S7: FY25 | T7: =EDATE(R7,1) -> 46023 | U7: =EDATE(T7,1) -> 46054 | V7: =EDATE(U7,1) -> 46082 | W7: =EDATE(V7,1) -> 46113 | X7: =EDATE(W7,1) -> 46143 | Y7: =EDATE(X7,1) -> 46174 | Z7: =EDATE(Y7,1) -> 46204 | AA7: =EDATE(Z7,1) -> 46235 | AB7: =EDATE(AA7,1) -> 46266 | ... AE7: =EDATE(AD7,1) -> 46357 | AF7: FY26
E8: [CAKE] - Payday
E9: App-in | F9: # | M9: 57914 | N9: 161694 | O9: 165859 | P9: =P54 -> 180000 | Q9: =Q54 -> 200000 | R9: =R54 -> 230000 | S9: =SUM(G9:R9) -> 995467 | T9: =SUM(T22,T35) -> 244169.65 | U9: =SUM(U22,U35) -> 225521.72 | V9: =SUM(V22,V35) -> 243106.43 | W9: =SUM(W22,W35) -> 251644.06 | X9: =SUM(X22,X35) -> 251134.38 | Y9: =SUM(Y22,Y35) -> 250633.09 | Z9: =SUM(Z22,Z35) -> 259648.67 | AA9: =SUM(AA22,AA35) -> 259163.53 | ... AE9: =SUM(AE22,AE35) -> 267283.14 | AF9: =SUM(T9:AE9) -> 3046929.6
E10: %Los check | F10: % | M10: 1 | N10: 1 | O10: 1 | P10: 0.99999364 | Q10: 0.99999364 | R10: 0.99999364 | S10: 1 | T10: 1 | U10: 1 | V10: 1 | W10: 1 | X10: 1 | Y10: 1 | Z10: 1 | AA10: 1 | AB10: 1 | AC10: 1 | AD10: 1 | AE10: 1 | AF10: 1
B11: Mass | E11: %Los process | F11: % | M11: 1 | N11: 1 | O11: 0.9979983 | P11: 0.99805492 | Q11: 0.99805492 | R11: 0.99805492 | S11: 1 | T11: 1 | U11: 1 | V11: 1 | W11: 1 | X11: 1 | Y11: 1 | Z11: 1 | AA11: 1 | AB11: 1 | AC11: 1 | AD11: 1 | AE11: 1 | AF11: 1
B12: ETB | E12: %AR | F12: % | M12: 0.40202714 | N12: 0.33494749 | O12: 0.49715152 | P12: =O12 -> 0.49715152 | Q12: =P12 -> 0.49715152 | R12: =Q12 -> 0.49715152 | S12: =S13/S9 -> 0.46451026 | T12: =T13/T9 -> 0.534 | U12: =U13/U9 -> 0.53854545 | V12: =V13/V9 -> 0.54309091 | W12: =W13/W9 -> 0.54763636 | X12: =X13/X9 -> 0.55218182 | Y12: =Y13/Y9 -> 0.55672727 | Z12: =Z13/Z9 -> 0.56127273 | ... AF12: =AF13/AF9 -> 0.55965503 | AG12: =AG13/(T10*T11*T12*T14*T16*T18) -> 225455.97 | AH12: =AH13/(U10*U11*U12*U14*U16*U18) -> 206963.08 | AI12: =AI13/(V10*V11*V12*V14*V16*V18) -> 224700.28 | AJ12: =AJ13/(W10*W11*W12*W14*W16*W18) -> 233387.91 | AK12: =AK13/(X10*X11*X12*X14*X16*X18) -> 233025.81 | AL12: =AL13/(Y10*Y11*Y12*Y14*Y16*Y18) -> 232669.73 | AM12: =AM13/(Z10*Z11*Z12*Z14*Z16*Z18) -> 241828.21 | AN12: =AN13/(AA10*AA11*AA12*AA14*AA16*AA18) -> 241483.71 | ... AR12: =AR13/(AE10*AE11*AE12*AE14*AE16*AE18) -> 250144.38
E13: Approved App | F13: # | M13: =M9*M10*M11*M12 -> 23283 | N13: =N9*N10*N11*N12 -> 54159 | O13: =O9*O10*O11*O12 -> 82292 | P13: =P9*P10*P11*P12 -> 89312.646 | Q13: =Q9*Q10*Q11*Q12 -> 99236.274 | R13: =R9*R10*R11*R12 -> 114121.71 | S13: =SUM(G13:R13) -> 462404.63 | T13: =SUM(T26,T39) -> 130386.59 | U13: =SUM(U26,U39) -> 121453.7 | V13: =SUM(V26,V39) -> 132028.89 | W13: =SUM(W26,W39) -> 137809.44 | X13: =SUM(X26,X39) -> 138671.84 | Y13: =SUM(Y26,Y39) -> 139534.28 | Z13: =SUM(Z26,Z39) -> 145733.72 | AA13: =SUM(AA26,AA39) -> 146639.44 | ... AE13: =SUM(AE26,AE39) -> 156093.35 | AF13: =SUM(T13:AE13) -> 1705229.5 | AG13: =T19+$AI$19 -> 390818.67 | AH13: =U19+$AI$19 -> 361759.02 | AI13: =V19+$AI$19 -> 396016.47 | AJ13: =W19+$AI$19 -> 414707.42 | AK13: =X19+$AI$19 -> 417438.44 | AL13: =Y19+$AI$19 -> 420169.84 | AM13: =Z19+$AI$19 -> 440210.72 | AN13: =AA19+$AI$19 -> 443080.54 | ... AR13: =AE19+$AI$19 -> 473460.7
E14: %Sign | F14: % | M14: 0.95047889 | N14: 0.93347366 | O14: 0.93700481 | P14: =O14 -> 0.93700481 | Q14: =P14 -> 0.93700481 | R14: =Q14 -> 0.93700481 | S14: =S15/S13 -> 0.93726967 | T14: =T15/T13 -> 0.93700481 | U14: =U15/U13 -> 0.93700481 | V14: =V15/V13 -> 0.93700481 | W14: =W15/W13 -> 0.93700481 | X14: =X15/X13 -> 0.93700481 | Y14: =Y15/Y13 -> 0.93700481 | Z14: =Z15/Z13 -> 0.93700481 | ... AF14: =AF15/AF13 -> 0.93700481
E15: Sign App | F15: # | M15: =M13*M14 -> 22130 | N15: =N13*N14 -> 50556 | O15: =O13*O14 -> 77108 | P15: =P13*P14 -> 83686.379 | Q15: =Q13*Q14 -> 92984.866 | R15: =R13*R14 -> 106932.6 | S15: =SUM(G15:R15) -> 433397.84 | T15: =SUM(T28,T41) -> 122172.86 | U15: =SUM(U28,U41) -> 113802.7 | V15: =SUM(V28,V41) -> 123711.71 | W15: =SUM(W28,W41) -> 129128.11 | X15: =SUM(X28,X41) -> 129936.18 | Y15: =SUM(Y28,Y41) -> 130744.29 | Z15: =SUM(Z28,Z41) -> 136553.19 | AA15: =SUM(AA28,AA41) -> 137401.86 | ... AE15: =SUM(AE28,AE41) -> 146260.22 | AF15: =SUM(T15:AE15) -> 1597808.2
E16: %Disb | F16: % | M16: 1 | N16: 1 | O16: 0.99992219 | P16: =O16 -> 0.99992219 | Q16: =P16 -> 0.99992219 | R16: =Q16 -> 0.99992219 | S16: =S17/S15 -> 0.99993524 | T16: =T17/T15 -> 1 | U16: =U17/U15 -> 1 | V16: =V17/V15 -> 1 | W16: =W17/W15 -> 1 | X16: =X17/X15 -> 1 | Y16: =Y17/Y15 -> 1 | Z16: =Z17/Z15 -> 1 | ... AF16: =AF17/AF15 -> 1
E17: Disbursed app | F17: # | M17: =M15*M16 -> 22130 | N17: =N15*N16 -> 50556 | O17: =O15*O16 -> 77102 | P17: =P15*P16 -> 83679.868 | Q17: =Q15*Q16 -> 92977.631 | R17: =R15*R16 -> 106924.28 | S17: =SUM(G17:R17) -> 433369.77 | T17: =SUM(T30,T43) -> 122172.86 | U17: =SUM(U30,U43) -> 113802.7 | V17: =SUM(V30,V43) -> 123711.71 | W17: =SUM(W30,W43) -> 129128.11 | X17: =SUM(X30,X43) -> 129936.18 | Y17: =SUM(Y30,Y43) -> 130744.29 | Z17: =SUM(Z30,Z43) -> 136553.19 | AA17: =SUM(AA30,AA43) -> 137401.86 | ... AE17: =SUM(AE30,AE43) -> 146260.22 | AF17: =SUM(T17:AE17) -> 1597808.2
E18: Ticket size | F18: Mil VND | M18: 2.4702377 | N18: 2.467474 | O18: 2.5536169 | P18: =O18 -> 2.5536169 | Q18: =P18 -> 2.5536169 | R18: =Q18 -> 2.5536169 | S18: =S19/S17 -> 2.5393099 | T18: =T19/T17 -> 3.4644195 | U18: =U19/U17 -> 3.4638758 | V18: =V19/V17 -> 3.4633411 | W18: =W19/W17 -> 3.4628154 | X18: =X19/X17 -> 3.4622983 | Y18: =Y19/Y17 -> 3.4617897 | Z18: =Z19/Z17 -> 3.4612893 | ... AF18: =AF19/AF17 -> 3.4614664
E19: Disburse amt | F19: Mil VND | M19: =M17*M18 -> 54666.36 | N19: =N17*N18 -> 124745.62 | O19: 196888.97 | P19: =P17*P18 -> 213686.32 | Q19: =Q17*Q18 -> 237429.25 | R19: =R17*R18 -> 273043.63 | S19: =SUM(G19:R19) -> 1100460.1 | T19: =SUM(T32,T45) -> 423258.05 | U19: =SUM(U32,U45) -> 394198.4 | V19: =SUM(V32,V45) -> 428455.85 | W19: =SUM(W32,W45) -> 447146.8 | X19: =SUM(X32,X45) -> 449877.82 | Y19: =SUM(Y32,Y45) -> 452609.23 | Z19: =SUM(Z32,Z45) -> 472650.1 | AA19: =SUM(AA32,AA45) -> 475519.92 | ... AE19: =SUM(AE32,AE45) -> 505900.08 | AF19: =SUM(T19:AE19) -> 5530759.6 | AG19: 5141487 | AH19: =AG19-AF19 -> -389272.59 | AI19: =AH19/12 -> -32439.383
A21: [Cake] - Cashloan | E21: [Cake] - Mass
A22: [Cake] - Cashloan | E22: App-in | F22: # | T22: =SUM(T112,T125) -> 195335.72 | U22: =SUM(U112,U125) -> 180417.37 | V22: =SUM(V112,V125) -> 194485.15 | W22: =SUM(W112,W125) -> 201315.25 | X22: =SUM(X112,X125) -> 200907.51 | Y22: =SUM(Y112,Y125) -> 200506.47 | Z22: =SUM(Z112,Z125) -> 207718.93 | AA22: =SUM(AA112,AA125) -> 207330.82 | ... AF22: =SUM(AF112,AF125) -> 2437543.7
A23: [Cake] - Cashloan | E23: %Los check | F23: % | T23: 1 | U23: 1 | V23: 1 | W23: 1 | X23: 1 | Y23: 1 | Z23: 1 | AA23: 1 | AB23: 1 | AC23: 1 | AD23: 1 | AE23: 1 | AF23: 1
A24: [Cake] - Cashloan | E24: %Los process | F24: % | T24: 1 | U24: 1 | V24: 1 | W24: 1 | X24: 1 | Y24: 1 | Z24: 1 | AA24: 1 | AB24: 1 | AC24: 1 | AD24: 1 | AE24: 1 | AF24: 1
A25: [Cake] - Cashloan | E25: %AR | F25: % | T25: =T26/T22 -> 0.51 | U25: =U26/U22 -> 0.51454545 | V25: =V26/V22 -> 0.51909091 | W25: =W26/W22 -> 0.52363636 | X25: =X26/X22 -> 0.52818182 | Y25: =Y26/Y22 -> 0.53272727 | Z25: =Z26/Z22 -> 0.53727273 | AA25: =AA26/AA22 -> 0.54181818 | ... AF25: =AF26/AF22 -> 0.53565503
A26: [Cake] - Cashloan | E26: Approved App | F26: # | T26: =SUM(T116,T129) -> 99621.216 | U26: =SUM(U116,U129) -> 92832.94 | V26: =SUM(V116,V129) -> 100955.47 | W26: =SUM(W116,W129) -> 105415.99 | X26: =SUM(X116,X129) -> 106115.69 | Y26: =SUM(Y116,Y129) -> 106815.27 | Z26: =SUM(Z116,Z129) -> 111601.72 | AA26: =SUM(AA116,AA129) -> 112335.61 | ... AE26: =SUM(AE116,AE129) -> 119742.85 | AF26: =SUM(T26:AE26) -> 1305682.5
A27: [Cake] - Cashloan | E27: %Sign | F27: % | T27: =T28/T26 -> 0.93700481 | U27: =U28/U26 -> 0.93700481 | V27: =V28/V26 -> 0.93700481 | W27: =W28/W26 -> 0.93700481 | X27: =X28/X26 -> 0.93700481 | Y27: =Y28/Y26 -> 0.93700481 | Z27: =Z28/Z26 -> 0.93700481 | AA27: =AA28/AA26 -> 0.93700481 | ... AF27: =AF28/AF26 -> 0.93700481
A28: [Cake] - Cashloan | E28: Sign App | F28: # | T28: =SUM(T118,T131) -> 93345.559 | U28: =SUM(U118,U131) -> 86984.911 | V28: =SUM(V118,V131) -> 94595.763 | W28: =SUM(W118,W131) -> 98775.286 | X28: =SUM(X118,X131) -> 99430.914 | Y28: =SUM(Y118,Y131) -> 100086.42 | Z28: =SUM(Z118,Z131) -> 104571.35 | AA28: =SUM(AA118,AA131) -> 105259.01 | ... AE28: =SUM(AE118,AE131) -> 112199.62 | AF28: =SUM(T28:AE28) -> 1223430.8
A29: [Cake] - Cashloan | E29: %Disb | F29: % | T29: =T30/T28 -> 1 | U29: =U30/U28 -> 1 | V29: =V30/V28 -> 1 | W29: =W30/W28 -> 1 | X29: =X30/X28 -> 1 | Y29: =Y30/Y28 -> 1 | Z29: =Z30/Z28 -> 1 | AA29: =AA30/AA28 -> 1 | ... AF29: =AF30/AF28 -> 1
A30: [Cake] - Cashloan | E30: Disbursed app | F30: # | T30: =SUM(T120,T133) -> 93345.559 | U30: =SUM(U120,U133) -> 86984.911 | V30: =SUM(V120,V133) -> 94595.763 | W30: =SUM(W120,W133) -> 98775.286 | X30: =SUM(X120,X133) -> 99430.914 | Y30: =SUM(Y120,Y133) -> 100086.42 | Z30: =SUM(Z120,Z133) -> 104571.35 | AA30: =SUM(AA120,AA133) -> 105259.01 | ... AE30: =SUM(AE120,AE133) -> 112199.62 | AF30: =SUM(T30:AE30) -> 1223430.8
A31: [Cake] - Cashloan | E31: Ticket size | F31: Mil VND | T31: =T32/T30 -> 3.1078431 | U31: =U32/U30 -> 3.1077739 | V31: =V32/V30 -> 3.1077058 | W31: =W32/W30 -> 3.1076389 | X31: =X32/X30 -> 3.1075731 | Y31: =Y32/Y30 -> 3.1075085 | Z31: =Z32/Z30 -> 3.107445 | AA31: =AA32/AA30 -> 3.1073826 | ... AF31: =AF32/AF30 -> 3.1074675
A32: [Cake] - Cashloan | E32: Disburse amt | F32: Mil VND | T32: =SUM(T122,T135) -> 290103.35 | U32: =SUM(U122,U135) -> 270329.43 | V32: =SUM(V122,V135) -> 293975.8 | W32: =SUM(W122,W135) -> 306957.92 | X32: =SUM(X122,X135) -> 308988.84 | Y32: =SUM(Y122,Y135) -> 311019.4 | Z32: =SUM(Z122,Z135) -> 324949.71 | AA32: =SUM(AA122,AA135) -> 327080 | ... AE32: =SUM(AE122,AE135) -> 348620.26 | AF32: =SUM(T32:AE32) -> 3801771.5
A34: [Cake] - Cashloan | E34: [Cake] - Pre-approved
A35: [Cake] - Cashloan | E35: App-in | F35: # | T35: =SUM(T142,T155) -> 48833.929 | U35: =SUM(U142,U155) -> 45104.343 | V35: =SUM(V142,V155) -> 48621.287 | W35: =SUM(W142,W155) -> 50328.812 | X35: =SUM(X142,X155) -> 50226.877 | Y35: =SUM(Y142,Y155) -> 50126.618 | Z35: =SUM(Z142,Z155) -> 51929.733 | AA35: =SUM(AA142,AA155) -> 51832.705 | ... AE35: =SUM(AE142,AE155) -> 53456.627 | AF35: =SUM(T35:AE35) -> 609385.92
