Workbook
Name Raw_B0: #REF!
Name Raw_B0: #REF!
Name Raw_RF_tbl: [1]!Table4[#All]
Name Raw_RFB0_B1: #REF!
Name Raw_RFB0_B1: #REF!
Name RFB0_B1_Tbl: [1]!RF_B0_B1_tbl[#All]
Name sum_prod_target: 'Tracking daily Target'!$E$20:$I$31
Name sum_target: 'Tracking daily Target'!$E$35:$F$39
Name top_largest_gap: 'Tracking daily Target'!$E$46:$F$50

Sheet Road to 3k
C1: ROAD TO 3K — Q2 2026 (Apr / May / Jun)
C4: Baseline tháng 3 (Daily_Mar): ~66.5 bil/day = 2k2 | Target Jun: 3k (~97 bil/day, ~3,008 bil/tháng)
D5: Daily_Mar | E5: Initiatives | F5: Group Initiative | G5: Incremental | H5: Daily_Apr | I5: Incremental | J5: Daily_May | K5: Incremental | L5: Daily_Jun | M5: PIC | N5: Status
C6: [VDS] - Cashloan | D6: 15986858000 | E6: - Universal pool | F6: Risk Enhance | G6: 2000000000 | H6: 17986858000 | J6: 20986858000 | M6: Risk | N6: Live
E7: - Risk: request = approve (50%) | F7: Risk Enhance | I7: 3000000000 | M7: Risk | N7: In progress
E8: - Risk: request = approve (70%) | F8: Risk Enhance | K8: 1000000000 | L8: 21986858000 | M8: Risk | N8: In progress
C9: [VDS] - Payday | D9: 11592244800 | E9: - VDS PD tăng app từ 5k lên 6k (Jan benchmark) | F9: App Growth | H9: 11592244800 | I9: 1738836720 | J9: 13331081520 | L9: 13331081520 | M9: MKT | N9: New
C11: [Cake] - Cashloan | D11: 12628304667 | E11: - Cake CL tăng app từ 5k6 lên 6k8 (Jan benchmark) | F11: App Growth | G11: 2525660933 | H11: 18153965600 | J11: 18153965600 | L11: 19969362160 | M11: MKT | N11: New
E12: - Universal Pool | F12: Risk Enhance | G12: 3000000000 | M12: Risk | N12: Live
E13: - Cake CL tăng app từ 6k8 lên 7k5 | F13: App Growth | K13: 1815396560 | M13: MKT | N13: New
C14: [Cake] - Payday | D14: 13618558800 | E14: - Cake PD tăng app từ 7k5 lên 8k2 (Jan benchmark) | F14: App Growth | G14: 1361855880 | H14: 17250174480 | J14: 17250174480 | L14: 17250174480 | M14: MKT | N14: New
E15: - Ticket size 4mil-5mil (repeat segment) | F15: Risk Enhance | G15: 2269759800 | M15: Risk | N15: In progress
C16: [ZALOPAY] - Cashloan | D16: 2994474000 | E16: - Universal pool | F16: Risk Enhance | G16: 1000000000 | H16: 5994474000 | J16: 5994474000 | L16: 6994474000 | M16: Risk | N16: Live
E17: - ZLP CL tăng app 600 app lên 800 app (Jan benchmark) | F17: App Growth | G17: 1000000000 | M17: Sales | N17: In progress
E18: - Pool non-score | F18: App Growth | G18: 1000000000 | K18: 1000000000 | M18: Squad team | N18: In progress
C19: [MWG] - Cashloan | D19: 3364767667 | E19: - MWG tăng app từ 350 lên 400 app | F19: App Growth | G19: 480681095 | H19: 3845448762 | M19: Sales | N19: In progress
E20: - MWG tăng app từ 400 lên 550 app (Jan benchmark) | F20: App Growth | I20: 1442043286 | J20: 5287492048 | L20: 5287492048 | M20: Sales | N20: In progress
C21: [MWG] - Paylater (QTV) | D21: 1171196560 | E21: - Benchmark với Jan | F21: App Growth | G21: 400000000 | H21: 1571196560 | J21: 3571196560 | L21: 5571196560 | M21: Sales | N21: In progress
E22: - Live CD 1:1 | F22: New Feature/Product/Partner | I22: 2000000000 | K22: 2000000000 | M22: Squad team | N22: In progress
C23: [VNPAY] | D23: 1573544661 | E23: - Tối ưu luồng sản phẩm tăng 50% Appin | F23: App Growth | G23: 786772331 | H23: 2360316992 | J23: 2360316992 | L23: 2360316992 | M23: Squad team | N23: In progress
C24: [FIZA] - Payday | F24: New Feature/Product/Partner | K24: 1000000000 | L24: 1000000000 | M24: Squad team | N24: In progress
C25: Others | D25: 3568655822 | H25: 3568655822 | J25: 3568655822 | L25: 3568655822
C26: Total | D26: 66498604977 | G26: 15824730039 | H26: 82323335016 | I26: 8180880006 | J26: 90504215021 | K26: 6815396560 | L26: 97319611581
C27: Monthly total (bil) | H27: 2552023385486 | J27: 2805630665663 | L27: 3016907959023
C28: Avg ticket size (mil)
F29: Risk Enhance | G29: =SUMIFS(G$6:G$24,$F$6:$F$24,$F29) -> 8269759800 | H29: =SUMIFS(H$6:H$24,$F$6:$F$24,$F29) -> 23981332000 | I29: =SUMIFS(I$6:I$24,$F$6:$F$24,$F29) -> 3000000000 | J29: =SUMIFS(J$6:J$24,$F$6:$F$24,$F29) -> 26981332000 | K29: =SUMIFS(K$6:K$24,$F$6:$F$24,$F29) -> 1000000000 | L29: =SUMIFS(L$6:L$24,$F$6:$F$24,$F29) -> 28981332000
F30: App Growth | G30: =SUMIFS(G$6:G$24,$F$6:$F$24,$F30) -> 7554970239 | H30: =SUMIFS(H$6:H$24,$F$6:$F$24,$F30) -> 54773347194 | I30: =SUMIFS(I$6:I$24,$F$6:$F$24,$F30) -> 3180880006 | J30: =SUMIFS(J$6:J$24,$F$6:$F$24,$F30) -> 59954227200 | K30: =SUMIFS(K$6:K$24,$F$6:$F$24,$F30) -> 2815396560 | L30: =SUMIFS(L$6:L$24,$F$6:$F$24,$F30) -> 63769623760
F31: New Feature/Product/Partner | G31: =SUMIFS(G$6:G$24,$F$6:$F$24,$F31) -> 0 | H31: =SUMIFS(H$6:H$24,$F$6:$F$24,$F31) -> 0 | I31: =SUMIFS(I$6:I$24,$F$6:$F$24,$F31) -> 2000000000 | J31: =SUMIFS(J$6:J$24,$F$6:$F$24,$F31) -> 0 | K31: =SUMIFS(K$6:K$24,$F$6:$F$24,$F31) -> 3000000000 | L31: =SUMIFS(L$6:L$24,$F$6:$F$24,$F31) -> 1000000000
C32: [Cake] - Cashloan | E32: - Risk: request = approve (50%) | F32: Risk Enhance
E33: - Risk: request = approve (70%) | F33: Risk Enhance
C34: [ZALOPAY] - Cashloan | E34: Tăng ticket size | F34: Risk Enhance
C35: [MWG] - Payday | E35: New product launch | F35: App Growth | M35: Sales | N35: In progress

Sheet Road to 3k v2
C1: ROAD TO 3K — Q2 2026 (Apr / May / Jun)
C4: Baseline tháng 3 (Daily_MTD Apr): ~75 bil/day | Target Jun: 3k (~97 bil/day, ~3,008 bil/tháng)
D5: Daily_MTD Apr | E5: Initiatives | F5: Group Initiative | G5: Incremental | H5: Daily_MTG | I5: Incremental | J5: Daily_May | K5: Incremental | L5: Daily_Jun | M5: PIC | N5: Status
B6: VDS | C6: [VDS] - Cashloan | D6: =Pivot!C13 -> 168117780000 | H6: =D6 -> 168117780000 | J6: =H6+I7 -> 170117780000 | L6: =J6+K8 -> 173117780000
C7: =C6 -> [VDS] - Cashloan | E7: - Risk: request = approve (50%) | F7: Risk Enhance | I7: 2000000000 | M7: Risk | N7: In progress
C8: =C7 -> [VDS] - Cashloan | E8: - Risk: request = approve (70%) | F8: Risk Enhance | K8: 3000000000 | M8: Risk | N8: In progress
B9: VDS | C9: [VDS] - Payday | D9: =Pivot!C14 -> 119993292000 | H9: =D9 -> 119993292000 | J9: =H9+I11+I10 -> 1.4070792e+11 | L9: =J9 -> 1.4070792e+11
C10: =C9 -> [VDS] - Payday | E10: - VDS PD tăng app từ 5k7 lên 6k (Jan benchmark) | F10: App Growth | I10: =(6/5.7-1)*H9 -> 6.3154364e+09 | M10: MKT | N10: In progress
C11: =C10 -> [VDS] - Payday | E11: - Tăng ticket nhóm repeat từ 4,7tr lên 5tr2 | F11: Risk Enhance | I11: =D9*15%*80% -> 14399195040 | M11: Risk | N11: In progress
B12: Cake | C12: [Cake] - Cashloan | D12: =Pivot!C5 -> 147805250000 | H12: =D12+G13 -> 149805250000 | J12: =H12+I14 -> 151805250000 | L12: =J12+K14 -> 154805250000
C13: =C12 -> [Cake] - Cashloan | E13: - Cake CL tăng app new (loại universal pool) từ 3k8 lên 5k4 | F13: App Growth | G13: 2000000000 | J13: =H13+I15 -> 0 | M13: MKT | N13: In progress
C14: =C13 -> [Cake] - Cashloan | E14: - Risk: request = approve (50%-70%) | F14: Risk Enhance | I14: 2000000000 | K14: 3000000000 | M14: Risk | N14: In progress
B15: Cake | C15: [Cake] - Payday | D15: =Pivot!C7 -> 157621248000 | H15: =D15 -> 157621248000 | J15: =H15+I17+I18 -> 159621248000 | L15: =J15 -> 159621248000
C16: =C15 -> [Cake] - Payday | E16: - Cake PD tăng app từ 7k5 lên 8k2 (Jan benchmark) | F16: App Growth | M16: MKT | N16: In progress
C18: =C15 -> [Cake] - Payday | E18: - Tăng ticket size avg 4.5 => 5.5 mil (repeat segment) | F18: Risk Enhance | I18: 2000000000
B19: ZLP | C19: [ZALOPAY] - Cashloan | D19: =Pivot!C21 -> 60270480000 | H19: =D19 -> 60270480000 | J19: =H19+I20+I21 -> 6.9880549e+10 | L19: =J19+K21 -> 7.0880549e+10
C20: =C19 -> [ZALOPAY] - Cashloan | E20: - Tăng ticket size (14mil-16mil) | F20: App Growth | I20: =(16/14-1)*D19 -> 8.6100686e+09 | M20: Risk | N20: In progress
C21: =C20 -> [ZALOPAY] - Cashloan | E21: - Pool non-score | F21: App Growth | I21: 1000000000 | K21: 1000000000 | M21: Squad team | N21: In progress
B22: MWG | C22: [MWG] - Cashloan | D22: =Pivot!C9+Pivot!C10 -> 37938060000 | H22: =D22 -> 37938060000 | J22: =H22+I23+I24 -> 42231866000 | L22: =J22 -> 42231866000
C23: =C22 -> [MWG] - Cashloan | E23: - MWG tăng app từ 400 lên 550 app (Jan benchmark) | F23: App Growth | I23: 500000000 | M23: Sales | N23: In progress
C24: =C23 -> [MWG] - Cashloan | E24: - Tăng AR 50%-55% | F24: Risk Enhance | I24: =(55/50-1)*H22 -> 3.793806e+09 | M24: Sales | N24: In progress
B25: MWG | C25: [MWG] - Paylater (QTV) | D25: =Pivot!C11 -> 13217452045 | H25: =D25+G26 -> 13517452045 | J25: =H25+I27 -> 15517452045 | L25: =J25+K27 -> 17517452045
C26: =C25 -> [MWG] - Paylater (QTV) | E26: - Benchmark với Jan | F26: App Growth | G26: 300000000 | L26: =J26+K28 -> 0 | M26: Sales | N26: In progress
C27: =C26 -> [MWG] - Paylater (QTV) | E27: - Live CD 1:1 | F27: New Feature/Product/Partner | I27: 2000000000 | K27: 2000000000 | M27: Squad team | N27: In progress
B28: NEW CHANNEL | C28: [VNPAY] | D28: =SUM(Pivot!C18:C20) -> 18051788374 | E28: - Tối ưu luồng sản phẩm tăng 50% Appin | F28: App Growth | H28: =D28 -> 18051788374 | I28: 700000000 | J28: =H28+I28 -> 18751788374 | L28: =J28 -> 18751788374 | M28: Squad team | N28: In progress
B29: NEW CHANNEL | C29: [FIZA] - Payday | F29: New Feature/Product/Partner | I29: 700000000 | J29: =H29+I29 -> 700000000 | K29: 300000000 | L29: =J29+K29 -> 1000000000 | M29: Squad team | N29: In progress
B30: OTHERS | C30: Others | D30: =Pivot!C22-SUM('Road to 3k v2'!D6:D28) -> -723015350419 | H30: =D30 -> -723015350419 | J30: =H30 -> -723015350419 | L30: =J30 -> -723015350419
C31: Total | D31: =Pivot!C22 -> 0 | G31: =SUM(G6:G30) -> 2300000000 | H31: =SUM(H6:H30) -> 2300000000 | I31: =SUM(I6:I30) -> 4.4018506e+10 | J31: =SUM(J6:J30) -> 4.6318506e+10 | K31: =SUM(K6:K30) -> 9300000000 | L31: =SUM(L6:L30) -> 5.5618506e+10
C32: Monthly total (bil) | H32: =H31*30 -> 69000000000 | J32: =J31*31 -> 1.4358737e+12 | L32: =L31*30 -> 1.6685552e+12
C33: Avg ticket size (mil) | G33: =H32-D34 -> 69000000000 | H33: =G33/11 -> 6.2727273e+09
D34: =D31*30 -> 0 | E34: =(D31*19)+(D31+G31)*11 -> 25300000000 | G34: =(D31*19)+(G31+D31)*11 -> 25300000000
G35: TARGET DAILY | H35: CHANNEL | I35: APR | J35: MAY | K35: JUN | M35: CHANNEL | N35: APR | O35: MAY | P35: JUN
H36: VDS | I36: 27 | J36: 35 | K36: 40 | M36: VDS | N36: =SUM('waterfall 3k'!E5:E6)/1000000000 -> 0 | O36: =SUM('waterfall 3k'!G5:G6)/1000000000 -> 30.087646 | P36: =SUM('waterfall 3k'!I5:I6)/1000000000 -> 30.087646
H37: CAKE | I37: 35 | J37: 37 | K37: 40 | M37: CAKE | N37: =SUM('waterfall 3k'!E7:E8)/1000000000 -> 0 | O37: =SUM('waterfall 3k'!G7:G8)/1000000000 -> 40.554051 | P37: =SUM('waterfall 3k'!I7:I8)/1000000000 -> 40.554051
H38: ZLP | I38: 6 | J38: 8 | K38: 10 | M38: ZLP | N38: ='waterfall 3k'!E9/1000000000 -> 0 | O38: ='waterfall 3k'!G9/1000000000 -> 7.7270829 | P38: ='waterfall 3k'!I9/1000000000 -> 9.7270829
H39: MWG | I39: 5 | J39: 8 | K39: 10 | M39: MWG | N39: =SUM('waterfall 3k'!E10:E11)/1000000000 -> 0 | O39: =SUM('waterfall 3k'!G10:G11)/1000000000 -> 8.3381256 | P39: =SUM('waterfall 3k'!I10:I11)/1000000000 -> 10.338126
H40: NEW CHANNEL | J40: 1 | K40: 1 | M40: [VNPAY] | N40: ='waterfall 3k'!E12/1000000000 -> 0 | O40: ='waterfall 3k'!G12/1000000000 -> 2.2158571 | P40: ='waterfall 3k'!I12/1000000000 -> 2.2158571
H41: OTHERS | I41: 5 | J41: 5 | K41: 5 | M41: NEW CHANNEL | N41: ='waterfall 3k'!E13/1000000000 -> 0 | O41: ='waterfall 3k'!G13/1000000000 -> 0.7 | P41: ='waterfall 3k'!I13/1000000000 -> 1
H42: DAILY DISBURSE | I42: =SUM(I36:I41) -> 78 | J42: =SUM(J36:J41) -> 94 | K42: =SUM(K36:K41) -> 106 | M42: OTHERS | N42: ='waterfall 3k'!E14/1000000000 -> 0 | O42: ='waterfall 3k'!G14/1000000000 -> 3.8154967 | P42: ='waterfall 3k'!I14/1000000000 -> 3.8154967
H43: MONTLY DISBURSE | I43: =I42*30 -> 2340 | J43: =J42*31 -> 2914 | K43: =K42*30 -> 3180 | M43: DAILY DISBURSE | N43: =SUM(N36:N42) -> 0 | O43: =SUM(O36:O42) -> 93.43826 | P43: =SUM(P36:P42) -> 97.73826
...

Sheet Road to 3k v2 (2)
C1: ROAD TO 3K — Q2 2026 (Apr / May / Jun)
C4: Baseline tháng 3 (Daily_MTD Apr): ~75 bil/day | Target Jun: 3k (~97 bil/day, ~3,008 bil/tháng)
D5: Daily_MTD May | E5: Initiatives | F5: Group Initiative | G5: Incremental | H5: Daily_Apr | I5: Incremental | J5: Daily_May | K5: Incremental | L5: Daily_Jun | M5: PIC | N5: Status
B6: VDS | C6: [VDS] - Cashloan | D6: =168117780000/10 -> 16811778000 | H6: =GETPIVOTDATA("Total",Pivot!$A$2,"lending_product_transform",'Road to 3k v2 (2)'!$C6)/30 -> 1.6402516e+10 | J6: =H6+I7 -> 1.8402516e+10 | L6: =J6+K7 -> 1.8402516e+10
C7: =C6 -> [VDS] - Cashloan | E7: - Risk: request = approve | F7: Risk Enhance | I7: 2000000000 | M7: Risk | N7: Lived
B8: VDS | C8: [VDS] - Payday | D8: =Pivot!C14/10 -> 11999329200 | H8: =GETPIVOTDATA("Total",Pivot!$A$2,"lending_product_transform",'Road to 3k v2 (2)'!$C8)/30 -> 11100873600 | J8: =H8+I10+I9 -> 1.168513e+10 | L8: =J8 -> 1.168513e+10
C9: =C8 -> [VDS] - Payday | E9: - VDS PD tăng app từ 5k7 lên 6k (Jan benchmark) | F9: App Growth | I9: =(6/5.7-1)*H8 -> 5.8425651e+08 | M9: MKT | N9: Lived (W19 VDS PD App-in hit 6,797 app/daily)
C10: =C9 -> [VDS] - Payday | E10: - Tăng ticket nhóm repeat từ 4,7tr lên 5tr2 | F10: Risk Enhance | M10: Risk | N10: On hold
B11: Cake | C11: [Cake] - Cashloan | D11: =Pivot!C5/10 -> 14780525000 | H11: =GETPIVOTDATA("Total",Pivot!$A$2,"lending_product_transform",'Road to 3k v2 (2)'!$C11)/30 -> 1.4795032e+10 | J11: =H11+I13+I12 -> 2.2233542e+10 | L11: =J11+K13 -> 2.2233542e+10
C12: =C11 -> [Cake] - Cashloan | E12: - Cake CL daily app 11k5 (vs Apr 8k9) | F12: App Growth | I12: =H11*30% -> 4438509700 | J12: =H12+I14 -> 0 | M12: MKT | N12: In progress
C13: =C12 -> [Cake] - Cashloan | E13: - Risk: request = approve | F13: Risk Enhance | I13: 3000000000 | M13: Risk | N13: Lived | P13: =SUM(I12:I13) -> 7438509700
B14: Cake | C14: [Cake] - Payday | D14: =Pivot!C7/10 -> 15762124800 | H14: =GETPIVOTDATA("Total",Pivot!$A$2,"lending_product_transform",'Road to 3k v2 (2)'!$C14)/30 -> 14191747200 | J14: =H14+I17+I15 -> 18320509280 | L14: =J14 -> 18320509280
C15: =C14 -> [Cake] - Payday | E15: - Cake PD daily app 9k9 (vs Apr 8k6) | F15: App Growth | I15: =H14*15% -> 2128762080 | M15: MKT | N15: Lived | P15: =SUM(I15:I17) -> 4128762080
C17: =C14 -> [Cake] - Payday | E17: - Tăng ticket size nhóm repeat | F17: Risk Enhance | I17: 2000000000 | M17: Risk | N17: Lived
B18: ZLP | C18: [ZALOPAY] - Cashloan | D18: =Pivot!C21/10 -> 6027048000 | H18: =GETPIVOTDATA("Total",Pivot!$A$2,"lending_product_transform",'Road to 3k v2 (2)'!$C18)/30 -> 5866076000 | J18: =H18+I19+I20 -> 7.7270829e+09 | L18: =J18+K20+K21 -> 9.7270829e+09
C19: =C18 -> [ZALOPAY] - Cashloan | E19: - Tăng ticket size cho nhóm NTB1/2/3 | F19: Risk Enhance | I19: =(16/14-1)*D18 -> 8.6100686e+08 | M19: Risk | N19: To live this week
C20: =C19 -> [ZALOPAY] - Cashloan | E20: - Pool non-score | F20: App Growth | I20: 1000000000 | K20: 1000000000 | M20: Squad team | N20: Done | P20: =SUM(I19:I20) -> 1.8610069e+09
E21: - Paylater pool | F21: App Growth | K21: =1000000*0.2%*15000000/30 -> 1000000000 | M21: Squad team | N21: In progress
B22: MWG | C22: [MWG] - Cashloan | D22: =(Pivot!C9+Pivot!C10)/10 -> 3793806000 | H22: =GETPIVOTDATA("Total",Pivot!$A$2,"lending_product_transform",'Road to 3k v2 (2)'!$C22)/30 -> 2.6233607e+09 | J22: =H22+I23+I24 -> 4.8856967e+09 | L22: =J22 -> 4.8856967e+09
C23: =C22 -> [MWG] - Cashloan | E23: - MWG tăng app từ 400 lên 550 app (Jan benchmark) | F23: App Growth | I23: 2000000000 | M23: Sales | N23: In progress | P23: =SUM(I23:I24) -> 2.2623361e+09
C24: =C23 -> [MWG] - Cashloan | E24: - Tăng AR 50%-55% | F24: Risk Enhance | I24: =(55/50-1)*H22 -> 2.6233607e+08 | M24: Sales | N24: In progress
B25: MWG | C25: [MWG] - Paylater (QTV) | D25: =Pivot!C11/10 -> 1.3217452e+09 | H25: =GETPIVOTDATA("Total",Pivot!$A$2,"lending_product_transform",'Road to 3k v2 (2)'!$C25)/30 -> 1.1524289e+09 | J25: =H25+I27+I26 -> 3.4524289e+09 | L25: =J25+K27 -> 5.4524289e+09
C26: =C25 -> [MWG] - Paylater (QTV) | E26: - Benchmark với Jan | F26: App Growth | I26: 300000000 | L26: =J26+K28 -> 0 | M26: Sales | N26: In progress
C27: =C26 -> [MWG] - Paylater (QTV) | E27: - Live CD 1:1 | F27: New Feature/Product/Partner | I27: 2000000000 | K27: 2000000000 | M27: Squad team | N27: In progress
B28: NEW CHANNEL | C28: [VNPAY] | D28: =SUM(Pivot!C18:C20)/10 -> 1.8051788e+09 | E28: - Tối ưu luồng sản phẩm tăng 50% Appin | F28: App Growth | H28: =(GETPIVOTDATA("Total",Pivot!$A$2,"lending_product_transform","[VNPAY] - Cashloan")+GETPIVOTDATA("Total",Pivot!$A$2,"lending_product_transform","[VNPAY] - Payday")+GETPIVOTDATA("Total",Pivot!$A$2,"lending_product_transform","[VNPAY] - Paylater"))/30 -> 1.5158571e+09 | I28: 700000000 | J28: =H28+I28 -> 2.2158571e+09 | L28: =J28 -> 2.2158571e+09 | M28: Squad team | N28: In progress
B29: NEW CHANNEL | C29: [FIZA] - Payday | F29: New Feature/Product/Partner | I29: 700000000 | J29: =H29+I29 -> 700000000 | K29: 300000000 | L29: =J29+K29 -> 1000000000 | M29: Squad team | N29: In progress
B30: OTHERS | C30: Others | D30: =(Pivot!C31-SUM('Road to 3k v2 (2)'!D6:D28))/10 -> 6.9007448e+10 | H30: =H31-SUM(H6:H29) -> 3.8154967e+09 | J30: =H30 -> 3.8154967e+09 | L30: =J30 -> 3.8154967e+09
C31: Total | D31: =Pivot!C31/10 -> 7.6237601e+10 | G31: =SUM(G6:G30) -> 0 | H31: =GETPIVOTDATA("Total",Pivot!$A$2)/30 -> 7.1463389e+10 | I31: =SUM(I6:I30) -> 2.1974871e+10 | J31: =SUM(J6:J30) -> 9.343826e+10 | K31: =SUM(K6:K30) -> 4300000000 | L31: =SUM(L6:L30) -> 9.773826e+10
C32: Monthly total (bil) | D32: =D31*10 -> 762376012773 | H32: =H31*30 -> 2143901666325 | J32: =J31*31 -> 2.8965861e+12 | L32: =L31*30 -> 2.9321478e+12
J33: =J31-D31 -> 1.7200659e+10
C34: Avg ticket size (mil)
D35: =D31*30 -> 2287128038319 | E35: =(D31*19)+(D31+G31)*11 -> 2287128038319 | H35: =H32-D35 -> -143226371994
H36: =(D31*19)+(G31+D31)*11 -> 2287128038319
H37: TARGET DAILY | I37: CHANNEL | J37: APR | K37: MAY | L37: JUN | N37: CHANNEL | O37: APR | P37: MAY | Q37: JUN
I38: VDS | J38: 27 | K38: 35 | L38: 40 | N38: VDS | O38: =SUM('waterfall 3k'!E5:E6)/1000000000 -> 0 | P38: =SUM('waterfall 3k'!G5:G6)/1000000000 -> 30.087646 | Q38: =SUM('waterfall 3k'!I5:I6)/1000000000 -> 30.087646
I39: CAKE | J39: 35 | K39: 37 | L39: 40 | N39: CAKE | O39: =SUM('waterfall 3k'!E7:E8)/1000000000 -> 0 | P39: =SUM('waterfall 3k'!G7:G8)/1000000000 -> 40.554051 | Q39: =SUM('waterfall 3k'!I7:I8)/1000000000 -> 40.554051
I40: ZLP | J40: 6 | K40: 8 | L40: 10 | N40: ZLP | O40: ='waterfall 3k'!E9/1000000000 -> 0 | P40: ='waterfall 3k'!G9/1000000000 -> 7.7270829 | Q40: ='waterfall 3k'!I9/1000000000 -> 9.7270829
I41: MWG | J41: 5 | K41: 8 | L41: 10 | N41: MWG | O41: =SUM('waterfall 3k'!E10:E11)/1000000000 -> 0 | P41: =SUM('waterfall 3k'!G10:G11)/1000000000 -> 8.3381256 | Q41: =SUM('waterfall 3k'!I10:I11)/1000000000 -> 10.338126
I42: NEW CHANNEL | K42: 1 | L42: 1 | N42: [VNPAY] | O42: ='waterfall 3k'!E12/1000000000 -> 0 | P42: ='waterfall 3k'!G12/1000000000 -> 2.2158571 | Q42: ='waterfall 3k'!I12/1000000000 -> 2.2158571
I43: OTHERS | J43: 5 | K43: 5 | L43: 5 | N43: NEW CHANNEL | O43: ='waterfall 3k'!E13/1000000000 -> 0 | P43: ='waterfall 3k'!G13/1000000000 -> 0.7 | Q43: ='waterfall 3k'!I13/1000000000 -> 1
...

Sheet Initiative tracking
H3: APRIL | Y3: MAY | AP3: Jun
H4: Daily Actual - MTD | O4: Daily Target | Y4: Daily Actual - MTD | AF4: Daily Target | AP4: Daily Actual - MTD | AW4: Daily Target
B5: Product | C5: Initiatives | D5: Group Initiative | E5: PIC | F5: Action Month | G5: Status | H5: #App | I5: %Loscheck | J5: %Losprocess | K5: %AR | L5: %Sign | M5: Ticket size | N5: Daily Disburse amt | O5: #App | P5: %Loscheck | Q5: %Losprocess | R5: %AR | S5: %Sign | T5: Ticket size | U5: Daily Disburse amt | V5: Impact factors | X5: Impact Apr | Y5: #App | Z5: %Loscheck | AA5: %Losprocess | AB5: %AR | AC5: %Sign | AD5: Ticket size | AE5: Daily Disburse amt | AF5: #App | AG5: %Loscheck | AH5: %Losprocess | AI5: %AR | AJ5: %Sign | AK5: Ticket size | AL5: Daily Disburse amt | AM5: Impact factors | AO5: Impact May | AP5: #App | AQ5: %Loscheck | AR5: %Losprocess | AS5: %AR | AT5: %Sign | AU5: Ticket size | AV5: Daily Disburse amt | AW5: #App | AX5: %Loscheck | AY5: %Losprocess | AZ5: %AR | BA5: %Sign | BB5: Ticket size | BC5: Daily Disburse amt | BD5: Impact factors | BF5: Impact Jun
B6: [VDS] - Cashloan | C6: - Risk: request = approve (50%) | D6: Risk Enhance | E6: Risk | F6: May | G6: In progress | U6: =O6*P6*Q6*R6*S6*T6 -> 0 | Y6: 5787.6 | Z6: 0.91315917 | AA6: 0.99878903 | AB6: 0.24163604 | AC6: 0.84312034 | AD6: 15.662757 | AE6: =Y6*Z6*AA6*AB6*AC6*AD6 -> 16843.729 | AF6: 4339.2667 | AG6: 0.89147168 | AH6: 0.99914692 | AI6: 0.31496925 | AJ6: 0.84381589 | AK6: 17.944988 | AL6: 18433.69 | AM6: Ticket size | AN6: =AL6-AE6 -> 1589.9605 | AO6: 2000000000 | BC6: =AW6*AX6*AY6*AZ6*BA6*BB6 -> 0
B7: [VDS] - Cashloan | C7: - Risk: request = approve (70%) | D7: Risk Enhance | E7: Risk | F7: Jun | G7: In progress | U7: =O7*P7*Q7*R7*S7*T7 -> 0 | AL7: 0 | AP7: =AF6 -> 4339.2667 | AQ7: =AG6 -> 0.89147168 | AR7: =AH6 -> 0.99914692 | AS7: =AI6 -> 0.31496925 | AT7: =AJ6 -> 0.84381589 | AU7: =AK6 -> 17.944988 | AV7: =AP7*AQ7*AR7*AS7*AT7*AU7 -> 18433.69 | AW7: 4339.2667 | AX7: 0.89147168 | AY7: 0.99914692 | AZ7: 0.31496925 | BA7: 0.84381589 | BB7: 20.865454 | BC7: 21433.69 | BD7: Ticket size | BE7: =BC7-AV7 -> 3000 | BF7: ='Road to 3k v2'!K8 -> 3000000000
B8: [VDS] - Payday | C8: - VDS PD tăng app từ 5k7 lên 6k (Jan benchmark) | D8: App Growth | E8: MKT | F8: May | G8: In progress | U8: =O8*P8*Q8*R8*S8*T8 -> 0 | Y8: 6499.7 | Z8: 0.75938889 | AA8: 0.99870335 | AB8: 0.58092263 | AC8: 0.91171951 | AD8: 4.5960354 | AE8: =Y8*Z8*AA8*AB8*AC8*AD8 -> 11999.329 | AF8: 6102.7194 | AG8: 0.7592846 | AH8: 0.99887184 | AI8: 0.60826688 | AJ8: 0.91426257 | AK8: 4.5479334 | AL8: 11706.228 | AM8: App | AN8: =AL8-AE8 -> -293.10156 | AO8: ='Road to 3k v2'!I10 -> 6.3154364e+09 | BC8: 0
B9: [VDS] - Payday | C9: - Tăng ticket nhóm repeat từ 4,7tr lên 5tr2 | D9: Risk Enhance | E9: Risk | F9: May | G9: In progress | U9: =O9*P9*Q9*R9*S9*T9 -> 0 | Y9: 6499.7 | Z9: 0.75938889 | AA9: 0.99870335 | AB9: 0.58092263 | AC9: 0.91171951 | AD9: 4.5960354 | AE9: =Y9*Z9*AA9*AB9*AC9*AD9 -> 11999.329 | AF9: 5798.1333 | AG9: 0.7592846 | AH9: 0.99887184 | AI9: 0.60826688 | AJ9: 0.91426257 | AK9: 5.0926502 | AL9: 12454.076 | AM9: Ticket size | AN9: =AL9-AE9 -> 454.74677 | AO9: ='Road to 3k v2'!I11 -> 14399195040 | BC9: 0
B10: [Cake] - Cashloan | C10: - Cake CL tăng app new (loại universal pool) từ 3k8 lên 5k4 | D10: App Growth | E10: MKT | F10: Apr | G10: In progress | H10: 8904.9333 | I10: 1 | J10: 1 | K10: 0.16870765 | L10: 0.73936406 | M10: 13.354992 | N10: =H10*I10*J10*K10*L10*M10 -> 14834.312 | O10: 10105.519 | P10: 1 | Q10: 1 | R10: 0.16870765 | S10: 0.73936406 | T10: 13.354992 | U10: 16834.312 | V10: App | W10: =U10-N10 -> 2000 | X10: ='Road to 3k v2'!I14 -> 2000000000 | AL10: 0 | BC10: 0
B11: [Cake] - Cashloan | C11: - Risk: request = approve (50%-70%) | D11: Risk Enhance | E11: Risk | F11: May, Jun | G11: In progress | U11: 0 | Y11: 10197.4 | Z11: 1 | AA11: 1 | AB11: 0.12324718 | AC11: 0.75364513 | AD11: 15.64739 | AE11: =Y11*Z11*AA11*AB11*AC11*AD11 -> 14820.924 | AF11: 8904.9333 | AG11: 1 | AH11: 1 | AI11: 0.16870765 | AJ11: 0.73936406 | AK11: 16.055823 | AL11: 17834.312 | AM11: Ticket size | AN11: =AL11-AE11 -> 3013.3884 | AO11: 3000000000 | AP11: =AF11 -> 8904.9333 | AQ11: =AG11 -> 1 | AR11: =AH11 -> 1 | AS11: =AI11 -> 0.16870765 | AT11: =AJ11 -> 0.73936406 | AU11: =AK11 -> 16.055823 | AV11: =AP11*AQ11*AR11*AS11*AT11*AU11 -> 17834.312 | AW11: 8904.9333 | AX11: 1 | AY11: 1 | AZ11: 0.16870765 | BA11: 0.73936406 | BB11: 18.756655 | BC11: 20834.312 | BD11: Ticket size | BE11: =BC11-AV11 -> 3000 | BF11: ='Road to 3k v2'!K14 -> 3000000000
B12: [Cake] - Payday | C12: - Cake PD tăng app từ 7k5 lên 8k2 (Jan benchmark) | D12: App Growth | E12: MKT | F12: May | G12: In progress | U12: 0 | AL12: 0 | BC12: 0
B13: [Cake] - Payday | C13: - Ticket size 3,5-4,5mil (repeat segment) | D13: Risk Enhance | E13: Risk | F13: May | G13: In progress | U13: 0 | Y13: 10429 | Z13: 1 | AA13: 1 | AB13: 0.46300388 | AC13: 0.91716983 | AD13: 3.5674637 | AE13: =Y13*Z13*AA13*AB13*AC13*AD13 -> 15799.255 | AF13: 8682.2333 | AG13: 1 | AH13: 1 | AI13: 0.50165249 | AJ13: 0.9318967 | AK13: 3.5065523 | AL13: 14232.544 | AM13: Ticket size | AN13: =AL13-AE13 -> -1566.7119 | AO13: ='Road to 3k v2'!I17 -> 0 | BC13: 0
B14: [Cake] - Payday | C14: - Ticket size 4,5-6mil (repeat segment) | D14: Risk Enhance | E14: Risk | F14: May | G14: In progress | Y14: 10429 | Z14: 1 | AA14: 1 | AB14: 0.46300388 | AC14: 0.91716983 | AD14: 3.5674637 | AE14: =Y14*Z14*AA14*AB14*AC14*AD14 -> 15799.255 | AF14: 8682.2333 | AG14: 1 | AH14: 1 | AI14: 0.50165249 | AJ14: 0.9318967 | AK14: 3.9993036 | AL14: 16232.544 | AM14: Ticket size | AN14: =AL14-AE14 -> 433.28812 | AO14: 2000000000
B15: [ZALOPAY] - Cashloan | C15: - Tăng ticket size (14mil-16mil) | D15: App Growth | E15: Risk | F15: May | G15: In progress | U15: 0 | Y15: 1436.3 | Z15: 0.82454919 | AA15: 0.99881787 | AB15: 0.37856116 | AC15: 0.93948191 | AD15: 14.374071 | AE15: =Y15*Z15*AA15*AB15*AC15*AD15 -> 6047.1717 | AF15: 1233.1333 | AG15: 0.80215711 | AH15: 0.99841618 | AI15: 0.44147428 | AJ15: 0.95214067 | AK15: 16.17766 | AL15: 6715.886 | AM15: Ticket size | AN15: =AL15-AE15 -> 668.71433 | AO15: ='Road to 3k v2'!I20 -> 8.6100686e+09 | BC15: 0
B16: [ZALOPAY] - Cashloan | C16: - Pool non-score | D16: App Growth | E16: Squad team | F16: May, Jun | G16: In progress | U16: 0 | Y16: 1436.3 | Z16: 0.82454919 | AA16: 0.99881787 | AB16: 0.37856116 | AC16: 0.93948191 | AD16: 14.374071 | AE16: =Y16*Z16*AA16*AB16*AC16*AD16 -> 6047.1717 | AF16: 1442.9257 | AG16: 0.80215711 | AH16: 0.99841618 | AI16: 0.44147428 | AJ16: 0.95214067 | AK16: 14.159006 | AL16: 6877.8752 | AM16: App | AN16: =AL16-AE16 -> 830.70347 | AO16: ='Road to 3k v2'!I21 -> 1000000000 | AP16: =AF16 -> 1442.9257 | AQ16: =AG16 -> 0.80215711 | AR16: =AH16 -> 0.99841618 | AS16: =AI16 -> 0.44147428 | AT16: =AJ16 -> 0.95214067 | AU16: =AK16 -> 14.159006 | AV16: =AP16*AQ16*AR16*AS16*AT16*AU16 -> 6877.8752 | AW16: 1652.7181 | AX16: 0.80215711 | AY16: 0.99841618 | AZ16: 0.44147428 | BA16: 0.95214067 | BB16: 14.159006 | BC16: 7877.8752 | BD16: Ticket size | BE16: =BC16-AV16 -> 1000 | BF16: ='Road to 3k v2'!K21 -> 1000000000
B17: [MWG] - Cashloan | C17: - MWG tăng app từ 400 lên 550 app (Jan benchmark) | D17: App Growth | E17: Sales | F17: May | G17: In progress | U17: 0 | Y17: 440.8 | Z17: 1 | AA17: 1 | AB17: 0.41488879 | AC17: 0.90754923 | AD17: 22.868029 | AE17: =Y17*Z17*AA17*AB17*AC17*AD17 -> 3795.5281 | AF17: 442.66182 | AG17: 1 | AH17: 1 | AI17: 0.44149956 | AJ17: 0.90916272 | AK17: 22.650284 | AL17: 4024.5527 | AM17: App | AN17: =AL17-AE17 -> 229.02462 | AO17: ='Road to 3k v2'!I23 -> 500000000 | BC17: 0
B18: [MWG] - Cashloan | C18: - Tăng AR 50%-55% | D18: Risk Enhance | E18: Sales | F18: May | G18: In progress | U18: 0 | Y18: 440.8 | Z18: 1 | AA18: 1 | AB18: 0.41488879 | AC18: 0.90754923 | AD18: 22.868029 | AE18: =Y18*Z18*AA18*AB18*AC18*AD18 -> 3795.5281 | AF18: 387.66667 | AG18: 1 | AH18: 1 | AI18: 0.48489094 | AJ18: 0.90916272 | AK18: 22.650284 | AL18: 3870.9522 | AM18: AR | AN18: =AL18-AE18 -> 75.424049 | AO18: ='Road to 3k v2'!I24 -> 3.793806e+09 | BC18: 0
B19: [MWG] - Paylater (QTV) | C19: - Benchmark với Jan | D19: App Growth | E19: Sales | F19: Apr | G19: In progress | H19: 285.52381 | I19: 1 | J19: 1 | K19: 0.60440661 | L19: 0.81248274 | M19: 4.2 | N19: 1208.7673 | O19: 397.33333 | P19: 1 | Q19: 1 | R19: 0.60440661 | S19: 0.81248274 | T19: 4.2 | U19: 1508.7673 | V19: App | W19: =U19-N19 -> 300 | X19: ='Road to 3k v2'!G26 -> 300000000 | AL19: 0 | BC19: 0
B20: [MWG] - Paylater (QTV) | C20: - Live CD 1:1 | D20: New Feature/Product/Partner | E20: Squad team | F20: May, Jun | G20: In progress | U20: 0 | Y20: 285.52381 | Z20: 1 | AA20: 1 | AB20: 0.60440661 | AC20: 0.81248274 | AD20: 4.2 | AE20: 1208.7673 | AM20: App | AO20: ='Road to 3k v2'!I27 -> 2000000000 | AP20: 285.52381 | AQ20: 1 | AR20: 1 | AS20: 0.60440661 | AT20: 0.81248274 | AU20: 4.2 | AV20: 1208.7673 | BC20: 0 | BF20: ='Road to 3k v2'!K27 -> 2000000000
B21: [VNPAY] | C21: - Tối ưu luồng sản phẩm tăng 50% Appin | D21: App Growth | E21: Squad team | F21: May | G21: In progress | U21: 0 | AL21: 0 | AO21: ='Road to 3k v2'!I28 -> 700000000
B22: [VNPAY] - Cashloan | U22: 0 | Y22: 144.3 | Z22: 1 | AA22: 1 | AB22: 0.32453092 | AC22: 0.81798715 | AD22: 19.918901 | AE22: =Y22*Z22*AA22*AB22*AC22*AD22 -> 763.01709 | AF22: 214.6 | AG22: 1 | AH22: 1 | AI22: 0.32104526 | AJ22: 0.8502907 | AK22: 19.456036 | AL22: 1139.7715 | AM22: App | AN22: =AL22-AE22 -> 376.75437 | AP22: 143.85714 | AQ22: 1 | AR22: 1 | AS22: 0.31564987 | AT22: 0.8539916 | AU22: 19.802311 | AV22: =AP22*AQ22*AR22*AS22*AT22*AU22 -> 767.90325
B23: [VNPAY] - Payday | U23: 0 | Y23: 251.9 | Z23: 1 | AA23: 1 | AB23: 0.27969805 | AC23: 0.93039773 | AD23: 4.3769725 | AE23: =Y23*Z23*AA23*AB23*AC23*AD23 -> 286.9195 | AF23: 283.15 | AG23: 1 | AH23: 1 | AI23: 0.42400141 | AJ23: 0.92746978 | AK23: 4.3890898 | AL23: 488.71774 | AM23: App | AN23: =AL23-AE23 -> 201.79824 | AP23: 159.47619 | AQ23: 1 | AR23: 1 | AS23: 0.51001495 | AT23: 0.92790152 | AU23: 4.3890898 | AV23: =AP23*AQ23*AR23*AS23*AT23*AU23 -> 331.24941
B24: [VNPAY] - Paylater | U24: 0 | Y24: 400.19048 | Z24: 1 | AA24: 1 | AB24: 0.088555858 | AC24: 0.83846154 | AD24: 1.7 | AE24: 506.04596 | AF24: 600.28571 | AG24: 1 | AH24: 1 | AI24: 0.088555858 | AJ24: 0.83846154 | AK24: 1.7 | AL24: 663.21623 | AM24: App | AN24: =AO21/1000000-AN22-AN23 -> 121.44739 | AP24: 400.19048 | AQ24: 1 | AR24: 1 | AS24: 0.093377799 | AT24: 0.83928571 | AU24: 1.7 | AV24: 506.04596
B25: [FIZA] - Payday | D25: New Feature/Product/Partner | E25: Squad team | F25: Jun | G25: In progress | U25: =O25*P25*Q25*R25*S25*T25 -> 0 | AL25: 0 | AO25: ='Road to 3k v2'!I29 -> 700000000 | BC25: =AW25*AX25*AY25*AZ25*BA25*BB25 -> 0 | BF25: ='Road to 3k v2'!K29 -> 300000000
X26: =SUM(X6:X25) -> 2300000000 | AE26: =AE24/AD24 -> 297.6741 | AL26: =AL24/AK24 -> 390.12719
AE27: =16449+10855+7155 -> 34459 | AL27: =AL26/AE26-1 -> 0.31058496
AE28: =AE27/22 -> 1566.3182
H33: APRIL | Y33: MAY | AP33: Jun
H34: Daily Actual - Last Week | O34: Daily Target | Y34: Daily Actual - Last Week | AF34: Daily Target | AP34: Daily Actual - Last Week | AW34: Daily Target
B35: Product | C35: Initiatives | D35: Group Initiative | E35: PIC | F35: Action Month | G35: Status | H35: #App | I35: %Loscheck | J35: %Losprocess | K35: %AR | L35: %Sign | M35: Ticket size | N35: Daily Disburse amt | O35: #App | P35: %Loscheck | Q35: %Losprocess | R35: %AR | S35: %Sign | T35: Ticket size | U35: Daily Disburse amt | X35: Impact Apr | Y35: #App | Z35: %Loscheck | AA35: %Losprocess | AB35: %AR | AC35: %Sign | AD35: Ticket size | AE35: Daily Disburse amt | AF35: #App | AG35: %Loscheck | AH35: %Losprocess | AI35: %AR | AJ35: %Sign | AK35: Ticket size | AL35: Daily Disburse amt | AO35: Impact May | AP35: #App | AQ35: %Loscheck | AR35: %Losprocess | AS35: %AR | AT35: %Sign | AU35: Ticket size | AV35: Daily Disburse amt | AW35: #App | AX35: %Loscheck | AY35: %Losprocess | AZ35: %AR | BA35: %Sign | BB35: Ticket size | BC35: Daily Disburse amt | BF35: Impact Jun
B36: [VDS] - Cashloan | C36: - Risk: request = approve (50%) | D36: Risk Enhance | E36: Risk | F36: May | G36: In progress | N36: =H36*I36*J36*K36*L36*M36 -> 0 | U36: =O36*P36*Q36*R36*S36*T36 -> 0 | AL36: =AF36*AG36*AH36*AI36*AJ36*AK36 -> 0 | AO36: ='Road to 3k v2'!I34 -> 0 | BC36: =AW36*AX36*AY36*AZ36*BA36*BB36 -> 0
B37: [VDS] - Cashloan | C37: - Risk: request = approve (70%) | D37: Risk Enhance | E37: Risk | F37: Jun | G37: In progress | N37: =H37*I37*J37*K37*L37*M37 -> 0 | U37: =O37*P37*Q37*R37*S37*T37 -> 0 | AL37: =AF37*AG37*AH37*AI37*AJ37*AK37 -> 0 | BC37: =AW37*AX37*AY37*AZ37*BA37*BB37 -> 0 | BF37: ='Road to 3k v2'!K35 -> JUN
B38: [VDS] - Payday | C38: - VDS PD tăng app từ 5k7 lên 6k (Jan benchmark) | D38: App Growth | E38: MKT | F38: May | G38: In progress | N38: =H38*I38*J38*K38*L38*M38 -> 0 | U38: =O38*P38*Q38*R38*S38*T38 -> 0 | AL38: =AF38*AG38*AH38*AI38*AJ38*AK38 -> 0 | AO38: ='Road to 3k v2'!I37 -> 35 | BC38: =AW38*AX38*AY38*AZ38*BA38*BB38 -> 0
B39: [VDS] - Payday | C39: - Tăng ticket nhóm repeat từ 4,7tr lên 5tr2 | D39: Risk Enhance | E39: Risk | F39: May | G39: In progress | N39: =H39*I39*J39*K39*L39*M39 -> 0 | U39: =O39*P39*Q39*R39*S39*T39 -> 0 | AL39: =AF39*AG39*AH39*AI39*AJ39*AK39 -> 0 | AO39: ='Road to 3k v2'!I38 -> 6 | BC39: =AW39*AX39*AY39*AZ39*BA39*BB39 -> 0
B40: [Cake] - Cashloan | C40: - Cake CL tăng app new (loại universal pool) từ 3k8 lên 5k4 | D40: App Growth | E40: MKT | F40: Apr | G40: In progress | N40: =H40*I40*J40*K40*L40*M40 -> 0 | U40: =O40*P40*Q40*R40*S40*T40 -> 0 | X40: ='Road to 3k v2'!I41 -> 5 | AL40: =AF40*AG40*AH40*AI40*AJ40*AK40 -> 0 | BC40: =AW40*AX40*AY40*AZ40*BA40*BB40 -> 0
B41: [Cake] - Cashloan | C41: - Risk: request = approve (50%-70%) | D41: Risk Enhance | E41: Risk | F41: May, Jun | G41: In progress | N41: =H41*I41*J41*K41*L41*M41 -> 0 | U41: =O41*P41*Q41*R41*S41*T41 -> 0 | AL41: =AF41*AG41*AH41*AI41*AJ41*AK41 -> 0 | AO41: ='Road to 3k v2'!G40 -> 0 | BC41: =AW41*AX41*AY41*AZ41*BA41*BB41 -> 0 | BF41: ='Road to 3k v2'!K41 -> 5
B42: [Cake] - Payday | C42: - Cake PD tăng app từ 7k5 lên 8k2 (Jan benchmark) | D42: App Growth | E42: MKT | F42: May | G42: In progress | N42: =H42*I42*J42*K42*L42*M42 -> 0 | U42: =O42*P42*Q42*R42*S42*T42 -> 0 | AL42: =AF42*AG42*AH42*AI42*AJ42*AK42 -> 0 | BC42: =AW42*AX42*AY42*AZ42*BA42*BB42 -> 0
B43: [Cake] - Payday | C43: - Ticket size 3,5-4,5mil (repeat segment) | D43: Risk Enhance | E43: Risk | F43: May | G43: In progress | N43: =H43*I43*J43*K43*L43*M43 -> 0 | U43: =O43*P43*Q43*R43*S43*T43 -> 0 | AL43: =AF43*AG43*AH43*AI43*AJ43*AK43 -> 0 | AO43: ='Road to 3k v2'!I44 -> 0 | BC43: =AW43*AX43*AY43*AZ43*BA43*BB43 -> 0
B44: [ZALOPAY] - Cashloan | C44: - Tăng ticket size (14mil-16mil) | D44: App Growth | E44: Risk | F44: May | G44: In progress | N44: =H44*I44*J44*K44*L44*M44 -> 0 | U44: =O44*P44*Q44*R44*S44*T44 -> 0 | AL44: =AF44*AG44*AH44*AI44*AJ44*AK44 -> 0 | AO44: ='Road to 3k v2'!I46 -> 0 | BC44: =AW44*AX44*AY44*AZ44*BA44*BB44 -> 0
B45: [ZALOPAY] - Cashloan | C45: - Pool non-score | D45: App Growth | E45: Squad team | F45: May, Jun | G45: In progress | N45: =H45*I45*J45*K45*L45*M45 -> 0 | U45: =O45*P45*Q45*R45*S45*T45 -> 0 | AL45: =AF45*AG45*AH45*AI45*AJ45*AK45 -> 0 | AO45: ='Road to 3k v2'!I47 -> 2.3 | BC45: =AW45*AX45*AY45*AZ45*BA45*BB45 -> 0 | BF45: ='Road to 3k v2'!K47 -> 1
B46: [MWG] - Cashloan | C46: - MWG tăng app từ 400 lên 550 app (Jan benchmark) | D46: App Growth | E46: Sales | F46: May | G46: In progress | N46: =H46*I46*J46*K46*L46*M46 -> 0 | U46: =O46*P46*Q46*R46*S46*T46 -> 0 | AL46: =AF46*AG46*AH46*AI46*AJ46*AK46 -> 0 | AO46: ='Road to 3k v2'!I49 -> 2.3 | BC46: =AW46*AX46*AY46*AZ46*BA46*BB46 -> 0
...

Sheet waterfall 3k
B1: WATERFALL DATA — Road to 3k Q2 2026
B3: Product Summary
B4: Product | C4: Daily_May_MTD | F4: Incr_May | G4: Daily_May | H4: Incr_Jun | I4: Daily_Jun
A5: VDS | B5: ='[2]Road to 3k'!C6 -> [VDS] - Cashloan | C5: =SUMIFS('Road to 3k v2 (2)'!$H$6:$H$30,'Road to 3k v2 (2)'!$C$6:$C$30,'waterfall 3k'!$B5) -> 1.6402516e+10 | F5: =SUMIFS('Road to 3k v2 (2)'!$I$6:$I$30,'Road to 3k v2 (2)'!$C$6:$C$30,'waterfall 3k'!$B5) -> 2000000000 | G5: =C5+F5 -> 1.8402516e+10 | I5: =G5+H5 -> 1.8402516e+10 | J5: 35 | K5: 32 | L5: 35
A6: VDS | B6: ='[2]Road to 3k'!C9 -> [VDS] - Payday | C6: =SUMIFS('Road to 3k v2 (2)'!$H$6:$H$30,'Road to 3k v2 (2)'!$C$6:$C$30,'waterfall 3k'!$B6) -> 11100873600 | F6: =SUMIFS('Road to 3k v2 (2)'!$I$6:$I$30,'Road to 3k v2 (2)'!$C$6:$C$30,'waterfall 3k'!$B6) -> 5.8425651e+08 | G6: =C6+F6 -> 1.168513e+10 | I6: =G6+H6 -> 1.168513e+10 | J6: 43 | K6: 35 | L6: 40
A7: Cake | B7: ='[2]Road to 3k'!C11 -> [Cake] - Cashloan | C7: =SUMIFS('Road to 3k v2 (2)'!$H$6:$H$30,'Road to 3k v2 (2)'!$C$6:$C$30,'waterfall 3k'!$B7) -> 1.4795032e+10 | F7: =SUMIFS('Road to 3k v2 (2)'!$I$6:$I$30,'Road to 3k v2 (2)'!$C$6:$C$30,'waterfall 3k'!$B7) -> 7438509700 | G7: =C7+F7 -> 2.2233542e+10 | I7: =G7+H7 -> 2.2233542e+10 | J7: 10 | K7: 6 | L7: 10
A8: Cake | B8: ='[2]Road to 3k'!C14 -> [Cake] - Payday | C8: =SUMIFS('Road to 3k v2 (2)'!$H$6:$H$30,'Road to 3k v2 (2)'!$C$6:$C$30,'waterfall 3k'!$B8) -> 14191747200 | F8: =SUMIFS('Road to 3k v2 (2)'!$I$6:$I$30,'Road to 3k v2 (2)'!$C$6:$C$30,'waterfall 3k'!$B8) -> 4128762080 | G8: =C8+F8 -> 18320509280 | H8: =SUMIFS('Road to 3k v2'!$K$6:$K$30,'Road to 3k v2'!$C$6:$C$30,'waterfall 3k'!B8) -> 0 | I8: =G8+H8 -> 18320509280 | J8: 10 | K8: 7 | L8: 10
A9: ZLP | B9: ='[2]Road to 3k'!C16 -> [ZALOPAY] - Cashloan | C9: =SUMIFS('Road to 3k v2 (2)'!$H$6:$H$30,'Road to 3k v2 (2)'!$C$6:$C$30,'waterfall 3k'!$B9) -> 5866076000 | F9: =SUMIFS('Road to 3k v2 (2)'!$I$6:$I$30,'Road to 3k v2 (2)'!$C$6:$C$30,'waterfall 3k'!$B9) -> 1.8610069e+09 | G9: =C9+F9 -> 7.7270829e+09 | H9: ='Road to 3k v2 (2)'!K20+'Road to 3k v2 (2)'!K21 -> 2000000000 | I9: =G9+H9 -> 9.7270829e+09 | J9: 2.3 | K9: 2.3 | L9: 2.3
A10: MWG | B10: ='[2]Road to 3k'!C19 -> [MWG] - Cashloan | C10: =SUMIFS('Road to 3k v2 (2)'!$H$6:$H$30,'Road to 3k v2 (2)'!$C$6:$C$30,'waterfall 3k'!$B10) -> 2.6233607e+09 | F10: =SUMIFS('Road to 3k v2 (2)'!$I$6:$I$30,'Road to 3k v2 (2)'!$C$6:$C$30,'waterfall 3k'!$B10) -> 2.2623361e+09 | G10: =C10+F10 -> 4.8856967e+09 | H10: =SUMIFS('Road to 3k v2'!$K$6:$K$30,'Road to 3k v2'!$C$6:$C$30,'waterfall 3k'!B10) -> 0 | I10: =G10+H10 -> 4.8856967e+09 | J10: 1 | K10: 0.7 | L10: 1
A11: MWG | B11: ='[2]Road to 3k'!C21 -> [MWG] - Paylater (QTV) | C11: =SUMIFS('Road to 3k v2 (2)'!$H$6:$H$30,'Road to 3k v2 (2)'!$C$6:$C$30,'waterfall 3k'!$B11) -> 1.1524289e+09 | F11: =SUMIFS('Road to 3k v2 (2)'!$I$6:$I$30,'Road to 3k v2 (2)'!$C$6:$C$30,'waterfall 3k'!$B11) -> 2300000000 | G11: =C11+F11 -> 3.4524289e+09 | H11: ='Road to 3k v2 (2)'!K27 -> 2000000000 | I11: =G11+H11 -> 5.4524289e+09 | J11: 4 | K11: 4 | L11: 4
A12: VNPAY | B12: ='[2]Road to 3k'!C23 -> [VNPAY] | C12: =SUMIFS('Road to 3k v2 (2)'!$H$6:$H$30,'Road to 3k v2 (2)'!$C$6:$C$30,'waterfall 3k'!$B12) -> 1.5158571e+09 | F12: =SUMIFS('Road to 3k v2 (2)'!$I$6:$I$30,'Road to 3k v2 (2)'!$C$6:$C$30,'waterfall 3k'!$B12) -> 700000000 | G12: =C12+F12 -> 2.2158571e+09 | H12: =SUMIFS('Road to 3k v2'!$K$6:$K$30,'Road to 3k v2'!$C$6:$C$30,'waterfall 3k'!B12) -> 0 | I12: =G12+H12 -> 2.2158571e+09
A13: NEW CHANNEL | B13: [FIZA] - Payday | C13: =SUMIFS('Road to 3k v2 (2)'!$H$6:$H$30,'Road to 3k v2 (2)'!$C$6:$C$30,'waterfall 3k'!$B13) -> 0 | F13: =SUMIFS('Road to 3k v2 (2)'!$I$6:$I$30,'Road to 3k v2 (2)'!$C$6:$C$30,'waterfall 3k'!$B13) -> 700000000 | G13: =C13+F13 -> 700000000 | H13: ='Road to 3k v2 (2)'!K29 -> 300000000 | I13: =G13+H13 -> 1000000000
A14: Others | B14: ='[2]Road to 3k'!C25 -> Others | C14: =SUMIFS('Road to 3k v2 (2)'!$H$6:$H$30,'Road to 3k v2 (2)'!$C$6:$C$30,'waterfall 3k'!$B14) -> 3.8154967e+09 | F14: =SUMIFS('Road to 3k v2 (2)'!$I$6:$I$30,'Road to 3k v2 (2)'!$C$6:$C$30,'waterfall 3k'!$B14) -> 0 | G14: =C14+F14 -> 3.8154967e+09 | H14: =SUMIFS('Road to 3k v2'!$K$6:$K$30,'Road to 3k v2'!$C$6:$C$30,'waterfall 3k'!B14) -> 0 | I14: =G14+H14 -> 3.8154967e+09
B15: Total | C15: =SUM(C5:C14) -> 7.1463389e+10 | F15: =SUM(F5:F14) -> 2.1974871e+10 | G15: =C15+F15 -> 9.343826e+10 | H15: =SUM(H5:H14) -> 4300000000 | I15: =G15+H15 -> 9.773826e+10
F16: 1.7107129e+10 | G16: =G15-'Road to 3k v2'!J31 -> 4.7119754e+10
B17: Waterfall Chart Data | F17: =F16-F15 -> -4.8677425e+09 | I17: =I18/30 -> 71.463389 | J17: =I18/11 -> 194.90015
B18: Category | C18: Value | D18: Is Total | E18: Value (bil) | G18: Category | H18: Value (bil) | I18: =I19-I27 -> 2143.9017 | K18: Channel | L18: Value (bil)
B19: Daily_Apr | C19: =C15 -> 7.1463389e+10 | D19: Total | E19: =C19/1000000000 -> 71.463389 | G19: =B19 -> Daily_Apr | H19: =E19 -> 71.463389 | I19: =H19*30 -> 2143.9017 | K19: =G19 -> Daily_Apr | L19: =H19 -> 71.463389
B20: =B5 -> [VDS] - Cashloan | C20: =D5 -> 0 | E20: =C20/1000000000 -> 0 | G20: VDS CL | I20: 1421.315 | K20: VDS | L20: =SUMIFS($D$5:$D$14,$A$5:$A$14,K20)/1000000000 -> 0
B21: =B7 -> [Cake] - Cashloan | C21: =D7 -> 0 | E21: =C21/1000000000 -> 0 | G21: Cake CL | H21: =E21 -> 0 | I21: =I20-I27 -> 1421.315 | K21: CAKE | L21: =SUMIFS($D$5:$D$14,$A$5:$A$14,K21)/1000000000 -> 0
B22: =B8 -> [Cake] - Payday | C22: =D8 -> 0 | E22: =C22/1000000000 -> 0 | G22: Cake PD | I22: =I21/11 -> 129.21045 | K22: ZLP | L22: =SUMIFS($D$5:$D$14,$A$5:$A$14,K22)/1000000000 -> 0
B23: =B9 -> [ZALOPAY] - Cashloan | C23: =D9 -> 0 | E23: =C23/1000000000 -> 0 | G23: ZLP CL | K23: MWG | L23: =SUMIFS($D$5:$D$14,$A$5:$A$14,K23)/1000000000 -> 0
B24: =B10 -> [MWG] - Cashloan | C24: =D10 -> 0 | E24: =C24/1000000000 -> 0 | G24: MWG CL | K24: VNPAY | L24: =SUMIFS($D$5:$D$14,$A$5:$A$14,K24)/1000000000 -> 0
B25: =B11 -> [MWG] - Paylater (QTV) | C25: =D11 -> 0 | E25: =C25/1000000000 -> 0 | G25: MWG PL QTV | H25: =E25 -> 0 | K25: NEW CHANNEL | L25: =SUMIFS($D$5:$D$14,$A$5:$A$14,K25)/1000000000 -> 0
B26: =B12 -> [VNPAY] | C26: =D12 -> 0 | E26: =C26/1000000000 -> 0 | G26: VNPAY | K26: OTHERS | L26: =SUMIFS($D$5:$D$14,$A$5:$A$14,K26)/1000000000 -> 0
B27: Daily_Apr_Target | C27: =E15 -> 0 | D27: Total | E27: =C27/1000000000 -> 0 | G27: =B27 -> Daily_Apr_Target | I27: =H27*30 -> 0 | K27: =G27 -> Daily_Apr_Target | L27: =SUM(L19:L26) -> 71.463389 | M27: =L27*30 -> 2143.9017
B28: =B5 -> [VDS] - Cashloan | C28: =F5 -> 2000000000 | E28: =C28/1000000000 -> 2 | G28: VDS CL | K28: VDS | L28: =SUMIFS($F$5:$F$14,$A$5:$A$14,K28)/1000000000 -> 2.5842565
B29: =B6 -> [VDS] - Payday | C29: =F6 -> 5.8425651e+08 | E29: =C29/1000000000 -> 0.58425651 | G29: VDS PD | K29: CAKE | L29: =SUMIFS($F$5:$F$14,$A$5:$A$14,K29)/1000000000 -> 11.567272
B30: =B10 -> [MWG] - Cashloan | C30: =F10 -> 2.2623361e+09 | E30: =C30/1000000000 -> 2.2623361 | G30: MWG CL | K30: ZLP | L30: =SUMIFS($F$5:$F$14,$A$5:$A$14,K30)/1000000000 -> 1.8610069
B31: =B11 -> [MWG] - Paylater (QTV) | C31: =F11 -> 2300000000 | E31: =C31/1000000000 -> 2.3 | G31: MWG PL QTV | K31: MWG | L31: =SUMIFS($F$5:$F$14,$A$5:$A$14,K31)/1000000000 -> 4.5623361
B32: Daily_May | C32: =G15 -> 9.343826e+10 | D32: Total | E32: =C32/1000000000 -> 93.43826 | G32: =B32 -> Daily_May | H32: =E32 -> 93.43826 | I32: =H32*31 -> 2896.5861 | K32: VNPAY | L32: =SUMIFS($F$5:$F$14,$A$5:$A$14,K32)/1000000000 -> 0.7
B33: =B5 -> [VDS] - Cashloan | C33: =H5 -> 0 | E33: =C33/1000000000 -> 0 | G33: VDS CL | H33: =E33 -> 0 | K33: NEW CHANNEL | L33: =SUMIFS($F$5:$F$14,$A$5:$A$14,K33)/1000000000 -> 0.7
B34: =B7 -> [Cake] - Cashloan | C34: =H7 -> 0 | E34: =C34/1000000000 -> 0 | G34: Cake CL | H34: =E34 -> 0 | K34: OTHERS | L34: =SUMIFS($F$5:$F$14,$A$5:$A$14,K34)/1000000000 -> 0
B35: =B9 -> [ZALOPAY] - Cashloan | C35: =H9 -> 2000000000 | E35: =C35/1000000000 -> 2 | G35: ZLP CL | H35: =E35 -> 2 | K35: =G32 -> Daily_May | L35: =SUM(L27:L34) -> 93.43826 | M35: =L35*31 -> 2896.5861
B36: =B11 -> [MWG] - Paylater (QTV) | C36: =H11 -> 2000000000 | E36: =C36/1000000000 -> 2 | G36: MWG PL QTV | H36: =E36 -> 2 | K36: VDS | L36: =SUMIFS($H$5:$H$14,$A$5:$A$14,K36)/1000000000 -> 0
B37: =B13 -> [FIZA] - Payday | C37: =H13 -> 300000000 | E37: =C37/1000000000 -> 0.3 | G37: =B37 -> [FIZA] - Payday | H37: =E37 -> 0.3 | K37: CAKE | L37: =SUMIFS($H$5:$H$14,$A$5:$A$14,K37)/1000000000 -> 0
B38: Daily_Jun | C38: =I15 -> 9.773826e+10 | D38: Total | E38: =C38/1000000000 -> 97.73826 | G38: =B38 -> Daily_Jun | H38: =E38 -> 97.73826 | I38: =H38*30 -> 2932.1478 | K38: ZLP | L38: =SUMIFS($H$5:$H$14,$A$5:$A$14,K38)/1000000000 -> 2
K39: MWG | L39: =SUMIFS($H$5:$H$14,$A$5:$A$14,K39)/1000000000 -> 2
K40: VNPAY | L40: =SUMIFS($H$5:$H$14,$A$5:$A$14,K40)/1000000000 -> 0
K41: NEW CHANNEL | L41: =SUMIFS($H$5:$H$14,$A$5:$A$14,K41)/1000000000 -> 0.3
...

Sheet Tracking daily Target
G2: 10
G3: 5
E4: Mapping | F4: Channel | G4: MTD-Daily Disbursement | H4: Target May | I4: % | J4: Gap with Target
E5: [VDS] - Cashloan | F5: [VDS] - Cashloan | G5: =IFERROR(GETPIVOTDATA("Total",source!$K$4,"Year",2026,"Month",'Tracking daily Target'!G$3,"Product_use",'Tracking daily Target'!$E5)/$G$2,0) -> 16811778000 | H5: =VLOOKUP(F5,'waterfall 3k'!$B$4:$G$15,6,0) -> 1.8402516e+10 | I5: =G5/H5 -> 0.91355865 | J5: =G5-H5 -> -1.5907383e+09
E6: [VDS] - Payday | F6: [VDS] - Payday | G6: =IFERROR(GETPIVOTDATA("Total",source!$K$4,"Year",2026,"Month",'Tracking daily Target'!G$3,"Product_use",'Tracking daily Target'!$E6)/$G$2,0) -> 11999329200 | H6: =VLOOKUP(F6,'waterfall 3k'!$B$4:$G$15,6,0) -> 1.168513e+10 | I6: =G6/H6 -> 1.0268888 | J6: =G6-H6 -> 3.1419909e+08
E7: [Cake] - Cashloan | F7: [Cake] - Cashloan | G7: =IFERROR(GETPIVOTDATA("Total",source!$K$4,"Year",2026,"Month",'Tracking daily Target'!G$3,"Product_use",'Tracking daily Target'!$E7)/$G$2,0) -> 14780525000 | H7: =VLOOKUP(F7,'waterfall 3k'!$B$4:$G$15,6,0) -> 2.2233542e+10 | I7: =G7/H7 -> 0.66478499 | J7: =G7-H7 -> -7.453017e+09
E8: [Cake] - Payday | F8: [Cake] - Payday | G8: =IFERROR(GETPIVOTDATA("Total",source!$K$4,"Year",2026,"Month",'Tracking daily Target'!G$3,"Product_use",'Tracking daily Target'!$E8)/$G$2,0) -> 15762124800 | H8: =VLOOKUP(F8,'waterfall 3k'!$B$4:$G$15,6,0) -> 18320509280 | I8: =G8/H8 -> 0.86035407 | J8: =G8-H8 -> -2558384480
E9: [ZLP] - Cashloan | F9: [ZALOPAY] - Cashloan | G9: =IFERROR(GETPIVOTDATA("Total",source!$K$4,"Year",2026,"Month",'Tracking daily Target'!G$3,"Product_use",'Tracking daily Target'!$E9)/$G$2,0) -> 6027048000 | H9: =VLOOKUP(F9,'waterfall 3k'!$B$4:$G$15,6,0) -> 7.7270829e+09 | I9: =G9/H9 -> 0.77999008 | J9: =G9-H9 -> -1.7000349e+09
E10: [MWG] - Cashloan | F10: [MWG] - Cashloan | G10: =IFERROR(GETPIVOTDATA("Total",source!$K$4,"Year",2026,"Month",'Tracking daily Target'!G$3,"Product_use",'Tracking daily Target'!$E10)/$G$2,0) -> 3793806000 | H10: =VLOOKUP(F10,'waterfall 3k'!$B$4:$G$15,6,0) -> 4.8856967e+09 | I10: =G10/H10 -> 0.77651279 | J10: =G10-H10 -> -1.0918907e+09
E11: [MWG] - Paylater | F11: [MWG] - Paylater (QTV) | G11: =IFERROR(GETPIVOTDATA("Total",source!$K$4,"Year",2026,"Month",'Tracking daily Target'!G$3,"Product_use",'Tracking daily Target'!$E11)/$G$2,0) -> 1.3363773e+09 | H11: =VLOOKUP(F11,'waterfall 3k'!$B$4:$G$15,6,0) -> 3.4524289e+09 | I11: =G11/H11 -> 0.38708323 | J11: =G11-H11 -> -2.1160515e+09
A12: [VNPAY] - Cashloan | B12: [VNPAY] - Payday | C12: [VNPAY] - Paylater | E12: [VNPAY] | F12: [VNPAY] | G12: =(IFERROR(GETPIVOTDATA("Total",source!$K$4,"Year",2026,"Month",'Tracking daily Target'!G$3,"Product_use","[VNPAY] - Payday"),0)+IFERROR(GETPIVOTDATA("Total",source!$K$4,"Year",2026,"Month",'Tracking daily Target'!G$3,"Product_use","[VNPAY] - Paylater"),0)+IFERROR(GETPIVOTDATA("Total",source!$K$4,"Year",2026,"Month",'Tracking daily Target'!G$3,"Product_use","[VNPAY] - Cashloan"),0))/$G$2 -> 1.8051788e+09 | H12: =VLOOKUP(F12,'waterfall 3k'!$B$4:$G$15,6,0) -> 2.2158571e+09 | I12: =G12/H12 -> 0.81466391 | J12: =G12-H12 -> -4.1067831e+08
E13: [FIZA] - Payday | F13: [FIZA] - Payday | G13: =IFERROR(GETPIVOTDATA("Total",source!$K$4,"Year",2026,"Month",'Tracking daily Target'!G$3,"Product_use",'Tracking daily Target'!$E13)/$G$2,0) -> 0 | H13: =VLOOKUP(F13,'waterfall 3k'!$B$4:$G$15,6,0) -> 700000000 | J13: =G13-H13 -> -700000000
E14: Others | F14: Others | G14: =G15-SUM(G5:G13) -> 3.9214341e+09 | H14: =VLOOKUP(F14,'waterfall 3k'!$B$4:$G$15,6,0) -> 3.8154967e+09 | I14: =G14/H14 -> 1.027765 | J14: =G14-H14 -> 1.0593739e+08
F15: Total | G15: =GETPIVOTDATA("Total",source!$K$4,"Year",2026,"Month",'Tracking daily Target'!G$3)/10 -> 7.6237601e+10 | H15: =SUM(H5:H14) -> 9.343826e+10 | I15: =G15/H15 -> 0.81591418 | J15: =SUM(J5:J14) -> -1.7200659e+10
E18: TRACKING DASHBOARD — Week 15 vs Target 82 Bil/day
E20: Channel | F20: Daily Disbursement (bil) | G20: Target May (bil) | H20: Gap (bil) | I20: % Achieved | J20: Status
E21: =F5 -> [VDS] - Cashloan | F21: =G5/1000000000 -> 16.811778 | G21: =H5/1000000000 -> 18.402516 | H21: =F21-G21 -> -1.5907383 | I21: =I5 -> 0.91355865 | J21: =IF(G5>=H5,"✅ On Track",IF(I5>=0.8,"⚠️ Below Target","❌ Below")) -> ⚠️ Below Target
E22: =F6 -> [VDS] - Payday | F22: =G6/1000000000 -> 11.999329 | G22: =H6/1000000000 -> 11.68513 | H22: =F22-G22 -> 0.31419909 | I22: =I6 -> 1.0268888 | J22: =IF(G6>=H6,"✅ On Track",IF(I6>=0.8,"⚠️ Below Target","❌ Below")) -> ✅ On Track
E23: =F7 -> [Cake] - Cashloan | F23: =G7/1000000000 -> 14.780525 | G23: =H7/1000000000 -> 22.233542 | H23: =F23-G23 -> -7.453017 | I23: =I7 -> 0.66478499 | J23: =IF(G7>=H7,"✅ On Track",IF(I7>=0.8,"⚠️ Below Target","❌ Below")) -> ❌ Below
E24: =F8 -> [Cake] - Payday | F24: =G8/1000000000 -> 15.762125 | G24: =H8/1000000000 -> 18.320509 | H24: =F24-G24 -> -2.5583845 | I24: =I8 -> 0.86035407 | J24: =IF(G8>=H8,"✅ On Track",IF(I8>=0.8,"⚠️ Below Target","❌ Below")) -> ⚠️ Below Target
E25: =F9 -> [ZALOPAY] - Cashloan | F25: =G9/1000000000 -> 6.027048 | G25: =H9/1000000000 -> 7.7270829 | H25: =F25-G25 -> -1.7000349 | I25: =I9 -> 0.77999008 | J25: =IF(G9>=H9,"✅ On Track",IF(I9>=0.8,"⚠️ Below Target","❌ Below")) -> ❌ Below
E26: =F10 -> [MWG] - Cashloan | F26: =G10/1000000000 -> 3.793806 | G26: =H10/1000000000 -> 4.8856967 | H26: =F26-G26 -> -1.0918907 | I26: =I10 -> 0.77651279 | J26: =IF(G10>=H10,"✅ On Track",IF(I10>=0.8,"⚠️ Below Target","❌ Below")) -> ❌ Below
E27: =F11 -> [MWG] - Paylater (QTV) | F27: =G11/1000000000 -> 1.3363773 | G27: =H11/1000000000 -> 3.4524289 | H27: =F27-G27 -> -2.1160515 | I27: =I11 -> 0.38708323 | J27: =IF(G11>=H11,"✅ On Track",IF(I11>=0.8,"⚠️ Below Target","❌ Below")) -> ❌ Below
E28: =F12 -> [VNPAY] | F28: =G12/1000000000 -> 1.8051788 | G28: =H12/1000000000 -> 2.2158571 | H28: =F28-G28 -> -0.41067831 | I28: =I12 -> 0.81466391 | J28: =IF(G12>=H12,"✅ On Track",IF(I12>=0.8,"⚠️ Below Target","❌ Below")) -> ⚠️ Below Target
E29: =F13 -> [FIZA] - Payday | G29: =H13/1000000000 -> 0.7 | H29: =F29-G29 -> -0.7
E30: =F14 -> Others | F30: =G14/1000000000 -> 3.9214341 | G30: =H14/1000000000 -> 3.8154967 | H30: =F30-G30 -> 0.10593739 | I30: =I14 -> 1.027765 | J30: =IF(G14>=H14,"✅ On Track",IF(I14>=0.8,"⚠️ Below Target","❌ Below")) -> ✅ On Track
E31: TOTAL | F31: =SUM(F21:F30) -> 76.237601 | G31: =SUM(G21:G30) -> 93.43826 | H31: =J15/1000000000 -> -17.200659 | I31: =I15 -> 0.81591418 | J31: =IF(G15>=H15,"✅ On Track",IF(I15>=0.8,"⚠️ Below Target","❌ Below")) -> ⚠️ Below Target
E33: KEY METRICS SUMMARY
E35: Summary | F35: Daily disbursement amount
E36: Total Actual (bil/day) | F36: =F31 -> 76.237601
E37: Total Target (bil/day) | F37: =G31 -> 93.43826
E38: Total Gap with Target (bil/day) | F38: =H31 -> -17.200659
E39: Overall Achievement | F39: =I31 -> 0.81591418
E41: Products Below 80% Target | F41: =COUNTIFS(I21:I30,"<0.8",I21:I30,"<>-") -> 4 | G41: / 9 products
E42: Products Near Target (80-99%) | F42: =COUNTIFS(I21:I30,">=0.8",I21:I30,"<1") -> 3 | G42: / 9 products
E43: Products On Track (≥100%) | F43: =COUNTIF(I21:I30,">=1") -> 2 | G43: / 9 products
E46: Top Largest Gaps | F46: Gap with Target (bil/day)
E47: =INDEX(E21:E30,MATCH(SMALL(H21:H30,1),H21:H30,0)) -> [Cake] - Cashloan | F47: =SMALL(H21:H30,1) -> -7.453017
E48: =INDEX(E21:E30,MATCH(SMALL(H21:H30,2),H21:H30,0)) -> [Cake] - Payday | F48: =SMALL(H21:H30,2) -> -2.5583845
E49: =INDEX(E21:E30,MATCH(SMALL(H21:H30,3),H21:H30,0)) -> [MWG] - Paylater (QTV) | F49: =SMALL(H21:H30,3) -> -2.1160515
...

Sheet Pivot
C1: 46152
A2: lending_product_transform | B2: Sum of Total | C2: MTD
A3: [BE] - Cashloan | B3: 16993230000 | C3: =VLOOKUP(A3,source!$K$510:$P$538,6,0) -> 8606560000 | D3: =C3/10 -> 860656000
A4: [BE] - Paylater | B4: 9358548670 | C4: =VLOOKUP(A4,source!$K$510:$P$538,6,0) -> 3862036644 | D4: =C4/10 -> 3.8620366e+08
A5: [Cake] - Cashloan | B5: 443850970000 | C5: 147805250000 | D5: =C5/10 -> 14780525000
A6: [Cake] - Overdraft | B6: 49898840707 | C6: =VLOOKUP(A6,source!$K$510:$P$538,6,0) -> 21098365039 | D6: =C6/10 -> 2.1098365e+09
A7: [Cake] - Payday | B7: 425752416000 | C7: =VLOOKUP(A7,source!$K$510:$P$538,6,0) -> 157621248000 | D7: =C7/10 -> 15762124800
A8: [MISA] - Cashloan | B8: 950000000 | C8: =VLOOKUP(A8,source!$K$510:$P$538,6,0) -> 80000000 | D8: =C8/10 -> 8000000
A9: [MWG] - Cashloan | B9: 78700820000 | C9: =VLOOKUP(A9,source!$K$510:$P$538,6,0) -> 28188440000 | D9: =C9/10 -> 2818844000
A10: [MWG] - Cashloan (QTV) | B10: 25219010000 | C10: =VLOOKUP(A10,source!$K$510:$P$538,6,0) -> 9749620000 | D10: =C10/10 -> 974962000
A11: [MWG] - Paylater (QTV) | B11: 34572866125 | C11: =VLOOKUP(A11,source!$K$510:$P$538,6,0) -> 13217452045 | D11: =C11/10 -> 1.3217452e+09
A12: [NORTHSTAR] - Cashloan | B12: 1425700000 | C12: =VLOOKUP(A12,source!$K$510:$P$538,6,0) -> 602300000 | D12: =C12/10 -> 60230000
A13: [VDS] - Cashloan | B13: 492075490000 | C13: =VLOOKUP(A13,source!$K$510:$P$538,6,0) -> 168117780000 | D13: =C13/10 -> 16811778000
A14: [VDS] - Payday | B14: 333026208000 | C14: =VLOOKUP(A14,source!$K$510:$P$538,6,0) -> 119993292000 | D14: =C14/10 -> 11999329200
A15: [VDS] - Paylater | B15: 7030263262 | C15: =VLOOKUP(A15,source!$K$510:$P$538,6,0) -> 3926999449 | D15: =C15/10 -> 3.9269994e+08
A16: [VDS] - Payroll Cashloan | B16: 1117000000 | C16: =VLOOKUP(A16,source!$K$510:$P$538,6,0) -> 445650000 | D16: =C16/10 -> 44565000
A17: [VDS] - Payroll Payday | B17: 1602000000 | C17: =VLOOKUP(A17,source!$K$510:$P$538,6,0) -> 406000000 | D17: =C17/10 -> 40600000
... A30: [ZALOPAY] - Payday | B30: 73008000 | C30: =VLOOKUP(A30,source!$K$510:$P$538,6,0) -> 0 | D30: =C30/10 -> 0
A31: Grand Total | B31: 2143901666325 | C31: =SUM(C3:C30) -> 762376012773 | D31: =SUM(D3:D30) -> 7.6237601e+10

Sheet RawMTD
B2: report_date | C2: lending_product_transform | D2: Total
B3: 46113 | C3: [BE] - Cashloan | D3: 629980000
B4: 46113 | C4: [BE] - Paylater | D4: 308993836
B5: 46113 | C5: [Cake] - Cashloan | D5: 22731350000
B6: 46113 | C6: [Cake] - Overdraft | D6: 2812778254
B7: 46113 | C7: [Cake] - Payday | D7: 14857452000
B8: 46113 | C8: [FPT] - Paylater | D8: 6410587
B9: 46113 | C9: [MISA] - Cashloan | D9: 0
B10: 46113 | C10: [MWG] - Cashloan | D10: 2649000000
B11: 46113 | C11: [MWG] - Cashloan (QTV) | D11: 719020000
B12: 46113 | C12: [MWG] - Paylater | D12: 9890000
B13: 46113 | C13: [MWG] - Paylater (QTV) | D13: 1143977797
B14: 46113 | C14: [NGS] - Cashloan | D14: 0
... B842: 46142 | C842: [ZALOPAY] - Payday | D842: 0

Sheet source
A1: cop thêm tháng mới vào bên dưới
A2: report_date | B2: Year | C2: Month | D2: Weeknum | E2: Day | F2: lending_product_transform | G2: Product_use | H2: Product Group | I2: Total | K2: MONTHLY | U2: Last updated: | V2: =MAX($A:$A) -> 46152
A3: 45292 | B3: =YEAR(source[[#This Row],[report_date]]) -> 2024 | C3: 1 | D3: =WEEKNUM(A3,2) -> 1 | E3: =DAY(A3) -> 1 | F3: [VDS] - Payday | G3: =VLOOKUP(source[[#This Row],[lending_product_transform]],[3]Mapping!$B$4:$C$37,2,0) -> [VDS] - Payday | H3: =VLOOKUP(source[[#This Row],[lending_product_transform]],[3]Mapping!$B$3:$D$37,3,0) -> payday | I3: 885500000
A4: 45292 | B4: =YEAR(source[[#This Row],[report_date]]) -> 2024 | C4: 1 | D4: =WEEKNUM(A4,2) -> 1 | E4: =DAY(A4) -> 1 | F4: [VDS] - Payroll Cashloan | G4: =VLOOKUP(source[[#This Row],[lending_product_transform]],[3]Mapping!$B$4:$C$37,2,0) -> [VDS] - Payroll Cashloan | H4: =VLOOKUP(source[[#This Row],[lending_product_transform]],[3]Mapping!$B$3:$D$37,3,0) -> cashloan | I4: 63000000 | K4: Sum of Total | L4: Column Labels
A5: 45292 | B5: =YEAR(source[[#This Row],[report_date]]) -> 2024 | C5: 1 | D5: =WEEKNUM(A5,2) -> 1 | E5: =DAY(A5) -> 1 | F5: [VDS] - Cashloan | G5: =VLOOKUP(source[[#This Row],[lending_product_transform]],[3]Mapping!$B$4:$C$37,2,0) -> [VDS] - Cashloan | H5: =VLOOKUP(source[[#This Row],[lending_product_transform]],[3]Mapping!$B$3:$D$37,3,0) -> cashloan | I5: 1360850000 | L5: 2025 | X5: 2,025 Total | Y5: 2026 | AD5: 2,026 Total | AE5: Grand Total
A6: 45292 | B6: =YEAR(source[[#This Row],[report_date]]) -> 2024 | C6: 1 | D6: =WEEKNUM(A6,2) -> 1 | E6: =DAY(A6) -> 1 | F6: [BE] - Cashloan | G6: =VLOOKUP(source[[#This Row],[lending_product_transform]],[3]Mapping!$B$4:$C$37,2,0) -> [BE] - Cashloan | H6: =VLOOKUP(source[[#This Row],[lending_product_transform]],[3]Mapping!$B$3:$D$37,3,0) -> cashloan | I6: 178500000 | K6: Row Labels | L6: 1 | M6: 2 | N6: 3 | O6: 4 | P6: 5 | Q6: 6 | R6: 7 | S6: 8 | T6: 9 | U6: 10 | V6: 11 | W6: 12 | Y6: 1 | Z6: 2 | AA6: 3 | AB6: 4 | AC6: 5
A7: 45292 | B7: =YEAR(source[[#This Row],[report_date]]) -> 2024 | C7: 1 | D7: =WEEKNUM(A7,2) -> 1 | E7: =DAY(A7) -> 1 | F7: All | G7: =VLOOKUP(source[[#This Row],[lending_product_transform]],[3]Mapping!$B$4:$C$37,2,0) -> 0 | H7: =VLOOKUP(source[[#This Row],[lending_product_transform]],[3]Mapping!$B$3:$D$37,3,0) -> 0 | I7: 4603693408 | K7: [BE] - Cashloan | L7: 305150000 | M7: 106500000 | N7: 120150000 | O7: 31000000 | P7: 0 | Q7: 48650000 | R7: 98750000 | S7: 18900000 | T7: 42000000 | U7: 856450000 | V7: 2125700000 | W7: 9557000000 | X7: 13310250000 | Y7: 21136600000 | Z7: 15124750000 | AA7: 23471820000 | AB7: 16993230000 | AC7: 8606560000 | AD7: 85332960000 | AE7: 98643210000
A8: 45292 | B8: =YEAR(source[[#This Row],[report_date]]) -> 2024 | C8: 1 | D8: =WEEKNUM(A8,2) -> 1 | E8: =DAY(A8) -> 1 | F8: [Cake] - Overdraft | G8: =VLOOKUP(source[[#This Row],[lending_product_transform]],[3]Mapping!$B$4:$C$37,2,0) -> [Cake] - Overdraft | H8: =VLOOKUP(source[[#This Row],[lending_product_transform]],[3]Mapping!$B$3:$D$37,3,0) -> overdraft | I8: 2100843408 | K8: [BE] - Paylater | L8: 5181256600 | M8: 5543897694 | N8: 5692337428 | O8: 5604594501 | P8: 7145959179 | Q8: 7745288700 | R8: 8142216513 | S8: 7801255169 | T8: 7926201248 | U8: 10040639446 | V8: 9491708718 | W8: 11211193272 | X8: 91526548468 | Y8: 10867603221 | Z8: 9233648329 | AA8: 10631003862 | AB8: 9358548670 | AC8: 3862036644 | AD8: 43952840726 | AE8: 135479389194
A9: 45292 | B9: =YEAR(source[[#This Row],[report_date]]) -> 2024 | C9: 1 | D9: =WEEKNUM(A9,2) -> 1 | E9: =DAY(A9) -> 1 | F9: [VDS] - Payroll Payday | G9: =VLOOKUP(source[[#This Row],[lending_product_transform]],[3]Mapping!$B$4:$C$37,2,0) -> [VDS] - Payroll Payday | H9: =VLOOKUP(source[[#This Row],[lending_product_transform]],[3]Mapping!$B$3:$D$37,3,0) -> payday | I9: 15000000 | K9: [Cake] - Cashloan | L9: 148327830000 | M9: 111579440000 | N9: 175949310000 | O9: 227662410000 | P9: 232669350000 | Q9: 273801460000 | R9: 377695150000 | S9: 338629710000 | T9: 486195060000 | U9: 501046570000 | V9: 587879520000 | W9: 522091590000 | X9: 3983527400000 | Y9: 467929410000 | Z9: 316516710000 | AA9: 399979990000 | AB9: 443850970000 | AC9: 147805250000 | AD9: 1776082330000 | AE9: 5759609730000
A10: 45293 | B10: =YEAR(source[[#This Row],[report_date]]) -> 2024 | C10: 1 | D10: =WEEKNUM(A10,2) -> 1 | E10: =DAY(A10) -> 2 | F10: [BE] - Cashloan | G10: =VLOOKUP(source[[#This Row],[lending_product_transform]],[3]Mapping!$B$4:$C$37,2,0) -> [BE] - Cashloan | H10: =VLOOKUP(source[[#This Row],[lending_product_transform]],[3]Mapping!$B$3:$D$37,3,0) -> cashloan | I10: 555450000 | K10: [Cake] - Overdraft | L10: 109061423275 | M10: 95253172206 | N10: 112073329818 | O10: 114487336129 | P10: 119537601659 | Q10: 118759501319 | R10: 118080713257 | S10: 97304269148 | T10: 86259163136 | U10: 84239414747 | V10: 73074848767 | W10: 71004297401 | X10: 1199135070862 | Y10: 63409743099 | Z10: 53755295193 | AA10: 55189788461 | AB10: 49898840707 | AC10: 21098365039 | AD10: 243352032499 | AE10: 1442487103361
A11: 45293 | B11: =YEAR(source[[#This Row],[report_date]]) -> 2024 | C11: 1 | D11: =WEEKNUM(A11,2) -> 1 | E11: =DAY(A11) -> 2 | F11: [Cake] - Overdraft | G11: =VLOOKUP(source[[#This Row],[lending_product_transform]],[3]Mapping!$B$4:$C$37,2,0) -> [Cake] - Overdraft | H11: =VLOOKUP(source[[#This Row],[lending_product_transform]],[3]Mapping!$B$3:$D$37,3,0) -> overdraft | I11: 2821136978 | K11: [NGS] - Cashloan | L11: 0 | M11: 0 | N11: 0 | P11: 0 | T11: 0 | U11: 0 | V11: 0 | W11: 0 | X11: 0 | Y11: 0 | Z11: 0 | AA11: 0 | AB11: 0 | AC11: 0 | AD11: 0 | AE11: 0
