Workbook
Name __S1: {"Book1"}
Name __S1: {"Book1"}
Name _a1: {"'Sheet1'!$L$16"}
Name _a1: {"'Sheet1'!$L$16"}
Name _S1: {"Book1"}
Name _S1: {"Book1"}
Name Ă: #REF!
Name Ạ196: #REF!
Name â259: #REF!
Name â259: #REF!
Name â312: #REF!
Name â312: #REF!
Name Acquisition_PlanA: #REF!
Name Acquisition_PlanB: #REF!
Name Actual: (PeriodInActual*(#REF!>0))*PeriodInPlan
Name ActualBeyond: PeriodInActual*(#REF!>0)
Name adf: #REF!
Name adf: #REF!
Name AdvIncQ12020: #REF!
Name AdvIncQ12021: #REF!
Name AdvIncQ12022: #REF!
Name AdvIncQ12023: #REF!
Name AdvIncQ12024: #REF!
Name AdvIncQ22020: #REF!
Name AdvIncQ22021: #REF!
Name AdvIncQ22022: #REF!
Name AdvIncQ22023: #REF!
Name AdvIncQ22024: #REF!
Name AdvIncQ32020: #REF!
Name AdvIncQ32021: #REF!
Name AdvIncQ32022: #REF!
Name AdvIncQ32023: #REF!
Name AdvIncQ32024: #REF!
Name AdvIncQ42020: #REF!
Name AdvIncQ42021: #REF!
Name AdvIncQ42022: #REF!
Name AdvIncQ42023: #REF!
Name AdvIncQ42024: #REF!
Name AdvPenRate2020: #REF!
Name AdvPenRate2021: #REF!
Name AdvPenRate2022: #REF!
Name AdvPenRate2023: #REF!
Name AdvPenRate2024: #REF!
Name AllReportList: #REF!
Name Amount_act: #REF!
Name Amount_CF: #REF!
Name Amount_F: #REF!
Name Amount_KPI_act: #REF!
Name approval: #REF!
Name approval: #REF!
Name Attribute_F: #REF!
Name B: #REF!
Name b2bSpr: #REF!
Name BaoHanhSuaChua: #REF!
Name be_KPI_bud: #REF!
Name be2B: #REF!
Name bf: #REF!
Name bf: #REF!
Name BieuPhi: #REF!
Name BrMarQ12020: #REF!

Sheet NOTE
A1: SAP MODEL - PAYLATER
N2: KHN | O2: v8 | P2: 20250401
B3: 1. Notes and disclaimer
C4: a. Giới thiệu về SAP
D5: - SAP: Single Account Profitability (Hiệu quả sản phẩm trên từng đơn vị sản phẩm)
D6: - Model SAP được sử dụng như 1 mô hình dự đoán hiệu quả vòng đời của sản phẩm.
D7: - Do sự phức tạp của sản phẩm, các hệ thống vận hành (hệ thống hạch kế toán, hệ thống quản trị rủi ro, hệ thống quản trị…), hành vi người sử dụng hành vi người sử dụng, model chỉ có thể mô phỏng tương đối trung bình vòng đời của sản phẩm.
D8: - Mô hình được tính toán dựa vào các yếu tố đầu vào xác định tại thời điểm, do đó kết quả của mô hình có thể có sự khác biệt so với thực tế vận hành sản phẩm.
D9: - Mô hình SAP Paylater tính hiệu quả của 1 thẻ mở và được cutoff tối đa tại thời điểm 5 năm ( 60 tháng) kể từ ngày bắt đầu sản phẩm
E10: - Trường hợp sử dụng phương pháp tính dự phòng VAS, cần ghi nhận thêm chi phí dự phòng năm thứ 6 liên quan tới hiệu quả sản phẩm thẻ 5 năm.
E11: - Trường hợp sử dụng phương pháp tính dự phòng VAS, cần ghi nhận thêm chi phí dự phòng năm thứ 4 liên quan tới hiệu quả sản phẩm thẻ 3 năm.
C13: b. Giới thiệu về PnL
D14: - Trong file tính này, Profit & Lost (PnL) được dự phóng từ trung bình cộng kết quả kinh doanh trên từng sản phẩm (SAP) với yếu tố "sale plan" (số thẻ mở mới) qua từng tháng, do đó có thể khác biệt so với kết quả thực tế vận hành.
D15: - Dòng tiền thực tế qua từng tháng có thể khác biệt với mô hình tính toán do nhiều yếu tố tác động bên ngoài thay đổi, do đó, vui lòng chỉ sử dụng mô hình cho mục đích tham khảo.
D16: - Cho mục đích tính dự phòng dòng tiền ngắn và trung hạn, mô hình PnL được cutoff tại thời điểm 5 năm (60 tháng) kể từ ngày bắt đầu khởi chạy sản phẩm đầu tiên.
B18: 2. Instruction
D19: - Dành cho người sử dụng
E20: - Chỉ chỉnh sửa vào các ô màu vàng
E21: - 2 sheets "SAP_Leadsheet" và "Sale plan&PL" cung cấp yếu tố đầu vào và đầu ra để tính toán mô hình SAP cũng như PnL.
F22: - Sheet SAP_Leadsheet được cấu trúc 2 phần, bên trái là các yếu tố đầu vào (input) và bên phải là kết quả dự đoán (output). Đơn vị sử dụng tại bảng tính là triệu VND (mVND) và phần trăm (%)
F23: - Sheet "Sale plan & PL" được cấu trúc 2 phần, bên trên là sale plan và bên dưới là kết quả PnL
E24: - 2 sheets "SAP_Spreadsheet" và "PL projection speadsheet" là các file tính toán cho 2 sheet "SAP_Leadsheet", "Sales plan & PL"
F25: - 2 sheets được cấu trúc từ trên xuống dưới theo thứ tự tính toán mô phỏng để đưa ra kết quả kinh doanh cuối cùng
F26: - 2 sheets đã được tạm khóa. Trường hợp cần mở khóa, điều chỉnh các yếu tố, vui lòng liên hệ với nhóm vận hành để được hỗ trợ.
D28: - Dành riêng cho người vận hành, hiệu chỉnh
E29: - Cần cẩn trọng khi điều chỉnh ở các file "speadsheet" vì 1 khi sai lệch rất khó tìm ra lỗi (VD: sửa nhầm ô, link nhầm vị trí,…)
B32: 3. Legend
C34: REVENUE INPUT
C36: Card Status
D37: Activate at beginning | E37: Tỉ lệ active thẻ tại thời điểm tháng 1 | G37: Tỉ lệ active được tính là khách hàng có spending và/hoặc có outstanding balance
D38: Average attrition rate | E38: Tỉ lệ giảm active qua từng thàng | G38: Lấy trung bình tỉ lệ giảm active thẻ của các tháng (tính theo cohort)
C40: Term of using
D41: Tenor | E41: Thời hạn tài khoản
D42: Due date | E42: Ngày tới thời hạn miễn lãi
D43: Free-interest period | E43: Thời gian được miễn lãi (VD 45-55 ngày)
C45: Usage Status
D46: Spd / active card | E46: Tổng chi tiêu tiêu tháng/số thẻ active
C48: Payment status
D49: Port Revolving rate | E49: Tỉ lệ chuyển đổi dư nợ (được tính là %/ANR tháng trước)
D50: Repayment rate | E50: Tỉ lệ thanh toán dư nợ (được tính %/ANR tháng trước)
...

Sheet SAP_Leadsheet
B1: SAP MODEL - PAYLATER CARD
B2: Leadsheet | Y2: OUTPUT
B3: HKN | C3: =NOTE!P2 -> 20250401 | D3: =NOTE!O2 -> v8 | Y3: ANR
Y4: TOI
B5: Select model type | Y5: Net interest income
B6: Write off | C6: DPD180+
B7: Provision | C7: VAS | Y7: PROVISION
B8: Chanel | C8: ALL | Y8: OPEX
B9: EMI mode | C9: EMI | Y9: Acq
B10: Customer type | Y10: Alter-sale mgt
B11: Quarter | C11: Q3.2025
E12: 0.98 | H12: %
B13: REVENUE INPUT | I13: Cur: mVND, % | L13: PERFORMANCE OUTPUT | V13: Cur: mVND, %
E15: Year 1 | F15: Year 2 | G15: Year 3 | H15: Year 4 | I15: Year 5 | N15: Lifetime | O15: Year 1 | P15: Year 2 | Q15: Year 3 | R15: Year 4 | S15: Year 5 | T15: Year 6 | U15: % of ANR | V15: % of Spending
L16: Spending | N16: =SUM(O16:S16) -> 12.727565 | O16: =SUM(SAP_Spreadsheet!G24:R24) -> 4.375036 | P16: =SUM(SAP_Spreadsheet!S24:AD24) -> 2.746214 | Q16: =SUM(SAP_Spreadsheet!AE24:AP24) -> 2.4523703 | R16: =SUM(SAP_Spreadsheet!AQ24:BB24) -> 1.8369478 | S16: =SUM(SAP_Spreadsheet!BC24:BN24) -> 1.3169969 | W16: Avg card sau attrition * spending/card
B17: Card Status | C17: Activate at beginning | E17: =DATA!B5 -> 0.66492241 | F17: Account having spending at month 1 | L17: ANR | N17: =AVERAGEIF(SAP_Spreadsheet!G202:BN202,"<>0") -> 0.50119744 | O17: =IFERROR(AVERAGEIF(SAP_Spreadsheet!G202:R202,"<>0"),0) -> 0.80495309 | P17: =IFERROR(AVERAGEIF(SAP_Spreadsheet!S202:AD202,"<>0"),0) -> 0.54304049 | Q17: =IFERROR(AVERAGEIF(SAP_Spreadsheet!AE202:AP202,"<>0"),0) -> 0.49769693 | R17: =IFERROR(AVERAGEIF(SAP_Spreadsheet!AQ202:BB202,"<>0"),0) -> 0.38169086 | S17: =IFERROR(AVERAGEIF(SAP_Spreadsheet!BC202:BN202,"<>0"),0) -> 0.27860583
C18: Average attrition rate | E18: =DATA!B6 -> 0.024514721 | F18: =DATA!C6 -> 0.0096187086 | G18: =DATA!D6 -> 0.0058085881 | H18: =DATA!E6 -> 0.0044311984 | I18: =DATA!F6 -> 0.0041467977 | J18: =IF(E17-E18*11-(F18+G18+H18+I18)*12<0,"check","OK") -> OK | L18: TOI | N18: =N19+N22 -> 0.76624159 | O18: =O19+O22 -> 0.30433161 | P18: =P19+P22 -> 0.28020682 | Q18: =Q19+Q22 -> 0.085345069 | R18: =R19+R22 -> 0.058305771 | S18: =S19+S22 -> 0.038052318 | U18: =N18/$N$17/60*12 -> 0.30576437 | V18: =N18/$N$16 -> 0.060203314
C19: per cohort | E19: including account have spending & balance | L19: Net interest income | N19: =SUM(N20:N21) -> 0.045832731 | O19: =SUM(O20:O21) -> 0.048879927 | P19: =SUM(P20:P21) -> 0.0068769217 | Q19: =SUM(Q20:Q21) -> 0.0023911483 | R19: =SUM(R20:R21) -> -0.004659294 | S19: =SUM(S20:S21) -> -0.0076559717 | U19: =N19/$N$17/60*12 -> 0.018289292 | V19: =N19/$N$16 -> 0.0036010605
L20: CII | N20: =SUM( SAP_Spreadsheet!G216:BN216) -> 0.17865005 | O20: =SUM(SAP_Spreadsheet!G216:R216) -> 0.091542441 | P20: =SUM(SAP_Spreadsheet!S216:AD216) -> 0.035658067 | Q20: =SUM( SAP_Spreadsheet!AE216:AP216) -> 0.028769086 | R20: =SUM( SAP_Spreadsheet!AQ216:BB216) -> 0.015570321 | S20: =SUM(SAP_Spreadsheet!BC216:BN216) -> 0.0071101374 | U20: =N20/$N$17/60*12 -> 0.071289292 | V20: =N20/$N$16 -> 0.014036467 | W20: ANR*%B0&1 thu được*%IR
B21: Term of using | C21: Tenor | E21: 60 | F21: month | L21: COF | N21: =SUM( SAP_Spreadsheet!G219:BN219) -> -0.13281732 | O21: =SUM(SAP_Spreadsheet!G219:R219) -> -0.042662514 | P21: =SUM(SAP_Spreadsheet!S219:AD219) -> -0.028781146 | Q21: =SUM( SAP_Spreadsheet!AE219:AP219) -> -0.026377937 | R21: =SUM( SAP_Spreadsheet!AQ219:BB219) -> -0.020229615 | S21: =SUM(SAP_Spreadsheet!BC219:BN219) -> -0.014766109 | U21: =N21/$N$17/60*12 -> -0.053 | V21: =N21/$N$16 -> -0.010435407 | W21: ANR*%COF
C22: Due date | E22: 5 | F22: Date of month | L22: Net fee income | N22: =SUM(N23:N32) -> 0.72040886 | O22: =SUM(O23:O32) -> 0.25545168 | P22: =SUM(P23:P32) -> 0.2733299 | Q22: =SUM(Q23:Q32) -> 0.082953921 | R22: =SUM(R23:R32) -> 0.062965065 | S22: =SUM(S23:S32) -> 0.04570829 | U22: =N22/$N$17/60*12 -> 0.28747508 | V22: =N22/$N$16 -> 0.056602253
C23: Free-interest period | E23: 45 | F23: days | L23: Annual fee | N23: =SUM( SAP_Spreadsheet!G222:BN222) -> 0 | O23: =SUM(SAP_Spreadsheet!G222:R222) -> 0 | P23: =SUM(SAP_Spreadsheet!S222:AD222) -> 0 | Q23: =SUM( SAP_Spreadsheet!AE222:AP222) -> 0 | R23: =SUM( SAP_Spreadsheet!AQ222:BB222) -> 0 | S23: =SUM( SAP_Spreadsheet!BC222:BN222) -> 0 | U23: =N23/$N$17/60*12 -> 0 | V23: =N23/$N$16 -> 0 | W23: Avg card sau waiver * annual fee
L24: Monthly fee | N24: =SUM( SAP_Spreadsheet!G223:BN223) -> 0.46565712 | O24: =SUM(SAP_Spreadsheet!G223:R223) -> 0.16955432 | P24: =SUM(SAP_Spreadsheet!S223:AD223) -> 0.10601758 | Q24: =SUM( SAP_Spreadsheet!AE223:AP223) -> 0.082206687 | R24: =SUM( SAP_Spreadsheet!AQ223:BB223) -> 0.062482458 | S24: =SUM( SAP_Spreadsheet!BC223:BN223) -> 0.045396071 | U24: =N24/$N$17/60*12 -> 0.18581784 | V24: =N24/$N$16 -> 0.036586505 | W24: Avg card*%B0&1 thu được*monthly fee
B25: Usage Status | C25: Spd / activate card | E25: =DATA!B13 -> 0.68778008 | F25: =DATA!C13 -> 0.68778008 | G25: =DATA!D13 -> 0.84420051 | H25: =DATA!E13 -> 0.84420051 | I25: =DATA!F13 -> 0.84420051 | L25: Transaction fee | N25: =SUM( SAP_Spreadsheet!G224:BN224) -> 0 | O25: =SUM(SAP_Spreadsheet!G224:R224) -> 0 | P25: =SUM(SAP_Spreadsheet!S224:AD224) -> 0 | Q25: =SUM( SAP_Spreadsheet!AE224:AP224) -> 0 | R25: =SUM( SAP_Spreadsheet!AQ224:BB224) -> 0 | S25: =SUM( SAP_Spreadsheet!BC224:BN224) -> 0 | U25: =N25/$N$17/60*12 -> 0 | V25: =N25/$N$16 -> 0 | W25: Newspending * %transaction fee * (1-%RRB0-1)
L26: Issuance fee | N26: =SUM( SAP_Spreadsheet!G225:BN225) -> 0 | O26: =SUM(SAP_Spreadsheet!G225:R225) -> 0 | P26: =SUM(SAP_Spreadsheet!S225:AD225) -> 0 | Q26: =SUM( SAP_Spreadsheet!AE225:AP225) -> 0 | R26: =SUM( SAP_Spreadsheet!AQ225:BB225) -> 0 | S26: =SUM( SAP_Spreadsheet!BC225:BN225) -> 0 | U26: =N26/$N$17/60*12 -> 0 | V26: =N26/$N$16 -> 0 | AB26: New spending = spending/active * avg active card sau attrition
B27: Payment status | C27: Port Revolving rate | E27: =DATA!D20 -> 0.5115999 | L27: Termination fee | N27: =SUM( SAP_Spreadsheet!G226:BN226) -> 0 | O27: =SUM(SAP_Spreadsheet!G226:R226) -> 0 | P27: =SUM(SAP_Spreadsheet!S226:AD226) -> 0 | Q27: =SUM( SAP_Spreadsheet!AE226:AP226) -> 0 | R27: =SUM( SAP_Spreadsheet!AQ226:BB226) -> 0 | S27: =SUM( SAP_Spreadsheet!BC226:BN226) -> 0 | U27: =N27/$N$17/60*12 -> 0 | V27: =N27/$N$16 -> 0
C28: Payment rate | E28: =DATA!D21 -> 0.39533386 | F28: =E28 -> 0.39533386 | G28: =F28 -> 0.39533386 | H28: =G28 -> 0.39533386 | I28: =H28 -> 0.39533386 | L28: Late payment | N28: =SUM( SAP_Spreadsheet!G227:BN227) -> 0.0054397423 | O28: =SUM(SAP_Spreadsheet!G227:R227) -> 0.0027933642 | P28: =SUM(SAP_Spreadsheet!S227:AD227) -> 0.0011043173 | Q28: =SUM( SAP_Spreadsheet!AE227:AP227) -> 0.00074723412 | R28: =SUM( SAP_Spreadsheet!AQ227:BB227) -> 0.00048260761 | S28: =SUM( SAP_Spreadsheet!BC227:BN227) -> 0.0003122191 | U28: =N28/$N$17/60*12 -> 0.0021706984 | V28: =N28/$N$16 -> 0.00042739851 | W28: Late pmt fee * [B1 * (1-%RRB1-2)/total balacne] * avg card
E29: payment T/ANR T-1 (excl WO) | L29: Min due fee | N29: =SUM( SAP_Spreadsheet!G230:BN230) -> 0 | O29: =SUM(SAP_Spreadsheet!G230:R230) -> 0 | P29: =SUM(SAP_Spreadsheet!S230:AD230) -> 0 | Q29: =SUM( SAP_Spreadsheet!AE230:AP230) -> 0 | R29: =SUM( SAP_Spreadsheet!AQ230:BB230) -> 0 | S29: =SUM( SAP_Spreadsheet!BC230:BN230) -> 0 | U29: =N29/$N$17/60*12 -> 0 | V29: =N29/$N$16 -> 0 | W29: ANR*%B0&1 thu được*%Mindue | AB29: [B1 * (1-%RRB1-2)/total balacne] -> tính ra số thẻ late
L30: EMI initial fee | N30: =SUM( SAP_Spreadsheet!G231:BN231) -> 0.249312 | O30: =SUM(SAP_Spreadsheet!G231:R231) -> 0.083104 | P30: =SUM(SAP_Spreadsheet!S231:AD231) -> 0.166208 | Q30: =SUM( SAP_Spreadsheet!AE231:AP231) -> 0 | R30: =SUM( SAP_Spreadsheet!AQ231:BB231) -> 0 | S30: =SUM( SAP_Spreadsheet!BC231:BN231) -> 0 | U30: =N30/$N$17/60*12 -> 0.099486542 | V30: =N30/$N$16 -> 0.01958835 | W30: EMI amt * tenor * 3%
B31: Pricing | C31: CII rate | E31: =DATA!D22 -> 0.41540864 | F31: annually | L31: EMI- early termination | N31: =SUM( SAP_Spreadsheet!G235:BN235) -> 0 | O31: =SUM(SAP_Spreadsheet!G235:R235) -> 0 | P31: =SUM(SAP_Spreadsheet!S235:AD235) -> 0 | Q31: =SUM( SAP_Spreadsheet!AE235:AP235) -> 0 | R31: =SUM( SAP_Spreadsheet!AQ235:BB235) -> 0 | S31: =SUM( SAP_Spreadsheet!BC235:BN235) -> 0 | U31: =N31/$N$17/60*12 -> 0 | V31: =N31/$N$16 -> 0
C32: COF rate | E32: 0.053 | F32: annually | L32: Fee suspended due to CIC | N32: =SUM( SAP_Spreadsheet!G236:BN236) -> 0 | O32: =SUM(SAP_Spreadsheet!G236:R236) -> 0 | P32: =SUM(SAP_Spreadsheet!S236:AD236) -> 0 | Q32: =SUM( SAP_Spreadsheet!AE236:AP236) -> 0 | R32: =SUM( SAP_Spreadsheet!AQ236:BB236) -> 0 | S32: =SUM( SAP_Spreadsheet!BC236:BN236) -> 0 | U32: =N32/$N$17/60*12 -> 0 | V32: =N32/$N$16 -> 0
L33: Other income | N33: =SUM( SAP_Spreadsheet!G240:BN240) -> 0 | O33: =SUM(SAP_Spreadsheet!G240:R240) -> 0 | P33: =SUM(SAP_Spreadsheet!S240:AD240) -> 0 | Q33: =SUM( SAP_Spreadsheet!AE240:AP240) -> 0 | R33: =SUM( SAP_Spreadsheet!AQ240:BB240) -> 0 | S33: =SUM( SAP_Spreadsheet!BC240:BN240) -> 0 | U33: =N33/$N$17/60*12 -> 0 | V33: =N33/$N$16 -> 0
B34: Fee/charge | C34: Annual fee | F34: per card/year | L34: PROVISION | N34: =SUM(O34:T34) -> -0.73067779 | O34: =SUM(SAP_Spreadsheet!G335:R335) -> -0.22082755 | P34: =SUM(SAP_Spreadsheet!S335:AD335) -> -0.23313954 | Q34: =SUM(SAP_Spreadsheet!AE335:AP335) -> -0.11835593 | R34: =SUM(SAP_Spreadsheet!AQ335:BB335) -> -0.084536149 | S34: =SUM(SAP_Spreadsheet!BC335:BN335) -> -0.053594948 | T34: =SUM(SAP_Spreadsheet!BO335:BZ335) -> -0.020223678 | U34: =N34/$N$17/60*12 -> -0.29157284 | V34: =N34/$N$16 -> -0.05740908
C35: Annual Fee waiver | F35: % accard port | L35: OPEX | N35: =N36+N41+N42+N48+N45+N49 -> -0.38866078 | O35: =O36+O41+O42+O48+O45+O49 -> -0.19668238 | P35: =P36+P41+P42+P48+P45+P49 -> -0.10842667 | Q35: =Q36+Q41+Q42+Q48+Q45+Q49 -> -0.036183467 | R35: =R36+R41+R42+R48+R45+R49 -> -0.027442497 | S35: =S36+S41+S42+S48+S45+S49 -> -0.019925772 | U35: =N35/$N$17/60*12 -> -0.15509288 | V35: =N35/$N$16 -> -0.030536932
C36: Monthtly fee (Subcription fee) | E36: =DATA!D26 -> 0.03222005 | F36: per card having spending/month | L36: Sales & Marketing | N36: =SUM(N38:N41) -> -0.11800728 | O36: =SUM(O38:O41) -> -0.058711755 | P36: =SUM(P38:P41) -> -0.05929552 | Q36: =SUM(Q38:Q41) -> 0 | R36: =SUM(R38:R41) -> 0 | S36: =SUM(S38:S41) -> 0 | U36: =N36/$N$17/60*12 -> -0.047090135 | V36: =N36/$N$16 -> -0.0092717873
C37: Transaction fee | F37: per spend/month | L37: Lead acquisition | N37: =SUM( SAP_Spreadsheet!G244:BN244) -> 0 | O37: =SUM(SAP_Spreadsheet!G244:R244) -> 0 | P37: =SUM(SAP_Spreadsheet!S244:AD244) -> 0 | Q37: =SUM( SAP_Spreadsheet!AE244:AP244) -> 0 | R37: =SUM( SAP_Spreadsheet!AQ244:BB244) -> 0 | S37: =SUM( SAP_Spreadsheet!BC244:BN244) -> 0 | U37: =N37/$N$17/60*12 -> 0 | V37: =N37/$N$16 -> 0
C38: Issuance fee | F38: per issued account | L38: Sharing TOI +Risk DPD90+ | N38: =SUM( SAP_Spreadsheet!G245:BN245) -> -0.11800728 | O38: =SUM(SAP_Spreadsheet!G245:R245) -> -0.058711755 | P38: =SUM(SAP_Spreadsheet!S245:AD245) -> -0.05929552 | Q38: =SUM( SAP_Spreadsheet!AE245:AP245) -> 0 | R38: =SUM( SAP_Spreadsheet!AQ245:BB245) -> 0 | S38: =SUM( SAP_Spreadsheet!BC245:BN245) -> 0 | U38: =N38/$N$17/60*12 -> -0.047090135 | V38: =N38/$N$16 -> -0.0092717873
C39: Termination fee | F39: per terminated account | L39: Sharing adjusted | N39: =SUM( SAP_Spreadsheet!G246:BN246) -> 0 | O39: =SUM(SAP_Spreadsheet!G246:R246) -> 0 | P39: =SUM(SAP_Spreadsheet!S246:AD246) -> 0 | Q39: =SUM( SAP_Spreadsheet!AE246:AP246) -> 0 | R39: =SUM( SAP_Spreadsheet!AQ246:BB246) -> 0 | S39: =SUM( SAP_Spreadsheet!BC246:BN246) -> 0 | U39: =N39/$N$17/60*12 -> 0 | V39: =N39/$N$16 -> 0
L40: Marketing cost for acquistion | N40: =SUM( SAP_Spreadsheet!G250:BN250) -> 0 | O40: =SUM(SAP_Spreadsheet!G250:R250) -> 0 | P40: =SUM(SAP_Spreadsheet!S250:AD250) -> 0 | Q40: =SUM( SAP_Spreadsheet!AE250:AP250) -> 0 | R40: =SUM( SAP_Spreadsheet!AQ250:BB250) -> 0 | S40: =SUM( SAP_Spreadsheet!BC250:BN250) -> 0 | U40: =N40/$N$17/60*12 -> 0 | V40: =N40/$N$16 -> 0
C41: Late payment interest | E41: 0 | F41: annually | L41: Promotion cost | N41: =-SUM( SAP_Spreadsheet!G251:BN251) -> 0 | O41: =-SUM(SAP_Spreadsheet!G251:R251) -> 0 | P41: =-SUM(SAP_Spreadsheet!S251:AD251) -> 0 | Q41: =-SUM( SAP_Spreadsheet!AE251:AP251) -> 0 | R41: =-SUM( SAP_Spreadsheet!AQ251:BB251) -> 0 | S41: =-SUM( SAP_Spreadsheet!BC251:BN251) -> 0 | U41: =N41/$N$17/60*12 -> 0 | V41: =N41/$N$16 -> 0
...

Sheet DATA
B3: 1. Attrition
B5: =SUMPRODUCT(I5:I8,$H$46:$H$49)/SUM($H$46:$H$49) -> 0.66492241 | C5: Account having spending at month 1 | H5: VDS | I5: 0.54 | J5: 0.012 | K5: 0.01 | L5: 0.005 | M5: 0.005 | N5: 0.005
B6: =SUMPRODUCT(J5:J8,$H$46:$H$49)/SUM($H$46:$H$49) -> 0.024514721 | C6: =SUMPRODUCT(K5:K8,$H$46:$H$49)/SUM($H$46:$H$49) -> 0.0096187086 | D6: =SUMPRODUCT(L5:L8,$H$46:$H$49)/SUM($H$46:$H$49) -> 0.0058085881 | E6: =SUMPRODUCT(M5:M8,$H$46:$H$49)/SUM($H$46:$H$49) -> 0.0044311984 | F6: =SUMPRODUCT(N5:N8,$H$46:$H$49)/SUM($H$46:$H$49) -> 0.0041467977 | H6: BE | I6: 0.8 | J6: 0.05 | K6: 0.007 | L6: 0.003 | M6: 0.003 | N6: 0.002
H7: VNPAY | I7: 0.72247981 | J7: 0.02 | K7: 0.013 | L7: 0.01 | M7: 0.005 | N7: 0.005
H8: MWG | I8: 0.55 | J8: 0.005 | K8: 0.005 | L8: 0.005 | M8: 0.005 | N8: 0.005
B10: 2. Spending
B13: =SUMPRODUCT(I13:I16,$H$46:$H$49)/SUM($H$46:$H$49) -> 0.68778008 | C13: =SUMPRODUCT(J13:J16,$H$46:$H$49)/SUM($H$46:$H$49) -> 0.68778008 | D13: =SUMPRODUCT(K13:K16,$H$46:$H$49)/SUM($H$46:$H$49) -> 0.84420051 | E13: =SUMPRODUCT(L13:L16,$H$46:$H$49)/SUM($H$46:$H$49) -> 0.84420051 | F13: =SUMPRODUCT(M13:M16,$H$46:$H$49)/SUM($H$46:$H$49) -> 0.84420051 | H13: VDS | I13: 0.45 | J13: =I13 -> 0.45 | K13: =J13 -> 0.45 | L13: =K13 -> 0.45 | M13: =L13 -> 0.45
H14: BE | I14: 0.45 | J14: =I14 -> 0.45 | K14: 1 | L14: 1 | M14: 1
H15: VNPAY | I15: 1 | J15: 1 | K15: 1 | L15: 1 | M15: 1
H16: MWG | I16: =5/3 -> 1.6666667 | J16: =I16 -> 1.6666667 | K16: =J16 -> 1.6666667 | L16: =K16 -> 1.6666667 | M16: =L16 -> 1.6666667
B18: 3. Revolving, repayment | I18: Revolving | J18: Repayment | K18: IR
H19: VDS | I19: 0.6212039 | J19: 0.3760479 | K19: 0.39
B20: Revolving | D20: =SUMPRODUCT(I19:I22,$M$56:$M$59)/SUM($M$56:$M$59) -> 0.5115999 | H20: BE | I20: 0.56195721 | J20: 0.44620293 | K20: 0.39
B21: Repayment | D21: =SUMPRODUCT(J19:J22,$M$56:$M$59)/SUM($M$56:$M$59) -> 0.39533386 | H21: VNPAY | I21: 0.56195721 | J21: 0.44620293 | K21: 0.39
B22: IR | D22: =SUMPRODUCT(K19:K22,$M$61:$M$64)/SUM($M$61:$M$64) -> 0.41540864 | H22: MWG | I22: 0.3 | J22: 0.3 | K22: 0.55
B25: 4. FEE
B26: Monthly fee | D26: =SUMPRODUCT(I27:I30,$H$46:$H$49)/SUM($H$46:$H$49) -> 0.03222005 | I26: monthly fee
H27: VDS | I27: 0.033
H28: BE | I28: 0.033
H29: VNPAY | I29: 0.033
H30: MWG | I30: 0.022
B32: 5. UW
B33: UW | D33: =SUM(E33:G33)/SUM(E34:G34)/10^6 -> 0.056689763 | E33: 518864882 | F33: 491421302 | G33: 477366582
B34: new account | E34: 9371 | F34: 8431 | G34: 8440
H35: VDS | I35: 0.5
B36: Sharing | D36: =SUMPRODUCT(I35:I38,$M$56:$M$59)/SUM($M$56:$M$59) -> 0.37546996 | H36: BE | I36: 0.5
H37: VNPAY | I37: 0.1
H38: MWG | I38: 0.35
D39: 45809 | E39: 45839 | F39: 45870 | G39: 45901
B40: New account
C41: VDS | D41: 3055 | E41: 1904 | F41: 1887 | G41: 2031
C42: BEG | D42: 1914 | E42: 1866 | F42: 1741 | G42: 1832
C43: VNPAY | D43: 2503 | E43: 2589 | F43: 2029 | G43: 2239
C44: MWG | D44: 1974 | E44: 2919 | F44: 2689 | G44: 2261
B45: Active account
C46: VDS | D46: 12498 | E46: 12437 | F46: 11083 | G46: 10452 | H46: =SUM(E46:G46) -> 33972
C47: BEG | D47: 7542 | E47: 8354 | F47: 8582 | G47: 9232 | H47: =SUM(E47:G47) -> 26168
C48: VNPAY | D48: 8022 | E48: 9017 | F48: 8214 | G48: 8116 | H48: =SUM(E48:G48) -> 25347
C49: MWG | D49: 733 | E49: 1762 | F49: 2527 | G49: 2235 | H49: =SUM(E49:G49) -> 6524
B50: Spending | I50: Repayment | J50: Installment spending | K50: =SUM(J54:L54)/SUM(E51:G54) -> 0.11722891
...

Sheet SAP_Spreadsheet
A1: Index!A1 | B1: SAP Model Paylater
B2: Spreadsheet
B4: Calendar | C4: =(30*4+31*7+28)/12 -> 30.416667 | AE4: =IF(AE$7<13,SAP_Leadsheet!$E$18,IF(SAP_Leadsheet!AF$6<25,SAP_Leadsheet!$F$18,IF(AE$7<37,SAP_Leadsheet!$G$18,IF(AE$7<49,SAP_Leadsheet!$H$18,SAP_Leadsheet!$I$18)))) -> 0.0096187086
B5: Validation | C5: No | D5: COF (*) | E5: =SAP_Leadsheet!E32 -> 0.053
E6: Year | G6: =ROUNDUP(G7/12,0) -> 1 | H6: =ROUNDUP(H7/12,0) -> 1 | I6: =ROUNDUP(I7/12,0) -> 1 | J6: =ROUNDUP(J7/12,0) -> 1 | K6: =ROUNDUP(K7/12,0) -> 1 | L6: =ROUNDUP(L7/12,0) -> 1 | M6: =ROUNDUP(M7/12,0) -> 1 | N6: =ROUNDUP(N7/12,0) -> 1 | ... BZ6: =ROUNDUP(BZ7/12,0) -> 6
E7: Month | G7: 1 | H7: =G7+1 -> 2 | I7: =H7+1 -> 3 | J7: =I7+1 -> 4 | K7: =J7+1 -> 5 | L7: =K7+1 -> 6 | M7: =L7+1 -> 7 | N7: =M7+1 -> 8 | O7: =N7+1 -> 9 | ... BZ7: =BY7+1 -> 72
A8: 1 | B8: CARD OPERATION | AE8: =IF(AE$7<37,SAP_Leadsheet!$G$18,IF(AE$7<49,SAP_Leadsheet!$H$18,SAP_Leadsheet!$I$18)) -> 0.0058085881
C10: Card Status | D10: Issued card | F10: # Card | G10: 1 | H10: =G10 -> 1 | I10: =H10 -> 1 | J10: =I10 -> 1 | K10: =J10 -> 1 | L10: =K10 -> 1 | M10: =L10 -> 1 | N10: =M10 -> 1 | O10: =N10 -> 1 | ... BN10: =BM10 -> 1
D11: Activate card | F11: # Card | G11: =G10*SAP_Leadsheet!E17 -> 0.66492241 | H11: =G11-H12 -> 0.64040769 | I11: =H11-I12 -> 0.61589297 | J11: =I11-J12 -> 0.59137825 | K11: =J11-K12 -> 0.56686352 | L11: =K11-L12 -> 0.5423488 | M11: =L11-M12 -> 0.51783408 | N11: =M11-N12 -> 0.49331936 | O11: =N11-O12 -> 0.46880464 | ... BN11: =BM11-BN12 -> 0.10719696
D12: Attrition rate | F12: % | G12: =OFFSET(SAP_Leadsheet!$D$18,0,SAP_Spreadsheet!G6) -> 0.024514721 | H12: =OFFSET(SAP_Leadsheet!$D$18,0,SAP_Spreadsheet!H6) -> 0.024514721 | I12: =OFFSET(SAP_Leadsheet!$D$18,0,SAP_Spreadsheet!I6) -> 0.024514721 | J12: =OFFSET(SAP_Leadsheet!$D$18,0,SAP_Spreadsheet!J6) -> 0.024514721 | K12: =OFFSET(SAP_Leadsheet!$D$18,0,SAP_Spreadsheet!K6) -> 0.024514721 | L12: =OFFSET(SAP_Leadsheet!$D$18,0,SAP_Spreadsheet!L6) -> 0.024514721 | M12: =OFFSET(SAP_Leadsheet!$D$18,0,SAP_Spreadsheet!M6) -> 0.024514721 | N12: =OFFSET(SAP_Leadsheet!$D$18,0,SAP_Spreadsheet!N6) -> 0.024514721 | ... BN12: =OFFSET(SAP_Leadsheet!$D$18,0,SAP_Spreadsheet!BN6) -> 0.0041467977
C15: Spending status | D15: Spd per activate card (Port) | F15: mVND | G15: =OFFSET(SAP_Leadsheet!$E$25,0,SAP_Spreadsheet!G6-1) -> 0.68778008 | H15: =OFFSET(SAP_Leadsheet!$E$25,0,SAP_Spreadsheet!H6-1) -> 0.68778008 | I15: =OFFSET(SAP_Leadsheet!$E$25,0,SAP_Spreadsheet!I6-1) -> 0.68778008 | J15: =OFFSET(SAP_Leadsheet!$E$25,0,SAP_Spreadsheet!J6-1) -> 0.68778008 | K15: =OFFSET(SAP_Leadsheet!$E$25,0,SAP_Spreadsheet!K6-1) -> 0.68778008 | L15: =OFFSET(SAP_Leadsheet!$E$25,0,SAP_Spreadsheet!L6-1) -> 0.68778008 | M15: =OFFSET(SAP_Leadsheet!$E$25,0,SAP_Spreadsheet!M6-1) -> 0.68778008 | N15: =OFFSET(SAP_Leadsheet!$E$25,0,SAP_Spreadsheet!N6-1) -> 0.68778008 | ... BN15: =OFFSET(SAP_Leadsheet!$E$25,0,SAP_Spreadsheet!BN6-1) -> 0.84420051
D17: Card Port | F17: % | G17: 1 | H17: 1 | I17: 1 | J17: 1 | K17: 1 | L17: 1 | M17: 1 | N17: 1 | O17: 1 | P17: 1 | Q17: 1 | R17: 1 | S17: 1 | T17: 1 | U17: 1 | V17: 1 | W17: 1 | X17: 1 | Y17: 1 | Z17: 1 | AA17: 1 | AB17: 1 | AC17: 1 | AD17: 1 | AE17: 1 | AF17: 1 | AG17: 1 | AH17: 1 | AI17: 1 | AJ17: 1 | AK17: 1 | AL17: 1 | AM17: 1 | AN17: 1 | AO17: 1 | AP17: 1 | AQ17: 1 | AR17: 1 | AS17: 1 | AT17: 1 | AU17: 1 | AV17: 1 | AW17: 1 | AX17: 1 | AY17: 1 | AZ17: 1 | BA17: 1 | BB17: 1 | BC17: 1 | BD17: 1 | BE17: 1 | BF17: 1 | BG17: 1 | BH17: 1 | BI17: 1 | BJ17: 1 | BK17: 1 | BL17: 1 | BM17: 1 | BN17: 1
D18: Transactor | F18: % | G18: =1-G19 -> 0.4884001 | H18: =1-H19 -> 0.4884001 | I18: =1-I19 -> 0.4884001 | J18: =1-J19 -> 0.4884001 | K18: =1-K19 -> 0.4884001 | L18: =1-L19 -> 0.4884001 | M18: =1-M19 -> 0.4884001 | N18: =1-N19 -> 0.4884001 | ... BN18: =1-BN19 -> 0.4884001
D19: Revolver | F19: % | G19: =SAP_Leadsheet!$E$27 -> 0.5115999 | H19: =SAP_Leadsheet!$E$27 -> 0.5115999 | I19: =SAP_Leadsheet!$E$27 -> 0.5115999 | J19: =SAP_Leadsheet!$E$27 -> 0.5115999 | K19: =SAP_Leadsheet!$E$27 -> 0.5115999 | L19: =SAP_Leadsheet!$E$27 -> 0.5115999 | M19: =SAP_Leadsheet!$E$27 -> 0.5115999 | N19: =SAP_Leadsheet!$E$27 -> 0.5115999 | ... BN19: =SAP_Leadsheet!$E$27 -> 0.5115999
A21: 3 | B21: BS by bucket
B23: CORE | C23: Core statement | D23: Beginning Bal | F23: mVND | G23: 0 | H23: =IF(H7>SAP_Leadsheet!$E$21,0,G28) -> 0.45732039 | I23: =IF(I7>SAP_Leadsheet!$E$21,0,H28) -> 0.83586421 | J23: =IF(J7>SAP_Leadsheet!$E$21,0,I28) -> 1.0274185 | K23: =IF(K7>SAP_Leadsheet!$E$21,0,J28) -> 1.077777 | L23: =IF(L7>SAP_Leadsheet!$E$21,0,K28) -> 1.0546632 | M23: =IF(M7>SAP_Leadsheet!$E$21,0,L28) -> 0.30472749 | N23: =IF(N7>SAP_Leadsheet!$E$21,0,M28) -> 0.3273984 | O23: =IF(O7>SAP_Leadsheet!$E$21,0,N28) -> 0.37367686 | ... BN23: =IF(BN7>SAP_Leadsheet!$E$21,0,BM28) -> 0.9358462
D24: New spending | F24: mVND | G24: =IF(G7>SAP_Leadsheet!$E$21,0,G15*G11) -> 0.45732039 | H24: =IF(H7>SAP_Leadsheet!$E$21,0,H15*H11) -> 0.44045965 | I24: =IF(I7>SAP_Leadsheet!$E$21,0,I15*I11) -> 0.42359892 | J24: =IF(J7>SAP_Leadsheet!$E$21,0,J15*J11) -> 0.40673818 | K24: =IF(K7>SAP_Leadsheet!$E$21,0,K15*K11) -> 0.38987744 | L24: =IF(L7>SAP_Leadsheet!$E$21,0,L15*L11) -> 0.37301671 | M24: =IF(M7>SAP_Leadsheet!$E$21,0,M15*M11) -> 0.35615597 | N24: =IF(N7>SAP_Leadsheet!$E$21,0,N15*N11) -> 0.33929523 | ... BN24: =IF(BN7>SAP_Leadsheet!$E$21,0,BN15*BN11) -> 0.090495731
D25: EMI Capitalized | F25: mVND | H25: =-G34 -> 0 | I25: =-H34 -> 0 | J25: =-I34 -> 0 | K25: =-J34 -> 0 | L25: =-K34 -> 0 | M25: =-L34 -> 0 | N25: =-M34 -> 0.0233017 | O25: =-N34 -> 0.029585133 | ... BN25: =-BM34 -> 0
D26: Move to EMI | F26: mVND | G26: =-G31 -> 0 | H26: =-H31 -> 0 | I26: =-I31 -> 0 | J26: =-J31 -> 0 | K26: =-K31 -> 0 | L26: =-L31 -> -0.7 | M26: =-M31 -> 0 | N26: =-N31 -> 0 | ... BN26: =-BN31 -> 0
D27: Paid off | F27: mVND | H27: {=IF(G7>SAP_Leadsheet!$E$21,0,-G202*INDEX(SAP_Leadsheet!$E$28:$I$28,1,SAP_Spreadsheet!G6)-H33)} -> -0.061915834 | I27: {=IF(H7>SAP_Leadsheet!$E$21,0,-H202*INDEX(SAP_Leadsheet!$E$28:$I$28,1,SAP_Spreadsheet!H6)-I33)} -> -0.23204464 | J27: {=IF(I7>SAP_Leadsheet!$E$21,0,-I202*INDEX(SAP_Leadsheet!$E$28:$I$28,1,SAP_Spreadsheet!I6)-J33)} -> -0.35637963 | K27: {=IF(J7>SAP_Leadsheet!$E$21,0,-J202*INDEX(SAP_Leadsheet!$E$28:$I$28,1,SAP_Spreadsheet!J6)-K33)} -> -0.41299127 | L27: {=IF(K7>SAP_Leadsheet!$E$21,0,-K202*INDEX(SAP_Leadsheet!$E$28:$I$28,1,SAP_Spreadsheet!K6)-L33)} -> -0.42295241 | M27: {=IF(L7>SAP_Leadsheet!$E$21,0,-L202*INDEX(SAP_Leadsheet!$E$28:$I$28,1,SAP_Spreadsheet!L6)-M33)} -> -0.33348506 | N27: {=IF(M7>SAP_Leadsheet!$E$21,0,-M202*INDEX(SAP_Leadsheet!$E$28:$I$28,1,SAP_Spreadsheet!M6)-N33)} -> -0.31631848 | O27: {=IF(N7>SAP_Leadsheet!$E$21,0,-N202*INDEX(SAP_Leadsheet!$E$28:$I$28,1,SAP_Spreadsheet!N6)-O33)} -> -0.29452411 | ... BN27: {=IF(BM7>SAP_Leadsheet!$E$21,0,-BM202*INDEX(SAP_Leadsheet!$E$28:$I$28,1,SAP_Spreadsheet!BM6)-BN33)} -> -0.095278857
D28: Ending Bal | F28: mVND | G28: =IF(SAP_Leadsheet!$E$21<G7,0,SUM(G23:G27)) -> 0.45732039 | H28: =IF(SAP_Leadsheet!$E$21<H7,0,SUM(H23:H27)) -> 0.83586421 | I28: =IF(SAP_Leadsheet!$E$21<I7,0,SUM(I23:I27)) -> 1.0274185 | J28: =IF(SAP_Leadsheet!$E$21<J7,0,SUM(J23:J27)) -> 1.077777 | K28: =IF(SAP_Leadsheet!$E$21<K7,0,SUM(K23:K27)) -> 1.0546632 | L28: =IF(SAP_Leadsheet!$E$21<L7,0,SUM(L23:L27)) -> 0.30472749 | M28: =IF(SAP_Leadsheet!$E$21<M7,0,SUM(M23:M27)) -> 0.3273984 | N28: =IF(SAP_Leadsheet!$E$21<N7,0,SUM(N23:N27)) -> 0.37367686 | ... BN28: =IF(SAP_Leadsheet!$E$21<BN7,0,SUM(BN23:BN27)) -> 0.93106307
B30: Installment | C30: Total EMI | D30: Beginning Bal | F30: mVND | G30: =G38+G106 -> 0 | H30: =H38+H106 -> 0 | I30: =I38+I106 -> 0 | J30: =J38+J106 -> 0 | K30: =K38+K106 -> 0 | L30: =L38+L106 -> 0 | M30: =M38+M106 -> 0.7 | N30: =N38+N106 -> 0.6 | ... BN30: =BN38+BN106 -> 3.6082248e-16
D31: New Billing | F31: mVND | G31: =IF(SAP_Leadsheet!$C$9="non-EMI",0,G39+G107) -> 0 | H31: =IF(SAP_Leadsheet!$C$9="non-EMI",0,H39+H107) -> 0 | I31: =IF(SAP_Leadsheet!$C$9="non-EMI",0,I39+I107) -> 0 | J31: =IF(SAP_Leadsheet!$C$9="non-EMI",0,J39+J107) -> 0 | K31: =IF(SAP_Leadsheet!$C$9="non-EMI",0,K39+K107) -> 0 | L31: =IF(SAP_Leadsheet!$C$9="non-EMI",0,L39+L107) -> 0.7 | M31: =IF(SAP_Leadsheet!$C$9="non-EMI",0,M39+M107) -> 0 | N31: =IF(SAP_Leadsheet!$C$9="non-EMI",0,N39+N107) -> 0 | ... BN31: =IF(SAP_Leadsheet!$C$9="non-EMI",0,BN39+BN107) -> 0
D32: Paid off | F32: mVND | G32: =G40+G108 -> 0 | H32: =H40+H108 -> 0 | I32: =I40+I108 -> 0 | J32: =J40+J108 -> 0 | K32: =K40+K108 -> 0 | L32: =L40+L108 -> 0 | M32: =M40+M108 -> -0.1 | N32: =N40+N108 -> -0.1 | ... BN32: =BN40+BN108 -> 0
D33: Paid off | F33: mVND | H33: =H32*G181/G172 -> 0 | I33: =I32*H181/H172 -> 0 | J33: =J32*I181/I172 -> 0 | K33: =K32*J181/J172 -> 0 | L33: =L32*K181/K172 -> 0 | M33: =M32*L181/L172 -> -0.0766983 | N33: =N32*M181/M172 -> -0.070414867 | O33: =O32*N181/N172 -> -0.064834608 | ... BN33: =BN32*BM181/BM172 -> 0
D34: Move to Core statement | F34: mVND | H34: =H32-H33 -> 0 | I34: =I32-I33 -> 0 | J34: =J32-J33 -> 0 | K34: =K32-K33 -> 0 | L34: =L32-L33 -> 0 | M34: =M32-M33 -> -0.0233017 | N34: =N32-N33 -> -0.029585133 | O34: =O32-O33 -> -0.035165392 | ... BN34: =BN32-BN33 -> 0
D35: Ending Bal | F35: mVND | G35: =G101+G169 -> 0 | H35: =H101+H169 -> 0 | I35: =I101+I169 -> 0 | J35: =J101+J169 -> 0 | K35: =K101+K169 -> 0 | L35: =L101+L169 -> 0.7 | M35: =M101+M169 -> 0.6 | N35: =N101+N169 -> 0.5 | ... BN35: =BN101+BN169 -> 3.6082248e-16
A37: 2.4 | B37: Loại 1 | C37: EMI penetration | G37: =SAP_Leadsheet!$E$49 -> 0 | H37: =SAP_Leadsheet!$E$49 -> 0 | I37: =SAP_Leadsheet!$E$49 -> 0 | J37: =SAP_Leadsheet!$E$49 -> 0 | K37: =SAP_Leadsheet!$E$49 -> 0 | L37: =SAP_Leadsheet!$E$49 -> 0 | M37: =SAP_Leadsheet!$E$49 -> 0 | N37: =SAP_Leadsheet!$E$49 -> 0 | ... BN37: =SAP_Leadsheet!$E$49 -> 0
B38: Sửa sau | C38: EMI statement | D38: Beginning Bal | G38: 0 | H38: =IF(H7>SAP_Leadsheet!$E$21,0,G101) -> 0 | I38: =IF(I7>SAP_Leadsheet!$E$21,0,H101) -> 0 | J38: =IF(J7>SAP_Leadsheet!$E$21,0,I101) -> 0 | K38: =IF(K7>SAP_Leadsheet!$E$21,0,J101) -> 0 | L38: =IF(L7>SAP_Leadsheet!$E$21,0,K101) -> 0 | M38: =IF(M7>SAP_Leadsheet!$E$21,0,L101) -> 0 | N38: =IF(N7>SAP_Leadsheet!$E$21,0,M101) -> 0 | O38: =IF(O7>SAP_Leadsheet!$E$21,0,N101) -> 0 | ... BN38: =IF(BN7>SAP_Leadsheet!$E$21,0,BM101) -> 0
D39: New Billing | G39: =IF(SAP_Leadsheet!$C$9="non-EMI",0,IF(G7>SAP_Leadsheet!$E$21,0,G37*G24)) -> 0 | H39: =IF(SAP_Leadsheet!$C$9="non-EMI",0,IF(H7>SAP_Leadsheet!$E$21,0,H37*H24)) -> 0 | I39: =IF(SAP_Leadsheet!$C$9="non-EMI",0,IF(I7>SAP_Leadsheet!$E$21,0,I37*I24)) -> 0 | J39: =IF(SAP_Leadsheet!$C$9="non-EMI",0,IF(J7>SAP_Leadsheet!$E$21,0,J37*J24)) -> 0 | K39: =IF(SAP_Leadsheet!$C$9="non-EMI",0,IF(K7>SAP_Leadsheet!$E$21,0,K37*K24)) -> 0 | L39: =IF(SAP_Leadsheet!$C$9="non-EMI",0,IF(L7>SAP_Leadsheet!$E$21,0,L37*L24)) -> 0 | M39: =IF(SAP_Leadsheet!$C$9="non-EMI",0,IF(M7>SAP_Leadsheet!$E$21,0,M37*M24)) -> 0 | N39: =IF(SAP_Leadsheet!$C$9="non-EMI",0,IF(N7>SAP_Leadsheet!$E$21,0,N37*N24)) -> 0 | ... BN39: =IF(SAP_Leadsheet!$C$9="non-EMI",0,IF(BN7>SAP_Leadsheet!$E$21,0,BN37*BN24)) -> 0
D40: Paid off | G40: 0 | H40: =IF(H7>SAP_Leadsheet!$E$21,0,-SUM(H41:H100)*G208) -> 0 | I40: =IF(I7>SAP_Leadsheet!$E$21,0,-SUM(I41:I100)*H208) -> 0 | J40: =IF(J7>SAP_Leadsheet!$E$21,0,-SUM(J41:J100)*I208) -> 0 | K40: =IF(K7>SAP_Leadsheet!$E$21,0,-SUM(K41:K100)*J208) -> 0 | L40: =IF(L7>SAP_Leadsheet!$E$21,0,-SUM(L41:L100)*K208) -> 0 | M40: =IF(M7>SAP_Leadsheet!$E$21,0,-SUM(M41:M100)*L208) -> 0 | N40: =IF(N7>SAP_Leadsheet!$E$21,0,-SUM(N41:N100)*M208) -> 0 | O40: =IF(O7>SAP_Leadsheet!$E$21,0,-SUM(O41:O100)*N208) -> 0 | ... BN40: =IF(BN7>SAP_Leadsheet!$E$21,0,-SUM(BN41:BN100)*BM208) -> 0
C41: {=TRANSPOSE(G7:BN7)} -> 1 | D41: {=TRANSPOSE(G39:BN39)} -> 0 | E41: =SAP_Leadsheet!$E$50 -> 0 | G41: =IF($C41+1>G$7,0,IF($D41>SUM(#REF!),$D41/$E41,0)) -> 0 | H41: =IF($C41+1>H$7,0,IF($D41>SUM($G41:G41),$D41/$E41,0)) -> 0 | I41: =IF($C41+1>I$7,0,IF($D41>SUM($G41:H41),$D41/$E41,0)) -> 0 | J41: =IF($C41+1>J$7,0,IF($D41>SUM($G41:I41),$D41/$E41,0)) -> 0 | K41: =IF($C41+1>K$7,0,IF($D41>SUM($G41:J41),$D41/$E41,0)) -> 0 | L41: =IF($C41+1>L$7,0,IF($D41>SUM($G41:K41),$D41/$E41,0)) -> 0 | M41: =IF($C41+1>M$7,0,IF($D41>SUM($G41:L41),$D41/$E41,0)) -> 0 | N41: =IF($C41+1>N$7,0,IF($D41>SUM($G41:M41),$D41/$E41,0)) -> 0 | O41: =IF($C41+1>O$7,0,IF($D41>SUM($G41:N41),$D41/$E41,0)) -> 0 | ... BN41: =IF($C41+1>BN$7,0,IF($D41>SUM($G41:BM41),$D41/$E41,0)) -> 0
C42: 2 | D42: 0 | E42: =SAP_Leadsheet!$E$50 -> 0 | G42: =IF($C42+1>G$7,0,IF($D42>SUM(#REF!),$D42/$E42,0)) -> 0 | H42: =IF($C42+1>H$7,0,IF($D42>SUM($G42:G42),$D42/$E42,0)) -> 0 | I42: =IF($C42+1>I$7,0,IF($D42>SUM($G42:H42),$D42/$E42,0)) -> 0 | J42: =IF($C42+1>J$7,0,IF($D42>SUM($G42:I42),$D42/$E42,0)) -> 0 | K42: =IF($C42+1>K$7,0,IF($D42>SUM($G42:J42),$D42/$E42,0)) -> 0 | L42: =IF($C42+1>L$7,0,IF($D42>SUM($G42:K42),$D42/$E42,0)) -> 0 | M42: =IF($C42+1>M$7,0,IF($D42>SUM($G42:L42),$D42/$E42,0)) -> 0 | N42: =IF($C42+1>N$7,0,IF($D42>SUM($G42:M42),$D42/$E42,0)) -> 0 | O42: =IF($C42+1>O$7,0,IF($D42>SUM($G42:N42),$D42/$E42,0)) -> 0 | ... BN42: =IF($C42+1>BN$7,0,IF($D42>SUM($G42:BM42),$D42/$E42,0)) -> 0
C43: 3 | D43: 0 | E43: =SAP_Leadsheet!$E$50 -> 0 | G43: =IF($C43+1>G$7,0,IF($D43>SUM(#REF!),$D43/$E43,0)) -> 0 | H43: =IF($C43+1>H$7,0,IF($D43>SUM($G43:G43),$D43/$E43,0)) -> 0 | I43: =IF($C43+1>I$7,0,IF($D43>SUM($G43:H43),$D43/$E43,0)) -> 0 | J43: =IF($C43+1>J$7,0,IF($D43>SUM($G43:I43),$D43/$E43,0)) -> 0 | K43: =IF($C43+1>K$7,0,IF($D43>SUM($G43:J43),$D43/$E43,0)) -> 0 | L43: =IF($C43+1>L$7,0,IF($D43>SUM($G43:K43),$D43/$E43,0)) -> 0 | M43: =IF($C43+1>M$7,0,IF($D43>SUM($G43:L43),$D43/$E43,0)) -> 0 | N43: =IF($C43+1>N$7,0,IF($D43>SUM($G43:M43),$D43/$E43,0)) -> 0 | O43: =IF($C43+1>O$7,0,IF($D43>SUM($G43:N43),$D43/$E43,0)) -> 0 | ... BN43: =IF($C43+1>BN$7,0,IF($D43>SUM($G43:BM43),$D43/$E43,0)) -> 0
C44: 4 | D44: 0 | E44: =SAP_Leadsheet!$E$50 -> 0 | G44: =IF($C44+1>G$7,0,IF($D44>SUM(#REF!),$D44/$E44,0)) -> 0 | H44: =IF($C44+1>H$7,0,IF($D44>SUM($G44:G44),$D44/$E44,0)) -> 0 | I44: =IF($C44+1>I$7,0,IF($D44>SUM($G44:H44),$D44/$E44,0)) -> 0 | J44: =IF($C44+1>J$7,0,IF($D44>SUM($G44:I44),$D44/$E44,0)) -> 0 | K44: =IF($C44+1>K$7,0,IF($D44>SUM($G44:J44),$D44/$E44,0)) -> 0 | L44: =IF($C44+1>L$7,0,IF($D44>SUM($G44:K44),$D44/$E44,0)) -> 0 | M44: =IF($C44+1>M$7,0,IF($D44>SUM($G44:L44),$D44/$E44,0)) -> 0 | N44: =IF($C44+1>N$7,0,IF($D44>SUM($G44:M44),$D44/$E44,0)) -> 0 | O44: =IF($C44+1>O$7,0,IF($D44>SUM($G44:N44),$D44/$E44,0)) -> 0 | ... BN44: =IF($C44+1>BN$7,0,IF($D44>SUM($G44:BM44),$D44/$E44,0)) -> 0
C45: 5 | D45: 0 | E45: =SAP_Leadsheet!$E$50 -> 0 | G45: =IF($C45+1>G$7,0,IF($D45>SUM(#REF!),$D45/$E45,0)) -> 0 | H45: =IF($C45+1>H$7,0,IF($D45>SUM($G45:G45),$D45/$E45,0)) -> 0 | I45: =IF($C45+1>I$7,0,IF($D45>SUM($G45:H45),$D45/$E45,0)) -> 0 | J45: =IF($C45+1>J$7,0,IF($D45>SUM($G45:I45),$D45/$E45,0)) -> 0 | K45: =IF($C45+1>K$7,0,IF($D45>SUM($G45:J45),$D45/$E45,0)) -> 0 | L45: =IF($C45+1>L$7,0,IF($D45>SUM($G45:K45),$D45/$E45,0)) -> 0 | M45: =IF($C45+1>M$7,0,IF($D45>SUM($G45:L45),$D45/$E45,0)) -> 0 | N45: =IF($C45+1>N$7,0,IF($D45>SUM($G45:M45),$D45/$E45,0)) -> 0 | O45: =IF($C45+1>O$7,0,IF($D45>SUM($G45:N45),$D45/$E45,0)) -> 0 | ... BN45: =IF($C45+1>BN$7,0,IF($D45>SUM($G45:BM45),$D45/$E45,0)) -> 0
C46: 6 | D46: 0 | E46: =SAP_Leadsheet!$E$50 -> 0 | G46: =IF($C46+1>G$7,0,IF($D46>SUM(#REF!),$D46/$E46,0)) -> 0 | H46: =IF($C46+1>H$7,0,IF($D46>SUM($G46:G46),$D46/$E46,0)) -> 0 | I46: =IF($C46+1>I$7,0,IF($D46>SUM($G46:H46),$D46/$E46,0)) -> 0 | J46: =IF($C46+1>J$7,0,IF($D46>SUM($G46:I46),$D46/$E46,0)) -> 0 | K46: =IF($C46+1>K$7,0,IF($D46>SUM($G46:J46),$D46/$E46,0)) -> 0 | L46: =IF($C46+1>L$7,0,IF($D46>SUM($G46:K46),$D46/$E46,0)) -> 0 | M46: =IF($C46+1>M$7,0,IF($D46>SUM($G46:L46),$D46/$E46,0)) -> 0 | N46: =IF($C46+1>N$7,0,IF($D46>SUM($G46:M46),$D46/$E46,0)) -> 0 | O46: =IF($C46+1>O$7,0,IF($D46>SUM($G46:N46),$D46/$E46,0)) -> 0 | ... BN46: =IF($C46+1>BN$7,0,IF($D46>SUM($G46:BM46),$D46/$E46,0)) -> 0
C47: 7 | D47: 0 | E47: =SAP_Leadsheet!$E$50 -> 0 | G47: =IF($C47+1>G$7,0,IF($D47>SUM(#REF!),$D47/$E47,0)) -> 0 | H47: =IF($C47+1>H$7,0,IF($D47>SUM($G47:G47),$D47/$E47,0)) -> 0 | I47: =IF($C47+1>I$7,0,IF($D47>SUM($G47:H47),$D47/$E47,0)) -> 0 | J47: =IF($C47+1>J$7,0,IF($D47>SUM($G47:I47),$D47/$E47,0)) -> 0 | K47: =IF($C47+1>K$7,0,IF($D47>SUM($G47:J47),$D47/$E47,0)) -> 0 | L47: =IF($C47+1>L$7,0,IF($D47>SUM($G47:K47),$D47/$E47,0)) -> 0 | M47: =IF($C47+1>M$7,0,IF($D47>SUM($G47:L47),$D47/$E47,0)) -> 0 | N47: =IF($C47+1>N$7,0,IF($D47>SUM($G47:M47),$D47/$E47,0)) -> 0 | O47: =IF($C47+1>O$7,0,IF($D47>SUM($G47:N47),$D47/$E47,0)) -> 0 | ... BN47: =IF($C47+1>BN$7,0,IF($D47>SUM($G47:BM47),$D47/$E47,0)) -> 0
C48: 8 | D48: 0 | E48: =SAP_Leadsheet!$E$50 -> 0 | G48: =IF($C48+1>G$7,0,IF($D48>SUM(#REF!),$D48/$E48,0)) -> 0 | H48: =IF($C48+1>H$7,0,IF($D48>SUM($G48:G48),$D48/$E48,0)) -> 0 | I48: =IF($C48+1>I$7,0,IF($D48>SUM($G48:H48),$D48/$E48,0)) -> 0 | J48: =IF($C48+1>J$7,0,IF($D48>SUM($G48:I48),$D48/$E48,0)) -> 0 | K48: =IF($C48+1>K$7,0,IF($D48>SUM($G48:J48),$D48/$E48,0)) -> 0 | L48: =IF($C48+1>L$7,0,IF($D48>SUM($G48:K48),$D48/$E48,0)) -> 0 | M48: =IF($C48+1>M$7,0,IF($D48>SUM($G48:L48),$D48/$E48,0)) -> 0 | N48: =IF($C48+1>N$7,0,IF($D48>SUM($G48:M48),$D48/$E48,0)) -> 0 | O48: =IF($C48+1>O$7,0,IF($D48>SUM($G48:N48),$D48/$E48,0)) -> 0 | ... BN48: =IF($C48+1>BN$7,0,IF($D48>SUM($G48:BM48),$D48/$E48,0)) -> 0
C49: 9 | D49: 0 | E49: =SAP_Leadsheet!$E$50 -> 0 | G49: =IF($C49+1>G$7,0,IF($D49>SUM(#REF!),$D49/$E49,0)) -> 0 | H49: =IF($C49+1>H$7,0,IF($D49>SUM($G49:G49),$D49/$E49,0)) -> 0 | I49: =IF($C49+1>I$7,0,IF($D49>SUM($G49:H49),$D49/$E49,0)) -> 0 | J49: =IF($C49+1>J$7,0,IF($D49>SUM($G49:I49),$D49/$E49,0)) -> 0 | K49: =IF($C49+1>K$7,0,IF($D49>SUM($G49:J49),$D49/$E49,0)) -> 0 | L49: =IF($C49+1>L$7,0,IF($D49>SUM($G49:K49),$D49/$E49,0)) -> 0 | M49: =IF($C49+1>M$7,0,IF($D49>SUM($G49:L49),$D49/$E49,0)) -> 0 | N49: =IF($C49+1>N$7,0,IF($D49>SUM($G49:M49),$D49/$E49,0)) -> 0 | O49: =IF($C49+1>O$7,0,IF($D49>SUM($G49:N49),$D49/$E49,0)) -> 0 | ... BN49: =IF($C49+1>BN$7,0,IF($D49>SUM($G49:BM49),$D49/$E49,0)) -> 0
...

Sheet Sales plan& PnL
E1: PROFIT & LOSS 60M | H1: =SAP_Leadsheet!C6 -> DPD180+
A3: Code | B3: Product | C3: Old/new | D3: Item | F3: I. | G3: SALES PLAN
A4: =B4&D4&C4 -> Auto loan | B4: Auto loan
H5: If you want to estimate the mix price & promotion tenor for your product package, please input here & link to Leadsheet properly in term of pricing
A6: =B6&D6&C6 -> Auto loan | B6: Auto loan | H6: Please input your expected disbursement volume with date of lauching out product if you would like to project 60M profit and loss.
A8: =B8&D8&C8 -> Auto loan | B8: Auto loan | H8: Business month | J8: 45658 | K8: =EOMONTH(J8,1) -> 45716 | L8: =EOMONTH(K8,1) -> 45747 | M8: =EOMONTH(L8,1) -> 45777 | N8: =EOMONTH(M8,1) -> 45808 | O8: =EOMONTH(N8,1) -> 45838 | P8: =EOMONTH(O8,1) -> 45869 | Q8: =EOMONTH(P8,1) -> 45900 | R8: =EOMONTH(Q8,1) -> 45930 | ... BR8: =EOMONTH(BQ8,1) -> 47514
H9: Don't delete | J9: =YEAR(J8) -> 2025 | K9: =YEAR(K8) -> 2025 | L9: =YEAR(L8) -> 2025 | M9: =YEAR(M8) -> 2025 | N9: =YEAR(N8) -> 2025 | O9: =YEAR(O8) -> 2025 | P9: =YEAR(P8) -> 2025 | Q9: =YEAR(Q8) -> 2025 | ... BR9: =YEAR(BR8) -> 2030
A10: =B10&D10&C10 -> Auto loan | B10: Auto loan | H10: New issued (Card)
F12: II. | G12: PROFIT & LOSS
H14: FISCAL YEAR | J14: Total | K14: =J9 -> 2025 | L14: =K14+1 -> 2026 | M14: =L14+1 -> 2027 | N14: =M14+1 -> 2028 | O14: =N14+1 -> 2029 | P14: =O14+1 -> 2030
J15: bVND | K15: bVND | L15: bVND | M15: bVND | N15: bVND | O15: bVND | P15: bVND
H17: New Issued Paylater | J17: =SUM(K17:U17) -> 0 | K17: =SUMIF($J$9:$BQ$9,K$14,$J$10:$BQ$10) -> 0 | L17: =SUMIF($J$9:$BQ$9,L$14,$J$10:$BQ$10) -> 0 | M17: =SUMIF($J$9:$BQ$9,M$14,$J$10:$BQ$10) -> 0 | N17: =SUMIF($J$9:$BQ$9,N$14,$J$10:$BQ$10) -> 0 | O17: =SUMIF($J$9:$BQ$9,O$14,$J$10:$BQ$10) -> 0 | P17: =SUMIF($J$9:$BQ$9,P$14,$J$10:$BQ$10) -> 0
H18: Average monthly issued Paylater | J18: =AVERAGE(J10:AS10) -> #DIV/0! | K18: =K17/COUNTIF($J$9:$AS$9,K14) -> 0 | L18: =L17/COUNTIF($J$9:$AS$9,L14) -> 0 | M18: =M17/COUNTIF($J$9:$AS$9,M14) -> 0 | N18: =N17/COUNTIF($J$9:$BQ$9,N14) -> 0 | O18: =O17/COUNTIF($J$9:$BQ$9,O14) -> 0 | P18: =IFERROR(P17/COUNTIF($J$9:$BQ$9,P14),0) -> 0
H20: EOP | K20: =OFFSET(PnL_Speadsheet!$D$7,0,MATCH(DATE('Sales plan& PnL'!K$14,12,31),PnL_Speadsheet!$E$4:$BL$4,0))/1000 -> 0 | L20: =OFFSET(PnL_Speadsheet!$D$7,0,MATCH(DATE('Sales plan& PnL'!L$14,12,31),PnL_Speadsheet!$E$4:$BL$4,0))/1000 -> 0 | M20: =OFFSET(PnL_Speadsheet!$D$7,0,MATCH(DATE('Sales plan& PnL'!M$14,12,31),PnL_Speadsheet!$E$4:$BL$4,0))/1000 -> 0 | N20: =OFFSET(PnL_Speadsheet!$D$7,0,MATCH(DATE('Sales plan& PnL'!N$14,12,31),PnL_Speadsheet!$E$4:$BL$4,0))/1000 -> 0 | O20: =PnL_Speadsheet!BL7/1000 -> 0 | P20: =PnL_Speadsheet!BN7/1000 -> 0
H21: ADB | J21: =SUM(PnL_Speadsheet!E8:BK8)/1000/COUNT(PnL_Speadsheet!E3:BK3) -> 0 | K21: =SUMIF(PnL_Speadsheet!$E$3:$BL$3,K$14,PnL_Speadsheet!$E8:$BL8)/1000/COUNTIF(PnL_Speadsheet!$E$3:$BL$3,'Sales plan& PnL'!K$14) -> 0 | L21: =SUMIF(PnL_Speadsheet!$E$3:$BL$3,L$14,PnL_Speadsheet!$E8:$BL8)/1000/COUNTIF(PnL_Speadsheet!$E$3:$BL$3,'Sales plan& PnL'!L$14) -> 0 | M21: =SUMIF(PnL_Speadsheet!$E$3:$BL$3,M$14,PnL_Speadsheet!$E8:$BL8)/1000/COUNTIF(PnL_Speadsheet!$E$3:$BL$3,'Sales plan& PnL'!M$14) -> 0 | N21: =SUMIF(PnL_Speadsheet!$E$3:$BL$3,N$14,PnL_Speadsheet!$E8:$BL8)/1000/COUNTIF(PnL_Speadsheet!$E$3:$BL$3,'Sales plan& PnL'!N$14) -> 0 | O21: =SUMIF(PnL_Speadsheet!$E$3:$BL$3,O$14,PnL_Speadsheet!$E8:$BL8)/1000/COUNTIF(PnL_Speadsheet!$E$3:$BL$3,'Sales plan& PnL'!O$14) -> 0 | P21: =IFERROR(SUMIF(PnL_Speadsheet!$E$3:$BL$3,P$14,PnL_Speadsheet!$E8:$BL8)/1000/COUNTIF(PnL_Speadsheet!$E$3:$BL$3,'Sales plan& PnL'!P$14),0) -> 0
H23: TOI | J23: =SUM(K23:U23) -> 0 | K23: =SUMIF(PnL_Speadsheet!$E$3:$BL$3,K$14,PnL_Speadsheet!$E9:$BL9)/1000 -> 0 | L23: =SUMIF(PnL_Speadsheet!$E$3:$BL$3,L$14,PnL_Speadsheet!$E9:$BL9)/1000 -> 0 | M23: =SUMIF(PnL_Speadsheet!$E$3:$BL$3,M$14,PnL_Speadsheet!$E9:$BL9)/1000 -> 0 | N23: =SUMIF(PnL_Speadsheet!$E$3:$BL$3,N$14,PnL_Speadsheet!$E9:$BL9)/1000 -> 0 | O23: =SUMIF(PnL_Speadsheet!$E$3:$BL$3,O$14,PnL_Speadsheet!$E9:$BL9)/1000 -> 0 | P23: =SUMIF(PnL_Speadsheet!$E$3:$BL$3,P$14,PnL_Speadsheet!$E9:$BL9)/1000 -> 0
H24: NII | J24: =SUM(K24:U24) -> 0 | K24: =SUMIF(PnL_Speadsheet!$E$3:$BL$3,K$14,PnL_Speadsheet!$E10:$BL10)/1000 -> 0 | L24: =SUMIF(PnL_Speadsheet!$E$3:$BL$3,L$14,PnL_Speadsheet!$E10:$BL10)/1000 -> 0 | M24: =SUMIF(PnL_Speadsheet!$E$3:$BL$3,M$14,PnL_Speadsheet!$E10:$BL10)/1000 -> 0 | N24: =SUMIF(PnL_Speadsheet!$E$3:$BL$3,N$14,PnL_Speadsheet!$E10:$BL10)/1000 -> 0 | O24: =SUMIF(PnL_Speadsheet!$E$3:$BL$3,O$14,PnL_Speadsheet!$E10:$BL10)/1000 -> 0 | P24: =SUMIF(PnL_Speadsheet!$E$3:$BL$3,P$14,PnL_Speadsheet!$E10:$BL10)/1000 -> 0
H25: CII | J25: =SUM(K25:U25) -> 0 | K25: =SUMIF(PnL_Speadsheet!$E$3:$BL$3,K$14,PnL_Speadsheet!$E11:$BL11)/1000 -> 0 | L25: =SUMIF(PnL_Speadsheet!$E$3:$BL$3,L$14,PnL_Speadsheet!$E11:$BL11)/1000 -> 0 | M25: =SUMIF(PnL_Speadsheet!$E$3:$BL$3,M$14,PnL_Speadsheet!$E11:$BL11)/1000 -> 0 | N25: =SUMIF(PnL_Speadsheet!$E$3:$BL$3,N$14,PnL_Speadsheet!$E11:$BL11)/1000 -> 0 | O25: =SUMIF(PnL_Speadsheet!$E$3:$BL$3,O$14,PnL_Speadsheet!$E11:$BL11)/1000 -> 0 | P25: =SUMIF(PnL_Speadsheet!$E$3:$BL$3,P$14,PnL_Speadsheet!$E11:$BL11)/1000 -> 0
H26: COF | J26: =SUM(K26:U26) -> 0 | K26: =SUMIF(PnL_Speadsheet!$E$3:$BL$3,K$14,PnL_Speadsheet!$E12:$BL12)/1000 -> 0 | L26: =SUMIF(PnL_Speadsheet!$E$3:$BL$3,L$14,PnL_Speadsheet!$E12:$BL12)/1000 -> 0 | M26: =SUMIF(PnL_Speadsheet!$E$3:$BL$3,M$14,PnL_Speadsheet!$E12:$BL12)/1000 -> 0 | N26: =SUMIF(PnL_Speadsheet!$E$3:$BL$3,N$14,PnL_Speadsheet!$E12:$BL12)/1000 -> 0 | O26: =SUMIF(PnL_Speadsheet!$E$3:$BL$3,O$14,PnL_Speadsheet!$E12:$BL12)/1000 -> 0 | P26: =SUMIF(PnL_Speadsheet!$E$3:$BL$3,P$14,PnL_Speadsheet!$E12:$BL12)/1000 -> 0
H27: NFI | J27: =SUM(K27:U27) -> 0 | K27: =SUMIF(PnL_Speadsheet!$E$3:$BL$3,K$14,PnL_Speadsheet!$E13:$BL13)/1000 -> 0 | L27: =SUMIF(PnL_Speadsheet!$E$3:$BL$3,L$14,PnL_Speadsheet!$E13:$BL13)/1000 -> 0 | M27: =SUMIF(PnL_Speadsheet!$E$3:$BL$3,M$14,PnL_Speadsheet!$E13:$BL13)/1000 -> 0 | N27: =SUMIF(PnL_Speadsheet!$E$3:$BL$3,N$14,PnL_Speadsheet!$E13:$BL13)/1000 -> 0 | O27: =SUMIF(PnL_Speadsheet!$E$3:$BL$3,O$14,PnL_Speadsheet!$E13:$BL13)/1000 -> 0 | P27: =SUMIF(PnL_Speadsheet!$E$3:$BL$3,P$14,PnL_Speadsheet!$E13:$BL13)/1000 -> 0
H28: Annual fee | J28: =SUM(K28:U28) -> 0 | K28: =SUMIF(PnL_Speadsheet!$E$3:$BL$3,K$14,PnL_Speadsheet!$E14:$BL14)/1000 -> 0 | L28: =SUMIF(PnL_Speadsheet!$E$3:$BL$3,L$14,PnL_Speadsheet!$E14:$BL14)/1000 -> 0 | M28: =SUMIF(PnL_Speadsheet!$E$3:$BL$3,M$14,PnL_Speadsheet!$E14:$BL14)/1000 -> 0 | N28: =SUMIF(PnL_Speadsheet!$E$3:$BL$3,N$14,PnL_Speadsheet!$E14:$BL14)/1000 -> 0 | O28: =SUMIF(PnL_Speadsheet!$E$3:$BL$3,O$14,PnL_Speadsheet!$E14:$BL14)/1000 -> 0 | P28: =SUMIF(PnL_Speadsheet!$E$3:$BL$3,P$14,PnL_Speadsheet!$E14:$BL14)/1000 -> 0
H29: Monthly fee | J29: =SUM(K29:U29) -> 0 | K29: =SUMIF(PnL_Speadsheet!$E$3:$BL$3,K$14,PnL_Speadsheet!$E15:$BL15)/1000 -> 0 | L29: =SUMIF(PnL_Speadsheet!$E$3:$BL$3,L$14,PnL_Speadsheet!$E15:$BL15)/1000 -> 0 | M29: =SUMIF(PnL_Speadsheet!$E$3:$BL$3,M$14,PnL_Speadsheet!$E15:$BL15)/1000 -> 0 | N29: =SUMIF(PnL_Speadsheet!$E$3:$BL$3,N$14,PnL_Speadsheet!$E15:$BL15)/1000 -> 0 | O29: =SUMIF(PnL_Speadsheet!$E$3:$BL$3,O$14,PnL_Speadsheet!$E15:$BL15)/1000 -> 0 | P29: =SUMIF(PnL_Speadsheet!$E$3:$BL$3,P$14,PnL_Speadsheet!$E15:$BL15)/1000 -> 0
H30: Transaction fee | J30: =SUM(K30:U30) -> 0 | K30: =SUMIF(PnL_Speadsheet!$E$3:$BL$3,K$14,PnL_Speadsheet!$E16:$BL16)/1000 -> 0 | L30: =SUMIF(PnL_Speadsheet!$E$3:$BL$3,L$14,PnL_Speadsheet!$E16:$BL16)/1000 -> 0 | M30: =SUMIF(PnL_Speadsheet!$E$3:$BL$3,M$14,PnL_Speadsheet!$E16:$BL16)/1000 -> 0 | N30: =SUMIF(PnL_Speadsheet!$E$3:$BL$3,N$14,PnL_Speadsheet!$E16:$BL16)/1000 -> 0 | O30: =SUMIF(PnL_Speadsheet!$E$3:$BL$3,O$14,PnL_Speadsheet!$E16:$BL16)/1000 -> 0 | P30: =SUMIF(PnL_Speadsheet!$E$3:$BL$3,P$14,PnL_Speadsheet!$E16:$BL16)/1000 -> 0
H31: Issuance fee | J31: =SUM(K31:U31) -> 0 | K31: =SUMIF(PnL_Speadsheet!$E$3:$BL$3,K$14,PnL_Speadsheet!$E17:$BL17)/1000 -> 0 | L31: =SUMIF(PnL_Speadsheet!$E$3:$BL$3,L$14,PnL_Speadsheet!$E17:$BL17)/1000 -> 0 | M31: =SUMIF(PnL_Speadsheet!$E$3:$BL$3,M$14,PnL_Speadsheet!$E17:$BL17)/1000 -> 0 | N31: =SUMIF(PnL_Speadsheet!$E$3:$BL$3,N$14,PnL_Speadsheet!$E17:$BL17)/1000 -> 0 | O31: =SUMIF(PnL_Speadsheet!$E$3:$BL$3,O$14,PnL_Speadsheet!$E17:$BL17)/1000 -> 0 | P31: =SUMIF(PnL_Speadsheet!$E$3:$BL$3,P$14,PnL_Speadsheet!$E17:$BL17)/1000 -> 0
H32: Termination fee | J32: =SUM(K32:U32) -> 0 | K32: =SUMIF(PnL_Speadsheet!$E$3:$BL$3,K$14,PnL_Speadsheet!$E18:$BL18)/1000 -> 0 | L32: =SUMIF(PnL_Speadsheet!$E$3:$BL$3,L$14,PnL_Speadsheet!$E18:$BL18)/1000 -> 0 | M32: =SUMIF(PnL_Speadsheet!$E$3:$BL$3,M$14,PnL_Speadsheet!$E18:$BL18)/1000 -> 0 | N32: =SUMIF(PnL_Speadsheet!$E$3:$BL$3,N$14,PnL_Speadsheet!$E18:$BL18)/1000 -> 0 | O32: =SUMIF(PnL_Speadsheet!$E$3:$BL$3,O$14,PnL_Speadsheet!$E18:$BL18)/1000 -> 0 | P32: =SUMIF(PnL_Speadsheet!$E$3:$BL$3,P$14,PnL_Speadsheet!$E18:$BL18)/1000 -> 0
H33: Late payment | J33: =SUM(K33:U33) -> 0 | K33: =SUMIF(PnL_Speadsheet!$E$3:$BL$3,K$14,PnL_Speadsheet!$E19:$BL19)/1000 -> 0 | L33: =SUMIF(PnL_Speadsheet!$E$3:$BL$3,L$14,PnL_Speadsheet!$E19:$BL19)/1000 -> 0 | M33: =SUMIF(PnL_Speadsheet!$E$3:$BL$3,M$14,PnL_Speadsheet!$E19:$BL19)/1000 -> 0 | N33: =SUMIF(PnL_Speadsheet!$E$3:$BL$3,N$14,PnL_Speadsheet!$E19:$BL19)/1000 -> 0 | O33: =SUMIF(PnL_Speadsheet!$E$3:$BL$3,O$14,PnL_Speadsheet!$E19:$BL19)/1000 -> 0 | P33: =SUMIF(PnL_Speadsheet!$E$3:$BL$3,P$14,PnL_Speadsheet!$E19:$BL19)/1000 -> 0
H34: Min due fee | J34: =SUM(K34:U34) -> 0 | K34: =SUMIF(PnL_Speadsheet!$E$3:$BL$3,K$14,PnL_Speadsheet!$E20:$BL20)/1000 -> 0 | L34: =SUMIF(PnL_Speadsheet!$E$3:$BL$3,L$14,PnL_Speadsheet!$E20:$BL20)/1000 -> 0 | M34: =SUMIF(PnL_Speadsheet!$E$3:$BL$3,M$14,PnL_Speadsheet!$E20:$BL20)/1000 -> 0 | N34: =SUMIF(PnL_Speadsheet!$E$3:$BL$3,N$14,PnL_Speadsheet!$E20:$BL20)/1000 -> 0 | O34: =SUMIF(PnL_Speadsheet!$E$3:$BL$3,O$14,PnL_Speadsheet!$E20:$BL20)/1000 -> 0 | P34: =SUMIF(PnL_Speadsheet!$E$3:$BL$3,P$14,PnL_Speadsheet!$E20:$BL20)/1000 -> 0
... H37: Fee suspended due to CIC | J37: =SUM(K37:U37) -> 0 | K37: =SUMIF(PnL_Speadsheet!$E$3:$BL$3,K$14,PnL_Speadsheet!$E23:$BL23)/1000 -> 0 | L37: =SUMIF(PnL_Speadsheet!$E$3:$BL$3,L$14,PnL_Speadsheet!$E23:$BL23)/1000 -> 0 | M37: =SUMIF(PnL_Speadsheet!$E$3:$BL$3,M$14,PnL_Speadsheet!$E23:$BL23)/1000 -> 0 | N37: =SUMIF(PnL_Speadsheet!$E$3:$BL$3,N$14,PnL_Speadsheet!$E23:$BL23)/1000 -> 0 | O37: =SUMIF(PnL_Speadsheet!$E$3:$BL$3,O$14,PnL_Speadsheet!$E23:$BL23)/1000 -> 0 | P37: =SUMIF(PnL_Speadsheet!$E$3:$BL$3,P$14,PnL_Speadsheet!$E23:$BL23)/1000 -> 0
H38: OPEX | J38: =SUM(K38:U38) -> 0 | K38: =(SUMIF(PnL_Speadsheet!$E$3:$BL$3,K$14,PnL_Speadsheet!$E24:$BL24)/1000) -> 0 | L38: =(SUMIF(PnL_Speadsheet!$E$3:$BL$3,L$14,PnL_Speadsheet!$E24:$BL24)/1000) -> 0 | M38: =(SUMIF(PnL_Speadsheet!$E$3:$BL$3,M$14,PnL_Speadsheet!$E24:$BL24)/1000) -> 0 | N38: =(SUMIF(PnL_Speadsheet!$E$3:$BL$3,N$14,PnL_Speadsheet!$E24:$BL24)/1000) -> 0 | O38: =(SUMIF(PnL_Speadsheet!$E$3:$BL$3,O$14,PnL_Speadsheet!$E24:$BL24)/1000) -> 0 | P38: =(SUMIF(PnL_Speadsheet!$E$3:$BL$3,P$14,PnL_Speadsheet!$E24:$BL24)/1000) -> 0
H39: Sharing to partner | J39: =SUM(K39:U39) -> 0 | K39: =(SUMIF(PnL_Speadsheet!$E$3:$BL$3,K$14,PnL_Speadsheet!$E25:$BL25)/1000)-K40 -> 0 | L39: =(SUMIF(PnL_Speadsheet!$E$3:$BL$3,L$14,PnL_Speadsheet!$E25:$BL25)/1000)-L40 -> 0 | M39: =(SUMIF(PnL_Speadsheet!$E$3:$BL$3,M$14,PnL_Speadsheet!$E25:$BL25)/1000)-M40 -> 0 | N39: =(SUMIF(PnL_Speadsheet!$E$3:$BL$3,N$14,PnL_Speadsheet!$E25:$BL25)/1000)-N40 -> 0 | O39: =(SUMIF(PnL_Speadsheet!$E$3:$BL$3,O$14,PnL_Speadsheet!$E25:$BL25)/1000)-O40 -> 0 | P39: =(SUMIF(PnL_Speadsheet!$E$3:$BL$3,P$14,PnL_Speadsheet!$E25:$BL25)/1000)-P40 -> 0
H40: Marketing acquisition | J40: =SUM(K40:U40) -> 0 | K40: =SUMIF(PnL_Speadsheet!$E$3:$BL$3,K$14,PnL_Speadsheet!$E29:$BL29)/1000 -> 0 | L40: =SUMIF(PnL_Speadsheet!$E$3:$BL$3,L$14,PnL_Speadsheet!$E29:$BL29)/1000 -> 0 | M40: =SUMIF(PnL_Speadsheet!$E$3:$BL$3,M$14,PnL_Speadsheet!$E29:$BL29)/1000 -> 0 | N40: =SUMIF(PnL_Speadsheet!$E$3:$BL$3,N$14,PnL_Speadsheet!$E29:$BL29)/1000 -> 0 | O40: =SUMIF(PnL_Speadsheet!$E$3:$BL$3,O$14,PnL_Speadsheet!$E29:$BL29)/1000 -> 0 | P40: =SUMIF(PnL_Speadsheet!$E$3:$BL$3,P$14,PnL_Speadsheet!$E29:$BL29)/1000 -> 0
H41: Marketing promotion | J41: =SUM(K41:U41) -> 0 | K41: =(SUMIF(PnL_Speadsheet!$E$3:$BL$3,K$14,PnL_Speadsheet!$E30:$BL30)/1000) -> 0 | L41: =(SUMIF(PnL_Speadsheet!$E$3:$BL$3,L$14,PnL_Speadsheet!$E30:$BL30)/1000) -> 0 | M41: =(SUMIF(PnL_Speadsheet!$E$3:$BL$3,M$14,PnL_Speadsheet!$E30:$BL30)/1000) -> 0 | N41: =(SUMIF(PnL_Speadsheet!$E$3:$BL$3,N$14,PnL_Speadsheet!$E30:$BL30)/1000) -> 0 | O41: =(SUMIF(PnL_Speadsheet!$E$3:$BL$3,O$14,PnL_Speadsheet!$E30:$BL30)/1000) -> 0 | P41: =(SUMIF(PnL_Speadsheet!$E$3:$BL$3,P$14,PnL_Speadsheet!$E30:$BL30)/1000) -> 0
H42: UW & Disbursal | J42: =SUM(K42:U42) -> 0 | K42: =SUMIF(PnL_Speadsheet!$E$3:$BL$3,K$14,PnL_Speadsheet!$E31:$BL31)/1000 -> 0 | L42: =SUMIF(PnL_Speadsheet!$E$3:$BL$3,L$14,PnL_Speadsheet!$E31:$BL31)/1000 -> 0 | M42: =SUMIF(PnL_Speadsheet!$E$3:$BL$3,M$14,PnL_Speadsheet!$E31:$BL31)/1000 -> 0 | N42: =SUMIF(PnL_Speadsheet!$E$3:$BL$3,N$14,PnL_Speadsheet!$E31:$BL31)/1000 -> 0 | O42: =SUMIF(PnL_Speadsheet!$E$3:$BL$3,O$14,PnL_Speadsheet!$E31:$BL31)/1000 -> 0 | P42: =SUMIF(PnL_Speadsheet!$E$3:$BL$3,P$14,PnL_Speadsheet!$E31:$BL31)/1000 -> 0
H43: Collection & AMC | J43: =SUM(K43:U43) -> 0 | K43: =SUMIF(PnL_Speadsheet!$E$3:$BL$3,K$14,PnL_Speadsheet!$E32:$BL32)/1000 -> 0 | L43: =SUMIF(PnL_Speadsheet!$E$3:$BL$3,L$14,PnL_Speadsheet!$E32:$BL32)/1000 -> 0 | M43: =SUMIF(PnL_Speadsheet!$E$3:$BL$3,M$14,PnL_Speadsheet!$E32:$BL32)/1000 -> 0 | N43: =SUMIF(PnL_Speadsheet!$E$3:$BL$3,N$14,PnL_Speadsheet!$E32:$BL32)/1000 -> 0 | O43: =SUMIF(PnL_Speadsheet!$E$3:$BL$3,O$14,PnL_Speadsheet!$E32:$BL32)/1000 -> 0 | P43: =SUMIF(PnL_Speadsheet!$E$3:$BL$3,P$14,PnL_Speadsheet!$E32:$BL32)/1000 -> 0
H44: After-sales services | J44: =SUM(K44:U44) -> 0 | K44: =SUMIF(PnL_Speadsheet!$E$3:$BL$3,K$14,PnL_Speadsheet!$E35:$BL35)/1000 -> 0 | L44: =SUMIF(PnL_Speadsheet!$E$3:$BL$3,L$14,PnL_Speadsheet!$E35:$BL35)/1000 -> 0 | M44: =SUMIF(PnL_Speadsheet!$E$3:$BL$3,M$14,PnL_Speadsheet!$E35:$BL35)/1000 -> 0 | N44: =SUMIF(PnL_Speadsheet!$E$3:$BL$3,N$14,PnL_Speadsheet!$E35:$BL35)/1000 -> 0 | O44: =SUMIF(PnL_Speadsheet!$E$3:$BL$3,O$14,PnL_Speadsheet!$E35:$BL35)/1000 -> 0 | P44: =SUMIF(PnL_Speadsheet!$E$3:$BL$3,P$14,PnL_Speadsheet!$E35:$BL35)/1000 -> 0
H45: Other support units | J45: =SUM(K45:U45) -> 0 | K45: =SUMIF(PnL_Speadsheet!$E$3:$BL$3,K$14,PnL_Speadsheet!$E36:$BL36)/1000 -> 0 | L45: =SUMIF(PnL_Speadsheet!$E$3:$BL$3,L$14,PnL_Speadsheet!$E36:$BL36)/1000 -> 0 | M45: =SUMIF(PnL_Speadsheet!$E$3:$BL$3,M$14,PnL_Speadsheet!$E36:$BL36)/1000 -> 0 | N45: =SUMIF(PnL_Speadsheet!$E$3:$BL$3,N$14,PnL_Speadsheet!$E36:$BL36)/1000 -> 0 | O45: =SUMIF(PnL_Speadsheet!$E$3:$BL$3,O$14,PnL_Speadsheet!$E36:$BL36)/1000 -> 0 | P45: =SUMIF(PnL_Speadsheet!$E$3:$BL$3,P$14,PnL_Speadsheet!$E36:$BL36)/1000 -> 0
H46: PROVISION | J46: =SUM(K46:U46) -> 0 | K46: =SUMIF(PnL_Speadsheet!$E$3:$BL$3,K$14,PnL_Speadsheet!$E37:$BL37)/1000 -> 0 | L46: =SUMIF(PnL_Speadsheet!$E$3:$BL$3,L$14,PnL_Speadsheet!$E37:$BL37)/1000 -> 0 | M46: =SUMIF(PnL_Speadsheet!$E$3:$BL$3,M$14,PnL_Speadsheet!$E37:$BL37)/1000 -> 0 | N46: =SUMIF(PnL_Speadsheet!$E$3:$BL$3,N$14,PnL_Speadsheet!$E37:$BL37)/1000 -> 0 | O46: =SUMIF(PnL_Speadsheet!$E$3:$BL$3,O$14,PnL_Speadsheet!$E37:$BL37)/1000 -> 0 | P46: =SUMIF(PnL_Speadsheet!$E$3:$BL$3,P$14,PnL_Speadsheet!$E37:$BL37)/1000 -> 0
H47: Other income | J47: =SUM(K47:U47) -> 0 | K47: =SUMIF(PnL_Speadsheet!$E$3:$BL$3,K$14,PnL_Speadsheet!$E38:$BL38)/1000 -> 0 | L47: =SUMIF(PnL_Speadsheet!$E$3:$BL$3,L$14,PnL_Speadsheet!$E38:$BL38)/1000 -> 0 | M47: =SUMIF(PnL_Speadsheet!$E$3:$BL$3,M$14,PnL_Speadsheet!$E38:$BL38)/1000 -> 0 | N47: =SUMIF(PnL_Speadsheet!$E$3:$BL$3,N$14,PnL_Speadsheet!$E38:$BL38)/1000 -> 0 | O47: =SUMIF(PnL_Speadsheet!$E$3:$BL$3,O$14,PnL_Speadsheet!$E38:$BL38)/1000 -> 0 | P47: =SUMIF(PnL_Speadsheet!$E$3:$BL$3,P$14,PnL_Speadsheet!$E38:$BL38)/1000 -> 0
H48: PBT | J48: =SUM(K48:U48) -> 0 | K48: =SUMIF(PnL_Speadsheet!$E$3:$BL$3,K$14,PnL_Speadsheet!$E39:$BL39)/1000 -> 0 | L48: =SUMIF(PnL_Speadsheet!$E$3:$BL$3,L$14,PnL_Speadsheet!$E39:$BL39)/1000 -> 0 | M48: =SUMIF(PnL_Speadsheet!$E$3:$BL$3,M$14,PnL_Speadsheet!$E39:$BL39)/1000 -> 0 | N48: =SUMIF(PnL_Speadsheet!$E$3:$BL$3,N$14,PnL_Speadsheet!$E39:$BL39)/1000 -> 0 | O48: =SUMIF(PnL_Speadsheet!$E$3:$BL$3,O$14,PnL_Speadsheet!$E39:$BL39)/1000 -> 0 | P48: =SUMIF(PnL_Speadsheet!$E$3:$BL$3,P$14,PnL_Speadsheet!$E39:$BL39)/1000 -> 0
H49: In which: PROFIT BEFORE SUPPORT COST | J49: =SUM(K49:U49) -> 0 | K49: =K23+K46+SUM(K41:K44) -> 0 | L49: =L23+L46+SUM(L41:L44) -> 0 | M49: =M23+M46+SUM(M41:M44) -> 0 | N49: =N23+N46+SUM(N41:N44) -> 0 | O49: =O23+O46+SUM(O41:O44) -> 0 | P49: =P23+P46+SUM(P41:P44) -> 0

Sheet PnL_Speadsheet
C1: ='Sales plan& PnL'!H1 -> DPD180+ | D1: PL PROJECTION
D2: 60 months
E3: =YEAR(E4) -> 2025 | F3: =YEAR(F4) -> 2025 | G3: =YEAR(G4) -> 2025 | H3: =YEAR(H4) -> 2025 | I3: =YEAR(I4) -> 2025 | J3: =YEAR(J4) -> 2025 | K3: =YEAR(K4) -> 2025 | L3: =YEAR(L4) -> 2025 | ... BL3: =YEAR(BL4) -> 2029
D4: Business month | E4: ='Sales plan& PnL'!J8 -> 45658 | F4: ='Sales plan& PnL'!K8 -> 45716 | G4: ='Sales plan& PnL'!L8 -> 45747 | H4: ='Sales plan& PnL'!M8 -> 45777 | I4: ='Sales plan& PnL'!N8 -> 45808 | J4: ='Sales plan& PnL'!O8 -> 45838 | K4: ='Sales plan& PnL'!P8 -> 45869 | L4: ='Sales plan& PnL'!Q8 -> 45900 | ... BL4: ='Sales plan& PnL'!BQ8 -> 47483
D5: Month on board | E5: =1 -> 1 | F5: =E5+1 -> 2 | G5: =F5+1 -> 3 | H5: =G5+1 -> 4 | I5: =H5+1 -> 5 | J5: =I5+1 -> 6 | K5: =J5+1 -> 7 | L5: =K5+1 -> 8 | M5: =L5+1 -> 9 | ... BL5: =BK5+1 -> 60
D6: Unit: mVND
D7: ENR | E7: {=SUMPRODUCT(E$63:E$122,TRANSPOSE(SAP_Spreadsheet!$G$172:$BN$172))} -> 0 | F7: {=SUMPRODUCT(F$63:F$122,TRANSPOSE(SAP_Spreadsheet!$G$172:$BN$172))} -> 0 | G7: {=SUMPRODUCT(G$63:G$122,TRANSPOSE(SAP_Spreadsheet!$G$172:$BN$172))} -> 0 | H7: {=SUMPRODUCT(H$63:H$122,TRANSPOSE(SAP_Spreadsheet!$G$172:$BN$172))} -> 0 | I7: {=SUMPRODUCT(I$63:I$122,TRANSPOSE(SAP_Spreadsheet!$G$172:$BN$172))} -> 0 | J7: {=SUMPRODUCT(J$63:J$122,TRANSPOSE(SAP_Spreadsheet!$G$172:$BN$172))} -> 0 | K7: {=SUMPRODUCT(K$63:K$122,TRANSPOSE(SAP_Spreadsheet!$G$172:$BN$172))} -> 0 | L7: {=SUMPRODUCT(L$63:L$122,TRANSPOSE(SAP_Spreadsheet!$G$172:$BN$172))} -> 0 | ... BL7: {=SUMPRODUCT(BL$63:BL$122,TRANSPOSE(SAP_Spreadsheet!$G$172:$BN$172))} -> 0
D8: ANR | E8: {=SUMPRODUCT(E$63:E$122,TRANSPOSE(SAP_Spreadsheet!$G$202:$BN$202))} -> 0 | F8: {=SUMPRODUCT(F$63:F$122,TRANSPOSE(SAP_Spreadsheet!$G$202:$BN$202))} -> 0 | G8: {=SUMPRODUCT(G$63:G$122,TRANSPOSE(SAP_Spreadsheet!$G$202:$BN$202))} -> 0 | H8: {=SUMPRODUCT(H$63:H$122,TRANSPOSE(SAP_Spreadsheet!$G$202:$BN$202))} -> 0 | I8: {=SUMPRODUCT(I$63:I$122,TRANSPOSE(SAP_Spreadsheet!$G$202:$BN$202))} -> 0 | J8: {=SUMPRODUCT(J$63:J$122,TRANSPOSE(SAP_Spreadsheet!$G$202:$BN$202))} -> 0 | K8: {=SUMPRODUCT(K$63:K$122,TRANSPOSE(SAP_Spreadsheet!$G$202:$BN$202))} -> 0 | L8: {=SUMPRODUCT(L$63:L$122,TRANSPOSE(SAP_Spreadsheet!$G$202:$BN$202))} -> 0 | ... BL8: {=SUMPRODUCT(BL$63:BL$122,TRANSPOSE(SAP_Spreadsheet!$G$202:$BN$202))} -> 0
D9: TOI | E9: {=SUMPRODUCT(E$63:E$122,TRANSPOSE(SAP_Spreadsheet!$G$239:$BN$239))} -> 0 | F9: {=SUMPRODUCT(F$63:F$122,TRANSPOSE(SAP_Spreadsheet!$G$239:$BN$239))} -> 0 | G9: {=SUMPRODUCT(G$63:G$122,TRANSPOSE(SAP_Spreadsheet!$G$239:$BN$239))} -> 0 | H9: {=SUMPRODUCT(H$63:H$122,TRANSPOSE(SAP_Spreadsheet!$G$239:$BN$239))} -> 0 | I9: {=SUMPRODUCT(I$63:I$122,TRANSPOSE(SAP_Spreadsheet!$G$239:$BN$239))} -> 0 | J9: {=SUMPRODUCT(J$63:J$122,TRANSPOSE(SAP_Spreadsheet!$G$239:$BN$239))} -> 0 | K9: {=SUMPRODUCT(K$63:K$122,TRANSPOSE(SAP_Spreadsheet!$G$239:$BN$239))} -> 0 | L9: {=SUMPRODUCT(L$63:L$122,TRANSPOSE(SAP_Spreadsheet!$G$239:$BN$239))} -> 0 | ... BL9: {=SUMPRODUCT(BL$63:BL$122,TRANSPOSE(SAP_Spreadsheet!$G$239:$BN$239))} -> 0
D10: Net interest income | E10: {=SUMPRODUCT(E$63:E$122,TRANSPOSE(SAP_Spreadsheet!$G$220:$BN$220))} -> 0 | F10: {=SUMPRODUCT(F$63:F$122,TRANSPOSE(SAP_Spreadsheet!$G$220:$BN$220))} -> 0 | G10: {=SUMPRODUCT(G$63:G$122,TRANSPOSE(SAP_Spreadsheet!$G$220:$BN$220))} -> 0 | H10: {=SUMPRODUCT(H$63:H$122,TRANSPOSE(SAP_Spreadsheet!$G$220:$BN$220))} -> 0 | I10: {=SUMPRODUCT(I$63:I$122,TRANSPOSE(SAP_Spreadsheet!$G$220:$BN$220))} -> 0 | J10: {=SUMPRODUCT(J$63:J$122,TRANSPOSE(SAP_Spreadsheet!$G$220:$BN$220))} -> 0 | K10: {=SUMPRODUCT(K$63:K$122,TRANSPOSE(SAP_Spreadsheet!$G$220:$BN$220))} -> 0 | L10: {=SUMPRODUCT(L$63:L$122,TRANSPOSE(SAP_Spreadsheet!$G$220:$BN$220))} -> 0 | ... BL10: {=SUMPRODUCT(BL$63:BL$122,TRANSPOSE(SAP_Spreadsheet!$G$220:$BN$220))} -> 0
