Workbook
Name __S1: {"Book1"}
Name __S1: {"Book1"}
Name __S1: {"Book1"}
Name _a1: {"'Sheet1'!$L$16"}
Name _a1: {"'Sheet1'!$L$16"}
Name _a1: {"'Sheet1'!$L$16"}
Name _S1: {"Book1"}
Name _S1: {"Book1"}
Name _S1: {"Book1"}
Name Ă: #REF!
Name Ạ196: #REF!
Name â259: #REF!
Name â259: #REF!
Name â312: #REF!
Name â312: #REF!
Name Acquisition_PlanA: #REF!
Name Acquisition_PlanB: #REF!
Name Actual: (PeriodInActual*(#REF!>0))*PeriodInPlan
Name Actual: (PeriodInActual*(#REF!>0))*PeriodInPlan
Name Actual: (PeriodInActual*(#REF!>0))*PeriodInPlan
Name ActualBeyond: PeriodInActual*(#REF!>0)
Name ActualBeyond: PeriodInActual*(#REF!>0)
Name ActualBeyond: PeriodInActual*(#REF!>0)
Name adf: #REF!
Name adf: #REF!
Name adf: #REF!
Name AdvIncQ12020: #REF!
Name AdvIncQ12020: #REF!
Name AdvIncQ12021: #REF!
Name AdvIncQ12021: #REF!
Name AdvIncQ12022: #REF!
Name AdvIncQ12022: #REF!
Name AdvIncQ12023: #REF!
Name AdvIncQ12023: #REF!
Name AdvIncQ12024: #REF!
Name AdvIncQ12024: #REF!
Name AdvIncQ22020: #REF!
Name AdvIncQ22020: #REF!
Name AdvIncQ22021: #REF!
Name AdvIncQ22021: #REF!
Name AdvIncQ22022: #REF!
Name AdvIncQ22022: #REF!
Name AdvIncQ22023: #REF!
Name AdvIncQ22023: #REF!
Name AdvIncQ22024: #REF!
Name AdvIncQ22024: #REF!
Name AdvIncQ32020: #REF!
Name AdvIncQ32020: #REF!
Name AdvIncQ32021: #REF!
Name AdvIncQ32021: #REF!
Name AdvIncQ32022: #REF!
Name AdvIncQ32022: #REF!
Name AdvIncQ32023: #REF!
Name AdvIncQ32023: #REF!
Name AdvIncQ32024: #REF!
Name AdvIncQ32024: #REF!
Name AdvIncQ42020: #REF!
Name AdvIncQ42020: #REF!
Name AdvIncQ42021: #REF!
Name AdvIncQ42021: #REF!

Sheet NOTE
A1: SAP MODEL - CASHLOAN
B2: OFFICIAL | N2: HKN | O2: v9 | P2: 20251001
B3: 1. Notes and disclaimer
C4: a. Giới thiệu về SAP
D5: - SAP: Single Account Profitability (Hiệu quả sản phẩm trên từng đơn vị sản phẩm)
D6: - Model SAP được sử dụng như một (01) trong các mô hình dự đoán hiệu quả vòng đời của sản phẩm.
D7: - Do sự phức tạp của sản phẩm, các hệ thống vận hành (hệ thống hạch kế toán, hệ thống quản trị rủi ro, hệ thống quản trị…), hành vi người sử dụng hành vi người sử dụng, model chỉ có thể mô phỏng tương đối trung bình vòng đời của sản phẩm.
D8: - Do tính chất thời điểm, mô hình được xây dựng mô phỏng theo cách vận hành sản phẩm tại thời điểm phát hành. Trường hợp hệ thống thay đổi, sản phẩm thay đổi, mô hình sẽ không thể phản ánh đúng bản chất vận hành sản phẩm.
D9: - Mô hình được tính toán dựa vào các yếu tố đầu vào xác định tại một thời điểm xác định, do đó kết quả của mô hình có thể có sự khác biệt so với thực tế vận hành sản phẩm.
D10: - Mô hình SAP Cashloan tính hiệu quả của khoản vay giải ngân và thời hạn tối đa được áp dụng là 5 năm ( 60 tháng) kể từ ngày bắt đầu sản phẩm đối với sử dụng phương pháp dự phòng IFRS
E11: - Lưu ý rằng trường hợp áp dụng cho khoản vay 5 năm, thì các chi phí sẽ không được tính toán đầy đủ do chi phí COF cho thời gian từ lúc khoản vay kết thúc tới lúc được xóa trên sổ kế toán.
E12: - Chỉ nên sử dụng với khoản vay dưới 4 năm (48 tháng) để được tính toán đầy đủ chi phí
E13: - Đối với phương pháp tính rủi ro VAS, thời hạn khoản vay tối đa sử dụng là 4 năm (48 tháng)
C15: b. Giới thiệu về PnL
D16: - Trong file tính này, Profit & Lost (PnL) được dự phóng từ trung bình cộng kết quả kinh doanh trên từng sản phẩm (SAP) với yếu tố "sale plan" (số giải ngân) qua từng tháng, do đó có thể khác biệt so với kết quả thực tế vận hành.
D17: - Dòng tiền thực tế qua từng tháng có thể khác biệt với mô hình tính toán do nhiều yếu tố tác động bên ngoài thay đổi, do đó, vui lòng chỉ sử dụng mô hình cho mục đích tham khảo.
D18: - Cho mục đích tính dự phòng dòng tiền ngắn và trung hạn, mô hình PnL được cutoff tại thời điểm 5 năm (60 tháng) kể từ ngày bắt đầu khởi chạy sản phẩm đầu tiên.
B20: 2. Instruction
D21: - Dành cho người sử dụng
E22: - Chỉ chỉnh sửa vào các ô màu vàng
E23: - 2 sheets "SAP_Leadsheet" và "Sale plan&PnL" cung cấp yếu tố đầu vào và đầu ra để tính toán mô hình SAP cũng như PnL.
F24: - Sheet SAP_Leadsheet được cấu trúc 2 phần, bên trái là các yếu tố đầu vào (input) và bên phải là kết quả dự đoán (output). Đơn vị sử dụng tại bảng tính là triệu VND (mVND) và phần trăm (%)
F25: - Sheet "Sale plan & PL" được cấu trúc 2 phần, bên trên là sale plan và bên dưới là kết quả PnL
E26: - 2 sheets "SAP_Spreadsheet" và "PL projection speadsheet" là các file tính toán cho 2 sheet "SAP_Leadsheet", "Sales plan & PL"
F27: - 2 sheets được cấu trúc từ trên xuống dưới theo thứ tự tính toán mô phỏng để đưa ra kết quả kinh doanh cuối cùng
F28: - 2 sheets đã được tạm khóa. Trường hợp cần mở khóa, điều chỉnh các yếu tố, vui lòng liên hệ với nhóm vận hành để được hỗ trợ.
D30: - Dành riêng cho người vận hành, hiệu chỉnh
E31: - Cần cẩn trọng khi điều chỉnh ở các file "speadsheet" vì 1 khi sai lệch rất khó tìm ra lỗi (VD: sửa nhầm ô, link nhầm vị trí,…)
B34: 3. Legend
C35: GENERAL INPUT
G37: Diễn giải | L37: Chú thích
D38: Risk input | G38: Loại phương pháp tính rủi ro | L38: Lựa chon phương pháp tính rủi ro VAS và IFRS
D39: Write off | G39: Thời điểm WO | L39: Lựa chọn thời điểm ghi nhận WO là 360 hoặc 180
C40: REVENUE INPUT
G42: Diễn giải | L42: Chú thích
C43: Amount & Tenor
D44: Loan amount | G44: Số tiền vay giải ngân (có thể bao gồm bảo hiểm hoặc không) | L44: Trường hợp số tiền giải ngân > giá trị hàng hóa, chỉ ghi = số thực tế giải ngân
D45: Payment Method | G45: Phương pháp tính lãi | L45: EMI (Equated monthly Installment)- số tiền thanh toán cố định hàng tháng
D46: Nominal Tenor | G46: Thời hạn vay | L46: Thời hạn ghi nhận trên khoản vay ( VD: 1 tháng, 3 tháng, 12 tháng,…)
D47: Maturity to Termination | G47: Thời hạn từ lúc đáo hạn tới lúc tới khi ra ngoại bảng | L47: Nên để 6 tháng để khớp với hệ thống kế toán, rủi ro đang ghi nhận WO180+
...

Sheet DATA
C1: HKN
C2: Export source: 20260122
B4: 1 | C4: Aproval rate, signed rate
C6: aprroval rate | E6: =D10/D9 -> 0.38146326
C7: Signed rate | E7: =D11/D10 -> 0.93733228
C9: Application | D9: 2947196
C10: Approval | D10: 1124247
C11: Signed | D11: 1053793
B19: 2 | C19: Disburse, Tenor, Insurance, IR
C21: Disburse date | D21: # Disburse | E21: Disburse amount (VND) | G21: Ticket size (VND) | H21: Avg tenor (Month) | I21: Avg IR (%) | J21: Insurance fee (VND) | K21: % Insurance penetration by date
B22: PD | C22: 45992 | D22: 188031 | E22: 699210716000 | F22: 190721187321 | G22: 3718592.8 | H22: 1 | I22: 0.56689296 | J22: 51741676000 | K22: 0.99998936 | L22: =E22-J22 -> 647469040000
B23: PD | C23: 45962 | D23: 168520 | E23: 573628436000 | F23: 34260992528 | G23: 3403919 | H23: 1 | I23: 0.56788096 | J23: 42439206000 | K23: 1 | L23: =E23-J23 -> 531189230000
B24: PD | C24: 45931 | D24: 170703 | E24: 591442880000 | F24: 36240388319 | G24: 3464748 | H24: 1 | I24: 0.56997153 | J24: 43760590000 | K24: 1 | L24: =E24-J24 -> 547682290000
B25: PD | C25: 45901 | D25: 137891 | E25: 468373996000 | F25: 31047611939 | G25: 3396697.4 | H25: 1 | I25: 0.57105322 | J25: 34644786000 | K25: 1 | L25: =E25-J25 -> 433729210000
B26: PD | C26: 45870 | D26: 92113 | E26: 314000196000 | F26: 15439379324 | G26: 3408858.6 | H26: 1 | I26: 0.57115065 | J26: 23212896000 | K26: 1 | L26: =E26-J26 -> 290787300000
B27: PD | C27: 45839 | D27: 63333 | E27: 236663940000 | F27: 12296965387 | G27: 3736818.7 | H27: 1 | I27: 0.58071937 | J27: 17494140000 | K27: 1 | L27: =E27-J27 -> 219169800000
B28: PD | C28: 45809 | D28: 37045 | E28: 164604632000 | F28: 5584537745 | G28: 4443369.7 | H28: 1 | I28: 0.59810501 | J28: 12170632000 | K28: 0.99997301 | L28: =E28-J28 -> 152434000000
B29: PD | C29: 45778 | D29: 40652 | E29: 167858172000 | F29: 6206674079 | G29: 4129149.2 | H29: 1 | I29: 0.59718095 | J29: 12395692000 | K29: 1 | L29: =E29-J29 -> 155462480000
B30: PD | C30: 45748 | D30: 40388 | E30: 163797828000 | F30: 5553237320 | G30: 4055606.3 | H30: 1 | I30: 0.59601862 | J30: 12087558000 | K30: 1 | L30: =E30-J30 -> 151710270000
B31: PD | C31: 45717 | D31: 42319 | E31: 158845500000 | F31: 5459971468 | G31: 3753526.8 | H31: 1 | I31: 0.59481084 | J31: 12610100000 | K31: 0.99981096 | L31: =E31-J31 -> 146235400000
B32: PD | C32: 45689 | D32: 35363 | E32: 133485000000 | F32: 4749141919 | G32: 3774708 | H32: 1 | I32: 0.59569041 | J32: 10618710000 | K32: 1 | L32: =E32-J32 -> 122866290000
B33: PD | C33: 45658 | D33: 37562 | E33: 141375000000 | F33: 5354592901 | G33: 3763777.2 | H33: 1 | I33: 0.59706086 | J33: 11270440000 | K33: 1 | L33: =E33-J33 -> 130104560000
H35: =SUMPRODUCT(H22:H33,D22:D33)/SUM(D22:D33) -> 1
F36: Adj ticket size | G36: Ticketsize | H36: Tenor | J36: % Insurance rate | K36: Penetration
C37: AVG | F37: =G37 -> 3.5358329 | G37: =SUM(E22:E24)/SUM(D22:D24)/10^6 -> 3.5358329 | H37: =ROUND(SUMPRODUCT(H22:H24,E22:E24)/SUM(E22:E24),0) -> 1 | I37: =AVERAGE(I22:I24) -> 0.56824848 | J37: 0.08 | K37: =SUMPRODUCT(K22:K24,E22:E24)/SUM(E22:E24) -> 0.99999601
D39: 1 | E39: =D39+1 -> 2 | F39: =E39+1 -> 3 | G39: =F39+1 -> 4 | H39: =G39+1 -> 5 | I39: =H39+1 -> 6 | J39: =I39+1 -> 7 | K39: =J39+1 -> 8 | L39: =K39+1 -> 9 | M39: =L39+1 -> 10 | N39: 11 | O39: 12
C40: Limit OD | D40: 581050000 | E40: 427800000 | F40: 512350000 | G40: 514550000 | H40: 517850000 | I40: 527000000 | J40: 425350000 | K40: 78350000 | L40: 86800000 | M40: 104300000 | N40: 85100000 | O40: 69950000
C42: Limit fee | D42: =SUM(M40:O40)/SUM(D22:D24)/10^6 -> 0.00049188816
B47: 3 | C47: UW, collection, MKT
D49: 1 | E49: =D49+1 -> 2 | F49: =E49+1 -> 3 | G49: =F49+1 -> 4 | H49: =G49+1 -> 5 | I49: =H49+1 -> 6 | J49: =I49+1 -> 7 | K49: =J49+1 -> 8 | L49: =K49+1 -> 9 | M49: =L49+1 -> 10 | N49: 11 | O49: 12
C50: New ACC | D50: =PNL!M517+PNL!M556+PNL!M595+PNL!M634+PNL!M672 -> 37557 | E50: =PNL!N517+PNL!N556+PNL!N595+PNL!N634+PNL!N672 -> 35357 | F50: =PNL!O517+PNL!O556+PNL!O595+PNL!O634+PNL!O672 -> 42315 | G50: =PNL!P517+PNL!P556+PNL!P595+PNL!P634+PNL!P672 -> 40433 | H50: =PNL!Q517+PNL!Q556+PNL!Q595+PNL!Q634+PNL!Q672 -> 40883 | I50: =PNL!R517+PNL!R556+PNL!R595+PNL!R634+PNL!R672 -> 37045 | J50: =PNL!S517+PNL!S556+PNL!S595+PNL!S634+PNL!S672 -> 63333 | K50: =PNL!T517+PNL!T556+PNL!T595+PNL!T634+PNL!T672 -> 92113 | ... O50: =PNL!X517+PNL!X556+PNL!X595+PNL!X634+PNL!X672 -> 188031
C51: Accum | D51: =PNL!M519+PNL!M558+PNL!M597+PNL!M636+PNL!M674 -> 48569 | E51: =PNL!N519+PNL!N558+PNL!N597+PNL!N636+PNL!N674 -> 43818 | F51: =PNL!O519+PNL!O558+PNL!O597+PNL!O636+PNL!O674 -> 45385 | G51: =PNL!P519+PNL!P558+PNL!P597+PNL!P636+PNL!P674 -> 44806 | H51: =PNL!Q519+PNL!Q558+PNL!Q597+PNL!Q636+PNL!Q674 -> 44647 | I51: =PNL!R519+PNL!R558+PNL!R597+PNL!R636+PNL!R674 -> 42621 | J51: =PNL!S519+PNL!S558+PNL!S597+PNL!S636+PNL!S674 -> 45925 | K51: =PNL!T519+PNL!T558+PNL!T597+PNL!T636+PNL!T674 -> 83734 | ... O51: =PNL!X519+PNL!X558+PNL!X597+PNL!X636+PNL!X674 -> 184132
C52: Disbursement | D52: =PNL!M520+PNL!M559+PNL!M598+PNL!M637+PNL!M675 -> 141375000000 | E52: =PNL!N520+PNL!N559+PNL!N598+PNL!N637+PNL!N675 -> 133485000000 | F52: =PNL!O520+PNL!O559+PNL!O598+PNL!O637+PNL!O675 -> 158817500000 | G52: =PNL!P520+PNL!P559+PNL!P598+PNL!P637+PNL!P675 -> 163797828000 | H52: =PNL!Q520+PNL!Q559+PNL!Q598+PNL!Q637+PNL!Q675 -> 167858172000 | I52: =PNL!R520+PNL!R559+PNL!R598+PNL!R637+PNL!R675 -> 164604632000 | J52: =PNL!S520+PNL!S559+PNL!S598+PNL!S637+PNL!S675 -> 236641260000 | K52: =PNL!T520+PNL!T559+PNL!T598+PNL!T637+PNL!T675 -> 314000196000 | ... O52: =PNL!X520+PNL!X559+PNL!X598+PNL!X637+PNL!X675 -> 699210716000
C54: UW | D54: =PNL!M547+PNL!M586+PNL!M625+PNL!M664+PNL!M702 -> 294708631 | E54: =PNL!N547+PNL!N586+PNL!N625+PNL!N664+PNL!N702 -> 241456911 | F54: =PNL!O547+PNL!O586+PNL!O625+PNL!O664+PNL!O702 -> 274430890 | G54: =PNL!P547+PNL!P586+PNL!P625+PNL!P664+PNL!P702 -> 2.5677811e+08 | H54: =PNL!Q547+PNL!Q586+PNL!Q625+PNL!Q664+PNL!Q702 -> 230726390 | I54: =PNL!R547+PNL!R586+PNL!R625+PNL!R664+PNL!R702 -> 2.6131897e+08 | J54: =PNL!S547+PNL!S586+PNL!S625+PNL!S664+PNL!S702 -> 774554348 | K54: =PNL!T547+PNL!T586+PNL!T625+PNL!T664+PNL!T702 -> 1088847457 | ... O54: =PNL!X547+PNL!X586+PNL!X625+PNL!X664+PNL!X702 -> 1567243148
C55: MKT acquisition | D55: =PNL!M545+PNL!M584+PNL!M623+PNL!M662+PNL!M700 -> 0 | E55: =PNL!N545+PNL!N584+PNL!N623+PNL!N662+PNL!N700 -> 0 | F55: =PNL!O545+PNL!O584+PNL!O623+PNL!O662+PNL!O700 -> 0 | G55: =PNL!P545+PNL!P584+PNL!P623+PNL!P662+PNL!P700 -> 0 | H55: =PNL!Q545+PNL!Q584+PNL!Q623+PNL!Q662+PNL!Q700 -> 0 | I55: =PNL!R545+PNL!R584+PNL!R623+PNL!R662+PNL!R700 -> 0 | J55: =PNL!S545+PNL!S584+PNL!S623+PNL!S662+PNL!S700 -> 40000000 | K55: =PNL!T545+PNL!T584+PNL!T623+PNL!T662+PNL!T700 -> 38824927 | ... O55: =PNL!X545+PNL!X584+PNL!X623+PNL!X662+PNL!X700 -> 24403980
C56: Partner acquisition | D56: =PNL!M546+PNL!M585+PNL!M624+PNL!M663+PNL!M701 -> 5613597335 | E56: =PNL!N546+PNL!N585+PNL!N624+PNL!N663+PNL!N701 -> 5090892820 | F56: =PNL!O546+PNL!O585+PNL!O624+PNL!O663+PNL!O701 -> 5481907837 | G56: =PNL!P546+PNL!P585+PNL!P624+PNL!P663+PNL!P701 -> 3923265598 | H56: =PNL!Q546+PNL!Q585+PNL!Q624+PNL!Q663+PNL!Q701 -> 4564628668 | I56: =PNL!R546+PNL!R585+PNL!R624+PNL!R663+PNL!R701 -> 5017928237 | J56: =PNL!S546+PNL!S585+PNL!S624+PNL!S663+PNL!S701 -> 5519565810 | K56: =PNL!T546+PNL!T585+PNL!T624+PNL!T663+PNL!T701 -> 5578703708 | ... O56: =PNL!X546+PNL!X585+PNL!X624+PNL!X663+PNL!X701 -> 9293871690
C57: Open cost (Esign, NFC) | D57: =PNL!M548+PNL!M549+PNL!M587+PNL!M588+PNL!M626+PNL!M627+PNL!M665+PNL!M666+PNL!M703+PNL!M704 -> 74545065 | E57: =PNL!N548+PNL!N549+PNL!N587+PNL!N588+PNL!N626+PNL!N627+PNL!N665+PNL!N666+PNL!N703+PNL!N704 -> 56131305 | F57: =PNL!O548+PNL!O549+PNL!O587+PNL!O588+PNL!O626+PNL!O627+PNL!O665+PNL!O666+PNL!O703+PNL!O704 -> 75152614 | G57: =PNL!P548+PNL!P549+PNL!P587+PNL!P588+PNL!P626+PNL!P627+PNL!P665+PNL!P666+PNL!P703+PNL!P704 -> 119315953 | H57: =PNL!Q548+PNL!Q549+PNL!Q587+PNL!Q588+PNL!Q626+PNL!Q627+PNL!Q665+PNL!Q666+PNL!Q703+PNL!Q704 -> 66792605 | I57: =PNL!R548+PNL!R549+PNL!R587+PNL!R588+PNL!R626+PNL!R627+PNL!R665+PNL!R666+PNL!R703+PNL!R704 -> 68376864 | J57: =PNL!S548+PNL!S549+PNL!S587+PNL!S588+PNL!S626+PNL!S627+PNL!S665+PNL!S666+PNL!S703+PNL!S704 -> 91851795 | K57: =PNL!T548+PNL!T549+PNL!T587+PNL!T588+PNL!T626+PNL!T627+PNL!T665+PNL!T666+PNL!T703+PNL!T704 -> 111126840 | ... O57: =PNL!X548+PNL!X549+PNL!X587+PNL!X588+PNL!X626+PNL!X627+PNL!X665+PNL!X666+PNL!X703+PNL!X704 -> 2.0607168e+08
C58: Collection | D58: =PNL!M550+PNL!M589+PNL!M628+PNL!M667+PNL!M705 -> 3.8013328e+08 | E58: =PNL!N550+PNL!N589+PNL!N628+PNL!N667+PNL!N705 -> 4.5412169e+08 | F58: =PNL!O550+PNL!O589+PNL!O628+PNL!O667+PNL!O705 -> 2.0636976e+08 | G58: =PNL!P550+PNL!P589+PNL!P628+PNL!P667+PNL!P705 -> 1.9828551e+08 | H58: =PNL!Q550+PNL!Q589+PNL!Q628+PNL!Q667+PNL!Q705 -> 2.3158827e+08 | I58: =PNL!R550+PNL!R589+PNL!R628+PNL!R667+PNL!R705 -> 80922783 | J58: =PNL!S550+PNL!S589+PNL!S628+PNL!S667+PNL!S705 -> 121000549 | K58: =PNL!T550+PNL!T589+PNL!T628+PNL!T667+PNL!T705 -> 1.2149155e+08 | ... O58: =PNL!X550+PNL!X589+PNL!X628+PNL!X667+PNL!X705 -> 5.9461648e+08
C59: SMS | D59: =PNL!M552+PNL!M591+PNL!M630+PNL!M669+PNL!M707 -> 29016624 | E59: =PNL!N552+PNL!N591+PNL!N630+PNL!N669+PNL!N707 -> 14547401 | F59: =PNL!O552+PNL!O591+PNL!O630+PNL!O669+PNL!O707 -> 19220055 | G59: =PNL!P552+PNL!P591+PNL!P630+PNL!P669+PNL!P707 -> 26683398 | H59: =PNL!Q552+PNL!Q591+PNL!Q630+PNL!Q669+PNL!Q707 -> 20358234 | I59: =PNL!R552+PNL!R591+PNL!R630+PNL!R669+PNL!R707 -> 17135613 | J59: =PNL!S552+PNL!S591+PNL!S630+PNL!S669+PNL!S707 -> 23219446 | K59: =PNL!T552+PNL!T591+PNL!T630+PNL!T669+PNL!T707 -> 16912920 | ... O59: =PNL!X552+PNL!X591+PNL!X630+PNL!X669+PNL!X707 -> 67674083
C64: =SUM(M55:O55)/SUM(M50:O50)/10^6 -> 0.00046334764 | D64: marketing_acquisition_cost
...

Sheet PNL
J1: 6.9400224e+11
B2: Group | C2: Product | D2: Subproduct | E2: Chanel | F2: Catergory | G2: Index | I2: Product PnL | K2: 45597 | L2: 45627 | M2: 45658 | N2: 45689 | O2: 45717 | P2: 45748 | Q2: 45778 | R2: 45809 | S2: 45839 | T2: 45870 | U2: 45901 | V2: 45931 | W2: 45962 | X2: 45992
I3: LENDING
B4: lending | D4: all | G4: =B4&"_"&C4&"_"&D4&"_"&E4&"_"&F4 -> lending__all__ | I4: New account | J4: =SUM(M4:X4) -> 1710749 | K4: =SUMIFS(K$48:K$3038,$I$48:$I$3038,"New account") -> 69275 | L4: =SUMIFS(L$48:L$3038,$I$48:$I$3038,"New account") -> 83163 | M4: =SUMIFS(M$48:M$3038,$I$48:$I$3038,"New account") -> 72675 | N4: =SUMIFS(N$48:N$3038,$I$48:$I$3038,"New account") -> 62148 | O4: =SUMIFS(O$48:O$3038,$I$48:$I$3038,"New account") -> 83436 | P4: =SUMIFS(P$48:P$3038,$I$48:$I$3038,"New account") -> 82811 | Q4: =SUMIFS(Q$48:Q$3038,$I$48:$I$3038,"New account") -> 83424 | R4: =SUMIFS(R$48:R$3038,$I$48:$I$3038,"New account") -> 86016 | ... V4: =SUMIFS(V$48:V$3038,$I$48:$I$3038,"New account") -> 242972 | W4: =SUMIFS($W$48:$W$3038,$I$48:$I$3038,"New account") -> 248246 | X4: =SUMIFS(X$48:X$3038,$I$48:$I$3038,"New account") -> 271168 | Y4: =X4-W4 -> 22922 | Z4: 248246
B5: lending | D5: all | G5: =B5&"_"&C5&"_"&D5&"_"&E5&"_"&F5 -> lending__all__ | I5: Repeat account | J5: =SUM(M5:X5) -> 977652 | K5: =SUMIFS(K$48:K$3038,$I$48:$I$3038,"Repeat account") -> 31467 | L5: =SUMIFS(L$48:L$3038,$I$48:$I$3038,"Repeat account") -> 41624 | M5: =SUMIFS(M$48:M$3038,$I$48:$I$3038,"Repeat account") -> 36793 | N5: =SUMIFS(N$48:N$3038,$I$48:$I$3038,"Repeat account") -> 35375 | O5: =SUMIFS(O$48:O$3038,$I$48:$I$3038,"Repeat account") -> 45120 | P5: =SUMIFS(P$48:P$3038,$I$48:$I$3038,"Repeat account") -> 44837 | Q5: =SUMIFS(Q$48:Q$3038,$I$48:$I$3038,"Repeat account") -> 44599 | R5: =SUMIFS(R$48:R$3038,$I$48:$I$3038,"Repeat account") -> 45859 | ... X5: =SUMIFS(X$48:X$3038,$I$48:$I$3038,"Repeat account") -> 176457 | Y5: =X5-W5 -> 18648
B6: lending | D6: all | G6: =B6&"_"&C6&"_"&D6&"_"&E6&"_"&F6 -> lending__all__ | I6: Accumulated account | J6: =W6 -> 596972 | K6: =SUMIFS(K$48:K$3038,$I$48:$I$3038,"Accumulated account") -> 263026 | L6: =SUMIFS(L$48:L$3038,$I$48:$I$3038,"Accumulated account") -> 289241 | M6: =SUMIFS(M$48:M$3038,$I$48:$I$3038,"Accumulated account") -> 293226 | N6: =SUMIFS(N$48:N$3038,$I$48:$I$3038,"Accumulated account") -> 286953 | O6: =SUMIFS(O$48:O$3038,$I$48:$I$3038,"Accumulated account") -> 302253 | P6: =SUMIFS(P$48:P$3038,$I$48:$I$3038,"Accumulated account") -> 315835 | Q6: =SUMIFS(Q$48:Q$3038,$I$48:$I$3038,"Accumulated account") -> 335201 | R6: =SUMIFS(R$48:R$3038,$I$48:$I$3038,"Accumulated account") -> 346940 | ... X6: =SUMIFS(X$48:X$3038,$I$48:$I$3038,"Accumulated account") -> 641252 | Y6: =X6-W6 -> 44280
B7: lending | D7: all | G7: =B7&"_"&C7&"_"&D7&"_"&E7&"_"&F7 -> lending__all__ | I7: Disbursement | J7: =SUM(M7:X7) -> 14621515936862 | K7: =SUMIFS(K$48:K$3038,$I$48:$I$3038,"Disbursement") -> 565385177155 | L7: =SUMIFS(L$48:L$3038,$I$48:$I$3038,"Disbursement") -> 648539970448 | M7: =SUMIFS(M$48:M$3038,$I$48:$I$3038,"Disbursement") -> 607486373275 | N7: =SUMIFS(N$48:N$3038,$I$48:$I$3038,"Disbursement") -> 495446382206 | O7: =SUMIFS(O$48:O$3038,$I$48:$I$3038,"Disbursement") -> 683532749818 | P7: =SUMIFS(P$48:P$3038,$I$48:$I$3038,"Disbursement") -> 798190174129 | Q7: =SUMIFS(Q$48:Q$3038,$I$48:$I$3038,"Disbursement") -> 840951063659 | R7: =SUMIFS(R$48:R$3038,$I$48:$I$3038,"Disbursement") -> 923959113319 | ... X7: =SUMIFS(X$48:X$3038,$I$48:$I$3038,"Disbursement") -> 2134949493401 | Y7: =X7-W7 -> 155850768634
B8: lending | D8: all | G8: =B8&"_"&C8&"_"&D8&"_"&E8&"_"&F8 -> lending__all__ | I8: Disbursement w insurance | K8: =SUMIFS(K$48:K$3038,$I$48:$I$3038,"Disbursement w insurance") -> 415183060000 | L8: =SUMIFS(L$48:L$3038,$I$48:$I$3038,"Disbursement w insurance") -> 482160430000 | M8: =SUMIFS(M$48:M$3038,$I$48:$I$3038,"Disbursement w insurance") -> 444116950000 | N8: =SUMIFS(N$48:N$3038,$I$48:$I$3038,"Disbursement w insurance") -> 350181210000 | O8: =SUMIFS(O$48:O$3038,$I$48:$I$3038,"Disbursement w insurance") -> 496968420000 | P8: =SUMIFS(P$48:P$3038,$I$48:$I$3038,"Disbursement w insurance") -> 588092938000 | Q8: =SUMIFS(Q$48:Q$3038,$I$48:$I$3038,"Disbursement w insurance") -> 593910462000 | R8: =SUMIFS(R$48:R$3038,$I$48:$I$3038,"Disbursement w insurance") -> 669560212000 | ... X8: =SUMIFS(X$48:X$3038,$I$48:$I$3038,"Disbursement w insurance") -> 1785933196000 | Y8: =X8-W8 -> 130786320000
B9: lending | D9: all | G9: =B9&"_"&C9&"_"&D9&"_"&E9&"_"&F9 -> lending__all__ | I9: Disbursement w/o insurance | K9: =SUMIFS(K$48:K$3038,$I$48:$I$3038,"Disbursement w/o insurance") -> 44524560000 | L9: =SUMIFS(L$48:L$3038,$I$48:$I$3038,"Disbursement w/o insurance") -> 52877400000 | M9: =SUMIFS(M$48:M$3038,$I$48:$I$3038,"Disbursement w/o insurance") -> 54308000000 | N9: =SUMIFS(N$48:N$3038,$I$48:$I$3038,"Disbursement w/o insurance") -> 50012000000 | O9: =SUMIFS(O$48:O$3038,$I$48:$I$3038,"Disbursement w/o insurance") -> 74491000000 | P9: =SUMIFS(P$48:P$3038,$I$48:$I$3038,"Disbursement w/o insurance") -> 95609900000 | Q9: =SUMIFS(Q$48:Q$3038,$I$48:$I$3038,"Disbursement w/o insurance") -> 127503000000 | R9: =SUMIFS(R$48:R$3038,$I$48:$I$3038,"Disbursement w/o insurance") -> 135639400000 | ... X9: =SUMIFS(X$48:X$3038,$I$48:$I$3038,"Disbursement w/o insurance") -> 278008000000 | Y9: =X9-W9 -> 27131000000
B10: lending | D10: all | G10: =B10&"_"&C10&"_"&D10&"_"&E10&"_"&F10 -> lending__all__ | I10: Balance ENR | J10: =V10 -> 5341105587162 | K10: =SUMIFS(K$48:K$3038,$I$48:$I$3038,"Balance ENR") -> 2052438476066 | L10: =SUMIFS(L$48:L$3038,$I$48:$I$3038,"Balance ENR") -> 2208691233824 | M10: =SUMIFS(M$48:M$3038,$I$48:$I$3038,"Balance ENR") -> 2353465097862 | N10: =SUMIFS(N$48:N$3038,$I$48:$I$3038,"Balance ENR") -> 2269348501981 | O10: =SUMIFS(O$48:O$3038,$I$48:$I$3038,"Balance ENR") -> 2381914281455 | P10: =SUMIFS(P$48:P$3038,$I$48:$I$3038,"Balance ENR") -> 2586626572528 | Q10: =SUMIFS(Q$48:Q$3038,$I$48:$I$3038,"Balance ENR") -> 2809564235670 | R10: =SUMIFS(R$48:R$3038,$I$48:$I$3038,"Balance ENR") -> 3047094181089 | ... X10: =SUMIFS(X$48:X$3038,$I$48:$I$3038,"Balance ENR") -> 6617059046336 | Y10: =X10-W10 -> 627698525984
B11: lending | D11: all | G11: =B11&"_"&C11&"_"&D11&"_"&E11&"_"&F11 -> lending__all__ | I11: Indue balance | K11: =SUMIFS(K$48:K$3038,$I$48:$I$3038,"Indue balance") -> 1861677245641 | L11: =SUMIFS(L$48:L$3038,$I$48:$I$3038,"Indue balance") -> 2017439375775 | M11: =SUMIFS(M$48:M$3038,$I$48:$I$3038,"Indue balance") -> 2146462749230 | N11: =SUMIFS(N$48:N$3038,$I$48:$I$3038,"Indue balance") -> 2109310363676 | O11: =SUMIFS(O$48:O$3038,$I$48:$I$3038,"Indue balance") -> 2212171474295 | P11: =SUMIFS(P$48:P$3038,$I$48:$I$3038,"Indue balance") -> 2407668341994 | Q11: =SUMIFS(Q$48:Q$3038,$I$48:$I$3038,"Indue balance") -> 2623647731424 | R11: =SUMIFS(R$48:R$3038,$I$48:$I$3038,"Indue balance") -> 2862461599102 | ... X11: =SUMIFS(X$48:X$3038,$I$48:$I$3038,"Indue balance") -> 6319462955843 | Y11: =X11-W11 -> 607432583519
B12: lending | D12: all | G12: =B12&"_"&C12&"_"&D12&"_"&E12&"_"&F12 -> lending__all__ | I12: Overdue balance (dpd >0) | K12: =SUMIFS(K$48:K$3038,$I$48:$I$3038,"Overdue balance (dpd >0)") -> 190761230425 | L12: =SUMIFS(L$48:L$3038,$I$48:$I$3038,"Overdue balance (dpd >0)") -> 191251858049 | M12: =SUMIFS(M$48:M$3038,$I$48:$I$3038,"Overdue balance (dpd >0)") -> 207002348632 | N12: =SUMIFS(N$48:N$3038,$I$48:$I$3038,"Overdue balance (dpd >0)") -> 160038138305 | O12: =SUMIFS(O$48:O$3038,$I$48:$I$3038,"Overdue balance (dpd >0)") -> 169742807160 | P12: =SUMIFS(P$48:P$3038,$I$48:$I$3038,"Overdue balance (dpd >0)") -> 178958230534 | Q12: =SUMIFS(Q$48:Q$3038,$I$48:$I$3038,"Overdue balance (dpd >0)") -> 185916504246 | R12: =SUMIFS(R$48:R$3038,$I$48:$I$3038,"Overdue balance (dpd >0)") -> 184632581987 | ... X12: =SUMIFS(X$48:X$3038,$I$48:$I$3038,"Overdue balance (dpd >0)") -> 297596090493 | Y12: =X12-W12 -> 20265942465
B13: lending | D13: all | G13: =B13&"_"&C13&"_"&D13&"_"&E13&"_"&F13 -> lending__all__ | I13: Overdue balance (90d+)- CAKE | K13: =SUMIFS(K$48:K$3038,$I$48:$I$3038,"Overdue balance (90d+)- CAKE") -> 209084219244 | L13: =SUMIFS(L$48:L$3038,$I$48:$I$3038,"Overdue balance (90d+)- CAKE") -> 218890134025 | M13: =SUMIFS(M$48:M$3038,$I$48:$I$3038,"Overdue balance (90d+)- CAKE") -> 251298767400 | N13: =SUMIFS(N$48:N$3038,$I$48:$I$3038,"Overdue balance (90d+)- CAKE") -> 189681407635 | O13: =SUMIFS(O$48:O$3038,$I$48:$I$3038,"Overdue balance (90d+)- CAKE") -> 197886173133 | P13: =SUMIFS(P$48:P$3038,$I$48:$I$3038,"Overdue balance (90d+)- CAKE") -> 205873544624 | Q13: =SUMIFS(Q$48:Q$3038,$I$48:$I$3038,"Overdue balance (90d+)- CAKE") -> 223901043135 | R13: =SUMIFS(R$48:R$3038,$I$48:$I$3038,"Overdue balance (90d+)- CAKE") -> 210075662340 | ... X13: =SUMIFS(X$48:X$3038,$I$48:$I$3038,"Overdue balance (90d+)- CAKE") -> 246201433440 | Y13: =X13-W13 -> 10263474907
B14: lending | D14: all | G14: =B14&"_"&C14&"_"&D14&"_"&E14&"_"&F14 -> lending__all__ | I14: Overdue balance (10d+) | K14: =SUMIFS(K$48:K$3038,$I$48:$I$3038,"Overdue balance (10d+)") -> 425943553591 | L14: =SUMIFS(L$48:L$3038,$I$48:$I$3038,"Overdue balance (10d+)") -> 470976426376 | M14: =SUMIFS(M$48:M$3038,$I$48:$I$3038,"Overdue balance (10d+)") -> 495636150490 | N14: =SUMIFS(N$48:N$3038,$I$48:$I$3038,"Overdue balance (10d+)") -> 446334022206 | O14: =SUMIFS(O$48:O$3038,$I$48:$I$3038,"Overdue balance (10d+)") -> 482513889165 | P14: =SUMIFS(P$48:P$3038,$I$48:$I$3038,"Overdue balance (10d+)") -> 467190144812 | Q14: =SUMIFS(Q$48:Q$3038,$I$48:$I$3038,"Overdue balance (10d+)") -> 488876105575 | R14: =SUMIFS(R$48:R$3038,$I$48:$I$3038,"Overdue balance (10d+)") -> 535617603799 | ... X14: =SUMIFS(X$48:X$3038,$I$48:$I$3038,"Overdue balance (10d+)") -> 0 | Y14: =X14-W14 -> -882816124425
B15: lending | D15: all | G15: =B15&"_"&C15&"_"&D15&"_"&E15&"_"&F15 -> lending__all__ | I15: Overdue balance (90+) | K15: =SUMIFS(K$48:K$3038,$I$48:$I$3038,"Overdue balance (90+)") -> 229333356425 | L15: =SUMIFS(L$48:L$3038,$I$48:$I$3038,"Overdue balance (90+)") -> 246335530146 | M15: =SUMIFS(M$48:M$3038,$I$48:$I$3038,"Overdue balance (90+)") -> 273128559163 | N15: =SUMIFS(N$48:N$3038,$I$48:$I$3038,"Overdue balance (90+)") -> 216556182793 | O15: =SUMIFS(O$48:O$3038,$I$48:$I$3038,"Overdue balance (90+)") -> 241525121033 | P15: =SUMIFS(P$48:P$3038,$I$48:$I$3038,"Overdue balance (90+)") -> 239203735205 | Q15: =SUMIFS(Q$48:Q$3038,$I$48:$I$3038,"Overdue balance (90+)") -> 257266404757 | R15: =SUMIFS(R$48:R$3038,$I$48:$I$3038,"Overdue balance (90+)") -> 264987269863 | ... X15: =SUMIFS(X$48:X$3038,$I$48:$I$3038,"Overdue balance (90+)") -> 0 | Y15: =X15-W15 -> -288216101887
B16: lending | D16: all | G16: =B16&"_"&C16&"_"&D16&"_"&E16&"_"&F16 -> lending__all__ | I16: Overdue balance (11-90d) | K16: =SUMIFS(K$48:K$3038,$I$48:$I$3038,"Overdue balance (11-90d)") -> 196610197166 | L16: =SUMIFS(L$48:L$3038,$I$48:$I$3038,"Overdue balance (11-90d)") -> 224392444824 | M16: =SUMIFS(M$48:M$3038,$I$48:$I$3038,"Overdue balance (11-90d)") -> 222507591327 | N16: =SUMIFS(N$48:N$3038,$I$48:$I$3038,"Overdue balance (11-90d)") -> 229777839413 | O16: =SUMIFS(O$48:O$3038,$I$48:$I$3038,"Overdue balance (11-90d)") -> 240988768132 | P16: =SUMIFS(P$48:P$3038,$I$48:$I$3038,"Overdue balance (11-90d)") -> 227986409607 | Q16: =SUMIFS(Q$48:Q$3038,$I$48:$I$3038,"Overdue balance (11-90d)") -> 231609700818 | R16: =SUMIFS(R$48:R$3038,$I$48:$I$3038,"Overdue balance (11-90d)") -> 270630333936 | ... X16: =SUMIFS(X$48:X$3038,$I$48:$I$3038,"Overdue balance (11-90d)") -> 0 | Y16: =X16-W16 -> -593736182398
B17: lending | D17: all | G17: =B17&"_"&C17&"_"&D17&"_"&E17&"_"&F17 -> lending__all__ | I17: %NPL CAKE | K17: =K13/K10 -> 0.10187113 | L17: =L13/L10 -> 0.099103999 | M17: =M13/M10 -> 0.1067782 | N17: =N13/N10 -> 0.08358408 | O17: =O13/O10 -> 0.083078629 | P17: =P13/P10 -> 0.079591522 | Q17: =Q13/Q10 -> 0.079692445 | R17: =R13/R10 -> 0.06894295 | ... X17: =X13/X10 -> 0.037207078 | Y17: =X17-W17 -> -0.0021857681
B18: lending | D18: all | F18: npl | G18: =B18&"_"&C18&"_"&D18&"_"&E18&"_"&F18 -> lending__all__npl | I18: %NPL CIC | K18: =K15/K10 -> 0.11173702 | L18: =L15/L10 -> 0.11153009 | M18: =M15/M10 -> 0.1160538 | N18: =N15/N10 -> 0.095426587 | O18: =O15/O10 -> 0.10139959 | P18: =P15/P10 -> 0.092477104 | Q18: =Q15/Q10 -> 0.091568081 | R18: =R15/R10 -> 0.086963925 | ... X18: =X15/X10 -> 0 | Y18: =X18-W18 -> -0.048121348
B19: lending | D19: all | G19: =B19&"_"&C19&"_"&D19&"_"&E19&"_"&F19 -> lending__all__ | I19: TOI | J19: =J20+J25+J29 -> 2.1042215e+12 | K19: =K20+K25+K29 -> 79814464956 | L19: =L20+L25+L29 -> 9.0589203e+10 | M19: =M20+M25+M29 -> 93976364502 | N19: =N20+N25+N29 -> 83352868197 | O19: =O20+O25+O29 -> 1.0271915e+11 | P19: =P20+P25+P29 -> 111585837773 | Q19: =Q20+Q25+Q29 -> 120805173410 | ... X19: =X20+X25+X29 -> 320447530496 | Y19: =X19-W19 -> 36422964193
B20: lending | D20: all | G20: =B20&"_"&C20&"_"&D20&"_"&E20&"_"&F20 -> lending__all__ | I20: Net interest income | J20: =J21-J24 -> 1.2814118e+12 | K20: =K21-K24 -> 52213603901 | L20: =L21-L24 -> 58117593045 | M20: =M21-M24 -> 64177638510 | N20: =N21-N24 -> 58823369739 | O20: =O21-O24 -> 6.7391301e+10 | P20: =P21-P24 -> 71053250087 | Q20: =Q21-Q24 -> 79740766095 | ... X20: =X21-X24 -> 190414952434 | Y20: =X20-W20 -> 25163690176
B21: lending | D21: all | G21: =B21&"_"&C21&"_"&D21&"_"&E21&"_"&F21 -> lending__all__ | I21: Interest Income | J21: =SUM(M21:X21) -> 1525705629347 | K21: 62223552804 | L21: =L22+K23-L23 -> 69272878417 | M21: =M22+L23-M23 -> 76219395758 | N21: =N22+M23-N23 -> 69975903294 | O21: =O22+N23-O23 -> 79648572501 | P21: =P22+O23-P23 -> 83805884795 | Q21: =Q22+P23-Q23 -> 94103072191 | R21: =R22+Q23-R23 -> 100381074810 | S21: =S22+R23-S23 -> 118193939617 | ... X21: =X22+W23-X23 -> 229979382831 | Y21: =X21-W21 -> 31622681111
B22: lending | D22: all | G22: =B22&"_"&C22&"_"&D22&"_"&E22&"_"&F22 -> lending__all__ | I22: Thu lãi vay | J22: =SUM(M22:X22) -> 1539717162560 | K22: =SUMIFS(K$48:K$3038,$I$48:$I$3038,"Thu lãi vay") -> 63214223471 | L22: =SUMIFS(L$48:L$3038,$I$48:$I$3038,"Thu lãi vay") -> 70990475112 | M22: =SUMIFS(M$48:M$3038,$I$48:$I$3038,"Thu lãi vay") -> 76707556347 | N22: =SUMIFS(N$48:N$3038,$I$48:$I$3038,"Thu lãi vay") -> 69254610169 | O22: =SUMIFS(O$48:O$3038,$I$48:$I$3038,"Thu lãi vay") -> 79789204964 | P22: =SUMIFS(P$48:P$3038,$I$48:$I$3038,"Thu lãi vay") -> 84276037008 | Q22: =SUMIFS(Q$48:Q$3038,$I$48:$I$3038,"Thu lãi vay") -> 94567752275 | R22: =SUMIFS(R$48:R$3038,$I$48:$I$3038,"Thu lãi vay") -> 100878684667 | ... X22: =SUMIFS(X$48:X$3038,$I$48:$I$3038,"Thu lãi vay") -> 232297213106 | Y22: =X22-W22 -> 31297405614 | AA22: =W22-W23+V23 -> 198356701720
B23: lending | D23: all | G23: =B23&"_"&C23&"_"&D23&"_"&E23&"_"&F23 -> lending__all__ | I23: Thoái lãi | K23: =SUMIFS(K$48:K$3038,$I$48:$I$3038,"Thoái lãi") -> 7999287750 | L23: =SUMIFS(L$48:L$3038,$I$48:$I$3038,"Thoái lãi") -> 9716884445 | M23: =SUMIFS(M$48:M$3038,$I$48:$I$3038,"Thoái lãi") -> 10205045034 | N23: =SUMIFS(N$48:N$3038,$I$48:$I$3038,"Thoái lãi") -> 9483751909 | O23: =SUMIFS(O$48:O$3038,$I$48:$I$3038,"Thoái lãi") -> 9624384372 | P23: =SUMIFS(P$48:P$3038,$I$48:$I$3038,"Thoái lãi") -> 10094536585 | Q23: =SUMIFS(Q$48:Q$3038,$I$48:$I$3038,"Thoái lãi") -> 10559216669 | R23: =SUMIFS(R$48:R$3038,$I$48:$I$3038,"Thoái lãi") -> 11056826526 | ... X23: =SUMIFS(X$48:X$3038,$I$48:$I$3038,"Thoái lãi") -> 23728417658 | Y23: =X23-W23 -> 2317830275
B24: lending | D24: all | G24: =B24&"_"&C24&"_"&D24&"_"&E24&"_"&F24 -> lending__all__ | I24: COF | J24: =SUM(M24:X24) -> 2.4429386e+11 | K24: =SUMIFS(K$48:K$3038,$I$48:$I$3038,"COF") -> 10009948903 | L24: =SUMIFS(L$48:L$3038,$I$48:$I$3038,"COF") -> 11155285372 | M24: =SUMIFS(M$48:M$3038,$I$48:$I$3038,"COF") -> 12041757248 | N24: =SUMIFS(N$48:N$3038,$I$48:$I$3038,"COF") -> 11152533555 | O24: =SUMIFS(O$48:O$3038,$I$48:$I$3038,"COF") -> 1.2257271e+10 | P24: =SUMIFS(P$48:P$3038,$I$48:$I$3038,"COF") -> 12752634708 | Q24: =SUMIFS(Q$48:Q$3038,$I$48:$I$3038,"COF") -> 14362306096 | R24: =SUMIFS(R$48:R$3038,$I$48:$I$3038,"COF") -> 15239240769 | ... X24: =SUMIFS(X$48:X$3038,$I$48:$I$3038,"COF") -> 39564430397 | Y24: =X24-W24 -> 6458990935 | AA24: 1562245635
B25: lending | D25: all | G25: =B25&"_"&C25&"_"&D25&"_"&E25&"_"&F25 -> lending__all__ | I25: Net fee income | J25: =SUM(J26:J28) -> 803908966781 | K25: =SUM(K26:K28) -> 27583083979 | L25: =SUM(L26:L28) -> 3.2434754e+10 | M25: =SUM(M26:M28) -> 29756782715 | N25: =SUM(N26:N28) -> 24284197615 | O25: =SUM(O26:O28) -> 34259497297 | P25: =SUM(P26:P28) -> 39687689775 | Q25: =SUM(Q26:Q28) -> 39889216104 | ... X25: =SUM(X26:X28) -> 126910887822 | Y25: =X25-W25 -> 10509921230 | AA25: =AA24+W20 -> 166813507893
B26: lending | D26: all | G26: =B26&"_"&C26&"_"&D26&"_"&E26&"_"&F26 -> lending__all__ | I26: Insurance fee | J26: =SUM(M26:X26) -> 656687659991 | K26: =SUMIFS(K$48:K$3038,$I$48:$I$3038,"Insurance fee") -> 24710450873 | L26: =SUMIFS(L$48:L$3038,$I$48:$I$3038,"Insurance fee") -> 2.9076808e+10 | M26: =SUMIFS(M$48:M$3038,$I$48:$I$3038,"Insurance fee") -> 26590524165 | N26: =SUMIFS(N$48:N$3038,$I$48:$I$3038,"Insurance fee") -> 21215572578 | O26: =SUMIFS(O$48:O$3038,$I$48:$I$3038,"Insurance fee") -> 29713730593 | P26: =SUMIFS(P$48:P$3038,$I$48:$I$3038,"Insurance fee") -> 33878604810 | Q26: =SUMIFS(Q$48:Q$3038,$I$48:$I$3038,"Insurance fee") -> 34268836103 | R26: =SUMIFS(R$48:R$3038,$I$48:$I$3038,"Insurance fee") -> 38448492066 | ... X26: =SUMIFS(X$48:X$3038,$I$48:$I$3038,"Insurance fee") -> 100963671223 | Y26: =X26-W26 -> 7965801966
B27: lending | D27: all | G27: =B27&"_"&C27&"_"&D27&"_"&E27&"_"&F27 -> lending__all__ | I27: Early repayment fee | J27: =SUM(M27:X27) -> 143290856790 | K27: =SUMIFS(K$48:K$3038,$I$48:$I$3038,"Early repayment fee") -> 2422383106 | L27: =SUMIFS(L$48:L$3038,$I$48:$I$3038,"Early repayment fee") -> 2633346724 | M27: =SUMIFS(M$48:M$3038,$I$48:$I$3038,"Early repayment fee") -> 2585208550 | N27: =SUMIFS(N$48:N$3038,$I$48:$I$3038,"Early repayment fee") -> 2640825037 | O27: =SUMIFS(O$48:O$3038,$I$48:$I$3038,"Early repayment fee") -> 4033416704 | P27: =SUMIFS(P$48:P$3038,$I$48:$I$3038,"Early repayment fee") -> 5294534965 | Q27: =SUMIFS(Q$48:Q$3038,$I$48:$I$3038,"Early repayment fee") -> 5102530001 | R27: =SUMIFS(R$48:R$3038,$I$48:$I$3038,"Early repayment fee") -> 8503845964 | ... X27: =SUMIFS(X$48:X$3038,$I$48:$I$3038,"Early repayment fee") -> 25877266599 | Y27: =X27-W27 -> 2559269264
B28: lending | D28: all | G28: =B28&"_"&C28&"_"&D28&"_"&E28&"_"&F28 -> lending__all__ | I28: Limit fee | J28: =SUM(M28:X28) -> 3930450000 | K28: =SUMIFS(K$48:K$3038,$I$48:$I$3038,"Limit fee") -> 450250000 | L28: =SUMIFS(L$48:L$3038,$I$48:$I$3038,"Limit fee") -> 724600000 | M28: =SUMIFS(M$48:M$3038,$I$48:$I$3038,"Limit fee") -> 581050000 | N28: =SUMIFS(N$48:N$3038,$I$48:$I$3038,"Limit fee") -> 427800000 | O28: =SUMIFS(O$48:O$3038,$I$48:$I$3038,"Limit fee") -> 512350000 | P28: =SUMIFS(P$48:P$3038,$I$48:$I$3038,"Limit fee") -> 514550000 | Q28: =SUMIFS(Q$48:Q$3038,$I$48:$I$3038,"Limit fee") -> 517850000 | R28: =SUMIFS(R$48:R$3038,$I$48:$I$3038,"Limit fee") -> 527000000 | ... X28: =SUMIFS(X$48:X$3038,$I$48:$I$3038,"Limit fee") -> 69950000 | Y28: =X28-W28 -> -15150000 | AE28: T3 | AF28: 4 | AG28: 5 | AH28: 6
B29: lending | D29: all | G29: =B29&"_"&C29&"_"&D29&"_"&E29&"_"&F29 -> lending__all__ | I29: Other TOI | J29: =SUM(M29:X29) -> 18900766405 | K29: =SUMIFS(K$48:K$3038,$I$48:$I$3038,"Other TOI") -> 17777076 | L29: =SUMIFS(L$48:L$3038,$I$48:$I$3038,"Other TOI") -> 36855729 | M29: =SUMIFS(M$48:M$3038,$I$48:$I$3038,"Other TOI") -> 41943277 | N29: =SUMIFS(N$48:N$3038,$I$48:$I$3038,"Other TOI") -> 245300843 | O29: =SUMIFS(O$48:O$3038,$I$48:$I$3038,"Other TOI") -> 1068351047 | P29: =SUMIFS(P$48:P$3038,$I$48:$I$3038,"Other TOI") -> 844897911 | Q29: =SUMIFS(Q$48:Q$3038,$I$48:$I$3038,"Other TOI") -> 1175191211 | R29: =SUMIFS(R$48:R$3038,$I$48:$I$3038,"Other TOI") -> 1380588199 | ... X29: =SUMIFS(X$48:X$3038,$I$48:$I$3038,"Other TOI") -> 3121690240 | Y29: =X29-W29 -> 749352787
B30: lending | D30: all | G30: =B30&"_"&C30&"_"&D30&"_"&E30&"_"&F30 -> lending__all__ | I30: Provision expenses | J30: =SUM(M30:X30) -> 910112574484 | K30: =SUMIFS(K$48:K$3038,$I$48:$I$3038,"Provision expenses") -> 21518247295 | L30: =SUMIFS(L$48:L$3038,$I$48:$I$3038,"Provision expenses") -> 31138146416 | M30: =SUMIFS(M$48:M$3038,$I$48:$I$3038,"Provision expenses") -> 73619871731 | N30: =SUMIFS(N$48:N$3038,$I$48:$I$3038,"Provision expenses") -> 45681275021 | O30: =SUMIFS(O$48:O$3038,$I$48:$I$3038,"Provision expenses") -> 55722136445 | P30: =SUMIFS(P$48:P$3038,$I$48:$I$3038,"Provision expenses") -> 39812626019 | Q30: =SUMIFS(Q$48:Q$3038,$I$48:$I$3038,"Provision expenses") -> 62627976854 | R30: =SUMIFS(R$48:R$3038,$I$48:$I$3038,"Provision expenses") -> 62111404665 | ... X30: =SUMIFS(X$48:X$3038,$I$48:$I$3038,"Provision expenses") -> 139120336347 | Y30: =X30-W30 -> 22876470286 | AE30: =O33/(O19-PNL!$R30) -> 0.34888206 | AF30: =P33/(P19-PNL!$R30) -> 0.45399467 | AG30: =Q33/(Q19-PNL!$R30) -> 0.30569865 | AH30: =R33/(R19-PNL!$R30) -> 0.33858353
B31: lending | D31: all | G31: =B31&"_"&C31&"_"&D31&"_"&E31&"_"&F31 -> lending__all__ | I31: Variable expenses | J31: =SUM(J32:J39) -> 4.7548279e+11 | K31: =SUM(K32:K39) -> 2.0090911e+10 | L31: =SUM(L32:L39) -> 2.0567001e+10 | M31: =SUM(M32:M39) -> 1.9830158e+10 | N31: =SUM(N32:N39) -> 1.9592649e+10 | O31: =SUM(O32:O39) -> 2.0036374e+10 | P31: =SUM(P32:P39) -> 2.9249124e+10 | Q31: =SUM(Q32:Q39) -> 2.4248721e+10 | ... X31: =SUM(X32:X39) -> 6.7714843e+10 | Y31: =X31-W31 -> 4.2236889e+09
B32: lending | D32: all | G32: =B32&"_"&C32&"_"&D32&"_"&E32&"_"&F32 -> lending__all__ | I32: Marketing acquisition cost | J32: =SUM(M32:X32) -> 33561348302 | K32: =SUMIFS(K$48:K$3038,$I$48:$I$3038,"Marketing acquisition cost") -> 1057341055 | L32: =SUMIFS(L$48:L$3038,$I$48:$I$3038,"Marketing acquisition cost") -> 1358095141 | M32: =SUMIFS(M$48:M$3038,$I$48:$I$3038,"Marketing acquisition cost") -> 1181479170 | N32: =SUMIFS(N$48:N$3038,$I$48:$I$3038,"Marketing acquisition cost") -> 885757119 | O32: =SUMIFS(O$48:O$3038,$I$48:$I$3038,"Marketing acquisition cost") -> 1503077794 | P32: =SUMIFS(P$48:P$3038,$I$48:$I$3038,"Marketing acquisition cost") -> 2078254342 | Q32: =SUMIFS(Q$48:Q$3038,$I$48:$I$3038,"Marketing acquisition cost") -> 1414197238 | R32: =SUMIFS(R$48:R$3038,$I$48:$I$3038,"Marketing acquisition cost") -> 2978507515 | ... X32: =SUMIFS(X$48:X$3038,$I$48:$I$3038,"Marketing acquisition cost") -> 4458472607 | Y32: =X32-W32 -> 760056426 | AF32: =SUM(P33:R33)/(SUM(P19:R19)-SUM(P30:R30)) -> 0.32077081
B33: lending | D33: all | G33: =B33&"_"&C33&"_"&D33&"_"&E33&"_"&F33 -> lending__all__ | I33: Partner acquisition cost | J33: =SUM(M33:X33) -> 365824861719 | K33: =SUMIFS(K$48:K$3038,$I$48:$I$3038,"Partner acquisition cost") -> 15057180956 | L33: =SUMIFS(L$48:L$3038,$I$48:$I$3038,"Partner acquisition cost") -> 14005998385 | M33: =SUMIFS(M$48:M$3038,$I$48:$I$3038,"Partner acquisition cost") -> 13808398735 | N33: =SUMIFS(N$48:N$3038,$I$48:$I$3038,"Partner acquisition cost") -> 13830372027 | O33: =SUMIFS(O$48:O$3038,$I$48:$I$3038,"Partner acquisition cost") -> 14167313884 | P33: =SUMIFS(P$48:P$3038,$I$48:$I$3038,"Partner acquisition cost") -> 22461128822 | Q33: =SUMIFS(Q$48:Q$3038,$I$48:$I$3038,"Partner acquisition cost") -> 17942605735 | R33: =SUMIFS(R$48:R$3038,$I$48:$I$3038,"Partner acquisition cost") -> 24340890312 | ... X33: =SUMIFS(X$48:X$3038,$I$48:$I$3038,"Partner acquisition cost") -> 53410055880 | Y33: =X33-W33 -> 2731194887
B34: lending | D34: all | G34: =B34&"_"&C34&"_"&D34&"_"&E34&"_"&F34 -> lending__all__ | I34: Underwritting | J34: =SUM(M34:X34) -> 48625010811 | K34: =SUMIFS(K$48:K$3038,$I$48:$I$3038,"Underwritting") -> 2.3518551e+09 | L34: =SUMIFS(L$48:L$3038,$I$48:$I$3038,"Underwritting") -> 3.0051226e+09 | M34: =SUMIFS(M$48:M$3038,$I$48:$I$3038,"Underwritting") -> 2481935995 | N34: =SUMIFS(N$48:N$3038,$I$48:$I$3038,"Underwritting") -> 1864713205 | O34: =SUMIFS(O$48:O$3038,$I$48:$I$3038,"Underwritting") -> 2200530610 | P34: =SUMIFS(P$48:P$3038,$I$48:$I$3038,"Underwritting") -> 2327024294 | Q34: =SUMIFS(Q$48:Q$3038,$I$48:$I$3038,"Underwritting") -> 2381411929 | R34: =SUMIFS(R$48:R$3038,$I$48:$I$3038,"Underwritting") -> 2.7435755e+09 | ... X34: =SUMIFS(X$48:X$3038,$I$48:$I$3038,"Underwritting") -> 6.9355259e+09 | Y34: =X34-W34 -> 7.6363578e+08 | AE34: =SUM(M33:Q33)/(SUM(M19:Q19)-SUM(M30:Q30)) -> 0.34986548
B35: lending | D35: all | G35: =B35&"_"&C35&"_"&D35&"_"&E35&"_"&F35 -> lending__all__ | I35: E Contract | J35: =SUM(M35:X35) -> 1519628255 | K35: =SUMIFS(K$48:K$3038,$I$48:$I$3038,"E Contract") -> 53857518 | L35: =SUMIFS(L$48:L$3038,$I$48:$I$3038,"E Contract") -> 65273472 | M35: =SUMIFS(M$48:M$3038,$I$48:$I$3038,"E Contract") -> 56495896 | N35: =SUMIFS(N$48:N$3038,$I$48:$I$3038,"E Contract") -> 49048615 | O35: =SUMIFS(O$48:O$3038,$I$48:$I$3038,"E Contract") -> 67832022 | P35: =SUMIFS(P$48:P$3038,$I$48:$I$3038,"E Contract") -> 175886615 | Q35: =SUMIFS(Q$48:Q$3038,$I$48:$I$3038,"E Contract") -> 68122992 | R35: =SUMIFS(R$48:R$3038,$I$48:$I$3038,"E Contract") -> 72317391 | ... X35: =SUMIFS(X$48:X$3038,$I$48:$I$3038,"E Contract") -> 213824235 | Y35: =X35-W35 -> 24215944 | AE35: =SUM(O33:Q33)/(SUM(O19:Q19)-SUM(O30:Q30)) -> 0.30840262
B36: lending | D36: all | G36: =B36&"_"&C36&"_"&D36&"_"&E36&"_"&F36 -> lending__all__ | I36: NFC | J36: =SUM(M36:X36) -> 1.8790432e+09 | K36: =SUMIFS(K$48:K$3038,$I$48:$I$3038,"NFC") -> 0 | L36: =SUMIFS(L$48:L$3038,$I$48:$I$3038,"NFC") -> 0 | M36: =SUMIFS(M$48:M$3038,$I$48:$I$3038,"NFC") -> 169563600 | N36: =SUMIFS(N$48:N$3038,$I$48:$I$3038,"NFC") -> 106067025 | O36: =SUMIFS(O$48:O$3038,$I$48:$I$3038,"NFC") -> 1.5749527e+08 | P36: =SUMIFS(P$48:P$3038,$I$48:$I$3038,"NFC") -> 130956075 | Q36: =SUMIFS(Q$48:Q$3038,$I$48:$I$3038,"NFC") -> 1.311741e+08 | R36: =SUMIFS(R$48:R$3038,$I$48:$I$3038,"NFC") -> 142207875 | ... X36: =SUMIFS(X$48:X$3038,$I$48:$I$3038,"NFC") -> 2.2355044e+08 | Y36: =X36-W36 -> 48698663
B37: lending | D37: all | G37: =B37&"_"&C37&"_"&D37&"_"&E37&"_"&F37 -> lending__all__ | I37: Collection | J37: =SUM(M37:X37) -> 2.1745285e+10 | K37: =SUMIFS(K$48:K$3038,$I$48:$I$3038,"Collection") -> 1.519396e+09 | L37: =SUMIFS(L$48:L$3038,$I$48:$I$3038,"Collection") -> 2.0116083e+09 | M37: =SUMIFS(M$48:M$3038,$I$48:$I$3038,"Collection") -> 1.9697249e+09 | N37: =SUMIFS(N$48:N$3038,$I$48:$I$3038,"Collection") -> 2.7642571e+09 | O37: =SUMIFS(O$48:O$3038,$I$48:$I$3038,"Collection") -> 1.8174388e+09 | P37: =SUMIFS(P$48:P$3038,$I$48:$I$3038,"Collection") -> 1.8878663e+09 | Q37: =SUMIFS(Q$48:Q$3038,$I$48:$I$3038,"Collection") -> 2.1552092e+09 | R37: =SUMIFS(R$48:R$3038,$I$48:$I$3038,"Collection") -> 7.98981e+08 | ... X37: =SUMIFS(X$48:X$3038,$I$48:$I$3038,"Collection") -> 2.1716428e+09 | Y37: =X37-W37 -> -1.1192268e+08
B38: lending | D38: all | G38: =B38&"_"&C38&"_"&D38&"_"&E38&"_"&F38 -> lending__all__ | I38: Promotion | K38: =SUMIFS(K$48:K$3038,$I$48:$I$3038,"Promotion") -> 0 | L38: =SUMIFS(L$48:L$3038,$I$48:$I$3038,"Promotion") -> 0 | M38: =SUMIFS(M$48:M$3038,$I$48:$I$3038,"Promotion") -> 0 | N38: =SUMIFS(N$48:N$3038,$I$48:$I$3038,"Promotion") -> 0 | O38: =SUMIFS(O$48:O$3038,$I$48:$I$3038,"Promotion") -> 0 | P38: =SUMIFS(P$48:P$3038,$I$48:$I$3038,"Promotion") -> 0 | Q38: =SUMIFS(Q$48:Q$3038,$I$48:$I$3038,"Promotion") -> 0 | R38: =SUMIFS(R$48:R$3038,$I$48:$I$3038,"Promotion") -> 0 | ... X38: =SUMIFS(X$48:X$3038,$I$48:$I$3038,"Promotion") -> 0 | Y38: =X38-W38 -> 0
B39: lending | D39: all | G39: =B39&"_"&C39&"_"&D39&"_"&E39&"_"&F39 -> lending__all__ | I39: SMS | J39: =SUM(M39:X39) -> 2.3276164e+09 | K39: =SUMIFS(K$48:K$3038,$I$48:$I$3038,"SMS") -> 51280493 | L39: =SUMIFS(L$48:L$3038,$I$48:$I$3038,"SMS") -> 1.2090274e+08 | M39: =SUMIFS(M$48:M$3038,$I$48:$I$3038,"SMS") -> 1.6255954e+08 | N39: =SUMIFS(N$48:N$3038,$I$48:$I$3038,"SMS") -> 92434059 | O39: =SUMIFS(O$48:O$3038,$I$48:$I$3038,"SMS") -> 1.2268585e+08 | P39: =SUMIFS(P$48:P$3038,$I$48:$I$3038,"SMS") -> 1.8800768e+08 | Q39: =SUMIFS(Q$48:Q$3038,$I$48:$I$3038,"SMS") -> 1.5599935e+08 | R39: =SUMIFS(R$48:R$3038,$I$48:$I$3038,"SMS") -> 1.4185615e+08 | ... X39: =SUMIFS(X$48:X$3038,$I$48:$I$3038,"SMS") -> 3.0177097e+08 | Y39: =X39-W39 -> 7809869.7
B40: lending | D40: all | F40: overhead_cost | G40: =B40&"_"&C40&"_"&D40&"_"&E40&"_"&F40 -> lending__all__overhead_cost | I40: Overhead expenses | J40: =J41+J42+J43+J44 -> 2.5119714e+11 | K40: =SUM(K41:K44) -> 13411705149 | L40: =SUM(L41:L44) -> 3.4364414e+10 | M40: =SUM(M41:M44) -> 1.6575132e+10 | N40: =SUM(N41:N44) -> 1.6692886e+10 | O40: =SUM(O41:O44) -> 1.5924716e+10 | P40: =SUM(P41:P44) -> 1.8131155e+10 | Q40: =SUM(Q41:Q44) -> 1.6327544e+10 | R40: =SUM(R41:R44) -> 1.8135932e+10 | ... X40: =SUM(X41:X44) -> 5.555639e+09 | Y40: =X40-W40 -> -1.5682497e+10
...

Sheet Early repayment
M6: VNPOST
M29: CAKE
M51: VDS
L73: MWG
L95: Zalopay
L117: VNPAY
D144: MOB1-3 | R144: MOB4-end
B145: RATE
D146: 1 | E146: 2 | F146: =E146+1 -> 3 | G146: =F146+1 -> 4 | H146: =G146+1 -> 5 | I146: =H146+1 -> 6 | J146: =I146+1 -> 7 | K146: =J146+1 -> 8 | L146: =K146+1 -> 9 | M146: =L146+1 -> 10 | ... O146: =N146+1 -> 12 | T146: 1 | U146: 2 | V146: =U146+1 -> 3 | W146: =V146+1 -> 4 | X146: =W146+1 -> 5 | Y146: =X146+1 -> 6 | Z146: =Y146+1 -> 7 | AA146: =Z146+1 -> 8 | AB146: =AA146+1 -> 9 | AC146: =AB146+1 -> 10 | ... AE146: =AD146+1 -> 12
B147: CL | C147: VDS | D147: 0.03 | E147: 0.03 | F147: 0.03 | G147: 0.03 | H147: 0.03 | I147: 0.03 | J147: 0.03 | K147: 0.08 | L147: 0.08 | M147: 0.08 | N147: 0.08 | O147: 0.08 | R147: CL | S147: VDS | T147: 0.03 | U147: 0.03 | V147: 0.03 | W147: 0.03 | X147: 0.03 | Y147: 0.03 | Z147: 0.03 | AA147: 0.05 | AB147: 0.05 | AC147: 0.05 | AD147: 0.05 | AE147: 0.05
B148: CL | C148: VDS | D148: 0.03 | E148: 0.03 | F148: 0.03 | G148: 0.03 | H148: 0.03 | I148: 0.03 | J148: 0.03 | K148: 0.08 | L148: 0.08 | M148: 0.08 | N148: 0.08 | O148: 0.08 | R148: CL | S148: VDS | T148: 0.03 | U148: 0.03 | V148: 0.03 | W148: 0.03 | X148: 0.03 | Y148: 0.03 | Z148: 0.03 | AA148: 0.05 | AB148: 0.05 | AC148: 0.05 | AD148: 0.05 | AE148: 0.05
B149: CL | C149: CAKE | D149: 0.03 | E149: 0.03 | F149: 0.03 | G149: 0.05 | H149: 0.05 | I149: 0.05 | J149: 0.05 | K149: 0.08 | L149: 0.08 | M149: 0.08 | N149: 0.08 | O149: 0.08 | R149: CL | S149: CAKE | T149: 0.03 | U149: 0.03 | V149: 0.03 | W149: 0.05 | X149: 0.05 | Y149: 0.05 | Z149: 0.05 | AA149: 0.05 | AB149: 0.05 | AC149: 0.05 | AD149: 0.05 | AE149: 0.05
B150: CL | C150: MWG | D150: 0.03 | E150: 0.03 | F150: 0.03 | G150: 0.03 | H150: 0.03 | I150: 0.03 | J150: 0.03 | K150: 0.08 | L150: 0.08 | M150: 0.08 | N150: 0.08 | O150: 0.08 | R150: CL | S150: MWG | T150: 0.03 | U150: 0.03 | V150: 0.03 | W150: 0.03 | X150: 0.03 | Y150: 0.03 | Z150: 0.03 | AA150: 0.08 | AB150: 0.08 | AC150: 0.08 | AD150: 0.08 | AE150: 0.08
B151: CL | C151: VNPAY | D151: 0.03 | E151: 0.03 | F151: 0.03 | G151: 0.03 | H151: 0.03 | I151: 0.03 | J151: 0.03 | K151: 0.08 | L151: 0.08 | M151: 0.08 | N151: 0.08 | O151: 0.08 | R151: CL | S151: VNPAY | T151: 0.03 | U151: 0.03 | V151: 0.03 | W151: 0.03 | X151: 0.03 | Y151: 0.03 | Z151: 0.03 | AA151: 0.08 | AB151: 0.08 | AC151: 0.08 | AD151: 0.08 | AE151: 0.08
B152: CL | C152: ZaloPAY | D152: 0.03 | E152: 0.03 | F152: 0.03 | G152: 0.03 | H152: 0.03 | I152: 0.03 | J152: 0.03 | K152: 0.03 | L152: 0.03 | M152: 0.03 | N152: 0.03 | O152: 0.03 | R152: CL | S152: ZaloPAY | T152: 0.03 | U152: 0.03 | V152: 0.03 | W152: 0.03 | X152: 0.03 | Y152: 0.03 | Z152: 0.03 | AA152: 0.03 | AB152: 0.03 | AC152: 0.03 | AD152: 0.03 | AE152: 0.03
B153: CL | C153: VNPOST | D153: 0.03 | E153: 0.03 | F153: 0.03 | G153: 0.03 | H153: 0.03 | I153: 0.03 | J153: 0.03 | K153: 0.03 | L153: 0.03 | M153: 0.03 | N153: 0.03 | O153: 0.03 | R153: CL | S153: VNPOST | T153: 0.03 | U153: 0.03 | V153: 0.03 | W153: 0.03 | X153: 0.03 | Y153: 0.03 | Z153: 0.03 | AA153: 0.03 | AB153: 0.03 | AC153: 0.03 | AD153: 0.03 | AE153: 0.03
C157: Disburse | D157: 1 | E157: 2 | F157: =E157+1 -> 3 | G157: =F157+1 -> 4 | H157: =G157+1 -> 5 | I157: =H157+1 -> 6 | J157: =I157+1 -> 7 | K157: =J157+1 -> 8 | L157: =K157+1 -> 9 | M157: =L157+1 -> 10 | N157: 11 | O157: 12
B158: CL | C158: VDS | D158: =DATA!#REF! -> #REF! | E158: =DATA!#REF! -> #REF! | F158: =DATA!#REF! -> #REF! | G158: =DATA!#REF! -> #REF! | H158: =DATA!#REF! -> #REF! | I158: =DATA!#REF! -> #REF! | J158: =DATA!#REF! -> #REF! | K158: =DATA!#REF! -> #REF! | ... M158: =DATA!#REF! -> #REF! | N158: 513252480000 | O158: 548081580000
B159: CL | C159: VDS | D159: =DATA!#REF! -> #REF! | E159: =DATA!#REF! -> #REF! | F159: =DATA!#REF! -> #REF! | G159: =DATA!#REF! -> #REF! | H159: =DATA!#REF! -> #REF! | I159: =DATA!#REF! -> #REF! | J159: =DATA!#REF! -> #REF! | K159: =DATA!#REF! -> #REF! | ... M159: =DATA!#REF! -> #REF! | N159: 746250000 | O159: 593750000
B160: CL | C160: CAKE | D160: =DATA!#REF! -> #REF! | E160: =DATA!#REF! -> #REF! | F160: =DATA!#REF! -> #REF! | G160: =DATA!#REF! -> #REF! | H160: =DATA!#REF! -> #REF! | I160: =DATA!#REF! -> #REF! | J160: =DATA!#REF! -> #REF! | K160: =DATA!#REF! -> #REF! | ... M160: =DATA!#REF! -> #REF! | N160: 587879520000 | O160: 522091590000
B161: CL | C161: MWG | D161: =DATA!#REF! -> #REF! | E161: =DATA!#REF! -> #REF! | F161: =DATA!#REF! -> #REF! | G161: =DATA!#REF! -> #REF! | H161: =DATA!#REF! -> #REF! | I161: =DATA!#REF! -> #REF! | J161: =DATA!#REF! -> #REF! | K161: =DATA!#REF! -> #REF! | ... M161: =DATA!#REF! -> #REF! | N161: 100217490000 | O161: 126953670000
B162: CL | C162: VNPAY | D162: =DATA!#REF! -> #REF! | E162: =DATA!#REF! -> #REF! | F162: =DATA!#REF! -> #REF! | G162: =DATA!#REF! -> #REF! | H162: =DATA!#REF! -> #REF! | I162: =DATA!#REF! -> #REF! | J162: =DATA!#REF! -> #REF! | K162: =DATA!#REF! -> #REF! | ... M162: =DATA!#REF! -> #REF! | N162: 19620350000 | O162: 21697550000
B163: CL | C163: ZaloPAY | D163: =DATA!#REF! -> #REF! | E163: =DATA!#REF! -> #REF! | F163: =DATA!#REF! -> #REF! | G163: =DATA!#REF! -> #REF! | H163: =DATA!#REF! -> #REF! | I163: =DATA!#REF! -> #REF! | J163: =DATA!#REF! -> #REF! | K163: =DATA!#REF! -> #REF! | ... M163: =DATA!#REF! -> #REF! | N163: 98531400000 | O163: 117580890000
B164: CL | C164: VNPOST | D164: =DATA!#REF! -> #REF! | E164: =DATA!#REF! -> #REF! | F164: =DATA!#REF! -> #REF! | G164: =DATA!#REF! -> #REF! | H164: =DATA!#REF! -> #REF! | I164: =DATA!#REF! -> #REF! | J164: =DATA!#REF! -> #REF! | K164: =DATA!#REF! -> #REF! | ... M164: =DATA!#REF! -> #REF! | N164: 10022250000 | O164: 17538450000
C167: Balance
C168: VDS | D168: 1147479030231 | E168: 1059836524693 | F168: 1075941072798 | G168: 1136717782140 | H168: 1178814582203 | I168: 1219457237377 | J168: 1378305772338 | K168: 1490245196812 | L168: 1689128717794 | M168: 1873560534525 | N168: 2072466106173 | O168: 2269684868394
C169: VDS | D169: 9787251521 | E169: 9283199996 | F169: 9564466715 | G169: 9405286904 | H169: 9191757861 | I169: 8337120782 | J169: 7983124244 | K169: 7828795755 | L169: 7633800771 | M169: 7459775694 | N169: 6974057806 | O169: 6432786980
C170: CAKE | D170: 617388935208 | E170: 641355826984 | F170: 714122331087 | G170: 828149405266 | H170: 942281111056 | I170: 1061749655584 | J170: 1263411463377 | K170: 1408151899248 | L170: 1661204287348 | M170: 1884077906690 | N170: 2174765666320 | O170: 2357795195257
C171: MWG | D171: 36367269639 | E171: 46067112309 | F171: 65390137765 | G171: 87363644373 | H171: 113146946702 | I171: 143342303049 | J171: 182312198583 | K171: 229400437441 | L171: 310005556768 | M171: 375444603055 | N171: 442698671892 | O171: 529319867060
C172: VNPAY | D172: 13469430921 | E172: 21779092016 | F172: 31958511524 | G172: 42799955655 | H172: 57933433924 | I172: 69056405609 | J172: 76005949782 | K172: 80667491327 | L172: 91494491443 | M172: 101068876374 | N172: 107157807951 | O172: 114324863034
C173: ZaloPAY | F173: 9630000 | G173: 8294394 | H173: 28358115388 | I173: 70729974420 | J173: 147333061236 | K173: 210389493640 | L173: 265187908930 | M173: 354053782593 | N173: 405762171754 | O173: 466276829515
C174: VNPOST | G174: 31810609 | H174: 107196374 | I174: 692239123 | J174: 1249560912 | K174: 1781017598 | L174: 4151089766 | M174: 9760122310 | N174: 18483847677 | O174: 34203552680
E178: MOB1-3 | F178: MOB4-end
C179: CL | D179: VDS | E179: =SUMPRODUCT(M168:O168,M147:O147)/SUM(M168:O168) -> 0.08 | F179: =SUMPRODUCT(M168:O168,AC147:AE147)/SUM(M168:O168) -> 0.05
C180: CL | D180: VDS | E180: =SUMPRODUCT(M169:O169,M148:O148)/SUM(M169:O169) -> 0.08 | F180: =SUMPRODUCT(M169:O169,AC148:AE148)/SUM(M169:O169) -> 0.05
C181: CL | D181: CAKE | E181: =SUMPRODUCT(M170:O170,M149:O149)/SUM(M170:O170) -> 0.08 | F181: =SUMPRODUCT(M170:O170,AC149:AE149)/SUM(M170:O170) -> 0.05
C182: CL | D182: MWG | E182: =SUMPRODUCT(M171:O171,M150:O150)/SUM(M171:O171) -> 0.08 | F182: =SUMPRODUCT(M171:O171,AC150:AE150)/SUM(M171:O171) -> 0.08
C183: CL | D183: VNPAY | E183: =SUMPRODUCT(M172:O172,M151:O151)/SUM(M172:O172) -> 0.08 | F183: =SUMPRODUCT(M172:O172,AC151:AE151)/SUM(M172:O172) -> 0.08
C184: CL | D184: ZaloPAY | E184: =SUMPRODUCT(M173:O173,M152:O152)/SUM(M173:O173) -> 0.03 | F184: =SUMPRODUCT(M173:O173,AC152:AE152)/SUM(M173:O173) -> 0.03
C185: CL | D185: VNPOST | E185: =SUMPRODUCT(M174:O174,M153:O153)/SUM(M174:O174) -> 0.03 | F185: =SUMPRODUCT(M174:O174,AC153:AE153)/SUM(M174:O174) -> 0.03

Sheet RISK
B4: PD
B6: Sum of principal balance | C6: Column Labels
B7: Row Labels | C7: 202412 | D7: 202501 | E7: 202502 | F7: 202503 | G7: 202504 | H7: 202505 | I7: 202506 | J7: 202507 | K7: 202508 | L7: 202509 | M7: 202510 | O7: Row Labels | P7: 202412 | Q7: 202501 | R7: 202502 | S7: 202503 | T7: 202504 | U7: 202505 | V7: 202506 | W7: 202507 | X7: 202508 | Y7: 202509 | Z7: 202510 | AA7: 202511 | AB7: 202512
B8: B00 | C8: 140907432312 | D8: 125733474174 | E8: 120452958029 | F8: 124792371704 | G8: 130856706527 | H8: 132564696356 | I8: 131668433529 | J8: 187034559967 | K8: 234570648779 | L8: 361167057609 | M8: 427073147362 | O8: B00 | P8: 140907432312 | Q8: 125733474174 | R8: 120452958029 | S8: 124792371704 | T8: 130856706527 | U8: 132564696356 | V8: 131668433529 | W8: 187034559967 | X8: 234570648779 | Y8: 361167057609 | Z8: 427073147362 | AA8: 444050983683 | AB8: 518502880178
B9: B01 | C9: 8049379348 | D9: 10430070154 | E9: 9674986086 | F9: 8031063372 | G9: 7402106547 | H9: 8351092769 | I9: 8559537399 | J9: 8307280207 | K9: 16822083715 | L9: 19265374663 | M9: 40594276097 | O9: B01 | P9: 8049379348 | Q9: 10430070154 | R9: 9674986086 | S9: 8031063372 | T9: 7402106547 | U9: 8351092769 | V9: 8559537399 | W9: 8307280207 | X9: 16822083715 | Y9: 19265374663 | Z9: 40594276097 | AA9: 41642193407 | AB9: 38818570296
B10: B02 | C10: 4435792144 | D10: 4896829780 | E10: 8595511000 | F10: 7706420334 | G10: 5771683753 | H10: 5654194523 | I10: 6582155229 | J10: 6768128609 | K10: 6476677859 | L10: 12875173819 | M10: 15270541419 | O10: B02 | P10: 4435792144 | Q10: 4896829780 | R10: 8595511000 | S10: 7706420334 | T10: 5771683753 | U10: 5654194523 | V10: 6582155229 | W10: 6768128609 | X10: 6476677859 | Y10: 12875173819 | Z10: 15270541419 | AA10: 32868197980 | AB10: 34029191778
B11: B03 | C11: 5098774496 | D11: 4313905587 | E11: 4713700431 | F11: 7751016797 | G11: 7330539438 | H11: 5690338454 | I11: 5340986249 | J11: 5791073866 | K11: 6185152797 | L11: 6135605392 | M11: 11999715261 | O11: B03 | P11: 5098774496 | Q11: 4313905587 | R11: 4713700431 | S11: 7751016797 | T11: 7330539438 | U11: 5690338454 | V11: 5340986249 | W11: 5791073866 | X11: 6185152797 | Y11: 6135605392 | Z11: 11999715261 | AA11: 14553409292 | AB11: 31842681047
B12: B04 | C12: 4790023788 | D12: 4888975408 | E12: 4169222252 | F12: 4758990057 | G12: 7495611443 | H12: 7133370522 | I12: 5549175405 | J12: 5489579313 | K12: 5883465410 | L12: 5984050756 | M12: 5935025762 | O12: B04 | P12: 4790023788 | Q12: 4888975408 | R12: 4169222252 | S12: 4758990057 | T12: 7495611443 | U12: 7133370522 | V12: 5549175405 | W12: 5489579313 | X12: 5883465410 | Y12: 5984050756 | Z12: 5935025762 | AA12: 11657360869 | AB12: 14406280932
B13: B05 | C13: 4124645905 | D13: 4934745342 | E13: 4778161995 | F13: 3925917203 | G13: 4662271901 | H13: 7322457696 | I13: 6999822052 | J13: 5316725948 | K13: 5360248366 | L13: 5783462054 | M13: 5974154178 | O13: B05 | P13: 4124645905 | Q13: 4934745342 | R13: 4778161995 | S13: 3925917203 | T13: 4662271901 | U13: 7322457696 | V13: 6999822052 | W13: 5316725948 | X13: 5360248366 | Y13: 5783462054 | Z13: 5974154178 | AA13: 5854320253 | AB13: 11465822103
B14: B06 | C14: 3444566681 | D14: 4087432848 | E14: 4501563793 | F14: 4721019466 | G14: 3874414147 | H14: 4311181112 | I14: 7219004819 | J14: 7209935596 | K14: 5292425080 | L14: 5287955522 | M14: 5868477448 | O14: B06 | P14: 3444566681 | Q14: 4087432848 | R14: 4501563793 | S14: 4721019466 | T14: 3874414147 | U14: 4311181112 | V14: 7219004819 | W14: 7209935596 | X14: 5292425080 | Y14: 5287955522 | Z14: 5868417448 | AA14: 5926888411 | AB14: 5566562267
B15: B07 | C15: 3056608221 | D15: 3297912124 | E15: 4187173007 | F15: 4597721703 | G15: 4660876514 | H15: 3968094669 | I15: 4256572638 | J15: 6625430860 | K15: 7277688767 | L15: 5205196152 | M15: 5018131138 | O15: B07 | P15: 3056608221 | Q15: 3297912124 | R15: 4187173007 | S15: 4597721703 | T15: 4660876514 | U15: 3968094669 | V15: 4254982638 | W15: 6625430860 | X15: 7272688767 | Y15: 5198158627 | Z15: 4994629138 | AA15: 5772400183 | AB15: 5901405147
B16: B08 | C16: 2403947249 | D16: 3032344975 | E16: 3231259504 | F16: 3883092064 | G16: 4455085951 | H16: 4509113367 | I16: 3907179760 | J16: 4539312832 | K16: 6203958337 | L16: 7170503915 | M16: 5245986074 | O16: B08 | P16: 2403947249 | Q16: 3032344975 | R16: 3209061450 | S16: 3877434529 | T16: 4432611255 | U16: 4506713760 | V16: 3895059680 | W16: 4514742412 | X16: 6166309473 | Y16: 7131035354 | Z16: 5206442770 | AA16: 4941925114 | AB16: 5596138320
B17: B09 | C17: 1992845181 | D17: 2364770807 | E17: 2875111337 | F17: 3263425245 | G17: 3870803181 | H17: 4639256336 | I17: 4472172151 | J17: 4042746905 | K17: 4652678695 | L17: 6203958337 | M17: 5088884000 | O17: B09 | P17: 1992845181 | Q17: 2364770807 | R17: 2861013337 | S17: 3241227191 | T17: 3857609577 | U17: 4616781640 | V17: 4463656517 | W17: 4019506825 | X17: 4617428275 | Y17: 6166309473 | Z17: 5059247637 | AA17: 5206442770 | AB17: 5118772716
B18: B10 | C18: 1893505610 | D18: 2029094278 | E18: 2193788847 | F18: 2889791733 | G18: 3263425245 | H18: 3870803181 | I18: 4639256336 | J18: 4272667881 | K18: 3904006251 | L18: 4652678695 | M18: 8160105786 | O18: B10+ | P18: =SUM(P19:P41) -> 19100946411 | Q18: =SUM(Q19:Q41) -> 21071369888 | R18: =SUM(R19:R41) -> 22848159753 | S18: =SUM(S19:S41) -> 25814153486 | T18: =SUM(T19:T41) -> 29055380677 | U18: =SUM(U19:U41) -> 32912990254 | V18: =SUM(V19:V41) -> 37529771894 | W18: =SUM(W19:W41) -> 41986480470 | ... AB18: =SUM(AB19:AB41) -> 69549237551
B19: B11 | C19: 2615970631 | D19: 1853047905 | E19: 2016002111 | F19: 2284088847 | G19: 2889791733 | H19: 3150177356 | I19: 3870803181 | J19: 4264827550 | K19: 4383122556 | L19: 3904006251 | M19: 4755861069 | O19: B10 | P19: 1893505610 | Q19: 2029094278 | R19: 2188788847 | S19: 2875693733 | T19: 3241227191 | U19: 3857609577 | V19: 4616781640 | W19: 4264152247 | X19: 3880766171 | Y19: 4617428275 | Z19: 8109160127 | AA19: 5059247637 | AB19: 5240922659
B20: B12 | C20: 2699806684 | D20: 2660589206 | E20: 1815945991 | F20: 1936569111 | G20: 2284088847 | H20: 2883667643 | I20: 3150177356 | J20: 4095272285 | K20: 4222269485 | L20: 4383122556 | M20: 3918360283 | O20: B11 | P20: 2615970631 | Q20: 1853047905 | R20: 2013000076 | S20: 2279088847 | T20: 2875693733 | U20: 3127979302 | V20: 3857609577 | W20: 4245501387 | X20: 4374606922 | Y20: 3880766171 | Z20: 4721110655 | AA20: 8109160127 | AB20: 4948026348
B21: B13 | C21: 2678111331 | D21: 2736513609 | E21: 2627512020 | F21: 1803850991 | G21: 1936569111 | H21: 2278417771 | I21: 2883667643 | J21: 3374565195 | K21: 4168191840 | L21: 4222269485 | M21: 4527018767 | O21: B12 | P21: 2699806684 | Q21: 2660589206 | R21: 1812573991 | S21: 1933567076 | T21: 2279088847 | U21: 2869569643 | V21: 3127979302 | W21: 4078930148 | X21: 4202943322 | Y21: 4370606922 | Z21: 3894620197 | AA21: 4721110655 | AB21: 8367352555
B22: B14 | C22: 2335415793 | D22: 2496616461 | E22: 2530657107 | F22: 2539397243 | G22: 1803850991 | H22: 1986969275 | I22: 2278417771 | J22: 2899343075 | K22: 3484577486 | L22: 4168191840 | M22: 4016515924 | O22: B13 | P22: 2678111331 | Q22: 2736513609 | R22: 2623856020 | S22: 1800478991 | T22: 1933567076 | U22: 2273417771 | V22: 2869569643 | W22: 3352367141 | X22: 4151849703 | Y22: 4202943322 | Z22: 4514503133 | AA22: 3894620197 | AB22: 4569750243
