Workbook
Name IQ_CH: 110000
Name IQ_CQ: 5000
Name IQ_CY: 10000
Name IQ_DAILY: 500000
Name IQ_FH: 100000
Name IQ_FQ: 500
Name IQ_FY: 1000
Name IQ_LTM: 2000
Name IQ_MONTH: 15000
Name IQ_NTM: 6000
Name IQ_WEEK: 50000
Name IQ_YTD: 3000
Name SWITCH_EXPENSES: 1
Name SWITCH_LIABILITIES: 1
Name valuevx: 42.314159

Sheet Revenue
A1: Đơn vị: vnd | E1: 1 | F1: 2 | G1: 3 | H1: 4 | I1: 5 | J1: 6 | K1: 7 | L1: 8 | M1: 9 | N1: 10 | O1: 11 | P1: 12
A2: BeFinancial - CAKE | AH2: BeFinancial - CAKE
A3: Actual | F3: =F29/E29 -> 0.80888653 | G3: =G37/F37 -> 1.2604584 | H3: =H5/G5 -> 0.92674828 | I3: =I5/H5 -> 1.0281138 | J3: =J5/I5 -> 1.0013925 | M3: =L5-M5 -> 3.4969101e+08 | N3: =N5/N59 -> 0.2541237 | Q3: all figures in VND | AG3: 2638255471 | AH3: Budget | AI3: =AI13-AI12 -> 3.6442301e+09 | AJ3: =AJ13-AJ12 -> 3.2475356e+09 | AK3: =AK13-AK12 -> 3.4913905e+09 | AL3: =AL13-AL12 -> 2.9044626e+09 | AM3: =AM13-AM12 -> 3.5440335e+09 | AN3: =AN13-AN12 -> 3.8886047e+09 | AO3: =AO13-AO12 -> 4.1684033e+09 | AP3: =AP13-AP12 -> 4.14009e+09 | ... AT3: =AT13-AT12 -> 4.502786e+09 | AU3: all figures in VNĐ
A4: P&L summary after allocation | B4: % KPI | C4: % KPI | D4: YTD | E4: 45292 | F4: 45323 | G4: 45352 | H4: 45383 | I4: 45413 | J4: 45444 | K4: 45474 | L4: 45505 | M4: 45536 | N4: 45566 | O4: 45597 | P4: 45627 | Q4: 2024 Actual | R4: 2025 YTD | S4: 45658 | T4: 45689 | U4: 45717 | V4: 45748 | W4: 45778 | X4: 45809 | Y4: 45839 | Z4: 45870 | AA4: 45901 | AB4: 45931 | AC4: 45962 | AD4: 45992 | AE4: 2025 Actual | AG4: check | AH4: P&L summary after allocation | AI4: 45658 | AJ4: 45689 | AK4: 45717 | AL4: 45748 | AM4: 45778 | AN4: 45809 | AO4: 45839 | AP4: 45870 | AQ4: 45901 | AR4: 45931 | AS4: 45962 | AT4: 45992 | AU4: 2025 YTD | AV4: 2024 Actual
A5: Income from deposit products | B5: =(R5/1)/AU5 -> 0.59621368 | C5: =IFERROR(B5,0) -> 0.59621368 | D5: =SUM(E5:P5) -> 4.420101e+11 | E5: =SUM(E6:E8) -> 3.540048e+10 | F5: =SUM(F6:F8) -> 33999675821 | G5: =SUM(G6:G8) -> 3.6048406e+10 | H5: =SUM(H6:H8) -> 3.3407799e+10 | I5: =SUM(I6:I8) -> 3.434702e+10 | J5: =SUM(J6:J8) -> 3.4394848e+10 | K5: =SUM(K6:K8) -> 3.6437059e+10 | L5: =SUM(L6:L8) -> 3.740933e+10 | ... P5: =SUM(P6:P8) -> 42362236475 | Q5: =SUM(E5:P5) -> 4.420101e+11 | R5: =SUM(S5:AD5) -> 5.3169539e+11 | S5: =SUM(S6:S8) -> 45837772985 | T5: =SUM(T6:T8) -> 4.5941552e+10 | U5: =SUM(U6:U8) -> 5.4181546e+10 | V5: =SUM(V6:V8) -> 5.5214507e+10 | W5: =SUM(W6:W8) -> 6.1489923e+10 | X5: =SUM(X6:X8) -> 6.2476762e+10 | Y5: =SUM(Y6:Y8) -> 6.7156183e+10 | Z5: =SUM(Z6:Z8) -> 6.9629497e+10 | ... AD5: =SUM(AD6:AD8) -> 0 | AE5: =SUM(S5:AD5) -> 5.3169539e+11 | AH5: Income from deposit products | AI5: =SUM(AI6:AI8) -> 4.4992075e+10 | AJ5: =SUM(AJ6:AJ8) -> 5.0754935e+10 | AK5: =SUM(AK6:AK8) -> 56703006875 | AL5: =SUM(AL6:AL8) -> 6.2629412e+10 | AM5: =SUM(AM6:AM8) -> 6.8012059e+10 | AN5: =SUM(AN6:AN8) -> 7.2850948e+10 | AO5: =SUM(AO6:AO8) -> 77689836875 | AP5: =SUM(AP6:AP8) -> 8.2485392e+10 | ... AT5: =SUM(AT6:AT8) -> 9.969946e+10 | AU5: =SUM(AI5:AT5) -> 8.9178664e+11
A6: CASA | B6: =(R6/1)/AU6 -> 0.47082873 | C6: =IFERROR(B6,0) -> 0.47082873 | D6: =SUM(E6:P6) -> 1.9654287e+10 | E6: 1.4422921e+09 | F6: 1.3553569e+09 | G6: 1.4063825e+09 | H6: 1.3311403e+09 | I6: 1.3718093e+09 | J6: 1.4916783e+09 | K6: 1.7021247e+09 | L6: 1.7710066e+09 | M6: 1.80151e+09 | N6: 2006103524 | O6: 1956116410 | P6: 2018766820 | Q6: =SUM(E6:P6) -> 1.9654287e+10 | R6: =SUM(S6:AD6) -> 2.2585654e+10 | S6: 2223092407 | T6: 1.9887908e+09 | U6: 2.2054323e+09 | V6: 2.2492915e+09 | W6: 2.4533783e+09 | X6: 2.5923384e+09 | Y6: 3.0265847e+09 | Z6: 3.0418351e+09 | AA6: 2.8049108e+09 | AE6: =SUM(S6:AD6) -> 2.2585654e+10 | AH6: CASA | AI6: 2.3183333e+09 | AJ6: 2.7516667e+09 | AK6: 3.12e+09 | AL6: 3.4666667e+09 | AM6: 3.77e+09 | AN6: 4.03e+09 | AO6: 4290000000 | AP6: 4.5066667e+09 | AQ6: 4680000000 | AR6: 4.8533333e+09 | AS6: 5.0266667e+09 | AT6: 5.1566667e+09 | AU6: =SUM(AI6:AT6) -> 47970000000
A7: SS | B7: =(R7/1)/AU7 -> #DIV/0! | C7: =IFERROR(B7,0) -> 0 | D7: =SUM(E7:P7) -> 0 | Q7: =SUM(E7:P7) -> 0 | AE7: =SUM(S7:AD7) -> 0 | AH7: SS | AU7: =SUM(AI7:AT7) -> 0
A8: Term Deposits | B8: =(R8/1)/AU8 -> 0.60334167 | C8: =IFERROR(B8,0) -> 0.60334167 | D8: =SUM(E8:P8) -> 4.2235581e+11 | E8: 3.3958188e+10 | F8: 3.2644319e+10 | G8: 3.4642024e+10 | H8: 3.2076658e+10 | I8: 3.2975211e+10 | J8: 3.2903169e+10 | K8: 3.4734934e+10 | L8: 3.5638324e+10 | M8: 3.5258129e+10 | N8: 38870929658 | O8: 38310454706 | P8: 40343469655 | Q8: =SUM(E8:P8) -> 4.2235581e+11 | R8: =SUM(S8:AD8) -> 5.0910974e+11 | S8: 43614680578 | T8: 4.3952762e+10 | U8: 5.1976113e+10 | V8: 5.2965216e+10 | W8: 5.9036545e+10 | X8: 5.9884423e+10 | Y8: 6.4129598e+10 | Z8: 6.6587662e+10 | AA8: 6.6962735e+10 | AE8: =SUM(S8:AD8) -> 5.0910974e+11 | AH8: Term Deposits | AI8: 4.2673742e+10 | AJ8: 4.8003268e+10 | AK8: 53583006875 | AL8: 5.9162746e+10 | AM8: 6.4242059e+10 | AN8: 6.8820948e+10 | AO8: 73399836875 | AP8: 7.7978726e+10 | AQ8: 8.2557614e+10 | AR8: 87136503125 | AS8: 9.1715392e+10 | AT8: 94542793125 | AU8: =SUM(AI8:AT8) -> 8.4381664e+11
A9: Income from credit products | B9: =(R9/1)/AU9 -> 0.57790099 | C9: =IFERROR(B9,0) -> 0.57790099 | D9: =SUM(E9:P9) -> 8.2857719e+11 | E9: =E10+E14+E17+E20+E23 -> 28828668892 | F9: =F10+F14+F17+F20+F23 -> 30233023471 | G9: =G10+G14+G17+G20+G23 -> 3.1369122e+10 | H9: =H10+H14+H17+H20+H23 -> 3.9956004e+10 | I9: =I10+I14+I17+I20+I23 -> 4.7766964e+10 | J9: =J10+J14+J17+J20+J23 -> 5.5055892e+10 | K9: =K10+K14+K17+K20+K23 -> 75896454114 | L9: =L10+L14+L17+L20+L23 -> 85039924776 | ... P9: =P10+P14+P17+P20+P23 -> 121786257839 | Q9: =SUM(E9:P9) -> 8.2857719e+11 | R9: =SUM(S9:AD9) -> 1.4295451e+12 | S9: =S10+S14+S17+S20+S23 -> 1.2863271e+11 | T9: =T10+T14+T17+T20+T23 -> 1.169575e+11 | U9: =U10+U14+U17+U20+U23 -> 138096338246 | V9: =V10+V14+V17+V20+V23 -> 151078947518 | W9: =W10+W14+W17+W20+W23 -> 168215147029 | X9: =X10+X14+X17+X20+X23 -> 147554709449 | Y9: =Y10+Y14+Y17+Y20+Y23 -> 163239518794 | Z9: =Z10+Z14+Z17+Z20+Z23 -> 197622157190 | ... AD9: =AD10+AD14+AD17+AD20+AD23 -> 0 | AE9: =SUM(S9:AD9) -> 1.4295451e+12 | AH9: Income from credit products | AI9: =AI10+AI14+AI17+AI20+AI23+AI26 -> 1.4329723e+11 | AJ9: =AJ10+AJ14+AJ17+AJ20+AJ23+AJ26 -> 1.5227363e+11 | AK9: =AK10+AK14+AK17+AK20+AK23+AK26 -> 1.6341581e+11 | AL9: =AL10+AL14+AL17+AL20+AL23+AL26 -> 1.7408811e+11 | AM9: =AM10+AM14+AM17+AM20+AM23+AM26 -> 1.8608698e+11 | AN9: =AN10+AN14+AN17+AN20+AN23+AN26 -> 1.9791885e+11 | AO9: =AO10+AO14+AO17+AO20+AO23+AO26 -> 2.1013907e+11 | AP9: =AP10+AP14+AP17+AP20+AP23+AP26 -> 2.2275186e+11 | ... AT9: =AT10+AT14+AT17+AT20+AT23+AT26 -> 2.7604713e+11 | AU9: =SUM(AI9:AT9) -> 2.4736852e+12
A10: Credit card | B10: =(R10/1)/AU10 -> 0.72896863 | C10: =IFERROR(B10,0) -> 0.72896863 | D10: =SUM(E10:P10) -> 167388599156 | E10: =SUM(E11:E13) -> 7623886493 | F10: =SUM(F11:F13) -> 10147956150 | G10: =SUM(G11:G13) -> 7544483878 | H10: =SUM(H11:H13) -> 11676043557 | I10: =SUM(I11:I13) -> 11725540784 | J10: =SUM(J11:J13) -> 12851233295 | K10: =SUM(K11:K13) -> 13232162394 | L10: =SUM(L11:L13) -> 14698185849 | ... P10: =SUM(P11:P13) -> 18530470576 | Q10: =SUM(E10:P10) -> 167388599156 | R10: =SUM(S10:AD10) -> 2.6971099e+11 | S10: =SUM(S11:S13) -> 2.1711338e+10 | T10: =SUM(T11:T13) -> 2.1382921e+10 | U10: =SUM(U11:U13) -> 21692524249 | V10: =SUM(V11:V13) -> 25388538271 | W10: =SUM(W11:W13) -> 31392916810 | X10: =SUM(X11:X13) -> 34885977665 | Y10: =SUM(Y11:Y13) -> 30192067366 | Z10: =SUM(Z11:Z13) -> 40646648749 | ... AD10: =SUM(AD11:AD13) -> 0 | AE10: =SUM(S10:AD10) -> 2.6971099e+11 | AH10: Credit card | AI10: =AI11+AI13+AI12 -> 2.4491782e+10 | AJ10: =AJ11+AJ13+AJ12 -> 2.4660503e+10 | AK10: =AK11+AK13+AK12 -> 2.5711474e+10 | AL10: =AL11+AL13+AL12 -> 2.6474627e+10 | AM10: =AM11+AM13+AM12 -> 2.8400958e+10 | AN10: =AN11+AN13+AN12 -> 2.9979383e+10 | AO10: =AO11+AO13+AO12 -> 3.1526726e+10 | AP10: =AP11+AP13+AP12 -> 3.2796978e+10 | ... AT10: =AT11+AT13+AT12 -> 3.8559833e+10 | AU10: =SUM(AI10:AT10) -> 3.6998984e+11
A11: Interest Income | B11: =(R11/1)/AU11 -> 0.63888265 | C11: =IFERROR(B11,0) -> 0.63888265 | D11: =SUM(E11:P11) -> 95902899947 | E11: =4472730286-2321927855+2335699134 -> 4486501565 | F11: =4580516789+2321927855-1010518810 -> 5891925834 | G11: =5926713484+1010518810+3043745-2819491515 -> 4120784524 | H11: =7180956467+2819491515-2808491427+4091729 -> 7196048284 | I11: =7197889399+2808491427-3154407914 -> 6851972912 | J11: =8279181293+3154407914-3533621420 -> 7899967787 | K11: =7970752555+3533621420-3733269308 -> 7771104667 | L11: =9429096125+3733269308-4206787379 -> 8955578054 | M11: =10110875323+4206787379-4407951982 -> 9909710720 | N11: =10184346142+4407951982-4548658214 -> 10043639910 | O11: =11747409847+4548658214-5034040644 -> 11262027417 | P11: =11718103524+5034040644-5238505895 -> 11513638273 | Q11: =SUM(E11:P11) -> 95902899947 | R11: =SUM(S11:AD11) -> 1.4624591e+11 | S11: =12736.3252655556*10^6 -> 1.2736325e+10 | T11: =12711.793072*10^6 -> 12711793072 | U11: =18302210300-6396782252 -> 11905428048 | V11: 15048779990 | W11: =20038520765-4475367874 -> 15563152891 | X11: 17460193644 | Y11: 17669830163 | Z11: 21451679111 | AA11: 21698728050 | AE11: =SUM(S11:AD11) -> 1.4624591e+11 | AH11: Interest Income | AI11: 1.4715022e+10 | AJ11: 1.500064e+10 | AK11: 1.5518774e+10 | AL11: 1.6570558e+10 | AM11: 1.7549574e+10 | AN11: 1.8466109e+10 | AO11: 1.9406628e+10 | AP11: 2.0368332e+10 | AQ11: 2.1333337e+10 | AR11: 2.2318701e+10 | AS11: 2.3341118e+10 | AT11: 2.4320087e+10 | AU11: =SUM(AI11:AT11) -> 2.2890888e+11
A12: Interchange | B12: =(R12/1)/AU12 -> 0.62553037 | C12: =IFERROR(B12,0) -> 0.62553037 | D12: =SUM(E12:P12) -> 24576789128 | E12: 1179443896 | F12: 1032636916 | G12: 1883604576 | H12: 1578834209 | I12: 2075789609 | J12: =1823578547 -> 1823578547 | K12: 2210803421 | L12: 2137698801 | M12: 2380438413 | N12: 2682994684 | O12: 2609854914 | P12: 2981111142 | Q12: =SUM(E12:P12) -> 24576789128 | R12: =SUM(S12:AD12) -> 2.9444387e+10 | S12: 2326092651 | T12: 3294432114 | U12: 3200762702 | V12: 2818191674 | W12: 3413548040 | X12: 3274779830 | Y12: 3811177050 | Z12: 3483623072 | AA12: 3.8217798e+09 | AE12: =SUM(S12:AD12) -> 2.9444387e+10 | AH12: Interchange | AI12: 3.066265e+09 | AJ12: 3.2061634e+09 | AK12: 3.3506546e+09 | AL12: 3.4998036e+09 | AM12: 3.6536754e+09 | AN12: 3.812335e+09 | AO12: 3.9758476e+09 | AP12: 4.1442781e+09 | AQ12: 4.3176915e+09 | AR12: 4.496153e+09 | AS12: 4.6797275e+09 | AT12: 4.8684801e+09 | AU12: =SUM(AI12:AT12) -> 4.7071075e+10
A13: Fee income | B13: =(R13/1)/AU13 -> 1.0001149 | C13: =IFERROR(B13,0) -> 1.0001149 | D13: =SUM(E13:P13) -> 46908910081 | E13: =2078100221-1777041072+1656881883 -> 1957941032 | F13: =2240721485+1777041072-794369157 -> 3223393400 | G13: =2881710239+794369157-2135984618 -> 1540094778 | H13: =2744496517+2135984618-1979320071 -> 2901161064 | I13: =3016665362+1979320071-2198207170 -> 2797778263 | J13: =3509253994+2198207170-2579774203 -> 3127686961 | K13: =3081788559+2579774203-2552674298+141365842 -> 3250254306 | L13: =4024643118+2552674298-2972408422 -> 3604908994 | M13: =4576228503+2972408422-3177240607 -> 4371396318 | N13: =4497390199+3177240607-3217295228 -> 4457335578 | O13: =12793137531+3217295228-4369194533 -> 11641238226 | P13: =3794145294+4369194533-4127618666 -> 4035721161 | Q13: =SUM(E13:P13) -> 46908910081 | R13: =SUM(S13:AD13) -> 9.4020691e+10 | S13: =8975.01312666667*10^6-S12 -> 6.6489205e+09 | T13: =8671.12787144445*10^6-T12 -> 5.3766958e+09 | U13: =11625545500-5039212001 -> 6586333499 | V13: 7521566607 | W13: =15959900985-5887321470+2343636364 -> 12416215879 | X13: 14151004191 | Y13: 8711060153 | Z13: 15711346566 | AA13: 16897547442 | AE13: =SUM(S13:AD13) -> 9.4020691e+10 | AH13: Fee income | AI13: 6.7104951e+09 | AJ13: 6.453699e+09 | AK13: 6.8420451e+09 | AL13: 6.4042662e+09 | AM13: 7.1977088e+09 | AN13: 7.7009398e+09 | AO13: 8.1442509e+09 | AP13: 8.2843681e+09 | AQ13: =8415426063.98329+1443000000 -> 9.8584261e+09 | AR13: 8.4357429e+09 | AS13: 8.6066813e+09 | AT13: 9.3712661e+09 | AU13: =SUM(AI13:AT13) -> 9.4009889e+10
A14: Cash loan | B14: =(R14/1)/AU14 -> 0.58067341 | C14: =IFERROR(B14,0) -> 0.58067341 | D14: =SUM(E14:P14) -> 4.7718835e+11 | E14: =10130937223-1253000493-10154+1011910704+8044520+3605537323 -> 13503419123 | F14: =10454533267+1253000493+3480522-1545241177-68489+2164718047 -> 12330422663 | G14: =13224508357-1781009381+2721694059 -> 14165193035 | H14: =12480657889+1781009381-3262357-1929235088+5231264000.18855 -> 1.7560434e+10 | I14: =17340858209.331+5852182828 -> 2.3193041e+10 | J14: =18601155077+94707+10677923598+1228568678.77941-2284902288 -> 2.822284e+10 | K14: =30199814953+2284902288-2735072822+15952581491 -> 45702225910 | L14: =38164890166+2735072822-3902972065+14766644848 -> 51763635771 | M14: =40636567084+982792501+3902972065-5064275848+15057642423 -> 55515698225 | N14: =56723522005-6459362775+17219877407 -> 67484036637 | O14: =61334925217-7432024033+16282957435 -> 70185858619 | P14: =60932617104+7432024033-8216161374+17413068347 -> 77561548110 | Q14: =SUM(E14:P14) -> 4.7718835e+11 | R14: =SUM(S14:AD14) -> 9.5993088e+11 | S14: =S15+S16 -> 8.2877028e+10 | T14: =T15+T16 -> 7.3536218e+10 | U14: =U15+U16 -> 90806987870 | V14: =V15+V16 -> 100311182969 | W14: =W15+W16 -> 110191364925 | X14: =X15+X16 -> 96646485412 | Y14: =Y15+Y16 -> 115799565506 | Z14: =Z15+Z16 -> 136486258184 | AA14: =AA15+AA16 -> 153275790568 | AE14: =SUM(S14:AD14) -> 9.5993088e+11 | AH14: Cash loan | AI14: =AI15+AI16 -> 9.2364422e+10 | AJ14: =AJ15+AJ16 -> 9.9649496e+10 | AK14: =AK15+AK16 -> 1.0782682e+11 | AL14: =AL15+AL16 -> 1.1591693e+11 | AM14: =AM15+AM16 -> 1.2402256e+11 | AN14: =AN15+AN16 -> 1.3224206e+11 | AO14: =AO15+AO16 -> 1.4070221e+11 | AP14: =AP15+AP16 -> 1.4971643e+11 | ... AT14: =AT15+AT16 -> 1.8653539e+11 | AU14: =SUM(AI14:AT14) -> 1.6531339e+12
A15: Interest Income | E15: 9822684664 | F15: 10060580608 | G15: 11255014335 | H15: 12126013651 | I15: 17109986037 | J15: 16046492631 | K15: 29242392962 | L15: 35636664319 | M15: 39472033518 | N15: 48402415531 | O15: 51497992410 | P15: 56912007079 | Q15: =SUM(E15:P15) -> 337584277745 | R15: =SUM(S15:AD15) -> 7.9276186e+11 | S15: =63352.4307067778*10^6 -> 6.3352431e+10 | T15: 58657425818 | U15: =76344334175-8811641235 -> 67532692940 | V15: 71488136425 | W15: =91069031847-9633540635 -> 81435491212 | X15: 88142639448 | Y15: 105404205925 | Z15: 121870162370 | AA15: 134878672388 | AI15: 7.0792641e+10 | AJ15: 7.6628826e+10 | AK15: 8.3343191e+10 | AL15: 8.9959762e+10 | AM15: 9.6579176e+10 | AN15: 1.0330576e+11 | AO15: 1.1026494e+11 | AP15: 1.1775678e+11 | AQ15: 1.2546836e+11 | AR15: 1.3303144e+11 | AS15: 1.4060935e+11 | AT15: 1.4846144e+11 | AU15: =SUM(AI15:AT15) -> 1.2962017e+12
A16: Fee income | E16: 3680734459 | F16: 2269842055 | G16: 2910178700 | H16: 5.4344202e+09 | I16: 6.083055e+09 | J16: 1.2176347e+10 | K16: 16459832948 | L16: 16126971452 | M16: 16043664707 | N16: 19081621106 | O16: 18687866209 | P16: 20649541031 | Q16: =SUM(E16:P16) -> 1.3960407e+11 | R16: =SUM(S16:AD16) -> 1.6716902e+11 | S16: =2585208550+16939388929 -> 19524597479 | T16: 1.4878793e+10 | U16: =4357697099+18916597831 -> 23274294930 | V16: =5294534965+23528511579 -> 28823046544 | W16: =5102530001+23653343712 -> 28755873713 | X16: 8503845964 | Y16: 10395359581 | Z16: 14616095814 | AA16: 18397118180 | AI16: 2.1571781e+10 | AJ16: 2.3020671e+10 | AK16: 2.4483624e+10 | AL16: 2.5957168e+10 | AM16: 2.7443381e+10 | AN16: 2.8936294e+10 | AO16: 3.043727e+10 | AP16: 3.195965e+10 | AQ16: 3.3486892e+10 | AR16: 3.5017182e+10 | AS16: 3.6544326e+10 | AT16: 3.8073949e+10 | AU16: =SUM(AI16:AT16) -> 3.5693219e+11
A17: Pay day loan | B17: =(R17/1)/AU17 -> 0.51726684 | C17: =IFERROR(B17,0) -> 0.51726684 | D17: =SUM(E17:P17) -> 1.2836178e+11 | E17: =1731837685-27551638+74763964+3024414731 -> 4803464742 | F17: =1893405606+27551638-58249898+3016914165 -> 4879621511 | G17: =2433097916-43185351+3959227879.2 -> 6.3491404e+09 | H17: =2738252099+43185351-41105355+4667859999.7037 -> 7.4081921e+09 | I17: =3395471237+5796804892 -> 9192276129 | J17: =3609434923+6424397168-56271600 -> 9977560491 | K17: =4540246107+56271600-47851261+7851414034 -> 12400080480 | L17: =4985545722+47851261-77340097+8520985077 -> 13477041963 | M17: =5060551048+77340097-75500112+8309967451 -> 13372358484 | N17: =5558900401-96699988+9087046603 -> 14549247016 | O17: =5321181281-77091089+8427493438 -> 13671583630 | P17: =6675824625+77091089-135438883+11663739212 -> 18281216043 | Q17: =SUM(E17:P17) -> 1.2836178e+11 | R17: =SUM(S17:AD17) -> 1.2069203e+11 | S17: =S18+S19 -> 1.6267745e+10 | T17: =T18+T19 -> 14704552067 | U17: =U18+U19 -> 17050685748 | V17: =V18+V19 -> 16823379156 | W17: =W18+W19 -> 17302527583 | X17: =X18+X19 -> 6648549132 | Y17: =Y18+Y19 -> 7509366443 | Z17: =Z18+Z19 -> 10664313763 | AA17: =AA18+AA19 -> 13720914092 | AE17: =SUM(S17:AD17) -> 1.2069203e+11 | AH17: Pay day loan | AI17: =AI18+AI19 -> 1.667638e+10 | AJ17: =AJ18+AJ19 -> 1.7204842e+10 | AK17: =AK18+AK19 -> 1.7898854e+10 | AL17: =AL18+AL19 -> 1.834654e+10 | AM17: =AM18+AM19 -> 1.8802133e+10 | AN17: =AN18+AN19 -> 1.9259966e+10 | AO17: =AO18+AO19 -> 1.9714454e+10 | AP17: =AP18+AP19 -> 2.016686e+10 | ... AT17: =AT18+AT19 -> 2.2005117e+10 | AU17: =SUM(AI17:AT17) -> 2.3332644e+11
A18: Interest Income | E18: 1779050011 | F18: 1862707346 | G18: 2389912565 | H18: 2740332095 | I18: 3395471237 | J18: 3553163323 | K18: 4548666446 | L18: 4956056886 | M18: 5062391033 | N18: 5462200413 | O18: 5244090192 | P18: 6508988960 | Q18: =SUM(E18:P18) -> 47503030507 | R18: =SUM(S18:AD18) -> 7.0085585e+10 | S18: =6617.74465811111*10^6 -> 6.6177447e+09 | T18: =5508.505087*10^6 -> 5508505087 | U18: =6359746765-106193778 -> 6253552987 | V18: 6473661986 | W18: =6794376825-105399665 -> 6688977160 | X18: 6648549132 | Y18: 7509366443 | Z18: 10664313763 | AA18: 13720914092 | AI18: 6.1097463e+09 | AJ18: 6.339575e+09 | AK18: 6.7349535e+09 | AL18: 6.8840063e+09 | AM18: 7.0409663e+09 | AN18: 7.2001661e+09 | AO18: 7.3560206e+09 | AP18: 7.5097937e+09 | AQ18: 7.6606517e+09 | AR18: 7.8267751e+09 | AS18: 8.0008724e+09 | AT18: 8.1535168e+09 | AU18: =SUM(AI18:AT18) -> 8.6817044e+10
A19: Fee income | E19: 3024414731 | F19: 3016914165 | G19: 3.9592279e+09 | H19: 4.66786e+09 | I19: 5796804892 | J19: 6424397168 | K19: 7851414034 | L19: 8520985077 | M19: 8309967451 | N19: 9087046603 | O19: 8427493438 | P19: 11772227083 | Q19: =SUM(E19:P19) -> 8.0858753e+10 | R19: =SUM(S19:AD19) -> 50606447334 | S19: =9650*10^6 -> 9650000000 | T19: =9196.04698*10^6 -> 9196046980 | U19: 10797132761 | V19: 10349717170 | W19: 10613550423 | AI19: 1.0566633e+10 | AJ19: 1.0865267e+10 | AK19: 11163900000 | AL19: 1.1462533e+10 | AM19: 1.1761167e+10 | AN19: 1.20598e+10 | AO19: 1.2358433e+10 | AP19: 1.2657067e+10 | AQ19: 1.29557e+10 | AR19: 1.3254333e+10 | AS19: 1.3552967e+10 | AT19: 1.38516e+10 | AU19: =SUM(AI19:AT19) -> 1.465094e+11
A20: Paylater | B20: =(R20/1)/AU20 -> 0.59310015 | C20: =IFERROR(B20,0) -> 0.59310015 | D20: =SUM(E20:P20) -> 3124798247 | I20: 51061059 | J20: 125496366 | K20: =220940096+7973965-16167166 -> 212746895 | L20: =332748242+16167166-28944690 -> 319970718 | M20: =398037448+28944690-35276697 -> 391705441 | N20: =631534237-47352518 -> 584181719 | O20: =778169229-76040535 -> 702128694 | P20: =742339674+76040535-80872854 -> 737507355 | Q20: =SUM(E20:P20) -> 3124798247 | R20: =SUM(S20:AD20) -> 1.5923103e+10 | S20: =S21+S22 -> 8.8099864e+08 | T20: =T21+T22 -> 1069140221 | U20: =U21+U22 -> 1292789944 | V20: =V21+V22 -> 1351132922 | W20: =W21+W22 -> 1656385562 | X20: =X21+X22 -> 1875945039 | Y20: =Y21+Y22 -> 2091044528 | Z20: =Z21+Z22 -> 2673230298 | AA20: =AA21+AA22 -> 3032435697 | AE20: =SUM(S20:AD20) -> 1.5923103e+10 | AH20: BNPL | AI20: =AI21+AI22 -> 9.0247627e+08 | AJ20: =AJ21+AJ22 -> 1.1216932e+09 | AK20: =AK21+AK22 -> 1.4016528e+09 | AL20: =AL21+AL22 -> 1.6370788e+09 | AM20: =AM21+AM22 -> 1.86424e+09 | AN20: =AN21+AN22 -> 2.0893812e+09 | AO20: =AO21+AO22 -> 2.3259799e+09 | AP20: =AP21+AP22 -> 2.5601171e+09 | ... AT20: =AT21+AT22 -> 3.6888245e+09 | AU20: =SUM(AI20:AT20) -> 2.6847241e+10
A21: Interest Income | Q21: =SUM(E21:P21) -> 0 | R21: =SUM(S21:AD21) -> 5328377346 | T21: 189915753 | U21: =370785283-92711511 -> 278073772 | V21: 426213283 | W21: =520699092-30445764 -> 490253328 | X21: 569261256 | Y21: 689302043 | Z21: 1147845494 | AA21: 1537512417 | AI21: 1.401837e+08 | AJ21: 2.3568613e+08 | AK21: 3.4890238e+08 | AL21: 4.2448901e+08 | AM21: 4.9248507e+08 | AN21: 5.6492392e+08 | AO21: 6.3333331e+08 | AP21: 7.0170999e+08 | AQ21: 7.7858062e+08 | AR21: 8.6046062e+08 | AS21: 9.4546277e+08 | AT21: 1.0339184e+09 | AU21: =SUM(AI21:AT21) -> 7.1601359e+09
A22: Fee income | I22: 51061059 | J22: 125496366 | K22: =220940096+7973965-16167166 -> 212746895 | L22: =332748242+16167166-28944690 -> 319970718 | M22: =398037448+28944690-35276697 -> 391705441 | N22: =631534237-47352518 -> 584181719 | O22: =778169229-76040535 -> 702128694 | P22: =742339674+76040535-80872854 -> 737507355 | Q22: =SUM(E22:P22) -> 3124798247 | R22: =SUM(S22:AD22) -> 1.0594726e+10 | S22: =880.998637777778*10^6 -> 8.8099864e+08 | T22: 879224468 | U22: =1047083553-32367381 -> 1014716172 | V22: 924919639 | W22: =1278245610-112113376 -> 1166132234 | X22: 1306683783 | Y22: 1401742485 | Z22: 1525384804 | AA22: 1494923280 | AI22: 7.6229257e+08 | AJ22: 8.8600709e+08 | AK22: 1.0527505e+09 | AL22: 1.2125898e+09 | AM22: 1.3717549e+09 | AN22: 1.5244573e+09 | AO22: 1.6926466e+09 | AP22: 1.8584071e+09 | AQ22: 2.0283575e+09 | AR22: 2.216563e+09 | AS22: 2.4263729e+09 | AT22: 2.6549061e+09 | AU22: =SUM(AI22:AT22) -> 1.9687105e+10
A23: OD | B23: =(R23/1)/AU23 -> 0.41685544 | C23: =IFERROR(B23,0) -> 0.41685544 | D23: =SUM(E23:P23) -> 52513659020 | E23: =2916044602-230672955+212526887 -> 2897898534 | F23: =2898187184+230672955-253836992 -> 2875023147 | G23: =3601198061-290893363 -> 3310304698 | H23: =3292565159+290893363-272123540 -> 3311334982 | I23: =3895474182-290429443 -> 3605044739 | J23: =4152301850-273539921 -> 3878761929 | K23: =4382422078+273539921-306723564 -> 4349238435 | L23: =4840554142+306723564-366187231 -> 4781090475 | M23: =4794154299+412500000+366187231-421958623 -> 5150882907 | N23: =6199397537-452554320 -> 5746843217 | O23: =6421892830-490172628 -> 5931720202 | P23: =6756112570+490172628-570769443 -> 6675515755 | Q23: =SUM(E23:P23) -> 52513659020 | R23: =SUM(S23:AD23) -> 63288131261 | S23: =S24+S25 -> 6895598820 | T23: =T24+T25 -> 6264667900 | U23: =U24+U25 -> 7253350435 | V23: =V24+V25 -> 7204714200 | W23: =W24+W25 -> 7671952149 | X23: =X24+X25 -> 7497752201 | Y23: =Y24+Y25 -> 7647474951 | Z23: =Z24+Z25 -> 7151706196 | AA23: =AA24+AA25 -> 5700914409 | AE23: =SUM(S23:AD23) -> 63288131261 | AH23: OD | AI23: =AI24+AI25 -> 8.5282818e+09 | AJ23: =AJ24+AJ25 -> 8.973108e+09 | AK23: =AK24+AK25 -> 9.4903448e+09 | AL23: =AL24+AL25 -> 1.0150084e+10 | AM23: =AM24+AM25 -> 1.0908966e+10 | AN23: =AN24+AN25 -> 1.1689184e+10 | AO23: =AO24+AO25 -> 1.2596839e+10 | AP23: =AP24+AP25 -> 1.3584069e+10 | ... AT23: =AT24+AT25 -> 1.8363632e+10 | AU23: =SUM(AI23:AT23) -> 1.5182273e+11
A24: Interest Income | E24: 2676498534 | F24: 2741523147 | G24: 3160104698 | H24: 3180434982 | I24: 3437444739 | J24: 3575578015 | K24: 4036838435 | L24: 4433490475 | M24: 4738382907 | N24: 5294443217 | O24: 5481470202 | P24: 5950915755 | Q24: =SUM(E24:P24) -> 48707125106 | R24: =SUM(S24:AD24) -> 59625711261 | S24: =6314.54882*10^6 -> 6314548820 | T24: =5836.8679*10^6 -> 5836867900 | U24: =7447549794-706549359 -> 6741000435 | V24: 6690164200 | W24: =7974378518-820276369 -> 7154102149 | X24: 6970752201 | Y24: 7222124951 | Z24: 7073356196 | AA24: 5622794409 | AI24: 7.5903136e+09 | AJ24: 7.9896194e+09 | AK24: 8.4584409e+09 | AL24: 9.0669944e+09 | AM24: 9.772028e+09 | AN24: 1.0495827e+10 | AO24: 1.1344574e+10 | AP24: 1.2270478e+10 | AQ24: 1.3283406e+10 | AR24: 1.4374695e+10 | AS24: 1.55481e+10 | AT24: 1.6781696e+10 | AU24: =SUM(AI24:AT24) -> 1.3697617e+11
A25: Fee income | E25: 221400000 | F25: 133500000 | G25: 150200000 | H25: 130900000 | I25: 167600000 | J25: 303183914 | K25: 312400000 | L25: 347600000 | M25: 412500000 | N25: 452400000 | O25: 450250000 | P25: 724600000 | Q25: =SUM(E25:P25) -> 3806533914 | R25: =SUM(S25:AD25) -> 3662420000 | S25: 581050000 | T25: 427800000 | U25: 512350000 | V25: 514550000 | W25: 517850000 | X25: 527000000 | Y25: 425350000 | Z25: 78350000 | AA25: 78120000 | AI25: 9.3796813e+08 | AJ25: 9.8348858e+08 | AK25: 1.0319038e+09 | AL25: 1.0830894e+09 | AM25: 1.136938e+09 | AN25: 1.1933568e+09 | AO25: 1.2522646e+09 | AP25: 1.3135907e+09 | AQ25: 1.3772728e+09 | AR25: 1.443256e+09 | AS25: 1.5114915e+09 | AT25: 1.5819362e+09 | AU25: =SUM(AI25:AT25) -> 1.4846557e+10
A26: TW | B26: =(R26/1)/AU26 -> 0 | R26: =SUM(S26:AD26) -> 0 | S26: =S27+S28 -> 0 | AE26: =SUM(S26:AD26) -> 0 | AH26: TW | AI26: =AI27+AI28 -> 3.3388889e+08 | AJ26: =AJ27+AJ28 -> 6.6399239e+08 | AK26: =AK27+AK28 -> 1.0866648e+09 | AL26: =AL27+AL28 -> 1.5628474e+09 | AM26: =AM27+AM28 -> 2.088128e+09 | AN26: =AN27+AN28 -> 2.6588783e+09 | AO26: =AO27+AO28 -> 3.2728626e+09 | AP26: =AP27+AP28 -> 3.927407e+09 | ... AT26: =AT27+AT28 -> 6.894333e+09 | AU26: =SUM(AI26:AT26) -> 3.8565123e+10
A27: Interest Income | R27: =SUM(S27:AD27) -> 0 | AI27: 68055556 | AJ27: 1.3232572e+08 | AK27: 2.891648e+08 | AL27: 4.9951409e+08 | AM27: 7.5896129e+08 | AN27: 1.0638783e+09 | AO27: 1.4120292e+09 | AP27: 1.8007404e+09 | AQ27: 2.2273985e+09 | AR27: 2.6897924e+09 | AS27: 3.1837866e+09 | AT27: 3.7041304e+09 | AU27: =SUM(AI27:AT27) -> 1.7829777e+10
A28: Fee income | R28: =SUM(S28:AD28) -> 0 | AI28: 2.6583333e+08 | AJ28: 5.3166667e+08 | AK28: 7.975e+08 | AL28: 1.0633333e+09 | AM28: 1.3291667e+09 | AN28: 1.595e+09 | AO28: 1.8608333e+09 | AP28: 2.1266667e+09 | AQ28: 2392500000 | AR28: 2.6583698e+09 | AS28: 2.9242732e+09 | AT28: 3.1902026e+09 | AU28: =SUM(AI28:AT28) -> 2.0735346e+10
A29: Fee Income | B29: =(R29/1)/AU29 -> 0.20063723 | C29: =IFERROR(B29,0) -> 0.20063723 | D29: =SUM(E29:P29) -> 9.7215869e+10 | E29: =E30+E37+E43+E47+E50+E51+E34+E33 -> 823965395 | F29: =F30+F37+F43+F47+F50+F51+F34+F33 -> 6.6649451e+08 | G29: =G30+G37+G43+G47+G50+G51+G34+G33 -> 3738401916 | H29: =H30+H37+H43+H47+H50+H51+H34+H33 -> 1650605437 | I29: =I30+I37+I43+I47+I50+I51+I34+I33 -> 3.2030179e+09 | J29: =J30+J37+J43+J47+J50+J33+J34 -> 793890764 | K29: =K30+K37+K43+K47+K50+K51+K34+K33 -> 5.7604825e+09 | L29: =L30+L37+L43+L47+L50+L51+L34+L33 -> 17789506696 | M29: =M30+M37+M43+M47+M50+M51+M34+M33 -> 892636698 | N29: =N30+N37+N43+N47+N50+N51+N34+N33 -> 14429550885 | O29: =O30+O37+O43+O47+O50+O51+O34+O33 -> 6150919522 | P29: =P30+P37+P43+P47+P50+P51+P34+P33 -> 41316396324 | Q29: =SUM(E29:P29) -> 9.7215869e+10 | R29: =SUM(S29:AD29) -> 1.8741163e+10 | S29: =S30+S37+S43+S47+S50+S51+S34+S33+S46 -> 1419604308 | T29: =T30+T37+T43+T47+T50+T51+T34+T33+T46 -> 1.5423438e+09 | U29: =U30+U37+U43+U47+U50+U51+U34+U33+U46 -> 1.0729186e+09 | V29: =V30+V37+V43+V47+V50+V51+V34+V33+V46 -> 1443861435 | W29: =W30+W37+W43+W47+W50+W51+W34+W33+W46 -> 6288457136 | X29: =X30+X37+X43+X47+X50+X51+X34+X33+X46 -> 1.1170783e+09 | Y29: =Y30+Y37+Y43+Y47+Y50+Y51+Y34+Y33+Y46 -> 2751844521 | Z29: =Z30+Z37+Z43+Z47+Z50+Z51+Z34+Z33+Z46 -> 1559497946 | ... AD29: =AD30+AD37+AD43+AD47+AD50+AD51+AD34+AD33+AD46 -> 0 | AE29: =SUM(S29:AD29) -> 1.8741163e+10 | AH29: Fee Income | AI29: =AI30+AI37+AI43+AI47+AI50+AI51+AI33+AI34+AI35+AI36+AI46 -> 4.0589908e+09 | AJ29: =AJ30+AJ37+AJ43+AJ47+AJ50+AJ51+AJ33+AJ34+AJ35+AJ36+AJ46 -> 3.7314255e+09 | AK29: =AK30+AK37+AK43+AK47+AK50+AK51+AK33+AK34+AK35+AK36+AK46 -> 3.8067205e+09 | AL29: =AL30+AL37+AL43+AL47+AL50+AL51+AL33+AL34+AL35+AL36+AL46 -> 3.8873523e+09 | AM29: =AM30+AM37+AM43+AM47+AM50+AM51+AM33+AM34+AM35+AM36+AM46 -> 3.9657127e+09 | AN29: =AN30+AN37+AN43+AN47+AN50+AN51+AN33+AN34+AN35+AN36+AN46 -> 4.0480827e+09 | AO29: =AO30+AO37+AO43+AO47+AO50+AO51+AO33+AO34+AO35+AO36+AO46 -> 4.4344645e+09 | AP29: =AP30+AP37+AP43+AP47+AP50+AP51+AP33+AP34+AP35+AP36+AP46 -> 4.2152485e+09 | ... AT29: =AT30+AT37+AT43+AT47+AT50+AT51+AT33+AT34+AT35+AT36+AT46 -> 4.2822934e+10 | AU29: =SUM(AI29:AT29) -> 9.3408206e+10
A30: Commission from Payoo | B30: =(R30/1)/AU30 -> 0.45867847 | C30: =IFERROR(B30,0) -> 0.45867847 | D30: =SUM(E30:P30) -> 9.7412922e+08 | E30: =SUM(E31:E32) -> 114156931 | F30: =SUM(F31:F32) -> 60407573 | G30: =SUM(G31:G32) -> 69962901 | H30: =SUM(H31:H32) -> 67952746 | I30: =SUM(I31:I32) -> 76903891 | J30: =SUM(J31:J32) -> 75315209 | K30: =SUM(K31:K32) -> 79216437 | L30: =SUM(L31:L32) -> 78941409 | ... P30: =SUM(P31:P32) -> 83485307 | Q30: =SUM(E30:P30) -> 9.7412922e+08 | R30: =SUM(S30:AD30) -> 6.2326612e+08 | S30: =SUM(S31:S32) -> 77716977 | T30: =SUM(T31:T32) -> 67309473 | U30: =SUM(U31:U32) -> 76734210 | V30: =SUM(V31:V32) -> 74361945 | W30: =SUM(W31:W32) -> 71059507 | X30: =SUM(X31:X32) -> 6169630.1 | Y30: =SUM(Y31:Y32) -> 80344691 | Z30: =SUM(Z31:Z32) -> 84933690 | ... AD30: =SUM(AD31:AD32) -> 0 | AE30: =SUM(S30:AD30) -> 6.2326612e+08 | AH30: Commission from Payoo | AI30: =AI31+AI32 -> 64662170 | AJ30: =AJ31+AJ32 -> 75517869 | AK30: =AK31+AK32 -> 85520079 | AL30: =AL31+AL32 -> 95767673 | AM30: =AM31+AM32 -> 1.0395349e+08 | AN30: =AN31+AN32 -> 1.1233027e+08 | AO30: =AO31+AO32 -> 1.2090022e+08 | AP30: =AP31+AP32 -> 1.2726437e+08 | ... AT30: =AT31+AT32 -> 1.5156919e+08 | AU30: =SUM(AI30:AT30) -> 1.3588301e+09
A31: Bill Payment | B31: =(R31/1)/AU31 -> 0.010757861 | C31: =IFERROR(B31,0) -> 0.010757861 | D31: =SUM(E31:P31) -> 14983636 | E31: 1573636.4 | F31: 1421818.2 | G31: =1379000/1.1 -> 1253636.4 | H31: 1391818.2 | I31: =1422500/1.1 -> 1293181.8 | J31: 1375909.1 | K31: 841818.18 | L31: 993636.36 | M31: 885000 | N31: 1115909.1 | O31: 1439545.5 | P31: 1397727.3 | Q31: =SUM(E31:P31) -> 14983636 | R31: =SUM(S31:AD31) -> 13921273 | S31: 1378181.8 | T31: 1378181.8 | U31: 2486090.9 | V31: 2486090.9 | W31: 1249090.9 | X31: 1235909.1 | Y31: 1235909.1 | Z31: 1235909.1 | AA31: 1235909.1 | AE31: =SUM(S31:AD31) -> 13921273 | AH31: Bill Payment | AI31: 61872230 | AJ31: 72201736 | AK31: 81700561 | AL31: 91420037 | AM31: 99159286 | AN31: 1.0707034e+08 | AO31: 1.1515523e+08 | AP31: 1.2113051e+08 | AQ31: 1.2722819e+08 | AR31: 1.3344967e+08 | AS31: 1.3979634e+08 | AT31: 1.4387174e+08 | AU31: =SUM(AI31:AT31) -> 1.2940559e+09
A32: Mobile top-up | B32: =(R32/1)/AU32 -> 9.4072064 | C32: =IFERROR(B32,0) -> 9.4072064 | D32: =SUM(E32:P32) -> 9.5914559e+08 | E32: 1.1258329e+08 | F32: =60407573-1421818 -> 58985755 | G32: =69962901-G31 -> 68709265 | H32: 66560928 | I32: 75610709 | J32: 73939300 | K32: 78374619 | L32: =78941409-L31 -> 77947773 | M32: 90847836 | N32: 86677646 | O32: =88260427-O31 -> 86820882 | P32: =83485307-P31 -> 82087580 | Q32: =SUM(E32:P32) -> 9.5914559e+08 | R32: =SUM(S32:AD32) -> 6.0934485e+08 | S32: =77716977-S31 -> 76338795 | T32: =67309473-T31 -> 65931291 | U32: 74248119 | V32: 71875854 | W32: 69810416 | X32: =76541703-X33 -> 4933721 | Y32: 79108782 | Z32: 83697781 | AA32: 83400089 | AE32: =SUM(S32:AD32) -> 6.0934485e+08 | AH32: Mobile top-up | AI32: 2789940.2 | AJ32: 3316133.3 | AK32: 3819518.2 | AL32: 4347636.4 | AM32: 4794204.5 | AN32: 5259927.3 | AO32: 5744995.5 | AP32: 6133866.7 | AQ32: 6536250 | AR32: 6952272.7 | AS32: 7382062.1 | AT32: 7697454.5 | AU32: =SUM(AI32:AT32) -> 64774261
A33: Napas fee income | B33: =(R33/1)/AU33 -> 0.53168549 | C33: =IFERROR(B33,0) -> 0.53168549 | D33: =SUM(E33:P33) -> 528350355 | F33: 61642364 | G33: 33262203 | H33: 58847346 | I33: 30940911 | J33: 46558669 | K33: 46783626 | L33: 47703750 | M33: 48341777 | N33: 55670830 | O33: 49765206 | P33: 48833673 | Q33: =SUM(E33:P33) -> 528350355 | R33: =SUM(S33:AD33) -> 483946610 | S33: 52295822 | T33: 50487578 | U33: 44293151 | V33: 43798961 | W33: 48940205 | X33: 71607982 | Y33: 50937668 | Z33: 54885138 | AA33: 66700105 | AE33: =SUM(S33:AD33) -> 483946610 | AH33: Napas fee income | AI33: 45807801 | AJ33: 53014500 | AK33: 59496341 | AL33: 66029727 | AM33: 71036080 | AN33: 76081091 | AO33: 81164761 | AP33: 84689182 | AQ33: 88239375 | AR33: 91815341 | AS33: 95417080 | AT33: 97420909 | AU33: =SUM(AI33:AT33) -> 9.1021219e+08
A34: VNpay | B34: =(R34/1)/AU34 -> #DIV/0! | C34: =IFERROR(B34,0) -> 0 | D34: =SUM(E34:P34) -> 74604660 | F34: 8369568 | G34: 15938225 | I34: 16558020 | N34: 10545568 | O34: 10742450 | P34: 12450829 | R34: =SUM(S34:AD34) -> 106428124 | S34: 9620432 | T34: 12192592 | U34: 13700326 | W34: 20341309 | X34: 29331878 | Z34: 14921132 | AA34: 6320455 | AE34: =SUM(S34:AD34) -> 106428124 | AH34: VNpay | AI34: 0 | AJ34: 0 | AK34: 0 | AL34: 0 | AM34: 0 | AN34: 0 | AO34: 0 | AP34: 0 | AQ34: 0 | AR34: 0 | AS34: 0 | AT34: 0 | AU34: =SUM(AI34:AT34) -> 0
A35: Vietlot | B35: =(R35/1)/AU35 -> 0 | R35: =SUM(S35:AD35) -> 0 | AE35: =SUM(S35:AD35) -> 0 | AH35: Vietlot | AI35: 1689545.5 | AJ35: 3894545.5 | AK35: 6529090.9 | AL35: 9621818.2 | AM35: 12886364 | AN35: 16494545 | AO35: 20446364 | AP35: 24283636 | AQ35: 28350000 | AR35: 32645455 | AS35: 37170000 | AT35: 41236364 | AU35: =SUM(AI35:AT35) -> 2.3524773e+08
A36: Traveloka | B36: =(R36/1)/AU36 -> 0 | R36: =SUM(S36:AD36) -> 0 | AE36: =SUM(S36:AD36) -> 0 | AH36: Traveloka | AI36: 14079545 | AJ36: 32454545 | AK36: 54409091 | AL36: 80181818 | AM36: 1.0738636e+08 | AN36: 1.3745455e+08 | AO36: 1.7038636e+08 | AP36: 2.0236364e+08 | AQ36: 2.3625e+08 | AR36: 2.7204545e+08 | AS36: 3.0975e+08 | AT36: 3.4363636e+08 | AU36: =SUM(AI36:AT36) -> 1.9603977e+09
A37: Fee from Mastercard | B37: =(R37/1)/AU37 -> 0.24457789 | C37: =IFERROR(B37,0) -> 0.24457789 | D37: =SUM(E37:P37) -> 7.5885395e+09 | E37: =SUM(E38:E42) -> 642152995 | F37: =SUM(F38:F42) -> 491270025 | G37: =SUM(G38:G42) -> 619225414 | H37: =SUM(H38:H42) -> 547410709 | I37: =SUM(I38:I42) -> 712714978 | J37: =SUM(J38:J42) -> 649861962 | K37: =SUM(K38:K42) -> 7.5052302e+08 | L37: =SUM(L38:L42) -> 732763491 | ... P37: =SUM(P38:P42) -> 552194063 | Q37: =SUM(E37:P37) -> 7.5885395e+09 | R37: =SUM(S37:AD37) -> 3.5879882e+09 | S37: =SUM(S38:S42) -> 435886294 | T37: =SUM(T38:T42) -> 5.4851277e+08 | U37: =SUM(U38:U42) -> 281741112 | V37: =SUM(V38:V42) -> 261531231 | W37: =SUM(W38:W42) -> 375170209 | X37: =SUM(X38:X42) -> 408463753 | Y37: =SUM(Y38:Y42) -> 415417975 | Z37: =SUM(Z38:Z42) -> 443390529 | ... AD37: =SUM(AD38:AD42) -> 0 | AE37: =SUM(S37:AD37) -> 3.5879882e+09 | AH37: Fee from Mastercard | AI37: =AI38+AI39+AI42+AI40+AI41 -> 6.310404e+08 | AJ37: =AJ38+AJ39+AJ42+AJ40+AJ41 -> 658580400 | AK37: =AK38+AK39+AK42+AK40+AK41 -> 686120400 | AL37: =AL38+AL39+AL42+AL40+AL41 -> 713660400 | AM37: =AM38+AM39+AM42+AM40+AM41 -> 741200400 | AN37: =AN38+AN39+AN42+AN40+AN41 -> 768740400 | AO37: =AO38+AO39+AO42+AO40+AO41 -> 796280400 | AP37: =AP38+AP39+AP42+AP40+AP41 -> 823820400 | ... AT37: =AT38+AT39+AT42+AT40+AT41 -> 933980400 | AU37: =SUM(AI37:AT37) -> 14670124800
A38: Interchange fee from MasterCard | B38: =(R38/1)/AU38 -> #DIV/0! | C38: =IFERROR(B38,0) -> 0 | E38: 367451124 | F38: =252272418+97007 -> 252369425 | G38: 322171949 | H38: 284943281 | I38: 374396772 | J38: =287.919075*10^6 -> 287919075 | K38: 297599228 | L38: 212819314 | M38: 76198938 | Q38: =SUM(E38:P38) -> 2475869106 | R38: =SUM(S38:AD38) -> 0 | AE38: =SUM(S38:AD38) -> 0 | AU38: =SUM(AI38:AT38) -> 0
A39: FX fee from MasterCard | B39: =(R39/1)/AU39 -> #DIV/0! | C39: =IFERROR(B39,0) -> 0 | E39: 246601871 | F39: 218450600 | G39: 271803465 | H39: 240067428 | I39: 312968206 | J39: =233.29254*10^6 -> 233292540 | K39: 217382455 | L39: 167449444 | M39: 59723887 | Q39: =SUM(E39:P39) -> 1967739896 | R39: =SUM(S39:AD39) -> 0 | AE39: =SUM(S39:AD39) -> 0 | AU39: =SUM(AI39:AT39) -> 0
A40: Interchange fee from Visa | J40: 123150347 | K40: 2.3554134e+08 | L40: =296749175+55745558 -> 352494733 | M40: =562948852 -> 562948852 | N40: 608148561 | O40: 583402642 | P40: 552194063 | R40: =SUM(S40:AD40) -> 3.5879882e+09 | S40: 435886294 | T40: =548.512773333333*10^6 -> 5.4851277e+08 | U40: 281741112 | V40: 261531231 | W40: 375170209 | X40: 408463753 | Y40: 415417975 | Z40: 443390529 | AA40: 417874297 | AI40: 1.158864e+08 | AJ40: 123026400 | AK40: 1.301664e+08 | AL40: 137306400 | AM40: 1.444464e+08 | AN40: 1.515864e+08 | AO40: 158726400 | AP40: 1.658664e+08 | AQ40: =173006400+5280000000 -> 5453006400 | AR40: 1.801464e+08 | AS40: 187286400 | AT40: 194426400 | AU40: =SUM(AI40:AT40) -> 7141876800
...

Sheet EBITDA
A1: Đơn vị: Tỷ VNĐ
A2: BeFinancial - CAKE | B2: 11 | AF2: BeFinancial - CAKE
A3: Actual | B3: 1 | O3: =O16-O59 -> 118.0348 | S3: =Q30+R30+S30+Q77+R77+S77 -> 176.63408 | AF3: Budget
A5: CHỈ TIÊU | B5: % KPI | C5: YTD 2024 | D5: 45292 | E5: 45323 | F5: 45352 | G5: 45383 | H5: 45413 | I5: 45444 | J5: 45474 | K5: 45505 | L5: 45536 | M5: 45566 | N5: 45597 | O5: 45627 | P5: YTD 2025 | Q5: 45658 | R5: 45689 | S5: 45717 | T5: 45748 | U5: 45778 | V5: 45809 | W5: 45839 | X5: 45870 | Y5: 45901 | Z5: 45931 | AA5: 45962 | AB5: 45992 | AE5: CHỈ TIÊU | AF5: 45292 | AG5: 45323 | AH5: 45352 | AI5: 45383 | AJ5: 45413 | AK5: 45444 | AL5: 45474 | AM5: 45505 | AN5: 45536 | AO5: 45566 | AP5: 45597 | AQ5: 45627 | AR5: 2024 YTD | AS5: 2024 FY Budget | AT5: 45658 | AU5: 45689 | AV5: 45717 | AW5: 45748 | AX5: 45778 | AY5: 45809 | AZ5: 45839 | BA5: 45870 | BB5: 45901 | BC5: 45931 | BD5: 45962 | BE5: 45992 | BF5: 2025 YTD | BG5: 2025 FY Budget
A6: Disbursement | C6: =SUM(C7:C9) -> 223.13779 | D6: 201.39047 | E6: 152.77505 | F6: 181.82287 | G6: 229.69441 | H6: 256.22206 | I6: 320.05572 | J6: 363.26119 | K6: 395.4963 | L6: 434.77299 | M6: 473.80811 | N6: 420.42575 | O6: 470.23176 | P6: =SUM(OFFSET(Q6,0,$B$2-1):OFFSET(Q6,0,$B$3-1)) -> 0 | Q6: =SUM(Q7:Q9) -> 0 | R6: =SUM(R7:R9) -> 0 | S6: =SUM(S7:S9) -> 0 | T6: =SUM(T7:T9) -> 0 | U6: =SUM(U7:U9) -> 0 | V6: =SUM(V7:V9) -> 0 | W6: =SUM(W7:W9) -> 0 | X6: =SUM(X7:X9) -> 0 | ... AB6: =SUM(AB7:AB9) -> 0
A7: Cashloan | C7: =104585050000/10^9+4.263 -> 108.84805 | D7: 91.98835 | E7: 55.1652 | F7: 57.30889 | G7: 99.39909 | H7: 112.69616 | I7: 155.31388 | J7: 167.74406 | K7: 187.16389 | L7: 223.05886 | M7: 236.45691 | N7: 192.34919 | O7: 186.92712 | P7: =SUM(OFFSET(Q7,0,$B$2-1):OFFSET(Q7,0,$B$3-1)) -> 0
A8: Payday | C8: =38479500000/10^9 -> 38.4795 | D8: 43.961 | E8: 43.7385 | F8: 59.82 | G8: 67.741 | H8: 79.375 | I8: 93.3155 | J8: 114.003 | K8: 123.6105 | L8: 120.6545 | M8: 132.0375 | N8: 122.399 | O8: 169.8025 | P8: =SUM(OFFSET(Q8,0,$B$2-1):OFFSET(Q8,0,$B$3-1)) -> 0
A9: OD | C9: =75810236516/10^9 -> 75.810237 | D9: 65.441115 | E9: 53.871348 | F9: 64.693978 | G9: 62.554322 | H9: 64.150902 | I9: 71.426344 | J9: 81.514133 | K9: 84.72191 | L9: 91.059627 | M9: 105.3137 | N9: 105.67756 | O9: 113.50214 | P9: =SUM(OFFSET(Q9,0,$B$2-1):OFFSET(Q9,0,$B$3-1)) -> 0
A10: Balance | C10: =SUM(C11:C13) -> 6568.6498 | D10: 6990.6146 | E10: 7769.8141 | F10: 7841.8873 | G10: 8007.8578 | H10: 8577.2974 | I10: 8933.6391 | J10: 9389.6329 | K10: 9888.5933 | L10: 10496.431 | M10: 11015.993 | N10: 11280.538 | O10: 11653.887 | P10: =SUM(OFFSET(Q10,0,$B$2-1):OFFSET(Q10,0,$B$3-1)) -> 0 | Q10: =SUM(Q11:Q13) -> 0 | R10: =SUM(R11:R13) -> 0 | S10: =SUM(S11:S13) -> 0 | T10: =SUM(T11:T13) -> 0 | U10: =SUM(U11:U13) -> 0 | V10: =SUM(V11:V13) -> 0 | W10: =SUM(W11:W13) -> 0 | X10: =SUM(X11:X13) -> 0 | ... AB10: =SUM(AB11:AB13) -> 0
A11: Deposit | C11: =5673632553487/10^9 -> 5673.6326 | D11: 5985.4749 | E11: 6648.7962 | F11: 6605.514 | G11: 6625.9513 | H11: 7043.2664 | I11: 7299.9562 | J11: 7420.9175 | K11: 7660.9151 | L11: 7995.1687 | M11: 8274.0444 | N11: 8302.5022 | O11: 8480.7301 | P11: =SUM(OFFSET(Q11,0,$B$2-1):OFFSET(Q11,0,$B$3-1)) -> 0
A12: Lending | C12: =464182732087/10^9 -> 464.18273 | D12: 548.28836 | E12: 586.4096 | F12: 627.47499 | G12: 707.96482 | H12: 797.51277 | I12: 1017.9536 | J12: 1304.91 | K12: 1493.3742 | L12: 1695.5337 | M12: 1900.5866 | N12: 2052.4385 | O12: 2208.6912 | P12: =SUM(OFFSET(Q12,0,$B$2-1):OFFSET(Q12,0,$B$3-1)) -> 0
A13: Credit card | C13: =430834551930/10^9 -> 430.83455 | D13: 456.85133 | E13: 534.60833 | F13: 608.89833 | G13: 673.94167 | H13: 736.51824 | I13: 615.72933 | J13: 663.80537 | K13: 734.30399 | L13: 805.72849 | M13: 841.3621 | N13: 925.5971 | O13: 964.46527 | P13: =SUM(OFFSET(Q13,0,$B$2-1):OFFSET(Q13,0,$B$3-1)) -> 0
A14: REVENUE | B14: =P14/BG14 -> 0.64021911 | C14: =SUM(OFFSET(D14,0,$B$2-1):OFFSET(D14,0,$B$3-1)) -> 1268.0859 | D14: 65.089663 | E14: 64.885127 | F14: 71.156486 | G14: 75.007954 | H14: 85.291264 | I14: 103.96575 | J14: 136.4 | K14: 158.66772 | L14: 147.60043 | M14: 179.22531 | N14: 180.79622 | O14: 201.77328 | P14: =SUM(OFFSET(Q14,0,$B$2-1):OFFSET(Q14,0,$B$3-1)) -> 2214.4411 | Q14: 175.89947 | R14: 164.43364 | S14: 193.3508 | T14: 207.73738 | U14: 233.49353 | V14: 249.8301 | W14: 288.30868 | X14: 323.17577 | Y14: 378.21176 | AE14: REVENUE | AF14: 76.361358 | AG14: 75.639602 | AH14: 89.144128 | AI14: 103.58462 | AJ14: 119.25741 | AK14: 133.78752 | AL14: 147.33206 | AM14: 159.45381 | AN14: 172.66297 | AO14: 188.54409 | AP14: 202.67058 | AQ14: 224.48205 | AR14: =SUM(OFFSET(AF14,0,$B$2-1):OFFSET(AF14,0,$B$3-1)) -> 1468.4381 | AS14: =SUM(AF14:AQ14) -> 1692.9202 | AT14: 192.3483 | AU14: 206.75999 | AV14: 223.92553 | AW14: 240.60487 | AX14: 258.06475 | AY14: 274.81788 | AZ14: 292.26338 | BA14: 309.4525 | BB14: 333.9849 | BC14: 344.99816 | BD14: 363.09028 | BE14: 418.56953 | BF14: =SUM(OFFSET(AT14,0,$B$2-1):OFFSET(AT14,0,$B$3-1)) -> 3040.3106 | BG14: =SUM(AT14:BE14) -> 3458.8801
A15: EXPENSE | B15: =P15/BG15 -> 0.59071707 | C15: =SUM(OFFSET(D15,0,$B$2-1):OFFSET(D15,0,$B$3-1)) -> 569.91307 | D15: 38.990543 | E15: 38.557637 | F15: 40.01737 | G15: 37.6 | H15: 41.080038 | I15: 41.844071 | J15: 63.091627 | K15: 66.073304 | L15: 64.281654 | M15: 69.767832 | N15: 68.608996 | O15: 73.830938 | P15: =SUM(OFFSET(Q15,0,$B$2-1):OFFSET(Q15,0,$B$3-1)) -> 665.79169 | Q15: 60.596165 | R15: 58.535619 | S15: 66.146837 | T15: 67.024054 | U15: 74.810398 | V15: 72.353886 | W15: 83.685087 | X15: 89.812774 | Y15: 92.826868 | AE15: EXPENSE | AF15: 34.261358 | AG15: 36.739602 | AH15: 37.844128 | AI15: 43.084616 | AJ15: 46.657413 | AK15: 49.387519 | AL15: 51.332059 | AM15: 54.853814 | AN15: 58.062968 | AO15: 61.844089 | AP15: 65.670581 | AQ15: 33.082046 | AR15: =SUM(OFFSET(AF15,0,$B$2-1):OFFSET(AF15,0,$B$3-1)) -> 539.73815 | AS15: =SUM(AF15:AQ15) -> 572.82019 | AT15: =AT14-AT16 -> 59.663763 | AU15: =AU14-AU16 -> 65.941375 | AV15: =AV14-AV16 -> 72.724618 | AW15: =AW14-AW16 -> 79.441977 | AX15: =AX14-AX16 -> 85.68105 | AY15: =AY14-AY16 -> 91.509141 | AZ15: =AZ14-AZ16 -> 97.355548 | BA15: =BA14-BA16 -> 103.21068 | ... BE15: =BE14-BE16 -> 125.63807 | BF15: =SUM(OFFSET(AT15,0,$B$2-1):OFFSET(AT15,0,$B$3-1)) -> 1001.4526 | BG15: =SUM(AT15:BE15) -> 1127.0906
A16: Total TOI | B16: =P16/BG16 -> 0.66414635 | C16: =SUM(OFFSET(D16,0,$B$2-1):OFFSET(D16,0,$B$3-1)) -> 698.17286 | D16: 26.09912 | E16: 26.327489 | F16: 31.139116 | G16: 37.407954 | H16: 44.211226 | I16: 62.121678 | J16: 73.308373 | K16: 92.594417 | L16: 83.318778 | M16: 109.45748 | N16: 112.18722 | O16: 127.94235 | P16: =SUM(OFFSET(Q16,0,$B$2-1):OFFSET(Q16,0,$B$3-1)) -> 1548.6494 | Q16: =Q14-Q15 -> 115.30331 | R16: =R14-R15 -> 105.89802 | S16: =S14-S15 -> 127.20397 | T16: =T14-T15 -> 140.71332 | U16: =U14-U15 -> 158.68313 | V16: =V14-V15 -> 177.47622 | W16: =W14-W15 -> 204.62359 | X16: =X14-X15 -> 233.363 | ... AB16: =AB14-AB15 -> 0 | AE16: Total TOI | AF16: =AF17+AF21+AF24 -> 42.1 | AG16: =AG17+AG21+AG24 -> 38.9 | AH16: =AH17+AH21+AH24 -> 51.3 | AI16: =AI17+AI21+AI24 -> 60.5 | AJ16: =AJ17+AJ21+AJ24 -> 72.6 | AK16: =AK17+AK21+AK24 -> 84.4 | AL16: =AL17+AL21+AL24 -> 96 | AM16: =AM17+AM21+AM24 -> 104.6 | ... AQ16: =AQ17+AQ21+AQ24 -> 191.4 | AR16: =SUM(OFFSET(AF16,0,$B$2-1):OFFSET(AF16,0,$B$3-1)) -> 928.7 | AS16: =SUM(AF16:AQ16) -> 1120.1 | AT16: =AT17+AT21+AT24 -> 132.68453 | AU16: =AU17+AU21+AU24 -> 140.81862 | AV16: =AV17+AV21+AV24 -> 151.20091 | AW16: =AW17+AW21+AW24 -> 161.1629 | AX16: =AX17+AX21+AX24 -> 172.3837 | AY16: =AY17+AY21+AY24 -> 183.30874 | AZ16: =AZ17+AZ21+AZ24 -> 194.90783 | BA16: =BA17+BA21+BA24 -> 206.24182 | ... BE16: =BE17+BE21+BE24 -> 292.93145 | BF16: =SUM(OFFSET(AT16,0,$B$2-1):OFFSET(AT16,0,$B$3-1)) -> 2038.858 | BG16: =SUM(AT16:BE16) -> 2331.7894
A17: TOI of Liabilities | B17: =P17/BG17 -> 0.46070863 | C17: =SUM(D17:O17) -> 131.51851 | D17: 5.4542925 | E17: 4.383529 | F17: 9.1201571 | G17: 7 | H17: 5.4949001 | I17: 9.2604819 | J17: 7.801 | K17: 23.244424 | L17: 5.98 | M17: 19.32959 | N17: 11.9 | O17: 22.550141 | P17: =SUM(OFFSET(Q17,0,$B$2-1):OFFSET(Q17,0,$B$3-1)) -> 101.23719 | Q17: =Q18+Q19+Q20 -> 7.0133013 | R17: =R18+R19+R20 -> 7.5874353 | S17: =S18+S19+S20 -> 9.6820502 | T17: =T18+T19+T20 -> 11.360376 | U17: =U18+U19+U20 -> 13.075268 | V17: =V18+V19+V20 -> 12.200694 | W17: =W18+W19+W20 -> 13.701581 | X17: =X18+X19+X20 -> 13.051334 | ... AB17: =AB18+AB19+AB20 -> 0 | AE17: TOI of Liabilities | AF17: =SUM(AF18:AF20) -> 4.7 | AG17: =SUM(AG18:AG20) -> 5 | AH17: =SUM(AH18:AH20) -> 5.3 | AI17: =SUM(AI18:AI20) -> 5.7 | AJ17: =SUM(AJ18:AJ20) -> 6 | AK17: =SUM(AK18:AK20) -> 6.3 | AL17: =SUM(AL18:AL20) -> 6.5 | AM17: =SUM(AM18:AM20) -> 6.9 | ... AQ17: =SUM(AQ18:AQ20) -> 53.2 | AR17: =SUM(OFFSET(AF17,0,$B$2-1):OFFSET(AF17,0,$B$3-1)) -> 69 | AS17: =SUM(AF17:AQ17) -> 122.2 | AT17: =SUM(AT18:AT20) -> 10.022243 | AU17: =SUM(AU18:AU20) -> 10.68841 | AV17: =SUM(AV18:AV20) -> 11.760151 | AW17: =SUM(AW18:AW20) -> 12.829728 | AX17: =SUM(AX18:AX20) -> 13.844686 | AY17: =SUM(AY18:AY20) -> 14.74943 | AZ17: =SUM(AZ18:AZ20) -> 15.969795 | BA17: =SUM(BA18:BA20) -> 16.576801 | ... BE17: =SUM(BE18:BE20) -> 58.238777 | BF17: =SUM(OFFSET(AT17,0,$B$2-1):OFFSET(AT17,0,$B$3-1)) -> 161.50355 | BG17: =SUM(AT17:BE17) -> 219.74233
A18: TOI of Deposit | B18: =P18/BG18 -> 0.6084021 | C18: =SUM(D18:O18) -> 71.212918 | D18: 5.337681 | E18: 4.3534391 | F18: 6.3877329 | G18: 6.4 | H18: 5.3 | I18: 5.55 | J18: 6.266 | K18: 6.7 | L18: 6.22 | M18: 6.047924 | N18: 7 | O18: 5.650141 | P18: =SUM(OFFSET(Q18,0,$B$2-1):OFFSET(Q18,0,$B$3-1)) -> 93.820369 | Q18: 6.4134101 | R18: 7.0545337 | S18: 9.3597592 | T18: 10.705649 | U18: 10.2 | V18: 12.108847 | W18: 12.103127 | X18: 12.643311 | Y18: 13.231732 | AE18: TOI of Deposit | AF18: 4.6 | AG18: 4.9 | AH18: 5.2 | AI18: 5.5 | AJ18: 5.8 | AK18: 6.1 | AL18: 6.3 | AM18: 6.6 | AN18: 6.9 | AO18: 7.2 | AP18: 7.5 | AQ18: 7.8 | AR18: =SUM(OFFSET(AF18,0,$B$2-1):OFFSET(AF18,0,$B$3-1)) -> 66.6 | AS18: =SUM(AF18:AQ18) -> 74.4 | AT18: 7.2718333 | AU18: 8.3918333 | AV18: 9.5046167 | AW18: 10.611017 | AX18: 11.647783 | AY18: 12.570917 | AZ18: 13.50625 | BA18: 14.411283 | BB18: 15.286017 | BC18: 16.17295 | BD18: 17.072083 | BE18: 17.76125 | BF18: =SUM(OFFSET(AT18,0,$B$2-1):OFFSET(AT18,0,$B$3-1)) -> 136.44658 | BG18: =SUM(AT18:BE18) -> 154.20783
A19: TOI of Fee income | B19: =P19/BG19 -> -0.25557913 | C19: =SUM(D19:O19) -> 19.70284 | D19: 0.073660276 | E19: 0.030089906 | F19: 2.7324241 | G19: 0.4 | H19: -0.1 | I19: 2.94 | J19: -0.265 | K19: -0.3 | L19: -0.34 | M19: 13.181666 | N19: 0.35 | O19: 1 | P19: =SUM(OFFSET(Q19,0,$B$2-1):OFFSET(Q19,0,$B$3-1)) -> -3.3175444 | Q19: -0.21010883 | R19: =-293.09842/1000 -> -0.29309842 | S19: -0.17770902 | T19: -0.37827312 | U19: =-0.363 -> -0.363 | V19: -0.39340749 | W19: -0.48904613 | X19: -0.46231739 | Y19: -0.55058396 | AE19: TOI of Fee income | AF19: 0.1 | AG19: 0.1 | AH19: 0.1 | AI19: 0.2 | AJ19: 0.2 | AK19: 0.2 | AL19: 0.2 | AM19: 0.3 | AN19: 0.3 | AO19: 0.3 | AP19: 0.4 | AQ19: 0.4 | AR19: =SUM(OFFSET(AF19,0,$B$2-1):OFFSET(AF19,0,$B$3-1)) -> 2.4 | AS19: =SUM(AF19:AQ19) -> 2.8 | AT19: 1.2184095 | AU19: 1.1645765 | AV19: 1.1235339 | AW19: 1.0867112 | AX19: 1.0649029 | AY19: 1.0465136 | AZ19: 1.0315451 | BA19: 1.0335177 | BB19: 1.0377768 | BC19: 1.0443237 | BD19: 1.0531597 | BE19: 1.0755271 | BF19: =SUM(OFFSET(AT19,0,$B$2-1):OFFSET(AT19,0,$B$3-1)) -> 11.904971 | BG19: =SUM(AT19:BE19) -> 12.980498
A20: Other TOI | B20: =P20/BG20 -> 0.20425398 | C20: =SUM(D20:O20) -> 40.602757 | D20: 0.042951221 | E20: 3.0737917e-08 | G20: 0.2 | H20: 0.29490013 | I20: 0.77048189 | J20: 1.8 | K20: 16.844424 | L20: 0.1 | M20: 0.1 | N20: 4.55 | O20: 15.9 | P20: =SUM(OFFSET(Q20,0,$B$2-1):OFFSET(Q20,0,$B$3-1)) -> 10.734364 | Q20: 0.81 | R20: =826/1000 -> 0.826 | S20: 0.5 | T20: 1.033 | U20: 3.2382683 | V20: 0.485255 | W20: 2.0875 | X20: 0.87034044 | Y20: 0.884 | AE20: Other TOI | AQ20: 45 | AR20: =SUM(OFFSET(AF20,0,$B$2-1):OFFSET(AF20,0,$B$3-1)) -> 0 | AS20: =SUM(AF20:AQ20) -> 45 | AT20: 1.532 | AU20: 1.132 | AV20: 1.132 | AW20: 1.132 | AX20: 1.132 | AY20: 1.132 | AZ20: 1.432 | BA20: 1.132 | BB20: 1.132 | BC20: 1.132 | BD20: 1.132 | BE20: 39.402 | BF20: =SUM(OFFSET(AT20,0,$B$2-1):OFFSET(AT20,0,$B$3-1)) -> 13.152 | BG20: =SUM(AT20:BE20) -> 52.554
A21: TOI of Card | B21: =P21/BG21 -> 0.72797991 | C21: =SUM(D21:O21) -> 112.75678 | D21: 2.408777 | E21: 4.8955014 | F21: 1.3635527 | G21: 5.3614223 | H21: 6.8461201 | I21: 18.429695 | J21: 9.1618877 | K21: 6.8158602 | L21: 11.137047 | M21: 11.247661 | N21: 19.889255 | O21: 15.2 | P21: =SUM(OFFSET(Q21,0,$B$2-1):OFFSET(Q21,0,$B$3-1)) -> 203.3852 | Q21: =Q22+Q23 -> 13.767405 | R21: =R22+R23 -> 13.733703 | S21: =S22+S23 -> 13.579927 | T21: =T22+T23 -> 16.675694 | U21: =U22+U23 -> 23.434286 | V21: =V22+V23 -> 29.632297 | W21: =W22+W23 -> 21.186228 | X21: =X22+X23 -> 30.85078 | ... AB21: =AB22+AB23 -> 0 | AE21: TOI of Card | AF21: =SUM(AF22:AF23) -> 3.7 | AG21: =SUM(AG22:AG23) -> 4.6 | AH21: =SUM(AH22:AH23) -> 7.8 | AI21: =SUM(AI22:AI23) -> 8.7 | AJ21: =SUM(AJ22:AJ23) -> 9.5 | AK21: =SUM(AK22:AK23) -> 11.9 | AL21: =SUM(AL22:AL23) -> 12.9 | AM21: =SUM(AM22:AM23) -> 13.5 | ... AQ21: =SUM(AQ22:AQ23) -> 17.1 | AR21: =SUM(OFFSET(AF21,0,$B$2-1):OFFSET(AF21,0,$B$3-1)) -> 118.4 | AS21: =SUM(AF21:AQ21) -> 135.5 | AT21: =SUM(AT22:AT23) -> 18.257635 | AU21: =SUM(AU22:AU23) -> 18.226989 | AV21: =SUM(AV22:AV23) -> 18.950269 | AW21: =SUM(AW22:AW23) -> 19.409674 | AX21: =SUM(AX22:AX23) -> 21.04076 | AY21: =SUM(AY22:AY23) -> 22.319454 | AZ21: =SUM(AZ22:AZ23) -> 23.55813 | BA21: =SUM(BA22:BA23) -> 24.510296 | ... BE21: =SUM(BE22:BE23) -> 28.37985 | BF21: =SUM(OFFSET(AT21,0,$B$2-1):OFFSET(AT21,0,$B$3-1)) -> 251.00313 | BG21: =SUM(AT21:BE21) -> 279.38298
A22: TOI of Debit card | B22: =P22/BG22 -> 0.52160384 | C22: =SUM(D22:O22) -> 0.52089552 | D22: -2.0004205 | E22: -1.9212874 | F22: -2.7634134 | G22: -2.0568142 | H22: -2.0329462 | I22: 11.141066 | J22: 1.4348877 | K22: -1.6401398 | L22: -0.46295269 | M22: -0.29833919 | N22: 0.02125491 | O22: 1.1 | P22: =SUM(OFFSET(Q22,0,$B$2-1):OFFSET(Q22,0,$B$3-1)) -> 4.1939893 | Q22: -0.36985688 | S22: -0.10360138 | T22: -0.42228429 | U22: 0.11797397 | V22: -0.13616028 | W22: -0.057598087 | X22: 0.1991644 | Y22: 4.9663518 | AE22: TOI of Debit card | AF22: -2.4 | AG22: -2.4 | AH22: -0.4 | AI22: -0.4 | AJ22: -0.4 | AK22: 1 | AL22: 1 | AM22: 1 | AN22: 1 | AO22: 1 | AP22: 1 | AQ22: 1 | AR22: =SUM(OFFSET(AF22,0,$B$2-1):OFFSET(AF22,0,$B$3-1)) -> 0 | AS22: =SUM(AF22:AQ22) -> 1 | AT22: 0.076910362 | AU22: 0.10445036 | AV22: 0.13199036 | AW22: 0.15953036 | AX22: 0.18707036 | AY22: 0.21461036 | AZ22: 0.24215036 | BA22: 0.26969036 | BB22: =0.297230362+5.3 -> 5.5972304 | BC22: 0.32477036 | BD22: 0.35231036 | BE22: 0.37985036 | BF22: =SUM(OFFSET(AT22,0,$B$2-1):OFFSET(AT22,0,$B$3-1)) -> 7.660714 | BG22: =SUM(AT22:BE22) -> 8.0405643
A23: TOI of Credit card | B23: =P23/BG23 -> 0.73409536 | C23: =SUM(D23:O23) -> 112.23588 | D23: 4.4091975 | E23: 6.8167888 | F23: 4.1269661 | G23: 7.4182365 | H23: 8.8790663 | I23: 7.2886289 | J23: 7.727 | K23: 8.456 | L23: 11.6 | M23: 11.546 | N23: 19.868 | O23: 14.1 | P23: =SUM(OFFSET(Q23,0,$B$2-1):OFFSET(Q23,0,$B$3-1)) -> 199.19121 | Q23: 14.137262 | R23: =13733.7025684444/1000 -> 13.733703 | S23: 13.683529 | T23: 17.097979 | U23: 23.316312 | V23: 29.768457 | W23: 21.243826 | X23: 30.651616 | Y23: 35.558528 | AE23: TOI of Credit card | AF23: 6.1 | AG23: 7 | AH23: 8.2 | AI23: 9.1 | AJ23: 9.9 | AK23: 10.9 | AL23: 11.9 | AM23: 12.5 | AN23: 13.3 | AO23: 14.3 | AP23: 15.2 | AQ23: 16.1 | AR23: =SUM(OFFSET(AF23,0,$B$2-1):OFFSET(AF23,0,$B$3-1)) -> 118.4 | AS23: =SUM(AF23:AQ23) -> 134.5 | AT23: 18.180725 | AU23: 18.122539 | AV23: 18.818278 | AW23: 19.250144 | AX23: 20.85369 | AY23: 22.104844 | AZ23: 23.31598 | BA23: 24.240605 | BB23: =25.1512319990545+1.4 -> 26.551232 | BC23: 25.460843 | BD23: 26.443538 | BE23: 28 | BF23: =SUM(OFFSET(AT23,0,$B$2-1):OFFSET(AT23,0,$B$3-1)) -> 243.34242 | BG23: =SUM(AT23:BE23) -> 271.34242
A24: TOI of Lending products | B24: =P24/BG24 -> 0.67883517 | C24: =SUM(D24:O24) -> 583.02632 | D24: 18.257274 | E24: 17.003229 | F24: 20.569212 | G24: 24.99622 | H24: 31.967651 | I24: 37.734202 | J24: 52.320522 | K24: 62.543391 | L24: 66.231432 | M24: 78.884186 | N24: 80.419 | O24: 92.1 | P24: =SUM(OFFSET(Q24,0,$B$2-1):OFFSET(Q24,0,$B$3-1)) -> 1244.0769 | Q24: =SUM(Q25:Q29) -> 94.769915 | R24: =SUM(R25:R29) -> 84.284106 | S24: =SUM(S25:S29) -> 103.95841 | T24: =SUM(T25:T29) -> 112.74795 | U24: =SUM(U25:U29) -> 122.2 | V24: =SUM(V25:V29) -> 135.62717 | W24: =SUM(W25:W29) -> 169.73407 | X24: =SUM(X25:X29) -> 189.46095 | ... AB24: =SUM(AB25:AB29) -> 0 | AE24: TOI of Lending products | AF24: =SUM(AF25:AF29) -> 33.7 | AG24: =SUM(AG25:AG29) -> 29.3 | AH24: =SUM(AH25:AH29) -> 38.2 | AI24: =SUM(AI25:AI29) -> 46.1 | AJ24: =SUM(AJ25:AJ29) -> 57.1 | AK24: =SUM(AK25:AK29) -> 66.2 | AL24: =SUM(AL25:AL29) -> 76.6 | AM24: =SUM(AM25:AM29) -> 84.2 | ... AQ24: =SUM(AQ25:AQ29) -> 121.1 | AR24: =SUM(OFFSET(AF24,0,$B$2-1):OFFSET(AF24,0,$B$3-1)) -> 741.3 | AS24: =SUM(AF24:AQ24) -> 862.4 | AT24: =SUM(AT25:AT29) -> 104.40465 | AU24: =SUM(AU25:AU29) -> 111.90322 | AV24: =SUM(AV25:AV29) -> 120.4905 | AW24: =SUM(AW25:AW29) -> 128.92349 | AX24: =SUM(AX25:AX29) -> 137.49826 | AY24: =SUM(AY25:AY29) -> 146.23986 | AZ24: =SUM(AZ25:AZ29) -> 155.3799 | BA24: =SUM(BA25:BA29) -> 165.15473 | ... BE24: =SUM(BE25:BE29) -> 206.31283 | BF24: =SUM(OFFSET(AT24,0,$B$2-1):OFFSET(AT24,0,$B$3-1)) -> 1626.3513 | BG24: =SUM(AT24:BE24) -> 1832.6641
A25: TOI Vay kỳ hạn | B25: =P25/BG25 -> 0.70171083 | C25: =SUM(D25:O25) -> 416.72574 | D25: 11.314543 | E25: 10.03958 | F25: 11.664783 | G25: 15.035967 | H25: 20.488776 | I25: 24.78855 | J25: 40.697373 | K25: 45.272138 | L25: 48.583965 | M25: 59.440069 | N25: 61.5 | O25: 67.9 | P25: =SUM(OFFSET(Q25,0,$B$2-1):OFFSET(Q25,0,$B$3-1)) -> 996.00471 | Q25: 72.488775 | R25: =63843.9932084444/1000 -> 63.843993 | S25: 79.661951 | T25: ='Slide 2025'!H141 -> 89.130891 | U25: 97.5 | V25: 111.4093 | W25: 140.25025 | X25: 155.61405 | Y25: 186.1055 | AE25: TOI Vay kỳ hạn | AF25: 22.8 | AG25: 20.4 | AH25: 27.4 | AI25: 33.5 | AJ25: 41.5 | AK25: 47.5 | AL25: 52.8 | AM25: 55.9 | AN25: 60.4 | AO25: 66.2 | AP25: 70.9 | AQ25: 74.8 | AR25: =SUM(OFFSET(AF25,0,$B$2-1):OFFSET(AF25,0,$B$3-1)) -> 499.3 | AS25: =SUM(AF25:AQ25) -> 574.1 | AT25: 79.909379 | AU25: 86.021582 | AV25: 92.886533 | AW25: 99.681596 | AX25: 106.49004 | AY25: 113.41831 | AZ25: 120.58744 | BA25: 128.29637 | BB25: 136.2201 | BC25: 144.03172 | BD25: 151.87882 | BE25: 159.97291 | BF25: =SUM(OFFSET(AT25,0,$B$2-1):OFFSET(AT25,0,$B$3-1)) -> 1259.4219 | BG25: =SUM(AT25:BE25) -> 1419.3948
A26: TOI Vay ngắn ngày | B26: =P26/BG26 -> 0.80071949 | C26: =SUM(D26:O26) -> 119.45184 | D26: 4.5584224 | E26: 4.6202345 | F26: 6.0534337 | G26: 7.1014075 | H26: 8.4765154 | I26: 9.5441906 | J26: 8.7413173 | K26: 12.894384 | L26: 12.829769 | M26: 13.946168 | N26: 13.086 | O26: 17.6 | P26: =SUM(OFFSET(Q26,0,$B$2-1):OFFSET(Q26,0,$B$3-1)) -> 179.25145 | Q26: 15.505887 | R26: =14034.8572681111/1000 -> 14.034857 | S26: 16.682503 | T26: ='Slide 2025'!H202 -> 16.120455 | U26: 16.6 | V26: 16.107793 | W26: 21.318024 | X26: 25.749059 | Y26: 37.132869 | AE26: TOI Vay ngắn ngày | AF26: 7 | AG26: 4.9 | AH26: 6.4 | AI26: 7.1 | AJ26: 7.2 | AK26: 7.1 | AL26: 8.7 | AM26: 9 | AN26: 9.1 | AO26: 10 | AP26: 10.1 | AQ26: 10 | AR26: =SUM(OFFSET(AF26,0,$B$2-1):OFFSET(AF26,0,$B$3-1)) -> 86.6 | AS26: =SUM(AF26:AQ26) -> 96.6 | AT26: 16.012009 | AU26: 16.526957 | AV26: 17.173725 | AW26: 17.602274 | AX26: 18.038841 | AY26: 18.477187 | AZ26: 18.911118 | BA26: 19.343552 | BB26: 19.773786 | BC26: 20.220229 | BD26: 20.674673 | BE26: 21.108626 | BF26: =SUM(OFFSET(AT26,0,$B$2-1):OFFSET(AT26,0,$B$3-1)) -> 202.75435 | BG26: =SUM(AT26:BE26) -> 223.86298
A27: TOI Overdraft | B27: =P27/BG27 -> 0.41556808 | C27: =SUM(D27:O27) -> 44.023575 | D27: 2.3843083 | E27: 2.3434152 | F27: 2.8509951 | G27: 2.8588454 | H27: 2.9523596 | I27: 3.2905094 | J27: 2.6855987 | K27: 4.0848969 | L27: 4.4626971 | M27: 4.9979495 | N27: 5.212 | O27: 5.9 | P27: =SUM(OFFSET(Q27,0,$B$2-1):OFFSET(Q27,0,$B$3-1)) -> 54.473487 | Q27: 6.0033602 | R27: =5473.89711111111/1000 -> 5.4738971 | S27: 6.3746954 | T27: ='Slide 2025'!H172 -> 6.3344924 | U27: 6.7 | V27: 6.4882581 | W27: 6.4087893 | X27: 5.7167435 | Y27: 4.9732508 | AE27: TOI Overdraft | AF27: 2.8 | AG27: 2.9 | AH27: 2.8 | AI27: 2.7 | AJ27: 2.7 | AK27: 2.6 | AL27: 2.7 | AM27: 2.9 | AN27: 3 | AO27: 3.1 | AP27: 3.2 | AQ27: 3.1 | AR27: =SUM(OFFSET(AF27,0,$B$2-1):OFFSET(AF27,0,$B$3-1)) -> 31.4 | AS27: =SUM(AF27:AQ27) -> 34.5 | AT27: 7.3786114 | AU27: 7.7509983 | AV27: 8.1869764 | AW27: 8.7561859 | AX27: 9.4148165 | AY27: 10.084609 | AZ27: 10.871214 | BA27: 11.726317 | BB27: 12.659272 | BC27: 13.660911 | BD27: 14.734488 | BE27: 15.857581 | BF27: =SUM(OFFSET(AT27,0,$B$2-1):OFFSET(AT27,0,$B$3-1)) -> 115.2244 | BG27: =SUM(AT27:BE27) -> 131.08198
A28: TOI TW | B28: =P28/BG28 -> 0 | C28: =SUM(D28:O28) -> 0 | P28: =SUM(OFFSET(Q28,0,$B$2-1):OFFSET(Q28,0,$B$3-1)) -> 0 | AE28: TOI TW | AF28: 0.2 | AG28: 0.2 | AH28: 0.3 | AI28: -0.2 | AJ28: 0.6 | AK28: 1.5 | AL28: 2.6 | AM28: 4 | AN28: 5.6 | AO28: 7 | AP28: 8.4 | AQ28: 10.2 | AR28: =SUM(OFFSET(AF28,0,$B$2-1):OFFSET(AF28,0,$B$3-1)) -> 30.2 | AS28: =SUM(AF28:AQ28) -> 40.4 | AT28: 0.32277778 | AU28: 0.64200165 | AV28: 1.0378222 | AW28: 1.4771993 | AX28: 1.9561835 | AY28: 2.4716098 | AZ28: 3.0217052 | BA28: 3.6042589 | BB28: 4.2172429 | BC28: 4.8591794 | BD28: 5.5265922 | BE28: 6.2147711 | BF28: =SUM(OFFSET(AT28,0,$B$2-1):OFFSET(AT28,0,$B$3-1)) -> 29.136573 | BG28: =SUM(AT28:BE28) -> 35.351344
A29: TOI Paylater | B29: =P29/BG29 -> 0.62452487 | C29: =SUM(D29:O29) -> 2.8251561 | H29: 0.05 | I29: 0.11095187 | J29: 0.19623293 | K29: 0.29197129 | L29: 0.355 | M29: 0.5 | N29: 0.621 | O29: 0.7 | P29: =SUM(OFFSET(Q29,0,$B$2-1):OFFSET(Q29,0,$B$3-1)) -> 14.347212 | Q29: 0.77189184 | R29: =931.357997666667/1000 -> 0.931358 | S29: 1.2392599 | T29: 1.1621162 | U29: 1.4 | V29: 1.6218176 | W29: 1.7570116 | X29: 2.3811003 | Y29: 3.0826563 | AE29: TOI Paylater | AF29: 0.9 | AG29: 0.9 | AH29: 1.3 | AI29: 3 | AJ29: 5.1 | AK29: 7.5 | AL29: 9.8 | AM29: 12.4 | AN29: 15 | AO29: 17.6 | AP29: 20.3 | AQ29: 23 | AR29: =SUM(OFFSET(AF29,0,$B$2-1):OFFSET(AF29,0,$B$3-1)) -> 93.8 | AS29: =SUM(AF29:AQ29) -> 116.8 | AT29: 0.78187777 | AU29: 0.96168121 | AV29: 1.2054396 | AW29: 1.4062376 | AX29: 1.5983722 | AY29: 1.7881455 | AZ29: 1.9884248 | BA29: 2.1842275 | BB29: 2.3927852 | BC29: 2.6252157 | BD29: 2.8816603 | BE29: 3.1589355 | BF29: =SUM(OFFSET(AT29,0,$B$2-1):OFFSET(AT29,0,$B$3-1)) -> 19.814067 | BG29: =SUM(AT29:BE29) -> 22.973003
