Workbook
Name __S1: {"Book1"}
Name __S1: {"Book1"}
Name _a1: {"'Sheet1'!$L$16"}
Name _a1: {"'Sheet1'!$L$16"}
Name _S1: {"Book1"}
Name _S1: {"Book1"}
Name Ă: #REF!
Name Ạ196: #REF!
Name â259: #REF!
Name â259: #REF!
Name â312: #REF!
Name â312: #REF!
Name Acquisition_PlanA: #REF!
Name Acquisition_PlanB: #REF!
Name Actual: (PeriodInActual*(#REF!>0))*PeriodInPlan
Name Actual: (PeriodInActual*(#REF!>0))*PeriodInPlan
Name ActualBeyond: PeriodInActual*(#REF!>0)
Name ActualBeyond: PeriodInActual*(#REF!>0)
Name adf: #REF!
Name adf: #REF!
Name AdvIncQ12020: #REF!
Name AdvIncQ12021: #REF!
Name AdvIncQ12022: #REF!
Name AdvIncQ12023: #REF!
Name AdvIncQ12024: #REF!
Name AdvIncQ22020: #REF!
Name AdvIncQ22021: #REF!
Name AdvIncQ22022: #REF!
Name AdvIncQ22023: #REF!
Name AdvIncQ22024: #REF!
Name AdvIncQ32020: #REF!
Name AdvIncQ32021: #REF!
Name AdvIncQ32022: #REF!
Name AdvIncQ32023: #REF!
Name AdvIncQ32024: #REF!
Name AdvIncQ42020: #REF!
Name AdvIncQ42021: #REF!
Name AdvIncQ42022: #REF!
Name AdvIncQ42023: #REF!
Name AdvIncQ42024: #REF!
Name AdvPenRate2020: #REF!
Name AdvPenRate2021: #REF!
Name AdvPenRate2022: #REF!
Name AdvPenRate2023: #REF!
Name AdvPenRate2024: #REF!
Name AllReportList: #REF!
Name Amount_act: #REF!
Name Amount_CF: #REF!
Name Amount_F: #REF!
Name Amount_KPI_act: #REF!
Name approval: #REF!
Name approval: #REF!
Name Attribute_F: #REF!
Name B: #REF!
Name b2bSpr: #REF!
Name BaoHanhSuaChua: #REF!
Name be_KPI_bud: #REF!
Name be2B: #REF!
Name bf: #REF!
Name bf: #REF!

Sheet NOTE
A1: SAP MODEL - OVERDRAFT
N2: KHN | O2: v5 | P2: 20251001
B3: 1. Notes and disclaimer
C4: a. Giới thiệu về SAP
D5: - SAP: Single Account Profitability (Hiệu quả sản phẩm trên từng đơn vị sản phẩm)
D6: - Model SAP được sử dụng như một (01) mô hình dự đoán hiệu quả vòng đời của sản phẩm.
D7: - Do sự phức tạp của sản phẩm, các hệ thống vận hành (hệ thống hạch kế toán, hệ thống quản trị rủi ro, hệ thống quản trị…), hành vi người sử dụng hành vi người sử dụng, model chỉ có thể mô phỏng tương đối trung bình vòng đời của sản phẩm.
D8: - Do tính chất thời điểm, mô hình được xây dựng mô phỏng theo cách vận hành sản phẩm tại thời điểm phát hành. Trường hợp hệ thống thay đổi, sản phẩm thay đổi, mô hình sẽ không thể phản ánh đúng bản chất vận hành sản phẩm.
D9: - Mô hình được tính toán dựa vào các yếu tố đầu vào xác định tại thời điểm, do đó kết quả của mô hình có thể có sự khác biệt so với thực tế vận hành sản phẩm.
D10: - Mô hình SAP Overdraft tính hiệu quả dự kiến của 1 tài khoản Overdraft mở trong kỳ hoạt động 12 tháng
C12: b. Giới thiệu về PnL
D13: - Trong file tính này, Profit & Lost (PnL) được dự phóng từ trung bình cộng kết quả kinh doanh trên từng sản phẩm (SAP) với yếu tố "sale plan" (số giải ngân) qua từng tháng, do đó có thể khác biệt so với kết quả thực tế vận hành.
D14: - Dòng tiền thực tế qua từng tháng có thể khác biệt với mô hình tính toán do nhiều yếu tố tác động bên ngoài thay đổi, do đó, vui lòng chỉ sử dụng mô hình cho mục đích tham khảo.
D15: - Cho mục đích tính dự phòng dòng tiền ngắn và trung hạn, mô hình PnL được cutoff tại thời điểm 5 năm (60 tháng) kể từ ngày bắt đầu khởi chạy sản phẩm đầu tiên.
B17: 2. Instruction
D18: - Dành cho người sử dụng
E19: - Chỉ chỉnh sửa vào các ô màu vàng
E20: - 2 sheets "SAP_Leadsheet" và "Sale plan&PL" cung cấp yếu tố đầu vào và đầu ra để tính toán mô hình SAP cũng như PnL.
F21: - Sheet SAP_Leadsheet được cấu trúc 2 phần, bên trái là các yếu tố đầu vào (input) và bên phải là kết quả dự đoán (output). Đơn vị sử dụng tại bảng tính là triệu VND (mVND) và phần trăm (%)
F22: - Sheet "Sale plan & PL" được cấu trúc 2 phần, bên trên là sale plan và bên dưới là kết quả PnL
E23: - 2 sheets "SAP_Spreadsheet" và "PL projection speadsheet" là các file tính toán cho 2 sheet "SAP_Leadsheet", "Sales plan & PL"
F24: - 2 sheets được cấu trúc từ trên xuống dưới theo thứ tự tính toán mô phỏng để đưa ra kết quả kinh doanh cuối cùng
F25: - 2 sheets đã được tạm khóa. Trường hợp cần mở khóa, điều chỉnh các yếu tố, vui lòng liên hệ với nhóm vận hành để được hỗ trợ.
D27: - Dành riêng cho người vận hành, hiệu chỉnh
E28: - Cần cẩn trọng khi điều chỉnh ở các file "speadsheet" vì 1 khi sai lệch rất khó tìm ra lỗi (VD: sửa nhầm ô, link nhầm vị trí,…)
B31: 3. Legend
C33: GENERAL INPUT
G35: Diễn giải | L35: Chú thích
D36: Risk input | G36: Loại phương pháp tính rủi ro | L36: Lựa chon phương pháp tính rủi ro VAS và IFRS
D37: Write off | G37: Thời điểm WO | L37: Lựa chọn thời điểm ghi nhận WO là 360 hoặc 180
C38: REVENUE INPUT
G40: Diễn giải | L40: Chú thích
C41: Amount & Tenor
D42: Average active balance | G42: Trung bình dư nợ/1 tài khoản có dư nợ/ngày | L42: =toàn bộ dư nợ theo từng ngày của toàn bộ tài khoản có dư nợ/(số ngày có dư nợ * số tài khoản có dư nợ theo từng ngày).
D43: Payment Method | G43: Phương pháp tính lãi | L43: Bullet payment- hàng tháng trả lãi, cuối kỳ trả gốc
D44: Nominal Tenor | G44: Thời hạn vay trung bình (active) | L44: Thời hạn trung bình giữ dư nợ của 1 khoản vay active
D45: Maturity to Termination | G45: Thời hạn từ lúc đáo hạn tới lúc tới khi ra ngoại bảng | L45: Nên để 6 tháng để khớp với hệ thống kế toán, rủi ro đang ghi nhận WO180+
D46: Month on book | G46: Thời gian ghi nhận trên sổ sách | L46: = Nominal tenor + Maturity to termination
C48: Pricing
D49: From- To | G49: Từ tháng… tới tháng
...

Sheet DATA
B1: =Leadsheet!G6 -> Q1
B2: Mapping | C2: Value
A3: Average active balance | B3: AVG Ticket size | C3: =INDEX($F$26:$Y$27,MATCH($B$1,$F$26:$F$27,0),MATCH($B3,$F$26:$Y$26,0)) -> 8.3820479
A4: Nominal Tenor | B4: AVG Tenor | C4: =INDEX($F$26:$Y$27,MATCH($B$1,$F$26:$F$27,0),MATCH($B4,$F$26:$Y$26,0)) -> 9
A5: IR | B5: IR | C5: =INDEX($F$26:$Y$27,MATCH($B$1,$F$26:$F$27,0),MATCH($B5,$F$26:$Y$26,0)) -> 0.34950821
A6: COF | B6: COF | C6: =INDEX($F$26:$Y$27,MATCH($B$1,$F$26:$F$27,0),MATCH($B6,$F$26:$Y$26,0)) -> 0.066359342
A7: Loan grant fee | B7: Limit fee | C7: =INDEX($F$26:$Y$27,MATCH($B$1,$F$26:$F$27,0),MATCH($B7,$F$26:$Y$26,0)) -> 0.1512425
A8: Underwriting cost & Score | B8: UW | C8: =INDEX($F$26:$Y$27,MATCH($B$1,$F$26:$F$27,0),MATCH($B8,$F$26:$Y$26,0)) -> 0.014026942
A9: Disbursement cost | B9: Disburse cost | C9: =INDEX($F$26:$Y$27,MATCH($B$1,$F$26:$F$27,0),MATCH($B9,$F$26:$Y$26,0)) -> 0.00082621508
A10: Approval rate | B10: Aprroval rate | C10: =INDEX($F$26:$Y$27,MATCH($B$1,$F$26:$F$27,0),MATCH($B10,$F$26:$Y$26,0)) -> 0.14382507
A11: Disbursement rate | B11: Signed rate | C11: =INDEX($F$26:$Y$27,MATCH($B$1,$F$26:$F$27,0),MATCH($B11,$F$26:$Y$26,0)) -> 0.85010707
A12: Collections_all | B12: Collection | C12: =INDEX($F$26:$Y$27,MATCH($B$1,$F$26:$F$27,0),MATCH($B12,$F$26:$Y$26,0)) -> 0.004036068
A13: Email & SMS | B13: SMS | C13: =INDEX($F$26:$Y$27,MATCH($B$1,$F$26:$F$27,0),MATCH($B13,$F$26:$Y$26,0)) -> 7.6532027e-06
A14: Direct HR | B14: Direct HR cost | C14: =INDEX($AA$26:$AE$30,MATCH($B14,$AA$26:$AA$30,0),MATCH($B$1,$AA$26:$AE$26,0)) -> 0.0075933848
A15: Indirect HR | B15: Indirect HR cost | C15: =INDEX($AA$26:$AE$30,MATCH($B15,$AA$26:$AA$30,0),MATCH($B$1,$AA$26:$AE$26,0)) -> 0.018032513
A16: IT | B16: Indirect system cost | C16: =INDEX($AA$26:$AE$30,MATCH($B16,$AA$26:$AA$30,0),MATCH($B$1,$AA$26:$AE$26,0)) -> 0.0099529491
A17: Other supports | B17: Other indirect supporting cost | C17: =INDEX($AA$26:$AE$30,MATCH($B17,$AA$26:$AA$30,0),MATCH($B$1,$AA$26:$AE$26,0)) -> 0.0073406551
B19: %Attrition
A20: 0 | B20: =INDEX($F$26:$Y$27,MATCH($B$1,$F$26:$F$27,0),MATCH($A20,$F$26:$Y$26,0)) -> 0.05
A21: 1 | B21: =INDEX($F$26:$Y$27,MATCH($B$1,$F$26:$F$27,0),MATCH($A21,$F$26:$Y$26,0)) -> 0.1
A22: 2 | B22: =INDEX($F$26:$Y$27,MATCH($B$1,$F$26:$F$27,0),MATCH($A22,$F$26:$Y$26,0)) -> 0.03
A26: Group | B26: Partner | C26: Product | D26: Sub Product | E26: Index | F26: Period | G26: Aprroval rate | H26: Signed rate | I26: IR | J26: COF | K26: AVG Ticket size | L26: AVG Tenor | M26: Insurance rate | N26: Insurance penetration | O26: MKT | P26: UW | Q26: Collection | R26: SMS | S26: Disburse cost | T26: Limit fee | U26: Leadgen | V26: Sharing | W26: 0 | X26: 1 | Y26: 2 | AB26: Q1 | AC26: Q2 | AD26: Q3 | AE26: Q4
A27: UPL | B27: Cake | C27: Overdraft | D27: Overdraft | E27: Cake_Overdraft | F27: Q1 | G27: 0.14382507 | H27: 0.85010707 | I27: 0.34950821 | J27: 0.066359342 | K27: 8.3820479 | L27: 9 | O27: 0 | P27: 0.014026942 | Q27: 0.004036068 | R27: 7.6532027e-06 | S27: 0.00082621508 | T27: 0.1512425 | W27: 0.05 | X27: 0.1 | Y27: 0.03 | AA27: Direct HR cost | AB27: 0.0075933848
AA28: Indirect HR cost | AB28: 0.018032513
AA29: Indirect system cost | AB29: 0.0099529491
AA30: Other indirect supporting cost | AB30: 0.0073406551

Sheet Leadsheet
B1: SAP OVERDRAFT MODEL | D1: 1 | E1: =C4&C5&C6&G7&G5&G6&G4 -> OverdraftAllDPD180+Q1IFRS
B2: =NOTE!N2 -> KHN | C2: =NOTE!P2 -> 20251001 | D2: =NOTE!O2 -> v5
B4: Product | C4: Overdraft | D4: UPL | E4: Risk input | G4: IFRS | H4: =G4 -> IFRS
B5: Sub-Product | C5: All | D5: ALL | E5: Write off | G5: DPD180+ | H5: =G5 -> DPD180+
B6: Sub-Segments | D6: ALL | E6: Time | G6: Q1
H7: =G7 -> 0
B9: REVENUE INPUT | H9: Cur: mVND | K9: GENERAL OUTPUT | U9: Cur: mVND
B11: Amount & Tenor | C11: Average active balance | E11: =DATA!C3 -> 8.3820479 | N11: Life time | O11: Year 1 | P11: Year 2 | Q11: Year 3 | R11: Year 4 | S11: Year 5 | T11: % ANR | U11: % Disbursement
C12: Payment Method | E12: Bullet payment | K12: ANR | N12: =N30 -> 4.2346839 | O12: =O30 -> 4.9448101 | P12: =P30 -> 1.3941789 | Q12: =Q30 -> 0 | R12: =R30 -> 0 | S12: =S30 -> 0 | U12: =N12/$E$11 -> 0.50520875
C13: Nominal Tenor | E13: =DATA!C4 -> 9 | F13: Active time (=< 12m) | K13: TOI | N13: =SUM(N14:N16) -> 1.321896 | O13: =SUM(O14:O16) -> 1.3450252 | P13: =SUM(P14:P16) -> -0.023129199 | Q13: =SUM(Q14:Q16) -> 0 | R13: =SUM(R14:R16) -> 0 | S13: =SUM(S14:S16) -> 0 | T13: =N13/$E$15*12/$N$12 -> 0.24972745 | U13: =N13/$E$11 -> 0.15770562
C14: Maturity to Termination | E14: 6 | K14: Net interest income | N14: =N32 -> 1.1706535 | O14: =O32 -> 1.1937827 | P14: =P32 -> -0.023129199 | Q14: =Q32 -> 0 | R14: =R32 -> 0 | S14: =S32 -> 0 | T14: =N14/$E$15*12/$N$12 -> 0.22115531 | U14: =N14/$E$11 -> 0.13966199
C15: Month on book | E15: =E13+E14 -> 15 | K15: Net fee income | N15: =N35 -> 0.1512425 | O15: =O35 -> 0.1512425 | P15: =P35 -> 0 | Q15: =Q35 -> 0 | R15: =R35 -> 0 | S15: =S35 -> 0 | T15: =N15/$E$15*12/$N$12 -> 0.028572145 | U15: =N15/$E$11 -> 0.018043622
K16: Other income | N16: =N39 -> 0 | O16: =O39 -> 0 | P16: =P39 -> 0 | Q16: =Q39 -> 0 | R16: =R39 -> 0 | S16: =S39 -> 0 | T16: =N16/$E$15*12/$N$12 -> 0 | U16: =N16/$E$11 -> 0
B17: Pricing | C17: From | D17: To | E17: IR | F17: COF | G17: NIM | K17: PROVISION | N17: =N40 -> -1.3189242 | O17: =O40 -> -1.308878 | P17: =P40 -> -0.010046183 | Q17: =Q40 -> 0 | R17: =R40 -> 0 | S17: =S40 -> 0 | T17: =N17/$E$15*12/$N$12 -> -0.24916602 | U17: =N17/$E$11 -> -0.15735107
B18: Indue | C18: 1 | D18: =E13 -> 9 | E18: =DATA!C5 -> 0.34950821 | F18: =DATA!C6 -> 0.066359342 | G18: =E18-F18 -> 0.28314887 | K18: OPEX | N18: =SUM(N19:N22) -> -0.33047051 | O18: =SUM(O19:O22) -> -0.32827852 | P18: =SUM(P19:P22) -> -0.0021919861 | Q18: =SUM(Q19:Q22) -> 0 | R18: =SUM(R19:R22) -> 0 | S18: =SUM(S19:S22) -> 0 | T18: =N18/$E$15*12/$N$12 -> -0.062431203 | U18: =N18/$E$11 -> -0.039425987
A19: 1 | B19: Overdue | C19: =IF(D18="","",IF(D18>$E$13,"",D18+1)) -> 10 | D19: =E15 -> 15 | E19: =E18 -> 0.34950821 | F19: =F18 -> 0.066359342 | K19: Acquisition cost | N19: =SUM(N42) -> 0 | O19: =SUM(O42) -> 0 | P19: =SUM(P42) -> 0 | Q19: =SUM(Q42) -> 0 | R19: =SUM(R42) -> 0 | S19: =SUM(S42) -> 0 | T19: =N19/$E$15*12/$N$12 -> 0 | U19: =N19/$E$11 -> 0
A20: 2 | B20: 3 | C20: =IF(D19="","",IF(D19>$E$13,"",D19+1)) | K20: UW & Disbursal | N20: =N46 -> -0.014853157 | O20: =O46 -> -0.014853157 | P20: =P46 -> 0 | Q20: =Q46 -> 0 | R20: =R46 -> 0 | S20: =S46 -> 0 | T20: =N20/$E$15*12/$N$12 -> -0.0028060006 | U20: =N20/$E$11 -> -0.0017720201
A21: 3 | B21: 4 | K21: Collection & aftersale service | N21: =N49 -> -0.032348643 | O21: =O49 -> -0.030156657 | P21: =P49 -> -0.0021919861 | Q21: =Q49 -> 0 | R21: =R49 -> 0 | S21: =S49 -> 0 | T21: =N21/$E$15*12/$N$12 -> -0.0061111797 | U21: =N21/$E$11 -> -0.0038592768
A22: 4 | B22: 5 | K22: Support unit | N22: =N53 -> -0.28326871 | O22: =O53 -> -0.28326871 | P22: =P53 -> 0 | Q22: =Q53 -> 0 | R22: =R53 -> 0 | S22: =S53 -> 0 | T22: =N22/$E$15*12/$N$12 -> -0.053514022 | U22: =N22/$E$11 -> -0.03379469
A23: 5 | B23: 6 | K23: PBT | N23: =N13+N17+N18 -> -0.32749868 | O23: =O13+O17+O18 -> -0.29213131 | P23: =P13+P17+P18 -> -0.035367368 | Q23: =Q13+Q17+Q18 -> 0 | R23: =R13+R17+R18 -> 0 | S23: =S13+S17+S18 -> 0 | T23: =N23/$E$15*12/$N$12 -> -0.061869776 | U23: =N23/$E$11 -> -0.03907144
K24: In which: PROFIT BEFORE SU | N24: =N23-N22 -> -0.044229969 | O24: =O23-O22 -> -0.0088626013 | P24: =P23-P22 -> -0.035367368 | Q24: =Q23-Q22 -> 0 | R24: =R23-R22 -> 0 | S24: =S23-S22 -> 0 | T24: =N24/$E$15*12/$N$12 -> -0.0083557537 | U24: =N24/$E$11 -> -0.0052767498
B25: Early prepayment | C25: From | D25: To | E25: Penalty fee | F25: Penalty IR | G25: %Attrition
B26: Not Active rate | C26: 0 | D26: 0 | G26: =DATA!B20 -> 0.05 | H26: per cohort
B27: Attrition rate | C27: =IF(D26="","",IF(D26>$E$13,"",D26+1)) -> 1 | D27: 1 | G27: =DATA!B21 -> 0.1 | H27: per cohort | K27: PERFORMANCE OUTPUT | U27: Cur: mVND
C28: =IF(D27="","",IF(D27>$E$13,"",D27+1)) -> 2 | D28: =E13 -> 9 | G28: =DATA!B22 -> 0.03 | H28: per cohort
C29: =IF(D28="","",IF(D28>$E$13,"",D28+1)) -> 10 | N29: Life time | O29: Year 1 | P29: Year 2 | Q29: Year 3 | R29: Year 4 | S29: Year 5 | T29: % ANR | U29: % Disbursement
C30: =IF(D29="","",IF(D29>$E$13,"",D29+1)) | E30: =IF(D30="",0,SUMIFS(#REF!,#REF!,Leadsheet!G$24,#REF!,Leadsheet!$A31,#REF!,Leadsheet!$C$4,#REF!,Leadsheet!$G$5,#REF!,Leadsheet!$D$5,#REF!,Leadsheet!G4)) -> 0 | F30: 0 | K30: ANR | N30: =SUM(SAP_Speadsheet!$E$43:$BG$43)/COUNTIF(SAP_Speadsheet!$E$43:$BG$43,">0") -> 4.2346839 | O30: =IFERROR(SUM(SAP_Speadsheet!$E$43:$Q$43)/COUNTIF(SAP_Speadsheet!$E$43:$Q$43,">0"),0) -> 4.9448101 | P30: =IFERROR(SUM(SAP_Speadsheet!$R$43:$AC$43)/COUNTIF(SAP_Speadsheet!$R$43:$AC$43,">0"),0) -> 1.3941789 | Q30: =IFERROR(SUM(SAP_Speadsheet!$AD$43:$AO$43)/COUNTIF(SAP_Speadsheet!$AD$43:$AO$43,">0"),0) -> 0 | R30: =IFERROR(SUM(SAP_Speadsheet!$AP$43:$BA$43)/COUNTIF(SAP_Speadsheet!$AP$43:$BA$43,">0"),0) -> 0 | S30: =IFERROR(SUM(SAP_Speadsheet!$BB$43:$BG$43)/COUNTIF(SAP_Speadsheet!$BB$43:$BG$43,">0"),0) -> 0 | U30: =N30/$E$11 -> 0.50520875
C31: =IF(D30="","",IF(D30>$E$13,"",D30+1)) | E31: =IF(D31="",0,SUMIFS(#REF!,#REF!,Leadsheet!G$24,#REF!,Leadsheet!$A32,#REF!,Leadsheet!$C$4,#REF!,Leadsheet!$G$5,#REF!,Leadsheet!$D$5,#REF!,Leadsheet!G4)) -> 0 | F31: 0 | K31: TOI | N31: =SUM(O31:S31) -> 1.321896 | O31: =SUM(SAP_Speadsheet!$F$48:$Q$48) -> 1.3450252 | P31: =SUM(SAP_Speadsheet!$R$48:$AC$48) -> -0.023129199 | Q31: =SUM(SAP_Speadsheet!$AD$48:$AO$48) -> 0 | R31: =SUM(SAP_Speadsheet!$AP$48:$BA$48) -> 0 | S31: =SUM(SAP_Speadsheet!$BB$48:$BG$48) -> 0 | T31: =N31/$E$15*12/$N$30 -> 0.24972745 | U31: =N31/$E$11 -> 0.15770562
K32: Net interest income | N32: =SUM(O32:S32) -> 1.1706535 | O32: =SUM(SAP_Speadsheet!$F$50:$Q$50) -> 1.1937827 | P32: =SUM(SAP_Speadsheet!$R$50:$AC$50) -> -0.023129199 | Q32: =SUM(SAP_Speadsheet!$AD$50:$AO$50) -> 0 | R32: =SUM(SAP_Speadsheet!$AP$50:$BA$50) -> 0 | S32: =SUM(SAP_Speadsheet!$BB$50:$BG$50) -> 0 | T32: =N32/$E$15*12/$N$30 -> 0.22115531 | U32: =N32/$E$11 -> 0.13966199
B33: Monthly fee | F33: per active account/month | K33: Interest income | N33: =SUM(O33:S33) -> 1.5219171 | O33: =SUM(SAP_Speadsheet!$F$51:$Q$51) -> 1.5219171 | P33: =SUM(SAP_Speadsheet!$R$51:$AC$51) -> 0 | Q33: =SUM(SAP_Speadsheet!$AD$51:$AO$51) -> 0 | R33: =SUM(SAP_Speadsheet!$AP$51:$BA$51) -> 0 | S33: =SUM(SAP_Speadsheet!$BB$51:$BG$51) -> 0 | T33: =N33/$E$15*12/$N$30 -> 0.28751465 | U33: =N33/$E$11 -> 0.18156864
B34: Loan grant fee | E34: =DATA!C7 -> 0.1512425 | F34: per account | K34: Cost of fund | N34: =SUM(O34:S34) -> -0.35126355 | O34: =SUM(SAP_Speadsheet!$F$52:$Q$52) -> -0.32813435 | P34: =SUM(SAP_Speadsheet!$R$52:$AC$52) -> -0.023129199 | Q34: =SUM(SAP_Speadsheet!$AD$52:$AO$52) -> 0 | R34: =SUM(SAP_Speadsheet!$AP$52:$BA$52) -> 0 | S34: =SUM(SAP_Speadsheet!$BB$52:$BG$52) -> 0 | T34: =N34/$E$15*12/$N$30 -> -0.066359342 | U34: =N34/$E$11 -> -0.04190665
K35: Net fee income | N35: =SUM(O35:S35) -> 0.1512425 | O35: =SUM(SAP_Speadsheet!$F$54:$Q$54) -> 0.1512425 | P35: =SUM(SAP_Speadsheet!$R$54:$AC$54) -> 0 | Q35: =SUM(SAP_Speadsheet!$AD$54:$AO$54) -> 0 | R35: =SUM(SAP_Speadsheet!$AP$54:$BA$54) -> 0 | S35: =SUM(SAP_Speadsheet!$BB$54:$BG$54) -> 0 | T35: =N35/$E$15*12/$N$30 -> 0.028572145 | U35: =N35/$E$11 -> 0.018043622
B36: COST INPUT | H36: Cur: mVND | K36: Early termination fee | N36: =SUM(O36:S36) -> 0 | O36: =SUM(SAP_Speadsheet!$F$55:$Q$55) -> 0 | P36: =SUM(SAP_Speadsheet!$R$55:$AC$55) -> 0 | Q36: =SUM(SAP_Speadsheet!$AD$55:$AO$55) -> 0 | R36: =SUM(SAP_Speadsheet!$AP$55:$BA$55) -> 0 | S36: =SUM(SAP_Speadsheet!$BB$55:$BG$55) -> 0 | T36: =N36/$E$15*12/$N$30 -> 0 | U36: =N36/$E$11 -> 0
K37: Monthly fee | N37: =SUM(O37:S37) -> 0 | O37: =SUM(SAP_Speadsheet!$F$56:$Q$56) -> 0 | P37: =SUM(SAP_Speadsheet!$R$56:$AC$56) -> 0 | Q37: =SUM(SAP_Speadsheet!$AD$56:$AO$56) -> 0 | R37: =SUM(SAP_Speadsheet!$AP$56:$BA$56) -> 0 | S37: =SUM(SAP_Speadsheet!$BB$56:$BG$56) -> 0 | T37: =N37/$E$15*12/$N$30 -> 0 | U37: =N37/$E$11 -> 0
B38: Inflation rate | E38: 0.035 | F38: % per month | K38: Support fee | N38: =SUM(O38:S38) -> 0.1512425 | O38: =SUM(SAP_Speadsheet!$F$57:$Q$57) -> 0.1512425 | P38: =SUM(SAP_Speadsheet!$R$57:$AC$57) -> 0 | Q38: =SUM(SAP_Speadsheet!$AD$57:$AO$57) -> 0 | R38: =SUM(SAP_Speadsheet!$AP$57:$BA$57) -> 0 | S38: =SUM(SAP_Speadsheet!$BB$57:$BG$57) -> 0 | T38: =N38/$E$15*12/$N$30 -> 0.028572145 | U38: =N38/$E$11 -> 0.018043622
K39: Other income | N39: =SUM(O39:S39) -> 0 | O39: =SUM(SAP_Speadsheet!$F$59:$Q$59) -> 0 | P39: =SUM(SAP_Speadsheet!$R$59:$AC$59) -> 0 | Q39: =SUM(SAP_Speadsheet!$AD$59:$AO$59) -> 0 | R39: =SUM(SAP_Speadsheet!$AP$59:$BA$59) -> 0 | S39: =SUM(SAP_Speadsheet!$BB$59:$BG$59) -> 0 | T39: =N39/$E$15*12/$N$30 -> 0 | U39: =N39/$E$11 -> 0
B40: Acquisition cost | K40: PROVISION | N40: =SUM(O40:S40) -> -1.3189242 | O40: =SUM(SAP_Speadsheet!$F$171:$Q$171) -> -1.308878 | P40: =SUM(SAP_Speadsheet!$R$171:$AC$171) -> -0.010046183 | Q40: =SUM(SAP_Speadsheet!$AD$171:$AO$171) -> 0 | R40: =SUM(SAP_Speadsheet!$AP$171:$BA$171) -> 0 | S40: =SUM(SAP_Speadsheet!$BB$171:$BG$171) -> 0 | T40: =N40/$E$15*12/$N$30 -> -0.24916602 | U40: =N40/$E$11 -> -0.15735107
C41: Sale incentive | E41: Auto MODE | K41: OPEX | N41: =SUM(O41:S41) -> -0.33047051 | O41: =+SUM(O42,O46,O49,O53) -> -0.32827852 | P41: =+SUM(P42,P46,P49,P53) -> -0.0021919861 | Q41: =+SUM(Q42,Q46,Q49,Q53) -> 0 | R41: =+SUM(R42,R46,R49,R53) -> 0 | S41: =+SUM(S42,S46,S49,S53) -> 0 | T41: =N41/$E$15*12/$N$30 -> -0.062431203 | U41: =N41/$E$11 -> -0.039425987
C42: Sharing TOI and Risk DPD90+ | F42: % per month | K42: Acquisition cost | N42: =SUM(O42:S42) -> 0 | O42: =SUM(O43:O45) -> 0 | P42: =SUM(P43:P45) -> 0 | Q42: =SUM(Q43:Q45) -> 0 | R42: =SUM(R43:R45) -> 0 | S42: =SUM(S43:S45) -> 0 | T42: =N42/$E$15*12/$N$30 -> 0 | U42: =N42/$E$11 -> 0
C43: Sharing TOI and Risk DPD180+ | F43: % per month | K43: Lead Acquisition | N43: =SUM(O43:S43) -> 0 | O43: =SUM(SAP_Speadsheet!$F$64:$Q$64) -> 0 | P43: =SUM(SAP_Speadsheet!$R$64:$AC$64) -> 0 | Q43: =SUM(SAP_Speadsheet!$AD$64:$AO$64) -> 0 | R43: =SUM(SAP_Speadsheet!$AP$64:$BA$64) -> 0 | S43: =SUM(SAP_Speadsheet!$BB$64:$BG$64) -> 0 | T43: =N43/$E$15*12/$N$30 -> 0 | U43: =N43/$E$11 -> 0
...

Sheet SAP_Speadsheet
B1: SAP Speadsheet
D3: Method
C4: Month on book | E4: 0 | F4: =E4+1 -> 1 | G4: =F4+1 -> 2 | H4: =G4+1 -> 3 | I4: =H4+1 -> 4 | J4: =I4+1 -> 5 | K4: =J4+1 -> 6 | L4: =K4+1 -> 7 | M4: =L4+1 -> 8 | ... BM4: =BL4+1 -> 60
C5: Oustanding tenor | E5: =IF(Leadsheet!$E$13-SAP_Speadsheet!E4<0,0,Leadsheet!$E$13-SAP_Speadsheet!E4) -> 9 | F5: =IF(Leadsheet!$E$13-SAP_Speadsheet!F4<0,0,Leadsheet!$E$13-SAP_Speadsheet!F4) -> 8 | G5: =IF(Leadsheet!$E$13-SAP_Speadsheet!G4<0,0,Leadsheet!$E$13-SAP_Speadsheet!G4) -> 7 | H5: =IF(Leadsheet!$E$13-SAP_Speadsheet!H4<0,0,Leadsheet!$E$13-SAP_Speadsheet!H4) -> 6 | I5: =IF(Leadsheet!$E$13-SAP_Speadsheet!I4<0,0,Leadsheet!$E$13-SAP_Speadsheet!I4) -> 5 | J5: =IF(Leadsheet!$E$13-SAP_Speadsheet!J4<0,0,Leadsheet!$E$13-SAP_Speadsheet!J4) -> 4 | K5: =IF(Leadsheet!$E$13-SAP_Speadsheet!K4<0,0,Leadsheet!$E$13-SAP_Speadsheet!K4) -> 3 | L5: =IF(Leadsheet!$E$13-SAP_Speadsheet!L4<0,0,Leadsheet!$E$13-SAP_Speadsheet!L4) -> 2 | ... BM5: =IF(Leadsheet!$E$13-SAP_Speadsheet!BM4<0,0,Leadsheet!$E$13-SAP_Speadsheet!BM4) -> 0
C6: Last month on book | D6: Nominal Tenor + Maturity to Termination | F6: =Leadsheet!E14+Leadsheet!E13 -> 15
B8: Balance
B9: Interest rate
C10: INR rate | D10: Input table | E10: =Leadsheet!E18 -> 0.34950821 | F10: =IF(F$4>$F$6,0,VLOOKUP(SAP_Speadsheet!F$4,Leadsheet!$C$18:$F$23,3,1)) -> 0.34950821 | G10: =IF(G$4>$F$6,0,VLOOKUP(SAP_Speadsheet!G$4,Leadsheet!$C$18:$F$23,3,1)) -> 0.34950821 | H10: =IF(H$4>$F$6,0,VLOOKUP(SAP_Speadsheet!H$4,Leadsheet!$C$18:$F$23,3,1)) -> 0.34950821 | I10: =IF(I$4>$F$6,0,VLOOKUP(SAP_Speadsheet!I$4,Leadsheet!$C$18:$F$23,3,1)) -> 0.34950821 | J10: =IF(J$4>$F$6,0,VLOOKUP(SAP_Speadsheet!J$4,Leadsheet!$C$18:$F$23,3,1)) -> 0.34950821 | K10: =IF(K$4>$F$6,0,VLOOKUP(SAP_Speadsheet!K$4,Leadsheet!$C$18:$F$23,3,1)) -> 0.34950821 | L10: =IF(L$4>$F$6,0,VLOOKUP(SAP_Speadsheet!L$4,Leadsheet!$C$18:$F$23,3,1)) -> 0.34950821 | M10: =IF(M$4>$F$6,0,VLOOKUP(SAP_Speadsheet!M$4,Leadsheet!$C$18:$F$23,3,1)) -> 0.34950821 | ... BM10: =IF(BM$4>$F$6,0,VLOOKUP(SAP_Speadsheet!BM$4,Leadsheet!$C$18:$F$23,3,1)) -> 0
C11: COF rate (indue) | D11: Input table | E11: =Leadsheet!F18 -> 0.066359342 | F11: =IF(F$4>$F$6,0,VLOOKUP(SAP_Speadsheet!F$4,Leadsheet!$C$18:$F$23,4,1)) -> 0.066359342 | G11: =IF(G$4>$F$6,0,VLOOKUP(SAP_Speadsheet!G$4,Leadsheet!$C$18:$F$23,4,1)) -> 0.066359342 | H11: =IF(H$4>$F$6,0,VLOOKUP(SAP_Speadsheet!H$4,Leadsheet!$C$18:$F$23,4,1)) -> 0.066359342 | I11: =IF(I$4>$F$6,0,VLOOKUP(SAP_Speadsheet!I$4,Leadsheet!$C$18:$F$23,4,1)) -> 0.066359342 | J11: =IF(J$4>$F$6,0,VLOOKUP(SAP_Speadsheet!J$4,Leadsheet!$C$18:$F$23,4,1)) -> 0.066359342 | K11: =IF(K$4>$F$6,0,VLOOKUP(SAP_Speadsheet!K$4,Leadsheet!$C$18:$F$23,4,1)) -> 0.066359342 | L11: =IF(L$4>$F$6,0,VLOOKUP(SAP_Speadsheet!L$4,Leadsheet!$C$18:$F$23,4,1)) -> 0.066359342 | M11: =IF(M$4>$F$6,0,VLOOKUP(SAP_Speadsheet!M$4,Leadsheet!$C$18:$F$23,4,1)) -> 0.066359342 | ... BM11: =IF(BM$4>$F$6,0,VLOOKUP(SAP_Speadsheet!BM$4,Leadsheet!$C$18:$F$23,4,1)) -> 0
C12: COF rate(overdue) | E12: =IF(E4>$F$6,0,Leadsheet!$F$19) -> 0.066359342 | F12: =IF(F4>$F$6,0,Leadsheet!$F$19) -> 0.066359342 | G12: =IF(G4>$F$6,0,Leadsheet!$F$19) -> 0.066359342 | H12: =IF(H4>$F$6,0,Leadsheet!$F$19) -> 0.066359342 | I12: =IF(I4>$F$6,0,Leadsheet!$F$19) -> 0.066359342 | J12: =IF(J4>$F$6,0,Leadsheet!$F$19) -> 0.066359342 | K12: =IF(K4>$F$6,0,Leadsheet!$F$19) -> 0.066359342 | L12: =IF(L4>$F$6,0,Leadsheet!$F$19) -> 0.066359342 | ... AC12: =IF(AC4>$F$6,0,Leadsheet!$F$19) -> 0
C13: Attrition rate | D13: Input table | E13: =IF(E$4<Leadsheet!$E$13,VLOOKUP(SAP_Speadsheet!E$4,Leadsheet!$C$26:$G$30,5,1),0) -> 0.05 | F13: =IF(F$4<Leadsheet!$E$13,VLOOKUP(SAP_Speadsheet!F$4,Leadsheet!$C$26:$G$30,5,1),0) -> 0.1 | G13: =IF(G$4<Leadsheet!$E$13,VLOOKUP(SAP_Speadsheet!G$4,Leadsheet!$C$26:$G$30,5,1),0) -> 0.03 | H13: =IF(H$4<Leadsheet!$E$13,VLOOKUP(SAP_Speadsheet!H$4,Leadsheet!$C$26:$G$30,5,1),0) -> 0.03 | I13: =IF(I$4<Leadsheet!$E$13,VLOOKUP(SAP_Speadsheet!I$4,Leadsheet!$C$26:$G$30,5,1),0) -> 0.03 | J13: =IF(J$4<Leadsheet!$E$13,VLOOKUP(SAP_Speadsheet!J$4,Leadsheet!$C$26:$G$30,5,1),0) -> 0.03 | K13: =IF(K$4<Leadsheet!$E$13,VLOOKUP(SAP_Speadsheet!K$4,Leadsheet!$C$26:$G$30,5,1),0) -> 0.03 | L13: =IF(L$4<Leadsheet!$E$13,VLOOKUP(SAP_Speadsheet!L$4,Leadsheet!$C$26:$G$30,5,1),0) -> 0.03 | ... BM13: =IF(BM$4<Leadsheet!$E$13,VLOOKUP(SAP_Speadsheet!BM$4,Leadsheet!$C$26:$G$30,5,1),0) -> 0
C14: Prepayment Penalty | D14: Input table | E14: =IF(E$4<Leadsheet!$E$13,VLOOKUP(SAP_Speadsheet!E$4,Leadsheet!$C$26:$F$30,3,1),0) -> 0 | F14: =IF(F$4<Leadsheet!$E$13,VLOOKUP(SAP_Speadsheet!F$4,Leadsheet!$C$26:$F$30,3,1),0) -> 0 | G14: =IF(G$4<Leadsheet!$E$13,VLOOKUP(SAP_Speadsheet!G$4,Leadsheet!$C$26:$F$30,3,1),0) -> 0 | H14: =IF(H$4<Leadsheet!$E$13,VLOOKUP(SAP_Speadsheet!H$4,Leadsheet!$C$26:$F$30,3,1),0) -> 0 | I14: =IF(I$4<Leadsheet!$E$13,VLOOKUP(SAP_Speadsheet!I$4,Leadsheet!$C$26:$F$30,3,1),0) -> 0 | J14: =IF(J$4<Leadsheet!$E$13,VLOOKUP(SAP_Speadsheet!J$4,Leadsheet!$C$26:$F$30,3,1),0) -> 0 | K14: =IF(K$4<Leadsheet!$E$13,VLOOKUP(SAP_Speadsheet!K$4,Leadsheet!$C$26:$F$30,3,1),0) -> 0 | L14: =IF(L$4<Leadsheet!$E$13,VLOOKUP(SAP_Speadsheet!L$4,Leadsheet!$C$26:$F$30,3,1),0) -> 0 | ... BM14: =IF(BM$4<Leadsheet!$E$13,VLOOKUP(SAP_Speadsheet!BM$4,Leadsheet!$C$26:$F$30,3,1),0) -> 0
B16: BRM | C16: Account accumulated | D16: Tỉ lệ khoản vay còn tồn tại | E16: =100%-E13 -> 0.95 | F16: =IF(F4>$F$6,0,E16-F13) -> 0.85 | G16: =IF(G4>$F$6,0,F16-G13) -> 0.82 | H16: =IF(H4>$F$6,0,G16-H13) -> 0.79 | I16: =IF(I4>$F$6,0,H16-I13) -> 0.76 | J16: =IF(J4>$F$6,0,I16-J13) -> 0.73 | K16: =IF(K4>$F$6,0,J16-K13) -> 0.7 | L16: =IF(L4>$F$6,0,K16-L13) -> 0.67 | M16: =IF(M4>$F$6,0,L16-M13) -> 0.64 | ... BM16: =IF(BM4>$F$6,0,BL16-BM13) -> 0
A18: SBV | B18: Overdue | C18: Balance by Bucket/Group
A19: G1 | B19: 0 | C19: B0 | E19: =E37 -> 7.9629455 | F19: =IF(F4>=Leadsheet!$E$13,0,F37-SUM(F20:F33)) -> 6.9575188 | G19: =IF(G4>=Leadsheet!$E$13,0,G37-SUM(G20:G33)) -> 6.5683106 | H19: =IF(H4>=Leadsheet!$E$13,0,H37-SUM(H20:H33)) -> 6.1909859 | I19: =IF(I4>=Leadsheet!$E$13,0,I37-SUM(I20:I33)) -> 5.8236564 | J19: =IF(J4>=Leadsheet!$E$13,0,J37-SUM(J20:J33)) -> 5.4645328 | K19: =IF(K4>=Leadsheet!$E$13,0,K37-SUM(K20:K33)) -> 5.1127454 | L19: =IF(L4>=Leadsheet!$E$13,0,L37-SUM(L20:L33)) -> 4.7674344 | M19: =IF(M4>=Leadsheet!$E$13,0,M37-SUM(M20:M33)) -> 4.4285404 | ... BM19: =IF(BM4>=Leadsheet!$E$13,0,BM37-SUM(BM20:BM33)) -> 0
A20: G2 | B20: 30 | C20: B1 | F20: =IF(F$4>$F$6,0,E19*IF(F$5>=1,Leadsheet!$D87,Leadsheet!$E87)) -> 0.16722186 | G20: =IF(G$4>$F$6,0,F19*IF(G$5>=1,Leadsheet!$D87,Leadsheet!$E87)) -> 0.1461079 | H20: =IF(H$4>$F$6,0,G19*IF(H$5>=1,Leadsheet!$D87,Leadsheet!$E87)) -> 0.13793452 | I20: =IF(I$4>$F$6,0,H19*IF(I$5>=1,Leadsheet!$D87,Leadsheet!$E87)) -> 0.1300107 | J20: =IF(J$4>$F$6,0,I19*IF(J$5>=1,Leadsheet!$D87,Leadsheet!$E87)) -> 0.12229678 | K20: =IF(K$4>$F$6,0,J19*IF(K$5>=1,Leadsheet!$D87,Leadsheet!$E87)) -> 0.11475519 | L20: =IF(L$4>$F$6,0,K19*IF(L$5>=1,Leadsheet!$D87,Leadsheet!$E87)) -> 0.10736765 | M20: =IF(M$4>$F$6,0,L19*IF(M$5>=1,Leadsheet!$D87,Leadsheet!$E87)) -> 0.10011612 | ... AC20: =IF(AC$4>$F$6,0,AB19*IF(AC$5>=1,Leadsheet!$D87,Leadsheet!$E87)) -> 0 | AD20: =IF(AD$4>$F$6,0,AC19*Leadsheet!$D87) -> 0 | AE20: =IF(AE$4>$F$6,0,AD19*Leadsheet!$D87) -> 0 | AF20: =IF(AF$4>$F$6,0,AE19*Leadsheet!$D87) -> 0 | AG20: =IF(AG$4>$F$6,0,AF19*Leadsheet!$D87) -> 0 | AH20: =IF(AH$4>$F$6,0,AG19*Leadsheet!$D87) -> 0 | AI20: =IF(AI$4>$F$6,0,AH19*Leadsheet!$D87) -> 0 | AJ20: =IF(AJ$4>$F$6,0,AI19*Leadsheet!$D87) -> 0 | AK20: =IF(AK$4>$F$6,0,AJ19*Leadsheet!$D87) -> 0 | ... BM20: =IF(BM$4>$F$6,0,BL19*Leadsheet!$D87) -> 0
A21: G2 | B21: 60 | C21: B2 | F21: =IF(F$4>$F$6,0,E20*IF(F$5>=1,Leadsheet!$D88,Leadsheet!$E88)) -> 0 | G21: =IF(G$4>$F$6,0,F20*IF(G$5>=1,Leadsheet!$D88,Leadsheet!$E88)) -> 0.15886076 | H21: =IF(H$4>$F$6,0,G20*IF(H$5>=1,Leadsheet!$D88,Leadsheet!$E88)) -> 0.1388025 | I21: =IF(I$4>$F$6,0,H20*IF(I$5>=1,Leadsheet!$D88,Leadsheet!$E88)) -> 0.1310378 | J21: =IF(J$4>$F$6,0,I20*IF(J$5>=1,Leadsheet!$D88,Leadsheet!$E88)) -> 0.12351017 | K21: =IF(K$4>$F$6,0,J20*IF(K$5>=1,Leadsheet!$D88,Leadsheet!$E88)) -> 0.11618195 | L21: =IF(L$4>$F$6,0,K20*IF(L$5>=1,Leadsheet!$D88,Leadsheet!$E88)) -> 0.10901743 | M21: =IF(M$4>$F$6,0,L20*IF(M$5>=1,Leadsheet!$D88,Leadsheet!$E88)) -> 0.10199927 | ... AC21: =IF(AC$4>$F$6,0,AB20*IF(AC$5>=1,Leadsheet!$D88,Leadsheet!$E88)) -> 0 | AD21: =IF(AD$4>$F$6,0,AC20*Leadsheet!$D88) -> 0 | AE21: =IF(AE$4>$F$6,0,AD20*Leadsheet!$D88) -> 0 | AF21: =IF(AF$4>$F$6,0,AE20*Leadsheet!$D88) -> 0 | AG21: =IF(AG$4>$F$6,0,AF20*Leadsheet!$D88) -> 0 | AH21: =IF(AH$4>$F$6,0,AG20*Leadsheet!$D88) -> 0 | AI21: =IF(AI$4>$F$6,0,AH20*Leadsheet!$D88) -> 0 | AJ21: =IF(AJ$4>$F$6,0,AI20*Leadsheet!$D88) -> 0 | AK21: =IF(AK$4>$F$6,0,AJ20*Leadsheet!$D88) -> 0 | ... BM21: =IF(BM$4>$F$6,0,BL20*Leadsheet!$D88) -> 0
A22: G2 | B22: 90 | C22: B3 | F22: =IF(F$4>$F$6,0,E21*IF(F$5>=1,Leadsheet!$D89,Leadsheet!$E89)) -> 0 | G22: =IF(G$4>$F$6,0,F21*IF(G$5>=1,Leadsheet!$D89,Leadsheet!$E89)) -> 0 | H22: =IF(H$4>$F$6,0,G21*IF(H$5>=1,Leadsheet!$D89,Leadsheet!$E89)) -> 0.15409494 | I22: =IF(I$4>$F$6,0,H21*IF(I$5>=1,Leadsheet!$D89,Leadsheet!$E89)) -> 0.13463843 | J22: =IF(J$4>$F$6,0,I21*IF(J$5>=1,Leadsheet!$D89,Leadsheet!$E89)) -> 0.12710666 | K22: =IF(K$4>$F$6,0,J21*IF(K$5>=1,Leadsheet!$D89,Leadsheet!$E89)) -> 0.11980486 | L22: =IF(L$4>$F$6,0,K21*IF(L$5>=1,Leadsheet!$D89,Leadsheet!$E89)) -> 0.11269649 | M22: =IF(M$4>$F$6,0,L21*IF(M$5>=1,Leadsheet!$D89,Leadsheet!$E89)) -> 0.10574691 | ... AC22: =IF(AC$4>$F$6,0,AB21*IF(AC$5>=1,Leadsheet!$D89,Leadsheet!$E89)) -> 0 | AD22: =IF(AD$4>$F$6,0,AC21*Leadsheet!$D89) -> 0 | AE22: =IF(AE$4>$F$6,0,AD21*Leadsheet!$D89) -> 0 | AF22: =IF(AF$4>$F$6,0,AE21*Leadsheet!$D89) -> 0 | AG22: =IF(AG$4>$F$6,0,AF21*Leadsheet!$D89) -> 0 | AH22: =IF(AH$4>$F$6,0,AG21*Leadsheet!$D89) -> 0 | AI22: =IF(AI$4>$F$6,0,AH21*Leadsheet!$D89) -> 0 | AJ22: =IF(AJ$4>$F$6,0,AI21*Leadsheet!$D89) -> 0 | AK22: =IF(AK$4>$F$6,0,AJ21*Leadsheet!$D89) -> 0 | ... AV22: =IF(AV$4>$F$6,0,AU21*Leadsheet!$D89) -> 0 | AW22: 0 | AX22: =IF(AX$4>$F$6,0,AW21*Leadsheet!$D89) -> 0 | AY22: =IF(AY$4>$F$6,0,AX21*Leadsheet!$D89) -> 0 | AZ22: =IF(AZ$4>$F$6,0,AY21*Leadsheet!$D89) -> 0 | BA22: =IF(BA$4>$F$6,0,AZ21*Leadsheet!$D89) -> 0 | BB22: =IF(BB$4>$F$6,0,BA21*Leadsheet!$D89) -> 0 | BC22: =IF(BC$4>$F$6,0,BB21*Leadsheet!$D89) -> 0 | BD22: =IF(BD$4>$F$6,0,BC21*Leadsheet!$D89) -> 0 | BE22: =IF(BE$4>$F$6,0,BD21*Leadsheet!$D89) -> 0 | ... BM22: =IF(BM$4>$F$6,0,BL21*Leadsheet!$D89) -> 0
A23: G3 | B23: 120 | C23: B4 | F23: =IF(F$4>$F$6,0,E22*IF(F$5>=1,Leadsheet!$D90,Leadsheet!$E90)) -> 0 | G23: =IF(G$4>$F$6,0,F22*IF(G$5>=1,Leadsheet!$D90,Leadsheet!$E90)) -> 0 | H23: =IF(H$4>$F$6,0,G22*IF(H$5>=1,Leadsheet!$D90,Leadsheet!$E90)) -> 0 | I23: =IF(I$4>$F$6,0,H22*IF(I$5>=1,Leadsheet!$D90,Leadsheet!$E90)) -> 0.15101304 | J23: =IF(J$4>$F$6,0,I22*IF(J$5>=1,Leadsheet!$D90,Leadsheet!$E90)) -> 0.13194566 | K23: =IF(K$4>$F$6,0,J22*IF(K$5>=1,Leadsheet!$D90,Leadsheet!$E90)) -> 0.12456453 | L23: =IF(L$4>$F$6,0,K22*IF(L$5>=1,Leadsheet!$D90,Leadsheet!$E90)) -> 0.11740877 | M23: =IF(M$4>$F$6,0,L22*IF(M$5>=1,Leadsheet!$D90,Leadsheet!$E90)) -> 0.11044256 | ... AC23: =IF(AC$4>$F$6,0,AB22*IF(AC$5>=1,Leadsheet!$D90,Leadsheet!$E90)) -> 0 | AD23: =IF(AD$4>$F$6,0,AC22*Leadsheet!$D90) -> 0 | AE23: =IF(AE$4>$F$6,0,AD22*Leadsheet!$D90) -> 0 | AF23: =IF(AF$4>$F$6,0,AE22*Leadsheet!$D90) -> 0 | AG23: =IF(AG$4>$F$6,0,AF22*Leadsheet!$D90) -> 0 | AH23: =IF(AH$4>$F$6,0,AG22*Leadsheet!$D90) -> 0 | AI23: =IF(AI$4>$F$6,0,AH22*Leadsheet!$D90) -> 0 | AJ23: =IF(AJ$4>$F$6,0,AI22*Leadsheet!$D90) -> 0 | AK23: =IF(AK$4>$F$6,0,AJ22*Leadsheet!$D90) -> 0 | ... BM23: =IF(BM$4>$F$6,0,BL22*Leadsheet!$D90) -> 0
A24: G3 | B24: 150 | C24: B5 | F24: =IF(F$4>$F$6,0,E23*IF(F$5>=1,Leadsheet!$D91,Leadsheet!$E91)) -> 0 | G24: =IF(G$4>$F$6,0,F23*IF(G$5>=1,Leadsheet!$D91,Leadsheet!$E91)) -> 0 | H24: =IF(H$4>$F$6,0,G23*IF(H$5>=1,Leadsheet!$D91,Leadsheet!$E91)) -> 0 | I24: =IF(I$4>$F$6,0,H23*IF(I$5>=1,Leadsheet!$D91,Leadsheet!$E91)) -> 0 | J24: =IF(J$4>$F$6,0,I23*IF(J$5>=1,Leadsheet!$D91,Leadsheet!$E91)) -> 0.14950291 | K24: =IF(K$4>$F$6,0,J23*IF(K$5>=1,Leadsheet!$D91,Leadsheet!$E91)) -> 0.1306262 | L24: =IF(L$4>$F$6,0,K23*IF(L$5>=1,Leadsheet!$D91,Leadsheet!$E91)) -> 0.12331888 | M24: =IF(M$4>$F$6,0,L23*IF(M$5>=1,Leadsheet!$D91,Leadsheet!$E91)) -> 0.11623468 | ... AC24: =IF(AC$4>$F$6,0,AB23*IF(AC$5>=1,Leadsheet!$D91,Leadsheet!$E91)) -> 0 | AD24: =IF(AD$4>$F$6,0,AC23*Leadsheet!$D91) -> 0 | AE24: =IF(AE$4>$F$6,0,AD23*Leadsheet!$D91) -> 0 | AF24: =IF(AF$4>$F$6,0,AE23*Leadsheet!$D91) -> 0 | AG24: =IF(AG$4>$F$6,0,AF23*Leadsheet!$D91) -> 0 | AH24: =IF(AH$4>$F$6,0,AG23*Leadsheet!$D91) -> 0 | AI24: =IF(AI$4>$F$6,0,AH23*Leadsheet!$D91) -> 0 | AJ24: =IF(AJ$4>$F$6,0,AI23*Leadsheet!$D91) -> 0 | AK24: =IF(AK$4>$F$6,0,AJ23*Leadsheet!$D91) -> 0 | ... BM24: =IF(BM$4>$F$6,0,BL23*Leadsheet!$D91) -> 0
A25: G3 | B25: 180 | C25: B6 | F25: =IF(F$4>$F$6,0,E24*IF(F$5>=1,Leadsheet!$D92,Leadsheet!$E92)) -> 0 | G25: =IF(G$4>$F$6,0,F24*IF(G$5>=1,Leadsheet!$D92,Leadsheet!$E92)) -> 0 | H25: =IF(H$4>$F$6,0,G24*IF(H$5>=1,Leadsheet!$D92,Leadsheet!$E92)) -> 0 | I25: =IF(I$4>$F$6,0,H24*IF(I$5>=1,Leadsheet!$D92,Leadsheet!$E92)) -> 0 | J25: =IF(J$4>$F$6,0,I24*IF(J$5>=1,Leadsheet!$D92,Leadsheet!$E92)) -> 0 | K25: =IF(K$4>$F$6,0,J24*IF(K$5>=1,Leadsheet!$D92,Leadsheet!$E92)) -> 0.1487554 | L25: =IF(L$4>$F$6,0,K24*IF(L$5>=1,Leadsheet!$D92,Leadsheet!$E92)) -> 0.12997307 | M25: =IF(M$4>$F$6,0,L24*IF(M$5>=1,Leadsheet!$D92,Leadsheet!$E92)) -> 0.12270229 | ... AC25: =IF(AC$4>$F$6,0,AB24*IF(AC$5>=1,Leadsheet!$D92,Leadsheet!$E92)) -> 0 | AD25: =IF(AD$4>$F$6,0,AC24*Leadsheet!$D92) -> 0 | AE25: =IF(AE$4>$F$6,0,AD24*Leadsheet!$D92) -> 0 | AF25: =IF(AF$4>$F$6,0,AE24*Leadsheet!$D92) -> 0 | AG25: =IF(AG$4>$F$6,0,AF24*Leadsheet!$D92) -> 0 | AH25: =IF(AH$4>$F$6,0,AG24*Leadsheet!$D92) -> 0 | AI25: =IF(AI$4>$F$6,0,AH24*Leadsheet!$D92) -> 0 | AJ25: =IF(AJ$4>$F$6,0,AI24*Leadsheet!$D92) -> 0 | AK25: =IF(AK$4>$F$6,0,AJ24*Leadsheet!$D92) -> 0 | ... BM25: =IF(BM$4>$F$6,0,BL24*Leadsheet!$D92) -> 0
A26: G4 | B26: 210 | C26: B7 | F26: =IF(F$4>$F$6,0,E25*IF(F$5>=1,Leadsheet!$D93,Leadsheet!$E93)) -> 0 | G26: =IF(G$4>$F$6,0,F25*IF(G$5>=1,Leadsheet!$D93,Leadsheet!$E93)) -> 0 | H26: =IF(H$4>$F$6,0,G25*IF(H$5>=1,Leadsheet!$D93,Leadsheet!$E93)) -> 0 | I26: =IF(I$4>$F$6,0,H25*IF(I$5>=1,Leadsheet!$D93,Leadsheet!$E93)) -> 0 | J26: =IF(J$4>$F$6,0,I25*IF(J$5>=1,Leadsheet!$D93,Leadsheet!$E93)) -> 0 | K26: =IF(K$4>$F$6,0,J25*IF(K$5>=1,Leadsheet!$D93,Leadsheet!$E93)) -> 0 | L26: =IF(L$4>$F$6,0,K25*IF(L$5>=1,Leadsheet!$D93,Leadsheet!$E93)) -> 0.1487554 | M26: =IF(M$4>$F$6,0,L25*IF(M$5>=1,Leadsheet!$D93,Leadsheet!$E93)) -> 0.12997307 | ... AC26: =IF(AC$4>$F$6,0,AB25*IF(AC$5>=1,Leadsheet!$D93,Leadsheet!$E93)) -> 0 | AD26: =IF(AD$4>$F$6,0,AC25*Leadsheet!$D93) -> 0 | AE26: =IF(AE$4>$F$6,0,AD25*Leadsheet!$D93) -> 0 | AF26: =IF(AF$4>$F$6,0,AE25*Leadsheet!$D93) -> 0 | AG26: =IF(AG$4>$F$6,0,AF25*Leadsheet!$D93) -> 0 | AH26: =IF(AH$4>$F$6,0,AG25*Leadsheet!$D93) -> 0 | AI26: =IF(AI$4>$F$6,0,AH25*Leadsheet!$D93) -> 0 | AJ26: =IF(AJ$4>$F$6,0,AI25*Leadsheet!$D93) -> 0 | AK26: =IF(AK$4>$F$6,0,AJ25*Leadsheet!$D93) -> 0 | ... BM26: =IF(BM$4>$F$6,0,BL25*Leadsheet!$D93) -> 0
A27: G4 | B27: 240 | C27: B8 | F27: =IF(F$4>$F$6,0,E26*IF(F$5>=1,Leadsheet!$D94,Leadsheet!$E94)) -> 0 | G27: =IF(G$4>$F$6,0,F26*IF(G$5>=1,Leadsheet!$D94,Leadsheet!$E94)) -> 0 | H27: =IF(H$4>$F$6,0,G26*IF(H$5>=1,Leadsheet!$D94,Leadsheet!$E94)) -> 0 | I27: =IF(I$4>$F$6,0,H26*IF(I$5>=1,Leadsheet!$D94,Leadsheet!$E94)) -> 0 | J27: =IF(J$4>$F$6,0,I26*IF(J$5>=1,Leadsheet!$D94,Leadsheet!$E94)) -> 0 | K27: =IF(K$4>$F$6,0,J26*IF(K$5>=1,Leadsheet!$D94,Leadsheet!$E94)) -> 0 | L27: =IF(L$4>$F$6,0,K26*IF(L$5>=1,Leadsheet!$D94,Leadsheet!$E94)) -> 0 | M27: =IF(M$4>$F$6,0,L26*IF(M$5>=1,Leadsheet!$D94,Leadsheet!$E94)) -> 0.1487554 | ... AC27: =IF(AC$4>$F$6,0,AB26*IF(AC$5>=1,Leadsheet!$D94,Leadsheet!$E94)) -> 0 | AD27: =IF(AD$4>$F$6,0,AC26*Leadsheet!$D94) -> 0 | AE27: =IF(AE$4>$F$6,0,AD26*Leadsheet!$D94) -> 0 | AF27: =IF(AF$4>$F$6,0,AE26*Leadsheet!$D94) -> 0 | AG27: =IF(AG$4>$F$6,0,AF26*Leadsheet!$D94) -> 0 | AH27: =IF(AH$4>$F$6,0,AG26*Leadsheet!$D94) -> 0 | AI27: =IF(AI$4>$F$6,0,AH26*Leadsheet!$D94) -> 0 | AJ27: =IF(AJ$4>$F$6,0,AI26*Leadsheet!$D94) -> 0 | AK27: =IF(AK$4>$F$6,0,AJ26*Leadsheet!$D94) -> 0 | ... BM27: =IF(BM$4>$F$6,0,BL26*Leadsheet!$D94) -> 0
A28: G4 | B28: 270 | C28: B9 | F28: =IF(F$4>$F$6,0,E27*IF(F$5>=1,Leadsheet!$D95,Leadsheet!$E95)) -> 0 | G28: =IF(G$4>$F$6,0,F27*IF(G$5>=1,Leadsheet!$D95,Leadsheet!$E95)) -> 0 | H28: =IF(H$4>$F$6,0,G27*IF(H$5>=1,Leadsheet!$D95,Leadsheet!$E95)) -> 0 | I28: =IF(I$4>$F$6,0,H27*IF(I$5>=1,Leadsheet!$D95,Leadsheet!$E95)) -> 0 | J28: =IF(J$4>$F$6,0,I27*IF(J$5>=1,Leadsheet!$D95,Leadsheet!$E95)) -> 0 | K28: =IF(K$4>$F$6,0,J27*IF(K$5>=1,Leadsheet!$D95,Leadsheet!$E95)) -> 0 | L28: =IF(L$4>$F$6,0,K27*IF(L$5>=1,Leadsheet!$D95,Leadsheet!$E95)) -> 0 | M28: =IF(M$4>$F$6,0,L27*IF(M$5>=1,Leadsheet!$D95,Leadsheet!$E95)) -> 0 | ... AC28: =IF(AC$4>$F$6,0,AB27*IF(AC$5>=1,Leadsheet!$D95,Leadsheet!$E95)) -> 0 | AD28: =IF(AD$4>$F$6,0,AC27*Leadsheet!$D95) -> 0 | AE28: =IF(AE$4>$F$6,0,AD27*Leadsheet!$D95) -> 0 | AF28: =IF(AF$4>$F$6,0,AE27*Leadsheet!$D95) -> 0 | AG28: =IF(AG$4>$F$6,0,AF27*Leadsheet!$D95) -> 0 | AH28: =IF(AH$4>$F$6,0,AG27*Leadsheet!$D95) -> 0 | AI28: =IF(AI$4>$F$6,0,AH27*Leadsheet!$D95) -> 0 | AJ28: =IF(AJ$4>$F$6,0,AI27*Leadsheet!$D95) -> 0 | AK28: =IF(AK$4>$F$6,0,AJ27*Leadsheet!$D95) -> 0 | ... BM28: =IF(BM$4>$F$6,0,BL27*Leadsheet!$D95) -> 0
A29: G4 | B29: 300 | C29: B10 | F29: =IF(F$4>$F$6,0,E28*IF(F$5>=1,Leadsheet!$D96,Leadsheet!$E96)) -> 0 | G29: =IF(G$4>$F$6,0,F28*IF(G$5>=1,Leadsheet!$D96,Leadsheet!$E96)) -> 0 | H29: =IF(H$4>$F$6,0,G28*IF(H$5>=1,Leadsheet!$D96,Leadsheet!$E96)) -> 0 | I29: =IF(I$4>$F$6,0,H28*IF(I$5>=1,Leadsheet!$D96,Leadsheet!$E96)) -> 0 | J29: =IF(J$4>$F$6,0,I28*IF(J$5>=1,Leadsheet!$D96,Leadsheet!$E96)) -> 0 | K29: =IF(K$4>$F$6,0,J28*IF(K$5>=1,Leadsheet!$D96,Leadsheet!$E96)) -> 0 | L29: =IF(L$4>$F$6,0,K28*IF(L$5>=1,Leadsheet!$D96,Leadsheet!$E96)) -> 0 | M29: =IF(M$4>$F$6,0,L28*IF(M$5>=1,Leadsheet!$D96,Leadsheet!$E96)) -> 0 | ... AC29: =IF(AC$4>$F$6,0,AB28*IF(AC$5>=1,Leadsheet!$D96,Leadsheet!$E96)) -> 0 | AD29: =IF(AD$4>$F$6,0,AC28*Leadsheet!$D96) -> 0 | AE29: =IF(AE$4>$F$6,0,AD28*Leadsheet!$D96) -> 0 | AF29: =IF(AF$4>$F$6,0,AE28*Leadsheet!$D96) -> 0 | AG29: =IF(AG$4>$F$6,0,AF28*Leadsheet!$D96) -> 0 | AH29: =IF(AH$4>$F$6,0,AG28*Leadsheet!$D96) -> 0 | AI29: =IF(AI$4>$F$6,0,AH28*Leadsheet!$D96) -> 0 | AJ29: =IF(AJ$4>$F$6,0,AI28*Leadsheet!$D96) -> 0 | AK29: =IF(AK$4>$F$6,0,AJ28*Leadsheet!$D96) -> 0 | ... BM29: =IF(BM$4>$F$6,0,BL28*Leadsheet!$D96) -> 0
A30: G4 | B30: 330 | C30: B11 | F30: =IF(F$4>$F$6,0,E29*IF(F$5>=1,Leadsheet!$D97,Leadsheet!$E97)) -> 0 | G30: =IF(G$4>$F$6,0,F29*IF(G$5>=1,Leadsheet!$D97,Leadsheet!$E97)) -> 0 | H30: =IF(H$4>$F$6,0,G29*IF(H$5>=1,Leadsheet!$D97,Leadsheet!$E97)) -> 0 | I30: =IF(I$4>$F$6,0,H29*IF(I$5>=1,Leadsheet!$D97,Leadsheet!$E97)) -> 0 | J30: =IF(J$4>$F$6,0,I29*IF(J$5>=1,Leadsheet!$D97,Leadsheet!$E97)) -> 0 | K30: =IF(K$4>$F$6,0,J29*IF(K$5>=1,Leadsheet!$D97,Leadsheet!$E97)) -> 0 | L30: =IF(L$4>$F$6,0,K29*IF(L$5>=1,Leadsheet!$D97,Leadsheet!$E97)) -> 0 | M30: =IF(M$4>$F$6,0,L29*IF(M$5>=1,Leadsheet!$D97,Leadsheet!$E97)) -> 0 | ... AC30: =IF(AC$4>$F$6,0,AB29*IF(AC$5>=1,Leadsheet!$D97,Leadsheet!$E97)) -> 0 | AD30: =IF(AD$4>$F$6,0,AC29*Leadsheet!$D97) -> 0 | AE30: =IF(AE$4>$F$6,0,AD29*Leadsheet!$D97) -> 0 | AF30: =IF(AF$4>$F$6,0,AE29*Leadsheet!$D97) -> 0 | AG30: =IF(AG$4>$F$6,0,AF29*Leadsheet!$D97) -> 0 | AH30: =IF(AH$4>$F$6,0,AG29*Leadsheet!$D97) -> 0 | AI30: =IF(AI$4>$F$6,0,AH29*Leadsheet!$D97) -> 0 | AJ30: =IF(AJ$4>$F$6,0,AI29*Leadsheet!$D97) -> 0 | AK30: =IF(AK$4>$F$6,0,AJ29*Leadsheet!$D97) -> 0 | ... BM30: =IF(BM$4>$F$6,0,BL29*Leadsheet!$D97) -> 0
A31: G4 | B31: 360 | C31: B12 | F31: =IF(F$4>$F$6,0,E30*IF(F$5>=1,Leadsheet!$D98,Leadsheet!$E98)) -> 0 | G31: =IF(G$4>$F$6,0,F30*IF(G$5>=1,Leadsheet!$D98,Leadsheet!$E98)) -> 0 | H31: =IF(H$4>$F$6,0,G30*IF(H$5>=1,Leadsheet!$D98,Leadsheet!$E98)) -> 0 | I31: =IF(I$4>$F$6,0,H30*IF(I$5>=1,Leadsheet!$D98,Leadsheet!$E98)) -> 0 | J31: =IF(J$4>$F$6,0,I30*IF(J$5>=1,Leadsheet!$D98,Leadsheet!$E98)) -> 0 | K31: =IF(K$4>$F$6,0,J30*IF(K$5>=1,Leadsheet!$D98,Leadsheet!$E98)) -> 0 | L31: =IF(L$4>$F$6,0,K30*IF(L$5>=1,Leadsheet!$D98,Leadsheet!$E98)) -> 0 | M31: =IF(M$4>$F$6,0,L30*IF(M$5>=1,Leadsheet!$D98,Leadsheet!$E98)) -> 0 | ... AC31: =IF(AC$4>$F$6,0,AB30*IF(AC$5>=1,Leadsheet!$D98,Leadsheet!$E98)) -> 0 | AD31: =IF(AD$4>$F$6,0,AC30*Leadsheet!$D98) -> 0 | AE31: =IF(AE$4>$F$6,0,AD30*Leadsheet!$D98) -> 0 | AF31: =IF(AF$4>$F$6,0,AE30*Leadsheet!$D98) -> 0 | AG31: =IF(AG$4>$F$6,0,AF30*Leadsheet!$D98) -> 0 | AH31: =IF(AH$4>$F$6,0,AG30*Leadsheet!$D98) -> 0 | AI31: =IF(AI$4>$F$6,0,AH30*Leadsheet!$D98) -> 0 | AJ31: =IF(AJ$4>$F$6,0,AI30*Leadsheet!$D98) -> 0 | AK31: =IF(AK$4>$F$6,0,AJ30*Leadsheet!$D98) -> 0 | ... BM31: =IF(BM$4>$F$6,0,BL30*Leadsheet!$D98) -> 0
A32: G5 | B32: 390 | C32: B13 | F32: =IF(F$4>$F$6,0,E31*IF(F$5>=1,Leadsheet!$D99,Leadsheet!$E99)) -> 0 | G32: =IF(G$4>$F$6,0,F31*IF(G$5>=1,Leadsheet!$D99,Leadsheet!$E99)) -> 0 | H32: =IF(H$4>$F$6,0,G31*IF(H$5>=1,Leadsheet!$D99,Leadsheet!$E99)) -> 0 | I32: =IF(I$4>$F$6,0,H31*IF(I$5>=1,Leadsheet!$D99,Leadsheet!$E99)) -> 0 | J32: =IF(J$4>$F$6,0,I31*IF(J$5>=1,Leadsheet!$D99,Leadsheet!$E99)) -> 0 | K32: =IF(K$4>$F$6,0,J31*IF(K$5>=1,Leadsheet!$D99,Leadsheet!$E99)) -> 0 | L32: =IF(L$4>$F$6,0,K31*IF(L$5>=1,Leadsheet!$D99,Leadsheet!$E99)) -> 0 | M32: =IF(M$4>$F$6,0,L31*IF(M$5>=1,Leadsheet!$D99,Leadsheet!$E99)) -> 0 | ... AC32: =IF(AC$4>$F$6,0,AB31*IF(AC$5>=1,Leadsheet!$D99,Leadsheet!$E99)) -> 0 | AD32: =IF(AD$4>$F$6,0,AC31*Leadsheet!$D99) -> 0 | AE32: =IF(AE$4>$F$6,0,AD31*Leadsheet!$D99) -> 0 | AF32: =IF(AF$4>$F$6,0,AE31*Leadsheet!$D99) -> 0 | AG32: =IF(AG$4>$F$6,0,AF31*Leadsheet!$D99) -> 0 | AH32: =IF(AH$4>$F$6,0,AG31*Leadsheet!$D99) -> 0 | AI32: =IF(AI$4>$F$6,0,AH31*Leadsheet!$D99) -> 0 | AJ32: =IF(AJ$4>$F$6,0,AI31*Leadsheet!$D99) -> 0 | AK32: =IF(AK$4>$F$6,0,AJ31*Leadsheet!$D99) -> 0 | ... BM32: =IF(BM$4>$F$6,0,BL31*Leadsheet!$D99) -> 0
A33: G5 | B33: 420+ | C33: B14+ | F33: =IF(F$4>$F$6,0,E32+E33) -> 0 | G33: =IF(G$4>$F$6,0,F32+F33) -> 0 | H33: =IF(H$4>$F$6,0,G32+G33) -> 0 | I33: =IF(I$4>$F$6,0,H32+H33) -> 0 | J33: =IF(J$4>$F$6,0,I32+I33) -> 0 | K33: =IF(K$4>$F$6,0,J32+J33) -> 0 | L33: =IF(L$4>$F$6,0,K32+K33) -> 0 | M33: =IF(M$4>$F$6,0,L32+L33) -> 0 | ... AC33: =IF(AC$4>$F$6,0,AB32+AB33) -> 0 | AD33: =IF(AD4>$F$6,0,AC32+AC33) -> 0 | AE33: =IF(AE4>$F$6,0,AD32+AD33) -> 0 | AF33: =IF(AF4>$F$6,0,AE32+AE33) -> 0 | AG33: =IF(AG4>$F$6,0,AF32+AF33) -> 0 | AH33: =IF(AH4>$F$6,0,AG32+AG33) -> 0 | AI33: =IF(AI4>$F$6,0,AH32+AH33) -> 0 | AJ33: =IF(AJ4>$F$6,0,AI32+AI33) -> 0 | AK33: =IF(AK4>$F$6,0,AJ32+AJ33) -> 0 | ... BM33: =IF(BM4>$F$6,0,BL32+BL33) -> 0
B36: ENR
C37: Total bank | E37: =IF(E5>0,Leadsheet!$E$11*SAP_Speadsheet!E16,SUM(E20:E33)) -> 7.9629455 | F37: =IF(F5>0,Leadsheet!$E$11*SAP_Speadsheet!F16,SUM(F20:F33)) -> 7.1247407 | G37: =IF(G5>0,Leadsheet!$E$11*SAP_Speadsheet!G16,SUM(G20:G33)) -> 6.8732793 | H37: =IF(H5>0,Leadsheet!$E$11*SAP_Speadsheet!H16,SUM(H20:H33)) -> 6.6218178 | I37: =IF(I5>0,Leadsheet!$E$11*SAP_Speadsheet!I16,SUM(I20:I33)) -> 6.3703564 | J37: =IF(J5>0,Leadsheet!$E$11*SAP_Speadsheet!J16,SUM(J20:J33)) -> 6.1188949 | K37: =IF(K5>0,Leadsheet!$E$11*SAP_Speadsheet!K16,SUM(K20:K33)) -> 5.8674335 | L37: =IF(L5>0,Leadsheet!$E$11*SAP_Speadsheet!L16,SUM(L20:L33)) -> 5.6159721 | ... BM37: =IF(BM5>0,Leadsheet!$E$11*SAP_Speadsheet!BM16,SUM(BM20:BM33)) -> 0
C38: Outstanding balance | E38: {=IF(E4=$F$6,0,_xlfn.IFS(Leadsheet!$G$5="DPD360+",SUM(SAP_Speadsheet!E19:E32),Leadsheet!$G$5="DPD180+",SUM(SAP_Speadsheet!E19:E26)))} -> 7.9629455 | F38: {=IF(F4=$F$6,0,_xlfn.IFS(Leadsheet!$G$5="DPD360+",SUM(SAP_Speadsheet!F19:F32),Leadsheet!$G$5="DPD180+",SUM(SAP_Speadsheet!F19:F26)))} -> 7.1247407 | G38: {=IF(G4=$F$6,0,_xlfn.IFS(Leadsheet!$G$5="DPD360+",SUM(SAP_Speadsheet!G19:G32),Leadsheet!$G$5="DPD180+",SUM(SAP_Speadsheet!G19:G26)))} -> 6.8732793 | H38: {=IF(H4=$F$6,0,_xlfn.IFS(Leadsheet!$G$5="DPD360+",SUM(SAP_Speadsheet!H19:H32),Leadsheet!$G$5="DPD180+",SUM(SAP_Speadsheet!H19:H26)))} -> 6.6218178 | I38: {=IF(I4=$F$6,0,_xlfn.IFS(Leadsheet!$G$5="DPD360+",SUM(SAP_Speadsheet!I19:I32),Leadsheet!$G$5="DPD180+",SUM(SAP_Speadsheet!I19:I26)))} -> 6.3703564 | J38: {=IF(J4=$F$6,0,_xlfn.IFS(Leadsheet!$G$5="DPD360+",SUM(SAP_Speadsheet!J19:J32),Leadsheet!$G$5="DPD180+",SUM(SAP_Speadsheet!J19:J26)))} -> 6.1188949 | K38: {=IF(K4=$F$6,0,_xlfn.IFS(Leadsheet!$G$5="DPD360+",SUM(SAP_Speadsheet!K19:K32),Leadsheet!$G$5="DPD180+",SUM(SAP_Speadsheet!K19:K26)))} -> 5.8674335 | L38: {=IF(L4=$F$6,0,_xlfn.IFS(Leadsheet!$G$5="DPD360+",SUM(SAP_Speadsheet!L19:L32),Leadsheet!$G$5="DPD180+",SUM(SAP_Speadsheet!L19:L26)))} -> 5.6159721 | ... BM38: {=IF(BM4=$F$6,0,_xlfn.IFS(Leadsheet!$G$5="DPD360+",SUM(SAP_Speadsheet!BM19:BM32),Leadsheet!$G$5="DPD180+",SUM(SAP_Speadsheet!BM19:BM26)))} -> 0
C39: Writeoff balance | E39: =E37-E38 -> 0 | F39: =F37-F38 -> 0 | G39: =G37-G38 -> 0 | H39: =H37-H38 -> 0 | I39: =I37-I38 -> 0 | J39: =J37-J38 -> 0 | K39: =K37-K38 -> 0 | L39: =L37-L38 -> 0 | ... BM39: =BM37-BM38 -> 0
C40: Outstanding Bal/TB | E40: =IFERROR(E38/E37,"") -> 1 | F40: =IFERROR(F38/F37,"") -> 1 | G40: =IFERROR(G38/G37,"") -> 1 | H40: =IFERROR(H38/H37,"") -> 1 | I40: =IFERROR(I38/I37,"") -> 1 | J40: =IFERROR(J38/J37,"") -> 1 | K40: =IFERROR(K38/K37,"") -> 1 | L40: =IFERROR(L38/L37,"") -> 1 | ... BM40: =IFERROR(BM38/BM37,"")
B42: ANR
C43: Outstanding balance | D43: Average Balance Projected ENR (t and t-1) | F43: =IF(F4>$F$6,0,AVERAGE(E37:F37)) -> 7.5438431 | G43: =IF(G4>$F$6,0,AVERAGE(F37:G37)) -> 6.99901 | H43: =IF(H4>$F$6,0,AVERAGE(G37:H37)) -> 6.7475485 | I43: =IF(I4>$F$6,0,AVERAGE(H37:I37)) -> 6.4960871 | J43: =IF(J4>$F$6,0,AVERAGE(I37:J37)) -> 6.2446257 | K43: =IF(K4>$F$6,0,AVERAGE(J37:K37)) -> 5.9931642 | L43: =IF(L4>$F$6,0,AVERAGE(K37:L37)) -> 5.7417028 | M43: =IF(M4>$F$6,0,AVERAGE(L37:M37)) -> 5.4902414 | ... BM43: =IF(BM4>$F$6,0,AVERAGE(BL37:BM37)) -> 0
C44: ANR for CII (B0+B1A) | D44: Average Balance B0 only (t and t-1) | F44: =E19*(1-Leadsheet!$D$87)+E20*Leadsheet!$E$111 -> 7.7957236 | G44: =F19*(1-Leadsheet!$D$87)+F20*Leadsheet!$E$111 -> 6.819772 | H44: =G19*(1-Leadsheet!$D$87)+G20*Leadsheet!$E$111 -> 6.4376815 | I44: =H19*(1-Leadsheet!$D$87)+H20*Leadsheet!$E$111 -> 6.0678719 | J44: =I19*(1-Leadsheet!$D$87)+I20*Leadsheet!$E$111 -> 5.7078602 | K44: =J19*(1-Leadsheet!$D$87)+J20*Leadsheet!$E$111 -> 5.3558924 | L44: =K19*(1-Leadsheet!$D$87)+K20*Leadsheet!$E$111 -> 5.0111155 | M44: =L19*(1-Leadsheet!$D$87)+L20*Leadsheet!$E$111 -> 4.6726867 | ... BM44: =BL19*(1-Leadsheet!$D$87)+BL20*Leadsheet!$E$111 -> 0
B46: Performance
B48: TOI | F48: =F50+F54+F59 -> 0.33658125 | G48: =G50+G54+G59 -> 0.15992638 | H48: =H50+H54+H59 -> 0.1501883 | I48: =I50+I54+I59 -> 0.14080791 | J48: =J50+J54+J59 -> 0.13171289 | K48: =K50+K54+K59 -> 0.12285216 | L48: =L50+L54+L59 -> 0.11420086 | M48: =M50+M54+M59 -> 0.10573446 | ... BM48: =BM50+BM54+BM59 -> 0
C50: Net interest income | F50: =F51+F52 -> 0.18533874 | G50: =G51+G52 -> 0.15992638 | H50: =H51+H52 -> 0.1501883 | I50: =I51+I52 -> 0.14080791 | J50: =J51+J52 -> 0.13171289 | K50: =K51+K52 -> 0.12285216 | L50: =L51+L52 -> 0.11420086 | M50: =M51+M52 -> 0.10573446 | ... BM50: =BM51+BM52 -> 0
...

Sheet Saleplan&PnL
C1: PROFIT & LOSS 60M
C2: I. | D2: SALES PLAN
C4: Business month | D4: 45658 | E4: =EOMONTH(D4,1) -> 45716 | F4: =EOMONTH(E4,1) -> 45747 | G4: =EOMONTH(F4,1) -> 45777 | H4: =EOMONTH(G4,1) -> 45808 | I4: =EOMONTH(H4,1) -> 45838 | J4: =EOMONTH(I4,1) -> 45869 | K4: =EOMONTH(J4,1) -> 45900 | L4: =EOMONTH(K4,1) -> 45930 | ... BL4: =EOMONTH(BK4,1) -> 47514
C5: Don't delete | D5: =YEAR(D4) -> 2025 | E5: =YEAR(E4) -> 2025 | F5: =YEAR(F4) -> 2025 | G5: =YEAR(G4) -> 2025 | H5: =YEAR(H4) -> 2025 | I5: =YEAR(I4) -> 2025 | J5: =YEAR(J4) -> 2025 | K5: =YEAR(K4) -> 2025 | ... BL5: =YEAR(BL4) -> 2030
C6: New Account | D6: 1390
C8: II. | D8: PROFIT & LOSS
C10: FISCAL YEAR | D10: Total | F10: =YEAR(D4) -> 2025 | H10: =F10+1 -> 2026 | J10: =H10+1 -> 2027 | L10: =J10+1 -> 2028 | N10: =L10+1 -> 2029 | P10: =N10+1 -> 2030
D11: bVND | F11: bVND | H11: bVND | J11: bVND | L11: bVND | N11: bVND | P11: bVND
C13: NEW ACC | D13: =SUM(F13:P13) -> 1390 | F13: =SUMIF($D$5:$BL$5,F$10,$D$6:$BL$6) -> 1390 | H13: =SUMIF($D$5:$BL$5,H$10,$D$6:$BL$6) -> 0 | J13: =SUMIF($D$5:$BL$5,J$10,$D$6:$BL$6) -> 0 | L13: =SUMIF($D$5:$BL$5,L$10,$D$6:$BL$6) -> 0 | N13: =SUMIF($D$5:$BL$5,N$10,$D$6:$BL$6) -> 0 | P13: =SUMIF($D$5:$BL$5,P$10,$D$6:$BL$6) -> 0
C14: Monthly Acc | D14: =AVERAGE(D6:AM6) -> 1390 | F14: =F13/COUNTIF($D$5:$BL$5,F10) -> 115.83333 | H14: =H13/COUNTIF($D$5:$BL$5,H10) -> 0 | J14: =J13/COUNTIF($D$5:$BL$5,J10) -> 0 | L14: =L13/COUNTIF($D$5:$BL$5,L10) -> 0 | N14: =N13/COUNTIF($D$5:$BL$5,N10) -> 0 | P14: =P13/COUNTIF($D$5:$BL$5,P10) -> 0
C16: EOP | F16: =OFFSET(PnL_Speadsheet!$A$7,0,MATCH(DATE('Saleplan&PnL'!F$10,12,31),PnL_Speadsheet!$B$4:$BI$4,0))/1000 -> 1.9462162 | H16: =OFFSET(PnL_Speadsheet!$A$7,0,MATCH(DATE('Saleplan&PnL'!H$10,12,31),PnL_Speadsheet!$B$4:$BI$4,0))/1000 -> 0 | J16: =OFFSET(PnL_Speadsheet!$A$7,0,MATCH(DATE('Saleplan&PnL'!J$10,12,31),PnL_Speadsheet!$B$4:$BI$4,0))/1000 -> 0 | L16: =OFFSET(PnL_Speadsheet!$A$7,0,MATCH(DATE('Saleplan&PnL'!L$10,12,31),PnL_Speadsheet!$B$4:$BI$4,0))/1000 -> 0 | N16: =OFFSET(PnL_Speadsheet!$A$7,0,MATCH(DATE('Saleplan&PnL'!N$10,12,31),PnL_Speadsheet!$B$4:$BI$4,0))/1000 -> 0 | P16: =IFERROR(OFFSET(PnL_Speadsheet!$A$7,0,MATCH(DATE('Saleplan&PnL'!P$10,12,31),PnL_Speadsheet!$B$4:$BI$4,0))/1000,0) -> 0
C17: ADB | D17: =SUM(PnL_Speadsheet!B8:AK8)/1000/COUNT(PnL_Speadsheet!B3:AK3) -> 2.4525878 | F17: =SUMIF(PnL_Speadsheet!$B$3:$BI$3,F$10,PnL_Speadsheet!$B8:$BI8)/1000/COUNTIF(PnL_Speadsheet!$B$3:$BI$3,'Saleplan&PnL'!F$10) -> 6.8732861 | H17: =SUMIF(PnL_Speadsheet!$B$3:$BI$3,H$10,PnL_Speadsheet!$B8:$BI8)/1000/COUNTIF(PnL_Speadsheet!$B$3:$BI$3,'Saleplan&PnL'!H$10) -> 0.48447718 | J17: =SUMIF(PnL_Speadsheet!$B$3:$BI$3,J$10,PnL_Speadsheet!$B8:$BI8)/1000/COUNTIF(PnL_Speadsheet!$B$3:$BI$3,'Saleplan&PnL'!J$10) -> 0 | L17: =SUMIF(PnL_Speadsheet!$B$3:$BI$3,L$10,PnL_Speadsheet!$B8:$BI8)/1000/COUNTIF(PnL_Speadsheet!$B$3:$BI$3,'Saleplan&PnL'!L$10) -> 0 | N17: =SUMIF(PnL_Speadsheet!$B$3:$BI$3,N$10,PnL_Speadsheet!$B8:$BI8)/1000/COUNTIF(PnL_Speadsheet!$B$3:$BI$3,'Saleplan&PnL'!N$10) -> 0 | P17: =IFERROR(SUMIF(PnL_Speadsheet!$B$3:$BI$3,P$10,PnL_Speadsheet!$B8:$BI8)/1000/COUNTIF(PnL_Speadsheet!$B$3:$BI$3,'Saleplan&PnL'!P$10),0) -> 0
C19: TOI | D19: =SUM(F19:P19) -> 1.8374355 | F19: =SUMIF(PnL_Speadsheet!$B$3:$BI$3,F$10,PnL_Speadsheet!$B9:$BI9)/1000 -> 1.8695851 | H19: =SUMIF(PnL_Speadsheet!$B$3:$BI$3,H$10,PnL_Speadsheet!$B9:$BI9)/1000 -> -0.032149587 | J19: =SUMIF(PnL_Speadsheet!$B$3:$BI$3,J$10,PnL_Speadsheet!$B9:$BI9)/1000 -> 0 | L19: =SUMIF(PnL_Speadsheet!$B$3:$BI$3,L$10,PnL_Speadsheet!$B9:$BI9)/1000 -> 0 | N19: =SUMIF(PnL_Speadsheet!$B$3:$BI$3,N$10,PnL_Speadsheet!$B9:$BI9)/1000 -> 0 | P19: =SUMIF(PnL_Speadsheet!$B$3:$BI$3,P$10,PnL_Speadsheet!$B9:$BI9)/1000 -> 0
C20: NII | D20: =SUM(F20:P20) -> 1.6272084 | F20: =SUMIF(PnL_Speadsheet!$B$3:$BI$3,F$10,PnL_Speadsheet!$B11:$BI11)/1000 -> 1.659358 | H20: =SUMIF(PnL_Speadsheet!$B$3:$BI$3,H$10,PnL_Speadsheet!$B11:$BI11)/1000 -> -0.032149587 | J20: =SUMIF(PnL_Speadsheet!$B$3:$BI$3,J$10,PnL_Speadsheet!$B11:$BI11)/1000 -> 0 | L20: =SUMIF(PnL_Speadsheet!$B$3:$BI$3,L$10,PnL_Speadsheet!$B11:$BI11)/1000 -> 0 | N20: =SUMIF(PnL_Speadsheet!$B$3:$BI$3,N$10,PnL_Speadsheet!$B11:$BI11)/1000 -> 0 | P20: =SUMIF(PnL_Speadsheet!$B$3:$BI$3,P$10,PnL_Speadsheet!$B11:$BI11)/1000 -> 0
C21: NFI | D21: =SUM(F21:P21) -> 0.21022708 | F21: =SUMIF(PnL_Speadsheet!$B$3:$BI$3,F$10,PnL_Speadsheet!$B14:$BI14)/1000 -> 0.21022708 | H21: =SUMIF(PnL_Speadsheet!$B$3:$BI$3,H$10,PnL_Speadsheet!$B14:$BI14)/1000 -> 0 | J21: =SUMIF(PnL_Speadsheet!$B$3:$BI$3,J$10,PnL_Speadsheet!$B14:$BI14)/1000 -> 0 | L21: =SUMIF(PnL_Speadsheet!$B$3:$BI$3,L$10,PnL_Speadsheet!$B14:$BI14)/1000 -> 0 | N21: =SUMIF(PnL_Speadsheet!$B$3:$BI$3,N$10,PnL_Speadsheet!$B14:$BI14)/1000 -> 0 | P21: =SUMIF(PnL_Speadsheet!$B$3:$BI$3,P$10,PnL_Speadsheet!$B14:$BI14)/1000 -> 0
C22: Other TOI | D22: =SUM(F22:P22) -> 0 | F22: =SUMIF(PnL_Speadsheet!$B$3:$BI$3,F$10,PnL_Speadsheet!$B18:$BI18)/1000 -> 0 | H22: =SUMIF(PnL_Speadsheet!$B$3:$BI$3,H$10,PnL_Speadsheet!$B18:$BI18)/1000 -> 0 | J22: =SUMIF(PnL_Speadsheet!$B$3:$BI$3,J$10,PnL_Speadsheet!$B18:$BI18)/1000 -> 0 | L22: =SUMIF(PnL_Speadsheet!$B$3:$BI$3,L$10,PnL_Speadsheet!$B18:$BI18)/1000 -> 0 | N22: =SUMIF(PnL_Speadsheet!$B$3:$BI$3,N$10,PnL_Speadsheet!$B18:$BI18)/1000 -> 0 | P22: =SUMIF(PnL_Speadsheet!$B$3:$BI$3,P$10,PnL_Speadsheet!$B18:$BI18)/1000 -> 0
C23: PROVISION | D23: =SUM(F23:P23) -> -1.8333046 | F23: =SUMIF(PnL_Speadsheet!$B$3:$BI$3,F$10,PnL_Speadsheet!$B31:$BI31)/1000 -> -1.8193404 | H23: =SUMIF(PnL_Speadsheet!$B$3:$BI$3,H$10,PnL_Speadsheet!$B31:$BI31)/1000 -> -0.013964194 | J23: =SUMIF(PnL_Speadsheet!$B$3:$BI$3,J$10,PnL_Speadsheet!$B31:$BI31)/1000 -> 0 | L23: =SUMIF(PnL_Speadsheet!$B$3:$BI$3,L$10,PnL_Speadsheet!$B31:$BI31)/1000 -> 0 | N23: =SUMIF(PnL_Speadsheet!$B$3:$BI$3,N$10,PnL_Speadsheet!$B31:$BI31)/1000 -> 0 | P23: =SUMIF(PnL_Speadsheet!$B$3:$BI$3,P$10,PnL_Speadsheet!$B31:$BI31)/1000 -> 0
C24: OPEX | D24: =SUM(F24:P24) -> -0.45935401 | F24: =SUMIF(PnL_Speadsheet!$B$3:$BI$3,F$10,PnL_Speadsheet!$B19:$BI19)/1000 -> -0.45630715 | H24: =SUMIF(PnL_Speadsheet!$B$3:$BI$3,H$10,PnL_Speadsheet!$B19:$BI19)/1000 -> -0.0030468607 | J24: =SUMIF(PnL_Speadsheet!$B$3:$BI$3,J$10,PnL_Speadsheet!$B19:$BI19)/1000 -> 0 | L24: =SUMIF(PnL_Speadsheet!$B$3:$BI$3,L$10,PnL_Speadsheet!$B19:$BI19)/1000 -> 0 | N24: =SUMIF(PnL_Speadsheet!$B$3:$BI$3,N$10,PnL_Speadsheet!$B19:$BI19)/1000 -> 0 | P24: =SUMIF(PnL_Speadsheet!$B$3:$BI$3,P$10,PnL_Speadsheet!$B19:$BI19)/1000 -> 0
C25: Sales incentives | D25: =SUM(F25:P25) -> 0 | F25: =SUMIF(PnL_Speadsheet!$B$3:$BI$3,F$10,PnL_Speadsheet!$B21:$BI22)/1000 -> 0 | H25: =SUMIF(PnL_Speadsheet!$B$3:$BI$3,H$10,PnL_Speadsheet!$B21:$BI22)/1000 -> 0 | J25: =SUMIF(PnL_Speadsheet!$B$3:$BI$3,J$10,PnL_Speadsheet!$B21:$BI22)/1000 -> 0 | L25: =SUMIF(PnL_Speadsheet!$B$3:$BI$3,L$10,PnL_Speadsheet!$B21:$BI22)/1000 -> 0 | N25: =SUMIF(PnL_Speadsheet!$B$3:$BI$3,N$10,PnL_Speadsheet!$B21:$BI22)/1000 -> 0 | P25: =SUMIF(PnL_Speadsheet!$B$3:$BI$3,P$10,PnL_Speadsheet!$B21:$BI22)/1000 -> 0
C26: Marketing | D26: =SUM(F26:P26) -> 0 | F26: =SUMIF(PnL_Speadsheet!$B$3:$BI$3,F$10,PnL_Speadsheet!$B22:$BI22)/1000 -> 0 | H26: =SUMIF(PnL_Speadsheet!$B$3:$BI$3,H$10,PnL_Speadsheet!$B22:$BI22)/1000 -> 0 | J26: =SUMIF(PnL_Speadsheet!$B$3:$BI$3,J$10,PnL_Speadsheet!$B22:$BI22)/1000 -> 0 | L26: =SUMIF(PnL_Speadsheet!$B$3:$BI$3,L$10,PnL_Speadsheet!$B22:$BI22)/1000 -> 0 | N26: =SUMIF(PnL_Speadsheet!$B$3:$BI$3,N$10,PnL_Speadsheet!$B22:$BI22)/1000 -> 0 | P26: =SUMIF(PnL_Speadsheet!$B$3:$BI$3,P$10,PnL_Speadsheet!$B22:$BI22)/1000 -> 0
C27: UW & Disbursal | D27: =SUM(F27:P27) -> -0.020645888 | F27: =SUMIF(PnL_Speadsheet!$B$3:$BI$3,F$10,PnL_Speadsheet!$B24:$BI24)/1000 -> -0.020645888 | H27: =SUMIF(PnL_Speadsheet!$B$3:$BI$3,H$10,PnL_Speadsheet!$B24:$BI24)/1000 -> 0 | J27: =SUMIF(PnL_Speadsheet!$B$3:$BI$3,J$10,PnL_Speadsheet!$B24:$BI24)/1000 -> 0 | L27: =SUMIF(PnL_Speadsheet!$B$3:$BI$3,L$10,PnL_Speadsheet!$B24:$BI24)/1000 -> 0 | N27: =SUMIF(PnL_Speadsheet!$B$3:$BI$3,N$10,PnL_Speadsheet!$B24:$BI24)/1000 -> 0 | P27: =SUMIF(PnL_Speadsheet!$B$3:$BI$3,P$10,PnL_Speadsheet!$B24:$BI24)/1000 -> 0
C28: Collection & AMC | D28: =SUM(F28:P28) -> -0.044894403 | F28: =SUMIF(PnL_Speadsheet!$B$3:$BI$3,F$10,PnL_Speadsheet!$B28:$BI28)/1000 -> -0.041847542 | H28: =SUMIF(PnL_Speadsheet!$B$3:$BI$3,H$10,PnL_Speadsheet!$B28:$BI28)/1000 -> -0.0030468607 | J28: =SUMIF(PnL_Speadsheet!$B$3:$BI$3,J$10,PnL_Speadsheet!$B28:$BI28)/1000 -> 0 | L28: =SUMIF(PnL_Speadsheet!$B$3:$BI$3,L$10,PnL_Speadsheet!$B28:$BI28)/1000 -> 0 | N28: =SUMIF(PnL_Speadsheet!$B$3:$BI$3,N$10,PnL_Speadsheet!$B28:$BI28)/1000 -> 0 | P28: =SUMIF(PnL_Speadsheet!$B$3:$BI$3,P$10,PnL_Speadsheet!$B28:$BI28)/1000 -> 0
C29: After-sales services | D29: =SUM(F29:P29) -> -7.0210481e-05 | F29: =SUMIF(PnL_Speadsheet!$B$3:$BI$3,F$10,PnL_Speadsheet!$B29:$BI29)/1000 -> -7.0210481e-05 | H29: =SUMIF(PnL_Speadsheet!$B$3:$BI$3,H$10,PnL_Speadsheet!$B29:$BI29)/1000 -> 0 | J29: =SUMIF(PnL_Speadsheet!$B$3:$BI$3,J$10,PnL_Speadsheet!$B29:$BI29)/1000 -> 0 | L29: =SUMIF(PnL_Speadsheet!$B$3:$BI$3,L$10,PnL_Speadsheet!$B29:$BI29)/1000 -> 0 | N29: =SUMIF(PnL_Speadsheet!$B$3:$BI$3,N$10,PnL_Speadsheet!$B29:$BI29)/1000 -> 0 | P29: =SUMIF(PnL_Speadsheet!$B$3:$BI$3,P$10,PnL_Speadsheet!$B29:$BI29)/1000 -> 0
C30: Other support units | D30: =SUM(F30:P30) -> -0.39374351 | F30: =SUMIF(PnL_Speadsheet!$B$3:$BI$3,F$10,PnL_Speadsheet!$B30:$BI30)/1000 -> -0.39374351 | H30: =SUMIF(PnL_Speadsheet!$B$3:$BI$3,H$10,PnL_Speadsheet!$B30:$BI30)/1000 -> 0 | J30: =SUMIF(PnL_Speadsheet!$B$3:$BI$3,J$10,PnL_Speadsheet!$B30:$BI30)/1000 -> 0 | L30: =SUMIF(PnL_Speadsheet!$B$3:$BI$3,L$10,PnL_Speadsheet!$B30:$BI30)/1000 -> 0 | N30: =SUMIF(PnL_Speadsheet!$B$3:$BI$3,N$10,PnL_Speadsheet!$B30:$BI30)/1000 -> 0 | P30: =SUMIF(PnL_Speadsheet!$B$3:$BI$3,P$10,PnL_Speadsheet!$B30:$BI30)/1000 -> 0
C31: PBT | D31: =SUM(F31:P31) -> -0.45522317 | F31: =SUMIF(PnL_Speadsheet!$B$3:$BI$3,F$10,PnL_Speadsheet!$B32:$BI32)/1000 -> -0.40606252 | H31: =SUMIF(PnL_Speadsheet!$B$3:$BI$3,H$10,PnL_Speadsheet!$B32:$BI32)/1000 -> -0.049160642 | J31: =SUMIF(PnL_Speadsheet!$B$3:$BI$3,J$10,PnL_Speadsheet!$B32:$BI32)/1000 -> 0 | L31: =SUMIF(PnL_Speadsheet!$B$3:$BI$3,L$10,PnL_Speadsheet!$B32:$BI32)/1000 -> 0 | N31: =SUMIF(PnL_Speadsheet!$B$3:$BI$3,N$10,PnL_Speadsheet!$B32:$BI32)/1000 -> 0 | P31: =SUMIF(PnL_Speadsheet!$B$3:$BI$3,P$10,PnL_Speadsheet!$B32:$BI32)/1000 -> 0
C32: In which: PROFIT BEFORE SU | D32: =D19+D23+SUM(D25:D29) -> -0.061479657 | F32: =F19+F23+SUM(F25:F29) -> -0.012319016 | H32: =H19+H23+SUM(H25:H29) -> -0.049160642 | J32: =J19+J23+SUM(J25:J29) -> 0 | L32: =L19+L23+SUM(L25:L29) -> 0 | N32: =N19+N23+SUM(N25:N29) -> 0 | P32: =P19+P23+SUM(P25:P29) -> 0

Sheet PnL_Speadsheet
A1: PL PROJECTION
A2: 60 months
B3: =YEAR(B4) -> 2025 | C3: =YEAR(C4) -> 2025 | D3: =YEAR(D4) -> 2025 | E3: =YEAR(E4) -> 2025 | F3: =YEAR(F4) -> 2025 | G3: =YEAR(G4) -> 2025 | H3: =YEAR(H4) -> 2025 | I3: =YEAR(I4) -> 2025 | ... BI3: =YEAR(BI4) -> 2029
A4: Business month | B4: ='Saleplan&PnL'!D4 -> 45658 | C4: ='Saleplan&PnL'!E4 -> 45716 | D4: ='Saleplan&PnL'!F4 -> 45747 | E4: ='Saleplan&PnL'!G4 -> 45777 | F4: ='Saleplan&PnL'!H4 -> 45808 | G4: ='Saleplan&PnL'!I4 -> 45838 | H4: ='Saleplan&PnL'!J4 -> 45869 | I4: ='Saleplan&PnL'!K4 -> 45900 | ... BI4: ='Saleplan&PnL'!BK4 -> 47483
A5: Month on board | B5: 1 | C5: 2 | D5: 3 | E5: 4 | F5: 5 | G5: 6 | H5: 7 | I5: 8 | J5: 9 | K5: 10 | L5: 11 | M5: 12 | N5: 13 | O5: 14 | P5: 15 | Q5: 16 | R5: 17 | S5: 18 | T5: 19 | U5: 20 | V5: 21 | W5: 22 | X5: 23 | Y5: 24 | Z5: 25 | AA5: 26 | AB5: 27 | AC5: 28 | AD5: 29 | AE5: 30 | AF5: 31 | AG5: 32 | AH5: 33 | AI5: 34 | AJ5: 35 | AK5: 36 | AL5: =AK5+1 -> 37 | AM5: =AL5+1 -> 38 | AN5: =AM5+1 -> 39 | AO5: =AN5+1 -> 40 | AP5: =AO5+1 -> 41 | AQ5: =AP5+1 -> 42 | AR5: =AQ5+1 -> 43 | AS5: =AR5+1 -> 44 | ... BI5: =BH5+1 -> 60
A6: Unit: mVND
A7: ENR | B7: {=SUMPRODUCT(B$55:B$114,TRANSPOSE(SAP_Speadsheet!$F$37:$BM$37))} -> 9903.3896 | C7: {=SUMPRODUCT(C$55:C$114,TRANSPOSE(SAP_Speadsheet!$F$37:$BM$37))} -> 9553.8582 | D7: {=SUMPRODUCT(D$55:D$114,TRANSPOSE(SAP_Speadsheet!$F$37:$BM$37))} -> 9204.3268 | E7: {=SUMPRODUCT(E$55:E$114,TRANSPOSE(SAP_Speadsheet!$F$37:$BM$37))} -> 8854.7954 | F7: {=SUMPRODUCT(F$55:F$114,TRANSPOSE(SAP_Speadsheet!$F$37:$BM$37))} -> 8505.264 | G7: {=SUMPRODUCT(G$55:G$114,TRANSPOSE(SAP_Speadsheet!$F$37:$BM$37))} -> 8155.7326 | H7: {=SUMPRODUCT(H$55:H$114,TRANSPOSE(SAP_Speadsheet!$F$37:$BM$37))} -> 7806.2012 | I7: {=SUMPRODUCT(I$55:I$114,TRANSPOSE(SAP_Speadsheet!$F$37:$BM$37))} -> 7456.6698 | ... BI7: {=SUMPRODUCT(BI$55:BI$114,TRANSPOSE(SAP_Speadsheet!$F$37:$BM$37))} -> 0
