Workbook
Name IQ_CH: 110000
Name IQ_CQ: 5000
Name IQ_CY: 10000
Name IQ_DAILY: 500000
Name IQ_FH: 100000
Name IQ_FQ: 500
Name IQ_FY: 1000
Name IQ_LTM: 2000
Name IQ_MONTH: 15000
Name IQ_NTM: 6000
Name IQ_WEEK: 50000
Name IQ_YTD: 3000
Name SWITCH_EXPENSES: 1
Name SWITCH_LIABILITIES: 1
Name valuevx: 42.314159

Sheet SUM
B1: Group | C1: Indicators | D1: UPL | H1: CC
D2: Q4.25 | E2: % ANR | F2: Q3.25 | G2: % ANR | H2: Q4.25 | I2: % ANR | J2: Q3.25 | K2: % ANR
B3: SAP | C3: ANR | D3: =UPL!C3 -> 2.1278788 | F3: =UPL!E3 -> 2.7247316 | H3: 6.3975595 | J3: =CC!D2 -> 5.7023315
C4: TOI | D4: =UPL!C4 -> 1.5014426 | E4: =UPL!D4 -> 0.52920399 | F4: =UPL!E4 -> 1.8054191 | G4: =UPL!F4 -> 0.49695329 | H4: =CC!B3 -> 6.4976914 | I4: 0.20313032 | J4: =CC!D3 -> 4.7745402 | K4: =CC!E3 -> 0.16745923
C5: Provision | D5: =UPL!C8 -> -0.74448896 | E5: =UPL!D8 -> -0.26240532 | F5: =UPL!E8 -> -0.98714833 | G5: =UPL!F8 -> -0.27171896 | H5: =CC!B7 -> -4.5992838 | I5: -0.14378245 | J5: =CC!D7 -> -4.0988034 | K5: =CC!E7 -> -0.14375886
C6: OPEX | D6: =UPL!C9 -> -0.67697443 | E6: =UPL!D9 -> -0.2386089 | F6: =UPL!E9 -> -0.72842817 | G6: =UPL!F9 -> -0.20050457 | H6: =CC!B8 -> -2.0787752 | I6: -0.025405181 | J6: =CC!D8 -> -1.7224671 | K6: =CC!E8 -> -0.060412732
C7: PBT | D7: =UPL!C15 -> 0.079979182 | E7: =UPL!D15 -> 0.028189757 | F7: =UPL!E15 -> 0.089842629 | G7: =UPL!F15 -> 0.024729765 | H7: =CC!B14 -> -0.18036765 | I7: -0.0056386391 | J7: =CC!D14 -> -1.0467303 | K7: =CC!E14 -> -0.036712363
B9: Group | C9: Indicators | D9: Q4.25 | E9: %TOI | F9: Q3.25 | G9: %TOI | H9: Q4.25 | I9: %TOI | J9: Q3.25 | K9: %TOI
B10: Kinh doanh (Business Performance) | C10: Disburse/Spending | D10: =SUM(E24:G24) -> 6219.2999 | F10: =SUM(B24:D24) -> 4383.1873 | H10: =SUM(E43:G43)/10^9 -> 2836.1218 | J10: =SUM(B43:D43)/10^9 -> 2213.2744
C11: Balance | D11: =G27 -> 6942.3364 | F11: =D27 -> 5039.9037 | H11: =G44/10^9 -> 1526.7172 | J11: =D44/10^9 -> 1288.6859
C12: TOI | D12: =SUM(E30:G30) -> 886.48873 | E12: =D12/D$12 -> 1 | F12: =SUM(B30:D30) -> 590.39387 | G12: =F12/F$12 -> 1 | H12: =SUM(E45:G45)/10^9 -> 102.30841 | I12: =H12/H$12 -> 1 | J12: =SUM(B45:D45)/10^9 -> 86.862967 | K12: =J12/J$12 -> 1
C13: Provision | D13: =-SUM(E33:G33) -> -378.75388 | E13: =D13/D$12 -> -0.42725177 | F13: =-SUM(B33:D33) -> -236.01879 | G13: =F13/F$12 -> -0.39976498 | H13: =-SUM(E46:G46)/10^9 -> -75.778736 | I13: =H13/H$12 -> -0.74068921 | J13: =-SUM(B46:D46)/10^9 -> -64.673607 | K13: =J13/J$12 -> -0.74454752
C14: OPEX | D14: =-SUM(E36:G36)-SUM(E39:G39) -> -298.96083 | E14: =D14/D$12 -> -0.33724154 | F14: =-SUM(B36:D36)-SUM(B39:D39) -> -220.30859 | G14: =F14/F$12 -> -0.37315529 | H14: =-SUM(E47:G48)/10^9 -> -26.69349 | I14: =H14/H$12 -> -0.26091198 | J14: =-SUM(B47:D48)/10^9 -> -22.665906 | K14: =J14/J$12 -> -0.26093866
C15: PBT | D15: =D12+D13+D14 -> 208.77403 | E15: =D15/D$12 -> 0.23550669 | F15: =F12+F13+F14 -> 134.06648 | G15: =F15/F$12 -> 0.22707973 | H15: =H12+H13+H14 -> -0.16381588 | I15: =H15/H$12 -> -0.0016011966 | J15: =J12+J13+J14 -> -0.47654617 | K15: =J15/J$12 -> -0.0054861835
B16: Rủi ro (Risk) | C16: NPL | D16: 0.0537 | F16: 0.0659 | H16: 0.0587 | J16: 0.0722
C17: Loan group 2 | D17: 0.1102 | F17: 0.097 | H17: 0.087 | J17: 0.0907
A23: Lending | B23: 7 | C23: 8 | D23: 9 | E23: 10 | F23: 11 | G23: 12
A24: Disb | B24: =SUM(B25:B26)/10^9 -> 1316.8718 | C24: =SUM(C25:C26)/10^9 -> 1305.778 | D24: =SUM(D25:D26)/10^9 -> 1760.5376 | E24: =SUM(E25:E26)/10^9 -> 1972.1781 | F24: =SUM(F25:F26)/10^9 -> 2044.4451 | G24: =SUM(G25:G26)/10^9 -> 2202.6768
A25: Lend | B25: 1268523513257 | C25: 1258758785148 | D25: 1714453459136 | E25: 1916166104747 | F25: 1979098724767 | G25: 2134949493401
A26: PL | B26: 48348241756 | C26: 47019175255 | D26: 46084111381 | E26: 56011959212 | F26: 65346367397 | G26: 67727267652
A27: Balance | B27: =SUM(B28:B29)/10^9 -> 3933.4138 | C27: =SUM(C28:C29)/10^9 -> 4330.1548 | D27: =SUM(D28:D29)/10^9 -> 5039.9037 | E27: =SUM(E28:E29)/10^9 -> 5670.883 | F27: =SUM(F28:F29)/10^9 -> 6323.4987 | G27: =SUM(G28:G29)/10^9 -> 6942.3364
A28: Lend | B28: 3842542249454 | C28: 4223272311988 | D28: 4918139077644 | E28: 5541181903764 | F28: 6173157914715 | G28: 6773083111081
A29: PL | B29: 90871551821 | C29: 106882449807 | D29: 121764644082 | E29: 129701056042 | F29: 150340802454 | G29: 169253246441
A30: TOI | B30: =SUM(B31:B32)/10^9 -> 168.40021 | C30: =SUM(C31:C32)/10^9 -> 190.70326 | D30: =SUM(D31:D32)/10^9 -> 231.2904 | E30: =SUM(E31:E32)/10^9 -> 273.48745 | F30: =SUM(F31:F32)/10^9 -> 288.13213 | G30: =SUM(G31:G32)/10^9 -> 324.86916
A31: Lend | B31: 166643200482 | C31: 188368001928 | D31: 228207818774 | E31: 270089230602 | F31: 284024566303 | G31: 320447530496
A32: PL | B32: 1.7570116e+09 | C32: 2.3352577e+09 | D32: 3.0825768e+09 | E32: 3.398217e+09 | F32: 4.1075596e+09 | G32: 4.4216258e+09
A33: Provision | B33: =SUM(B34:B35)/10^9 -> 56.251918 | C33: =SUM(C34:C35)/10^9 -> 77.683192 | D33: =SUM(D34:D35)/10^9 -> 102.08368 | E33: =SUM(E34:E35)/10^9 -> 96.683579 | F33: =SUM(F34:F35)/10^9 -> 120.98057 | G33: =SUM(G34:G35)/10^9 -> 161.08973
A34: Lend | B34: 54290269578 | C34: 74096166881 | D34: 96789279416 | E34: 89997365466 | F34: 116243866061 | G34: 153697448775
A35: PL | B35: 1961648221 | C35: 3587025429 | D35: 5294403138 | E35: 6686213915 | F35: 4736705460 | G35: 7392277259
A36: Variable | B36: =SUM(B37:B38)/10^9 -> 48.753589 | C36: =SUM(C37:C38)/10^9 -> 40.457615 | D36: =SUM(D37:D38)/10^9 -> 53.34409 | E36: =SUM(E37:E38)/10^9 -> 61.990808 | F36: =SUM(F37:F38)/10^9 -> 65.457155 | G36: =SUM(G37:G38)/10^9 -> 72.785967
A37: Lend | B37: 4.7806214e+10 | C37: 3.9489225e+10 | D37: 5.2201902e+10 | E37: 6.0604093e+10 | F37: 6.3440027e+10 | G37: 7.0848916e+10
A38: PL | B38: 9.4737491e+08 | C38: 9.6838926e+08 | D38: 1.1421882e+09 | E38: 1.3867152e+09 | F38: 2.0171284e+09 | G38: 1.9370511e+09
A39: Overhead | B39: =B40/10^9 -> 29.820417 | C39: =C40/10^9 -> 24.187344 | D39: =D40/10^9 -> 23.745539 | E39: =E40/10^9 -> 44.862703 | F39: =F40/10^9 -> 21.238136 | G39: =G40/10^9 -> 32.626057
B40: 2.9820417e+10 | C40: 2.4187344e+10 | D40: 2.3745539e+10 | E40: 4.4862703e+10 | F40: 2.1238136e+10 | G40: 3.2626057e+10
A42: CC | B42: 7 | C42: =B42+1 -> 8 | D42: =C42+1 -> 9 | E42: =D42+1 -> 10 | F42: =E42+1 -> 11 | G42: =F42+1 -> 12
A43: Spend | B43: 729095173570 | C43: 7.8776999e+11 | D43: 696409205338 | E43: 850159523091 | F43: 836342237541 | G43: 1149620077165
A44: Balance | B44: 1137957901181 | C44: 1222872741673 | D44: 1288685931838 | E44: 1345398043554 | F44: 1462788996458 | G44: 1526717218023
A45: TOI | B45: 2.1099748e+10 | C45: 3.0455802e+10 | D45: 3.5307416e+10 | E45: 3.2235569e+10 | F45: 3.4063521e+10 | G45: 3.6009319e+10
A46: Provision | B46: 12950560114 | C46: 26624260010 | D46: 25098786740 | E46: 21789423336 | F46: 24826685539 | G46: 29162626763
A47: Variable | B47: 2.5062831e+09 | C47: 2.9070029e+09 | D47: 2.7996518e+09 | E47: 2.770358e+09 | F47: 3.4470389e+09 | G47: 3.3374261e+09
...

Sheet UPL
B2: OUTPUT UPL | C2: Q4.25 | D2: % ANR | E2: Q3.25 | F2: % ANR | G2: CL | H2: %ANR | I2: PD | J2: %ANR | K2: OD | L2: %ANR
B3: ANR | C3: 2.1278788 | E3: 2.7247316 | G3: 5.3154442 | I3: 0.42985568 | K3: 4.1860653
B4: TOI | C4: 1.5014426 | D4: 0.52920399 | E4: 1.8054191 | F4: 0.49695329 | G4: 4.3445684 | H4: 0.44582626 | I4: 0.36675528 | J4: 1.4626382 | K4: 1.4103862 | L4: 0.27738446
B5: Net interest income | C5: 0.9715005 | D5: 0.34241865 | E5: 1.2950848 | F5: 0.35648048 | G5: 3.2497903 | H5: 0.3334835 | I5: 0.14255811 | J5: 0.56852881 | K5: 1.2625242 | L5: 0.24830404
B6: Net fee income | C6: 0.52994208 | D6: 0.18678534 | E6: 0.51033431 | F6: 0.14047282 | G6: 1.0947781 | H6: 0.11234276 | I6: 0.22419717 | J6: 0.8941094 | K6: 0.14786203 | L6: 0.029080425
B7: Other income | C7: 0 | D7: 0 | E7: 0 | F7: 0 | G7: 0 | H7: 0 | I7: 0 | J7: 0 | K7: 0 | L7: 0
B8: PROVISION | C8: -0.74448896 | D8: -0.26240532 | E8: -0.98714833 | F8: -0.27171896 | G8: -2.654378 | H8: -0.27238411 | I8: -0.17376626 | J8: -0.69298843 | K8: -1.0323668 | L8: -0.20303836
B9: OPEX | C9: -0.67697443 | D9: -0.2386089 | E9: -0.72842817 | F9: -0.20050457 | G9: -1.3674514 | H9: -0.14032366 | I9: -0.11811444 | J9: -0.47104625 | K9: -0.45161934 | L9: -0.088821195
B10: Acquisition cost | C10: -0.19425794 | D10: -0.06846887 | E10: -0.24053646 | F10: -0.066209216 | G10: -0.56130303 | H10: -0.057599192 | I10: -0.04522502 | J10: -0.18035962 | K10: 0 | L10: 0
B11: UW & Disbursal | C11: -0.0270969 | D11: -0.0095506731 | E11: -0.035697198 | F11: -0.0098258847 | G11: -0.067770298 | H11: -0.0069543797 | I11: -0.0090250651 | J11: -0.035992406 | K11: -0.015808187 | L11: -0.0031090388
B12: Collection | C12: -0.053210653 | D12: -0.018754823 | E12: -0.060196653 | F12: -0.016569518 | G12: -0.0970129 | H12: -0.0099551656 | I12: -0.0066504319 | J12: -0.026522251 | K12: -0.054385719 | L12: -0.010696186
B13: After-sales services | C13: -0.0065506099 | D13: -0.0023088521 | E13: -0.007501 | F13: -0.0020646988 | G13: -0.010508231 | H13: -0.0010783224 | I13: -0.00042219527 | J13: -0.0016837356 | K13: -0.0066 | L13: -0.0012980398 | Q13: bao gồm promotion
B14: Support unit | C14: -0.39585833 | D14: -0.13952569 | E14: -0.38449686 | F14: -0.10583525 | G14: -0.63085698 | H14: -0.064736604 | I14: -0.056791732 | J14: -0.22648824 | K14: -0.37482543 | L14: -0.07371793
B15: PBT | C15: 0.079979182 | D15: 0.028189757 | E15: 0.089842629 | F15: 0.024729765 | G15: 0.32273904 | H15: 0.033118488 | I15: 0.07487458 | J15: 0.29860353 | K15: -0.073599932 | L15: -0.014475097
B16: Profit before support cost (PBSC) | C16: 0.47583751 | D16: 0.16771544 | E16: 0.47433949 | F16: 0.13056501 | G16: 0.95359602 | H16: 0.097855092 | I16: 0.13166631 | J16: 0.52509176 | K16: 0.3012255 | L16: 0.059242833
B18: INPUT UPL | C18: Q4.25 | E18: Q3.25 | G18: CL | I18: PD | K18: OD
B19: Ticket size/balance | C19: 7.9094011 | E19: 8.8766779 | G19: 16.867267 | I19: 3.5358329 | K19: 8.3141102
B20: Tenor | C20: 10 | E20: 10 | G20: 16 | I20: 1 | K20: 9
B21: IR | C21: 0.4881539 | E21: 0.48738193 | G21: 0.48835428 | I21: 0.56824848 | K21: 0.3510544
B22: Insurance | C22: 0.83404873 | E22: 0.7824628 | G22: 0.80384374 | I22: 0.99999601 | K22: 0
B23: B0-B1 | C23: 0.055769989 | E23: 0.051 | G23: 0.0512 | I23: 0.074 | K23: 0.04
B24: B0-B4 | C24: 0.035227782 | E24: 0.029081963 | G24: 0.033209836 | I24: 0.074228118 | K24: 0.029354578

Sheet CL
N1: mVND | AE1: mVND
B2: OUTPUT-CL Q4.25 | C2: CL all | D2: %ANR | E2: CAKE | F2: %ANR | G2: VDS | H2: %ANR | I2: MWG | J2: %ANR | K2: VNPAY | L2: %ANR | M2: ZLP | N2: %ANR | Y2: INPUT-CL Q4.25 | Z2: CL all | AA2: CAKE | AB2: VDS | AC2: MWG | AD2: VNPAY | AE2: ZLP
B3: ANR | C3: =UPL!G3 -> 5.3154442 | D3: =UPL!H3 -> 0 | E3: 5.2568565 | G3: 5.3372592 | I3: 6.3238063 | K3: 4.7456492 | M3: 3.9514537 | Y3: Ticket size | Z3: =UPL!G19 -> 16.867267 | AA3: 16.840199 | AB3: 17.381613 | AC3: 20.919738 | AD3: 14.837554 | AE3: 13.084425
B4: TOI | C4: =UPL!G4 -> 4.3445684 | D4: =UPL!H4 -> 0.44582626 | E4: 4.1077172 | F4: 0.42621918 | G4: 4.486583 | H4: 0.48035173 | I4: 5.2716319 | J4: 0.45470014 | K4: 3.5729466 | L4: 0.41066667 | M4: 2.7879213 | N4: 0.49803049 | Y4: Tenor | Z4: =UPL!G20 -> 16 | AA4: 16 | AB4: 15 | AC4: 16 | AD4: 16 | AE4: 11
B5: Net interest income | C5: =UPL!G5 -> 3.2497903 | D5: =UPL!H5 -> 0.3334835 | E5: 2.9852922 | F5: 0.30975569 | G5: 3.2712665 | H5: 0.35023502 | I5: 4.0995299 | J5: 0.35360147 | K5: 2.6903516 | L5: 0.30922313 | M5: 2.2036063 | N5: 0.39364925 | Y5: IR | Z5: =UPL!G21 -> 0.48835428 | AA5: 0.4688246 | AB5: 0.50594251 | AC5: 0.49067811 | AD5: 0.45290894 | AE5: 0.51333594
B6: Net fee income | C6: =UPL!G6 -> 1.0947781 | D6: =UPL!H6 -> 0.11234276 | E6: 1.122425 | F6: 0.11646348 | G6: 1.2153165 | H6: 0.1301167 | I6: 1.1721021 | J6: 0.10109867 | K6: 0.88259504 | L6: 0.10144354 | M6: 0.58431499 | N6: 0.10438124 | Y6: COF | Z6: 0.074073437 | AA6: 0.074024333 | AB6: 0.074149255 | AC6: 0.074263235 | AD6: 0.074 | AE6: 0.073
B7: Other income | C7: =UPL!G7 -> 0 | D7: =UPL!H7 -> 0 | E7: 0 | F7: 0 | G7: 0 | H7: 0 | I7: 0 | J7: 0 | K7: 0 | L7: 0 | M7: 0 | N7: 0 | Y7: %Insurance | Z7: =UPL!G22 -> 0.80384374 | AA7: 0.85460784 | AB7: 0.8370683 | AC7: 0.56325671 | AD7: 0.74160583 | AE7: 0.65675764
B8: PROVISION | C8: =UPL!G8 -> -2.654378 | D8: =UPL!H8 -> -0.27238411 | E8: -2.9819841 | F8: -0.30941244 | G8: -2.4374327 | H8: -0.26096141 | I8: -2.9210567 | J8: -0.25195326 | K8: -2.2889776 | L8: -0.26309009 | M8: -1.4180368 | N8: -0.25331618 | Y8: Insurance rate | Z8: 0.066130746 | AA8: 0.063474773 | AB8: 0.068360117 | AC8: 0.070077966 | AD8: 0.069722407 | AE8: 0.068766023
B9: OPEX | C9: =UPL!G9 -> -1.3674514 | D9: =UPL!H9 -> -0.14032366 | E9: -0.94476462 | F9: -0.098029337 | G9: -1.6955359 | H9: -0.18153093 | I9: -1.5959627 | J9: -0.13765841 | K9: -1.1152233 | L9: -0.12818133 | M9: -0.86059813 | N9: -0.15373609 | Y9: B0-B1 | Z9: =UPL!G23 -> 0.0512 | AA9: 0.0565 | AB9: 0.051 | AC9: 0.047 | AD9: 0.05 | AE9: 0.035
B10: Acquisition cost | C10: =UPL!G10 -> -0.56130303 | D10: =UPL!H10 -> -0.057599192 | E10: -0.1205038 | F10: -0.012503546 | G10: -0.98035963 | H10: -0.10496127 | I10: -0.84984541 | J10: -0.073302694 | K10: -0.29675107 | L10: -0.03410792 | M10: -0.26168849 | N10: -0.046747678 | Y10: B0-B4 | Z10: =UPL!G24 -> 0.033209836 | AA10: 0.03393428 | AB10: 0.031451185 | AC10: 0.02523425 | AD10: 0.029065036 | AE10: 0.02351816
B11: UW & Disbursal | C11: =UPL!G11 -> -0.067770298 | D11: =UPL!H11 -> -0.0069543797 | E11: -0.10499027 | F11: -0.010893853 | G11: -0.039784188 | H11: -0.0042594561 | I11: -0.03594871 | J11: -0.0031007255 | K11: -0.066001863 | L11: -0.0075861098 | M11: -0.040623996 | N11: -0.0072570157
B12: Collection | C12: =UPL!G12 -> -0.0970129 | D12: =UPL!H12 -> -0.0099551656 | E12: -0.096234951 | F12: -0.0099853956 | G12: -0.089235529 | H12: -0.010028239 | I12: -0.093139846 | J12: -0.0080336983 | K12: -0.098760427 | L12: -0.011351308 | M12: -0.073431848 | N12: -0.013117766
B13: Aftersale service | C13: =UPL!G13 -> -0.010508231 | D13: =UPL!H13 -> -0.0010783224 | E13: -0.0045594331 | F13: -0.00047308948 | G13: -0.0044302693 | H13: -0.00047432256 | I13: -0.0067944661 | J13: -0.0005860509 | K13: -0.0090030935 | L13: -0.0010347959 | M13: -0.0032599007 | N13: -0.00058234426
B14: Support unit | C14: =UPL!G14 -> -0.63085698 | D14: =UPL!H14 -> -0.064736604 | E14: -0.61847616 | F14: -0.064173454 | G14: -0.58172623 | H14: -0.062281965 | I14: -0.61023426 | J14: -0.052635238 | K14: -0.64470685 | L14: -0.074101195 | M14: -0.48159389 | N14: -0.086031281
B15: PBT | C15: =UPL!G15 -> 0.32273904 | D15: =UPL!H15 -> 0.033118488 | E15: 0.18096857 | F15: 0.018777406 | G15: 0.35361439 | H15: 0.037859387 | I15: 0.75461255 | J15: 0.065088465 | K15: 0.16874568 | L15: 0.01939526 | M15: 0.50928638 | N15: 0.09097823
B16: Profit before support cost (PBSC) | C16: =UPL!G16 -> 0.95359602 | D16: =UPL!H16 -> 0.097855092 | E16: 0.79944473 | F16: 0.08295086 | G16: 0.93534062 | H16: 0.10014135 | I16: 1.3648468 | J16: 0.1177237 | K16: 0.81345253 | L16: 0.093496455 | M16: 0.99088027 | N16: 0.17700951
Q18: 2025- update số chính xác
N19: mVND | AE19: mVND
B20: OUTPUT-CL Q3.25 | C20: CL all | D20: %ANR | E20: CAKE | F20: %ANR | G20: VDS | H20: %ANR | I20: MWG | J20: %ANR | K20: VNPAY | L20: %ANR | M20: ZLP | N20: %ANR | Q20: 2025 | R20: CAKE | S20: VDS | T20: MWG | U20: VNPAY | V20: ZALOPAY | W20: VNPOST | Y20: INPUT-CL Q3.25 | Z20: CL all | AA20: CAKE | AB20: VDS | AC20: MWG | AD20: VNPAY | AE20: ZLP
B21: ANR | C21: 5.0874047 | E21: 5.2815997 | G21: 4.8147952 | I21: 5.3082118 | K21: 3.9667575 | M21: 4.491385 | Q21: ANR | R21: 4.8510458 | S21: 4.6079268 | T21: 5.5101635 | U21: 4.0093313 | V21: 4.0176254 | W21: 4.1885304 | Y21: Ticket size | Z21: 16.17916 | AA21: 15.701281 | AB21: 15.244012 | AC21: 17.749743 | AD21: 12.481952 | AE21: 12.872001
B22: TOI | C22: 3.957503 | D22: 0.46674129 | E22: 4.0306292 | F22: 0.45788731 | G22: 4.1065206 | H22: 0.48736926 | I22: 4.1538536 | J22: 0.4695201 | K22: 2.9424098 | L22: 0.44506019 | M22: 3.4971427 | N22: 0.46718009 | Q22: TOI | R22: 3.7417421 | S22: 3.8453086 | T22: 4.6147629 | U22: 3.06527 | V22: 2.853451 | W22: 2.6986269 | Y22: Tenor | Z22: 14 | AA22: 15 | AB22: 15 | AC22: 16 | AD22: 15 | AE22: 12
B23: Net interest income | C23: 2.9290827 | D23: 0.34545112 | E23: 2.8811545 | F23: 0.32730476 | G23: 2.9908421 | H23: 0.35495853 | I23: 3.1577116 | J23: 0.35692377 | K23: 2.165832 | L23: 0.32759733 | M23: 2.9659145 | N23: 0.3962138 | Q23: Net interest income | R23: 2.7469097 | S23: 2.8750769 | T23: 3.5919173 | U23: 2.3117324 | V23: 2.3442506 | W23: 2.1777612 | Y23: IR | Z23: 0.49171714 | AA23: 0.48074914 | AB23: 0.49960028 | AC23: 0.4999 | AD23: 0.46182677 | AE23: 0.51610847
B24: Net fee income | C24: 1.0284203 | D24: 0.12129017 | E24: 1.1494746 | F24: 0.13058256 | G24: 1.1156784 | H24: 0.13241073 | I24: 0.99614198 | J24: 0.11259633 | K24: 0.77657779 | L24: 0.11746286 | M24: 0.53122822 | N24: 0.070966291 | Q24: Net fee income | R24: 0.99483241 | S24: 0.97023169 | T24: 1.0228457 | U24: 0.75353761 | V24: 0.50920043 | W24: 0.5208657 | Y24: COF | Z24: 0.069062919 | AA24: 0.069000786 | AB24: 0.069418206 | AC24: 0.070268942 | AD24: 0.066471711 | AE24: 0.072452529
B25: Other income | C25: 0 | D25: 0 | E25: 0 | F25: 0 | G25: 0 | H25: 0 | I25: 0 | J25: 0 | K25: 0 | L25: 0 | M25: 0 | N25: 0 | Q25: Other income | R25: 0 | S25: 0 | T25: 0 | U25: 0 | V25: 0 | W25: 0 | Y25: %Insurance | Z25: 0.78737421 | AA25: 0.838631 | AB25: 0.84366419 | AC25: 0.58738898 | AD25: 0.76346461 | AE25: 0.54373416
B26: PROVISION | C26: -2.4867754 | D26: -0.29328614 | E26: -2.7938741 | F26: -0.31738953 | G26: -2.4287587 | H26: -0.28824945 | I26: -2.3731795 | J26: -0.26824621 | K26: -1.8005698 | L26: -0.27234886 | M26: -1.8345326 | N26: -0.24507353 | Q26: PROVISION | R26: -2.6483212 | S26: -2.0615141 | T26: -2.6523747 | U26: -1.8339204 | V26: -1.5804208 | W26: -1.9687326 | Y26: Insurance rate | Z26: 0.068797748 | AA26: 0.066719498 | AB26: 0.068586572 | AC26: 0.069689054 | AD26: 0.068895819 | AE26: 0.069955586
B27: OPEX | C27: -1.0984948 | D27: -0.12955464 | E27: -0.85752434 | F27: -0.097416434 | G27: -1.4097903 | H27: -0.16731645 | I27: -1.2917247 | J27: -0.14600676 | K27: -0.92685263 | L27: -0.14019299 | M27: -0.99439331 | N27: -0.13284009 | Q27: OPEX | R27: -0.89429173 | S27: -1.5432364 | T27: -1.4624742 | U27: -1.0227486 | V27: -0.9420678 | W27: -1.1154263 | Y27: B0 - B1 | Z27: 0.051 | AA27: 0.054882022 | AB27: 0.049785227 | AC27: 0.057084155 | AD27: 0.048554378 | AE27: 0.034842547
B28: Acquisition cost | C28: -0.43632247 | D28: -0.051459143 | E28: -0.16401619 | F28: -0.018632558 | G28: -0.79698394 | H28: -0.094587489 | I28: -0.67931916 | J28: -0.076785086 | K28: -0.25130573 | L28: -0.038011761 | M28: -0.35973363 | N28: -0.048056485 | Q28: Acquisition cost | R28: -0.12699256 | S28: -0.85542807 | T28: -0.73082812 | U28: -0.2523564 | V28: -0.32667233 | W28: -0.46280761 | Y28: B0-B4 | Z28: 0.031023808 | AA28: 0.032162455 | AB28: 0.028741473 | AC28: 0.026295567 | AD28: 0.0287085 | AE28: 0.02324513
B29: UW & Disbursal | C29: -0.066756457 | D29: -0.0078731449 | E29: -0.11492326 | F29: -0.013055506 | G29: -0.016323977 | H29: -0.001937359 | I29: -0.045711099 | J29: -0.0051668359 | K29: -0.078267096 | L29: -0.011838449 | M29: -0.038198394 | N29: -0.0051028885 | Q29: UW & Disbursal | R29: -0.10256658 | S29: -0.035380849 | T29: -0.04480359 | U29: -0.077765496 | V29: -0.036738747 | W29: -0.032786197
B30: Collection | C30: -0.089243031 | D30: -0.010525174 | E30: -0.08785159 | F30: -0.0099801115 | G30: -0.089855962 | H30: -0.010664267 | I30: -0.084886508 | J30: -0.009594927 | K30: -0.08949884 | L30: -0.01353733 | M30: -0.088680324 | N30: -0.011846723 | Q30: Collection & aftersale service | R30: -0.096365419 | S30: -0.093726057 | T30: -0.1007614 | U30: -0.1030752 | V30: -0.082252594 | W30: -0.090967928
B31: Aftersale service | C31: -0.0096688256 | D31: -0.0011403251 | E31: -0.0065625 | F31: -0.00074551277 | G31: -0.0067585 | H31: -0.00080211095 | I31: -0.0057225 | J31: -0.00072753314 | K31: -0.0068285 | L31: -0.0010328587 | M31: -0.0068285 | N31: -0.00091221306
B32: Support unit | C32: -0.49650401 | D32: -0.058556853 | E32: -0.48417081 | F32: -0.055002746 | G32: -0.49986788 | H32: -0.059325221 | I32: -0.4753714 | J32: -0.053732377 | K32: -0.50095247 | L32: -0.075772588 | M32: -0.50095247 | N32: -0.066921781 | Q32: Support unit | R32: -0.56836718 | S32: -0.55870145 | T32: -0.58608113 | U32: -0.58955149 | V32: -0.49640412 | W32: -0.52886457
B33: PBT | C33: 0.37223275 | D33: 0.043900509 | E33: 0.37923073 | F33: 0.043081349 | G33: 0.26797165 | H33: 0.031803358 | I33: 0.48894947 | J33: 0.055267139 | K33: 0.21498733 | L33: 0.032518347 | M33: 0.66821686 | N33: 0.089266478 | Q33: PBT | R33: 0.1991292 | S33: 0.24055802 | T33: 0.49991399 | U33: 0.20860101 | V33: 0.33096238 | W33: -0.38553206
B34: Profit before support cost (PBSC) | C34: 0.86873677 | D34: 0.10245736 | E34: 0.86340154 | F34: 0.098084094 | G34: 0.76783953 | H34: 0.091128578 | I34: 0.96432087 | J34: 0.10899952 | K34: 0.71593979 | L34: 0.10829093 | M34: 1.1691693 | N34: 0.15618826 | Q34: Profit before support cost (PBSC) | R34: 0.76749637 | S34: 0.79925947 | T34: 1.0859951 | U34: 0.79815249 | V34: 0.8273665 | W34: 0.14333251
Q36: 2025 | R36: CAKE | S36: VDS | T36: MWG | U36: VNPAY | V36: ZALOPAY | W36: VNPOST
Q37: Ticket size | R37: 15.535167 | S37: 15.099872 | T37: 18.006321 | U37: 12.61782 | V37: 13.066893 | W37: 13.292814
Q38: Tenor | R38: 15 | S38: 15 | T38: 16 | U38: 15 | V38: 12 | W38: 13
Q39: IR | R39: 0.47805541 | S39: 0.50047328 | T39: 0.4999 | U39: 0.46188391 | V39: 0.51530281 | W39: 0.47370485
Q40: COF | R40: 0.069752525 | S40: 0.069921072 | T40: 0.070991996 | U40: 0.067126505 | V40: 0.073159269 | W40: 0.078471561
Q41: %Insurance | R41: 0.83962346 | S41: 0.84426988 | T41: 0.58273936 | U41: 0.76232181 | V41: 0.53916259 | W41: 0.54950855
Q42: Insurance rate | R42: 0.066314516 | S42: 0.068608414 | T42: 0.069706621 | U42: 0.068873419 | V42: 0.069542155 | W42: 0.068196212
...

Sheet PD
D1: 2025- nộp tháng 11.2025 | L1: 2025 - update số chính xác | R1: Q4.2025
G2: mVND | U2: mVND
D3: INPUT-PD Q3.25 | E3: PD all | F3: CAKE | G3: VDS | L3: 2025 | M3: CAKE | N3: VDS | R3: INPUT-PD Q4.25 | S3: PD all | T3: CAKE | U3: VDS
D4: Ticket size | E4: 3.4739502 | F4: 2.5131631 | G4: 4.4801054 | L4: Ticket size | M4: 2.7285551 | N4: 4.3735227 | R4: Ticket size | S4: 3.5358329 | T4: 2.8274266 | U4: 4.7630081
D5: Tenor | E5: 1 | F5: 1 | G5: 1 | L5: Tenor | M5: 1 | N5: 1 | R5: Tenor | S5: 1 | T5: 1 | U5: 1
D6: IR | E6: 0.57430775 | F6: 0.55 | G6: 0.59726686 | L6: IR | M6: 0.55 | N6: 0.59713662 | R6: IR | S6: 0.56824848 | T6: 0.55 | U6: 0.59764771
D7: COF | E7: 0.055252162 | F7: 0.054709424 | G7: 0.055431244 | L7: COF | M7: 0.05815972 | N7: 0.055095971 | R7: COF | S7: 0.059930813 | T7: 0.059166233 | U7: 0.060605705
D8: %Insurance | E8: 1 | F8: 1 | G8: 1 | L8: %Insurance | M8: 1 | N8: 1 | R8: %Insurance | S8: 0.99999601 | T8: 1 | U8: 1
D9: Insurance rate | E9: 0.079848379 | F9: 0.08 | G9: 0.079759347 | L9: Insurance rate | M9: 0.08 | N9: 0.08 | R9: Insurance rate | S9: 0.08 | T9: 0.08 | U9: 0.08
D10: Risk cost/Disbursement | L10: Risk cost/Disbursement | M10: -0.052643831 | N10: -0.048297793
D11: 2025 | L11: 2025 | M11: CAKE | N11: VDS
D12: B0 - B1 | E12: 0.076 | F12: 0.083 | G12: 0.072 | L12: B0 - B1 | M12: 0.082601486 | N12: 0.077489504 | R12: B0 - B1 | S12: 0.074 | T12: 0.074773935 | U12: 0.072
D13: B1 - B2 | L13: B1 - B2 | M13: 0.76449418 | N13: 0.77912703
D14: B2 - B3 | L14: B2 - B3 | M14: 0.94 | N14: 0.94250025
D15: B3 - B4 | L15: B3 - B4 | M15: 0.98111813 | N15: 0.98250314
D16: B4 - B5 | L16: B4 - B5 | M16: 0.98483752 | N16: 0.98100557
D17: B5 - B6 | L17: B5 - B6 | M17: 0.99 | N17: 0.97985578
D18: B6 - B7 | L18: B6 - B7 | M18: 0.995 | N18: 0.98617731
D19: B7 - B8 | L19: B7 - B8 | M19: 1 | N19: 0.97804457
D20: B0-B4 | E20: 0.051862721 | F20: 0.053183749 | G20: 0.050867041 | L20: B0-B4 | M20: =PRODUCT(M12:M15) -> 0.058238637 | N20: =PRODUCT(N12:N15) -> 0.05590705 | R20: B0-B4 | S20: 0.054633182 | T20: 0.054303899 | U20: 0.054393183
J22: mVND | X22: mVND
D23: OUTPUT-PD Q3.25 | E23: PD all | F23: %ANR | G23: CAKE | H23: %ANR | I23: VDS | J23: % ANR | L23: 2025 | M23: CAKE | N23: %ANR | O23: VDS | P23: % ANR | R23: OUTPUT-PD Q4.25 | S23: PD all | T23: %ANR | U23: CAKE | V23: %ANR | W23: VDS | X23: % ANR
D24: ANR | E24: 0.41787859 | G24: 0.3062337 | I24: 0.53243154 | L24: ANR | M24: 0.34203825 | O24: 0.53685543 | R24: ANR | S24: 0.42985568 | U24: 0.34322332 | W24: 0.57670862
D25: TOI | E25: 0.36294935 | F25: 1.4889466 | G25: 0.25811663 | H25: 1.444928 | I25: 0.47625066 | J25: 1.5333985 | L25: TOI | M25: 0.27856797 | N25: 1.3961745 | O25: 0.46455273 | P25: 1.4834089 | R25: TOI | S25: 0.36675528 | T25: 1.4626382 | U25: 0.28939376 | V25: 1.4454251 | W25: 0.50483786 | X25: 1.5006475
D26: Net interest income | E26: 0.14306179 | F26: 0.58689003 | G26: 0.098763469 | H26: 0.55287449 | I26: 0.19297021 | J26: 0.62131192 | L26: Net interest income | M26: 0.10555736 | N26: 0.5290504 | O26: 0.187239 | P26: 0.5978912 | R26: Net interest income | S26: 0.14255811 | T26: 0.56852881 | U26: 0.11011397 | V26: 0.54998247 | W26: 0.20282786 | X26: 0.60291261
D27: Net fee income | E27: 0.21988757 | F27: 0.90205655 | G27: 0.15935316 | H27: 0.89205349 | I27: 0.28328046 | J27: 0.91208654 | L27: Net fee income | M27: 0.17301061 | N27: 0.86712411 | O27: 0.27731374 | P27: 0.88551768 | R27: Net fee income | S27: 0.22419717 | T27: 0.8941094 | U27: 0.17927979 | V27: 0.89544261 | W27: 0.30201 | X27: 0.89773485
D28: Other income | E28: 0 | F28: 0 | G28: 0 | H28: 0 | I28: 0 | J28: 0 | L28: Other income | M28: 0 | N28: 0 | O28: 0 | P28: 0 | R28: Other income | S28: 0 | T28: 0 | U28: 0 | V28: 0 | W28: 0 | X28: 0
D29: PROVISION | E29: -0.16371398 | F29: -0.67161265 | G29: -0.12145252 | H29: -0.679887 | I29: -0.20498519 | J29: -0.65999693 | L29: PROVISION | M29: -0.1436416 | N29: -0.71992748 | O29: -0.21123149 | P29: -0.67450399 | R29: PROVISION | S29: -0.17376626 | T29: -0.69298843 | U29: -0.13879015 | V29: -0.69321038 | W29: -0.23303629 | X29: -0.6927082
D30: OPEX | E30: -0.15047878 | F30: -0.61731718 | G30: -0.092240044 | H30: -0.51635658 | I30: -0.21365702 | J30: -0.68791787 | L30: OPEX | M30: -0.072021394 | N30: -0.36096912 | O30: -0.18804137 | P30: -0.60045335 | R30: OPEX | S30: -0.11811444 | T30: -0.47104625 | U30: -0.072947415 | V30: -0.36434795 | W30: -0.20158865 | X30: -0.59922904
D31: Acquisition cost | E31: -0.059634389 | F31: -0.24464135 | G31: -0.0012237288 | H31: -0.0068503914 | I31: -0.12812878 | J31: -0.41254005 | L31: Acquisition cost | M31: -0.00097946806 | N31: -0.0049090653 | O31: -0.11638353 | P31: -0.37163565 | R31: Acquisition cost | S31: -0.04522502 | T31: -0.18035962 | U31: -0.00086734651 | V31: -0.0043321058 | W31: -0.12736995 | X31: -0.37861145
D32: UW & Disbursal | E32: -0.018614428 | F32: -0.076362964 | G32: -0.01876021 | H32: -0.10501901 | I32: -0.013336227 | J32: -0.042939047 | L32: UW & Disbursal | M32: -0.0094072455 | N32: -0.04714884 | O32: -0.0099876386 | P32: -0.031892508 | R32: UW & Disbursal | S32: -0.0090250651 | T32: -0.035992406 | U32: -0.0082669198 | V32: -0.0412905 | W32: -0.01033573 | X32: -0.030723305
D33: Collection | E33: -0.0065830034 | F33: -0.027005808 | G33: -0.0066091403 | H33: -0.03699774 | I33: -0.0065450458 | J33: -0.021073279 | L33: Collection & aftersale service | M33: -0.0070907703 | N33: -0.035538734 | O33: -0.0071262987 | P33: -0.022755683 | R33: Collection | S33: -0.0066504319 | T33: -0.026522251 | U33: -0.0066382101 | V33: -0.03315564 | W33: -0.0066403684 | X33: -0.0013941543
D34: Aftersale service | E34: -0.001 | F34: -0.0041023536 | G34: -0.001 | H34: -0.0055979655 | I34: -0.001 | J34: -0.0032197298 | R34: Aftersale service | S34: -0.00042219527 | T34: -0.0016837356 | U34: -0.00038320582 | V34: -0.001913985 | W34: -0.00045087401 | X34: -9.4661608e-05
D35: Support unit | E35: -0.064646964 | F35: -0.2652047 | G35: -0.064646964 | H35: -0.36189148 | I35: -0.064646964 | J35: -0.20814576 | L35: Support unit | M35: -0.05454391 | N35: -0.27337248 | O35: -0.05454391 | P35: -0.17416951 | R35: Support unit | S35: -0.056791732 | T35: -0.22648824 | U35: -0.056791732 | V35: -0.28365571 | W35: -0.056791732 | X35: -0.16881533
D36: PBT | E36: 0.048756586 | F36: 0.20001676 | G36: 0.044424068 | H36: 0.2486844 | I36: 0.057608455 | J36: 0.18548366 | L36: PBT | M36: 0.062904978 | N36: 0.31527791 | O36: 0.065279866 | P36: 0.20845154 | R36: PBT | S36: 0.07487458 | T36: 0.29860353 | U36: 0.077656199 | V36: 0.38786675 | W36: 0.070212907 | X36: 0.20871022
D37: Profit before support cost (PBSC) | E37: 0.11340355 | F37: 0.46522146 | G37: 0.10907103 | H37: 0.61057588 | I37: 0.12225542 | J37: 0.39362942 | L37: Profit before support cost (PBSC) | M37: 0.11744889 | N37: 0.58865039 | O37: 0.11982378 | P37: 0.38262105 | R37: Profit before support cost (PBSC) | S37: 0.13166631 | T37: 0.52509176 | U37: 0.13444793 | V37: 0.67152246 | W37: 0.12700464 | X37: 0.37752555

Sheet PL
C4: RR | D4: Q3.2025 | E4: MWG | F4: VNPAY | G4: BE | H4: VDS
C5: B0 - B1 | D5: =AVERAGE(D17:H17) -> 0.0354 | E5: =AVERAGE(D27:H27) -> 0.026 | F5: =AVERAGE(D37:H37) -> 0.0316 | G5: =AVERAGE(D46:H46) -> 0.031 | H5: =AVERAGE(D56:H56) -> 0.0396 | L5: OUTPUT- Q4.25 | M5: PL all | N5: %ANR | O5: MWG | P5: % ANR | Q5: VNPAY | R5: % ANR | S5: BE | T5: % ANR | U5: VDS | V5: % ANR | Y5: INPUT | Z5: PL Q4.25 | AA5: MWG | AB5: VNPAY | AC5: BE | AD5: VDS | AE5: PL Q3.25
C6: B1 - B2 | D6: =AVERAGE(D18:H18) -> 0.836537 | E6: =AVERAGE(D28:H28) -> 0.846537 | F6: =AVERAGE(D38:H38) -> 0.848 | G6: =AVERAGE(D47:H47) -> 0.84 | H6: =AVERAGE(D57:H57) -> 0.836537 | L6: Spending | M6: 23.378979 | O6: 70.053499 | Q6: 28.345619 | S6: 13.867901 | U6: 10.931268 | Y6: Spending/actived card | Z6: 0.94837812 | AA6: 2.7614908 | AB6: 0.99931411 | AC6: 0.48485774 | AD6: 0.46655481 | AE6: =Z26 -> 0.68778008
C7: B2 - B3 | D7: =AVERAGE(D19:H19) -> 0.91739543 | E7: =AVERAGE(D29:H29) -> 0.91739543 | F7: =AVERAGE(D39:H39) -> 0.912 | G7: =AVERAGE(D48:H48) -> 0.912 | H7: =AVERAGE(D58:H58) -> 0.91739543 | L7: ANR | M7: 0.85162395 | O7: 3.4029014 | Q7: 1.2857537 | S7: 0.58727134 | U7: 0.69799179 | Y7: IR | Z7: 0.39918244 | AA7: 0.55 | AB7: 0.29 | AC7: 0.4 | AD7: 0.39 | AE7: =Z27 -> 0.41540864
C8: B3 - B4 | D8: =AVERAGE(D20:H20) -> 0.95910102 | E8: =AVERAGE(D30:H30) -> 0.95910102 | F8: =AVERAGE(D40:H40) -> 0.95640398 | G8: =AVERAGE(D49:H49) -> 0.95640398 | H8: =AVERAGE(D59:H59) -> 0.95910102 | L8: TOI | M8: 1.2514562 | N8: =M8/$M$7/60*12 -> 0.29389878 | O8: 5.2530109 | P8: =O8/$O$7/60*12 -> 0.30873718 | Q8: 1.2178535 | R8: =Q8/$Q$7/60*12 -> 0.18943808 | S8: 1.1660819 | T8: =S8/$S$7/60*12 -> 0.39711863 | U8: 1.2597551 | V8: =U8/$U$7/60*12 -> 0.3609656 | Y8: COF | Z8: 0.058486563 | AA8: 0.05801542 | AB8: 0.058283453 | AC8: 0.058366656 | AD8: 0.057819823 | AE8: =Z28 -> 0.053
C9: B4 - B5 | D9: =AVERAGE(D21:H21) -> 0.98613911 | E9: =AVERAGE(D31:H31) -> 0.98613911 | F9: =AVERAGE(D41:H41) -> 0.96499631 | G9: =AVERAGE(D50:H50) -> 0.96499631 | H9: =AVERAGE(D60:H60) -> 0.98613911 | L9: Net interest income | M9: 0.19544302 | N9: =M9/$M$7/60*12 -> 0.045898902 | O9: 1.5634382 | P9: =O9/$O$7/60*12 -> 0.091888542 | Q9: 0.46381274 | R9: =Q9/$Q$7/60*12 -> 0.072146439 | S9: 0.41454961 | T9: =S9/$S$7/60*12 -> 0.14117822 | U9: 0.65095156 | V9: =U9/$U$7/60*12 -> 0.18652127 | Y9: Monthlyfee | Z9: 0.0275 | AA9: 0.02 | AB9: 0.03 | AC9: 0.03 | AD9: 0.03 | AE9: =Z29 -> 0.03222005
C10: B5 - B6 | D10: =AVERAGE(D22:H22) -> 0.98774565 | E10: =AVERAGE(D32:H32) -> 0.98774565 | F10: =AVERAGE(D42:H42) -> 0.98811344 | G10: =AVERAGE(D51:H51) -> 0.98811344 | H10: =AVERAGE(D61:H61) -> 0.98774565 | L10: Net fee income | M10: 1.0560132 | N10: =M10/$M$7/60*12 -> 0.24799988 | O10: 3.6895727 | P10: =O10/$O$7/60*12 -> 0.21684864 | Q10: 0.75404077 | R10: =Q10/$Q$7/60*12 -> 0.11729164 | S10: 0.75153234 | T10: =S10/$S$7/60*12 -> 0.25594041 | U10: 0.60880355 | V10: =U10/$U$7/60*12 -> 0.17444433 | Y10: Revolving rate | Z10: 0.50625801 | AA10: 0.596559 | AB10: 0.57723772 | AC10: 0.6374889 | AD10: 0.78605061 | AE10: =Z30 -> 0.5115999
C11: B6 - B7 | D11: =AVERAGE(D23:H23) -> 0.98997591 | E11: =AVERAGE(D33:H33) -> 0.98997591 | F11: =AVERAGE(D43:H43) -> 0.99128937 | G11: =AVERAGE(D52:H52) -> 0.99128937 | H11: =AVERAGE(D62:H62) -> 0.98997591 | L11: Other income | M11: 0 | N11: =M11/$M$7/60*12 -> 0 | O11: 0 | P11: =O11/$O$7/60*12 -> 0 | Q11: 0 | R11: =Q11/$Q$7/60*12 -> 0 | S11: 0 | T11: =S11/$S$7/60*12 -> 0 | U11: 0 | V11: =U11/$U$7/60*12 -> 0 | Y11: Activated rate at Month1 | Z11: 0.68390833 | AA11: 0.68 | AB11: 0.71086667 | AC11: 0.8441 | AD11: 0.50066667 | AE11: =Z31 -> 0.66492241
C12: B7 - B8 | D12: =AVERAGE(D24:H24) -> 1 | E12: =AVERAGE(D34:H34) -> 1 | F12: =AVERAGE(D44:H44) -> 1 | G12: =AVERAGE(D53:H53) -> 1 | H12: =AVERAGE(D63:H63) -> 1 | L12: PROVISION | M12: -1.0709506 | N12: =M12/$M$7/60*12 -> -0.25150786 | O12: -3.1603759 | P12: =O12/$O$7/60*12 -> -0.18574596 | Q12: -1.5019712 | R12: =Q12/$Q$7/60*12 -> -0.23363281 | S12: -0.74502468 | T12: =S12/$S$7/60*12 -> -0.25372417 | U12: -1.013543 | V12: =U12/$U$7/60*12 -> -0.29041687 | Y12: Activated rate at Month4 | Z12: 0.64928731 | AA12: 0.635 | AB12: 0.68288883 | AC12: 0.7931 | AD12: 0.48616042 | AE12: =Z32 -> 0.59137825
C13: B0-B4 | D13: =PRODUCT(D5:D8) -> 0.026056096 | E13: =PRODUCT(E5:E8) -> 0.019366013 | F13: =PRODUCT(F5:F8) -> 0.023373252 | G13: =PRODUCT(G5:G8) -> 0.022713141 | H13: =PRODUCT(H5:H8) -> 0.029147497 | L13: OPEX | M13: -0.59544075 | N13: =M13/$M$7/60*12 -> -0.13983654 | O13: -1.603651 | P13: =O13/$O$7/60*12 -> -0.09425198 | Q13: -0.4343051 | R13: =Q13/$Q$7/60*12 -> -0.067556502 | S13: -0.82618587 | T13: =S13/$S$7/60*12 -> -0.28136427 | U13: -0.53750267 | V13: =U13/$U$7/60*12 -> -0.15401404 | Y13: % installment | Z13: 0.32710646 | AA13: 0.51523934 | AE13: =Z33 -> 0.37546996
L14: Sales & Marketing | M14: -0.13745488 | N14: =M14/$M$7/60*12 -> -0.032280651 | O14: -0.88136368 | P14: =O14/$O$7/60*12 -> -0.051800717 | Q14: -0.030062065 | R14: =Q14/$Q$7/60*12 -> -0.004676178 | S14: -0.24392793 | T14: =S14/$S$7/60*12 -> -0.083071626 | U14: -0.19328664 | V14: =U14/$U$7/60*12 -> -0.055383643 | Y14: B0-B1 | Z14: 0.0325 | AA14: 0.024 | AB14: 0.03 | AC14: 0.033 | AD14: 0.043 | AE14: =Z34 -> 0.0354
L15: UW & Disbursal cost | M15: -0.053205367 | N15: =M15/$M$7/60*12 -> -0.012495038 | O15: -0.15872761 | P15: =O15/$O$7/60*12 -> -0.0093289571 | Q15: -0.030107629 | R15: =Q15/$Q$7/60*12 -> -0.0046832656 | S15: -0.017626638 | T15: =S15/$S$7/60*12 -> -0.0060028941 | U15: -0.063071382 | V15: =U15/$U$7/60*12 -> -0.018072242 | Y15: B0-B4 | Z15: 0.023250136 | AA15: 0.017002592 | AB15: 0.021733417 | AC15: 0.023805635 | AD15: 0.030412932 | AE15: =Z35 -> 0.026056096
L16: Collection | M16: -0.1972123 | N16: =M16/$M$7/60*12 -> -0.046314409 | O16: -0.202944 | P16: =O16/$O$7/60*12 -> -0.011927704 | Q16: -0.19855552 | R16: =Q16/$Q$7/60*12 -> -0.030885468 | S16: -0.228816 | T16: =S16/$S$7/60*12 -> -0.077925137 | U16: -0.16400834 | V16: =U16/$U$7/60*12 -> -0.046994346
C17: Q3 | D17: 0.065 | E17: 0.035 | F17: 0.03 | G17: 0.025 | H17: 0.022 | L17: After-sales services | M17: -0.09358774 | N17: =M17/$M$7/60*12 -> -0.021978654 | O17: -0.24283755 | P17: =O17/$O$7/60*12 -> -0.014272383 | Q17: -0.04404579 | R17: =Q17/$Q$7/60*12 -> -0.0068513575 | S17: -0.20383534 | T17: =S17/$S$7/60*12 -> -0.069417772 | U17: -0.0077765291 | V17: =U17/$U$7/60*12 -> -0.002228258
D18: 0.9 | E18: 0.85268498 | F18: 0.83 | G18: 0.8 | H18: 0.8 | L18: Support unit | M18: -0.11398046 | N18: =M18/$M$7/60*12 -> -0.026767792 | O18: -0.11777815 | P18: =O18/$O$7/60*12 -> -0.0069222194 | Q18: -0.1315341 | R18: =Q18/$Q$7/60*12 -> -0.020460233 | S18: -0.13197997 | T18: =S18/$S$7/60*12 -> -0.044946844 | U18: -0.10935978 | V18: =U18/$U$7/60*12 -> -0.03133555
D19: 0.96 | E19: 0.92697715 | F19: 0.9 | G19: 0.9 | H19: 0.9 | L19: PBT | M19: -0.41493513 | N19: =M19/$M$7/60*12 -> -0.097445622 | O19: 0.48898399 | P19: =O19/$O$7/60*12 -> 0.028739239 | Q19: -0.71842283 | R19: =Q19/$Q$7/60*12 -> -0.11175124 | S19: -0.4051286 | T19: =S19/$S$7/60*12 -> -0.13796982 | U19: -0.29129051 | V19: =U19/$U$7/60*12 -> -0.083465313
D20: 0.98201991 | E20: 0.9634852 | F20: 0.95 | G20: 0.95 | H20: 0.95 | L20: Profit before support cost (PBSC) | M20: -0.30095466 | N20: =M20/$M$7/60*12 -> -0.07067783 | O20: 0.60676214 | P20: =O20/$O$7/60*12 -> 0.035661458 | Q20: -0.58688873 | R20: =Q20/$Q$7/60*12 -> -0.091291006 | S20: -0.27314864 | T20: =S20/$S$7/60*12 -> -0.093022974 | U20: -0.18193073 | V20: =U20/$U$7/60*12 -> -0.052129762
D21: 0.98498153 | E21: 0.97571401 | F21: 0.99 | G21: 0.99 | H21: 0.99
D22: 0.9852836 | E22: 0.98344467 | F22: 0.99 | G22: 0.99 | H22: 0.99
D23: 0.99322342 | E23: 0.98665613 | F23: 0.99 | G23: 0.99 | H23: 0.99
D24: 1 | E24: 1 | F24: 1 | G24: 1 | H24: 1
D25: 1 | E25: 1 | F25: 1 | G25: 1 | H25: 1 | L25: OUTPUT-PL Q3.25 | M25: PL all | N25: %ANR | O25: MWG | P25: % ANR | Q25: VNPAY | R25: % ANR | S25: BE | T25: % ANR | U25: VDS | V25: % ANR | Y25: INPUT-PL Q3.25 | Z25: PL all | AA25: MWG | AB25: VNPAY | AC25: BE | AD25: VDS
L26: Spending | M26: 12.727565 | O26: 40.25 | Q26: 19.678789 | S26: 7.9953 | U26: 7.5789 | Y26: Spending/actived card | Z26: 0.68778008 | AA26: 1.6666667 | AB26: 1 | AC26: 0.45 | AD26: 0.45
C27: MWG | D27: 0.05 | E27: 0.025 | F27: 0.02 | G27: 0.02 | H27: 0.015 | L27: ANR | M27: 0.50119744 | O27: 2.0683353 | Q27: 0.6957773 | S27: 0.28224752 | U27: 0.31151108 | Y27: IR | Z27: 0.41540864 | AA27: 0.55 | AB27: 0.39 | AC27: 0.39 | AD27: 0.39
D28: 0.95 | E28: 0.85268498 | F28: 0.83 | G28: 0.8 | H28: 0.8 | L28: TOI | M28: 0.76624159 | N28: =M28/M$27/60*12 -> 0.30576437 | O28: 1.7707783 | P28: =O28/O$27/60*12 -> 0.1712274 | Q28: 0.68428776 | R28: =Q28/Q$27/60*12 -> 0.19669735 | S28: 0.41088347 | T28: =S28/S$27/60*12 -> 0.29115117 | U28: 0.52807999 | V28: =U28/U$27/60*12 -> 0.33904412 | Y28: COF | Z28: 0.053 | AA28: 0.053 | AB28: 0.053 | AC28: 0.053 | AD28: 0.053
D29: 0.96 | E29: 0.92697715 | F29: 0.9 | G29: 0.9 | H29: 0.9 | L29: Net interest income | M29: 0.045832731 | N29: =M29/M$27/60*12 -> 0.018289292 | O29: 0.0093353935 | P29: =O29/O$27/60*12 -> 0.00090269633 | Q29: 0.12010269 | R29: =Q29/Q$27/60*12 -> 0.034523315 | S29: 0.047951085 | T29: =S29/S$27/60*12 -> 0.033978038 | U29: 0.054384219 | V29: =U29/U$27/60*12 -> 0.034916395 | Y29: Monthlyfee | Z29: 0.03222005 | AA29: 0.022 | AB29: 0.033 | AC29: 0.033 | AD29: 0.033
D30: 0.98201991 | E30: 0.9634852 | F30: 0.95 | G30: 0.95 | H30: 0.95 | L30: Net fee income | M30: 0.72040886 | N30: =M30/M$27/60*12 -> 0.28747508 | O30: 1.761443 | P30: =O30/O$27/60*12 -> 0.1703247 | Q30: 0.56418506 | R30: =Q30/Q$27/60*12 -> 0.16217404 | S30: 0.36293238 | T30: =S30/S$27/60*12 -> 0.25717313 | U30: 0.47369577 | V30: =U30/U$27/60*12 -> 0.30412772 | Y30: Revolving rate | Z30: 0.5115999 | AA30: 0.3 | AB30: 0.56195721 | AC30: 0.56195721 | AD30: 0.6212039
D31: 0.98498153 | E31: 0.97571401 | F31: 0.99 | G31: 0.99 | H31: 0.99 | L31: Other income | N31: =M31/M$27/60*12 -> 0 | P31: =O31/O$27/60*12 -> 0 | R31: =Q31/Q$27/60*12 -> 0 | T31: =S31/S$27/60*12 -> 0 | V31: =U31/U$27/60*12 -> 0 | Y31: Activated rate at Month1 | Z31: 0.66492241 | AA31: 0.55 | AB31: 0.72247981 | AC31: 0.8 | AD31: 0.54
D32: 0.9852836 | E32: 0.98344467 | F32: 0.99 | G32: 0.99 | H32: 0.99 | L32: PROVISION | M32: -0.73067779 | N32: =M32/M$27/60*12 -> -0.29157284 | O32: -2.1468018 | P32: =O32/O$27/60*12 -> -0.2075874 | Q32: -0.94948097 | R32: =Q32/Q$27/60*12 -> -0.27292669 | S32: -0.37080476 | T32: =S32/S$27/60*12 -> -0.26275148 | U32: -0.49083779 | V32: =U32/U$27/60*12 -> -0.31513344 | Y32: Activated rate at Month4 | Z32: 0.59137825 | AA32: 0.535 | AB32: 0.66247981 | AC32: 0.65 | AD32: 0.504
D33: 0.99322342 | E33: 0.98665613 | F33: 0.99 | G33: 0.99 | H33: 0.99 | L33: OPEX | M33: -0.38866078 | N33: =M33/M$27/60*12 -> -0.15509288 | O33: =O34+O39 -> -0.81285499 | P33: =O33/O$27/60*12 -> -0.078599923 | Q33: =Q34+Q39 -> -0.36080081 | R33: =Q33/Q$27/60*12 -> -0.10371158 | S33: =S34+S39 -> -0.26706367 | T33: =S33/S$27/60*12 -> -0.18924076 | U33: =U34+U39 -> -0.3554792 | V33: =U33/U$27/60*12 -> -0.22822893 | Y33: % installment | Z33: 0.37546996 | AA33: 0.5 | AB33: 0 | AC33: 0 | AD33: 0
D34: 1 | E34: 1 | F34: 1 | G34: 1 | H34: 1 | L34: Variable Cost | M34: =SUM(M35:M38) -> -0.32714226 | N34: =M34/M$27/60*12 -> -0.13054426 | O34: =SUM(O35:O38) -> -0.7242593 | P34: =O34/O$27/60*12 -> -0.070033064 | Q34: =SUM(Q35:Q38) -> -0.2896933 | R34: =Q34/Q$27/60*12 -> -0.083271846 | S34: =SUM(S35:S38) -> -0.22110252 | T34: =S34/S$27/60*12 -> -0.15667278 | U34: =SUM(U35:U38) -> -0.2943315 | V34: =U34/U$27/60*12 -> -0.18897017 | Y34: B0 - B1 | Z34: 0.0354 | AA34: 0.0242 | AB34: 0.029 | AC34: 0.031 | AD34: 0.0356
L35: Sales & Marketing | M35: -0.11800728 | N35: =M35/M$27/60*12 -> -0.047090135 | O35: -0.42030631 | P35: =O35/O$27/60*12 -> -0.040641989 | Q35: -0.068428776 | R35: =Q35/Q$27/60*12 -> -0.019669735 | S35: -0.079350118 | T35: =S35/S$27/60*12 -> -0.056227328 | U35: -0.072915689 | V35: =U35/U$27/60*12 -> -0.046814187 | Y35: B0-B4 | Z35: 0.026056096 | AA35: 0.018025289 | AB35: 0.020994827 | AC35: 0.022713141 | AD35: 0.026203305
C36: VNPAY | L36: UW & Disbursal cost | M36: -0.060689763 | N36: =M36/M$27/60*12 -> -0.024217906 | O36: -0.092771754 | P36: =O36/O$27/60*12 -> -0.0089706687 | Q36: -0.04940235 | R36: =Q36/Q$27/60*12 -> -0.014200621 | S36: -0.0299442 | T36: =S36/S$27/60*12 -> -0.021218397 | U36: -0.074269372 | V36: =U36/U$27/60*12 -> -0.047683295
D37: 0.06 | E37: 0.029 | F37: 0.026 | G37: 0.023 | H37: 0.02 | L37: Collection | M37: -0.13595951 | N37: =M37/M$27/60*12 -> -0.054253874 | O37: -0.1932 | P37: =O37/O$27/60*12 -> -0.01868169 | Q37: -0.15743031 | R37: =Q37/Q$27/60*12 -> -0.045253075 | S37: -0.10248 | T37: =S37/S$27/60*12 -> -0.072617114 | U37: -0.134736 | V37: =U37/U$27/60*12 -> -0.086504789
D38: 0.9 | E38: 0.86 | F38: 0.86 | G38: 0.82 | H38: 0.8 | L38: After-sales services | M38: -0.012485702 | N38: =M38/M$27/60*12 -> -0.0049823486 | O38: -0.017981238 | P38: =O38/O$27/60*12 -> -0.001738716 | Q38: -0.014431865 | R38: =Q38/Q$27/60*12 -> -0.0041484152 | S38: -0.0093282016 | T38: =S38/S$27/60*12 -> -0.0066099442 | U38: -0.012410439 | V38: =U38/U$27/60*12 -> -0.0079678958
D39: 0.96 | E39: 0.9 | F39: 0.9 | G39: 0.9 | H39: 0.9 | L39: Overhead cost | M39: -0.061518527 | N39: =M39/M$27/60*12 -> -0.02454862 | O39: -0.088595685 | P39: =O39/O$27/60*12 -> -0.008566859 | Q39: -0.071107506 | R39: =Q39/Q$27/60*12 -> -0.020439731 | S39: -0.045961151 | T39: =S39/S$27/60*12 -> -0.032567976 | U39: -0.061147699 | V39: =U39/U$27/60*12 -> -0.039258764
D40: 0.98201991 | E40: 0.95 | F40: 0.95 | G40: 0.95 | H40: 0.95 | L40: PBT | M40: -0.29157846 | N40: =M40/M$27/60*12 -> -0.11635273 | O40: -1.1888784 | P40: =O40/O$27/60*12 -> -0.11495993 | Q40: -0.62599402 | R40: =Q40/Q$27/60*12 -> -0.17994092 | S40: -0.22698496 | T40: =S40/S$27/60*12 -> -0.16084107 | U40: -0.318237 | V40: =U40/U$27/60*12 -> -0.20431825
D41: 0.98498153 | E41: 0.95 | F41: 0.95 | G41: 0.95 | H41: 0.99 | L41: Profit before support cost (PBSC) | M41: -0.29157846 | N41: =M41/M$27/60*12 -> -0.11635273 | O41: -1.1002827 | P41: =O41/O$27/60*12 -> -0.10639307 | Q41: -0.55488651 | R41: =Q41/Q$27/60*12 -> -0.15950118 | S41: -0.18102381 | T41: =S41/S$27/60*12 -> -0.1282731 | U41: -0.2570893 | V41: =U41/U$27/60*12 -> -0.16505949
D42: 0.9852836 | E42: 0.9852836 | F42: 0.99 | G42: 0.99 | H42: 0.99
D43: 0.99322342 | E43: 0.99322342 | F43: 0.99 | G43: 0.99 | H43: 0.99
...

Sheet CC
A1: OUTPUT-CC 2025 | B1: Q4.25 | C1: %ANR | D1: Q3.25 | E1: %ANR
A2: ANR | B2: 6.3975595 | D2: 5.7023315
A3: TOI | B3: 6.4976914 | C3: 0.20313032 | D3: 4.7745402 | E3: =D3/$D$2/60*12 -> 0.16745923
A4: Net interest income | B4: 3.951425 | C4: 0.12352914 | D4: 2.7900762 | E4: =D4/$D$2/60*12 -> 0.097857382
A5: Net fee income | B5: 2.5462664 | C5: 0.079601179 | D5: 1.984464 | E5: =D5/$D$2/60*12 -> 0.069601847
A6: Other income | B6: 0 | C6: 0 | D6: 0 | E6: =D6/$D$2/60*12 -> 0
A7: PROVISION | B7: -4.5992838 | C7: -0.14378245 | D7: -4.0988034 | E7: =D7/$D$2/60*12 -> -0.14375886
A8: OPEX | B8: -2.0787752 | C8: =B8/B3/60*12 -> -0.063985039 | D8: -1.7224671 | E8: =D8/$D$2/60*12 -> -0.060412732
A9: Acquisition cost | B9: -0.2218681 | C9: -0.0069360229 | D9: -0.2 | E9: =D9/$D$2/60*12 -> -0.0070146746
A10: UW & Disbursal cost, physical | B10: -0.20858999 | C10: =B10/B2 -> -0.032604619 | D10: -0.25722735 | E10: =D10/$D$2/60*12 -> -0.0090218309
A11: Collection | B11: -0.25032 | C11: -0.0078254841 | D11: -0.267778 | E11: =D11/$D$2/60*12 -> -0.0093918777
A12: After-sales services | B12: -0.13187768 | C12: =B12/B2 -> -0.020613749 | D12: -0.15892321 | E12: =D12/$D$2/60*12 -> -0.0055739731
A13: Support unit | B13: -1.2661194 | C13: -0.039581325 | D13: -0.83853855 | E13: =D13/$D$2/60*12 -> -0.029410376
A14: PBT | B14: -0.18036765 | C14: -0.0056386391 | D14: -1.0467303 | E14: =D14/$D$2/60*12 -> -0.036712363
A15: Profit before support cost (PBSC) | B15: 1.0857518 | C15: 0.033942686 | D15: -0.20819175 | E15: =D15/$D$2/60*12 -> -0.0073019871
A20: INPUT- CC 2025 | B20: Q4.25 | D20: Q3.25
A21: spending per card per month | B21: 5.8941158 | D21: 4.7
A22: revolving rate | B22: 0.53345835 | D22: 0.55783393
A23: IR | B23: 0.45066 | D23: 0.45066
A24: COF | B24: 0.058332905 | D24: 0.055
A25: interchange | B25: 0.0051800628 | D25: 0.0052
A26: cashback | B26: 0.0037001972 | D26: 0.0042
A27: B0-B1 | B27: 0.0178 | D27: 0.019074444
A28: B0-B4 | B28: 0.013618737 | D28: 0.014115897

Sheet OD
A1: OUTPUT-OD 2025 | B1: Q1.26 | C1: %ANR | D1: Q4.25 | E1: %ANR
A2: ANR | B2: 4.2346839 | D2: =UPL!K3 -> 4.1860653
A3: TOI | B3: 1.321896 | C3: 0.24972745 | D3: =UPL!K4 -> 1.4103862 | E3: =UPL!L4 -> 0.27738446
A4: Net interest income | B4: 1.1706535 | C4: 0.22115531 | D4: =UPL!K5 -> 1.2625242 | E4: =UPL!L5 -> 0.24830404
A5: Net fee income | B5: 0.1512425 | C5: 0.028572145 | D5: =UPL!K6 -> 0.14786203 | E5: =UPL!L6 -> 0.029080425
A6: Other income | B6: 0 | C6: 0 | D6: =UPL!K7 -> 0 | E6: =UPL!L7 -> 0
A7: PROVISION | B7: -1.3189242 | C7: -0.24916602 | D7: =UPL!K8 -> -1.0323668 | E7: =UPL!L8 -> -0.20303836
A8: OPEX | B8: -0.42202723 | C8: -0.079727742 | D8: =UPL!K9 -> -0.45161934 | E8: =UPL!L9 -> -0.088821195
A9: Acquisition cost | B9: 0 | C9: 0 | D9: =UPL!K10 -> 0 | E9: =UPL!L10 -> 0
A10: UW & Disbursal cost | B10: -0.014853157 | C10: -0.0028060006 | D10: =UPL!K11 -> -0.015808187 | E10: =UPL!L11 -> -0.0031090388
A11: Collection | B11: -0.032298132 | C11: =B11/$B$2*12/15 -> -0.0061016373 | D11: =UPL!K12 -> -0.054385719 | E11: =UPL!L12 -> -0.010696186
A12: After-sales services | B12: -5.0511138e-05 | C12: =B12/$B$2*12/15 -> -9.5423675e-06 | D12: =UPL!K13 -> -0.0066 | E12: =UPL!L13 -> -0.0012980398
A13: Support unit | B13: -0.37482543 | C13: -0.070810562 | D13: =UPL!K14 -> -0.37482543 | E13: =UPL!L14 -> -0.07371793
A14: PBT | B14: =B3+B7+B8 -> -0.4190554 | C14: -0.079166315 | D14: =UPL!K15 -> -0.073599932 | E14: =UPL!L15 -> -0.014475097
A15: Profit before support cost (PBSC) | B15: =B14-B13 -> -0.044229969 | C15: -0.0083557537 | D15: =UPL!K16 -> 0.3012255 | E15: =UPL!L16 -> 0.059242833
A20: INPUT-OD 2025 | B20: Q1.26 | D20: Q4.25
A21: Ticket size/balance | B21: 8.3820479 | D21: =UPL!K19 -> 8.3141102
A22: Tenor | B22: 9 | D22: =UPL!K20 -> 9
A23: IR | B23: 0.34950821 | D23: =UPL!K21 -> 0.3510544
A24: Insurance | B24: 0 | D24: =UPL!K22 -> 0
A25: B0-B1 | B25: 0.040888889 | D25: =UPL!K23 -> 0.04
A26: B0-B4 | B26: 0.030157307 | D26: =UPL!K24 -> 0.029354578

Sheet Sheet1
