Workbook
Name __S1: {"Book1"}
Name __S1: {"Book1"}
Name _a1: {"'Sheet1'!$L$16"}
Name _a1: {"'Sheet1'!$L$16"}
Name _S1: {"Book1"}
Name _S1: {"Book1"}
Name Ă: #REF!
Name Ạ196: #REF!
Name â259: #REF!
Name â259: #REF!
Name â312: #REF!
Name â312: #REF!
Name Acquisition_PlanA: #REF!
Name Acquisition_PlanB: #REF!
Name Actual: (PeriodInActual*(#REF!>0))*PeriodInPlan
Name Actual: (PeriodInActual*(#REF!>0))*PeriodInPlan
Name ActualBeyond: PeriodInActual*(#REF!>0)
Name ActualBeyond: PeriodInActual*(#REF!>0)
Name adf: #REF!
Name adf: #REF!
Name AdvIncQ12020: #REF!
Name AdvIncQ12021: #REF!
Name AdvIncQ12022: #REF!
Name AdvIncQ12023: #REF!
Name AdvIncQ12024: #REF!
Name AdvIncQ22020: #REF!
Name AdvIncQ22021: #REF!
Name AdvIncQ22022: #REF!
Name AdvIncQ22023: #REF!
Name AdvIncQ22024: #REF!
Name AdvIncQ32020: #REF!
Name AdvIncQ32021: #REF!
Name AdvIncQ32022: #REF!
Name AdvIncQ32023: #REF!
Name AdvIncQ32024: #REF!
Name AdvIncQ42020: #REF!
Name AdvIncQ42021: #REF!
Name AdvIncQ42022: #REF!
Name AdvIncQ42023: #REF!
Name AdvIncQ42024: #REF!
Name AdvPenRate2020: #REF!
Name AdvPenRate2021: #REF!
Name AdvPenRate2022: #REF!
Name AdvPenRate2023: #REF!
Name AdvPenRate2024: #REF!
Name AllReportList: #REF!
Name Amount_act: #REF!
Name Amount_CF: #REF!
Name Amount_F: #REF!
Name Amount_KPI_act: #REF!
Name approval: #REF!
Name approval: #REF!
Name Attribute_F: #REF!
Name B: #REF!
Name b2bSpr: #REF!
Name BaoHanhSuaChua: #REF!
Name be_KPI_bud: #REF!
Name be2B: #REF!
Name bf: #REF!
Name bf: #REF!

Sheet NOTE
A1: SAP MODEL - CASHLOAN
B2: OFFICIAL | N2: HKN | O2: v9 | P2: 20251001
B3: 1. Notes and disclaimer
C4: a. Giới thiệu về SAP
D5: - SAP: Single Account Profitability (Hiệu quả sản phẩm trên từng đơn vị sản phẩm)
D6: - Model SAP được sử dụng như một (01) trong các mô hình dự đoán hiệu quả vòng đời của sản phẩm.
D7: - Do sự phức tạp của sản phẩm, các hệ thống vận hành (hệ thống hạch kế toán, hệ thống quản trị rủi ro, hệ thống quản trị…), hành vi người sử dụng hành vi người sử dụng, model chỉ có thể mô phỏng tương đối trung bình vòng đời của sản phẩm.
D8: - Do tính chất thời điểm, mô hình được xây dựng mô phỏng theo cách vận hành sản phẩm tại thời điểm phát hành. Trường hợp hệ thống thay đổi, sản phẩm thay đổi, mô hình sẽ không thể phản ánh đúng bản chất vận hành sản phẩm.
D9: - Mô hình được tính toán dựa vào các yếu tố đầu vào xác định tại một thời điểm xác định, do đó kết quả của mô hình có thể có sự khác biệt so với thực tế vận hành sản phẩm.
D10: - Mô hình SAP Cashloan tính hiệu quả của khoản vay giải ngân và thời hạn tối đa được áp dụng là 5 năm ( 60 tháng) kể từ ngày bắt đầu sản phẩm đối với sử dụng phương pháp dự phòng IFRS
E11: - Lưu ý rằng trường hợp áp dụng cho khoản vay 5 năm, thì các chi phí sẽ không được tính toán đầy đủ do chi phí COF cho thời gian từ lúc khoản vay kết thúc tới lúc được xóa trên sổ kế toán.
E12: - Chỉ nên sử dụng với khoản vay dưới 4 năm (48 tháng) để được tính toán đầy đủ chi phí
E13: - Đối với phương pháp tính rủi ro VAS, thời hạn khoản vay tối đa sử dụng là 4 năm (48 tháng)
C15: b. Giới thiệu về PnL
D16: - Trong file tính này, Profit & Lost (PnL) được dự phóng từ trung bình cộng kết quả kinh doanh trên từng sản phẩm (SAP) với yếu tố "sale plan" (số giải ngân) qua từng tháng, do đó có thể khác biệt so với kết quả thực tế vận hành.
D17: - Dòng tiền thực tế qua từng tháng có thể khác biệt với mô hình tính toán do nhiều yếu tố tác động bên ngoài thay đổi, do đó, vui lòng chỉ sử dụng mô hình cho mục đích tham khảo.
D18: - Cho mục đích tính dự phòng dòng tiền ngắn và trung hạn, mô hình PnL được cutoff tại thời điểm 5 năm (60 tháng) kể từ ngày bắt đầu khởi chạy sản phẩm đầu tiên.
B20: 2. Instruction
D21: - Dành cho người sử dụng
E22: - Chỉ chỉnh sửa vào các ô màu vàng
E23: - 2 sheets "SAP_Leadsheet" và "Sale plan&PnL" cung cấp yếu tố đầu vào và đầu ra để tính toán mô hình SAP cũng như PnL.
F24: - Sheet SAP_Leadsheet được cấu trúc 2 phần, bên trái là các yếu tố đầu vào (input) và bên phải là kết quả dự đoán (output). Đơn vị sử dụng tại bảng tính là triệu VND (mVND) và phần trăm (%)
F25: - Sheet "Sale plan & PL" được cấu trúc 2 phần, bên trên là sale plan và bên dưới là kết quả PnL
E26: - 2 sheets "SAP_Spreadsheet" và "PL projection speadsheet" là các file tính toán cho 2 sheet "SAP_Leadsheet", "Sales plan & PL"
F27: - 2 sheets được cấu trúc từ trên xuống dưới theo thứ tự tính toán mô phỏng để đưa ra kết quả kinh doanh cuối cùng
F28: - 2 sheets đã được tạm khóa. Trường hợp cần mở khóa, điều chỉnh các yếu tố, vui lòng liên hệ với nhóm vận hành để được hỗ trợ.
D30: - Dành riêng cho người vận hành, hiệu chỉnh
E31: - Cần cẩn trọng khi điều chỉnh ở các file "speadsheet" vì 1 khi sai lệch rất khó tìm ra lỗi (VD: sửa nhầm ô, link nhầm vị trí,…)
B34: 3. Legend
C35: GENERAL INPUT
G37: Diễn giải | L37: Chú thích
D38: Risk input | G38: Loại phương pháp tính rủi ro | L38: Lựa chon phương pháp tính rủi ro VAS và IFRS
D39: Write off | G39: Thời điểm WO | L39: Lựa chọn thời điểm ghi nhận WO là 360 hoặc 180
C40: REVENUE INPUT
G42: Diễn giải | L42: Chú thích
C43: Amount & Tenor
D44: Loan amount | G44: Số tiền vay giải ngân (có thể bao gồm bảo hiểm hoặc không) | L44: Trường hợp số tiền giải ngân > giá trị hàng hóa, chỉ ghi = số thực tế giải ngân
D45: Payment Method | G45: Phương pháp tính lãi | L45: EMI (Equated monthly Installment)- số tiền thanh toán cố định hàng tháng
D46: Nominal Tenor | G46: Thời hạn vay | L46: Thời hạn ghi nhận trên khoản vay ( VD: 1 tháng, 3 tháng, 12 tháng,…)
D47: Maturity to Termination | G47: Thời hạn từ lúc đáo hạn tới lúc tới khi ra ngoại bảng | L47: Nên để 6 tháng để khớp với hệ thống kế toán, rủi ro đang ghi nhận WO180+
...

Sheet Leadsheet
B1: SAP CASHLOAN MODEL | D1: 1
B2: =NOTE!N2 -> HKN | C2: =NOTE!P2 -> 20251001 | D2: =NOTE!O2 -> v9 | K2: NOTE
K3: Please read carefully about before using model
B4: Product | C4: Unsecured Cashloan | D4: UPL | E4: Risk input | G4: IFRS | H4: =G4 -> IFRS | L4: Disclaimer
B5: Sub-Product | C5: Cashloan | D5: ALL | E5: Write off | G5: DPD180+ | H5: =G5 -> DPD180+ | L5: Instruction
B6: Sub-Segments | C6: VNPAY | D6: ALL | E6: Quarter | G6: 2025 | H6: =G6 -> 2025 | L6: Legend
B8: REVENUE INPUT | H8: Cur: mVND | K8: GENERAL OUTPUT | U8: Cur: mVND
B10: Amount & Tenor | C10: Loan amount | E10: =DATA!G25 -> 14.837554 | N10: Life time | O10: Year 1 | P10: Year 2 | Q10: Year 3 | R10: Year 4 | S10: Year 5 | T10: % ANR | U10: % Disbursement
C11: Payment Method | E11: EMI | K11: ANR | N11: =N29 -> 4.7456492 | O11: =O29 -> 8.0917437 | P11: =P29 -> 0.73033581 | Q11: =Q29 -> 0 | R11: =R29 -> 0 | S11: =S29 -> 0 | U11: =N11/$E$10 -> 0.31984041
C12: Nominal Tenor | E12: =DATA!H25 -> 16 | K12: TOI | N12: =SUM(N13:N15) -> 3.5729466 | O12: =SUM(O13:O15) -> 3.4390338 | P12: =SUM(P13:P15) -> 0.13391282 | Q12: =SUM(Q13:Q15) -> 0 | R12: =SUM(R13:R15) -> 0 | S12: =SUM(S13:S15) -> 0 | T12: =N12/$E$14*12/$N$11 -> 0.41066667 | U12: =N12/$E$10 -> 0.24080429
C13: Maturity to Termination | E13: 6 | K13: Net interest income | N13: =N31 -> 2.6903516 | O13: =O31 -> 2.5637561 | P13: =P31 -> 0.12659546 | Q13: =Q31 -> 0 | R13: =R31 -> 0 | S13: =S31 -> 0 | T13: =N13/$E$14*12/$N$11 -> 0.30922313 | U13: =N13/$E$10 -> 0.18132043
C14: Month on book | E14: =E12+E13 -> 22 | K14: Net fee income | N14: =N34 -> 0.88259504 | O14: =O34 -> 0.87527767 | P14: =P34 -> 0.0073173634 | Q14: =Q34 -> 0 | R14: =R34 -> 0 | S14: =S34 -> 0 | T14: =N14/$E$14*12/$N$11 -> 0.10144354 | U14: =N14/$E$10 -> 0.059483865
K15: Other income | N15: =N38 -> 0 | O15: =O38 -> 0 | P15: =P38 -> 0 | Q15: =Q38 -> 0 | R15: =R38 -> 0 | S15: =S38 -> 0 | T15: =N15/$E$14*12/$N$11 -> 0 | U15: =N15/$E$10 -> 0
K16: PROVISION | N16: =N39 -> -2.2889776 | O16: =O39 -> -2.1659984 | P16: =P39 -> -0.12297927 | Q16: =Q39 -> 0 | R16: =R39 -> 0 | S16: =S39 -> 0 | T16: =N16/$E$14*12/$N$11 -> -0.26309009 | U16: =N16/$E$10 -> -0.15426921
B17: Pricing | C17: From | D17: To | E17: IR | F17: COF | G17: NIM | K17: OPEX | N17: =SUM(N18:N21) -> -1.1152233 | O17: =SUM(O18:O21) -> -0.95965086 | P17: =SUM(P18:P21) -> -0.15557244 | Q17: =SUM(Q18:Q21) -> 0 | R17: =SUM(R18:R21) -> 0 | S17: =SUM(S18:S21) -> 0 | T17: =N17/$E$14*12/$N$11 -> -0.12818133 | U17: =N17/$E$10 -> -0.075162208
A18: 1 | B18: 1 | C18: 1 | D18: =E12 -> 16 | E18: =DATA!D33 -> 0.45290894 | F18: =DATA!D37 -> 0.074 | G18: =E18-F18 -> 0.37890894 | K18: Acquisition cost | N18: =SUM(N41) -> -0.29675107 | O18: =SUM(O41) -> -0.29675107 | P18: =SUM(P41) -> 0 | Q18: =SUM(Q41) -> 0 | R18: =SUM(R41) -> 0 | S18: =SUM(S41) -> 0 | T18: =N18/$E$14*12/$N$11 -> -0.03410792 | U18: =N18/$E$10 -> -0.02
A19: 2 | B19: 2 | C19: =IF(D18="","",IF(D18>$E$12,"",D18+1)) -> 17 | D19: =E14 -> 22 | E19: =E18 -> 0.45290894 | F19: =F18 -> 0.074 | G19: =E19-F19 -> 0.37890894 | K19: UW & Disbursal | N19: =N45 -> -0.066001863 | O19: =O45 -> -0.066001863 | P19: =P45 -> 0 | Q19: =Q45 -> 0 | R19: =R45 -> 0 | S19: =S45 -> 0 | T19: =N19/$E$14*12/$N$11 -> -0.0075861098 | U19: =N19/$E$10 -> -0.0044482982
A20: 3 | B20: 3 | K20: Collection & aftersale service | N20: =N48 -> -0.10776352 | O20: =O48 -> -0.080036365 | P20: =P48 -> -0.027727156 | Q20: =Q48 -> 0 | R20: =R48 -> 0 | S20: =S48 -> 0 | T20: =N20/$E$14*12/$N$11 -> -0.012386103 | U20: =N20/$E$10 -> -0.00726289
A21: 4 | B21: 4 | K21: Support unit | N21: =N52 -> -0.64470685 | O21: =O52 -> -0.51686156 | P21: =P52 -> -0.12784529 | Q21: =Q52 -> 0 | R21: =R52 -> 0 | S21: =S52 -> 0 | T21: =N21/$E$14*12/$N$11 -> -0.074101195 | U21: =N21/$E$10 -> -0.04345102
A22: 5 | B22: 5 | K22: PBT | N22: =N12+N16+N17 -> 0.16874568 | O22: =O12+O16+O17 -> 0.31338457 | P22: =P12+P16+P17 -> -0.14463889 | Q22: =Q12+Q16+Q17 -> 0 | R22: =R12+R16+R17 -> 0 | S22: =S12+S16+S17 -> 0 | T22: =N22/$E$14*12/$N$11 -> 0.01939526 | U22: =N22/$E$10 -> 0.011372878
B23: 6 | K23: In which: PROFIT BEFORE SU | N23: =N22-N21 -> 0.81345253 | O23: =O22-O21 -> 0.83024613 | P23: =P22-P21 -> -0.016793604 | Q23: =Q22-Q21 -> 0 | R23: =R22-R21 -> 0 | S23: =S22-S21 -> 0 | T23: =N23/$E$14*12/$N$11 -> 0.093496455 | U23: =N23/$E$10 -> 0.054823898
B25: Early prepayment | C25: From | D25: To | E25: Penalty fee | F25: Penalty IR | G25: %Attrition
B26: 1 | C26: 1 | D26: 1 | E26: =DATA!E125 -> 0.0608466 | G26: 0.08 | H26: per cohort | K26: PERFORMANCE OUTPUT | U26: Cur: mVND
B27: 2 | C27: =D26+1 -> 2 | D27: 3 | E27: =E26 -> 0.0608466 | G27: 0.06 | H27: per cohort
B28: 3 | C28: =D27+1 -> 4 | D28: 14 | E28: 0.05 | G28: 0.025 | H28: per cohort | N28: Life time | O28: Year 1 | P28: Year 2 | Q28: Year 3 | R28: Year 4 | S28: Year 5 | T28: % ANR | U28: % Disbursement
B29: 4 | C29: =IF(D28="","",IF(D28>$E$12,"",D28+1)) -> 15 | K29: ANR | N29: =SUM(SAP_Speadsheet!$D$50:$BF$50)/COUNTIF(SAP_Speadsheet!$D$50:$BF$50,">0") -> 4.7456492 | O29: =IFERROR(SUM(SAP_Speadsheet!$D$50:$P$50)/COUNTIF(SAP_Speadsheet!$D$50:$P$50,">0"),0) -> 8.0917437 | P29: =IFERROR(SUM(SAP_Speadsheet!$Q$50:$AB$50)/COUNTIF(SAP_Speadsheet!$Q$50:$AB$50,">0"),0) -> 0.73033581 | Q29: =IFERROR(SUM(SAP_Speadsheet!$AC$50:$AN$50)/COUNTIF(SAP_Speadsheet!$AC$50:$AN$50,">0"),0) -> 0 | R29: =IFERROR(SUM(SAP_Speadsheet!$AO$50:$AZ$50)/COUNTIF(SAP_Speadsheet!$AO$50:$AZ$50,">0"),0) -> 0 | S29: =IFERROR(SUM(SAP_Speadsheet!$BA$50:$BF$50)/COUNTIF(SAP_Speadsheet!$BA$50:$BF$50,">0"),0) -> 0 | U29: =N29/$E$10 -> 0.31984041
B30: 5 | C30: =IF(D29="","",IF(D29>$E$12,"",D29+1)) | E30: =IF(D30="",0,SUMIFS(#REF!,#REF!,Leadsheet!G$24,#REF!,Leadsheet!$A30,#REF!,Leadsheet!$C$4,#REF!,Leadsheet!$G$5,#REF!,Leadsheet!$D$5,#REF!,Leadsheet!G4)) -> 0 | F30: 0 | K30: TOI | N30: =SUM(O30:S30) -> 3.5729466 | O30: =SUM(SAP_Speadsheet!$E$55:$P$55) -> 3.4390338 | P30: =SUM(SAP_Speadsheet!$Q$55:$AB$55) -> 0.13391282 | Q30: =SUM(SAP_Speadsheet!$AC$55:$AN$55) -> 0 | R30: =SUM(SAP_Speadsheet!$AO$55:$AZ$55) -> 0 | S30: =SUM(SAP_Speadsheet!$BA$55:$BF$55) -> 0 | T30: =N30/$E$14*12/$N$29 -> 0.41066667 | U30: =N30/$E$10 -> 0.24080429
B31: 6 | C31: =IF(D30="","",IF(D30>$E$12,"",D30+1)) | E31: =IF(D31="",0,SUMIFS(#REF!,#REF!,Leadsheet!G$24,#REF!,Leadsheet!$A31,#REF!,Leadsheet!$C$4,#REF!,Leadsheet!$G$5,#REF!,Leadsheet!$D$5,#REF!,Leadsheet!G4)) -> 0 | F31: 0 | K31: Net interest income | N31: =SUM(O31:S31) -> 2.6903516 | O31: =SUM(SAP_Speadsheet!$E$57:$P$57) -> 2.5637561 | P31: =SUM(SAP_Speadsheet!$Q$57:$AB$57) -> 0.12659546 | Q31: =SUM(SAP_Speadsheet!$AC$57:$AN$57) -> 0 | R31: =SUM(SAP_Speadsheet!$AO$57:$AZ$57) -> 0 | S31: =SUM(SAP_Speadsheet!$BA$57:$BF$57) -> 0 | T31: =N31/$E$14*12/$N$29 -> 0.30922313 | U31: =N31/$E$10 -> 0.18132043
K32: Interest income | N32: =SUM(O32:S32) -> 3.334178 | O32: =SUM(SAP_Speadsheet!$E$58:$P$58) -> 3.1625452 | P32: =SUM(SAP_Speadsheet!$Q$58:$AB$58) -> 0.17163283 | Q32: =SUM(SAP_Speadsheet!$AC$58:$AN$58) -> 0 | R32: =SUM(SAP_Speadsheet!$AO$58:$AZ$58) -> 0 | S32: =SUM(SAP_Speadsheet!$BA$58:$BF$58) -> 0 | T32: =N32/$E$14*12/$N$29 -> 0.38322313 | U32: =N32/$E$10 -> 0.22471211
B33: Credit insurrance | C33: Banca Premium (excl. in loan) | F33: per disbursement amount | K33: Cost of fund | N33: =SUM(O33:S33) -> -0.64382641 | O33: =SUM(SAP_Speadsheet!$E$59:$P$59) -> -0.59878904 | P33: =SUM(SAP_Speadsheet!$Q$59:$AB$59) -> -0.045037375 | Q33: =SUM(SAP_Speadsheet!$AC$59:$AN$59) -> 0 | R33: =SUM(SAP_Speadsheet!$AO$59:$AZ$59) -> 0 | S33: =SUM(SAP_Speadsheet!$BA$59:$BF$59) -> 0 | T33: =N33/$E$14*12/$N$29 -> -0.074 | U33: =N33/$E$10 -> -0.043391682
C34: Banca Premium (incl. in loan) | E34: =DATA!J25 -> 0.069722407 | F34: per disbursement amount | K34: Net fee income | N34: =SUM(O34:S34) -> 0.88259504 | O34: =SUM(SAP_Speadsheet!$E$61:$P$61) -> 0.87527767 | P34: =SUM(SAP_Speadsheet!$Q$61:$AB$61) -> 0.0073173634 | Q34: =SUM(SAP_Speadsheet!$AC$61:$AN$61) -> 0 | R34: =SUM(SAP_Speadsheet!$AO$61:$AZ$61) -> 0 | S34: =SUM(SAP_Speadsheet!$BA$61:$BF$61) -> 0 | T34: =N34/$E$14*12/$N$29 -> 0.10144354 | U34: =N34/$E$10 -> 0.059483865
C35: Penetration | E35: =DATA!K25 -> 0.74160583 | F35: per disbursement amount | K35: Early termination fee | N35: =SUM(O35:S35) -> 0.25816039 | O35: =SUM(SAP_Speadsheet!$E$62:$P$62) -> 0.25084302 | P35: =SUM(SAP_Speadsheet!$Q$62:$AB$62) -> 0.0073173634 | Q35: =SUM(SAP_Speadsheet!$AC$62:$AN$62) -> 0 | R35: =SUM(SAP_Speadsheet!$AO$62:$AZ$62) -> 0 | S35: =SUM(SAP_Speadsheet!$BA$62:$BF$62) -> 0 | T35: =N35/$E$14*12/$N$29 -> 0.02967239 | U35: =N35/$E$10 -> 0.017399121
C36: Commission to CAKE | E36: 0.856 | F36: per disbursement amount | H36: done | K36: Insurance commission | N36: =SUM(O36:S36) -> 0.62443465 | O36: =SUM(SAP_Speadsheet!$E$63:$P$63) -> 0.62443465 | P36: =SUM(SAP_Speadsheet!$Q$63:$AB$63) -> 0 | Q36: =SUM(SAP_Speadsheet!$AC$63:$AN$63) -> 0 | R36: =SUM(SAP_Speadsheet!$AO$63:$AZ$63) -> 0 | S36: =SUM(SAP_Speadsheet!$BA$63:$BF$63) -> 0 | T36: =N36/$E$14*12/$N$29 -> 0.071771154 | U36: =N36/$E$10 -> 0.042084744
H37: done | K37: Support fee | N37: =SUM(O37:S37) -> 0 | O37: =SUM(SAP_Speadsheet!$E$64:$P$64) -> 0 | P37: =SUM(SAP_Speadsheet!$Q$64:$AB$64) -> 0 | Q37: =SUM(SAP_Speadsheet!$AC$64:$AN$64) -> 0 | R37: =SUM(SAP_Speadsheet!$AO$64:$AZ$64) -> 0 | S37: =SUM(SAP_Speadsheet!$BA$64:$BF$64) -> 0 | T37: =N37/$E$14*12/$N$29 -> 0 | U37: =N37/$E$10 -> 0
B38: Support fee | C38: One-time | F38: $ per account | K38: Other income | N38: =SUM(O38:S38) -> 0 | O38: =SUM(SAP_Speadsheet!$E$68:$P$68) -> 0 | P38: =SUM(SAP_Speadsheet!$Q$68:$AB$68) -> 0 | Q38: =SUM(SAP_Speadsheet!$AC$68:$AN$68) -> 0 | R38: =SUM(SAP_Speadsheet!$AO$68:$AZ$68) -> 0 | S38: =SUM(SAP_Speadsheet!$BA$68:$BF$68) -> 0 | T38: =N38/$E$14*12/$N$29 -> 0 | U38: =N38/$E$10 -> 0
C39: One-time | F39: % per ticketsize | K39: PROVISION | N39: =SUM(O39:S39) -> -2.2889776 | O39: =SUM(SAP_Speadsheet!$E$183:$P$183) -> -2.1659984 | P39: =SUM(SAP_Speadsheet!$Q$183:$AB$183) -> -0.12297927 | Q39: =SUM(SAP_Speadsheet!$AC$183:$AN$183) -> 0 | R39: =SUM(SAP_Speadsheet!$AO$183:$AZ$183) -> 0 | S39: =SUM(SAP_Speadsheet!$BA$183:$BF$183) -> 0 | T39: =N39/$E$14*12/$N$29 -> -0.26309009 | U39: =N39/$E$10 -> -0.15426921
C40: Monthly fee | F40: %monthly per ticketsize | K40: OPEX | N40: =SUM(O40:S40) -> -1.1152233 | O40: =+SUM(O41,O45,O48,O52) -> -0.95965086 | P40: =+SUM(P41,P45,P48,P52) -> -0.15557244 | Q40: =+SUM(Q41,Q45,Q48,Q52) -> 0 | R40: =+SUM(R41,R45,R48,R52) -> 0 | S40: =+SUM(S41,S45,S48,S52) -> 0 | T40: =N40/$E$14*12/$N$29 -> -0.12818133 | U40: =N40/$E$10 -> -0.075162208
B41: COST INPUT | H41: Cur: mVND | K41: Acquisition cost | N41: =SUM(O41:S41) -> -0.29675107 | O41: =SUM(O42:O44) -> -0.29675107 | P41: =SUM(P42:P44) -> 0 | Q41: =SUM(Q42:Q44) -> 0 | R41: =SUM(R42:R44) -> 0 | S41: =SUM(S42:S44) -> 0 | T41: =N41/$E$14*12/$N$29 -> -0.03410792 | U41: =N41/$E$10 -> -0.02
K42: Lead Acquisition | N42: =SUM(O42:S42) -> -0.29675107 | O42: =SUM(SAP_Speadsheet!$E$73:$P$73) -> -0.29675107 | P42: =SUM(SAP_Speadsheet!$Q$73:$AB$73) -> 0 | Q42: =SUM(SAP_Speadsheet!$AC$73:$AN$73) -> 0 | R42: =SUM(SAP_Speadsheet!$AO$73:$AZ$73) -> 0 | S42: =SUM(SAP_Speadsheet!$BA$73:$BF$73) -> 0 | T42: =N42/$E$14*12/$N$29 -> -0.03410792 | U42: =N42/$E$10 -> -0.02
B43: Inflation rate | E43: 0.035 | F43: % per year | K43: Sharing performance | N43: =SUM(O43:S43) -> 0 | O43: =SUM(SAP_Speadsheet!$E$74:$P$74) -> 0 | P43: =SUM(SAP_Speadsheet!$Q$74:$AB$74) -> 0 | Q43: =SUM(SAP_Speadsheet!$AC$74:$AN$74) -> 0 | R43: =SUM(SAP_Speadsheet!$AO$74:$AZ$74) -> 0 | S43: =SUM(SAP_Speadsheet!$BA$74:$BF$74) -> 0 | T43: =N43/$E$14*12/$N$29 -> 0 | U43: =N43/$E$10 -> 0
...

Sheet DATA
B1: HKN-TTA
B2: 20260119
B5: 1 | C5: Aproval rate, signed rate
C7: aprroval rate | E7: 0.361
C8: Signed rate | E8: 0.714
B17: 2 | C17: Disburse, Tenor, Insurance, IR, COF
C19: Disburse date | D19: # Disburse | E19: Disburse amount (VND) | F19: Current balance (VND) | G19: Ticket size (VND) | H19: Avg tenor (Month) | I19: Avg IR (%) | J19: Insurance fee (VND) | K19: % Insurance penetration by date
C20: 45992 | D20: 1395 | E20: 21697550000 | G20: 15553799 | H20: 16.288172 | I20: 0.46336918 | J20: 1054550000 | K20: 0.73261649 | L20: =E20-J20 -> 20643000000
C21: 45962 | D21: 1413 | E21: 19620350000 | G21: 13885598 | H21: 15.781316 | I21: 0.46266808 | J21: 973350000 | K21: 0.74663836 | L21: =E21-J21 -> 18647000000
C22: 45931 | D22: 1476 | E22: 22246180000 | G22: 15071938 | H22: 16.036585 | I22: 0.46270325 | J22: 1097180000 | K22: 0.74593496 | L22: =E22-J22 -> 21149000000
C25: AVG | G25: =SUM(E20:E22)/SUM(D20:D22)/10^6 -> 14.837554 | H25: =ROUND(SUMPRODUCT(H20:H22,E20:E22)/SUM(E20:E22),0) -> 16 | I25: =SUMPRODUCT(I20:I22,E20:E22)/SUM(E20:E22) -> 0.46291971 | J25: =SUM(J20:J22)/SUMPRODUCT(K20:K22,L20:L22) -> 0.069722407 | K25: =SUMPRODUCT(K20:K22,E20:E22)/SUM(E20:E22) -> 0.74160583
D28: 10 | E28: =D28+1 -> 11 | F28: =E28+1 -> 12
C29: ENR | D29: 101068876374 | E29: 107157807951 | F29: 114324863034
D30: =E22 -> 22246180000 | E30: =E21 -> 19620350000 | F30: =E20 -> 21697550000
E32: Cân nhắc xem lại
C33: IR | D33: =E33 -> 0.45290894 | E33: =SUM(D35:F35)/SUM(D34:F34)*365 -> 0.45290894
C34: Balance by day | D34: 2646528857360 | E34: 2803832735492 | F34: 3008910958344
C35: Thu lãi vay | D35: 3293167691 | E35: 3487480127 | F35: 3716010119
C37: COF | D37: 0.074
C39: Years (BUSINESS_DATE) | D39: Months (BUSINESS_DATE) | E39: Sum of BALANCE | F39: Sum of Lai DCV
C40: 2025 | D40: Oct | E40: 2976030609952 | F40: 5.7012589e+08
D41: Nov | E41: 3170699687949 | F41: 6.2131961e+08
D42: Dec | E42: 3089737356645 | F42: 6.1744428e+08
M48: =M49/D52 -> 6.9132791
M49: =D53-L53 -> 10204
B50: 3 | C50: UW, collection, MKT
D51: 10 | E51: =D51+1 -> 11 | F51: =E51+1 -> 12
C52: New ACC | D52: 1476 | E52: 1413 | F52: 1395
C53: Active acc | D53: 10204 | E53: 10704 | F53: 11056
C55: MKT acquisition
C56: UW | D56: 95580912 | E56: 93154244 | F56: 84245739
C57: Collection | D57: 28426097 | E57: 43427799 | F57: 38729442
C58: SMS | D58: 9210396.9 | E58: 9053041.7 | F58: 8431819.3
C59: Partner acquisition | D59: 422980000 | E59: 372940000 | F59: 412860000
C60: Econtract | D60: 1086785 | E60: 1024658 | F60: 1027878
C61: NFC | D61: 2277938 | E61: 1971115.7 | F61: 2382711.5
C64: MKT acquisition | D64: =SUM(D55:L55)/SUM(D52:L52)/10^6 -> 0
C65: UW | D65: =SUM(D56:F56)/SUM(D52:F52)/10^6 -> 0.063721031
C66: Collection | D66: =8000/10^6 -> 0.008 | E66: Sử dụng mức tương đương Q2 do quý 3 thay đổi collection, chi phí ko đầy đủ
C67: SMS | D67: =SUM(D58:F58)/SUM(D53:F53)/10^6 -> 0.00083516637
...

Sheet SAP_Speadsheet
B1: SAP Speadsheet
C4: Method
C5: Month on book | D5: 0 | E5: =D5+1 -> 1 | F5: =E5+1 -> 2 | G5: =F5+1 -> 3 | H5: =G5+1 -> 4 | I5: =H5+1 -> 5 | J5: =I5+1 -> 6 | K5: =J5+1 -> 7 | L5: =K5+1 -> 8 | ... BL5: =BK5+1 -> 60
C6: Oustanding tenor | D6: =IF(Leadsheet!$E$12-SAP_Speadsheet!D5<0,0,Leadsheet!$E$12-SAP_Speadsheet!D5) -> 16 | E6: =IF(Leadsheet!$E$12-SAP_Speadsheet!E5<0,0,Leadsheet!$E$12-SAP_Speadsheet!E5) -> 15 | F6: =IF(Leadsheet!$E$12-SAP_Speadsheet!F5<0,0,Leadsheet!$E$12-SAP_Speadsheet!F5) -> 14 | G6: =IF(Leadsheet!$E$12-SAP_Speadsheet!G5<0,0,Leadsheet!$E$12-SAP_Speadsheet!G5) -> 13 | H6: =IF(Leadsheet!$E$12-SAP_Speadsheet!H5<0,0,Leadsheet!$E$12-SAP_Speadsheet!H5) -> 12 | I6: =IF(Leadsheet!$E$12-SAP_Speadsheet!I5<0,0,Leadsheet!$E$12-SAP_Speadsheet!I5) -> 11 | J6: =IF(Leadsheet!$E$12-SAP_Speadsheet!J5<0,0,Leadsheet!$E$12-SAP_Speadsheet!J5) -> 10 | K6: =IF(Leadsheet!$E$12-SAP_Speadsheet!K5<0,0,Leadsheet!$E$12-SAP_Speadsheet!K5) -> 9 | ... BL6: =IF(Leadsheet!$E$12-SAP_Speadsheet!BL5<0,0,Leadsheet!$E$12-SAP_Speadsheet!BL5) -> 0
C7: Last month on book | D7: =Leadsheet!E13+Leadsheet!E12 -> 22
B9: Balance
B10: Interest rate
C11: INR rate | D11: =Leadsheet!E18 -> 0.45290894 | E11: =IF(E$5>$D$7,0,VLOOKUP(SAP_Speadsheet!E$5,Leadsheet!$C$18:$F$23,3,1)) -> 0.45290894 | F11: =IF(F$5>$D$7,0,VLOOKUP(SAP_Speadsheet!F$5,Leadsheet!$C$18:$F$23,3,1)) -> 0.45290894 | G11: =IF(G$5>$D$7,0,VLOOKUP(SAP_Speadsheet!G$5,Leadsheet!$C$18:$F$23,3,1)) -> 0.45290894 | H11: =IF(H$5>$D$7,0,VLOOKUP(SAP_Speadsheet!H$5,Leadsheet!$C$18:$F$23,3,1)) -> 0.45290894 | I11: =IF(I$5>$D$7,0,VLOOKUP(SAP_Speadsheet!I$5,Leadsheet!$C$18:$F$23,3,1)) -> 0.45290894 | J11: =IF(J$5>$D$7,0,VLOOKUP(SAP_Speadsheet!J$5,Leadsheet!$C$18:$F$23,3,1)) -> 0.45290894 | K11: =IF(K$5>$D$7,0,VLOOKUP(SAP_Speadsheet!K$5,Leadsheet!$C$18:$F$23,3,1)) -> 0.45290894 | L11: =IF(L$5>$D$7,0,VLOOKUP(SAP_Speadsheet!L$5,Leadsheet!$C$18:$F$23,3,1)) -> 0.45290894 | ... BL11: =IF(BL$5>$D$7,0,VLOOKUP(SAP_Speadsheet!BL$5,Leadsheet!$C$18:$F$23,3,1)) -> 0
C12: COF rate | D12: =Leadsheet!F18 -> 0.074 | E12: =IF(E$5>$D$7,0,VLOOKUP(SAP_Speadsheet!E$5,Leadsheet!$C$18:$F$23,4,1)) -> 0.074 | F12: =IF(F$5>$D$7,0,VLOOKUP(SAP_Speadsheet!F$5,Leadsheet!$C$18:$F$23,4,1)) -> 0.074 | G12: =IF(G$5>$D$7,0,VLOOKUP(SAP_Speadsheet!G$5,Leadsheet!$C$18:$F$23,4,1)) -> 0.074 | H12: =IF(H$5>$D$7,0,VLOOKUP(SAP_Speadsheet!H$5,Leadsheet!$C$18:$F$23,4,1)) -> 0.074 | I12: =IF(I$5>$D$7,0,VLOOKUP(SAP_Speadsheet!I$5,Leadsheet!$C$18:$F$23,4,1)) -> 0.074 | J12: =IF(J$5>$D$7,0,VLOOKUP(SAP_Speadsheet!J$5,Leadsheet!$C$18:$F$23,4,1)) -> 0.074 | K12: =IF(K$5>$D$7,0,VLOOKUP(SAP_Speadsheet!K$5,Leadsheet!$C$18:$F$23,4,1)) -> 0.074 | L12: =IF(L$5>$D$7,0,VLOOKUP(SAP_Speadsheet!L$5,Leadsheet!$C$18:$F$23,4,1)) -> 0.074 | ... BL12: =IF(BL$5>$D$7,0,VLOOKUP(SAP_Speadsheet!BL$5,Leadsheet!$C$18:$F$23,4,1)) -> 0
C13: Attrition rate | E13: =IF(E$5<Leadsheet!$E$12,VLOOKUP(SAP_Speadsheet!E$5,Leadsheet!$C$26:$G$30,5,1),0) -> 0.08 | F13: =IF(F$5<Leadsheet!$E$12,VLOOKUP(SAP_Speadsheet!F$5,Leadsheet!$C$26:$G$30,5,1),0) -> 0.06 | G13: =IF(G$5<Leadsheet!$E$12,VLOOKUP(SAP_Speadsheet!G$5,Leadsheet!$C$26:$G$30,5,1),0) -> 0.06 | H13: =IF(H$5<Leadsheet!$E$12,VLOOKUP(SAP_Speadsheet!H$5,Leadsheet!$C$26:$G$30,5,1),0) -> 0.025 | I13: =IF(I$5<Leadsheet!$E$12,VLOOKUP(SAP_Speadsheet!I$5,Leadsheet!$C$26:$G$30,5,1),0) -> 0.025 | J13: =IF(J$5<Leadsheet!$E$12,VLOOKUP(SAP_Speadsheet!J$5,Leadsheet!$C$26:$G$30,5,1),0) -> 0.025 | K13: =IF(K$5<Leadsheet!$E$12,VLOOKUP(SAP_Speadsheet!K$5,Leadsheet!$C$26:$G$30,5,1),0) -> 0.025 | L13: =IF(L$5<Leadsheet!$E$12,VLOOKUP(SAP_Speadsheet!L$5,Leadsheet!$C$26:$G$30,5,1),0) -> 0.025 | ... BL13: =IF(BL$5<Leadsheet!$E$12,VLOOKUP(SAP_Speadsheet!BL$5,Leadsheet!$C$26:$G$30,5,1),0) -> 0
C14: Prepayment Penalty | E14: =IF(E$5<Leadsheet!$E$12,VLOOKUP(SAP_Speadsheet!E$5,Leadsheet!$C$26:$F$30,3,1),0) -> 0.0608466 | F14: =IF(F$5<Leadsheet!$E$12,VLOOKUP(SAP_Speadsheet!F$5,Leadsheet!$C$26:$F$30,3,1),0) -> 0.0608466 | G14: =IF(G$5<Leadsheet!$E$12,VLOOKUP(SAP_Speadsheet!G$5,Leadsheet!$C$26:$F$30,3,1),0) -> 0.0608466 | H14: =IF(H$5<Leadsheet!$E$12,VLOOKUP(SAP_Speadsheet!H$5,Leadsheet!$C$26:$F$30,3,1),0) -> 0.05 | I14: =IF(I$5<Leadsheet!$E$12,VLOOKUP(SAP_Speadsheet!I$5,Leadsheet!$C$26:$F$30,3,1),0) -> 0.05 | J14: =IF(J$5<Leadsheet!$E$12,VLOOKUP(SAP_Speadsheet!J$5,Leadsheet!$C$26:$F$30,3,1),0) -> 0.05 | K14: =IF(K$5<Leadsheet!$E$12,VLOOKUP(SAP_Speadsheet!K$5,Leadsheet!$C$26:$F$30,3,1),0) -> 0.05 | L14: =IF(L$5<Leadsheet!$E$12,VLOOKUP(SAP_Speadsheet!L$5,Leadsheet!$C$26:$F$30,3,1),0) -> 0.05 | ... BL14: =IF(BL$5<Leadsheet!$E$12,VLOOKUP(SAP_Speadsheet!BL$5,Leadsheet!$C$26:$F$30,3,1),0) -> 0
B16: EMI | C16: Account accumulated | D16: 1 | E16: =IF(E5>$D$7,0,D16-E13) -> 0.92 | F16: =IF(F5>$D$7,0,E16-F13) -> 0.86 | G16: =IF(G5>$D$7,0,F16-G13) -> 0.8 | H16: =IF(H5>$D$7,0,G16-H13) -> 0.775 | I16: =IF(I5>$D$7,0,H16-I13) -> 0.75 | J16: =IF(J5>$D$7,0,I16-J13) -> 0.725 | K16: =IF(K5>$D$7,0,J16-K13) -> 0.7 | L16: =IF(L5>$D$7,0,K16-L13) -> 0.675 | ... BL16: =IF(BL5>$D$7,0,BK16-BL13) -> 0
C17: Nominal ENR | D17: =Leadsheet!E10 -> 14.837554 | E17: =IF(E$5>Leadsheet!$E$12,0,D17+E21+E18) -> 12.958311 | F17: =IF(F$5>Leadsheet!$E$12,0,SAP_Speadsheet!E17+SAP_Speadsheet!F21+F18) -> 11.501246 | G17: =IF(G$5>Leadsheet!$E$12,0,SAP_Speadsheet!F17+SAP_Speadsheet!G21+G18) -> 10.130648 | H17: =IF(H$5>Leadsheet!$E$12,0,SAP_Speadsheet!G17+SAP_Speadsheet!H21+H18) -> 9.2336188 | I17: =IF(I$5>Leadsheet!$E$12,0,SAP_Speadsheet!H17+SAP_Speadsheet!I21+I18) -> 8.3557068 | J17: =IF(J$5>Leadsheet!$E$12,0,SAP_Speadsheet!I17+SAP_Speadsheet!J21+J18) -> 7.4964378 | K17: =IF(K$5>Leadsheet!$E$12,0,SAP_Speadsheet!J17+SAP_Speadsheet!K21+K18) -> 6.6550052 | L17: =IF(L$5>Leadsheet!$E$12,0,SAP_Speadsheet!K17+SAP_Speadsheet!L21+L18) -> 5.8314685 | M17: =IF(M$5>Leadsheet!$E$12,0,SAP_Speadsheet!L17+SAP_Speadsheet!M21+M18) -> 5.0260463 | ... BL17: =IF(BL$5>Leadsheet!$E$12,0,SAP_Speadsheet!BK17+SAP_Speadsheet!BL21+BL18) -> 0
C18: Fully Prepayment Amount | E18: =-IF(E6>0,IFERROR(D27*(D16-E16)/D16,0),0) -> -1.1870043 | F18: =-IF(F6>0,IFERROR(E27*(E16-F16)/E16,0),0) -> -0.79898121 | G18: =-IF(G6>0,IFERROR(F27*(F16-G16)/F16,0),0) -> -0.73203714 | H18: =-IF(H6>0,IFERROR(G27*(G16-H16)/G16,0),0) -> -0.27902412 | I18: =-IF(I6>0,IFERROR(H27*(H16-I16)/H16,0),0) -> -0.25539339 | J18: =-IF(J6>0,IFERROR(I27*(I16-J16)/I16,0),0) -> -0.23241501 | K18: =-IF(K6>0,IFERROR(J27*(J16-K16)/J16,0),0) -> -0.21048116 | L18: =-IF(L6>0,IFERROR(K27*(K16-L16)/K16,0),0) -> -0.18884539 | ... BL18: =-IF(BL6>0,IFERROR(BK27*(BK16-BL16)/BK16,0),0) -> 0
C19: EMI payment | E19: =-IFERROR(PMT(D11/12,D6,-D17),0) -> -1.2522435 | F19: =-IFERROR(PMT(E11/12,E6,-E17),0) -> -1.1471615 | G19: =-IFERROR(PMT(F11/12,F6,-F17),0) -> -1.0726458 | H19: =-IFERROR(PMT(G11/12,G6,-G17),0) -> -1.0003601 | I19: =-IFERROR(PMT(H11/12,H6,-H17),0) -> -0.97101761 | J19: =-IFERROR(PMT(I11/12,I6,-I17),0) -> -0.94221856 | K19: =-IFERROR(PMT(J11/12,J6,-J17),0) -> -0.91388503 | L19: =-IFERROR(PMT(K11/12,K6,-K17),0) -> -0.88586726 | ... BL19: =-IFERROR(PMT(BK11/12,BK6,-BK17),0) -> 0
C20: Nominal Interest | E20: =-IF(E5>$D$6,0,D17*D11/12) -> -0.56000506 | F20: =-IF(F5>$D$6,0,E17*E11/12) -> -0.4890779 | G20: =-IF(G5>$D$6,0,F17*F11/12) -> -0.43408476 | H20: =-IF(H5>$D$6,0,G17*G11/12) -> -0.38235508 | I20: =-IF(I5>$D$6,0,H17*H11/12) -> -0.34849904 | J20: =-IF(J5>$D$6,0,I17*I11/12) -> -0.31536453 | K20: =-IF(K5>$D$6,0,J17*J11/12) -> -0.28293364 | L20: =-IF(L5>$D$6,0,K17*K11/12) -> -0.25117595 | ... BL20: =-IF(BL5>$D$6,0,BK17*BK11/12) -> 0
C21: Nominal Payment | E21: =E19-E20 -> -0.69223848 | F21: =F19-F20 -> -0.65808361 | G21: =G19-G20 -> -0.63856101 | H21: =H19-H20 -> -0.61800501 | I21: =I19-I20 -> -0.62251857 | J21: =J19-J20 -> -0.62685404 | K21: =K19-K20 -> -0.63095139 | L21: =L19-L20 -> -0.63469131 | ... BL21: =BL19-BL20 -> 0
C24: Schedule Payment | E24: =IF(E5>Leadsheet!$E$12,0,IFERROR(E21/D17*D27*(1-Leadsheet!$D$91)+E18,0)) -> -1.8446309 | F24: =IF(F5>Leadsheet!$E$12,0,IFERROR(F21/E17*E27*(1-Leadsheet!$D$91)+F18,0)) -> -1.3900383 | G24: =IF(G5>Leadsheet!$E$12,0,IFERROR(G21/F17*F27*(1-Leadsheet!$D$91)+G18,0)) -> -1.2854655 | H24: =IF(H5>Leadsheet!$E$12,0,IFERROR(H21/G17*G27*(1-Leadsheet!$D$91)+H18,0)) -> -0.79647617 | I24: =IF(I5>Leadsheet!$E$12,0,IFERROR(I21/H17*H27*(1-Leadsheet!$D$91)+I18,0)) -> -0.76247205 | J24: =IF(J5>Leadsheet!$E$12,0,IFERROR(J21/I17*I27*(1-Leadsheet!$D$91)+J18,0)) -> -0.72934164 | K24: =IF(K5>Leadsheet!$E$12,0,IFERROR(K21/J17*J27*(1-Leadsheet!$D$91)+K18,0)) -> -0.69854405 | L24: =IF(L5>Leadsheet!$E$12,0,IFERROR(L21/K17*K27*(1-Leadsheet!$D$91)+L18,0)) -> -0.66791891 | ... BL24: =IF(BL5>Leadsheet!$E$12,0,IFERROR(BL21/BK17*BK27*(1-Leadsheet!$D$91)+BL18,0)) -> 0
A26: SBV | B26: Overdue | C26: Balance by Bucket/Group
A27: G1 | B27: 0 | C27: B0 | D27: =Leadsheet!E10 -> 14.837554 | E27: =IF(E5>=Leadsheet!$E$12,0,D44+E24-SUM(E28:E41)) -> 12.251045 | F27: =IF(F5>=Leadsheet!$E$12,0,E44+F24-SUM(F28:F41)) -> 10.492532 | G27: =IF(G5>=Leadsheet!$E$12,0,F44+G24-SUM(G28:G41)) -> 8.9287719 | H27: =IF(H5>=Leadsheet!$E$12,0,G44+H24-SUM(H28:H41)) -> 7.9171952 | I27: =IF(I5>=Leadsheet!$E$12,0,H44+I24-SUM(I28:I41)) -> 6.9724504 | J27: =IF(J5>=Leadsheet!$E$12,0,I44+J24-SUM(J28:J41)) -> 6.1039536 | K27: =IF(K5>=Leadsheet!$E$12,0,J44+K24-SUM(K28:K41)) -> 5.2876708 | L27: =IF(L5>=Leadsheet!$E$12,0,K44+L24-SUM(L28:L41)) -> 4.5207869 | ... BL27: =IF(BL5>=Leadsheet!$E$12,0,BK44+BL24-SUM(BL28:BL41)) -> 0
A28: G2 | B28: 30 | C28: B1 | E28: =IF(E$5>$D$7,0,D27*Leadsheet!$D91) -> 0.74187768 | F28: =IF(F$5>$D$7,0,E27*Leadsheet!$D91) -> 0.61255226 | G28: =IF(G$5>$D$7,0,F27*Leadsheet!$D91) -> 0.52462662 | H28: =IF(H$5>$D$7,0,G27*Leadsheet!$D91) -> 0.4464386 | I28: =IF(I$5>$D$7,0,H27*Leadsheet!$D91) -> 0.39585976 | J28: =IF(J$5>$D$7,0,I27*Leadsheet!$D91) -> 0.34862252 | K28: =IF(K$5>$D$7,0,J27*Leadsheet!$D91) -> 0.30519768 | L28: =IF(L$5>$D$7,0,K27*Leadsheet!$D91) -> 0.26438354 | ... BL28: =IF(BL$5>$D$7,0,BK27*Leadsheet!$D91) -> 0
A29: G2 | B29: 60 | C29: B2 | E29: =IF(E$5>$D$7,0,D28*Leadsheet!$D92) -> 0 | F29: =IF(F$5>$D$7,0,E28*Leadsheet!$D92) -> 0.49779993 | G29: =IF(G$5>$D$7,0,F28*Leadsheet!$D92) -> 0.41102256 | H29: =IF(H$5>$D$7,0,G28*Leadsheet!$D92) -> 0.35202446 | I29: =IF(I$5>$D$7,0,H28*Leadsheet!$D92) -> 0.2995603 | J29: =IF(J$5>$D$7,0,I28*Leadsheet!$D92) -> 0.2656219 | K29: =IF(K$5>$D$7,0,J28*Leadsheet!$D92) -> 0.23392571 | L29: =IF(L$5>$D$7,0,K28*Leadsheet!$D92) -> 0.20478764 | ... BL29: =IF(BL$5>$D$7,0,BK28*Leadsheet!$D92) -> 0
A30: G2 | B30: 90 | C30: B3 | E30: =IF(E$5>$D$7,0,D29*Leadsheet!$D93) -> 0 | F30: =IF(F$5>$D$7,0,E29*Leadsheet!$D93) -> 0 | G30: =IF(G$5>$D$7,0,F29*Leadsheet!$D93) -> 0.45299793 | H30: =IF(H$5>$D$7,0,G29*Leadsheet!$D93) -> 0.37403053 | I30: =IF(I$5>$D$7,0,H29*Leadsheet!$D93) -> 0.32034226 | J30: =IF(J$5>$D$7,0,I29*Leadsheet!$D93) -> 0.27259987 | K30: =IF(K$5>$D$7,0,J29*Leadsheet!$D93) -> 0.24171593 | L30: =IF(L$5>$D$7,0,K29*Leadsheet!$D93) -> 0.2128724 | ... AU30: =IF(AU$5>$D$7,0,AT29*Leadsheet!$D93) -> 0 | AV30: 0 | AW30: =IF(AW$5>$D$7,0,AV29*Leadsheet!$D93) -> 0 | AX30: =IF(AX$5>$D$7,0,AW29*Leadsheet!$D93) -> 0 | AY30: =IF(AY$5>$D$7,0,AX29*Leadsheet!$D93) -> 0 | AZ30: =IF(AZ$5>$D$7,0,AY29*Leadsheet!$D93) -> 0 | BA30: =IF(BA$5>$D$7,0,AZ29*Leadsheet!$D93) -> 0 | BB30: =IF(BB$5>$D$7,0,BA29*Leadsheet!$D93) -> 0 | BC30: =IF(BC$5>$D$7,0,BB29*Leadsheet!$D93) -> 0 | BD30: =IF(BD$5>$D$7,0,BC29*Leadsheet!$D93) -> 0 | ... BL30: =IF(BL$5>$D$7,0,BK29*Leadsheet!$D93) -> 0
A31: G3 | B31: 120 | C31: B4 | E31: =IF(E$5>$D$7,0,D30*Leadsheet!$D94) -> 0 | F31: =IF(F$5>$D$7,0,E30*Leadsheet!$D94) -> 0 | G31: =IF(G$5>$D$7,0,F30*Leadsheet!$D94) -> 0 | H31: =IF(H$5>$D$7,0,G30*Leadsheet!$D94) -> 0.43125403 | I31: =IF(I$5>$D$7,0,H30*Leadsheet!$D94) -> 0.35607707 | J31: =IF(J$5>$D$7,0,I30*Leadsheet!$D94) -> 0.30496583 | K31: =IF(K$5>$D$7,0,J30*Leadsheet!$D94) -> 0.25951508 | L31: =IF(L$5>$D$7,0,K30*Leadsheet!$D94) -> 0.23011356 | ... BL31: =IF(BL$5>$D$7,0,BK30*Leadsheet!$D94) -> 0
A32: G3 | B32: 150 | C32: B5 | E32: =IF(E$5>$D$7,0,D31*Leadsheet!$D95) -> 0 | F32: =IF(F$5>$D$7,0,E31*Leadsheet!$D95) -> 0 | G32: =IF(G$5>$D$7,0,F31*Leadsheet!$D95) -> 0 | H32: =IF(H$5>$D$7,0,G31*Leadsheet!$D95) -> 0 | I32: =IF(I$5>$D$7,0,H31*Leadsheet!$D95) -> 0.41418107 | J32: =IF(J$5>$D$7,0,I31*Leadsheet!$D95) -> 0.34198029 | K32: =IF(K$5>$D$7,0,J31*Leadsheet!$D95) -> 0.2928925 | L32: =IF(L$5>$D$7,0,K31*Leadsheet!$D95) -> 0.24924111 | ... BL32: =IF(BL$5>$D$7,0,BK31*Leadsheet!$D95) -> 0
A33: G3 | B33: 180 | C33: B6 | E33: =IF(E$5>$D$7,0,D32*Leadsheet!$D96) -> 0 | F33: =IF(F$5>$D$7,0,E32*Leadsheet!$D96) -> 0 | G33: =IF(G$5>$D$7,0,F32*Leadsheet!$D96) -> 0 | H33: =IF(H$5>$D$7,0,G32*Leadsheet!$D96) -> 0 | I33: =IF(I$5>$D$7,0,H32*Leadsheet!$D96) -> 0 | J33: =IF(J$5>$D$7,0,I32*Leadsheet!$D96) -> 0.39138511 | K33: =IF(K$5>$D$7,0,J32*Leadsheet!$D96) -> 0.32315817 | L33: =IF(L$5>$D$7,0,K32*Leadsheet!$D96) -> 0.2767721 | ... BL33: =IF(BL$5>$D$7,0,BK32*Leadsheet!$D96) -> 0
A34: G4 | B34: 210 | C34: B7 | E34: =IF(E$5>$D$7,0,D33*Leadsheet!$D97) -> 0 | F34: =IF(F$5>$D$7,0,E33*Leadsheet!$D97) -> 0 | G34: =IF(G$5>$D$7,0,F33*Leadsheet!$D97) -> 0 | H34: =IF(H$5>$D$7,0,G33*Leadsheet!$D97) -> 0 | I34: =IF(I$5>$D$7,0,H33*Leadsheet!$D97) -> 0 | J34: =IF(J$5>$D$7,0,I33*Leadsheet!$D97) -> 0 | K34: =IF(K$5>$D$7,0,J33*Leadsheet!$D97) -> 0.38650925 | L34: =IF(L$5>$D$7,0,K33*Leadsheet!$D97) -> 0.31913228 | ... BL34: =IF(BL$5>$D$7,0,BK33*Leadsheet!$D97) -> 0
A35: G4 | B35: 240 | C35: B8 | E35: =IF(E$5>$D$7,0,D34*Leadsheet!$D98) -> 0 | F35: =IF(F$5>$D$7,0,E34*Leadsheet!$D98) -> 0 | G35: =IF(G$5>$D$7,0,F34*Leadsheet!$D98) -> 0 | H35: =IF(H$5>$D$7,0,G34*Leadsheet!$D98) -> 0 | I35: =IF(I$5>$D$7,0,H34*Leadsheet!$D98) -> 0 | J35: =IF(J$5>$D$7,0,I34*Leadsheet!$D98) -> 0 | K35: =IF(K$5>$D$7,0,J34*Leadsheet!$D98) -> 0 | L35: =IF(L$5>$D$7,0,K34*Leadsheet!$D98) -> 0.38457671 | ... BL35: =IF(BL$5>$D$7,0,BK34*Leadsheet!$D98) -> 0
A36: G4 | B36: 270 | C36: B9 | E36: =IF(E$5>$D$7,0,D35*Leadsheet!$D99) -> 0 | F36: =IF(F$5>$D$7,0,E35*Leadsheet!$D99) -> 0 | G36: =IF(G$5>$D$7,0,F35*Leadsheet!$D99) -> 0 | H36: =IF(H$5>$D$7,0,G35*Leadsheet!$D99) -> 0 | I36: =IF(I$5>$D$7,0,H35*Leadsheet!$D99) -> 0 | J36: =IF(J$5>$D$7,0,I35*Leadsheet!$D99) -> 0 | K36: =IF(K$5>$D$7,0,J35*Leadsheet!$D99) -> 0 | L36: =IF(L$5>$D$7,0,K35*Leadsheet!$D99) -> 0 | ... BL36: =IF(BL$5>$D$7,0,BK35*Leadsheet!$D99) -> 0
A37: G4 | B37: 300 | C37: B10 | E37: =IF(E$5>$D$7,0,D36*Leadsheet!$D100) -> 0 | F37: =IF(F$5>$D$7,0,E36*Leadsheet!$D100) -> 0 | G37: =IF(G$5>$D$7,0,F36*Leadsheet!$D100) -> 0 | H37: =IF(H$5>$D$7,0,G36*Leadsheet!$D100) -> 0 | I37: =IF(I$5>$D$7,0,H36*Leadsheet!$D100) -> 0 | J37: =IF(J$5>$D$7,0,I36*Leadsheet!$D100) -> 0 | K37: =IF(K$5>$D$7,0,J36*Leadsheet!$D100) -> 0 | L37: =IF(L$5>$D$7,0,K36*Leadsheet!$D100) -> 0 | ... BL37: =IF(BL$5>$D$7,0,BK36*Leadsheet!$D100) -> 0
A38: G4 | B38: 330 | C38: B11 | E38: =IF(E$5>$D$7,0,D37*Leadsheet!$D101) -> 0 | F38: =IF(F$5>$D$7,0,E37*Leadsheet!$D101) -> 0 | G38: =IF(G$5>$D$7,0,F37*Leadsheet!$D101) -> 0 | H38: =IF(H$5>$D$7,0,G37*Leadsheet!$D101) -> 0 | I38: =IF(I$5>$D$7,0,H37*Leadsheet!$D101) -> 0 | J38: =IF(J$5>$D$7,0,I37*Leadsheet!$D101) -> 0 | K38: =IF(K$5>$D$7,0,J37*Leadsheet!$D101) -> 0 | L38: =IF(L$5>$D$7,0,K37*Leadsheet!$D101) -> 0 | ... BL38: =IF(BL$5>$D$7,0,BK37*Leadsheet!$D101) -> 0
A39: G4 | B39: 360 | C39: B12 | E39: =IF(E$5>$D$7,0,D38*Leadsheet!$D102) -> 0 | F39: =IF(F$5>$D$7,0,E38*Leadsheet!$D102) -> 0 | G39: =IF(G$5>$D$7,0,F38*Leadsheet!$D102) -> 0 | H39: =IF(H$5>$D$7,0,G38*Leadsheet!$D102) -> 0 | I39: =IF(I$5>$D$7,0,H38*Leadsheet!$D102) -> 0 | J39: =IF(J$5>$D$7,0,I38*Leadsheet!$D102) -> 0 | K39: =IF(K$5>$D$7,0,J38*Leadsheet!$D102) -> 0 | L39: =IF(L$5>$D$7,0,K38*Leadsheet!$D102) -> 0 | ... BL39: =IF(BL$5>$D$7,0,BK38*Leadsheet!$D102) -> 0
A40: G5 | B40: 390 | C40: B13 | E40: =IF(E$5>$D$7,0,D39*Leadsheet!$D103) -> 0 | F40: =IF(F$5>$D$7,0,E39*Leadsheet!$D103) -> 0 | G40: =IF(G$5>$D$7,0,F39*Leadsheet!$D103) -> 0 | H40: =IF(H$5>$D$7,0,G39*Leadsheet!$D103) -> 0 | I40: =IF(I$5>$D$7,0,H39*Leadsheet!$D103) -> 0 | J40: =IF(J$5>$D$7,0,I39*Leadsheet!$D103) -> 0 | K40: =IF(K$5>$D$7,0,J39*Leadsheet!$D103) -> 0 | L40: =IF(L$5>$D$7,0,K39*Leadsheet!$D103) -> 0 | ... BL40: =IF(BL$5>$D$7,0,BK39*Leadsheet!$D103) -> 0
A41: G5 | B41: 420+ | C41: B14+ | E41: =IF(E5>$D$7,0,D40+D41) -> 0 | F41: =IF(F5>$D$7,0,E40+E41) -> 0 | G41: =IF(G5>$D$7,0,F40+F41) -> 0 | H41: =IF(H5>$D$7,0,G40+G41) -> 0 | I41: =IF(I5>$D$7,0,H40+H41) -> 0 | J41: =IF(J5>$D$7,0,I40+I41) -> 0 | K41: =IF(K5>$D$7,0,J40+J41) -> 0 | L41: =IF(L5>$D$7,0,K40+K41) -> 0 | ... BL41: =IF(BL5>$D$7,0,BK40+BK41) -> 0
B43: ENR
C44: Total bank | D44: =SUM(D27:D41) -> 14.837554 | E44: =SUM(E27:E41) -> 12.992923 | F44: =SUM(F27:F41) -> 11.602885 | G44: =SUM(G27:G41) -> 10.317419 | H44: =SUM(H27:H41) -> 9.5209429 | I44: =SUM(I27:I41) -> 8.7584708 | J44: =SUM(J27:J41) -> 8.0291292 | K44: =SUM(K27:K41) -> 7.3305851 | ... BL44: =SUM(BL27:BL41) -> 0
C45: Outstanding balance | D45: {=IF(D5=$D$7,0,_xlfn.IFS(Leadsheet!$G$5="DPD360+",SUM(SAP_Speadsheet!D27:D40),Leadsheet!$G$5="DPD180+",SUM(SAP_Speadsheet!D27:D34)))} -> 14.837554 | E45: {=IF(E5=$D$7,0,_xlfn.IFS(Leadsheet!$G$5="DPD360+",SUM(SAP_Speadsheet!E27:E40),Leadsheet!$G$5="DPD180+",SUM(SAP_Speadsheet!E27:E34)))} -> 12.992923 | F45: {=IF(F5=$D$7,0,_xlfn.IFS(Leadsheet!$G$5="DPD360+",SUM(SAP_Speadsheet!F27:F40),Leadsheet!$G$5="DPD180+",SUM(SAP_Speadsheet!F27:F34)))} -> 11.602885 | G45: {=IF(G5=$D$7,0,_xlfn.IFS(Leadsheet!$G$5="DPD360+",SUM(SAP_Speadsheet!G27:G40),Leadsheet!$G$5="DPD180+",SUM(SAP_Speadsheet!G27:G34)))} -> 10.317419 | H45: {=IF(H5=$D$7,0,_xlfn.IFS(Leadsheet!$G$5="DPD360+",SUM(SAP_Speadsheet!H27:H40),Leadsheet!$G$5="DPD180+",SUM(SAP_Speadsheet!H27:H34)))} -> 9.5209429 | I45: {=IF(I5=$D$7,0,_xlfn.IFS(Leadsheet!$G$5="DPD360+",SUM(SAP_Speadsheet!I27:I40),Leadsheet!$G$5="DPD180+",SUM(SAP_Speadsheet!I27:I34)))} -> 8.7584708 | J45: {=IF(J5=$D$7,0,_xlfn.IFS(Leadsheet!$G$5="DPD360+",SUM(SAP_Speadsheet!J27:J40),Leadsheet!$G$5="DPD180+",SUM(SAP_Speadsheet!J27:J34)))} -> 8.0291292 | K45: {=IF(K5=$D$7,0,_xlfn.IFS(Leadsheet!$G$5="DPD360+",SUM(SAP_Speadsheet!K27:K40),Leadsheet!$G$5="DPD180+",SUM(SAP_Speadsheet!K27:K34)))} -> 7.3305851 | ... BL45: {=IF(BL5=$D$7,0,_xlfn.IFS(Leadsheet!$G$5="DPD360+",SUM(SAP_Speadsheet!BL27:BL40),Leadsheet!$G$5="DPD180+",SUM(SAP_Speadsheet!BL27:BL34)))} -> 0
C46: Writeoff balance | D46: =D44-D45 -> 0 | E46: =E44-E45 -> 0 | F46: =F44-F45 -> 0 | G46: =G44-G45 -> 0 | H46: =H44-H45 -> 0 | I46: =I44-I45 -> 0 | J46: =J44-J45 -> 0 | K46: =K44-K45 -> 0 | ... BL46: =BL44-BL45 -> 0
C47: Outstanding Bal/TB | D47: =IFERROR(D45/D44,"") -> 1 | E47: =IFERROR(E45/E44,"") -> 1 | F47: =IFERROR(F45/F44,"") -> 1 | G47: =IFERROR(G45/G44,"") -> 1 | H47: =IFERROR(H45/H44,"") -> 1 | I47: =IFERROR(I45/I44,"") -> 1 | J47: =IFERROR(J45/J44,"") -> 1 | K47: =IFERROR(K45/K44,"") -> 1 | ... BL47: =IFERROR(BL45/BL44,"")
B49: ANR
...

Sheet Saleplan&PnL
C1: PROFIT & LOSS 60M
C2: I. | D2: SALES PLAN
C4: Business month | D4: 45658 | E4: =EOMONTH(D4,1) -> 45716 | F4: =EOMONTH(E4,1) -> 45747 | G4: =EOMONTH(F4,1) -> 45777 | H4: =EOMONTH(G4,1) -> 45808 | I4: =EOMONTH(H4,1) -> 45838 | J4: =EOMONTH(I4,1) -> 45869 | K4: =EOMONTH(J4,1) -> 45900 | L4: =EOMONTH(K4,1) -> 45930 | ... BL4: =EOMONTH(BK4,1) -> 47514
C5: Don't delete | D5: =YEAR(D4) -> 2025 | E5: =YEAR(E4) -> 2025 | F5: =YEAR(F4) -> 2025 | G5: =YEAR(G4) -> 2025 | H5: =YEAR(H4) -> 2025 | I5: =YEAR(I4) -> 2025 | J5: =YEAR(J4) -> 2025 | K5: =YEAR(K4) -> 2025 | ... BL5: =YEAR(BL4) -> 2030
C6: New disbursement (bVND) | J6: =DATA!#REF!/10^9 -> #REF! | K6: =DATA!#REF!/10^9 -> #REF! | L6: =DATA!#REF!/10^9 -> #REF!
C8: II. | D8: PROFIT & LOSS
C10: FISCAL YEAR | E10: Total | F10: =YEAR(D4) -> 2025 | G10: =F10+1 -> 2026 | H10: =G10+1 -> 2027 | I10: =H10+1 -> 2028 | J10: =I10+1 -> 2029 | K10: =J10+1 -> 2030
E11: bVND | F11: bVND | G11: bVND | H11: bVND | I11: bVND | J11: bVND | K11: bVND
C13: NEW DISBURSAL | E13: =SUM(F13:O13) -> #REF! | F13: =SUMIF($D$5:$BL$5,F$10,$D$6:$BL$6) -> #REF! | G13: =SUMIF($D$5:$BL$5,G$10,$D$6:$BL$6) -> 0 | H13: =SUMIF($D$5:$BL$5,H$10,$D$6:$BL$6) -> 0 | I13: =SUMIF($D$5:$BL$5,I$10,$D$6:$BL$6) -> 0 | J13: =SUMIF($D$5:$BL$5,J$10,$D$6:$BL$6) -> 0 | K13: =SUMIF($D$5:$BL$5,K$10,$D$6:$BL$6) -> 0
C14: Monthly disbursement | E14: =AVERAGE(D6:AM6) -> #REF! | F14: =IFERROR(F13/COUNTIFS($D$5:$BL$5,F10,$D$6:$BL$6,"<>"&""),0) -> 0 | G14: =IFERROR(G13/COUNTIFS($D$5:$BL$5,G10,$D$6:$BL$6,"<>"&""),0) -> 0 | H14: =IFERROR(H13/COUNTIFS($D$5:$BL$5,H10,$D$6:$BL$6,"<>"&""),0) -> 0 | I14: =IFERROR(I13/COUNTIFS($D$5:$BL$5,I10,$D$6:$BL$6,"<>"&""),0) -> 0 | J14: =IFERROR(J13/COUNTIFS($D$5:$BL$5,J10,$D$6:$BL$6,"<>"&""),0) -> 0 | K14: =IFERROR(K13/COUNTIFS($D$5:$BL$5,K10,$D$6:$BL$6,"<>"&""),0) -> 0
C16: EOP | F16: =OFFSET(PnL_Speadsheet!$A$7,0,MATCH(DATE('Saleplan&PnL'!F$10,12,31),PnL_Speadsheet!$B$4:$BI$4,0))/1000 -> #REF! | G16: =OFFSET(PnL_Speadsheet!$A$7,0,MATCH(DATE('Saleplan&PnL'!G$10,12,31),PnL_Speadsheet!$B$4:$BI$4,0))/1000 -> #REF! | H16: =OFFSET(PnL_Speadsheet!$A$7,0,MATCH(DATE('Saleplan&PnL'!H$10,12,31),PnL_Speadsheet!$B$4:$BI$4,0))/1000 -> #REF! | I16: =OFFSET(PnL_Speadsheet!$A$7,0,MATCH(DATE('Saleplan&PnL'!I$10,12,31),PnL_Speadsheet!$B$4:$BI$4,0))/1000 -> #REF! | J16: =OFFSET(PnL_Speadsheet!$A$7,0,MATCH(DATE('Saleplan&PnL'!J$10,12,31),PnL_Speadsheet!$B$4:$BI$4,0))/1000 -> #REF! | K16: =IFERROR(OFFSET(PnL_Speadsheet!$A$7,0,MATCH(DATE('Saleplan&PnL'!K$10,12,31),PnL_Speadsheet!$B$4:$BI$4,0))/1000,0) -> 0
C17: ADB | E17: =IFERROR(SUM(PnL_Speadsheet!B8:AK8)/1000/COUNTIF(PnL_Speadsheet!B8:BI8,"<>0"),0) -> 0 | F17: =IFERROR(SUMIF(PnL_Speadsheet!$B$3:$BI$3,F$10,PnL_Speadsheet!$B8:$BI8)/1000/COUNTIFS(PnL_Speadsheet!$B$3:$BI$3,'Saleplan&PnL'!F$10,PnL_Speadsheet!$B$8:$BI$8,"<>0"),0) -> 0 | G17: =IFERROR(SUMIF(PnL_Speadsheet!$B$3:$BI$3,G$10,PnL_Speadsheet!$B8:$BI8)/1000/COUNTIFS(PnL_Speadsheet!$B$3:$BI$3,'Saleplan&PnL'!G$10,PnL_Speadsheet!$B$8:$BI$8,"<>0"),0) -> 0 | H17: =IFERROR(SUMIF(PnL_Speadsheet!$B$3:$BI$3,H$10,PnL_Speadsheet!$B8:$BI8)/1000/COUNTIFS(PnL_Speadsheet!$B$3:$BI$3,'Saleplan&PnL'!H$10,PnL_Speadsheet!$B$8:$BI$8,"<>0"),0) -> 0 | I17: =IFERROR(SUMIF(PnL_Speadsheet!$B$3:$BI$3,I$10,PnL_Speadsheet!$B8:$BI8)/1000/COUNTIFS(PnL_Speadsheet!$B$3:$BI$3,'Saleplan&PnL'!I$10,PnL_Speadsheet!$B$8:$BI$8,"<>0"),0) -> 0 | J17: =IFERROR(SUMIF(PnL_Speadsheet!$B$3:$BI$3,J$10,PnL_Speadsheet!$B8:$BI8)/1000/COUNTIFS(PnL_Speadsheet!$B$3:$BI$3,'Saleplan&PnL'!J$10,PnL_Speadsheet!$B$8:$BI$8,"<>0"),0) -> 0 | K17: =IFERROR(SUMIF(PnL_Speadsheet!$B$3:$BI$3,K$10,PnL_Speadsheet!$B8:$BI8)/1000/COUNTIFS(PnL_Speadsheet!$B$3:$BI$3,'Saleplan&PnL'!K$10,PnL_Speadsheet!$B$8:$BI$8,"<>0"),0) -> 0
C19: TOI | E19: =SUM(F19:O19) -> #REF! | F19: =SUMIF(PnL_Speadsheet!$B$3:$BI$3,F$10,PnL_Speadsheet!$B9:$BI9)/1000 -> #REF! | G19: =SUMIF(PnL_Speadsheet!$B$3:$BI$3,G$10,PnL_Speadsheet!$B9:$BI9)/1000 -> #REF! | H19: =SUMIF(PnL_Speadsheet!$B$3:$BI$3,H$10,PnL_Speadsheet!$B9:$BI9)/1000 -> #REF! | I19: =SUMIF(PnL_Speadsheet!$B$3:$BI$3,I$10,PnL_Speadsheet!$B9:$BI9)/1000 -> #REF! | J19: =SUMIF(PnL_Speadsheet!$B$3:$BI$3,J$10,PnL_Speadsheet!$B9:$BI9)/1000 -> #REF! | K19: =SUMIF(PnL_Speadsheet!$B$3:$BI$3,K$10,PnL_Speadsheet!$B9:$BI9)/1000 -> 0
C20: NII | E20: =SUM(F20:O20) -> #REF! | F20: =SUMIF(PnL_Speadsheet!$B$3:$BI$3,F$10,PnL_Speadsheet!$B11:$BI11)/1000 -> #REF! | G20: =SUMIF(PnL_Speadsheet!$B$3:$BI$3,G$10,PnL_Speadsheet!$B11:$BI11)/1000 -> #REF! | H20: =SUMIF(PnL_Speadsheet!$B$3:$BI$3,H$10,PnL_Speadsheet!$B11:$BI11)/1000 -> #REF! | I20: =SUMIF(PnL_Speadsheet!$B$3:$BI$3,I$10,PnL_Speadsheet!$B11:$BI11)/1000 -> #REF! | J20: =SUMIF(PnL_Speadsheet!$B$3:$BI$3,J$10,PnL_Speadsheet!$B11:$BI11)/1000 -> #REF! | K20: =SUMIF(PnL_Speadsheet!$B$3:$BI$3,K$10,PnL_Speadsheet!$B11:$BI11)/1000 -> 0
C21: NFI | E21: =SUM(F21:O21) -> #REF! | F21: =SUMIF(PnL_Speadsheet!$B$3:$BI$3,F$10,PnL_Speadsheet!$B14:$BI14)/1000 -> #REF! | G21: =SUMIF(PnL_Speadsheet!$B$3:$BI$3,G$10,PnL_Speadsheet!$B14:$BI14)/1000 -> #REF! | H21: =SUMIF(PnL_Speadsheet!$B$3:$BI$3,H$10,PnL_Speadsheet!$B14:$BI14)/1000 -> #REF! | I21: =SUMIF(PnL_Speadsheet!$B$3:$BI$3,I$10,PnL_Speadsheet!$B14:$BI14)/1000 -> #REF! | J21: =SUMIF(PnL_Speadsheet!$B$3:$BI$3,J$10,PnL_Speadsheet!$B14:$BI14)/1000 -> #REF! | K21: =SUMIF(PnL_Speadsheet!$B$3:$BI$3,K$10,PnL_Speadsheet!$B14:$BI14)/1000 -> 0
C22: Other TOI | E22: =SUM(F22:O22) -> #REF! | F22: =SUMIF(PnL_Speadsheet!$B$3:$BI$3,F$10,PnL_Speadsheet!$B18:$BI18)/1000 -> #REF! | G22: =SUMIF(PnL_Speadsheet!$B$3:$BI$3,G$10,PnL_Speadsheet!$B18:$BI18)/1000 -> #REF! | H22: =SUMIF(PnL_Speadsheet!$B$3:$BI$3,H$10,PnL_Speadsheet!$B18:$BI18)/1000 -> #REF! | I22: =SUMIF(PnL_Speadsheet!$B$3:$BI$3,I$10,PnL_Speadsheet!$B18:$BI18)/1000 -> #REF! | J22: =SUMIF(PnL_Speadsheet!$B$3:$BI$3,J$10,PnL_Speadsheet!$B18:$BI18)/1000 -> #REF! | K22: =SUMIF(PnL_Speadsheet!$B$3:$BI$3,K$10,PnL_Speadsheet!$B18:$BI18)/1000 -> 0
C23: PROVISION | E23: =SUM(F23:O23) -> #REF! | F23: =SUMIF(PnL_Speadsheet!$B$3:$BI$3,F$10,PnL_Speadsheet!$B31:$BI31)/1000 -> #REF! | G23: =SUMIF(PnL_Speadsheet!$B$3:$BI$3,G$10,PnL_Speadsheet!$B31:$BI31)/1000 -> #REF! | H23: =SUMIF(PnL_Speadsheet!$B$3:$BI$3,H$10,PnL_Speadsheet!$B31:$BI31)/1000 -> #REF! | I23: =SUMIF(PnL_Speadsheet!$B$3:$BI$3,I$10,PnL_Speadsheet!$B31:$BI31)/1000 -> #REF! | J23: =SUMIF(PnL_Speadsheet!$B$3:$BI$3,J$10,PnL_Speadsheet!$B31:$BI31)/1000 -> #REF! | K23: =SUMIF(PnL_Speadsheet!$B$3:$BI$3,K$10,PnL_Speadsheet!$B31:$BI31)/1000 -> 0
C24: OPEX | E24: =SUM(F24:O24) -> #REF! | F24: =SUMIF(PnL_Speadsheet!$B$3:$BI$3,F$10,PnL_Speadsheet!$B19:$BI19)/1000 -> #REF! | G24: =SUMIF(PnL_Speadsheet!$B$3:$BI$3,G$10,PnL_Speadsheet!$B19:$BI19)/1000 -> #REF! | H24: =SUMIF(PnL_Speadsheet!$B$3:$BI$3,H$10,PnL_Speadsheet!$B19:$BI19)/1000 -> #REF! | I24: =SUMIF(PnL_Speadsheet!$B$3:$BI$3,I$10,PnL_Speadsheet!$B19:$BI19)/1000 -> #REF! | J24: =SUMIF(PnL_Speadsheet!$B$3:$BI$3,J$10,PnL_Speadsheet!$B19:$BI19)/1000 -> #REF! | K24: =SUMIF(PnL_Speadsheet!$B$3:$BI$3,K$10,PnL_Speadsheet!$B19:$BI19)/1000 -> 0
C25: Sales incentives | E25: =SUM(F25:O25) -> #REF! | F25: =(SUMIF(PnL_Speadsheet!$B$3:$BI$3,F$10,PnL_Speadsheet!$B21:$BI22)/1000+SUMIF(PnL_Speadsheet!$B$3:$BI$3,F$10,PnL_Speadsheet!$B22:$BI22)/1000) -> #REF! | G25: =(SUMIF(PnL_Speadsheet!$B$3:$BI$3,G$10,PnL_Speadsheet!$B21:$BI22)/1000+SUMIF(PnL_Speadsheet!$B$3:$BI$3,G$10,PnL_Speadsheet!$B22:$BI22)/1000) -> #REF! | H25: =(SUMIF(PnL_Speadsheet!$B$3:$BI$3,H$10,PnL_Speadsheet!$B21:$BI22)/1000+SUMIF(PnL_Speadsheet!$B$3:$BI$3,H$10,PnL_Speadsheet!$B22:$BI22)/1000) -> #REF! | I25: =(SUMIF(PnL_Speadsheet!$B$3:$BI$3,I$10,PnL_Speadsheet!$B21:$BI22)/1000+SUMIF(PnL_Speadsheet!$B$3:$BI$3,I$10,PnL_Speadsheet!$B22:$BI22)/1000) -> #REF! | J25: =(SUMIF(PnL_Speadsheet!$B$3:$BI$3,J$10,PnL_Speadsheet!$B21:$BI22)/1000+SUMIF(PnL_Speadsheet!$B$3:$BI$3,J$10,PnL_Speadsheet!$B22:$BI22)/1000) -> #REF! | K25: =(SUMIF(PnL_Speadsheet!$B$3:$BI$3,K$10,PnL_Speadsheet!$B21:$BI22)/1000+SUMIF(PnL_Speadsheet!$B$3:$BI$3,K$10,PnL_Speadsheet!$B22:$BI22)/1000) -> 0
C26: Marketing | E26: =SUM(F26:O26) -> #REF! | F26: =SUMIF(PnL_Speadsheet!$B$3:$BI$3,F$10,PnL_Speadsheet!$B23:$BI23)/1000 -> #REF! | G26: =SUMIF(PnL_Speadsheet!$B$3:$BI$3,G$10,PnL_Speadsheet!$B23:$BI23)/1000 -> #REF! | H26: =SUMIF(PnL_Speadsheet!$B$3:$BI$3,H$10,PnL_Speadsheet!$B23:$BI23)/1000 -> #REF! | I26: =SUMIF(PnL_Speadsheet!$B$3:$BI$3,I$10,PnL_Speadsheet!$B23:$BI23)/1000 -> #REF! | J26: =SUMIF(PnL_Speadsheet!$B$3:$BI$3,J$10,PnL_Speadsheet!$B23:$BI23)/1000 -> #REF! | K26: =SUMIF(PnL_Speadsheet!$B$3:$BI$3,K$10,PnL_Speadsheet!$B23:$BI23)/1000 -> 0
C27: UW & Disbursal | E27: =SUM(F27:O27) -> #REF! | F27: =SUMIF(PnL_Speadsheet!$B$3:$BI$3,F$10,PnL_Speadsheet!$B24:$BI24)/1000 -> #REF! | G27: =SUMIF(PnL_Speadsheet!$B$3:$BI$3,G$10,PnL_Speadsheet!$B24:$BI24)/1000 -> #REF! | H27: =SUMIF(PnL_Speadsheet!$B$3:$BI$3,H$10,PnL_Speadsheet!$B24:$BI24)/1000 -> #REF! | I27: =SUMIF(PnL_Speadsheet!$B$3:$BI$3,I$10,PnL_Speadsheet!$B24:$BI24)/1000 -> #REF! | J27: =SUMIF(PnL_Speadsheet!$B$3:$BI$3,J$10,PnL_Speadsheet!$B24:$BI24)/1000 -> #REF! | K27: =SUMIF(PnL_Speadsheet!$B$3:$BI$3,K$10,PnL_Speadsheet!$B24:$BI24)/1000 -> 0
C28: Collection & AMC | E28: =SUM(F28:O28) -> #REF! | F28: =SUMIF(PnL_Speadsheet!$B$3:$BI$3,F$10,PnL_Speadsheet!$B28:$BI28)/1000 -> #REF! | G28: =SUMIF(PnL_Speadsheet!$B$3:$BI$3,G$10,PnL_Speadsheet!$B28:$BI28)/1000 -> #REF! | H28: =SUMIF(PnL_Speadsheet!$B$3:$BI$3,H$10,PnL_Speadsheet!$B28:$BI28)/1000 -> #REF! | I28: =SUMIF(PnL_Speadsheet!$B$3:$BI$3,I$10,PnL_Speadsheet!$B28:$BI28)/1000 -> #REF! | J28: =SUMIF(PnL_Speadsheet!$B$3:$BI$3,J$10,PnL_Speadsheet!$B28:$BI28)/1000 -> #REF! | K28: =SUMIF(PnL_Speadsheet!$B$3:$BI$3,K$10,PnL_Speadsheet!$B28:$BI28)/1000 -> 0
C29: After-sales services | E29: =SUM(F29:O29) -> #REF! | F29: =SUMIF(PnL_Speadsheet!$B$3:$BI$3,F$10,PnL_Speadsheet!$B29:$BI29)/1000 -> #REF! | G29: =SUMIF(PnL_Speadsheet!$B$3:$BI$3,G$10,PnL_Speadsheet!$B29:$BI29)/1000 -> #REF! | H29: =SUMIF(PnL_Speadsheet!$B$3:$BI$3,H$10,PnL_Speadsheet!$B29:$BI29)/1000 -> #REF! | I29: =SUMIF(PnL_Speadsheet!$B$3:$BI$3,I$10,PnL_Speadsheet!$B29:$BI29)/1000 -> #REF! | J29: =SUMIF(PnL_Speadsheet!$B$3:$BI$3,J$10,PnL_Speadsheet!$B29:$BI29)/1000 -> #REF! | K29: =SUMIF(PnL_Speadsheet!$B$3:$BI$3,K$10,PnL_Speadsheet!$B29:$BI29)/1000 -> 0
C30: Other support units | E30: =SUM(F30:O30) -> #REF! | F30: =SUMIF(PnL_Speadsheet!$B$3:$BI$3,F$10,PnL_Speadsheet!$B30:$BI30)/1000 -> #REF! | G30: =SUMIF(PnL_Speadsheet!$B$3:$BI$3,G$10,PnL_Speadsheet!$B30:$BI30)/1000 -> #REF! | H30: =SUMIF(PnL_Speadsheet!$B$3:$BI$3,H$10,PnL_Speadsheet!$B30:$BI30)/1000 -> #REF! | I30: =SUMIF(PnL_Speadsheet!$B$3:$BI$3,I$10,PnL_Speadsheet!$B30:$BI30)/1000 -> #REF! | J30: =SUMIF(PnL_Speadsheet!$B$3:$BI$3,J$10,PnL_Speadsheet!$B30:$BI30)/1000 -> #REF! | K30: =SUMIF(PnL_Speadsheet!$B$3:$BI$3,K$10,PnL_Speadsheet!$B30:$BI30)/1000 -> 0
C31: PBT | E31: =SUM(F31:O31) -> #REF! | F31: =SUMIF(PnL_Speadsheet!$B$3:$BI$3,F$10,PnL_Speadsheet!$B32:$BI32)/1000 -> #REF! | G31: =SUMIF(PnL_Speadsheet!$B$3:$BI$3,G$10,PnL_Speadsheet!$B32:$BI32)/1000 -> #REF! | H31: =SUMIF(PnL_Speadsheet!$B$3:$BI$3,H$10,PnL_Speadsheet!$B32:$BI32)/1000 -> #REF! | I31: =SUMIF(PnL_Speadsheet!$B$3:$BI$3,I$10,PnL_Speadsheet!$B32:$BI32)/1000 -> #REF! | J31: =SUMIF(PnL_Speadsheet!$B$3:$BI$3,J$10,PnL_Speadsheet!$B32:$BI32)/1000 -> #REF! | K31: =SUMIF(PnL_Speadsheet!$B$3:$BI$3,K$10,PnL_Speadsheet!$B32:$BI32)/1000 -> 0
C32: In which: PROFIT BEFORE SU | E32: =E19+E23+SUM(E25:E29) -> #REF! | F32: =F19+F23+SUM(F25:F29) -> #REF! | G32: =G19+G23+SUM(G25:G29) -> #REF! | H32: =H19+H23+SUM(H25:H29) -> #REF! | I32: =I19+I23+SUM(I25:I29) -> #REF! | J32: =J19+J23+SUM(J25:J29) -> #REF! | K32: =K19+K23+SUM(K25:K29) -> 0

Sheet PnL_Speadsheet
A1: PL PROJECTION
A2: 60 months
B3: =YEAR(B4) -> 2025 | C3: =YEAR(C4) -> 2025 | D3: =YEAR(D4) -> 2025 | E3: =YEAR(E4) -> 2025 | F3: =YEAR(F4) -> 2025 | G3: =YEAR(G4) -> 2025 | H3: =YEAR(H4) -> 2025 | I3: =YEAR(I4) -> 2025 | ... BI3: =YEAR(BI4) -> 2029
A4: Business month | B4: ='Saleplan&PnL'!D4 -> 45658 | C4: ='Saleplan&PnL'!E4 -> 45716 | D4: ='Saleplan&PnL'!F4 -> 45747 | E4: ='Saleplan&PnL'!G4 -> 45777 | F4: ='Saleplan&PnL'!H4 -> 45808 | G4: ='Saleplan&PnL'!I4 -> 45838 | H4: ='Saleplan&PnL'!J4 -> 45869 | I4: ='Saleplan&PnL'!K4 -> 45900 | ... BI4: ='Saleplan&PnL'!BK4 -> 47483
A5: Month on board | B5: 1 | C5: 2 | D5: 3 | E5: 4 | F5: 5 | G5: 6 | H5: 7 | I5: 8 | J5: 9 | K5: 10 | L5: 11 | M5: 12 | N5: 13 | O5: 14 | P5: 15 | Q5: 16 | R5: 17 | S5: 18 | T5: 19 | U5: 20 | V5: 21 | W5: 22 | X5: 23 | Y5: 24 | Z5: 25 | AA5: 26 | AB5: 27 | AC5: 28 | AD5: 29 | AE5: 30 | AF5: 31 | AG5: 32 | AH5: 33 | AI5: 34 | AJ5: 35 | AK5: 36 | AL5: =AK5+1 -> 37 | AM5: =AL5+1 -> 38 | AN5: =AM5+1 -> 39 | AO5: =AN5+1 -> 40 | AP5: =AO5+1 -> 41 | AQ5: =AP5+1 -> 42 | AR5: =AQ5+1 -> 43 | AS5: =AR5+1 -> 44 | ... BI5: =BH5+1 -> 60
A6: Unit: mVND
A7: ENR | B7: {=SUMPRODUCT(B$55:B$114,TRANSPOSE(SAP_Speadsheet!$E$44:$BL$44))} -> 0 | C7: {=SUMPRODUCT(C$55:C$114,TRANSPOSE(SAP_Speadsheet!$E$44:$BL$44))} -> 0 | D7: {=SUMPRODUCT(D$55:D$114,TRANSPOSE(SAP_Speadsheet!$E$44:$BL$44))} -> 0 | E7: {=SUMPRODUCT(E$55:E$114,TRANSPOSE(SAP_Speadsheet!$E$44:$BL$44))} -> 0 | F7: {=SUMPRODUCT(F$55:F$114,TRANSPOSE(SAP_Speadsheet!$E$44:$BL$44))} -> 0 | G7: {=SUMPRODUCT(G$55:G$114,TRANSPOSE(SAP_Speadsheet!$E$44:$BL$44))} -> 0 | H7: {=SUMPRODUCT(H$55:H$114,TRANSPOSE(SAP_Speadsheet!$E$44:$BL$44))} -> #REF! | I7: {=SUMPRODUCT(I$55:I$114,TRANSPOSE(SAP_Speadsheet!$E$44:$BL$44))} -> #REF! | ... BI7: {=SUMPRODUCT(BI$55:BI$114,TRANSPOSE(SAP_Speadsheet!$E$44:$BL$44))} -> #REF!
A8: ANR | B8: {=SUMPRODUCT(B$55:B$114,TRANSPOSE(SAP_Speadsheet!$E$50:$BL$50))} -> 0 | C8: {=SUMPRODUCT(C$55:C$114,TRANSPOSE(SAP_Speadsheet!$E$50:$BL$50))} -> 0 | D8: {=SUMPRODUCT(D$55:D$114,TRANSPOSE(SAP_Speadsheet!$E$50:$BL$50))} -> 0 | E8: {=SUMPRODUCT(E$55:E$114,TRANSPOSE(SAP_Speadsheet!$E$50:$BL$50))} -> 0 | F8: {=SUMPRODUCT(F$55:F$114,TRANSPOSE(SAP_Speadsheet!$E$50:$BL$50))} -> 0 | G8: {=SUMPRODUCT(G$55:G$114,TRANSPOSE(SAP_Speadsheet!$E$50:$BL$50))} -> 0 | H8: {=SUMPRODUCT(H$55:H$114,TRANSPOSE(SAP_Speadsheet!$E$50:$BL$50))} -> #REF! | I8: {=SUMPRODUCT(I$55:I$114,TRANSPOSE(SAP_Speadsheet!$E$50:$BL$50))} -> #REF! | ... BI8: {=SUMPRODUCT(BI$55:BI$114,TRANSPOSE(SAP_Speadsheet!$E$50:$BL$50))} -> #REF!
A9: TOI | B9: {=SUMPRODUCT(B$55:B$114,TRANSPOSE(SAP_Speadsheet!$E$55:$BL$55))} -> 0 | C9: {=SUMPRODUCT(C$55:C$114,TRANSPOSE(SAP_Speadsheet!$E$55:$BL$55))} -> 0 | D9: {=SUMPRODUCT(D$55:D$114,TRANSPOSE(SAP_Speadsheet!$E$55:$BL$55))} -> 0 | E9: {=SUMPRODUCT(E$55:E$114,TRANSPOSE(SAP_Speadsheet!$E$55:$BL$55))} -> 0 | F9: {=SUMPRODUCT(F$55:F$114,TRANSPOSE(SAP_Speadsheet!$E$55:$BL$55))} -> 0 | G9: {=SUMPRODUCT(G$55:G$114,TRANSPOSE(SAP_Speadsheet!$E$55:$BL$55))} -> 0 | H9: {=SUMPRODUCT(H$55:H$114,TRANSPOSE(SAP_Speadsheet!$E$55:$BL$55))} -> #REF! | I9: {=SUMPRODUCT(I$55:I$114,TRANSPOSE(SAP_Speadsheet!$E$55:$BL$55))} -> #REF! | ... BI9: {=SUMPRODUCT(BI$55:BI$114,TRANSPOSE(SAP_Speadsheet!$E$55:$BL$55))} -> #REF!
A10: Checking | B10: =B9-B11-B14 -> 0 | C10: =C9-C11-C14 -> 0 | D10: =D9-D11-D14 -> 0 | E10: =E9-E11-E14 -> 0 | F10: =F9-F11-F14 -> 0 | G10: =G9-G11-G14 -> 0 | H10: =H9-H11-H14 -> #REF! | I10: =I9-I11-I14 -> #REF! | ... BI10: =BI9-BI11-BI14 -> #REF!
A11: Net interest income | B11: {=SUMPRODUCT(B$55:B$114,TRANSPOSE(SAP_Speadsheet!$E$57:$BL$57))} -> 0 | C11: {=SUMPRODUCT(C$55:C$114,TRANSPOSE(SAP_Speadsheet!$E$57:$BL$57))} -> 0 | D11: {=SUMPRODUCT(D$55:D$114,TRANSPOSE(SAP_Speadsheet!$E$57:$BL$57))} -> 0 | E11: {=SUMPRODUCT(E$55:E$114,TRANSPOSE(SAP_Speadsheet!$E$57:$BL$57))} -> 0 | F11: {=SUMPRODUCT(F$55:F$114,TRANSPOSE(SAP_Speadsheet!$E$57:$BL$57))} -> 0 | G11: {=SUMPRODUCT(G$55:G$114,TRANSPOSE(SAP_Speadsheet!$E$57:$BL$57))} -> 0 | H11: {=SUMPRODUCT(H$55:H$114,TRANSPOSE(SAP_Speadsheet!$E$57:$BL$57))} -> #REF! | I11: {=SUMPRODUCT(I$55:I$114,TRANSPOSE(SAP_Speadsheet!$E$57:$BL$57))} -> #REF! | ... BI11: {=SUMPRODUCT(BI$55:BI$114,TRANSPOSE(SAP_Speadsheet!$E$57:$BL$57))} -> #REF!
A12: Interest income | B12: {=SUMPRODUCT(B$55:B$114,TRANSPOSE(SAP_Speadsheet!$E$58:$BL$58))} -> 0 | C12: {=SUMPRODUCT(C$55:C$114,TRANSPOSE(SAP_Speadsheet!$E$58:$BL$58))} -> 0 | D12: {=SUMPRODUCT(D$55:D$114,TRANSPOSE(SAP_Speadsheet!$E$58:$BL$58))} -> 0 | E12: {=SUMPRODUCT(E$55:E$114,TRANSPOSE(SAP_Speadsheet!$E$58:$BL$58))} -> 0 | F12: {=SUMPRODUCT(F$55:F$114,TRANSPOSE(SAP_Speadsheet!$E$58:$BL$58))} -> 0 | G12: {=SUMPRODUCT(G$55:G$114,TRANSPOSE(SAP_Speadsheet!$E$58:$BL$58))} -> 0 | H12: {=SUMPRODUCT(H$55:H$114,TRANSPOSE(SAP_Speadsheet!$E$58:$BL$58))} -> #REF! | I12: {=SUMPRODUCT(I$55:I$114,TRANSPOSE(SAP_Speadsheet!$E$58:$BL$58))} -> #REF! | ... BI12: {=SUMPRODUCT(BI$55:BI$114,TRANSPOSE(SAP_Speadsheet!$E$58:$BL$58))} -> #REF!
A13: Cost of fund | B13: {=SUMPRODUCT(B$55:B$114,TRANSPOSE(SAP_Speadsheet!$E$59:$BL$59))} -> 0 | C13: {=SUMPRODUCT(C$55:C$114,TRANSPOSE(SAP_Speadsheet!$E$59:$BL$59))} -> 0 | D13: {=SUMPRODUCT(D$55:D$114,TRANSPOSE(SAP_Speadsheet!$E$59:$BL$59))} -> 0 | E13: {=SUMPRODUCT(E$55:E$114,TRANSPOSE(SAP_Speadsheet!$E$59:$BL$59))} -> 0 | F13: {=SUMPRODUCT(F$55:F$114,TRANSPOSE(SAP_Speadsheet!$E$59:$BL$59))} -> 0 | G13: {=SUMPRODUCT(G$55:G$114,TRANSPOSE(SAP_Speadsheet!$E$59:$BL$59))} -> 0 | H13: {=SUMPRODUCT(H$55:H$114,TRANSPOSE(SAP_Speadsheet!$E$59:$BL$59))} -> #REF! | I13: {=SUMPRODUCT(I$55:I$114,TRANSPOSE(SAP_Speadsheet!$E$59:$BL$59))} -> #REF! | ... BI13: {=SUMPRODUCT(BI$55:BI$114,TRANSPOSE(SAP_Speadsheet!$E$59:$BL$59))} -> #REF!
A14: Net fee income | B14: {=SUMPRODUCT(B$55:B$114,TRANSPOSE(SAP_Speadsheet!$E$61:$BL$61))} -> 0 | C14: {=SUMPRODUCT(C$55:C$114,TRANSPOSE(SAP_Speadsheet!$E$61:$BL$61))} -> 0 | D14: {=SUMPRODUCT(D$55:D$114,TRANSPOSE(SAP_Speadsheet!$E$61:$BL$61))} -> 0 | E14: {=SUMPRODUCT(E$55:E$114,TRANSPOSE(SAP_Speadsheet!$E$61:$BL$61))} -> 0 | F14: {=SUMPRODUCT(F$55:F$114,TRANSPOSE(SAP_Speadsheet!$E$61:$BL$61))} -> 0 | G14: {=SUMPRODUCT(G$55:G$114,TRANSPOSE(SAP_Speadsheet!$E$61:$BL$61))} -> 0 | H14: {=SUMPRODUCT(H$55:H$114,TRANSPOSE(SAP_Speadsheet!$E$61:$BL$61))} -> #REF! | I14: {=SUMPRODUCT(I$55:I$114,TRANSPOSE(SAP_Speadsheet!$E$61:$BL$61))} -> #REF! | ... BI14: {=SUMPRODUCT(BI$55:BI$114,TRANSPOSE(SAP_Speadsheet!$E$61:$BL$61))} -> #REF!
A15: Early termination income | B15: {=SUMPRODUCT(B$55:B$114,TRANSPOSE(SAP_Speadsheet!$E$62:$BL$62))} -> 0 | C15: {=SUMPRODUCT(C$55:C$114,TRANSPOSE(SAP_Speadsheet!$E$62:$BL$62))} -> 0 | D15: {=SUMPRODUCT(D$55:D$114,TRANSPOSE(SAP_Speadsheet!$E$62:$BL$62))} -> 0 | E15: {=SUMPRODUCT(E$55:E$114,TRANSPOSE(SAP_Speadsheet!$E$62:$BL$62))} -> 0 | F15: {=SUMPRODUCT(F$55:F$114,TRANSPOSE(SAP_Speadsheet!$E$62:$BL$62))} -> 0 | G15: {=SUMPRODUCT(G$55:G$114,TRANSPOSE(SAP_Speadsheet!$E$62:$BL$62))} -> 0 | H15: {=SUMPRODUCT(H$55:H$114,TRANSPOSE(SAP_Speadsheet!$E$62:$BL$62))} -> #REF! | I15: {=SUMPRODUCT(I$55:I$114,TRANSPOSE(SAP_Speadsheet!$E$62:$BL$62))} -> #REF! | ... BI15: {=SUMPRODUCT(BI$55:BI$114,TRANSPOSE(SAP_Speadsheet!$E$62:$BL$62))} -> #REF!
A16: Insurance fee | B16: {=SUMPRODUCT(B$55:B$114,TRANSPOSE(SAP_Speadsheet!$E$63:$BL$63))} -> 0 | C16: {=SUMPRODUCT(C$55:C$114,TRANSPOSE(SAP_Speadsheet!$E$63:$BL$63))} -> 0 | D16: {=SUMPRODUCT(D$55:D$114,TRANSPOSE(SAP_Speadsheet!$E$63:$BL$63))} -> 0 | E16: {=SUMPRODUCT(E$55:E$114,TRANSPOSE(SAP_Speadsheet!$E$63:$BL$63))} -> 0 | F16: {=SUMPRODUCT(F$55:F$114,TRANSPOSE(SAP_Speadsheet!$E$63:$BL$63))} -> 0 | G16: {=SUMPRODUCT(G$55:G$114,TRANSPOSE(SAP_Speadsheet!$E$63:$BL$63))} -> 0 | H16: {=SUMPRODUCT(H$55:H$114,TRANSPOSE(SAP_Speadsheet!$E$63:$BL$63))} -> #REF! | I16: {=SUMPRODUCT(I$55:I$114,TRANSPOSE(SAP_Speadsheet!$E$63:$BL$63))} -> #REF! | ... BI16: {=SUMPRODUCT(BI$55:BI$114,TRANSPOSE(SAP_Speadsheet!$E$63:$BL$63))} -> #REF!
A17: Support fee | B17: {=SUMPRODUCT(B$55:B$114,TRANSPOSE(SAP_Speadsheet!$E$64:$BL$64))} -> 0 | C17: {=SUMPRODUCT(C$55:C$114,TRANSPOSE(SAP_Speadsheet!$E$64:$BL$64))} -> 0 | D17: {=SUMPRODUCT(D$55:D$114,TRANSPOSE(SAP_Speadsheet!$E$64:$BL$64))} -> 0 | E17: {=SUMPRODUCT(E$55:E$114,TRANSPOSE(SAP_Speadsheet!$E$64:$BL$64))} -> 0 | F17: {=SUMPRODUCT(F$55:F$114,TRANSPOSE(SAP_Speadsheet!$E$64:$BL$64))} -> 0 | G17: {=SUMPRODUCT(G$55:G$114,TRANSPOSE(SAP_Speadsheet!$E$64:$BL$64))} -> 0 | H17: {=SUMPRODUCT(H$55:H$114,TRANSPOSE(SAP_Speadsheet!$E$64:$BL$64))} -> #REF! | I17: {=SUMPRODUCT(I$55:I$114,TRANSPOSE(SAP_Speadsheet!$E$64:$BL$64))} -> #REF! | ... BI17: {=SUMPRODUCT(BI$55:BI$114,TRANSPOSE(SAP_Speadsheet!$E$64:$BL$64))} -> #REF!
