Workbook
Name __S1: {"Book1"}
Name __S1: {"Book1"}
Name _a1: {"'Sheet1'!$L$16"}
Name _a1: {"'Sheet1'!$L$16"}
Name _S1: {"Book1"}
Name _S1: {"Book1"}
Name Ă: #REF!
Name Ạ196: #REF!
Name â259: #REF!
Name â312: #REF!
Name Acquisition_PlanA: #REF!
Name Acquisition_PlanB: #REF!
Name Actual: (PeriodInActual*(#REF!>0))*PeriodInPlan
Name ActualBeyond: PeriodInActual*(#REF!>0)
Name adf: #REF!
Name AdvIncQ12020: #REF!
Name AdvIncQ12021: #REF!
Name AdvIncQ12022: #REF!
Name AdvIncQ12023: #REF!
Name AdvIncQ12024: #REF!
Name AdvIncQ22020: #REF!
Name AdvIncQ22021: #REF!
Name AdvIncQ22022: #REF!
Name AdvIncQ22023: #REF!
Name AdvIncQ22024: #REF!
Name AdvIncQ32020: #REF!
Name AdvIncQ32021: #REF!
Name AdvIncQ32022: #REF!
Name AdvIncQ32023: #REF!
Name AdvIncQ32024: #REF!
Name AdvIncQ42020: #REF!
Name AdvIncQ42021: #REF!
Name AdvIncQ42022: #REF!
Name AdvIncQ42023: #REF!
Name AdvIncQ42024: #REF!
Name AdvPenRate2020: #REF!
Name AdvPenRate2021: #REF!
Name AdvPenRate2022: #REF!
Name AdvPenRate2023: #REF!
Name AdvPenRate2024: #REF!
Name AllReportList: #REF!
Name Amount_act: #REF!
Name Amount_CF: #REF!
Name Amount_F: #REF!
Name Amount_KPI_act: #REF!
Name approval: #REF!
Name Attribute_F: #REF!
Name B: #REF!
Name b2bSpr: #REF!
Name BaoHanhSuaChua: #REF!
Name be_KPI_bud: #REF!
Name be2B: #REF!
Name bf: #REF!
Name BieuPhi: #REF!
Name BrMarQ12020: #REF!
Name BrMarQ12021: #REF!
Name BrMarQ12022: #REF!
Name BrMarQ12023: #REF!
Name BrMarQ12024: #REF!
Name BrMarQ22020: #REF!

Sheet Data input
B2: DATE: | C2: 20260121
B3: PIC: | C3: HKN
B5: 1. Approval rate
B7: Approval rate | D7: 0.06642
B8: Issue rate | D8: =16862/23010 -> 0.73281182
B20: 2. Spending
F21: Total | I21: Sum of VND | J21: Column Labels
F22: =GETPIVOTDATA("VND",$I$21)+GETPIVOTDATA("<>VND",$I$37)-GETPIVOTDATA("VND",$I$21,"NAME_OPERATION_SUB_TYPE","On Us Billing") -> 2837771483271 | G22: Loại US billing | I22: Row Labels | J22: ATM | K22: On Us Billing | L22: Purchase ECOM | M22: Purchase POS | N22: Grand Total
C23: %International cash advance | I23: Oct | J23: 47611021040 | L23: 163520074913 | M23: 675071579227 | N23: 886202675180
C24: % Domestics cash advance | D24: =F24/$F$22 -> 0.057421974 | F24: =GETPIVOTDATA("VND",$I$21,"NAME_OPERATION_SUB_TYPE","ATM")+GETPIVOTDATA("<>VND",$I$37,"NAME_OPERATION_SUB_TYPE","ATM") -> 162950439187 | I24: Nov | J24: 54476257011 | L24: 185908871652 | M24: 633793294165 | N24: 874178422828
C25: % Retail spend | D25: =F25/$F$22 -> 0.9288336 | F25: =GETPIVOTDATA("VND",$I$21,"NAME_OPERATION_SUB_TYPE","Purchase ECOM")+GETPIVOTDATA("VND",$I$21,"NAME_OPERATION_SUB_TYPE","Purchase POS") -> 2635817497087 | I25: Dec | J25: 60209091649 | K25: 157982100358 | L25: 177485241597 | M25: 800038435533 | N25: 1195714869137
C26: % International spend | D26: =F26/$F$22 -> 0.013744428 | F26: =GETPIVOTDATA("<>VND",$I$37,"NAME_OPERATION_SUB_TYPE","Purchase ECOM")+GETPIVOTDATA("<>VND",$I$37,"NAME_OPERATION_SUB_TYPE","Purchase POS") -> 39003546997 | I26: Grand Total | J26: 162296369700 | K26: 157982100358 | L26: 526914188162 | M26: 2108903308925 | N26: 2956095967145
I37: Sum of <>VND | J37: Column Labels
I38: Row Labels | J38: ATM | K38: On Us Billing | L38: Purchase ECOM | M38: Purchase POS | N38: Grand Total
I39: Oct | J39: 158181800 | L39: 8771529008 | M39: 602392385 | N39: 9532103193
I40: Nov | J40: 240470987 | L40: 11868537947 | M40: 572935184 | N40: 12681944118
I41: Dec | J41: 255416700 | K41: 0 | L41: 16601224731 | M41: 586927742 | N41: 17443569173
I42: Grand Total | J42: 654069487 | K42: 0 | L42: 37241291686 | M42: 1762255311 | N42: 39657616484
B58: 3. Attrition &Active | I58: Sum of % Active card | J58: Column Labels
I59: Row Labels | J59: 0 | K59: 1 | L59: 2 | M59: 3 | N59: 4 | O59: 5 | P59: 6 | Q59: 7 | R59: 8 | S59: 9 | T59: 10 | U59: 11 | V59: 12 | W59: 13 | X59: 14 | Y59: 15 | Z59: 16 | AA59: 17 | AB59: 18 | AC59: 19 | AD59: 20 | AE59: 21 | AF59: 22 | AG59: 23 | AH59: 24 | AI59: 25 | AJ59: 26 | AK59: 27 | AL59: 28 | AM59: 29 | AN59: 30 | AO59: 31 | AP59: 32 | AQ59: 33 | AR59: 34 | AS59: 35 | AT59: 36 | AU59: 37 | AV59: 38 | AW59: 39 | AX59: 40 | AY59: 41
I60: 44774 | J60: 1 | K60: 1 | L60: 1 | M60: 1 | N60: 1 | O60: 1 | P60: 1 | Q60: 1 | R60: 1 | S60: 1 | T60: 1 | U60: 1 | V60: 1 | W60: 1 | X60: 1 | Y60: 0.97619048 | Z60: 0.96428571 | AA60: 0.96428571 | AB60: 0.96428571 | AC60: 0.96428571 | AD60: 0.95238095 | AE60: 0.95238095 | AF60: 0.94047619 | AG60: 0.94047619 | AH60: 0.94047619 | AI60: 0.94047619 | AJ60: 0.94047619 | AK60: 0.94047619 | AL60: 0.92857143 | AM60: 0.88095238 | AN60: 0.86904762 | AO60: 0.86904762 | AP60: 0.86904762 | AQ60: 0.75 | AR60: 0.67857143 | AS60: 0.67857143 | AT60: 0.67857143 | AU60: 0.6547619 | AV60: 0.64285714 | AW60: 0.64285714 | AX60: 0.64285714 | AY60: 0.63095238
C61: 1 | I61: 44805 | J61: 1 | K61: 1 | L61: 1 | M61: 1 | N61: 1 | O61: 1 | P61: 1 | Q61: 1 | R61: 1 | S61: 1 | T61: 0.99932318 | U61: 0.99864636 | V61: 0.99763113 | W61: 0.99695431 | X61: 0.97563452 | Y61: 0.94077834 | Z61: 0.93637902 | AA61: 0.9319797 | AB61: 0.93028765 | AC61: 0.92724196 | AD61: 0.92318105 | AE61: 0.91708968 | AF61: 0.91336717 | AG61: 0.83553299 | AH61: 0.83147208 | AI61: 0.81725888 | AJ61: 0.8108291 | AK61: 0.79695431 | AL61: 0.74010152 | AM61: 0.69103215 | AN61: 0.65786802 | AO61: 0.6463621 | AP61: 0.64162437 | AQ61: 0.61759729 | AR61: 0.60338409 | AS61: 0.59323181 | AT61: 0.58443316 | AU61: 0.57123519 | AV61: 0.55296108 | AW61: 0.53062606 | AX61: 0.52182741
C62: 0.013 | D62: 0.013 | E62: 0.01 | F62: 0.01 | G62: 0.01 | I62: 44835 | J62: 1 | K62: 1 | L62: 1 | M62: 1 | N62: 1 | O62: 1 | P62: 1 | Q62: 1 | R62: 1 | S62: 0.99899783 | T62: 0.9988308 | U62: 0.99849674 | V62: 0.99816269 | W62: 0.97678303 | X62: 0.94721897 | Y62: 0.94354435 | Z62: 0.93986972 | AA62: 0.9368632 | AB62: 0.93535995 | AC62: 0.93151829 | AD62: 0.92734258 | AE62: 0.92533823 | AF62: 0.78570236 | AG62: 0.78269584 | AH62: 0.76499081 | AI62: 0.75663939 | AJ62: 0.74277601 | AK62: 0.69149825 | AL62: 0.64589945 | AM62: 0.61115751 | AN62: 0.59428762 | AO62: 0.58810757 | AP62: 0.56739602 | AQ62: 0.5590446 | AR62: 0.55052614 | AS62: 0.54217471 | AT62: 0.52998163 | AU62: 0.51895774 | AV62: 0.5064306 | AW62: 0.48972774
C63: 0.02 | D63: 0.018 | E63: 0.017 | F63: 0.015 | G63: 0.015 | I63: 44866 | J63: 1 | K63: 1 | L63: 1 | M63: 1 | N63: 1 | O63: 1 | P63: 1 | Q63: 1 | R63: 0.99926668 | S63: 0.9991852 | T63: 0.99885928 | U63: 0.99845189 | V63: 0.97979304 | W63: 0.95852685 | X63: 0.95486026 | Y63: 0.95160108 | Z63: 0.94915669 | AA63: 0.94769005 | AB63: 0.94443086 | AC63: 0.94198647 | AD63: 0.93962356 | AE63: 0.69306608 | AF63: 0.69176241 | AG63: 0.66666667 | AH63: 0.65884462 | AI63: 0.64189685 | AJ63: 0.60327548 | AK63: 0.56937994 | AL63: 0.5306771 | AM63: 0.51649963 | AN63: 0.5110405 | AO63: 0.49604824 | AP63: 0.48969282 | AQ63: 0.48244113 | AR63: 0.47795975 | AS63: 0.4665526 | AT63: 0.45897499 | AU63: 0.45115294 | AV63: 0.43664956
I64: 44896 | J64: 1 | K64: 1 | L64: 1 | M64: 1 | N64: 1 | O64: 1 | P64: 1 | Q64: 0.9993195 | R64: 0.99846887 | S64: 0.99846887 | T64: 0.99812862 | U64: 0.98213678 | V64: 0.95951004 | W64: 0.95610752 | X64: 0.95423613 | Y64: 0.95219462 | Z64: 0.95049337 | AA64: 0.94709085 | AB64: 0.94334808 | AC64: 0.94113644 | AD64: 0.72303505 | AE64: 0.72167404 | AF64: 0.69037087 | AG64: 0.68084382 | AH64: 0.66212998 | AI64: 0.62861518 | AJ64: 0.59714188 | AK64: 0.55103777 | AL64: 0.53793807 | AM64: 0.53096291 | AN64: 0.51701259 | AO64: 0.50867642 | AP64: 0.49183396 | AQ64: 0.48451854 | AR64: 0.47192923 | AS64: 0.46444369 | AT64: 0.45610752 | AU64: 0.44641034
I65: 44927 | J65: 1 | K65: 1 | L65: 1 | M65: 1 | N65: 1 | O65: 1 | P65: 0.99826255 | Q65: 0.99826255 | R65: 0.99826255 | S65: 0.99787645 | T65: 0.98030888 | U65: 0.95772201 | V65: 0.95444015 | W65: 0.9503861 | X65: 0.9469112 | Y65: 0.9453668 | Z65: 0.94208494 | AA65: 0.93899614 | AB65: 0.93706564 | AC65: 0.74227799 | AD65: 0.74169884 | AE65: 0.70791506 | AF65: 0.6969112 | AG65: 0.67606178 | AH65: 0.64343629 | AI65: 0.61660232 | AJ65: 0.57104247 | AK65: 0.5546332 | AL65: 0.54826255 | AM65: 0.53320463 | AN65: 0.52181467 | AO65: 0.5011583 | AP65: 0.4953668 | AQ65: 0.48127413 | AR65: 0.47451737 | AS65: 0.46679537 | AT65: 0.45849421
I66: 44958 | J66: 1 | K66: 1 | L66: 1 | M66: 1 | N66: 1 | O66: 0.99894375 | P66: 0.99841563 | Q66: 0.99841563 | R66: 0.99841563 | S66: 0.98547663 | T66: 0.96012675 | U66: 0.95405334 | V66: 0.95088461 | W66: 0.94718775 | X66: 0.94454713 | Y66: 0.93926591 | Z66: 0.93372062 | AA66: 0.93108001 | AB66: 0.80380248 | AC66: 0.80195405 | AD66: 0.77766042 | AE66: 0.76841827 | AF66: 0.75125429 | AG66: 0.71296541 | AH66: 0.67995775 | AI66: 0.62978611 | AJ66: 0.61156588 | AK66: 0.60337998 | AL66: 0.5848957 | AM66: 0.57037233 | AN66: 0.54634275 | AO66: 0.53630842 | AP66: 0.52336942 | AQ66: 0.5146554 | AR66: 0.50673356 | AS66: 0.49485081
I67: 44986 | J67: 1 | K67: 1 | L67: 1 | M67: 1 | N67: 0.99955457 | O67: 0.99910913 | P67: 0.99888641 | Q67: 0.99844098 | R67: 0.99175947 | S67: 0.96258352 | T67: 0.95812918 | U67: 0.9518931 | V67: 0.94832962 | W67: 0.94498886 | X67: 0.9376392 | Y67: 0.93385301 | Z67: 0.93006682 | AA67: 0.83340757 | AB67: 0.82939866 | AC67: 0.79265033 | AD67: 0.78708241 | AE67: 0.76302895 | AF67: 0.71893096 | AG67: 0.69109131 | AH67: 0.63719376 | AI67: 0.61915367 | AJ67: 0.61180401 | AK67: 0.59242762 | AL67: 0.5830735 | AM67: 0.55746102 | AN67: 0.54788419 | AO67: 0.53340757 | AP67: 0.52405345 | AQ67: 0.51625835 | AR67: 0.50757238
I68: 45017 | J68: 1 | K68: 1 | L68: 1 | M68: 0.99963912 | N68: 0.99927824 | O68: 0.99855648 | P68: 0.99783472 | Q68: 0.99747384 | R68: 0.96174666 | S68: 0.95705521 | T68: 0.95128113 | U68: 0.9480332 | V68: 0.94370263 | W68: 0.93720678 | X68: 0.93359798 | Y68: 0.93107182 | Z68: 0.84843017 | AA68: 0.84662577 | AB68: 0.81162035 | AC68: 0.80043306 | AD68: 0.7773367 | AE68: 0.73583544 | AF68: 0.70732588 | AG68: 0.64633706 | AH68: 0.62973656 | AI68: 0.62071454 | AJ68: 0.59328762 | AK68: 0.57524359 | AL68: 0.55178636 | AM68: 0.5398773 | AN68: 0.52832912 | AO68: 0.51425478 | AP68: 0.50559365 | AQ68: 0.49224107
I69: 45047 | J69: 1 | K69: 1 | L69: 1 | M69: 1 | N69: 1 | O69: 1 | P69: 0.99955821 | Q69: 0.96929534 | R69: 0.96465651 | S69: 0.95957588 | T69: 0.95515794 | U69: 0.95272808 | V69: 0.94610117 | W69: 0.94035785 | X69: 0.9368235 | Y69: 0.89860835 | Z69: 0.89374862 | AA69: 0.83543185 | AB69: 0.8182019 | AC69: 0.79412414 | AD69: 0.74906119 | AE69: 0.71636846 | AF69: 0.66379501 | AG69: 0.64126353 | AH69: 0.63419483 | AI69: 0.61011708 | AJ69: 0.5946543 | AK69: 0.57079744 | AL69: 0.55864811 | AM69: 0.54163905 | AN69: 0.5314778 | AO69: 0.52264193 | AP69: 0.51137619
I70: 45078 | J70: 1 | K70: 1 | L70: 1 | M70: 1 | N70: 1 | O70: 0.99807591 | P70: 0.97551163 | Q70: 0.97008921 | R70: 0.9648417 | S70: 0.96081861 | T70: 0.95871961 | U70: 0.95294735 | V70: 0.94630051 | W70: 0.94175267 | X70: 0.91743922 | Y70: 0.91446563 | Z70: 0.86548889 | AA70: 0.85114571 | AB70: 0.82158475 | AC70: 0.77033409 | AD70: 0.73535071 | AE70: 0.68392514 | AF70: 0.66363477 | AG70: 0.6566381 | AH70: 0.63127514 | AI70: 0.61938079 | AJ70: 0.59594193 | AK70: 0.57827532 | AL70: 0.55920938 | AM70: 0.54748994 | AN70: 0.53647018 | AO70: 0.52475074
I71: 45108 | J71: 1 | K71: 1 | L71: 1 | M71: 0.99937441 | N71: 0.99843603 | O71: 0.98091961 | P71: 0.9766969 | Q71: 0.97153581 | R71: 0.9677823 | S71: 0.96621833 | T71: 0.9583985 | U71: 0.9535502 | V71: 0.95042227 | W71: 0.9307163 | X71: 0.9257116 | Y71: 0.89881139 | Z71: 0.8705036 | AA71: 0.83468877 | AB71: 0.78589302 | AC71: 0.74569909 | AD71: 0.69080388 | AE71: 0.67328746 | AF71: 0.6665624 | AG71: 0.63950579 | AH71: 0.63027839 | AI71: 0.61307476 | AJ71: 0.59493275 | AK71: 0.56803253 | AL71: 0.55317485 | AM71: 0.54285267 | AN71: 0.52815139
I72: 45139 | J72: 1 | K72: 1 | L72: 1 | M72: 0.99979335 | N72: 0.98388097 | O72: 0.97933457 | P72: 0.97354825 | Q72: 0.96817524 | R72: 0.9661087 | S72: 0.96094234 | T72: 0.9561893 | U72: 0.95288283 | V72: 0.93655714 | W72: 0.93139078 | X72: 0.92085142 | Y72: 0.90659227 | Z72: 0.86278157 | AA72: 0.81773094 | AB72: 0.78280636 | AC72: 0.72039678 | AD72: 0.6972515 | AE72: 0.68629882 | AF72: 0.66191362 | AG72: 0.64951436 | AH72: 0.63752841 | AI72: 0.62182269 | AJ72: 0.58751808 | AK72: 0.56519942 | AL72: 0.5494937 | AM72: 0.53647448
I73: 45170 | J73: 1 | K73: 1 | L73: 1 | M73: 0.99114353 | N73: 0.98619432 | O73: 0.97916124 | P73: 0.97447252 | Q73: 0.97212816 | R73: 0.96613701 | S73: 0.96275072 | T73: 0.95884345 | U73: 0.94946601 | V73: 0.94399583 | W73: 0.932795 | X73: 0.92914822 | Y73: 0.89163845 | Z73: 0.84579318 | AA73: 0.80854389 | AB73: 0.73482678 | AC73: 0.71190414 | AD73: 0.69992185 | AE73: 0.67283147 | AF73: 0.6621516 | AG73: 0.64990883 | AH73: 0.63948945 | AI73: 0.61891117 | AJ73: 0.5949466 | AK73: 0.57098203 | AL73: 0.55405053
I74: 45200 | J74: 1 | K74: 1 | L74: 0.9971223 | M74: 0.98581706 | N74: 0.97410072 | O74: 0.96361768 | P74: 0.95662898 | Q74: 0.94964029 | R74: 0.94265159 | S74: 0.9385406 | T74: 0.92887975 | U74: 0.92250771 | V74: 0.90935252 | W74: 0.90071942 | X74: 0.87687564 | Y74: 0.83843782 | Z74: 0.79177801 | AA74: 0.71181912 | AB74: 0.69516958 | AC74: 0.68591984 | AD74: 0.65734841 | AE74: 0.64892086 | AF74: 0.63782117 | AG74: 0.62651593 | AH74: 0.6049332 | AI74: 0.58890031 | AJ74: 0.56443988 | AK74: 0.54059609
I75: 45231 | J75: 1 | K75: 1 | L75: 0.99750872 | M75: 0.98181365 | N75: 0.96138515 | O75: 0.9529148 | P75: 0.93796712 | Q75: 0.92700548 | R75: 0.92127554 | S75: 0.91155954 | T75: 0.90607872 | U75: 0.89486796 | V75: 0.88863976 | W75: 0.87668161 | X75: 0.84155456 | Y75: 0.79870453 | Z75: 0.70976582 | AA75: 0.68809168 | AB75: 0.68011958 | AC75: 0.65470852 | AD75: 0.64125561 | AE75: 0.62730443 | AF75: 0.61484803 | AG75: 0.59566517 | AH75: 0.58121574 | AI75: 0.56601893 | AJ75: 0.53936223
I76: 45261 | J76: 0.99973205 | K76: 0.99973205 | L76: 0.99732047 | M76: 0.98606645 | N76: 0.97642015 | O76: 0.96436227 | P76: 0.95819936 | Q76: 0.95230439 | R76: 0.9482851 | S76: 0.94185423 | T76: 0.93569132 | U76: 0.92845659 | V76: 0.91666667 | W76: 0.89576635 | X76: 0.87057878 | Y76: 0.79930332 | Z76: 0.78054662 | AA76: 0.77009646 | AB76: 0.74732047 | AC76: 0.73633441 | AD76: 0.71543408 | AE76: 0.69506967 | AF76: 0.67202572 | AG76: 0.65541265 | AH76: 0.63987138 | AI76: 0.61682744
I77: 45292 | J77: 1 | K77: 1 | L77: 0.99615855 | M77: 0.98952331 | N77: 0.97520517 | O77: 0.96560154 | P77: 0.9573948 | Q77: 0.95180723 | R77: 0.94726733 | S77: 0.94098132 | T77: 0.93626681 | U77: 0.92683779 | V77: 0.90326523 | W77: 0.89418544 | X77: 0.81089576 | Y77: 0.78610093 | Z77: 0.77649729 | AA77: 0.7553693 | AB77: 0.744718 | AC77: 0.72655841 | AD77: 0.71189104 | AE77: 0.6884931 | AF77: 0.67190501 | AG77: 0.65793609 | AH77: 0.63872883
I78: 45323 | J78: 1 | K78: 1 | L78: 0.99722553 | M78: 0.98711851 | N78: 0.97661514 | O78: 0.96868807 | P78: 0.96353547 | Q78: 0.95897741 | R78: 0.95402299 | S78: 0.94986128 | T78: 0.94252874 | U78: 0.924891 | V78: 0.91478399 | W78: 0.81906461 | X78: 0.7849782 | Y78: 0.77011494 | Z78: 0.74098296 | AA78: 0.73087594 | AB78: 0.70630202 | AC78: 0.6876734 | AD78: 0.6595323 | AE78: 0.64466904 | AF78: 0.63040032 | AG78: 0.6169243
I79: 45352 | J79: 1 | K79: 1 | L79: 0.9954 | M79: 0.9858 | N79: 0.9732 | O79: 0.9664 | P79: 0.9618 | Q79: 0.9562 | R79: 0.952 | S79: 0.9468 | T79: 0.9212 | U79: 0.9084 | V79: 0.8386 | W79: 0.8092 | X79: 0.7928 | Y79: 0.756 | Z79: 0.7426 | AA79: 0.7196 | AB79: 0.7008 | AC79: 0.6728 | AD79: 0.652 | AE79: 0.6384 | AF79: 0.615
...

Sheet NOTE
A1: SAP MODEL - CREDIT CARD
N2: KHN | O2: v9 | P2: 20251101
B3: 1. Notes and disclaimer
C4: a. Giới thiệu về SAP
D5: - SAP: Single Account Profitability (Hiệu quả sản phẩm trên từng đơn vị sản phẩm)
D6: - Model SAP được sử dụng như 1 mô hình dự đoán hiệu quả vòng đời của sản phẩm.
D7: - Do sự phức tạp của sản phẩm, các hệ thống vận hành (hệ thống hạch kế toán, hệ thống quản trị rủi ro, hệ thống quản trị…), hành vi người sử dụng hành vi người sử dụng, model chỉ có thể mô phỏng tương đối trung bình vòng đời của sản phẩm.
D8: - Mô hình được tính toán dựa vào các yếu tố đầu vào xác định tại thời điểm, do đó kết quả của mô hình có thể có sự khác biệt so với thực tế vận hành sản phẩm.
D9: - Mô hình SAP Credit Card này được tính trên hiệu quả của 1 thẻ mở và được cutoff tại thời điểm 5 năm ( 60 tháng) kể từ ngày bắt đầu sản phẩm. Trường hợp sử dụng phương pháp tính dự phòng VAS, cần ghi nhận thêm chi phí dự phòng năm thứ 6 liên quan tới hiệu quả sản phẩm thẻ 5 năm.
C11: b. Giới thiệu về PnL
D12: - Trong file tính này, Profit & Lost (PnL) được dự phóng từ trung bình cộng kết quả kinh doanh trên từng sản phẩm (SAP) với yếu tố "sale plan" (số thẻ mở mới) qua từng tháng, do đó có thể khác biệt so với kết quả thực tế vận hành.
D13: - Dòng tiền thực tế qua từng tháng có thể khác biệt với mô hình tính toán do nhiều yếu tố tác động bên ngoài thay đổi, do đó, vui lòng chỉ sử dụng mô hình cho mục đích tham khảo.
D14: - Cho mục đích tính dự phòng dòng tiền ngắn và trung hạn, mô hình PnL được cutoff tại thời điểm 5 năm (60 tháng) kể từ ngày bắt đầu thẻ đầu tiên được mở.
B16: 2. Instruction
D17: - Cấu trúc file:
D18: NOTE | E18: Cung cấp các thông tin về file tính, lưu ý, định nghĩa sử dụng,…
D19: SAP_Leadsheet | E19: Các chỉ số và kết quả model SAP
D20: SAP_Speadsheet | E20: Các công thức tính SAP
D21: Sales plan & PL | E21: Số lượng thẻ mở và kết quả dự kiến
D22: PL projection speadsheet | E22: Các công thức tính PL
D24: - Dành cho người sử dụng
E25: - Chỉ chỉnh sửa vào các ô màu vàng
E26: - 2 sheets "SAP_Leadsheet" và "Sale plan&PL" cung cấp yếu tố đầu vào và đầu ra để tính toán mô hình SAP cũng như PnL.
F27: - Sheet SAP_Leadsheet được cấu trúc 2 phần, bên trái là các yếu tố đầu vào (input) và bên phải là kết quả dự đoán (output). Đơn vị sử dụng tại bảng tính là triệu VND (mVND) và phần trăm (%)
F28: - Sheet "Sale plan & PL" được cấu trúc 2 phần, bên trên là sale plan và bên dưới là kết quả PnL
E29: - 2 sheets "SAP_Spreadsheet" và "PL projection speadsheet" là các file tính toán cho 2 sheet "SAP_Leadsheet", "Sales plan & PL"
F30: - 2 sheets được cấu trúc từ trên xuống dưới theo thứ tự tính toán mô phỏng để đưa ra kết quả kinh doanh cuối cùng
F31: - 2 sheets đã được tạm khóa. Trường hợp cần mở khóa, điều chỉnh các yếu tố, vui lòng liên hệ với nhóm vận hành để được hỗ trợ.
D33: - Dành riêng cho người vận hành, hiệu chỉnh
E34: - Cần cẩn trọng khi điều chỉnh ở các file "speadsheet" vì 1 khi sai lệch rất khó tìm ra lỗi (VD: sửa nhầm ô, link nhầm vị trí,…)
B37: 3. Legend
C39: REVENUE INPUT
C41: Card Status
D42: %Activation rate | E42: Tỉ lệ activate thẻ | G42: Lấy activated rate tại tháng 1
D43: Normal attrition rate (others)/cohort | E43: Trung bình tỉ lệ rời bỏ thẻ | G43: Lấy trung bình tỉ lệ rời bỏ thẻ của các tháng (tính theo cohort)
D44: Seasonal attrition rate (month12-24,36,…)/cohort | E44: Tỉ lệ rời bỏ thẻ của các tháng đặc biệt (VD các tháng cuối năm) | G44: Lấy trung bình tỉ lệ rời bỏ thẻ của các tháng (tính theo cohort)
C46: Usage Status
D47: %International cash advance | E47: Tỉ lệ rút tiền mặt quốc tế/ tổng chi tiêu
D48: % Domestics cash advance | E48: Tỉ lệ rút tiền mặt nội địa/ tổng chi tiêu
D49: % Retail spend | E49: Tỉ lệ thanh toán nội địa qua pos,online/tổng chi tiêu
...

Sheet SAP_Leadsheet
B1: SAP MODEL - CREDIT CARD
B2: Leadsheet | C2: =NOTE!O2 -> v9
B3: KHN | C3: =NOTE!P2 -> 20251101
B5: Select model type | G5: NOTE
B6: Write off | C6: DPD180+ | D6: không dùng DPD180 với IFRS | G6: Please read carefully before using model
B7: Provision | C7: IFRS | H7: Disclaimer
B8: Card type | C8: ALL | H8: Instruction
B9: Chanel | C9: ALL | H9: Legend
B10: EMI mode | C10: EMI
B11: Customer type | C11: All | D11: Chưa test xong hiệu quả, ko nên đổi ô này
B12: Quarter | C12: 2025
B14: REVENUE INPUT | K14: Cur: mVND, % | M14: SUMMARY OUTPUT | W14: Cur: mVND, %
O15: Lifetime 5 Years | P15: Year 1 | Q15: Year 2 | R15: Year 3 | S15: Year 4 | T15: Year 5 | U15: =IF(C7="VAS","Year 6","") | V15: % of ANR 5Y | W15: % Spending
E16: Year 1 | F16: Year 2 | G16: Year 3 | H16: Year 4 | I16: Year 5
M17: ANR | O17: =O46 -> 6.3975595 | P17: =P46 -> 9.1247955 | Q17: =Q46 -> 8.0077877 | R17: =R46 -> 6.3347125 | S17: =S46 -> 4.9761104 | T17: =T46 -> 3.5443913 | U17: =U46 -> 0
B18: Card Status | C18: %Activation rate | E18: 0.99 | M18: Spending | O18: =O47 -> 210.77358 | P18: =P47 -> 63.962944 | Q18: =Q47 -> 51.496889 | R18: =R47 -> 40.698869 | S18: =S47 -> 31.728025 | T18: =T47 -> 22.886852
C19: Normal attrition rate (others)/cohort | E19: 0.013 | F19: 0.014 | G19: 0.01 | H19: 0.01 | I19: 0.01 | M19: TOI | O19: =O48 -> 6.5739424 | P19: =P48 -> 1.973176 | Q19: =Q48 -> 1.5624843 | R19: =R48 -> 1.2501523 | S19: =S48 -> 1.0225009 | T19: =T48 -> 0.76562904 | U19: =U48 -> 0 | V19: =O19/$O$46/60*12 -> 0.20551407 | W19: =O19/$O$18 -> 0.031189594
C20: Seasonal attrition rate (month12-24,36,…)/cohort | E20: 0.027 | F20: 0.025 | G20: 0.017 | H20: 0.015 | I20: 0.015 | M20: Net interest income | O20: =O49 -> 3.951425 | P20: =P49 -> 1.0539614 | Q20: =Q49 -> 0.96121531 | R20: =R49 -> 0.77487769 | S20: =S49 -> 0.64377475 | T20: =T49 -> 0.5175958 | U20: =U49 -> 0 | V20: =V49 -> 0.12352914 | W20: =W49 -> 0.01874725
M21: Net fee income | O21: =O52 -> 2.6225175 | P21: =P52 -> 0.91921454 | Q21: =Q52 -> 0.60126894 | R21: =R52 -> 0.47527458 | S21: =S52 -> 0.37872615 | T21: =T52 -> 0.24803324 | U21: =U52 -> 0 | V21: =V52 -> 0.081984934 | W21: =W52 -> 0.012442344
B22: Usage Status | C22: %International cash advance | E22: 0 | M22: Other income | O22: =O70 -> 0 | P22: =P70 -> 0 | Q22: =Q70 -> 0 | R22: =R70 -> 0 | S22: =S70 -> 0 | T22: =T70 -> 0 | U22: =U70 -> 0 | V22: =O22/$O$46/60*12 -> 0 | W22: =O22/$O$18 -> 0
C23: % Domestics cash advance | E23: 0.033 | M23: Provision cost | O23: =O71 -> -4.5992838 | P23: =P71 -> -1.6341193 | Q23: =Q71 -> -1.2327601 | R23: =R71 -> -0.91091959 | S23: =S71 -> -0.53588578 | T23: =T71 -> -0.28559898 | U23: =U71 -> 0 | V23: =O23/$O$46/60*12 -> -0.14378245 | W23: =O23/$O$18 -> -0.021820969
C24: % Retail spend | E24: =1-E23-E25 -> 0.917 | M24: Variable Cost | O24: =SUM(O25:O30) -> -0.81265577 | P24: =SUM(P25:P30) -> -0.54600186 | Q24: =SUM(Q25:Q30) -> -0.093267733 | R24: =SUM(R25:R30) -> -0.073877427 | S24: =SUM(S25:S30) -> -0.05774102 | T24: =SUM(T25:T30) -> -0.041767733 | U24: =SUM(U25:U30) -> 0 | V24: =SUM(V25:V30) -> -0.025405181 | W24: =SUM(W25:W30) -> -0.0038555865
C25: % International spend | E25: 0.05 | M25: Sales & Marketing | O25: =O73 -> -0.2218681 | P25: =P73 -> -0.2218681 | Q25: =Q73 -> 0 | R25: =R73 -> 0 | S25: =S73 -> 0 | T25: =T73 -> 0 | U25: =U73 -> 0 | V25: =V73 -> -0.0069360229 | W25: =W73 -> -0.0010526371
M26: Marketing promotion | O26: =O79 -> -0.10605185 | P26: =P79 -> -0.032183296 | Q26: =Q79 -> -0.025910934 | R26: =R79 -> -0.020477853 | S26: =S79 -> -0.015964125 | T26: =T79 -> -0.011515641 | U26: =U79 -> 0 | V26: =V79 -> -0.0033153846 | W26: =W79 -> -0.00050315533
C27: Spd / activated card | E27: ='Data input'!C129 -> 5.8941158 | F27: =E27 -> 5.8941158 | G27: =F27 -> 5.8941158 | H27: =G27 -> 5.8941158 | I27: =H27 -> 5.8941158 | M27: Physical card | O27: =O80 -> -0.077466542 | P27: =P80 -> -0.077466542 | Q27: =Q80 -> 0 | R27: =R80 -> 0 | S27: =S80 -> 0 | T27: =T80 -> 0 | U27: =U80 -> 0 | V27: =V80 -> -0.0024217529 | W27: =W80 -> -0.00036753441
M28: UW & Disbursal cost | O28: =O81 -> -0.13112345 | P28: =P81 -> -0.13112345 | Q28: =Q81 -> 0 | R28: =R81 -> 0 | S28: =S81 -> 0 | T28: =T81 -> 0 | U28: =U81 -> 0 | V28: =V81 -> -0.0040991709 | W28: =W81 -> -0.00062210571
B29: Payment status | C29: Minimal Payment | E29: 0.05 | F29: perbalance | M29: Collection | O29: =O86 -> -0.25032 | P29: =P86 -> -0.075964 | Q29: =Q86 -> -0.061159 | R29: =R86 -> -0.048335 | S29: =S86 -> -0.037681 | T29: =T86 -> -0.027181 | U29: =U86 -> 0 | V29: =V86 -> -0.0078254841 | W29: =W86 -> -0.0011876251
C30: Due date | E30: 5 | F30: date of month | M30: After-sales services | O30: =O89 -> -0.025825832 | P30: =P89 -> -0.007396473 | Q30: =Q89 -> -0.0061977988 | R30: =R89 -> -0.0050645736 | S30: =S89 -> -0.0040958951 | T30: =T89 -> -0.0030710919 | U30: =U89 -> 0 | V30: =V89 -> -0.00080736513 | W30: =W89 -> -0.00012252879
M31: Overhead cost | O31: =O72-O24 -> -1.2661194 | P31: =P72-P24 -> -0.36261438 | Q31: =Q72-Q24 -> -0.303849 | R31: =R72-R24 -> -0.24829228 | S31: =S72-S24 -> -0.20080252 | T31: =T72-T24 -> -0.15056123 | U31: =U72-U24 -> 0 | V31: =O31/$O$46/60*12 -> -0.039581325 | W31: =O31/$O$18 -> -0.006007012
C32: Free-interest period | E32: 45 | F32: days | M32: PBT | O32: =O92 -> -0.10411658 | P32: =P92 -> -0.5695596 | Q32: =Q92 -> -0.067392621 | R32: =R92 -> 0.017062963 | S32: =S92 -> 0.22807158 | T32: =T92 -> 0.28770109 | U32: =U92 -> 0 | V32: =V92 -> -0.0032548843 | W32: =W92 -> -0.00049397358
C33: Port Revolving rate | E33: ='Data input'!C127 -> 0.53345835 | F33: per ANR T-1 (excl EMI, WO) | M33: In which: Profit before Overhead | O33: =O91 -> 1.1620028 | P33: =P91 -> -0.20694522 | Q33: =Q91 -> 0.23645638 | R33: =R91 -> 0.26535525 | S33: =S91 -> 0.4288741 | T33: =T91 -> 0.43826232 | U33: =U91 -> 0 | V33: =V91 -> 0.036326441 | W33: =W91 -> 0.0055130384
C34: Repayment rate | E34: ='Data input'!C128 -> 0.58765108 | F34: =E34 -> 0.58765108 | G34: =F34 -> 0.58765108 | H34: =G34 -> 0.58765108 | I34: =H34 -> 0.58765108
E35: per ANR T-1
B36: Pricing | C36: CII rate | E36: =G36*(E22+E23)+F36*(E24+E25) -> 0.45066 | F36: 0.45 | G36: 0.47
C37: COF rate | E37: =COF!E2 -> 0.058332905 | F37: 45%spending &47%cashadvance
B39: Customer fee | C39: Annual fee | E39: ='Data input'!C228 -> 0.48176123 | F39: per card/year | G39: Annual Fee waiver | I39: 0.1 | J39: per total port
C40: Quarterly fee | F40: per card/quarter | G40: Quarterly Fee waiver | J40: per total port
C41: Monthly fee | F41: per card/month | G41: Monthly Fee waiver | J41: per total port
M42: PERFORMANCE OUTPUT | W42: Cur: mVND, %
C43: Issuance fee | E43: ='Data input'!C243 -> 0.076251067 | F43: per physical card
...

Sheet COF
E2: =SUM(E14:E16)/SUM(D14:D16)*365 -> 0.058332905
D3: Sum of BALANCE | E3: Sum of Lai DCV
B4: 2024 | C4: Dec | D4: 2444137528275 | E4: 308028372
B5: 2025 | C5: Jan | D5: 25799219832926 | E5: 3251409022
C6: Feb | D6: 24126737449976 | E6: 3.0406303e+09
C7: Mar | D7: 26989267925200 | E7: 3.4013937e+09
C8: Apr | D8: 26311152949564 | E8: 3.3161159e+09
C9: May | D9: 30467974367402 | E9: 3.8414955e+09
C10: Jun | D10: 31627213733087 | E10: 4.0213174e+09
C11: Jul | D11: 34742233428138 | E11: 4.7800311e+09
C12: Aug | D12: 37358792399704 | E12: 5.4247014e+09
C13: Sep | D13: 38486365009052 | E13: 5.663474e+09
C14: Oct | D14: 41287758219971 | E14: 6.2669032e+09
C15: Nov | D15: 42266567885886 | E15: 6.3414532e+09
C16: Dec | D16: 42654955260854 | E16: 7.5619285e+09
B17: Grand Total | D17: 404562375990035 | E17: 5.7218881e+10

Sheet SAP_Spreadsheet
A1: Index!A1 | B1: SAP MODEL - CREDIT CARD | G1: =G677/G21 -> 0.091194757 | H1: =H677/H21 -> 0.0064729236 | I1: =I677/I21 -> 0.006470038 | J1: =J677/J21 -> 0.00633684 | K1: =K677/K21 -> 0.0061200761 | L1: =L677/L21 -> 0.0058973063 | M1: =M677/M21 -> 0.0057146858 | N1: =N677/N21 -> 0.0055666625 | ... BN1: =BN677/BN21 -> 0.00083766242
B2: WO model | D2: =SAP_Leadsheet!$C$6 -> DPD180+
B3: Provision model | D3: =SAP_Leadsheet!C7 -> IFRS
B4: Calendar | D4: =(30*4+31*7+28)/12 -> 30.416667
B5: Validation | D5: No | BO5: For VAS only
D6: Year | G6: =ROUNDUP(G7/12,0) -> 1 | H6: =ROUNDUP(H7/12,0) -> 1 | I6: =ROUNDUP(I7/12,0) -> 1 | J6: =ROUNDUP(J7/12,0) -> 1 | K6: =ROUNDUP(K7/12,0) -> 1 | L6: =ROUNDUP(L7/12,0) -> 1 | M6: =ROUNDUP(M7/12,0) -> 1 | N6: =ROUNDUP(N7/12,0) -> 1 | ... BZ6: =ROUNDUP(BZ7/12,0) -> 6
D7: Month | G7: 1 | H7: =G7+1 -> 2 | I7: =H7+1 -> 3 | J7: =I7+1 -> 4 | K7: =J7+1 -> 5 | L7: =K7+1 -> 6 | M7: =L7+1 -> 7 | N7: =M7+1 -> 8 | O7: =N7+1 -> 9 | ... BZ7: =BY7+1 -> 72
B9: CARD OPERATION
C11: Card Status | D11: Issued card | F11: # Card | G11: 1
D12: Activated card | F12: # Card | G12: =G11*SAP_Leadsheet!$E$18 -> 0.99
D13: Attrition rate | F13: % | G13: =IF(G$7=12,SAP_Leadsheet!$E$20,IF(G$7=24,SAP_Leadsheet!$F$20,IF(G$7=36,SAP_Leadsheet!$G$20,IF(G$7=48,SAP_Leadsheet!$H$20,IF(G$7=60,SAP_Leadsheet!$I$20,IF(G$7<12,SAP_Leadsheet!$E$19,IF(G$7<24,SAP_Leadsheet!$F$19,IF(G$7<36,SAP_Leadsheet!$G$19,IF(G$7<48,SAP_Leadsheet!$H$19,SAP_Leadsheet!$I$19))))))))) -> 0.013 | H13: =IF(H$7=12,SAP_Leadsheet!$E$20,IF(H$7=24,SAP_Leadsheet!$F$20,IF(H$7=36,SAP_Leadsheet!$G$20,IF(H$7=48,SAP_Leadsheet!$H$20,IF(H$7=60,SAP_Leadsheet!$I$20,IF(H$7<12,SAP_Leadsheet!$E$19,IF(H$7<24,SAP_Leadsheet!$F$19,IF(H$7<36,SAP_Leadsheet!$G$19,IF(H$7<48,SAP_Leadsheet!$H$19,SAP_Leadsheet!$I$19))))))))) -> 0.013 | I13: =IF(I$7=12,SAP_Leadsheet!$E$20,IF(I$7=24,SAP_Leadsheet!$F$20,IF(I$7=36,SAP_Leadsheet!$G$20,IF(I$7=48,SAP_Leadsheet!$H$20,IF(I$7=60,SAP_Leadsheet!$I$20,IF(I$7<12,SAP_Leadsheet!$E$19,IF(I$7<24,SAP_Leadsheet!$F$19,IF(I$7<36,SAP_Leadsheet!$G$19,IF(I$7<48,SAP_Leadsheet!$H$19,SAP_Leadsheet!$I$19))))))))) -> 0.013 | J13: =IF(J$7=12,SAP_Leadsheet!$E$20,IF(J$7=24,SAP_Leadsheet!$F$20,IF(J$7=36,SAP_Leadsheet!$G$20,IF(J$7=48,SAP_Leadsheet!$H$20,IF(J$7=60,SAP_Leadsheet!$I$20,IF(J$7<12,SAP_Leadsheet!$E$19,IF(J$7<24,SAP_Leadsheet!$F$19,IF(J$7<36,SAP_Leadsheet!$G$19,IF(J$7<48,SAP_Leadsheet!$H$19,SAP_Leadsheet!$I$19))))))))) -> 0.013 | K13: =IF(K$7=12,SAP_Leadsheet!$E$20,IF(K$7=24,SAP_Leadsheet!$F$20,IF(K$7=36,SAP_Leadsheet!$G$20,IF(K$7=48,SAP_Leadsheet!$H$20,IF(K$7=60,SAP_Leadsheet!$I$20,IF(K$7<12,SAP_Leadsheet!$E$19,IF(K$7<24,SAP_Leadsheet!$F$19,IF(K$7<36,SAP_Leadsheet!$G$19,IF(K$7<48,SAP_Leadsheet!$H$19,SAP_Leadsheet!$I$19))))))))) -> 0.013 | L13: =IF(L$7=12,SAP_Leadsheet!$E$20,IF(L$7=24,SAP_Leadsheet!$F$20,IF(L$7=36,SAP_Leadsheet!$G$20,IF(L$7=48,SAP_Leadsheet!$H$20,IF(L$7=60,SAP_Leadsheet!$I$20,IF(L$7<12,SAP_Leadsheet!$E$19,IF(L$7<24,SAP_Leadsheet!$F$19,IF(L$7<36,SAP_Leadsheet!$G$19,IF(L$7<48,SAP_Leadsheet!$H$19,SAP_Leadsheet!$I$19))))))))) -> 0.013 | M13: =IF(M$7=12,SAP_Leadsheet!$E$20,IF(M$7=24,SAP_Leadsheet!$F$20,IF(M$7=36,SAP_Leadsheet!$G$20,IF(M$7=48,SAP_Leadsheet!$H$20,IF(M$7=60,SAP_Leadsheet!$I$20,IF(M$7<12,SAP_Leadsheet!$E$19,IF(M$7<24,SAP_Leadsheet!$F$19,IF(M$7<36,SAP_Leadsheet!$G$19,IF(M$7<48,SAP_Leadsheet!$H$19,SAP_Leadsheet!$I$19))))))))) -> 0.013 | N13: =IF(N$7=12,SAP_Leadsheet!$E$20,IF(N$7=24,SAP_Leadsheet!$F$20,IF(N$7=36,SAP_Leadsheet!$G$20,IF(N$7=48,SAP_Leadsheet!$H$20,IF(N$7=60,SAP_Leadsheet!$I$20,IF(N$7<12,SAP_Leadsheet!$E$19,IF(N$7<24,SAP_Leadsheet!$F$19,IF(N$7<36,SAP_Leadsheet!$G$19,IF(N$7<48,SAP_Leadsheet!$H$19,SAP_Leadsheet!$I$19))))))))) -> 0.013 | ... BN13: =IF(BN$7=12,SAP_Leadsheet!$E$20,IF(BN$7=24,SAP_Leadsheet!$F$20,IF(BN$7=36,SAP_Leadsheet!$G$20,IF(BN$7=48,SAP_Leadsheet!$H$20,IF(BN$7=60,SAP_Leadsheet!$I$20,IF(BN$7<12,SAP_Leadsheet!$E$19,IF(BN$7<24,SAP_Leadsheet!$F$19,IF(BN$7<36,SAP_Leadsheet!$G$19,IF(BN$7<48,SAP_Leadsheet!$H$19,SAP_Leadsheet!$I$19))))))))) -> 0.015
C15: # Activated Card | D15: Beginning Bal | F15: # Card | G15: 0 | H15: =G18 -> 0.977 | I15: =H18 -> 0.964 | J15: =I18 -> 0.951 | K15: =J18 -> 0.938 | L15: =K18 -> 0.925 | M15: =L18 -> 0.912 | N15: =M18 -> 0.899 | O15: =N18 -> 0.886 | ... BN15: =BM18 -> 0.279
D16: Newly activated card | F16: # Card | G16: =G12 -> 0.99 | H16: 0 | I16: 0 | J16: 0 | K16: 0 | L16: 0 | M16: 0 | N16: 0 | O16: 0 | P16: 0 | Q16: 0 | R16: 0 | S16: 0 | T16: 0 | U16: 0 | V16: 0 | W16: 0 | X16: 0 | Y16: 0 | Z16: 0 | AA16: 0 | AB16: 0 | AC16: 0 | AD16: 0 | AE16: 0 | AF16: 0 | AG16: 0 | AH16: 0 | AI16: 0 | AJ16: 0 | AK16: 0 | AL16: 0 | AM16: 0 | AN16: 0 | AO16: 0 | AP16: 0 | AQ16: 0 | AR16: 0 | AS16: 0 | AT16: 0 | AU16: 0 | AV16: 0 | AW16: 0 | AX16: 0 | AY16: 0 | AZ16: 0 | BA16: 0 | BB16: 0 | BC16: 0 | BD16: 0 | BE16: 0 | BF16: 0 | BG16: 0 | BH16: 0 | BI16: 0 | BJ16: 0 | BK16: 0 | BL16: 0 | BM16: 0 | BN16: 0
D17: Attrition # | F17: # Card | G17: =G13 -> 0.013 | H17: =H13 -> 0.013 | I17: =I13 -> 0.013 | J17: =J13 -> 0.013 | K17: =K13 -> 0.013 | L17: =L13 -> 0.013 | M17: =M13 -> 0.013 | N17: =N13 -> 0.013 | ... BN17: =BN13 -> 0.015
D18: Ending Bal | F18: # Card | G18: =G15+G16-G17 -> 0.977 | H18: =H15+H16-H17 -> 0.964 | I18: =I15+I16-I17 -> 0.951 | J18: =J15+J16-J17 -> 0.938 | K18: =K15+K16-K17 -> 0.925 | L18: =L15+L16-L17 -> 0.912 | M18: =M15+M16-M17 -> 0.899 | N18: =N15+N16-N17 -> 0.886 | ... BN18: =BN15+BN16-BN17 -> 0.264
D19: Avg Card | F19: # Card | G19: =AVERAGE(G18:G18) -> 0.977 | H19: =AVERAGE(G18:H18) -> 0.9705 | I19: =AVERAGE(H18:I18) -> 0.9575 | J19: =AVERAGE(I18:J18) -> 0.9445 | K19: =AVERAGE(J18:K18) -> 0.9315 | L19: =AVERAGE(K18:L18) -> 0.9185 | M19: =AVERAGE(L18:M18) -> 0.9055 | N19: =AVERAGE(M18:N18) -> 0.8925 | O19: =AVERAGE(N18:O18) -> 0.8795 | ... BN19: =AVERAGE(BM18:BN18) -> 0.2715
C21: Spending status | D21: Spd per activated card (Port) | F21: mVND | G21: =SAP_Leadsheet!E27 -> 5.8941158 | H21: =G21 -> 5.8941158 | I21: =H21 -> 5.8941158 | J21: =I21 -> 5.8941158 | K21: =J21 -> 5.8941158 | L21: =K21 -> 5.8941158 | M21: =L21 -> 5.8941158 | N21: =M21 -> 5.8941158 | O21: =N21 -> 5.8941158 | ... R21: =Q21 -> 5.8941158 | S21: =SAP_Leadsheet!F27 -> 5.8941158 | T21: =S21 -> 5.8941158 | U21: =T21 -> 5.8941158 | V21: =U21 -> 5.8941158 | W21: =V21 -> 5.8941158 | X21: =W21 -> 5.8941158 | Y21: =X21 -> 5.8941158 | Z21: =Y21 -> 5.8941158 | AA21: =Z21 -> 5.8941158 | ... AD21: =AC21 -> 5.8941158 | AE21: =SAP_Leadsheet!G27 -> 5.8941158 | AF21: =AE21 -> 5.8941158 | AG21: =AF21 -> 5.8941158 | AH21: =AG21 -> 5.8941158 | AI21: =AH21 -> 5.8941158 | AJ21: =AI21 -> 5.8941158 | AK21: =AJ21 -> 5.8941158 | AL21: =AK21 -> 5.8941158 | AM21: =AL21 -> 5.8941158 | ... AP21: =AO21 -> 5.8941158 | AQ21: =SAP_Leadsheet!H27 -> 5.8941158 | AR21: =AQ21 -> 5.8941158 | AS21: =AR21 -> 5.8941158 | AT21: =AS21 -> 5.8941158 | AU21: =AT21 -> 5.8941158 | AV21: =AU21 -> 5.8941158 | AW21: =AV21 -> 5.8941158 | AX21: =AW21 -> 5.8941158 | AY21: =AX21 -> 5.8941158 | ... BB21: =BA21 -> 5.8941158 | BC21: =SAP_Leadsheet!I27 -> 5.8941158 | BD21: =BC21 -> 5.8941158 | BE21: =BD21 -> 5.8941158 | BF21: =BE21 -> 5.8941158 | BG21: =BF21 -> 5.8941158 | BH21: =BG21 -> 5.8941158 | BI21: =BH21 -> 5.8941158 | BJ21: =BI21 -> 5.8941158 | BK21: =BJ21 -> 5.8941158 | ... BN21: =BM21 -> 5.8941158
D23: Card Port | F23: % | G23: 1 | H23: 1 | I23: 1 | J23: 1 | K23: 1 | L23: 1 | M23: 1 | N23: 1 | O23: 1 | P23: 1 | Q23: 1 | R23: 1 | S23: 1 | T23: 1 | U23: 1 | V23: 1 | W23: 1 | X23: 1 | Y23: 1 | Z23: 1 | AA23: 1 | AB23: 1 | AC23: 1 | AD23: 1 | AE23: 1 | AF23: 1 | AG23: 1 | AH23: 1 | AI23: 1 | AJ23: 1 | AK23: 1 | AL23: 1 | AM23: 1 | AN23: 1 | AO23: 1 | AP23: 1 | AQ23: 1 | AR23: 1 | AS23: 1 | AT23: 1 | AU23: 1 | AV23: 1 | AW23: 1 | AX23: 1 | AY23: 1 | AZ23: 1 | BA23: 1 | BB23: 1 | BC23: 1 | BD23: 1 | BE23: 1 | BF23: 1 | BG23: 1 | BH23: 1 | BI23: 1 | BJ23: 1 | BK23: 1 | BL23: 1 | BM23: 1 | BN23: 1
D24: Transactor | F24: % | G24: =1-G25 -> 0.46654165 | H24: =1-H25 -> 0.46654165 | I24: =1-I25 -> 0.46654165 | J24: =1-J25 -> 0.46654165 | K24: =1-K25 -> 0.46654165 | L24: =1-L25 -> 0.46654165 | M24: =1-M25 -> 0.46654165 | N24: =1-N25 -> 0.46654165 | ... BN24: =1-BN25 -> 0.46654165
D25: Revolver | F25: % | G25: =SAP_Leadsheet!$E$33 -> 0.53345835 | H25: =SAP_Leadsheet!$E$33 -> 0.53345835 | I25: =SAP_Leadsheet!$E$33 -> 0.53345835 | J25: =SAP_Leadsheet!$E$33 -> 0.53345835 | K25: =SAP_Leadsheet!$E$33 -> 0.53345835 | L25: =SAP_Leadsheet!$E$33 -> 0.53345835 | M25: =SAP_Leadsheet!$E$33 -> 0.53345835 | N25: =SAP_Leadsheet!$E$33 -> 0.53345835 | ... BN25: =SAP_Leadsheet!$E$33 -> 0.53345835
B27: EMI (Installment)
C29: EMI PORT
C30: CASH installment
D31: Beginning Bal | F31: milVND | G31: 0 | H31: =G156 -> 0 | I31: =H156 -> 0 | J31: =I156 -> 0 | K31: =J156 -> 0 | L31: =K156 -> 0 | M31: =L156 -> 0 | N31: =M156 -> 0 | O31: =N156 -> 0 | ... BN31: =BM156 -> 0
D32: New Billing | F32: milVND | G32: =IF(AND(SAP_Leadsheet!$C$10="EMI",G$7<60+2-SAP_Leadsheet!$E$71),SAP_Spreadsheet!G$611*SAP_Leadsheet!$E$70,0) -> 0 | H32: =IF(AND(SAP_Leadsheet!$C$10="EMI",H$7<60+2-SAP_Leadsheet!$E$71),SAP_Spreadsheet!H$611*SAP_Leadsheet!$E$70,0) -> 0 | I32: =IF(AND(SAP_Leadsheet!$C$10="EMI",I$7<60+2-SAP_Leadsheet!$E$71),SAP_Spreadsheet!I$611*SAP_Leadsheet!$E$70,0) -> 0 | J32: =IF(AND(SAP_Leadsheet!$C$10="EMI",J$7<60+2-SAP_Leadsheet!$E$71),SAP_Spreadsheet!J$611*SAP_Leadsheet!$E$70,0) -> 0 | K32: =IF(AND(SAP_Leadsheet!$C$10="EMI",K$7<60+2-SAP_Leadsheet!$E$71),SAP_Spreadsheet!K$611*SAP_Leadsheet!$E$70,0) -> 0 | L32: =IF(AND(SAP_Leadsheet!$C$10="EMI",L$7<60+2-SAP_Leadsheet!$E$71),SAP_Spreadsheet!L$611*SAP_Leadsheet!$E$70,0) -> 0 | M32: =IF(AND(SAP_Leadsheet!$C$10="EMI",M$7<60+2-SAP_Leadsheet!$E$71),SAP_Spreadsheet!M$611*SAP_Leadsheet!$E$70,0) -> 0 | N32: =IF(AND(SAP_Leadsheet!$C$10="EMI",N$7<60+2-SAP_Leadsheet!$E$71),SAP_Spreadsheet!N$611*SAP_Leadsheet!$E$70,0) -> 0 | ... BN32: =IF(AND(SAP_Leadsheet!$C$10="EMI",BN$7<60+2-SAP_Leadsheet!$E$71),SAP_Spreadsheet!BN$611*SAP_Leadsheet!$E$70,0) -> 0
D33: Paid off | F33: milVND | G33: =G34+G95 -> 0 | H33: =H34+H95 -> 0 | I33: =I34+I95 -> 0 | J33: =J34+J95 -> 0 | K33: =K34+K95 -> 0 | L33: =L34+L95 -> 0 | M33: =M34+M95 -> 0 | N33: =N34+N95 -> 0 | ... BN33: =BN34+BN95 -> 0
D34: Early payment | F34: milVND | G34: =-SUM(G35:G94) -> 0 | H34: =-SUM(H35:H94) -> 0 | I34: =-SUM(I35:I94) -> 0 | J34: =-SUM(J35:J94) -> 0 | K34: =-SUM(K35:K94) -> 0 | L34: =-SUM(L35:L94) -> 0 | M34: =-SUM(M35:M94) -> 0 | N34: =-SUM(N35:N94) -> 0 | ... BN34: =-SUM(BN35:BN94) -> 0
C35: {=TRANSPOSE(G$7:BN$7)} -> 1 | G35: =IF(OR($C96>G$7,$C96+$E96-2<G$7),0,($D96-SUM($F96:F96)-SUM($F35:F35))*SAP_Leadsheet!$E$75) -> 0 | H35: =IF(OR($C96>H$7,$C96+$E96-2<H$7),0,($D96-SUM($F96:G96)-SUM($F35:G35))*SAP_Leadsheet!$E$75) -> 0 | I35: =IF(OR($C96>I$7,$C96+$E96-2<I$7),0,($D96-SUM($F96:H96)-SUM($F35:H35))*SAP_Leadsheet!$E$75) -> 0 | J35: =IF(OR($C96>J$7,$C96+$E96-2<J$7),0,($D96-SUM($F96:I96)-SUM($F35:I35))*SAP_Leadsheet!$E$75) -> 0 | K35: =IF(OR($C96>K$7,$C96+$E96-2<K$7),0,($D96-SUM($F96:J96)-SUM($F35:J35))*SAP_Leadsheet!$E$75) -> 0 | L35: =IF(OR($C96>L$7,$C96+$E96-2<L$7),0,($D96-SUM($F96:K96)-SUM($F35:K35))*SAP_Leadsheet!$E$75) -> 0 | M35: =IF(OR($C96>M$7,$C96+$E96-2<M$7),0,($D96-SUM($F96:L96)-SUM($F35:L35))*SAP_Leadsheet!$E$75) -> 0 | N35: =IF(OR($C96>N$7,$C96+$E96-2<N$7),0,($D96-SUM($F96:M96)-SUM($F35:M35))*SAP_Leadsheet!$E$75) -> 0 | ... BN35: =IF(OR($C96>BN$7,$C96+$E96-2<BN$7),0,($D96-SUM($F96:BM96)-SUM($F35:BM35))*SAP_Leadsheet!$E$75) -> 0
C36: 2 | G36: =IF(OR($C97>G$7,$C97+$E97-2<G$7),0,($D97-SUM($F97:F97)-SUM($F36:F36))*SAP_Leadsheet!$E$75) -> 0 | H36: =IF(OR($C97>H$7,$C97+$E97-2<H$7),0,($D97-SUM($F97:G97)-SUM($F36:G36))*SAP_Leadsheet!$E$75) -> 0 | I36: =IF(OR($C97>I$7,$C97+$E97-2<I$7),0,($D97-SUM($F97:H97)-SUM($F36:H36))*SAP_Leadsheet!$E$75) -> 0 | J36: =IF(OR($C97>J$7,$C97+$E97-2<J$7),0,($D97-SUM($F97:I97)-SUM($F36:I36))*SAP_Leadsheet!$E$75) -> 0 | K36: =IF(OR($C97>K$7,$C97+$E97-2<K$7),0,($D97-SUM($F97:J97)-SUM($F36:J36))*SAP_Leadsheet!$E$75) -> 0 | L36: =IF(OR($C97>L$7,$C97+$E97-2<L$7),0,($D97-SUM($F97:K97)-SUM($F36:K36))*SAP_Leadsheet!$E$75) -> 0 | M36: =IF(OR($C97>M$7,$C97+$E97-2<M$7),0,($D97-SUM($F97:L97)-SUM($F36:L36))*SAP_Leadsheet!$E$75) -> 0 | N36: =IF(OR($C97>N$7,$C97+$E97-2<N$7),0,($D97-SUM($F97:M97)-SUM($F36:M36))*SAP_Leadsheet!$E$75) -> 0 | ... BN36: =IF(OR($C97>BN$7,$C97+$E97-2<BN$7),0,($D97-SUM($F97:BM97)-SUM($F36:BM36))*SAP_Leadsheet!$E$75) -> 0
C37: 3 | G37: =IF(OR($C98>G$7,$C98+$E98-2<G$7),0,($D98-SUM($F98:F98)-SUM($F37:F37))*SAP_Leadsheet!$E$75) -> 0 | H37: =IF(OR($C98>H$7,$C98+$E98-2<H$7),0,($D98-SUM($F98:G98)-SUM($F37:G37))*SAP_Leadsheet!$E$75) -> 0 | I37: =IF(OR($C98>I$7,$C98+$E98-2<I$7),0,($D98-SUM($F98:H98)-SUM($F37:H37))*SAP_Leadsheet!$E$75) -> 0 | J37: =IF(OR($C98>J$7,$C98+$E98-2<J$7),0,($D98-SUM($F98:I98)-SUM($F37:I37))*SAP_Leadsheet!$E$75) -> 0 | K37: =IF(OR($C98>K$7,$C98+$E98-2<K$7),0,($D98-SUM($F98:J98)-SUM($F37:J37))*SAP_Leadsheet!$E$75) -> 0 | L37: =IF(OR($C98>L$7,$C98+$E98-2<L$7),0,($D98-SUM($F98:K98)-SUM($F37:K37))*SAP_Leadsheet!$E$75) -> 0 | M37: =IF(OR($C98>M$7,$C98+$E98-2<M$7),0,($D98-SUM($F98:L98)-SUM($F37:L37))*SAP_Leadsheet!$E$75) -> 0 | N37: =IF(OR($C98>N$7,$C98+$E98-2<N$7),0,($D98-SUM($F98:M98)-SUM($F37:M37))*SAP_Leadsheet!$E$75) -> 0 | ... BN37: =IF(OR($C98>BN$7,$C98+$E98-2<BN$7),0,($D98-SUM($F98:BM98)-SUM($F37:BM37))*SAP_Leadsheet!$E$75) -> 0
C38: 4 | G38: =IF(OR($C99>G$7,$C99+$E99-2<G$7),0,($D99-SUM($F99:F99)-SUM($F38:F38))*SAP_Leadsheet!$E$75) -> 0 | H38: =IF(OR($C99>H$7,$C99+$E99-2<H$7),0,($D99-SUM($F99:G99)-SUM($F38:G38))*SAP_Leadsheet!$E$75) -> 0 | I38: =IF(OR($C99>I$7,$C99+$E99-2<I$7),0,($D99-SUM($F99:H99)-SUM($F38:H38))*SAP_Leadsheet!$E$75) -> 0 | J38: =IF(OR($C99>J$7,$C99+$E99-2<J$7),0,($D99-SUM($F99:I99)-SUM($F38:I38))*SAP_Leadsheet!$E$75) -> 0 | K38: =IF(OR($C99>K$7,$C99+$E99-2<K$7),0,($D99-SUM($F99:J99)-SUM($F38:J38))*SAP_Leadsheet!$E$75) -> 0 | L38: =IF(OR($C99>L$7,$C99+$E99-2<L$7),0,($D99-SUM($F99:K99)-SUM($F38:K38))*SAP_Leadsheet!$E$75) -> 0 | M38: =IF(OR($C99>M$7,$C99+$E99-2<M$7),0,($D99-SUM($F99:L99)-SUM($F38:L38))*SAP_Leadsheet!$E$75) -> 0 | N38: =IF(OR($C99>N$7,$C99+$E99-2<N$7),0,($D99-SUM($F99:M99)-SUM($F38:M38))*SAP_Leadsheet!$E$75) -> 0 | ... BN38: =IF(OR($C99>BN$7,$C99+$E99-2<BN$7),0,($D99-SUM($F99:BM99)-SUM($F38:BM38))*SAP_Leadsheet!$E$75) -> 0
C39: 5 | G39: =IF(OR($C100>G$7,$C100+$E100-2<G$7),0,($D100-SUM($F100:F100)-SUM($F39:F39))*SAP_Leadsheet!$E$75) -> 0 | H39: =IF(OR($C100>H$7,$C100+$E100-2<H$7),0,($D100-SUM($F100:G100)-SUM($F39:G39))*SAP_Leadsheet!$E$75) -> 0 | I39: =IF(OR($C100>I$7,$C100+$E100-2<I$7),0,($D100-SUM($F100:H100)-SUM($F39:H39))*SAP_Leadsheet!$E$75) -> 0 | J39: =IF(OR($C100>J$7,$C100+$E100-2<J$7),0,($D100-SUM($F100:I100)-SUM($F39:I39))*SAP_Leadsheet!$E$75) -> 0 | K39: =IF(OR($C100>K$7,$C100+$E100-2<K$7),0,($D100-SUM($F100:J100)-SUM($F39:J39))*SAP_Leadsheet!$E$75) -> 0 | L39: =IF(OR($C100>L$7,$C100+$E100-2<L$7),0,($D100-SUM($F100:K100)-SUM($F39:K39))*SAP_Leadsheet!$E$75) -> 0 | M39: =IF(OR($C100>M$7,$C100+$E100-2<M$7),0,($D100-SUM($F100:L100)-SUM($F39:L39))*SAP_Leadsheet!$E$75) -> 0 | N39: =IF(OR($C100>N$7,$C100+$E100-2<N$7),0,($D100-SUM($F100:M100)-SUM($F39:M39))*SAP_Leadsheet!$E$75) -> 0 | ... BN39: =IF(OR($C100>BN$7,$C100+$E100-2<BN$7),0,($D100-SUM($F100:BM100)-SUM($F39:BM39))*SAP_Leadsheet!$E$75) -> 0
C40: 6 | G40: =IF(OR($C101>G$7,$C101+$E101-2<G$7),0,($D101-SUM($F101:F101)-SUM($F40:F40))*SAP_Leadsheet!$E$75) -> 0 | H40: =IF(OR($C101>H$7,$C101+$E101-2<H$7),0,($D101-SUM($F101:G101)-SUM($F40:G40))*SAP_Leadsheet!$E$75) -> 0 | I40: =IF(OR($C101>I$7,$C101+$E101-2<I$7),0,($D101-SUM($F101:H101)-SUM($F40:H40))*SAP_Leadsheet!$E$75) -> 0 | J40: =IF(OR($C101>J$7,$C101+$E101-2<J$7),0,($D101-SUM($F101:I101)-SUM($F40:I40))*SAP_Leadsheet!$E$75) -> 0 | K40: =IF(OR($C101>K$7,$C101+$E101-2<K$7),0,($D101-SUM($F101:J101)-SUM($F40:J40))*SAP_Leadsheet!$E$75) -> 0 | L40: =IF(OR($C101>L$7,$C101+$E101-2<L$7),0,($D101-SUM($F101:K101)-SUM($F40:K40))*SAP_Leadsheet!$E$75) -> 0 | M40: =IF(OR($C101>M$7,$C101+$E101-2<M$7),0,($D101-SUM($F101:L101)-SUM($F40:L40))*SAP_Leadsheet!$E$75) -> 0 | N40: =IF(OR($C101>N$7,$C101+$E101-2<N$7),0,($D101-SUM($F101:M101)-SUM($F40:M40))*SAP_Leadsheet!$E$75) -> 0 | ... BN40: =IF(OR($C101>BN$7,$C101+$E101-2<BN$7),0,($D101-SUM($F101:BM101)-SUM($F40:BM40))*SAP_Leadsheet!$E$75) -> 0
C41: 7 | G41: =IF(OR($C102>G$7,$C102+$E102-2<G$7),0,($D102-SUM($F102:F102)-SUM($F41:F41))*SAP_Leadsheet!$E$75) -> 0 | H41: =IF(OR($C102>H$7,$C102+$E102-2<H$7),0,($D102-SUM($F102:G102)-SUM($F41:G41))*SAP_Leadsheet!$E$75) -> 0 | I41: =IF(OR($C102>I$7,$C102+$E102-2<I$7),0,($D102-SUM($F102:H102)-SUM($F41:H41))*SAP_Leadsheet!$E$75) -> 0 | J41: =IF(OR($C102>J$7,$C102+$E102-2<J$7),0,($D102-SUM($F102:I102)-SUM($F41:I41))*SAP_Leadsheet!$E$75) -> 0 | K41: =IF(OR($C102>K$7,$C102+$E102-2<K$7),0,($D102-SUM($F102:J102)-SUM($F41:J41))*SAP_Leadsheet!$E$75) -> 0 | L41: =IF(OR($C102>L$7,$C102+$E102-2<L$7),0,($D102-SUM($F102:K102)-SUM($F41:K41))*SAP_Leadsheet!$E$75) -> 0 | M41: =IF(OR($C102>M$7,$C102+$E102-2<M$7),0,($D102-SUM($F102:L102)-SUM($F41:L41))*SAP_Leadsheet!$E$75) -> 0 | N41: =IF(OR($C102>N$7,$C102+$E102-2<N$7),0,($D102-SUM($F102:M102)-SUM($F41:M41))*SAP_Leadsheet!$E$75) -> 0 | ... BN41: =IF(OR($C102>BN$7,$C102+$E102-2<BN$7),0,($D102-SUM($F102:BM102)-SUM($F41:BM41))*SAP_Leadsheet!$E$75) -> 0
C42: 8 | G42: =IF(OR($C103>G$7,$C103+$E103-2<G$7),0,($D103-SUM($F103:F103)-SUM($F42:F42))*SAP_Leadsheet!$E$75) -> 0 | H42: =IF(OR($C103>H$7,$C103+$E103-2<H$7),0,($D103-SUM($F103:G103)-SUM($F42:G42))*SAP_Leadsheet!$E$75) -> 0 | I42: =IF(OR($C103>I$7,$C103+$E103-2<I$7),0,($D103-SUM($F103:H103)-SUM($F42:H42))*SAP_Leadsheet!$E$75) -> 0 | J42: =IF(OR($C103>J$7,$C103+$E103-2<J$7),0,($D103-SUM($F103:I103)-SUM($F42:I42))*SAP_Leadsheet!$E$75) -> 0 | K42: =IF(OR($C103>K$7,$C103+$E103-2<K$7),0,($D103-SUM($F103:J103)-SUM($F42:J42))*SAP_Leadsheet!$E$75) -> 0 | L42: =IF(OR($C103>L$7,$C103+$E103-2<L$7),0,($D103-SUM($F103:K103)-SUM($F42:K42))*SAP_Leadsheet!$E$75) -> 0 | M42: =IF(OR($C103>M$7,$C103+$E103-2<M$7),0,($D103-SUM($F103:L103)-SUM($F42:L42))*SAP_Leadsheet!$E$75) -> 0 | N42: =IF(OR($C103>N$7,$C103+$E103-2<N$7),0,($D103-SUM($F103:M103)-SUM($F42:M42))*SAP_Leadsheet!$E$75) -> 0 | ... BN42: =IF(OR($C103>BN$7,$C103+$E103-2<BN$7),0,($D103-SUM($F103:BM103)-SUM($F42:BM42))*SAP_Leadsheet!$E$75) -> 0
C43: 9 | G43: =IF(OR($C104>G$7,$C104+$E104-2<G$7),0,($D104-SUM($F104:F104)-SUM($F43:F43))*SAP_Leadsheet!$E$75) -> 0 | H43: =IF(OR($C104>H$7,$C104+$E104-2<H$7),0,($D104-SUM($F104:G104)-SUM($F43:G43))*SAP_Leadsheet!$E$75) -> 0 | I43: =IF(OR($C104>I$7,$C104+$E104-2<I$7),0,($D104-SUM($F104:H104)-SUM($F43:H43))*SAP_Leadsheet!$E$75) -> 0 | J43: =IF(OR($C104>J$7,$C104+$E104-2<J$7),0,($D104-SUM($F104:I104)-SUM($F43:I43))*SAP_Leadsheet!$E$75) -> 0 | K43: =IF(OR($C104>K$7,$C104+$E104-2<K$7),0,($D104-SUM($F104:J104)-SUM($F43:J43))*SAP_Leadsheet!$E$75) -> 0 | L43: =IF(OR($C104>L$7,$C104+$E104-2<L$7),0,($D104-SUM($F104:K104)-SUM($F43:K43))*SAP_Leadsheet!$E$75) -> 0 | M43: =IF(OR($C104>M$7,$C104+$E104-2<M$7),0,($D104-SUM($F104:L104)-SUM($F43:L43))*SAP_Leadsheet!$E$75) -> 0 | N43: =IF(OR($C104>N$7,$C104+$E104-2<N$7),0,($D104-SUM($F104:M104)-SUM($F43:M43))*SAP_Leadsheet!$E$75) -> 0 | ... BN43: =IF(OR($C104>BN$7,$C104+$E104-2<BN$7),0,($D104-SUM($F104:BM104)-SUM($F43:BM43))*SAP_Leadsheet!$E$75) -> 0
C44: 10 | G44: =IF(OR($C105>G$7,$C105+$E105-2<G$7),0,($D105-SUM($F105:F105)-SUM($F44:F44))*SAP_Leadsheet!$E$75) -> 0 | H44: =IF(OR($C105>H$7,$C105+$E105-2<H$7),0,($D105-SUM($F105:G105)-SUM($F44:G44))*SAP_Leadsheet!$E$75) -> 0 | I44: =IF(OR($C105>I$7,$C105+$E105-2<I$7),0,($D105-SUM($F105:H105)-SUM($F44:H44))*SAP_Leadsheet!$E$75) -> 0 | J44: =IF(OR($C105>J$7,$C105+$E105-2<J$7),0,($D105-SUM($F105:I105)-SUM($F44:I44))*SAP_Leadsheet!$E$75) -> 0 | K44: =IF(OR($C105>K$7,$C105+$E105-2<K$7),0,($D105-SUM($F105:J105)-SUM($F44:J44))*SAP_Leadsheet!$E$75) -> 0 | L44: =IF(OR($C105>L$7,$C105+$E105-2<L$7),0,($D105-SUM($F105:K105)-SUM($F44:K44))*SAP_Leadsheet!$E$75) -> 0 | M44: =IF(OR($C105>M$7,$C105+$E105-2<M$7),0,($D105-SUM($F105:L105)-SUM($F44:L44))*SAP_Leadsheet!$E$75) -> 0 | N44: =IF(OR($C105>N$7,$C105+$E105-2<N$7),0,($D105-SUM($F105:M105)-SUM($F44:M44))*SAP_Leadsheet!$E$75) -> 0 | ... BN44: =IF(OR($C105>BN$7,$C105+$E105-2<BN$7),0,($D105-SUM($F105:BM105)-SUM($F44:BM44))*SAP_Leadsheet!$E$75) -> 0
C45: 11 | G45: =IF(OR($C106>G$7,$C106+$E106-2<G$7),0,($D106-SUM($F106:F106)-SUM($F45:F45))*SAP_Leadsheet!$E$75) -> 0 | H45: =IF(OR($C106>H$7,$C106+$E106-2<H$7),0,($D106-SUM($F106:G106)-SUM($F45:G45))*SAP_Leadsheet!$E$75) -> 0 | I45: =IF(OR($C106>I$7,$C106+$E106-2<I$7),0,($D106-SUM($F106:H106)-SUM($F45:H45))*SAP_Leadsheet!$E$75) -> 0 | J45: =IF(OR($C106>J$7,$C106+$E106-2<J$7),0,($D106-SUM($F106:I106)-SUM($F45:I45))*SAP_Leadsheet!$E$75) -> 0 | K45: =IF(OR($C106>K$7,$C106+$E106-2<K$7),0,($D106-SUM($F106:J106)-SUM($F45:J45))*SAP_Leadsheet!$E$75) -> 0 | L45: =IF(OR($C106>L$7,$C106+$E106-2<L$7),0,($D106-SUM($F106:K106)-SUM($F45:K45))*SAP_Leadsheet!$E$75) -> 0 | M45: =IF(OR($C106>M$7,$C106+$E106-2<M$7),0,($D106-SUM($F106:L106)-SUM($F45:L45))*SAP_Leadsheet!$E$75) -> 0 | N45: =IF(OR($C106>N$7,$C106+$E106-2<N$7),0,($D106-SUM($F106:M106)-SUM($F45:M45))*SAP_Leadsheet!$E$75) -> 0 | ... BN45: =IF(OR($C106>BN$7,$C106+$E106-2<BN$7),0,($D106-SUM($F106:BM106)-SUM($F45:BM45))*SAP_Leadsheet!$E$75) -> 0
C46: 12 | G46: =IF(OR($C107>G$7,$C107+$E107-2<G$7),0,($D107-SUM($F107:F107)-SUM($F46:F46))*SAP_Leadsheet!$E$75) -> 0 | H46: =IF(OR($C107>H$7,$C107+$E107-2<H$7),0,($D107-SUM($F107:G107)-SUM($F46:G46))*SAP_Leadsheet!$E$75) -> 0 | I46: =IF(OR($C107>I$7,$C107+$E107-2<I$7),0,($D107-SUM($F107:H107)-SUM($F46:H46))*SAP_Leadsheet!$E$75) -> 0 | J46: =IF(OR($C107>J$7,$C107+$E107-2<J$7),0,($D107-SUM($F107:I107)-SUM($F46:I46))*SAP_Leadsheet!$E$75) -> 0 | K46: =IF(OR($C107>K$7,$C107+$E107-2<K$7),0,($D107-SUM($F107:J107)-SUM($F46:J46))*SAP_Leadsheet!$E$75) -> 0 | L46: =IF(OR($C107>L$7,$C107+$E107-2<L$7),0,($D107-SUM($F107:K107)-SUM($F46:K46))*SAP_Leadsheet!$E$75) -> 0 | M46: =IF(OR($C107>M$7,$C107+$E107-2<M$7),0,($D107-SUM($F107:L107)-SUM($F46:L46))*SAP_Leadsheet!$E$75) -> 0 | N46: =IF(OR($C107>N$7,$C107+$E107-2<N$7),0,($D107-SUM($F107:M107)-SUM($F46:M46))*SAP_Leadsheet!$E$75) -> 0 | ... BN46: =IF(OR($C107>BN$7,$C107+$E107-2<BN$7),0,($D107-SUM($F107:BM107)-SUM($F46:BM46))*SAP_Leadsheet!$E$75) -> 0
C47: 13 | G47: =IF(OR($C108>G$7,$C108+$E108-2<G$7),0,($D108-SUM($F108:F108)-SUM($F47:F47))*SAP_Leadsheet!$E$75) -> 0 | H47: =IF(OR($C108>H$7,$C108+$E108-2<H$7),0,($D108-SUM($F108:G108)-SUM($F47:G47))*SAP_Leadsheet!$E$75) -> 0 | I47: =IF(OR($C108>I$7,$C108+$E108-2<I$7),0,($D108-SUM($F108:H108)-SUM($F47:H47))*SAP_Leadsheet!$E$75) -> 0 | J47: =IF(OR($C108>J$7,$C108+$E108-2<J$7),0,($D108-SUM($F108:I108)-SUM($F47:I47))*SAP_Leadsheet!$E$75) -> 0 | K47: =IF(OR($C108>K$7,$C108+$E108-2<K$7),0,($D108-SUM($F108:J108)-SUM($F47:J47))*SAP_Leadsheet!$E$75) -> 0 | L47: =IF(OR($C108>L$7,$C108+$E108-2<L$7),0,($D108-SUM($F108:K108)-SUM($F47:K47))*SAP_Leadsheet!$E$75) -> 0 | M47: =IF(OR($C108>M$7,$C108+$E108-2<M$7),0,($D108-SUM($F108:L108)-SUM($F47:L47))*SAP_Leadsheet!$E$75) -> 0 | N47: =IF(OR($C108>N$7,$C108+$E108-2<N$7),0,($D108-SUM($F108:M108)-SUM($F47:M47))*SAP_Leadsheet!$E$75) -> 0 | ... BN47: =IF(OR($C108>BN$7,$C108+$E108-2<BN$7),0,($D108-SUM($F108:BM108)-SUM($F47:BM47))*SAP_Leadsheet!$E$75) -> 0
...

Sheet Sales plan & PL
E1: PROFIT & LOSS 60M
A3: Code | B3: Product | C3: Old/new | D3: Item | F3: I. | G3: SALES PLAN
A4: =B4&D4&C4 -> Auto loan | B4: Auto loan
H5: If you want to estimate the mix price & promotion tenor for your product package, please input here & link to Leadsheet properly in term of pricing
A8: =B8&D8&C8 -> Auto loan | B8: Auto loan | H8: Please input your expected disbursement volume with date of lauching out product if you would like to project 60M profit and loss.
A10: =B10&D10&C10 -> Auto loan | B10: Auto loan | H10: Business month | J10: 45658 | K10: =EOMONTH(J10,1) -> 45716 | L10: =EOMONTH(K10,1) -> 45747 | M10: =EOMONTH(L10,1) -> 45777 | N10: =EOMONTH(M10,1) -> 45808 | O10: =EOMONTH(N10,1) -> 45838 | P10: =EOMONTH(O10,1) -> 45869 | Q10: =EOMONTH(P10,1) -> 45900 | R10: =EOMONTH(Q10,1) -> 45930 | ... BR10: =EOMONTH(BQ10,1) -> 47514
H11: Don't delete | J11: =YEAR(J10) -> 2025 | K11: =YEAR(K10) -> 2025 | L11: =YEAR(L10) -> 2025 | M11: =YEAR(M10) -> 2025 | N11: =YEAR(N10) -> 2025 | O11: =YEAR(O10) -> 2025 | P11: =YEAR(P10) -> 2025 | Q11: =YEAR(Q10) -> 2025 | ... BR11: =YEAR(BR10) -> 2030
A12: =B12&D12&C12 -> Auto loan | B12: Auto loan | H12: New disbursement (Card)
H13: Sales Plan 2025 | J13: 5300 | K13: 5400 | L13: 5500 | M13: 5600 | N13: 5700 | O13: 5800 | P13: 5800 | Q13: 5900 | R13: 6000 | S13: 6100 | T13: 6200 | U13: 6300
G14: New limit policy (apply for new cards) | H14: New card Forecast | J14: =J13*70% -> 3710 | K14: =K13*70% -> 3780 | L14: =L13*70% -> 3850 | M14: =M13*70% -> 3920 | N14: =N13*70% -> 3990 | O14: =O13*70% -> 4060 | P14: =P13*70% -> 4060 | Q14: =Q13*70% -> 4130 | ... U14: =U13*70% -> 4410
H15: CIF (new card only) | J15: =J14*60%*99% -> 2203.74 | K15: =K14*60%*99% -> 2245.32 | L15: =L14*60%*99% -> 2286.9 | M15: =M14*60%*99% -> 2328.48 | N15: =N14*60%*99% -> 2370.06 | O15: =O14*60%*99% -> 2411.64 | P15: =P14*60%*99% -> 2411.64 | Q15: =Q14*60%*99% -> 2453.22 | ... U15: =U14*60%*99% -> 2619.54
H16: % Affluent | J16: 0.6 | K16: =J16 -> 0.6 | L16: =K16 -> 0.6 | M16: =L16 -> 0.6 | N16: =M16 -> 0.6 | O16: =N16 -> 0.6 | P16: =O16 -> 0.6 | Q16: =P16 -> 0.6 | R16: =Q16 -> 0.6 | ... U16: =T16 -> 0.6
H17: # Card in Force Affluent | J17: =J15*J16 -> 1322.244 | K17: =K15*K16 -> 1347.192 | L17: =L15*L16 -> 1372.14 | M17: =M15*M16 -> 1397.088 | N17: =N15*N16 -> 1422.036 | O17: =O15*O16 -> 1446.984 | P17: =P15*P16 -> 1446.984 | Q17: =Q15*Q16 -> 1471.932 | ... U17: =U15*U16 -> 1571.724
H18: Limit per card (Mil VNĐ) | J18: 40 | K18: 40 | L18: 40 | M18: 40 | N18: 40 | O18: 40 | P18: 40 | Q18: 40 | R18: 40 | S18: 40 | T18: 40 | U18: 40
H19: Limit ultilization | J19: 0.25 | K19: =J19 -> 0.25 | L19: =K19 -> 0.25 | M19: =L19 -> 0.25 | N19: =M19 -> 0.25 | O19: =N19 -> 0.25 | P19: =O19 -> 0.25 | Q19: =P19 -> 0.25 | R19: =Q19 -> 0.25 | ... U19: =T19 -> 0.25
H20: Spending per card | J20: =J18*J19 -> 10 | K20: =K18*K19 -> 10 | L20: =L18*L19 -> 10 | M20: =M18*M19 -> 10 | N20: =N18*N19 -> 10 | O20: =O18*O19 -> 10 | P20: =P18*P19 -> 10 | Q20: =Q18*Q19 -> 10 | ... U20: =U18*U19 -> 10
H21: % Mass | J21: =1-J16 -> 0.4 | K21: =1-K16 -> 0.4 | L21: =1-L16 -> 0.4 | M21: =1-M16 -> 0.4 | N21: =1-N16 -> 0.4 | O21: =1-O16 -> 0.4 | P21: =1-P16 -> 0.4 | Q21: =1-Q16 -> 0.4 | ... U21: =1-U16 -> 0.4
H22: # Card in Force Mass | J22: =J15*J21 -> 881.496 | K22: =K15*K21 -> 898.128 | L22: =L15*L21 -> 914.76 | M22: =M15*M21 -> 931.392 | N22: =N15*N21 -> 948.024 | O22: =O15*O21 -> 964.656 | P22: =P15*P21 -> 964.656 | Q22: =Q15*Q21 -> 981.288 | ... U22: =U15*U21 -> 1047.816
H23: Limit per card (Mil VNĐ) | J23: 21 | K23: 21 | L23: 21 | M23: 21 | N23: 21 | O23: 21 | P23: 21 | Q23: 21 | R23: 21 | S23: 21 | T23: 21 | U23: 21
H24: Limit ultilization | J24: =30% -> 0.3 | K24: =J24 -> 0.3 | L24: =K24 -> 0.3 | M24: =L24 -> 0.3 | N24: =M24 -> 0.3 | O24: =N24 -> 0.3 | P24: =O24 -> 0.3 | Q24: =P24 -> 0.3 | R24: =Q24 -> 0.3 | ... U24: =T24 -> 0.3
H25: Spending per card | J25: =J23*J24 -> 6.3 | K25: =K23*K24 -> 6.3 | L25: =L23*L24 -> 6.3 | M25: =M23*M24 -> 6.3 | N25: =N23*N24 -> 6.3 | O25: =O23*O24 -> 6.3 | P25: =P23*P24 -> 6.3 | Q25: =Q23*Q24 -> 6.3 | ... U25: =U23*U24 -> 6.3
H26: Total spending (Mil VNĐ) | J26: =J20*J17+J25*J22 -> 18775.865 | K26: =K20*K17+K25*K22 -> 19130.126 | L26: =L20*L17+L25*L22 -> 19484.388 | M26: =M20*M17+M25*M22 -> 19838.65 | N26: =N20*N17+N25*N22 -> 20192.911 | O26: =O20*O17+O25*O22 -> 20547.173 | P26: =P20*P17+P25*P22 -> 20547.173 | Q26: =Q20*Q17+Q25*Q22 -> 20901.434 | ... U26: =U20*U17+U25*U22 -> 22318.481
G27: Current limit policy (2024 current active) | H27: # Card In Force | J27: 88000 | K27: =J27*99% -> 87120 | L27: =K27*99% -> 86248.8 | M27: =L27*99% -> 85386.312 | N27: =M27*99% -> 84532.449 | O27: =N27*99% -> 83687.124 | P27: =O27*99% -> 82850.253 | Q27: =P27*99% -> 82021.751 | R27: =Q27*99% -> 81201.533 | ... U27: =T27*99% -> 78789.766
H28: Spending per card | J28: 5.1 | K28: =J28*1.05 -> 5.355 | L28: =K28 -> 5.355 | M28: =L28*1.1 -> 5.8905 | N28: =M28 -> 5.8905 | O28: =N28*1.1 -> 6.47955 | P28: =O28 -> 6.47955 | Q28: =P28*1.1 -> 7.127505 | R28: =Q28 -> 7.127505 | S28: =R28*1.1 -> 7.8402555 | T28: =S28 -> 7.8402555 | U28: =T28*1.1 -> 8.6242811
H29: Total spending (Mil VNĐ) | J29: =J28*J27 -> 448800 | K29: =K28*K27 -> 466527.6 | L29: =L28*L27 -> 461862.32 | M29: =M28*M27 -> 502968.07 | N29: =N28*N27 -> 497938.39 | O29: =O28*O27 -> 542254.91 | P29: =P28*P27 -> 536832.36 | Q29: =Q28*Q27 -> 584610.44 | ... U29: =U28*U27 -> 679505.09
G30: Total porfolio | H30: # Card In Force | J30: =J27+J15 -> 90203.74 | K30: =J30+K15 -> 92449.06 | L30: =K30+L15 -> 94735.96 | M30: =L30+M15 -> 97064.44 | N30: =M30+N15 -> 99434.5 | O30: =N30+O15 -> 101846.14 | P30: =O30+P15 -> 104257.78 | Q30: =P30+Q15 -> 106711 | R30: =Q30+R15 -> 109205.8 | ... U30: =T30+U15 -> 116939.68
H31: Spending per card | J31: =J32/J30 -> 5.183553 | K31: =K32/K30 -> 5.2532468 | L31: =L32/L30 -> 5.0809293 | M31: =M32/M30 -> 5.3861818 | N31: =N32/N30 -> 5.21078 | O31: =O32/O30 -> 5.526003 | P31: =P32/P30 -> 5.3461673 | Q31: =Q32/Q30 -> 5.6743154 | ... U31: =U32/U30 -> 6.0015862
H32: Total spending (Mil VNĐ) | J32: =J29+J26 -> 467575.86 | K32: =K29+K26 -> 485657.73 | L32: =L29+L26 -> 481346.71 | M32: =M29+M26 -> 522806.72 | N32: =N29+N26 -> 518131.3 | O32: =O29+O26 -> 562802.08 | P32: =P29+P26 -> 557379.53 | Q32: =Q29+Q26 -> 605511.87 | ... U32: =U29+U26 -> 701823.57 | V32: =SUM(J32:U32) -> 6800875.6
G33: Limit increasing Batch | J33: Batch 1 | L33: Batch 2 | N33: Batch 3 | P33: Batch 4 | R33: Batch 5 | T33: Batch 6
G34: Note | J34: spending per active increase 5% (tet holiday) | L34: spending per active increase 10% | N34: 0.1 | P34: 0.1 | R34: 0.1 | T34: 0.1
F35: II. | G35: PROFIT & LOSS
H37: FISCAL YEAR | J37: Total | K37: =J11 -> 2025 | L37: =K37+1 -> 2026 | M37: =L37+1 -> 2027 | N37: =M37+1 -> 2028 | O37: =N37+1 -> 2029 | P37: =O37+1 -> 2030
J38: bVND | K38: bVND | L38: bVND | M38: bVND | N38: bVND | O38: bVND | P38: bVND
H40: NEW DISBURSAL | J40: =SUM(K40:O40) -> 0 | K40: =SUMIF($J$11:$BQ$11,K$37,$J$12:$BQ$12) -> 0 | L40: =SUMIF($J$11:$BQ$11,L$37,$J$12:$BQ$12) -> 0 | M40: =SUMIF($J$11:$BQ$11,M$37,$J$12:$BQ$12) -> 0 | N40: =SUMIF($J$11:$BQ$11,N$37,$J$12:$BQ$12) -> 0 | O40: =SUMIF($J$11:$BQ$11,O$37,$J$12:$BQ$12) -> 0 | P40: =SUMIF($J$11:$BQ$11,P$37,$J$12:$BQ$12) -> 0
H41: Monthly disbursement | J41: =AVERAGE(J12:AS12) -> #DIV/0! | K41: =K40/COUNTIF($J$11:$AS$11,K37) -> 0 | L41: =L40/COUNTIF($J$11:$AS$11,L37) -> 0 | M41: =M40/COUNTIF($J$11:$AS$11,M37) -> 0 | N41: =N40/COUNTIF($J$11:$BQ$11,N37) -> 0 | O41: =O40/COUNTIF($J$11:$BQ$11,O37) -> 0
H43: EOP | J43: =N43 -> 0 | K43: =OFFSET('PL projection speadsheet'!$B$7,0,MATCH(DATE('Sales plan & PL'!K$37,12,31),'PL projection speadsheet'!$C$4:$BJ$4,0))/1000 -> 0 | L43: =OFFSET('PL projection speadsheet'!$B$7,0,MATCH(DATE('Sales plan & PL'!L$37,12,31),'PL projection speadsheet'!$C$4:$BJ$4,0))/1000 -> 0 | M43: =OFFSET('PL projection speadsheet'!$B$7,0,MATCH(DATE('Sales plan & PL'!M$37,12,31),'PL projection speadsheet'!$C$4:$BJ$4,0))/1000 -> 0 | N43: =OFFSET('PL projection speadsheet'!$B$7,0,MATCH(DATE('Sales plan & PL'!N$37,12,31),'PL projection speadsheet'!$C$4:$BJ$4,0))/1000 -> 0 | O43: ='PL projection speadsheet'!BJ7/1000 -> 0 | P43: ='PL projection speadsheet'!BL7/1000 -> 0
H44: ADB | J44: =SUM('PL projection speadsheet'!C8:BI8)/1000/COUNT('PL projection speadsheet'!C3:BI3) -> 0 | K44: =SUMIF('PL projection speadsheet'!$C$3:$BJ$3,K$37,'PL projection speadsheet'!$C8:$BJ8)/1000/COUNTIF('PL projection speadsheet'!$C$3:$BJ$3,'Sales plan & PL'!K$37) -> 0 | L44: =SUMIF('PL projection speadsheet'!$C$3:$BJ$3,L$37,'PL projection speadsheet'!$C8:$BJ8)/1000/COUNTIF('PL projection speadsheet'!$C$3:$BJ$3,'Sales plan & PL'!L$37) -> 0 | M44: =SUMIF('PL projection speadsheet'!$C$3:$BJ$3,M$37,'PL projection speadsheet'!$C8:$BJ8)/1000/COUNTIF('PL projection speadsheet'!$C$3:$BJ$3,'Sales plan & PL'!M$37) -> 0 | N44: =SUMIF('PL projection speadsheet'!$C$3:$BJ$3,N$37,'PL projection speadsheet'!$C8:$BJ8)/1000/COUNTIF('PL projection speadsheet'!$C$3:$BJ$3,'Sales plan & PL'!N$37) -> 0 | O44: =SUMIF('PL projection speadsheet'!$C$3:$BJ$3,O$37,'PL projection speadsheet'!$C8:$BJ8)/1000/COUNTIF('PL projection speadsheet'!$C$3:$BJ$3,'Sales plan & PL'!O$37) -> 0
H46: TOI | J46: =SUM(K46:O46) -> 0 | K46: =SUMIF('PL projection speadsheet'!$C$3:$BJ$3,K$37,'PL projection speadsheet'!$C9:$BJ9)/1000 -> 0 | L46: =SUMIF('PL projection speadsheet'!$C$3:$BJ$3,L$37,'PL projection speadsheet'!$C9:$BJ9)/1000 -> 0 | M46: =SUMIF('PL projection speadsheet'!$C$3:$BJ$3,M$37,'PL projection speadsheet'!$C9:$BJ9)/1000 -> 0 | N46: =SUMIF('PL projection speadsheet'!$C$3:$BJ$3,N$37,'PL projection speadsheet'!$C9:$BJ9)/1000 -> 0 | O46: =SUMIF('PL projection speadsheet'!$C$3:$BJ$3,O$37,'PL projection speadsheet'!$C9:$BJ9)/1000 -> 0 | P46: =SUMIF('PL projection speadsheet'!$C$3:$BJ$3,P$37,'PL projection speadsheet'!$C9:$BJ9)/1000 -> 0
