Workbook
Name __S1: {"Book1"}
Name __S1: {"Book1"}
Name __S1: {"Book1"}
Name __S1: {"Book1"}
Name _a1: {"'Sheet1'!$L$16"}
Name _a1: {"'Sheet1'!$L$16"}
Name _a1: {"'Sheet1'!$L$16"}
Name _a1: {"'Sheet1'!$L$16"}
Name _S1: {"Book1"}
Name _S1: {"Book1"}
Name _S1: {"Book1"}
Name _S1: {"Book1"}
Name Ă: #REF!
Name Ạ196: #REF!
Name â259: #REF!
Name â259: #REF!
Name â312: #REF!
Name â312: #REF!
Name Acquisition_PlanA: #REF!
Name Acquisition_PlanB: #REF!
Name Actual: (PeriodInActual*(#REF!>0))*PeriodInPlan
Name Actual: (PeriodInActual*(#REF!>0))*PeriodInPlan
Name Actual: (PeriodInActual*(#REF!>0))*PeriodInPlan
Name Actual: (PeriodInActual*(#REF!>0))*PeriodInPlan
Name ActualBeyond: PeriodInActual*(#REF!>0)
Name ActualBeyond: PeriodInActual*(#REF!>0)
Name ActualBeyond: PeriodInActual*(#REF!>0)
Name ActualBeyond: PeriodInActual*(#REF!>0)
Name adf: #REF!
Name adf: #REF!
Name AdvIncQ12020: #REF!
Name AdvIncQ12021: #REF!
Name AdvIncQ12022: #REF!
Name AdvIncQ12023: #REF!
Name AdvIncQ12024: #REF!
Name AdvIncQ22020: #REF!
Name AdvIncQ22021: #REF!
Name AdvIncQ22022: #REF!
Name AdvIncQ22023: #REF!
Name AdvIncQ22024: #REF!
Name AdvIncQ32020: #REF!
Name AdvIncQ32021: #REF!
Name AdvIncQ32022: #REF!
Name AdvIncQ32023: #REF!
Name AdvIncQ32024: #REF!
Name AdvIncQ42020: #REF!
Name AdvIncQ42021: #REF!
Name AdvIncQ42022: #REF!
Name AdvIncQ42023: #REF!
Name AdvIncQ42024: #REF!
Name AdvPenRate2020: #REF!
Name AdvPenRate2021: #REF!
Name AdvPenRate2022: #REF!
Name AdvPenRate2023: #REF!
Name AdvPenRate2024: #REF!
Name AllReportList: #REF!
Name Amount_act: #REF!
Name Amount_CF: #REF!
Name Amount_F: #REF!
Name Amount_KPI_act: #REF!

Sheet COF
E1: =SUBTOTAL(9,E3:E43) -> 24063720300562 | F1: =SUBTOTAL(9,F3:F43) -> 3.6426646e+09 | H1: =F1/E1*365 -> 0.055252162 | J1: 0.055252162
E2: =SUM(E4:E42) -> 348822682508025 | F2: =SUM(F4:F42) -> 6.3783621e+10 | H2: =SUM(H4:H42) -> 1173
B3: Nhom | C3: SP | D3: pl | E3: Sum of BALANCE | F3: Sum of Lai DCV | G3: Month | H3: Day
B4: UPL | C4: cl | D4: BE CASHLOAN | E4: 175237237692 | F4: 35108054 | G4: 9 | H4: 30
B5: UPL | C5: cl | D5: CAKE CASHLOAN | E5: 45792086198052 | F5: 8.8220401e+09 | G5: 9 | H5: 30
B6: UPL | C6: OD | D6: CAKE OVERDRAFT | E6: 7169005435909 | F6: 9.9109849e+08 | G6: 9 | H6: 30
B7: UPL | C7: PD | D7: CAKE PAYDAY | E7: 3672603510227 | F7: 5.4667902e+08 | G7: 9 | H7: 30
B8: UPL | C8: cl | D8: MWG CASHLOAN | E8: 7860835561894 | F8: 1.5211837e+09 | G8: 9 | H8: 30
B9: UPL | C9: cl | D9: NGS CASHLOAN | E9: 530282165595 | F9: 1.1619612e+08 | G9: 9 | H9: 30
B10: UPL | C10: cl | D10: VIETTEL CASHLOAN | E10: 47500871433668 | F10: 9.1994775e+09 | G10: 9 | H10: 30
B11: UPL | C11: PD | D11: VIETTEL PAYDAY | E11: 6555226346162 | F11: 1.021781e+09 | G11: 9 | H11: 30
B12: UPL | C12: PD | D12: VIETTEL PAYDAYPAYROLL | E12: 25934847005 | F12: 3828070.8 | G12: 9 | H12: 30
B13: UPL | C13: cl | D13: VIETTEL PAYROLL CASHLOAN | E13: 234239258102 | F13: 44742343 | G13: 9 | H13: 30
B14: UPL | C14: cl | D14: VNPAY CASHLOAN | E14: 2538375718443 | F14: 4.6902939e+08 | G14: 9 | H14: 30
B15: UPL | C15: cl | D15: VNPOST CASHLOAN | E15: 74534379401 | F15: 14917048 | G15: 9 | H15: 30
... B42: UPL | C42: cl | D42: Zalopay CASHLOAN | E42: 3450971717669 | F42: 6.384429e+08 | G42: 7 | H42: 31

Sheet NOTE
A1: SAP MODEL - PAYDAY
N2: KHN | O2: v5 | P2: 20251001
B3: 1. Notes and disclaimer
C4: a. Giới thiệu về SAP
D5: - SAP: Single Account Profitability (Hiệu quả sản phẩm trên từng đơn vị sản phẩm)
D6: - Model SAP được sử dụng như 1 mô hình dự đoán hiệu quả vòng đời của sản phẩm.
D7: - Do sự phức tạp của sản phẩm, các hệ thống vận hành (hệ thống hạch kế toán, hệ thống quản trị rủi ro, hệ thống quản trị…), hành vi người sử dụng hành vi người sử dụng, model chỉ có thể mô phỏng tương đối trung bình vòng đời của sản phẩm.
D8: - Mô hình được tính toán dựa vào các yếu tố đầu vào xác định tại thời điểm, do đó kết quả của mô hình có thể có sự khác biệt so với thực tế vận hành sản phẩm.
D9: - Mô hình SAP Payday tính hiệu quả của khoản vay giải ngân và thời hạn tối thiểu là 1 tháng với sử dụng phương pháp dự phòng IFRS hoặc VAS
E10: - Lưu ý rằng trường hợp dùng model để tính toán cho các khoản vay < 1 tháng hoặc các khoản vay lẻ ngày thì cần tự quy đổi về hệ quy chiếu 1 tháng để tính
C12: b. Giới thiệu về PnL
D13: - Trong file tính này, Profit & Lost (PnL) được dự phóng từ trung bình cộng kết quả kinh doanh trên từng sản phẩm (SAP) với yếu tố "sale plan" (số giải ngân) qua từng tháng, do đó có thể khác biệt so với kết quả thực tế vận hành.
D14: - Dòng tiền thực tế qua từng tháng có thể khác biệt với mô hình tính toán do nhiều yếu tố tác động bên ngoài thay đổi, do đó, vui lòng chỉ sử dụng mô hình cho mục đích tham khảo.
D15: - Cho mục đích tính dự phòng dòng tiền ngắn và trung hạn, mô hình PnL được cutoff tại thời điểm 5 năm (60 tháng) kể từ ngày bắt đầu khởi chạy sản phẩm đầu tiên.
B17: 2. Instruction
D18: - Dành cho người sử dụng
E19: - Chỉ chỉnh sửa vào các ô màu vàng
E20: - 2 sheets "SAP_Leadsheet" và "Sale plan&PL" cung cấp yếu tố đầu vào và đầu ra để tính toán mô hình SAP cũng như PnL.
F21: - Sheet SAP_Leadsheet được cấu trúc 2 phần, bên trái là các yếu tố đầu vào (input) và bên phải là kết quả dự đoán (output). Đơn vị sử dụng tại bảng tính là triệu VND (mVND) và phần trăm (%)
F22: - Sheet "Sale plan & PL" được cấu trúc 2 phần, bên trên là sale plan và bên dưới là kết quả PnL
E23: - 2 sheets "SAP_Spreadsheet" và "PL projection speadsheet" là các file tính toán cho 2 sheet "SAP_Leadsheet", "Sales plan & PL"
F24: - 2 sheets được cấu trúc từ trên xuống dưới theo thứ tự tính toán mô phỏng để đưa ra kết quả kinh doanh cuối cùng
F25: - 2 sheets đã được tạm khóa. Trường hợp cần mở khóa, điều chỉnh các yếu tố, vui lòng liên hệ với nhóm vận hành để được hỗ trợ.
D27: - Dành riêng cho người vận hành, hiệu chỉnh
E28: - Cần cẩn trọng khi điều chỉnh ở các file "speadsheet" vì 1 khi sai lệch rất khó tìm ra lỗi (VD: sửa nhầm ô, link nhầm vị trí,…)
B31: 3. Legend
C33: REVENUE INPUT
C36: Amount & Tenor
D37: Loan amount | G37: Số tiền vay giải ngân | L37: Trường hợp số tiền giải ngân > giá trị hàng hóa, chỉ ghi = số thực tế giải ngân
D38: Payment Method | G38: Phương pháp tính lãi | L38: EMI (Equated monthly Installment)- số tiền thanh toán cố định hàng tháng
D39: Nominal Tenor | G39: Thời hạn vay | L39: Thời hạn ghi nhận trên khoản vay ( VD: 1 tháng, 3 tháng, 12 tháng,…)
D40: Maturity to Termination | G40: Thời hạn từ lúc đáo hạn tới lúc tới khi ra ngoại bảng | L40: Nên để 6 tháng để khớp với hệ thống kế toán, rủi ro đang ghi nhận WO180+
D41: Month on book | G41: Thời gian ghi nhận trên sổ sách | L41: = Nominal tenor + Maturity to termination
C43: Pricing
D44: From- To | G44: Từ tháng… tới tháng
D45: IR | G45: Interest rate- lãi suất khoản vay
D46: COF | G46: Cost of fund - Giá vốn | L46: Sử dụng matrix mua vốn của VPB
D47: NIM | G47: Net interest margin - Biên lãi ròng
C49: Early prepayment
D50: From- To | G50: Từ tháng… tới tháng
...

Sheet Leadsheet
B1: SAP PAYDAY MODEL | D1: 1
B2: HKN | C2: =NOTE!P2 -> 20251001 | D2: =NOTE!O2 -> v5 | K2: NOTE
K3: Please read carefully about before using model
B4: Product | C4: Unsecured loan | D4: UPL | E4: Risk input | G4: IFRS | H4: =G4 -> IFRS | L4: Disclaimer
B5: Sub-Product | C5: Payday | D5: ALL | E5: Write off | G5: DPD180+ | H5: =G5 -> DPD180+ | L5: Instruction
B6: Sub-Segments | C6: ALL | D6: ALL | E6: Quarter | G6: Q3.2025 | H6: =G6 -> Q3.2025 | L6: Legend
B8: REVENUE INPUT | H8: Cur: mVND | K8: GENERAL OUTPUT | U8: Cur: mVND
B10: Amount & Tenor | C10: Loan amount | E10: =DATA!E9/10^6 -> 3.4739502 | N10: Life time | O10: Year 1 | P10: Year 2 | Q10: Year 3 | R10: Year 4 | S10: Year 5 | T10: % ANR | U10: % Disbursement
C11: Payment Method | E11: EMI | K11: ANR | N11: =N29 -> 0.41787859 | O11: =O29 -> 0.41787859 | P11: =P29 -> 0 | Q11: =Q29 -> 0 | R11: =R29 -> 0 | S11: =S29 -> 0 | U11: =N11/$E$10 -> 0.12028917
C12: Nominal Tenor | E12: 1 | K12: TOI | N12: =SUM(N13:N15) -> 0.36294935 | O12: =SUM(O13:O15) -> 0.36294935 | P12: =SUM(P13:P15) -> 0 | Q12: =SUM(Q13:Q15) -> 0 | R12: =SUM(R13:R15) -> 0 | S12: =SUM(S13:S15) -> 0 | T12: =N12/$E$14*12/$N$11 -> 1.4889466 | U12: =N12/$E$10 -> 0.10447742
C13: Maturity to Termination | E13: 6 | K13: Net interest income | N13: =N31 -> 0.14306179 | O13: =O31 -> 0.14306179 | P13: =P31 -> 0 | Q13: =Q31 -> 0 | R13: =R31 -> 0 | S13: =S31 -> 0 | T13: =N13/$E$14*12/$N$11 -> 0.58689003 | U13: =N13/$E$10 -> 0.0411813
C14: Month on book | E14: =E12+E13 -> 7 | K14: Net fee income | N14: =N34 -> 0.21988757 | O14: =O34 -> 0.21988757 | P14: =P34 -> 0 | Q14: =Q34 -> 0 | R14: =R34 -> 0 | S14: =S34 -> 0 | T14: =N14/$E$14*12/$N$11 -> 0.90205655 | U14: =N14/$E$10 -> 0.06329612
K15: Other income | N15: =N37 -> 0 | O15: =O37 -> 0 | P15: =P37 -> 0 | Q15: =Q37 -> 0 | R15: =R37 -> 0 | S15: =S37 -> 0 | T15: =N15/$E$14*12/$N$11 -> 0 | U15: =N15/$E$10 -> 0
K16: PROVISION | N16: =N38 -> -0.16371398 | O16: =O38 -> -0.16371398 | P16: =P38 -> 0 | Q16: =Q38 -> 0 | R16: =R38 -> 0 | S16: =S38 -> 0 | T16: =N16/$E$14*12/$N$11 -> -0.67161265 | U16: =N16/$E$10 -> -0.047126175
B17: Pricing | C17: From | D17: To | E17: IR | F17: COF | G17: NIM | K17: OPEX | N17: =SUM(N18:N21) -> -0.15047878 | O17: =SUM(O18:O21) -> -0.15047878 | P17: =SUM(P18:P21) -> 0 | Q17: =SUM(Q18:Q21) -> 0 | R17: =SUM(R18:R21) -> 0 | S17: =SUM(S18:S21) -> 0 | T17: =N17/$E$14*12/$N$11 -> -0.61731718 | U17: =N17/$E$10 -> -0.043316333
A18: 1 | B18: In due | C18: 1 | D18: 1 | E18: =DATA!G9 -> 0.57430775 | F18: =COF!J1 -> 0.055252162 | G18: =E18-F18 -> 0.51905559 | K18: Acquisition cost | N18: =SUM(N40) -> -0.059634389 | O18: =SUM(O40) -> -0.059634389 | P18: =SUM(P40) -> 0 | Q18: =SUM(Q40) -> 0 | R18: =SUM(R40) -> 0 | S18: =SUM(S40) -> 0 | T18: =N18/$E$14*12/$N$11 -> -0.24464135 | U18: =N18/$E$10 -> -0.017166161
A19: 2 | B19: Overdue | C19: =D18+1 -> 2 | D19: =E14 -> 7 | E19: =E18 -> 0.57430775 | F19: =F18 -> 0.055252162 | G19: =E19-F19 -> 0.51905559 | K19: UW & Disbursal | N19: =N44 -> -0.018614428 | O19: =O44 -> -0.018614428 | P19: =P44 -> 0 | Q19: =Q44 -> 0 | R19: =R44 -> 0 | S19: =S44 -> 0 | T19: =N19/$E$14*12/$N$11 -> -0.076362964 | U19: =N19/$E$10 -> -0.0053582886
A20: 3 | K20: Collection & aftersale service | N20: =N47 -> -0.0075830034 | O20: =O47 -> -0.0075830034 | P20: =P47 -> 0 | Q20: =Q47 -> 0 | R20: =R47 -> 0 | S20: =S47 -> 0 | T20: =N20/$E$14*12/$N$11 -> -0.031108161 | U20: =N20/$E$10 -> -0.0021828187
A21: 4 | B21: Credit insurrance | C21: Banca Premium (excl. in loan) | F21: per disbursement amount | K21: Support unit | N21: =N51 -> -0.064646964 | O21: =O51 -> -0.064646964 | P21: =P51 -> 0 | Q21: =Q51 -> 0 | R21: =R51 -> 0 | S21: =S51 -> 0 | T21: =N21/$E$14*12/$N$11 -> -0.2652047 | U21: =N21/$E$10 -> -0.018609065
C22: Banca Premium (incl. in loan) | E22: =DATA!H9 -> 0.079848379 | F22: per disbursement amount | K22: PBT | N22: =N12+N16+N17 -> 0.048756586 | O22: =O12+O16+O17 -> 0.048756586 | P22: =P12+P16+P17 -> 0 | Q22: =Q12+Q16+Q17 -> 0 | R22: =R12+R16+R17 -> 0 | S22: =S12+S16+S17 -> 0 | T22: =N22/$E$14*12/$N$11 -> 0.20001676 | U22: =N22/$E$10 -> 0.014034912
A23: 5 | C23: Penetration | E23: 1 | F23: per disbursement amount | K23: In which: PROFIT BEFORE SU | N23: =N22-N21 -> 0.11340355 | O23: =O22-O21 -> 0.11340355 | P23: =P22-P21 -> 0 | Q23: =Q22-Q21 -> 0 | R23: =R22-R21 -> 0 | S23: =S22-S21 -> 0 | T23: =N23/$E$14*12/$N$11 -> 0.46522146 | U23: =N23/$E$10 -> 0.032643977
C24: Commission to CAKE | E24: 0.856 | F24: per disbursement amount | H24: done
H25: done
B26: Support fee | F26: per account | K26: PERFORMANCE OUTPUT | U26: Cur: mVND
F27: per ticketsize
N28: Life time | O28: Year 1 | P28: Year 2 | Q28: Year 3 | R28: Year 4 | S28: Year 5 | T28: % ANR | U28: % Disbursement
B29: COST INPUT | H29: Cur: mVND | K29: ANR | N29: =SUM(SAP_Speadsheet!$D$48:$BF$48)/COUNTIF(SAP_Speadsheet!$D$48:$BF$48,">0") -> 0.41787859 | O29: =IFERROR(SUM(SAP_Speadsheet!$D$48:$P$48)/COUNTIF(SAP_Speadsheet!$D$48:$P$48,">0"),0) -> 0.41787859 | P29: =IFERROR(SUM(SAP_Speadsheet!$Q$48:$AB$48)/COUNTIF(SAP_Speadsheet!$Q$48:$AB$48,">0"),0) -> 0 | Q29: =IFERROR(SUM(SAP_Speadsheet!$AC$48:$AN$48)/COUNTIF(SAP_Speadsheet!$AC$48:$AN$48,">0"),0) -> 0 | R29: =IFERROR(SUM(SAP_Speadsheet!$AO$48:$AZ$48)/COUNTIF(SAP_Speadsheet!$AO$48:$AZ$48,">0"),0) -> 0 | S29: =IFERROR(SUM(SAP_Speadsheet!$BA$48:$BF$48)/COUNTIF(SAP_Speadsheet!$BA$48:$BF$48,">0"),0) -> 0 | U29: =N29/$E$10 -> 0.12028917
K30: TOI | N30: =SUM(O30:S30) -> 0.36294935 | O30: =SUM(SAP_Speadsheet!$E$53:$P$53) -> 0.36294935 | P30: =SUM(SAP_Speadsheet!$Q$53:$AB$53) -> 0 | Q30: =SUM(SAP_Speadsheet!$AC$53:$AN$53) -> 0 | R30: =SUM(SAP_Speadsheet!$AO$53:$AZ$53) -> 0 | S30: =SUM(SAP_Speadsheet!$BA$53:$BF$53) -> 0 | T30: =N30/$E$14*12/$N$29 -> 1.4889466 | U30: =N30/$E$10 -> 0.10447742
B31: Inflation rate | E31: 0.035 | F31: % per year | K31: Net interest income | N31: =SUM(O31:S31) -> 0.14306179 | O31: =SUM(SAP_Speadsheet!$E$55:$P$55) -> 0.14306179 | P31: =SUM(SAP_Speadsheet!$Q$55:$AB$55) -> 0 | Q31: =SUM(SAP_Speadsheet!$AC$55:$AN$55) -> 0 | R31: =SUM(SAP_Speadsheet!$AO$55:$AZ$55) -> 0 | S31: =SUM(SAP_Speadsheet!$BA$55:$BF$55) -> 0 | T31: =N31/$E$14*12/$N$29 -> 0.58689003 | U31: =N31/$E$10 -> 0.0411813
K32: Interest income | N32: =SUM(O32:S32) -> 0.15653019 | O32: =SUM(SAP_Speadsheet!$E$56:$P$56) -> 0.15653019 | P32: =SUM(SAP_Speadsheet!$Q$56:$AB$56) -> 0 | Q32: =SUM(SAP_Speadsheet!$AC$56:$AN$56) -> 0 | R32: =SUM(SAP_Speadsheet!$AO$56:$AZ$56) -> 0 | S32: =SUM(SAP_Speadsheet!$BA$56:$BF$56) -> 0 | T32: =N32/$E$14*12/$N$29 -> 0.64214219 | U32: =N32/$E$10 -> 0.045058272
B33: Acquisition cost | K33: Cost of fund | N33: =SUM(O33:S33) -> -0.013468406 | O33: =SUM(SAP_Speadsheet!$E$57:$P$57) -> -0.013468406 | P33: =SUM(SAP_Speadsheet!$Q$57:$AB$57) -> 0 | Q33: =SUM(SAP_Speadsheet!$AC$57:$AN$57) -> 0 | R33: =SUM(SAP_Speadsheet!$AO$57:$AZ$57) -> 0 | S33: =SUM(SAP_Speadsheet!$BA$57:$BF$57) -> 0 | T33: =N33/$E$14*12/$N$29 -> -0.055252162 | U33: =N33/$E$10 -> -0.0038769714
C34: Sale incentive | E34: Auto MODE | K34: Net fee income | N34: =SUM(O34:S34) -> 0.21988757 | O34: =SUM(SAP_Speadsheet!$E$59:$P$59) -> 0.21988757 | P34: =SUM(SAP_Speadsheet!$Q$59:$AB$59) -> 0 | Q34: =SUM(SAP_Speadsheet!$AC$59:$AN$59) -> 0 | R34: =SUM(SAP_Speadsheet!$AO$59:$AZ$59) -> 0 | S34: =SUM(SAP_Speadsheet!$BA$59:$BF$59) -> 0 | T34: =N34/$E$14*12/$N$29 -> 0.90205655 | U34: =N34/$E$10 -> 0.06329612
C35: Sharing TOI and Risk DPD90+ | E35: =DATA!C112 -> 0.31500272 | F35: % per month | K35: Insurance commission | N35: =SUM(O35:S35) -> 0.21988757 | O35: =SUM(SAP_Speadsheet!$E$60:$P$60) -> 0.21988757 | P35: =SUM(SAP_Speadsheet!$Q$60:$AB$60) -> 0 | Q35: =SUM(SAP_Speadsheet!$AC$60:$AN$60) -> 0 | R35: =SUM(SAP_Speadsheet!$AO$60:$AZ$60) -> 0 | S35: =SUM(SAP_Speadsheet!$BA$60:$BF$60) -> 0 | T35: =N35/$E$14*12/$N$29 -> 0.90205655 | U35: =N35/$E$10 -> 0.06329612
C36: Sharing TOI and Risk DPD180+ | F36: % per month | K36: Support fee | N36: =SUM(O36:S36) -> 0 | O36: =SUM(SAP_Speadsheet!$E$61:$P$61) -> 0 | P36: =SUM(SAP_Speadsheet!$Q$61:$AB$61) -> 0 | Q36: =SUM(SAP_Speadsheet!$AC$61:$AN$61) -> 0 | R36: =SUM(SAP_Speadsheet!$AO$61:$AZ$61) -> 0 | S36: =SUM(SAP_Speadsheet!$BA$61:$BF$61) -> 0 | T36: =N36/$E$14*12/$N$29 -> 0 | U36: =N36/$E$10 -> 0
E37: Adjust MODE | K37: Other income | N37: =SUM(O37:S37) -> 0 | O37: =SUM(SAP_Speadsheet!$E$63:$P$63) -> 0 | P37: =SUM(SAP_Speadsheet!$Q$63:$AB$63) -> 0 | Q37: =SUM(SAP_Speadsheet!$AC$63:$AN$63) -> 0 | R37: =SUM(SAP_Speadsheet!$AO$63:$AZ$63) -> 0 | S37: =SUM(SAP_Speadsheet!$BA$63:$BF$63) -> 0 | T37: =N37/$E$14*12/$N$29 -> 0 | U37: =N37/$E$10 -> 0
C38: Sharing CII (only) | F38: % per month | K38: PROVISION | N38: =SUM(O38:S38) -> -0.16371398 | O38: =SUM(SAP_Speadsheet!$E$175:$P$175) -> -0.16371398 | P38: =SUM(SAP_Speadsheet!$Q$175:$AB$175) -> 0 | Q38: =SUM(SAP_Speadsheet!$AC$175:$AN$175) -> 0 | R38: =SUM(SAP_Speadsheet!$AO$175:$AZ$175) -> 0 | S38: =SUM(SAP_Speadsheet!$BA$175:$BF$175) -> 0 | T38: =N38/$E$14*12/$N$29 -> -0.67161265 | U38: =N38/$E$10 -> -0.047126175
C39: Sharing COF (only) | F39: % per month | K39: OPEX | N39: =SUM(O39:S39) -> -0.15047878 | O39: =+SUM(O40,O44,O47,O51) -> -0.15047878 | P39: =+SUM(P40,P44,P47,P51) -> 0 | Q39: =+SUM(Q40,Q44,Q47,Q51) -> 0 | R39: =+SUM(R40,R44,R47,R51) -> 0 | S39: =+SUM(S40,S44,S47,S51) -> 0 | T39: =N39/$E$14*12/$N$29 -> -0.61731718 | U39: =N39/$E$10 -> -0.043316333
C40: Sharing NFI (only) | F40: % per month | K40: Acquisition cost | N40: =SUM(O40:S40) -> -0.059634389 | O40: =SUM(O41:O43) -> -0.059634389 | P40: =SUM(P41:P43) -> 0 | Q40: =SUM(Q41:Q43) -> 0 | R40: =SUM(R41:R43) -> 0 | S40: =SUM(S41:S43) -> 0 | T40: =N40/$E$14*12/$N$29 -> -0.24464135 | U40: =N40/$E$10 -> -0.017166161
C41: Sharing Risk DPD90+ (Only) | F41: % per month | K41: Lead Acquisition | N41: =SUM(O41:S41) -> -2.5773143e-05 | O41: =SUM(SAP_Speadsheet!$E$68:$P$68) -> -2.5773143e-05 | P41: =SUM(SAP_Speadsheet!$Q$68:$AB$68) -> 0 | Q41: =SUM(SAP_Speadsheet!$AC$68:$AN$68) -> 0 | R41: =SUM(SAP_Speadsheet!$AO$68:$AZ$68) -> 0 | S41: =SUM(SAP_Speadsheet!$BA$68:$BF$68) -> 0 | T41: =N41/$E$14*12/$N$29 -> -0.00010573054 | U41: =N41/$E$10 -> -7.418973e-06
C42: Sharing Risk DPD180+ (only) | F42: % per month | K42: Sharing performance | N42: =SUM(O42:S42) -> -0.05898398 | O42: =SUM(SAP_Speadsheet!$E$69:$P$69) -> -0.05898398 | P42: =SUM(SAP_Speadsheet!$Q$69:$AB$69) -> 0 | Q42: =SUM(SAP_Speadsheet!$AC$69:$AN$69) -> 0 | R42: =SUM(SAP_Speadsheet!$AO$69:$AZ$69) -> 0 | S42: =SUM(SAP_Speadsheet!$BA$69:$BF$69) -> 0 | T42: =N42/$E$14*12/$N$29 -> -0.24197314 | U42: =N42/$E$10 -> -0.016978936
...

Sheet DATA
B2: 1. Income
B4: Disburse date | C4: # Disburse | D4: Disburse amount (VND) | E4: Ticket size (VND) | F4: Avg tenor (Day) | G4: Avg IR (%) | H4: Insurance fee (VND) | I4: Insurance penetration by date (%)
B5: 45901 | C5: 137891 | D5: 468373996000 | E5: 3396697.4 | F5: 35.441146 | G5: 57.105322 | H5: 34644786000 | I5: 1 | J5: 1
B6: 45870 | C6: 92113 | D6: 314000196000 | E6: 3408858.6 | F6: 35.57576 | G6: 57.115065 | H6: 23212896000 | I6: 1 | J6: 1
B7: 45839 | C7: 63333 | D7: 236663940000 | E7: 3736818.7 | F7: 34.315286 | G7: 58.071937 | H7: 17494140000 | I7: 1 | J7: 1
B9: Average | C9: =SUM(C5:C7) -> 293337 | D9: =SUM(D5:D7) -> 1019038132000 | E9: =SUM(D5:D7)/SUM(C5:C7) -> 3473950.2 | F9: 1 | G9: =AVERAGE(G5:G7)/100 -> 0.57430775 | H9: =SUM(H5:H7)/(SUM(D5:D7)-SUM(H5:H7)) -> 0.079848379
B13: 2. Cost
C16: Application | D16: Approval | E16: Disburse
C19: %Approval rate | D19: 0.452
C20: %Disburse | D20: 0.942
B36: 3. Risk
B38: Sum of principal balance | C38: Column Labels | L38: bucket | M38: report_month | N38: principal balance
B39: Row Labels | C39: 202506 | D39: 202507 | E39: 202508 | F39: 202509 | G39: Grand Total | L39: B00 | M39: 202403 | N39: 53525927234
B40: B00 | C40: 131698673529 | D40: 187078083967 | E40: 236445987551 | F40: 369412593653 | G40: 924635338700 | L40: B00 | M40: 202410 | N40: 110489281129
B41: B01 | C41: 8562993399 | D41: 8321080207 | E41: 16841740137 | F41: 19418748894 | G41: 53144562637 | L41: B00 | M41: 202412 | N41: 140915432312
B42: B02 | C42: 6582155229 | D42: 6771584609 | E42: 6490477859 | F42: 12894830241 | G42: 32739047938 | L42: B00 | M42: 202502 | N42: 120454958029
B43: B03 | C43: 5344986249 | D43: 5791073866 | E43: 6188608797 | F43: 6147932392 | G43: 23472601304 | L43: B00 | M43: 202401 | N43: 39352047960
B44: B04 | C44: 5550425405 | D44: 5493579313 | E44: 5883465410 | F44: 5987506756 | G44: 22914976884 | L44: B00 | M44: 202509 | N44: 369412593653
B45: B05 | C45: 7003321164 | D45: 5317975948 | E45: 5364248366 | F45: 5783462054 | G45: 23469007532 | L45: B00 | M45: 202506 | N45: 131698673529
B46: B06 | C46: 7227004819 | D46: 7213434708 | E46: 5293575080 | F46: 5291955522 | G46: 25025970129 | L46: B00 | M46: 202504 | N46: 130882226527
B47: B07 | C47: 4256572638 | D47: 6633430860 | E47: 7290287879 | F47: 5217146152 | G47: 23397437529 | L47: B00 | M47: 202407 | N47: 96238663386
B48: B08 | C48: 3923487920 | D48: 4547706832 | E48: 6247258058 | F48: 7217481891 | G48: 21935934701 | L48: B00 | M48: 202510 | N48: 342280626842
B49: B09 | C49: 4477782016 | D49: 4065255065 | E49: 4667227695 | F49: 6247258058 | G49: 19457522834 | L49: B00 | M49: 202503 | N49: 124804871704
B50: B10 | C50: 4648422654 | D50: 4276488143 | E50: 3923514411 | F50: 4667227695 | G50: 17515652903 | L50: B00 | M50: 202405 | N50: 68692214339
B51: B11 | C51: 3882239181 | D51: 4275758471 | E51: 4391942818 | F51: 3923514411 | G51: 16473454881 | L51: B00 | M51: 202501 | N51: 125736974174
... B66: B26 | C66: 99257496 | D66: 906527807 | E66: 1370035303 | F66: 1316039678 | G66: 3691860284 | L66: B01 | M66: 202509 | N66: 19418748894
B67: B27 | D67: 150805186 | E67: 911793752 | F67: 1370035303 | G67: 2432634241 | L67: B01 | M67: 202506 | N67: 8562993399
B68: B28 | E68: 195789186 | F68: 911793752 | G68: 1107582938 | L68: B01 | M68: 202504 | N68: 7406106547
B69: B29 | F69: 195789186 | G69: 195789186 | L69: B01 | M69: 202407 | N69: 5416018045
B70: Grand Total | C70: 222367471511 | D70: 283444108593 | E70: 347103122917 | F70: 494676389393 | G70: 1347591092414 | L70: B01 | M70: 202510 | N70: 27566527723
L71: B01 | M71: 202503 | N71: 8032313372
L72: B01 | M72: 202405 | N72: 3958274941
L73: B01 | M73: 202501 | N73: 10438070154
B74: Row Labels | C74: 202507 | D74: 202508 | E74: 202509 | L74: B01 | M74: 202408 | N74: 6368791795
B75: 0 | C75: =H76/G75 -> 0.063182718 | D75: =I76/H75 -> 0.09002519 | E75: =J76/I75 -> 0.082127631 | F75: =AVERAGE(C75:E75) -> 0.07844518 | G75: 131698673529 | H75: 187078083967 | I75: 236445987551 | J75: 369412593653 | L75: B01 | M75: 202404 | N75: 3672521113
B76: 1 | C76: =H77/G76 -> 0.79079643 | D76: =I77/H76 -> 0.78000424 | E76: =J77/I76 -> 0.76564714 | F76: 0.77 | G76: 8562993399 | H76: 8321080207 | I76: 16841740137 | J76: 19418748894 | L76: B01 | M76: 202409 | N76: 7091212819
B77: 2 | C77: =H78/G77 -> 0.87981423 | D77: =I78/H77 -> 0.91390851 | E77: =J78/I77 -> 0.94722338 | F77: =AVERAGE(C77:E77) -> 0.91364871 | G77: 6582155229 | H77: 6771584609 | I77: 6490477859 | J77: 12894830241 | L77: B01 | M77: 202406 | N77: 4302043622
B78: 3 | C78: =H79/G78 -> 1.0278005 | D78: =I79/H78 -> 1.0159541 | E78: =J79/I78 -> 0.96750448 | F78: =AVERAGE(C78:E78) -> 1.003753 | G78: 5344986249 | H78: 5791073866 | I78: 6188608797 | J78: 6147932392 | L78: B01 | M78: 202508 | N78: 16841740137
B79: 4 | C79: =H80/G79 -> 0.95812043 | D79: =I80/H79 -> 0.9764578 | E79: =J80/I79 -> 0.98300264 | F79: 0.97 | G79: 5550425405 | H79: 5493579313 | I79: 5883465410 | J79: 5987506756 | L79: B01 | M79: 202411 | N79: 6533997439
B80: 5 | C80: =H81/G80 -> 1.030002 | D80: =I81/H80 -> 0.99541162 | E80: =J81/I80 -> 0.98652321 | F80: =AVERAGE(C80:E80) -> 1.0039789 | G80: 7003321164 | H80: 5317975948 | I80: 5364248366 | J80: 5783462054 | L80: B01 | M80: 202507 | N80: 8321080207
...

Sheet SAP_Speadsheet
B1: SAP Speadsheet
C4: Method
C5: Month on book | D5: 0 | E5: =D5+1 -> 1 | F5: =E5+1 -> 2 | G5: =F5+1 -> 3 | H5: =G5+1 -> 4 | I5: =H5+1 -> 5 | J5: =I5+1 -> 6 | K5: =J5+1 -> 7 | L5: =K5+1 -> 8 | ... BL5: =BK5+1 -> 60
C6: Oustanding tenor | D6: =IF(Leadsheet!$E$12-SAP_Speadsheet!D5<0,0,Leadsheet!$E$12-SAP_Speadsheet!D5) -> 1 | E6: =IF(Leadsheet!$E$12-SAP_Speadsheet!E5<0,0,Leadsheet!$E$12-SAP_Speadsheet!E5) -> 0 | F6: =IF(Leadsheet!$E$12-SAP_Speadsheet!F5<0,0,Leadsheet!$E$12-SAP_Speadsheet!F5) -> 0 | G6: =IF(Leadsheet!$E$12-SAP_Speadsheet!G5<0,0,Leadsheet!$E$12-SAP_Speadsheet!G5) -> 0 | H6: =IF(Leadsheet!$E$12-SAP_Speadsheet!H5<0,0,Leadsheet!$E$12-SAP_Speadsheet!H5) -> 0 | I6: =IF(Leadsheet!$E$12-SAP_Speadsheet!I5<0,0,Leadsheet!$E$12-SAP_Speadsheet!I5) -> 0 | J6: =IF(Leadsheet!$E$12-SAP_Speadsheet!J5<0,0,Leadsheet!$E$12-SAP_Speadsheet!J5) -> 0 | K6: =IF(Leadsheet!$E$12-SAP_Speadsheet!K5<0,0,Leadsheet!$E$12-SAP_Speadsheet!K5) -> 0 | ... BL6: =IF(Leadsheet!$E$12-SAP_Speadsheet!BL5<0,0,Leadsheet!$E$12-SAP_Speadsheet!BL5) -> 0
C7: Last month on book | D7: =Leadsheet!E13+Leadsheet!E12 -> 7
B9: Balance
B10: Interest rate
C11: INR rate | D11: =Leadsheet!E18 -> 0.57430775 | E11: =IF(E$5>$D$7,0,VLOOKUP(SAP_Speadsheet!E$5,Leadsheet!$C$18:$F$19,3,1)) -> 0.57430775 | F11: =IF(F$5>$D$7,0,VLOOKUP(SAP_Speadsheet!F$5,Leadsheet!$C$18:$F$19,3,1)) -> 0.57430775 | G11: =IF(G$5>$D$7,0,VLOOKUP(SAP_Speadsheet!G$5,Leadsheet!$C$18:$F$19,3,1)) -> 0.57430775 | H11: =IF(H$5>$D$7,0,VLOOKUP(SAP_Speadsheet!H$5,Leadsheet!$C$18:$F$19,3,1)) -> 0.57430775 | I11: =IF(I$5>$D$7,0,VLOOKUP(SAP_Speadsheet!I$5,Leadsheet!$C$18:$F$19,3,1)) -> 0.57430775 | J11: =IF(J$5>$D$7,0,VLOOKUP(SAP_Speadsheet!J$5,Leadsheet!$C$18:$F$19,3,1)) -> 0.57430775 | K11: =IF(K$5>$D$7,0,VLOOKUP(SAP_Speadsheet!K$5,Leadsheet!$C$18:$F$19,3,1)) -> 0.57430775 | L11: =IF(L$5>$D$7,0,VLOOKUP(SAP_Speadsheet!L$5,Leadsheet!$C$18:$F$19,3,1)) -> 0 | ... BL11: =IF(BL$5>$D$7,0,VLOOKUP(SAP_Speadsheet!BL$5,Leadsheet!$C$18:$F$19,3,1)) -> 0
C12: COF rate | D12: =Leadsheet!F18 -> 0.055252162 | E12: =IF(E$5>$D$7,0,VLOOKUP(SAP_Speadsheet!E$5,Leadsheet!$C$18:$F$19,4,1)) -> 0.055252162 | F12: =IF(F$5>$D$7,0,VLOOKUP(SAP_Speadsheet!F$5,Leadsheet!$C$18:$F$19,4,1)) -> 0.055252162 | G12: =IF(G$5>$D$7,0,VLOOKUP(SAP_Speadsheet!G$5,Leadsheet!$C$18:$F$19,4,1)) -> 0.055252162 | H12: =IF(H$5>$D$7,0,VLOOKUP(SAP_Speadsheet!H$5,Leadsheet!$C$18:$F$19,4,1)) -> 0.055252162 | I12: =IF(I$5>$D$7,0,VLOOKUP(SAP_Speadsheet!I$5,Leadsheet!$C$18:$F$19,4,1)) -> 0.055252162 | J12: =IF(J$5>$D$7,0,VLOOKUP(SAP_Speadsheet!J$5,Leadsheet!$C$18:$F$19,4,1)) -> 0.055252162 | K12: =IF(K$5>$D$7,0,VLOOKUP(SAP_Speadsheet!K$5,Leadsheet!$C$18:$F$19,4,1)) -> 0.055252162 | L12: =IF(L$5>$D$7,0,VLOOKUP(SAP_Speadsheet!L$5,Leadsheet!$C$18:$F$19,4,1)) -> 0 | ... BL12: =IF(BL$5>$D$7,0,VLOOKUP(SAP_Speadsheet!BL$5,Leadsheet!$C$18:$F$19,4,1)) -> 0
C13: Prepayment Penalty | E13: =IF(E$5<Leadsheet!$E$12,VLOOKUP(SAP_Speadsheet!E$5,Leadsheet!#REF!,3,1),0) -> 0 | F13: =IF(F$5<Leadsheet!$E$12,VLOOKUP(SAP_Speadsheet!F$5,Leadsheet!#REF!,3,1),0) -> 0 | G13: =IF(G$5<Leadsheet!$E$12,VLOOKUP(SAP_Speadsheet!G$5,Leadsheet!#REF!,3,1),0) -> 0 | H13: =IF(H$5<Leadsheet!$E$12,VLOOKUP(SAP_Speadsheet!H$5,Leadsheet!#REF!,3,1),0) -> 0 | I13: =IF(I$5<Leadsheet!$E$12,VLOOKUP(SAP_Speadsheet!I$5,Leadsheet!#REF!,3,1),0) -> 0 | J13: =IF(J$5<Leadsheet!$E$12,VLOOKUP(SAP_Speadsheet!J$5,Leadsheet!#REF!,3,1),0) -> 0 | K13: =IF(K$5<Leadsheet!$E$12,VLOOKUP(SAP_Speadsheet!K$5,Leadsheet!#REF!,3,1),0) -> 0 | L13: =IF(L$5<Leadsheet!$E$12,VLOOKUP(SAP_Speadsheet!L$5,Leadsheet!#REF!,3,1),0) -> 0 | ... BL13: =IF(BL$5<Leadsheet!$E$12,VLOOKUP(SAP_Speadsheet!BL$5,Leadsheet!#REF!,3,1),0) -> 0
B15: EMI | C15: Account accumulated | D15: 1 | E15: =IF(E5>$D$7,0,D15) -> 1 | F15: =IF(F5>$D$7,0,E15) -> 1 | G15: =IF(G5>$D$7,0,F15) -> 1 | H15: =IF(H5>$D$7,0,G15) -> 1 | I15: =IF(I5>$D$7,0,H15) -> 1 | J15: =IF(J5>$D$7,0,I15) -> 1 | K15: =IF(K5>$D$7,0,J15) -> 1 | L15: =IF(L5>$D$7,0,K15) -> 0 | ... BL15: =IF(BL5>$D$7,0,BK15) -> 0
C16: Nominal ENR | D16: =Leadsheet!E10 -> 3.4739502 | E16: =IF(E$5>Leadsheet!$E$12,0,D16+E19) -> 8.8817842e-16 | F16: =IF(F$5>Leadsheet!$E$12,0,E16+F19) -> 0 | G16: =IF(G$5>Leadsheet!$E$12,0,F16+G19) -> 0 | H16: =IF(H$5>Leadsheet!$E$12,0,G16+H19) -> 0 | I16: =IF(I$5>Leadsheet!$E$12,0,H16+I19) -> 0 | J16: =IF(J$5>Leadsheet!$E$12,0,I16+J19) -> 0 | K16: =IF(K$5>Leadsheet!$E$12,0,J16+K19) -> 0 | L16: =IF(L$5>Leadsheet!$E$12,0,K16+L19) -> 0 | ... BL16: =IF(BL$5>Leadsheet!$E$12,0,BK16+BL19) -> 0
C17: EMI payment | E17: =-IFERROR(PMT(D11/12,D6,-D16),0) -> -3.6402099 | F17: =-IFERROR(PMT(E11/12,E6,-E16),0) -> 0 | G17: =-IFERROR(PMT(F11/12,F6,-F16),0) -> 0 | H17: =-IFERROR(PMT(G11/12,G6,-G16),0) -> 0 | I17: =-IFERROR(PMT(H11/12,H6,-H16),0) -> 0 | J17: =-IFERROR(PMT(I11/12,I6,-I16),0) -> 0 | K17: =-IFERROR(PMT(J11/12,J6,-J16),0) -> 0 | L17: =-IFERROR(PMT(K11/12,K6,-K16),0) -> 0 | ... BL17: =-IFERROR(PMT(BK11/12,BK6,-BK16),0) -> 0
C18: Nominal Interest | E18: =-IF(E5>$D$6,0,D16*D11/12) -> -0.16625971 | F18: =-IF(F5>$D$6,0,E16*E11/12) -> 0 | G18: =-IF(G5>$D$6,0,F16*F11/12) -> 0 | H18: =-IF(H5>$D$6,0,G16*G11/12) -> 0 | I18: =-IF(I5>$D$6,0,H16*H11/12) -> 0 | J18: =-IF(J5>$D$6,0,I16*I11/12) -> 0 | K18: =-IF(K5>$D$6,0,J16*J11/12) -> 0 | L18: =-IF(L5>$D$6,0,K16*K11/12) -> 0 | ... BL18: =-IF(BL5>$D$6,0,BK16*BK11/12) -> 0
C19: Nominal Payment | E19: =E17-E18 -> -3.4739502 | F19: =F17-F18 -> 0 | G19: =G17-G18 -> 0 | H19: =H17-H18 -> 0 | I19: =I17-I18 -> 0 | J19: =J17-J18 -> 0 | K19: =K17-K18 -> 0 | L19: =L17-L18 -> 0 | ... BL19: =BL17-BL18 -> 0
C22: Schedule Payment | E22: =IF(E5>Leadsheet!$E$12,0,IFERROR(E19/D16*D25*(1-Leadsheet!$D$76),0)) -> -3.20993 | F22: =IF(F5>Leadsheet!$E$12,0,IFERROR(F19/E16*E25*(1-Leadsheet!$D$76),0)) -> 0 | G22: =IF(G5>Leadsheet!$E$12,0,IFERROR(G19/F16*F25*(1-Leadsheet!$D$76),0)) -> 0 | H22: =IF(H5>Leadsheet!$E$12,0,IFERROR(H19/G16*G25*(1-Leadsheet!$D$76),0)) -> 0 | I22: =IF(I5>Leadsheet!$E$12,0,IFERROR(I19/H16*H25*(1-Leadsheet!$D$76),0)) -> 0 | J22: =IF(J5>Leadsheet!$E$12,0,IFERROR(J19/I16*I25*(1-Leadsheet!$D$76),0)) -> 0 | K22: =IF(K5>Leadsheet!$E$12,0,IFERROR(K19/J16*J25*(1-Leadsheet!$D$76),0)) -> 0 | L22: =IF(L5>Leadsheet!$E$12,0,IFERROR(L19/K16*K25*(1-Leadsheet!$D$76),0)) -> 0 | ... BL22: =IF(BL5>Leadsheet!$E$12,0,IFERROR(BL19/BK16*BK25*(1-Leadsheet!$D$76),0)) -> 0
A24: SBV | B24: Overdue | C24: Balance by Bucket/Group
A25: G1 | B25: 0 | C25: B0 | D25: =Leadsheet!E10 -> 3.4739502 | E25: =IF(E5>=Leadsheet!$E$12,0,D42+E22-SUM(E26:E39)) -> 0 | F25: =IF(F5>=Leadsheet!$E$12,0,E42+F22-SUM(F26:F39)) -> 0 | G25: =IF(G5>=Leadsheet!$E$12,0,F42+G22-SUM(G26:G39)) -> 0 | H25: =IF(H5>=Leadsheet!$E$12,0,G42+H22-SUM(H26:H39)) -> 0 | I25: =IF(I5>=Leadsheet!$E$12,0,H42+I22-SUM(I26:I39)) -> 0 | J25: =IF(J5>=Leadsheet!$E$12,0,I42+J22-SUM(J26:J39)) -> 0 | K25: =IF(K5>=Leadsheet!$E$12,0,J42+K22-SUM(K26:K39)) -> 0 | L25: =IF(L5>=Leadsheet!$E$12,0,K42+L22-SUM(L26:L39)) -> 0 | ... BL25: =IF(BL5>=Leadsheet!$E$12,0,BK42+BL22-SUM(BL26:BL39)) -> 0
A26: G2 | B26: 30 | C26: B1 | E26: =IF(E$5>$D$7,0,D25*Leadsheet!$D76) -> 0.26402022 | F26: =IF(F$5>$D$7,0,E25*Leadsheet!$D76) -> 0 | G26: =IF(G$5>$D$7,0,F25*Leadsheet!$D76) -> 0 | H26: =IF(H$5>$D$7,0,G25*Leadsheet!$D76) -> 0 | I26: =IF(I$5>$D$7,0,H25*Leadsheet!$D76) -> 0 | J26: =IF(J$5>$D$7,0,I25*Leadsheet!$D76) -> 0 | K26: =IF(K$5>$D$7,0,J25*Leadsheet!$D76) -> 0 | L26: =IF(L$5>$D$7,0,K25*Leadsheet!$D76) -> 0 | ... BL26: =IF(BL$5>$D$7,0,BK25*Leadsheet!$D76) -> 0
A27: G2 | B27: 60 | C27: B2 | E27: =IF(E$5>$D$7,0,D26*Leadsheet!$D77) -> 0 | F27: =IF(F$5>$D$7,0,E26*Leadsheet!$D77) -> 0.20329557 | G27: =IF(G$5>$D$7,0,F26*Leadsheet!$D77) -> 0 | H27: =IF(H$5>$D$7,0,G26*Leadsheet!$D77) -> 0 | I27: =IF(I$5>$D$7,0,H26*Leadsheet!$D77) -> 0 | J27: =IF(J$5>$D$7,0,I26*Leadsheet!$D77) -> 0 | K27: =IF(K$5>$D$7,0,J26*Leadsheet!$D77) -> 0 | L27: =IF(L$5>$D$7,0,K26*Leadsheet!$D77) -> 0 | ... BL27: =IF(BL$5>$D$7,0,BK26*Leadsheet!$D77) -> 0
A28: G2 | B28: 90 | C28: B3 | E28: =IF(E$5>$D$7,0,D27*Leadsheet!$D78) -> 0 | F28: =IF(F$5>$D$7,0,E27*Leadsheet!$D78) -> 0 | G28: =IF(G$5>$D$7,0,F27*Leadsheet!$D78) -> 0.18574073 | H28: =IF(H$5>$D$7,0,G27*Leadsheet!$D78) -> 0 | I28: =IF(I$5>$D$7,0,H27*Leadsheet!$D78) -> 0 | J28: =IF(J$5>$D$7,0,I27*Leadsheet!$D78) -> 0 | K28: =IF(K$5>$D$7,0,J27*Leadsheet!$D78) -> 0 | L28: =IF(L$5>$D$7,0,K27*Leadsheet!$D78) -> 0 | ... AU28: =IF(AU$5>$D$7,0,AT27*Leadsheet!$D78) -> 0 | AV28: 0 | AW28: =IF(AW$5>$D$7,0,AV27*Leadsheet!$D78) -> 0 | AX28: =IF(AX$5>$D$7,0,AW27*Leadsheet!$D78) -> 0 | AY28: =IF(AY$5>$D$7,0,AX27*Leadsheet!$D78) -> 0 | AZ28: =IF(AZ$5>$D$7,0,AY27*Leadsheet!$D78) -> 0 | BA28: =IF(BA$5>$D$7,0,AZ27*Leadsheet!$D78) -> 0 | BB28: =IF(BB$5>$D$7,0,BA27*Leadsheet!$D78) -> 0 | BC28: =IF(BC$5>$D$7,0,BB27*Leadsheet!$D78) -> 0 | BD28: =IF(BD$5>$D$7,0,BC27*Leadsheet!$D78) -> 0 | ... BL28: =IF(BL$5>$D$7,0,BK27*Leadsheet!$D78) -> 0
A29: G3 | B29: 120 | C29: B4 | E29: =IF(E$5>$D$7,0,D28*Leadsheet!$D79) -> 0 | F29: =IF(F$5>$D$7,0,E28*Leadsheet!$D79) -> 0 | G29: =IF(G$5>$D$7,0,F28*Leadsheet!$D79) -> 0 | H29: =IF(H$5>$D$7,0,G28*Leadsheet!$D79) -> 0.18016851 | I29: =IF(I$5>$D$7,0,H28*Leadsheet!$D79) -> 0 | J29: =IF(J$5>$D$7,0,I28*Leadsheet!$D79) -> 0 | K29: =IF(K$5>$D$7,0,J28*Leadsheet!$D79) -> 0 | L29: =IF(L$5>$D$7,0,K28*Leadsheet!$D79) -> 0 | ... BL29: =IF(BL$5>$D$7,0,BK28*Leadsheet!$D79) -> 0
A30: G3 | B30: 150 | C30: B5 | E30: =IF(E$5>$D$7,0,D29*Leadsheet!$D80) -> 0 | F30: =IF(F$5>$D$7,0,E29*Leadsheet!$D80) -> 0 | G30: =IF(G$5>$D$7,0,F29*Leadsheet!$D80) -> 0 | H30: =IF(H$5>$D$7,0,G29*Leadsheet!$D80) -> 0 | I30: =IF(I$5>$D$7,0,H29*Leadsheet!$D80) -> 0.17836682 | J30: =IF(J$5>$D$7,0,I29*Leadsheet!$D80) -> 0 | K30: =IF(K$5>$D$7,0,J29*Leadsheet!$D80) -> 0 | L30: =IF(L$5>$D$7,0,K29*Leadsheet!$D80) -> 0 | ... BL30: =IF(BL$5>$D$7,0,BK29*Leadsheet!$D80) -> 0
A31: G3 | B31: 180 | C31: B6 | E31: =IF(E$5>$D$7,0,D30*Leadsheet!$D81) -> 0 | F31: =IF(F$5>$D$7,0,E30*Leadsheet!$D81) -> 0 | G31: =IF(G$5>$D$7,0,F30*Leadsheet!$D81) -> 0 | H31: =IF(H$5>$D$7,0,G30*Leadsheet!$D81) -> 0 | I31: =IF(I$5>$D$7,0,H30*Leadsheet!$D81) -> 0 | J31: =IF(J$5>$D$7,0,I30*Leadsheet!$D81) -> 0.17658316 | K31: =IF(K$5>$D$7,0,J30*Leadsheet!$D81) -> 0 | L31: =IF(L$5>$D$7,0,K30*Leadsheet!$D81) -> 0 | ... BL31: =IF(BL$5>$D$7,0,BK30*Leadsheet!$D81) -> 0
A32: G4 | B32: 210 | C32: B7 | E32: =IF(E$5>$D$7,0,D31*Leadsheet!$D82) -> 0 | F32: =IF(F$5>$D$7,0,E31*Leadsheet!$D82) -> 0 | G32: =IF(G$5>$D$7,0,F31*Leadsheet!$D82) -> 0 | H32: =IF(H$5>$D$7,0,G31*Leadsheet!$D82) -> 0 | I32: =IF(I$5>$D$7,0,H31*Leadsheet!$D82) -> 0 | J32: =IF(J$5>$D$7,0,I31*Leadsheet!$D82) -> 0 | K32: =IF(K$5>$D$7,0,J31*Leadsheet!$D82) -> 0.17570024 | L32: =IF(L$5>$D$7,0,K31*Leadsheet!$D82) -> 0 | ... BL32: =IF(BL$5>$D$7,0,BK31*Leadsheet!$D82) -> 0
A33: G4 | B33: 240 | C33: B8 | E33: =IF(E$5>$D$7,0,D32*Leadsheet!$D83) -> 0 | F33: =IF(F$5>$D$7,0,E32*Leadsheet!$D83) -> 0 | G33: =IF(G$5>$D$7,0,F32*Leadsheet!$D83) -> 0 | H33: =IF(H$5>$D$7,0,G32*Leadsheet!$D83) -> 0 | I33: =IF(I$5>$D$7,0,H32*Leadsheet!$D83) -> 0 | J33: =IF(J$5>$D$7,0,I32*Leadsheet!$D83) -> 0 | K33: =IF(K$5>$D$7,0,J32*Leadsheet!$D83) -> 0 | L33: =IF(L$5>$D$7,0,K32*Leadsheet!$D83) -> 0 | ... BL33: =IF(BL$5>$D$7,0,BK32*Leadsheet!$D83) -> 0
A34: G4 | B34: 270 | C34: B9 | E34: =IF(E$5>$D$7,0,D33*Leadsheet!$D84) -> 0 | F34: =IF(F$5>$D$7,0,E33*Leadsheet!$D84) -> 0 | G34: =IF(G$5>$D$7,0,F33*Leadsheet!$D84) -> 0 | H34: =IF(H$5>$D$7,0,G33*Leadsheet!$D84) -> 0 | I34: =IF(I$5>$D$7,0,H33*Leadsheet!$D84) -> 0 | J34: =IF(J$5>$D$7,0,I33*Leadsheet!$D84) -> 0 | K34: =IF(K$5>$D$7,0,J33*Leadsheet!$D84) -> 0 | L34: =IF(L$5>$D$7,0,K33*Leadsheet!$D84) -> 0 | ... BL34: =IF(BL$5>$D$7,0,BK33*Leadsheet!$D84) -> 0
A35: G4 | B35: 300 | C35: B10 | E35: =IF(E$5>$D$7,0,D34*Leadsheet!$D85) -> 0 | F35: =IF(F$5>$D$7,0,E34*Leadsheet!$D85) -> 0 | G35: =IF(G$5>$D$7,0,F34*Leadsheet!$D85) -> 0 | H35: =IF(H$5>$D$7,0,G34*Leadsheet!$D85) -> 0 | I35: =IF(I$5>$D$7,0,H34*Leadsheet!$D85) -> 0 | J35: =IF(J$5>$D$7,0,I34*Leadsheet!$D85) -> 0 | K35: =IF(K$5>$D$7,0,J34*Leadsheet!$D85) -> 0 | L35: =IF(L$5>$D$7,0,K34*Leadsheet!$D85) -> 0 | ... BL35: =IF(BL$5>$D$7,0,BK34*Leadsheet!$D85) -> 0
A36: G4 | B36: 330 | C36: B11 | E36: =IF(E$5>$D$7,0,D35*Leadsheet!$D86) -> 0 | F36: =IF(F$5>$D$7,0,E35*Leadsheet!$D86) -> 0 | G36: =IF(G$5>$D$7,0,F35*Leadsheet!$D86) -> 0 | H36: =IF(H$5>$D$7,0,G35*Leadsheet!$D86) -> 0 | I36: =IF(I$5>$D$7,0,H35*Leadsheet!$D86) -> 0 | J36: =IF(J$5>$D$7,0,I35*Leadsheet!$D86) -> 0 | K36: =IF(K$5>$D$7,0,J35*Leadsheet!$D86) -> 0 | L36: =IF(L$5>$D$7,0,K35*Leadsheet!$D86) -> 0 | ... BL36: =IF(BL$5>$D$7,0,BK35*Leadsheet!$D86) -> 0
A37: G4 | B37: 360 | C37: B12 | E37: =IF(E$5>$D$7,0,D36*Leadsheet!$D87) -> 0 | F37: =IF(F$5>$D$7,0,E36*Leadsheet!$D87) -> 0 | G37: =IF(G$5>$D$7,0,F36*Leadsheet!$D87) -> 0 | H37: =IF(H$5>$D$7,0,G36*Leadsheet!$D87) -> 0 | I37: =IF(I$5>$D$7,0,H36*Leadsheet!$D87) -> 0 | J37: =IF(J$5>$D$7,0,I36*Leadsheet!$D87) -> 0 | K37: =IF(K$5>$D$7,0,J36*Leadsheet!$D87) -> 0 | L37: =IF(L$5>$D$7,0,K36*Leadsheet!$D87) -> 0 | ... BL37: =IF(BL$5>$D$7,0,BK36*Leadsheet!$D87) -> 0
A38: G5 | B38: 390 | C38: B13 | E38: =IF(E$5>$D$7,0,D37*Leadsheet!$D88) -> 0 | F38: =IF(F$5>$D$7,0,E37*Leadsheet!$D88) -> 0 | G38: =IF(G$5>$D$7,0,F37*Leadsheet!$D88) -> 0 | H38: =IF(H$5>$D$7,0,G37*Leadsheet!$D88) -> 0 | I38: =IF(I$5>$D$7,0,H37*Leadsheet!$D88) -> 0 | J38: =IF(J$5>$D$7,0,I37*Leadsheet!$D88) -> 0 | K38: =IF(K$5>$D$7,0,J37*Leadsheet!$D88) -> 0 | L38: =IF(L$5>$D$7,0,K37*Leadsheet!$D88) -> 0 | ... BL38: =IF(BL$5>$D$7,0,BK37*Leadsheet!$D88) -> 0
A39: G5 | B39: 420+ | C39: B14+ | E39: =IF(E5>$D$7,0,D38+D39) -> 0 | F39: =IF(F5>$D$7,0,E38+E39) -> 0 | G39: =IF(G5>$D$7,0,F38+F39) -> 0 | H39: =IF(H5>$D$7,0,G38+G39) -> 0 | I39: =IF(I5>$D$7,0,H38+H39) -> 0 | J39: =IF(J5>$D$7,0,I38+I39) -> 0 | K39: =IF(K5>$D$7,0,J38+J39) -> 0 | L39: =IF(L5>$D$7,0,K38+K39) -> 0 | ... BL39: =IF(BL5>$D$7,0,BK38+BK39) -> 0
B41: ENR
C42: Total bank | D42: =SUM(D25:D39) -> 3.4739502 | E42: =SUM(E25:E39) -> 0.26402022 | F42: =SUM(F25:F39) -> 0.20329557 | G42: =SUM(G25:G39) -> 0.18574073 | H42: =SUM(H25:H39) -> 0.18016851 | I42: =SUM(I25:I39) -> 0.17836682 | J42: =SUM(J25:J39) -> 0.17658316 | K42: =SUM(K25:K39) -> 0.17570024 | ... BL42: =SUM(BL25:BL39) -> 0
C43: Outstanding balance | D43: {=IF(D5=$D$7,0,_xlfn.IFS(Leadsheet!$G$5="DPD360+",SUM(SAP_Speadsheet!D25:D38),Leadsheet!$G$5="DPD180+",SUM(SAP_Speadsheet!D25:D32)))} -> 3.4739502 | E43: {=IF(E5=$D$7,0,_xlfn.IFS(Leadsheet!$G$5="DPD360+",SUM(SAP_Speadsheet!E25:E38),Leadsheet!$G$5="DPD180+",SUM(SAP_Speadsheet!E25:E32)))} -> 0.26402022 | F43: {=IF(F5=$D$7,0,_xlfn.IFS(Leadsheet!$G$5="DPD360+",SUM(SAP_Speadsheet!F25:F38),Leadsheet!$G$5="DPD180+",SUM(SAP_Speadsheet!F25:F32)))} -> 0.20329557 | G43: {=IF(G5=$D$7,0,_xlfn.IFS(Leadsheet!$G$5="DPD360+",SUM(SAP_Speadsheet!G25:G38),Leadsheet!$G$5="DPD180+",SUM(SAP_Speadsheet!G25:G32)))} -> 0.18574073 | H43: {=IF(H5=$D$7,0,_xlfn.IFS(Leadsheet!$G$5="DPD360+",SUM(SAP_Speadsheet!H25:H38),Leadsheet!$G$5="DPD180+",SUM(SAP_Speadsheet!H25:H32)))} -> 0.18016851 | I43: {=IF(I5=$D$7,0,_xlfn.IFS(Leadsheet!$G$5="DPD360+",SUM(SAP_Speadsheet!I25:I38),Leadsheet!$G$5="DPD180+",SUM(SAP_Speadsheet!I25:I32)))} -> 0.17836682 | J43: {=IF(J5=$D$7,0,_xlfn.IFS(Leadsheet!$G$5="DPD360+",SUM(SAP_Speadsheet!J25:J38),Leadsheet!$G$5="DPD180+",SUM(SAP_Speadsheet!J25:J32)))} -> 0.17658316 | K43: {=IF(K5=$D$7,0,_xlfn.IFS(Leadsheet!$G$5="DPD360+",SUM(SAP_Speadsheet!K25:K38),Leadsheet!$G$5="DPD180+",SUM(SAP_Speadsheet!K25:K32)))} -> 0 | ... BL43: {=IF(BL5=$D$7,0,_xlfn.IFS(Leadsheet!$G$5="DPD360+",SUM(SAP_Speadsheet!BL25:BL38),Leadsheet!$G$5="DPD180+",SUM(SAP_Speadsheet!BL25:BL32)))} -> 0
C44: Writeoff balance | D44: =D42-D43 -> 0 | E44: =E42-E43 -> 0 | F44: =F42-F43 -> 0 | G44: =G42-G43 -> 0 | H44: =H42-H43 -> 0 | I44: =I42-I43 -> 0 | J44: =J42-J43 -> 0 | K44: =K42-K43 -> 0.17570024 | ... BL44: =BL42-BL43 -> 0
C45: Outstanding Bal/TB | D45: =IFERROR(D43/D42,"") -> 1 | E45: =IFERROR(E43/E42,"") -> 1 | F45: =IFERROR(F43/F42,"") -> 1 | G45: =IFERROR(G43/G42,"") -> 1 | H45: =IFERROR(H43/H42,"") -> 1 | I45: =IFERROR(I43/I42,"") -> 1 | J45: =IFERROR(J43/J42,"") -> 1 | K45: =IFERROR(K43/K42,"") -> 0 | ... BL45: =IFERROR(BL43/BL42,"")
B47: ANR
C48: Outstanding balance | E48: =IF(E5>$D$7,0,AVERAGE(D43:E43)) -> 1.8689852 | F48: =IF(F5>$D$7,0,AVERAGE(E43:F43)) -> 0.23365789 | G48: =IF(G5>$D$7,0,AVERAGE(F43:G43)) -> 0.19451815 | H48: =IF(H5>$D$7,0,AVERAGE(G43:H43)) -> 0.18295462 | I48: =IF(I5>$D$7,0,AVERAGE(H43:I43)) -> 0.17926767 | J48: =IF(J5>$D$7,0,AVERAGE(I43:J43)) -> 0.17747499 | K48: =IF(K5>$D$7,0,AVERAGE(J43:K43)) -> 0.088291578 | L48: =IF(L5>$D$7,0,AVERAGE(K43:L43)) -> 0 | ... BL48: =IF(BL5>$D$7,0,AVERAGE(BK43:BL43)) -> 0
C49: ANR for CII (B0+B1A) | E49: =D25*(1-Leadsheet!$D$76)+D26*Leadsheet!$E$100 -> 3.20993 | F49: =E25*(1-Leadsheet!$D$76)+E26*Leadsheet!$E$100 -> 0.06072465 | G49: =F25*(1-Leadsheet!$D$76)+F26*Leadsheet!$E$100 -> 0 | H49: =G25*(1-Leadsheet!$D$76)+G26*Leadsheet!$E$100 -> 0 | I49: =H25*(1-Leadsheet!$D$76)+H26*Leadsheet!$E$100 -> 0 | J49: =I25*(1-Leadsheet!$D$76)+I26*Leadsheet!$E$100 -> 0 | K49: =J25*(1-Leadsheet!$D$76)+J26*Leadsheet!$E$100 -> 0 | L49: =K25*(1-Leadsheet!$D$76)+K26*Leadsheet!$E$100 -> 0 | ... BL49: =BK25*(1-Leadsheet!$D$76)+BK26*Leadsheet!$E$100 -> 0
...

Sheet Saleplan&PnL
C1: PROFIT & LOSS 60M
C2: I. | D2: SALES PLAN
C4: Business month | D4: 45658 | E4: =EOMONTH(D4,1) -> 45716 | F4: =EOMONTH(E4,1) -> 45747 | G4: =EOMONTH(F4,1) -> 45777 | H4: =EOMONTH(G4,1) -> 45808 | I4: =EOMONTH(H4,1) -> 45838 | J4: =EOMONTH(I4,1) -> 45869 | K4: =EOMONTH(J4,1) -> 45900 | L4: =EOMONTH(K4,1) -> 45930 | ... BL4: =EOMONTH(BK4,1) -> 47514
C5: Don't delete | D5: =YEAR(D4) -> 2025 | E5: =YEAR(E4) -> 2025 | F5: =YEAR(F4) -> 2025 | G5: =YEAR(G4) -> 2025 | H5: =YEAR(H4) -> 2025 | I5: =YEAR(I4) -> 2025 | J5: =YEAR(J4) -> 2025 | K5: =YEAR(K4) -> 2025 | ... BL5: =YEAR(BL4) -> 2030
C6: New disbursement (bVND) | G6: =DATA!D7/10^9 -> 236.66394 | H6: =DATA!D6/10^9 -> 314.0002 | I6: =DATA!D5/10^9 -> 468.374
C8: II. | D8: PROFIT & LOSS
C10: FISCAL YEAR | E10: Total | F10: =YEAR(D4) -> 2025 | G10: =F10+1 -> 2026 | H10: =G10+1 -> 2027 | I10: =H10+1 -> 2028 | J10: =I10+1 -> 2029 | K10: =J10+1 -> 2030
E11: bVND | F11: bVND | G11: bVND | H11: bVND | I11: bVND | J11: bVND | K11: bVND
C13: NEW DISBURSAL | E13: =SUM(F13:O13) -> 1019.0381 | F13: =SUMIF($D$5:$BL$5,F$10,$D$6:$BL$6) -> 1019.0381 | G13: =SUMIF($D$5:$BL$5,G$10,$D$6:$BL$6) -> 0 | H13: =SUMIF($D$5:$BL$5,H$10,$D$6:$BL$6) -> 0 | I13: =SUMIF($D$5:$BL$5,I$10,$D$6:$BL$6) -> 0 | J13: =SUMIF($D$5:$BL$5,J$10,$D$6:$BL$6) -> 0 | K13: =SUMIF($D$5:$BL$5,K$10,$D$6:$BL$6) -> 0
C14: Monthly disbursement | E14: =IFERROR(AVERAGE(D6:AM6),0) -> 339.67938 | F14: =IFERROR(F13/COUNTIFS($D$5:$BL$5,F10,$D$6:$BL$6,"<>"&""),0) -> 339.67938 | G14: =IFERROR(G13/COUNTIFS($D$5:$BL$5,G10,$D$6:$BL$6,"<>"&""),0) -> 0 | H14: =IFERROR(H13/COUNTIFS($D$5:$BL$5,H10,$D$6:$BL$6,"<>"&""),0) -> 0 | I14: =IFERROR(I13/COUNTIFS($D$5:$BL$5,I10,$D$6:$BL$6,"<>"&""),0) -> 0 | J14: =IFERROR(J13/COUNTIFS($D$5:$BL$5,J10,$D$6:$BL$6,"<>"&""),0) -> 0 | K14: =IFERROR(K13/COUNTIFS($D$5:$BL$5,K10,$D$6:$BL$6,"<>"&""),0) -> 0
C16: EOP | F16: =OFFSET(PnL_Speadsheet!$A$7,0,MATCH(DATE('Saleplan&PnL'!F$10,12,31),PnL_Speadsheet!$B$4:$BI$4,0))/1000 -> 23.688785 | G16: =OFFSET(PnL_Speadsheet!$A$7,0,MATCH(DATE('Saleplan&PnL'!G$10,12,31),PnL_Speadsheet!$B$4:$BI$4,0))/1000 -> 0 | H16: =OFFSET(PnL_Speadsheet!$A$7,0,MATCH(DATE('Saleplan&PnL'!H$10,12,31),PnL_Speadsheet!$B$4:$BI$4,0))/1000 -> 0 | I16: =OFFSET(PnL_Speadsheet!$A$7,0,MATCH(DATE('Saleplan&PnL'!I$10,12,31),PnL_Speadsheet!$B$4:$BI$4,0))/1000 -> 0 | J16: =OFFSET(PnL_Speadsheet!$A$7,0,MATCH(DATE('Saleplan&PnL'!J$10,12,31),PnL_Speadsheet!$B$4:$BI$4,0))/1000 -> 0 | K16: =IFERROR(OFFSET(PnL_Speadsheet!$A$7,0,MATCH(DATE('Saleplan&PnL'!K$10,12,31),PnL_Speadsheet!$B$4:$BI$4,0))/1000,0) -> 0
C17: ADB | E17: =IFERROR(SUM(PnL_Speadsheet!B8:AK8)/1000/COUNTIFS(PnL_Speadsheet!B8:BI8,"<>0"&""),0) -> 95.339417 | F17: =IFERROR(SUMIF(PnL_Speadsheet!$B$3:$BI$3,F$10,PnL_Speadsheet!$B8:$BI8)/1000/COUNTIFS(PnL_Speadsheet!$B$3:$BI$3,'Saleplan&PnL'!F$10,PnL_Speadsheet!$B$8:$BI$8,"<>0"),0) -> 95.339417 | G17: =IFERROR(SUMIF(PnL_Speadsheet!$B$3:$BI$3,G$10,PnL_Speadsheet!$B8:$BI8)/1000/COUNTIFS(PnL_Speadsheet!$B$3:$BI$3,'Saleplan&PnL'!G$10,PnL_Speadsheet!$B$8:$BI$8,"<>0"),0) -> 0 | H17: =IFERROR(SUMIF(PnL_Speadsheet!$B$3:$BI$3,H$10,PnL_Speadsheet!$B8:$BI8)/1000/COUNTIFS(PnL_Speadsheet!$B$3:$BI$3,'Saleplan&PnL'!H$10,PnL_Speadsheet!$B$8:$BI$8,"<>0"),0) -> 0 | I17: =IFERROR(SUMIF(PnL_Speadsheet!$B$3:$BI$3,I$10,PnL_Speadsheet!$B8:$BI8)/1000/COUNTIFS(PnL_Speadsheet!$B$3:$BI$3,'Saleplan&PnL'!I$10,PnL_Speadsheet!$B$8:$BI$8,"<>0"),0) -> 0 | J17: =IFERROR(SUMIF(PnL_Speadsheet!$B$3:$BI$3,J$10,PnL_Speadsheet!$B8:$BI8)/1000/COUNTIFS(PnL_Speadsheet!$B$3:$BI$3,'Saleplan&PnL'!J$10,PnL_Speadsheet!$B$8:$BI$8,"<>0"),0) -> 0 | K17: =IFERROR(SUMIF(PnL_Speadsheet!$B$3:$BI$3,K$10,PnL_Speadsheet!$B8:$BI8)/1000/COUNTIFS(PnL_Speadsheet!$B$3:$BI$3,'Saleplan&PnL'!K$10,PnL_Speadsheet!$B$8:$BI$8,"<>0"),0) -> 0
C19: TOI | E19: =SUM(F19:O19) -> 106.46647 | F19: =SUMIF(PnL_Speadsheet!$B$3:$BI$3,F$10,PnL_Speadsheet!$B9:$BI9)/1000 -> 106.46647 | G19: =SUMIF(PnL_Speadsheet!$B$3:$BI$3,G$10,PnL_Speadsheet!$B9:$BI9)/1000 -> 0 | H19: =SUMIF(PnL_Speadsheet!$B$3:$BI$3,H$10,PnL_Speadsheet!$B9:$BI9)/1000 -> 0 | I19: =SUMIF(PnL_Speadsheet!$B$3:$BI$3,I$10,PnL_Speadsheet!$B9:$BI9)/1000 -> 0 | J19: =SUMIF(PnL_Speadsheet!$B$3:$BI$3,J$10,PnL_Speadsheet!$B9:$BI9)/1000 -> 0 | K19: =SUMIF(PnL_Speadsheet!$B$3:$BI$3,K$10,PnL_Speadsheet!$B9:$BI9)/1000 -> 0
C20: NII | E20: =SUM(F20:O20) -> 41.965315 | F20: =SUMIF(PnL_Speadsheet!$B$3:$BI$3,F$10,PnL_Speadsheet!$B11:$BI11)/1000 -> 41.965315 | G20: =SUMIF(PnL_Speadsheet!$B$3:$BI$3,G$10,PnL_Speadsheet!$B11:$BI11)/1000 -> 0 | H20: =SUMIF(PnL_Speadsheet!$B$3:$BI$3,H$10,PnL_Speadsheet!$B11:$BI11)/1000 -> 0 | I20: =SUMIF(PnL_Speadsheet!$B$3:$BI$3,I$10,PnL_Speadsheet!$B11:$BI11)/1000 -> 0 | J20: =SUMIF(PnL_Speadsheet!$B$3:$BI$3,J$10,PnL_Speadsheet!$B11:$BI11)/1000 -> 0 | K20: =SUMIF(PnL_Speadsheet!$B$3:$BI$3,K$10,PnL_Speadsheet!$B11:$BI11)/1000 -> 0
C21: NFI | E21: =SUM(F21:O21) -> 64.50116 | F21: =SUMIF(PnL_Speadsheet!$B$3:$BI$3,F$10,PnL_Speadsheet!$B14:$BI14)/1000 -> 64.50116 | G21: =SUMIF(PnL_Speadsheet!$B$3:$BI$3,G$10,PnL_Speadsheet!$B14:$BI14)/1000 -> 0 | H21: =SUMIF(PnL_Speadsheet!$B$3:$BI$3,H$10,PnL_Speadsheet!$B14:$BI14)/1000 -> 0 | I21: =SUMIF(PnL_Speadsheet!$B$3:$BI$3,I$10,PnL_Speadsheet!$B14:$BI14)/1000 -> 0 | J21: =SUMIF(PnL_Speadsheet!$B$3:$BI$3,J$10,PnL_Speadsheet!$B14:$BI14)/1000 -> 0 | K21: =SUMIF(PnL_Speadsheet!$B$3:$BI$3,K$10,PnL_Speadsheet!$B14:$BI14)/1000 -> 0
C22: Other TOI | E22: =SUM(F22:O22) -> 0 | F22: =SUMIF(PnL_Speadsheet!$B$3:$BI$3,F$10,PnL_Speadsheet!$B17:$BI17)/1000 -> 0 | G22: =SUMIF(PnL_Speadsheet!$B$3:$BI$3,G$10,PnL_Speadsheet!$B17:$BI17)/1000 -> 0 | H22: =SUMIF(PnL_Speadsheet!$B$3:$BI$3,H$10,PnL_Speadsheet!$B17:$BI17)/1000 -> 0 | I22: =SUMIF(PnL_Speadsheet!$B$3:$BI$3,I$10,PnL_Speadsheet!$B17:$BI17)/1000 -> 0 | J22: =SUMIF(PnL_Speadsheet!$B$3:$BI$3,J$10,PnL_Speadsheet!$B17:$BI17)/1000 -> 0 | K22: =SUMIF(PnL_Speadsheet!$B$3:$BI$3,K$10,PnL_Speadsheet!$B17:$BI17)/1000 -> 0
C23: PROVISION | E23: =SUM(F23:O23) -> -48.023369 | F23: =SUMIF(PnL_Speadsheet!$B$3:$BI$3,F$10,PnL_Speadsheet!$B30:$BI30)/1000 -> -48.023369 | G23: =SUMIF(PnL_Speadsheet!$B$3:$BI$3,G$10,PnL_Speadsheet!$B30:$BI30)/1000 -> 0 | H23: =SUMIF(PnL_Speadsheet!$B$3:$BI$3,H$10,PnL_Speadsheet!$B30:$BI30)/1000 -> 0 | I23: =SUMIF(PnL_Speadsheet!$B$3:$BI$3,I$10,PnL_Speadsheet!$B30:$BI30)/1000 -> 0 | J23: =SUMIF(PnL_Speadsheet!$B$3:$BI$3,J$10,PnL_Speadsheet!$B30:$BI30)/1000 -> 0 | K23: =SUMIF(PnL_Speadsheet!$B$3:$BI$3,K$10,PnL_Speadsheet!$B30:$BI30)/1000 -> 0
C24: OPEX | E24: =SUM(F24:O24) -> -44.140995 | F24: =SUMIF(PnL_Speadsheet!$B$3:$BI$3,F$10,PnL_Speadsheet!$B18:$BI18)/1000 -> -44.140995 | G24: =SUMIF(PnL_Speadsheet!$B$3:$BI$3,G$10,PnL_Speadsheet!$B18:$BI18)/1000 -> 0 | H24: =SUMIF(PnL_Speadsheet!$B$3:$BI$3,H$10,PnL_Speadsheet!$B18:$BI18)/1000 -> 0 | I24: =SUMIF(PnL_Speadsheet!$B$3:$BI$3,I$10,PnL_Speadsheet!$B18:$BI18)/1000 -> 0 | J24: =SUMIF(PnL_Speadsheet!$B$3:$BI$3,J$10,PnL_Speadsheet!$B18:$BI18)/1000 -> 0 | K24: =SUMIF(PnL_Speadsheet!$B$3:$BI$3,K$10,PnL_Speadsheet!$B18:$BI18)/1000 -> 0
C25: Sales incentives | E25: =SUM(F25:O25) -> -0.0075602163 | F25: =SUMIF(PnL_Speadsheet!$B$3:$BI$3,F$10,PnL_Speadsheet!$B20:$BI21)/1000 -> -0.0075602163 | G25: =SUMIF(PnL_Speadsheet!$B$3:$BI$3,G$10,PnL_Speadsheet!$B20:$BI21)/1000 -> 0 | H25: =SUMIF(PnL_Speadsheet!$B$3:$BI$3,H$10,PnL_Speadsheet!$B20:$BI21)/1000 -> 0 | I25: =SUMIF(PnL_Speadsheet!$B$3:$BI$3,I$10,PnL_Speadsheet!$B20:$BI21)/1000 -> 0 | J25: =SUMIF(PnL_Speadsheet!$B$3:$BI$3,J$10,PnL_Speadsheet!$B20:$BI21)/1000 -> 0 | K25: =SUMIF(PnL_Speadsheet!$B$3:$BI$3,K$10,PnL_Speadsheet!$B20:$BI21)/1000 -> 0
C26: Marketing | E26: =SUM(F26:O26) -> -17.302184 | F26: =SUMIF(PnL_Speadsheet!$B$3:$BI$3,F$10,PnL_Speadsheet!$B21:$BI21)/1000 -> -17.302184 | G26: =SUMIF(PnL_Speadsheet!$B$3:$BI$3,G$10,PnL_Speadsheet!$B21:$BI21)/1000 -> 0 | H26: =SUMIF(PnL_Speadsheet!$B$3:$BI$3,H$10,PnL_Speadsheet!$B21:$BI21)/1000 -> 0 | I26: =SUMIF(PnL_Speadsheet!$B$3:$BI$3,I$10,PnL_Speadsheet!$B21:$BI21)/1000 -> 0 | J26: =SUMIF(PnL_Speadsheet!$B$3:$BI$3,J$10,PnL_Speadsheet!$B21:$BI21)/1000 -> 0 | K26: =SUMIF(PnL_Speadsheet!$B$3:$BI$3,K$10,PnL_Speadsheet!$B21:$BI21)/1000 -> 0
C27: UW & Disbursal | E27: =SUM(F27:O27) -> -5.4603004 | F27: =SUMIF(PnL_Speadsheet!$B$3:$BI$3,F$10,PnL_Speadsheet!$B23:$BI23)/1000 -> -5.4603004 | G27: =SUMIF(PnL_Speadsheet!$B$3:$BI$3,G$10,PnL_Speadsheet!$B23:$BI23)/1000 -> 0 | H27: =SUMIF(PnL_Speadsheet!$B$3:$BI$3,H$10,PnL_Speadsheet!$B23:$BI23)/1000 -> 0 | I27: =SUMIF(PnL_Speadsheet!$B$3:$BI$3,I$10,PnL_Speadsheet!$B23:$BI23)/1000 -> 0 | J27: =SUMIF(PnL_Speadsheet!$B$3:$BI$3,J$10,PnL_Speadsheet!$B23:$BI23)/1000 -> 0 | K27: =SUMIF(PnL_Speadsheet!$B$3:$BI$3,K$10,PnL_Speadsheet!$B23:$BI23)/1000 -> 0
C28: Collection & AMC | E28: =SUM(F28:O28) -> -1.9310385 | F28: =SUMIF(PnL_Speadsheet!$B$3:$BI$3,F$10,PnL_Speadsheet!$B27:$BI27)/1000 -> -1.9310385 | G28: =SUMIF(PnL_Speadsheet!$B$3:$BI$3,G$10,PnL_Speadsheet!$B27:$BI27)/1000 -> 0 | H28: =SUMIF(PnL_Speadsheet!$B$3:$BI$3,H$10,PnL_Speadsheet!$B27:$BI27)/1000 -> 0 | I28: =SUMIF(PnL_Speadsheet!$B$3:$BI$3,I$10,PnL_Speadsheet!$B27:$BI27)/1000 -> 0 | J28: =SUMIF(PnL_Speadsheet!$B$3:$BI$3,J$10,PnL_Speadsheet!$B27:$BI27)/1000 -> 0 | K28: =SUMIF(PnL_Speadsheet!$B$3:$BI$3,K$10,PnL_Speadsheet!$B27:$BI27)/1000 -> 0
C29: After-sales services | E29: =SUM(F29:O29) -> -0.293337 | F29: =SUMIF(PnL_Speadsheet!$B$3:$BI$3,F$10,PnL_Speadsheet!$B28:$BI28)/1000 -> -0.293337 | G29: =SUMIF(PnL_Speadsheet!$B$3:$BI$3,G$10,PnL_Speadsheet!$B28:$BI28)/1000 -> 0 | H29: =SUMIF(PnL_Speadsheet!$B$3:$BI$3,H$10,PnL_Speadsheet!$B28:$BI28)/1000 -> 0 | I29: =SUMIF(PnL_Speadsheet!$B$3:$BI$3,I$10,PnL_Speadsheet!$B28:$BI28)/1000 -> 0 | J29: =SUMIF(PnL_Speadsheet!$B$3:$BI$3,J$10,PnL_Speadsheet!$B28:$BI28)/1000 -> 0 | K29: =SUMIF(PnL_Speadsheet!$B$3:$BI$3,K$10,PnL_Speadsheet!$B28:$BI28)/1000 -> 0
C30: Other support units | E30: =SUM(F30:O30) -> -18.963347 | F30: =SUMIF(PnL_Speadsheet!$B$3:$BI$3,F$10,PnL_Speadsheet!$B29:$BI29)/1000 -> -18.963347 | G30: =SUMIF(PnL_Speadsheet!$B$3:$BI$3,G$10,PnL_Speadsheet!$B29:$BI29)/1000 -> 0 | H30: =SUMIF(PnL_Speadsheet!$B$3:$BI$3,H$10,PnL_Speadsheet!$B29:$BI29)/1000 -> 0 | I30: =SUMIF(PnL_Speadsheet!$B$3:$BI$3,I$10,PnL_Speadsheet!$B29:$BI29)/1000 -> 0 | J30: =SUMIF(PnL_Speadsheet!$B$3:$BI$3,J$10,PnL_Speadsheet!$B29:$BI29)/1000 -> 0 | K30: =SUMIF(PnL_Speadsheet!$B$3:$BI$3,K$10,PnL_Speadsheet!$B29:$BI29)/1000 -> 0
C31: PBT | E31: =SUM(F31:O31) -> 14.302111 | F31: =SUMIF(PnL_Speadsheet!$B$3:$BI$3,F$10,PnL_Speadsheet!$B31:$BI31)/1000 -> 14.302111 | G31: =SUMIF(PnL_Speadsheet!$B$3:$BI$3,G$10,PnL_Speadsheet!$B31:$BI31)/1000 -> 0 | H31: =SUMIF(PnL_Speadsheet!$B$3:$BI$3,H$10,PnL_Speadsheet!$B31:$BI31)/1000 -> 0 | I31: =SUMIF(PnL_Speadsheet!$B$3:$BI$3,I$10,PnL_Speadsheet!$B31:$BI31)/1000 -> 0 | J31: =SUMIF(PnL_Speadsheet!$B$3:$BI$3,J$10,PnL_Speadsheet!$B31:$BI31)/1000 -> 0 | K31: =SUMIF(PnL_Speadsheet!$B$3:$BI$3,K$10,PnL_Speadsheet!$B31:$BI31)/1000 -> 0
C32: In which: PROFIT BEFORE SU | E32: =E19+E23+SUM(E25:E29) -> 33.448686 | F32: =F19+F23+SUM(F25:F29) -> 33.448686 | G32: =G19+G23+SUM(G25:G29) -> 0 | H32: =H19+H23+SUM(H25:H29) -> 0 | I32: =I19+I23+SUM(I25:I29) -> 0 | J32: =J19+J23+SUM(J25:J29) -> 0 | K32: =K19+K23+SUM(K25:K29) -> 0

Sheet PnL_Speadsheet
A1: PL PROJECTION
A2: 60 months
B3: =YEAR(B4) -> 2025 | C3: =YEAR(C4) -> 2025 | D3: =YEAR(D4) -> 2025 | E3: =YEAR(E4) -> 2025 | F3: =YEAR(F4) -> 2025 | G3: =YEAR(G4) -> 2025 | H3: =YEAR(H4) -> 2025 | I3: =YEAR(I4) -> 2025 | ... BI3: =YEAR(BI4) -> 2029
A4: Business month | B4: ='Saleplan&PnL'!D4 -> 45658 | C4: ='Saleplan&PnL'!E4 -> 45716 | D4: ='Saleplan&PnL'!F4 -> 45747 | E4: ='Saleplan&PnL'!G4 -> 45777 | F4: ='Saleplan&PnL'!H4 -> 45808 | G4: ='Saleplan&PnL'!I4 -> 45838 | H4: ='Saleplan&PnL'!J4 -> 45869 | I4: ='Saleplan&PnL'!K4 -> 45900 | ... BI4: ='Saleplan&PnL'!BK4 -> 47483
A5: Month on board | B5: 1 | C5: 2 | D5: 3 | E5: 4 | F5: 5 | G5: 6 | H5: 7 | I5: 8 | J5: 9 | K5: 10 | L5: 11 | M5: 12 | N5: 13 | O5: 14 | P5: 15 | Q5: 16 | R5: 17 | S5: 18 | T5: 19 | U5: 20 | V5: 21 | W5: 22 | X5: 23 | Y5: 24 | Z5: 25 | AA5: 26 | AB5: 27 | AC5: 28 | AD5: 29 | AE5: 30 | AF5: 31 | AG5: 32 | AH5: 33 | AI5: 34 | AJ5: 35 | AK5: 36 | AL5: =AK5+1 -> 37 | AM5: =AL5+1 -> 38 | AN5: =AM5+1 -> 39 | AO5: =AN5+1 -> 40 | AP5: =AO5+1 -> 41 | AQ5: =AP5+1 -> 42 | AR5: =AQ5+1 -> 43 | AS5: =AR5+1 -> 44 | ... BI5: =BH5+1 -> 60
A6: Unit: mVND
A7: ENR | B7: {=SUMPRODUCT(B$54:B$113,TRANSPOSE(SAP_Speadsheet!$E$42:$BL$42))} -> 0 | C7: {=SUMPRODUCT(C$54:C$113,TRANSPOSE(SAP_Speadsheet!$E$42:$BL$42))} -> 0 | D7: {=SUMPRODUCT(D$54:D$113,TRANSPOSE(SAP_Speadsheet!$E$42:$BL$42))} -> 0 | E7: {=SUMPRODUCT(E$54:E$113,TRANSPOSE(SAP_Speadsheet!$E$42:$BL$42))} -> 17986.377 | F7: {=SUMPRODUCT(F$54:F$113,TRANSPOSE(SAP_Speadsheet!$E$42:$BL$42))} -> 37713.506 | G7: {=SUMPRODUCT(G$54:G$113,TRANSPOSE(SAP_Speadsheet!$E$42:$BL$42))} -> 66625.389 | H7: {=SUMPRODUCT(H$54:H$113,TRANSPOSE(SAP_Speadsheet!$E$42:$BL$42))} -> 56471.852 | I7: {=SUMPRODUCT(I$54:I$113,TRANSPOSE(SAP_Speadsheet!$E$42:$BL$42))} -> 53478.625 | ... BI7: {=SUMPRODUCT(BI$54:BI$113,TRANSPOSE(SAP_Speadsheet!$E$42:$BL$42))} -> 0
A8: ANR | B8: {=SUMPRODUCT(B$54:B$113,TRANSPOSE(SAP_Speadsheet!$E$48:$BL$48))} -> 0 | C8: {=SUMPRODUCT(C$54:C$113,TRANSPOSE(SAP_Speadsheet!$E$48:$BL$48))} -> 0 | D8: {=SUMPRODUCT(D$54:D$113,TRANSPOSE(SAP_Speadsheet!$E$48:$BL$48))} -> 0 | E8: {=SUMPRODUCT(E$54:E$113,TRANSPOSE(SAP_Speadsheet!$E$48:$BL$48))} -> 127324.62 | F8: {=SUMPRODUCT(F$54:F$113,TRANSPOSE(SAP_Speadsheet!$E$48:$BL$48))} -> 184849.91 | G8: {=SUMPRODUCT(G$54:G$113,TRANSPOSE(SAP_Speadsheet!$E$48:$BL$48))} -> 286357.12 | H8: {=SUMPRODUCT(H$54:H$113,TRANSPOSE(SAP_Speadsheet!$E$48:$BL$48))} -> 61548.621 | I8: {=SUMPRODUCT(I$54:I$113,TRANSPOSE(SAP_Speadsheet!$E$48:$BL$48))} -> 54975.239 | ... BI8: {=SUMPRODUCT(BI$54:BI$113,TRANSPOSE(SAP_Speadsheet!$E$48:$BL$48))} -> 0
A9: TOI | B9: {=SUMPRODUCT(B$54:B$113,TRANSPOSE(SAP_Speadsheet!$E$53:$BL$53))} -> 0 | C9: {=SUMPRODUCT(C$54:C$113,TRANSPOSE(SAP_Speadsheet!$E$53:$BL$53))} -> 0 | D9: {=SUMPRODUCT(D$54:D$113,TRANSPOSE(SAP_Speadsheet!$E$53:$BL$53))} -> 0 | E9: {=SUMPRODUCT(E$54:E$113,TRANSPOSE(SAP_Speadsheet!$E$53:$BL$53))} -> 24859.227 | F9: {=SUMPRODUCT(F$54:F$113,TRANSPOSE(SAP_Speadsheet!$E$53:$BL$53))} -> 33107.461 | G9: {=SUMPRODUCT(G$54:G$113,TRANSPOSE(SAP_Speadsheet!$E$53:$BL$53))} -> 49302.89 | H9: {=SUMPRODUCT(H$54:H$113,TRANSPOSE(SAP_Speadsheet!$E$53:$BL$53))} -> 108.43988 | I9: {=SUMPRODUCT(I$54:I$113,TRANSPOSE(SAP_Speadsheet!$E$53:$BL$53))} -> -253.12506 | ... BI9: {=SUMPRODUCT(BI$54:BI$113,TRANSPOSE(SAP_Speadsheet!$E$53:$BL$53))} -> 0
A10: Checking | B10: =B9-B11-B14 -> 0 | C10: =C9-C11-C14 -> 0 | D10: =D9-D11-D14 -> 0 | E10: =E9-E11-E14 -> 0 | F10: =F9-F11-F14 -> 0 | G10: =G9-G11-G14 -> 0 | H10: =H9-H11-H14 -> 0 | I10: =I9-I11-I14 -> 0 | ... BI10: =BI9-BI11-BI14 -> 0
A11: Net interest income | B11: {=SUMPRODUCT(B$54:B$113,TRANSPOSE(SAP_Speadsheet!$E$55:$BL$55))} -> 0 | C11: {=SUMPRODUCT(C$54:C$113,TRANSPOSE(SAP_Speadsheet!$E$55:$BL$55))} -> 0 | D11: {=SUMPRODUCT(D$54:D$113,TRANSPOSE(SAP_Speadsheet!$E$55:$BL$55))} -> 0 | E11: {=SUMPRODUCT(E$54:E$113,TRANSPOSE(SAP_Speadsheet!$E$55:$BL$55))} -> 9879.3864 | F11: {=SUMPRODUCT(F$54:F$113,TRANSPOSE(SAP_Speadsheet!$E$55:$BL$55))} -> 13232.483 | G11: {=SUMPRODUCT(G$54:G$113,TRANSPOSE(SAP_Speadsheet!$E$55:$BL$55))} -> 19656.549 | H11: {=SUMPRODUCT(H$54:H$113,TRANSPOSE(SAP_Speadsheet!$E$55:$BL$55))} -> 108.43988 | I11: {=SUMPRODUCT(I$54:I$113,TRANSPOSE(SAP_Speadsheet!$E$55:$BL$55))} -> -253.12506 | ... BI11: {=SUMPRODUCT(BI$54:BI$113,TRANSPOSE(SAP_Speadsheet!$E$55:$BL$55))} -> 0
A12: Interest income | B12: {=SUMPRODUCT(B$54:B$113,TRANSPOSE(SAP_Speadsheet!$E$56:$BL$56))} -> 0 | C12: {=SUMPRODUCT(C$54:C$113,TRANSPOSE(SAP_Speadsheet!$E$56:$BL$56))} -> 0 | D12: {=SUMPRODUCT(D$54:D$113,TRANSPOSE(SAP_Speadsheet!$E$56:$BL$56))} -> 0 | E12: {=SUMPRODUCT(E$54:E$113,TRANSPOSE(SAP_Speadsheet!$E$56:$BL$56))} -> 10465.633 | F12: {=SUMPRODUCT(F$54:F$113,TRANSPOSE(SAP_Speadsheet!$E$56:$BL$56))} -> 14083.596 | G12: {=SUMPRODUCT(G$54:G$113,TRANSPOSE(SAP_Speadsheet!$E$56:$BL$56))} -> 20975.037 | H12: {=SUMPRODUCT(H$54:H$113,TRANSPOSE(SAP_Speadsheet!$E$56:$BL$56))} -> 391.83108 | I12: {=SUMPRODUCT(I$54:I$113,TRANSPOSE(SAP_Speadsheet!$E$56:$BL$56))} -> 0 | ... BI12: {=SUMPRODUCT(BI$54:BI$113,TRANSPOSE(SAP_Speadsheet!$E$56:$BL$56))} -> 0
A13: Cost of fund | B13: {=SUMPRODUCT(B$54:B$113,TRANSPOSE(SAP_Speadsheet!$E$57:$BL$57))} -> 0 | C13: {=SUMPRODUCT(C$54:C$113,TRANSPOSE(SAP_Speadsheet!$E$57:$BL$57))} -> 0 | D13: {=SUMPRODUCT(D$54:D$113,TRANSPOSE(SAP_Speadsheet!$E$57:$BL$57))} -> 0 | E13: {=SUMPRODUCT(E$54:E$113,TRANSPOSE(SAP_Speadsheet!$E$57:$BL$57))} -> -586.24669 | F13: {=SUMPRODUCT(F$54:F$113,TRANSPOSE(SAP_Speadsheet!$E$57:$BL$57))} -> -851.11309 | G13: {=SUMPRODUCT(G$54:G$113,TRANSPOSE(SAP_Speadsheet!$E$57:$BL$57))} -> -1318.4875 | H13: {=SUMPRODUCT(H$54:H$113,TRANSPOSE(SAP_Speadsheet!$E$57:$BL$57))} -> -283.39119 | I13: {=SUMPRODUCT(I$54:I$113,TRANSPOSE(SAP_Speadsheet!$E$57:$BL$57))} -> -253.12506 | ... BI13: {=SUMPRODUCT(BI$54:BI$113,TRANSPOSE(SAP_Speadsheet!$E$57:$BL$57))} -> 0
A14: Net fee income | B14: {=SUMPRODUCT(B$54:B$113,TRANSPOSE(SAP_Speadsheet!$E$59:$BL$59))} -> 0 | C14: {=SUMPRODUCT(C$54:C$113,TRANSPOSE(SAP_Speadsheet!$E$59:$BL$59))} -> 0 | D14: {=SUMPRODUCT(D$54:D$113,TRANSPOSE(SAP_Speadsheet!$E$59:$BL$59))} -> 0 | E14: {=SUMPRODUCT(E$54:E$113,TRANSPOSE(SAP_Speadsheet!$E$59:$BL$59))} -> 14979.841 | F14: {=SUMPRODUCT(F$54:F$113,TRANSPOSE(SAP_Speadsheet!$E$59:$BL$59))} -> 19874.978 | G14: {=SUMPRODUCT(G$54:G$113,TRANSPOSE(SAP_Speadsheet!$E$59:$BL$59))} -> 29646.341 | H14: {=SUMPRODUCT(H$54:H$113,TRANSPOSE(SAP_Speadsheet!$E$59:$BL$59))} -> 0 | I14: {=SUMPRODUCT(I$54:I$113,TRANSPOSE(SAP_Speadsheet!$E$59:$BL$59))} -> 0 | ... BI14: {=SUMPRODUCT(BI$54:BI$113,TRANSPOSE(SAP_Speadsheet!$E$59:$BL$59))} -> 0
A15: Insurance fee | B15: {=SUMPRODUCT(B$54:B$113,TRANSPOSE(SAP_Speadsheet!$E$60:$BL$60))} -> 0 | C15: {=SUMPRODUCT(C$54:C$113,TRANSPOSE(SAP_Speadsheet!$E$60:$BL$60))} -> 0 | D15: {=SUMPRODUCT(D$54:D$113,TRANSPOSE(SAP_Speadsheet!$E$60:$BL$60))} -> 0 | E15: {=SUMPRODUCT(E$54:E$113,TRANSPOSE(SAP_Speadsheet!$E$60:$BL$60))} -> 14979.841 | F15: {=SUMPRODUCT(F$54:F$113,TRANSPOSE(SAP_Speadsheet!$E$60:$BL$60))} -> 19874.978 | G15: {=SUMPRODUCT(G$54:G$113,TRANSPOSE(SAP_Speadsheet!$E$60:$BL$60))} -> 29646.341 | H15: {=SUMPRODUCT(H$54:H$113,TRANSPOSE(SAP_Speadsheet!$E$60:$BL$60))} -> 0 | I15: {=SUMPRODUCT(I$54:I$113,TRANSPOSE(SAP_Speadsheet!$E$60:$BL$60))} -> 0 | ... BI15: {=SUMPRODUCT(BI$54:BI$113,TRANSPOSE(SAP_Speadsheet!$E$60:$BL$60))} -> 0
A16: Support fee | B16: {=SUMPRODUCT(B$54:B$113,TRANSPOSE(SAP_Speadsheet!$E$61:$BL$61))} -> 0 | C16: {=SUMPRODUCT(C$54:C$113,TRANSPOSE(SAP_Speadsheet!$E$61:$BL$61))} -> 0 | D16: {=SUMPRODUCT(D$54:D$113,TRANSPOSE(SAP_Speadsheet!$E$61:$BL$61))} -> 0 | E16: {=SUMPRODUCT(E$54:E$113,TRANSPOSE(SAP_Speadsheet!$E$61:$BL$61))} -> 0 | F16: {=SUMPRODUCT(F$54:F$113,TRANSPOSE(SAP_Speadsheet!$E$61:$BL$61))} -> 0 | G16: {=SUMPRODUCT(G$54:G$113,TRANSPOSE(SAP_Speadsheet!$E$61:$BL$61))} -> 0 | H16: {=SUMPRODUCT(H$54:H$113,TRANSPOSE(SAP_Speadsheet!$E$61:$BL$61))} -> 0 | I16: {=SUMPRODUCT(I$54:I$113,TRANSPOSE(SAP_Speadsheet!$E$61:$BL$61))} -> 0 | ... BI16: {=SUMPRODUCT(BI$54:BI$113,TRANSPOSE(SAP_Speadsheet!$E$61:$BL$61))} -> 0
A17: Other income | B17: {=SUMPRODUCT(B$54:B$113,TRANSPOSE(SAP_Speadsheet!$E$63:$BL$63))} -> 0 | C17: {=SUMPRODUCT(C$54:C$113,TRANSPOSE(SAP_Speadsheet!$E$63:$BL$63))} -> 0 | D17: {=SUMPRODUCT(D$54:D$113,TRANSPOSE(SAP_Speadsheet!$E$63:$BL$63))} -> 0 | E17: {=SUMPRODUCT(E$54:E$113,TRANSPOSE(SAP_Speadsheet!$E$63:$BL$63))} -> 0 | F17: {=SUMPRODUCT(F$54:F$113,TRANSPOSE(SAP_Speadsheet!$E$63:$BL$63))} -> 0 | G17: {=SUMPRODUCT(G$54:G$113,TRANSPOSE(SAP_Speadsheet!$E$63:$BL$63))} -> 0 | H17: {=SUMPRODUCT(H$54:H$113,TRANSPOSE(SAP_Speadsheet!$E$63:$BL$63))} -> 0 | I17: {=SUMPRODUCT(I$54:I$113,TRANSPOSE(SAP_Speadsheet!$E$63:$BL$63))} -> 0 | ... BI17: {=SUMPRODUCT(BI$54:BI$113,TRANSPOSE(SAP_Speadsheet!$E$63:$BL$63))} -> 0
